File: src/Milk_AI/Amul full cream after heating 532nm 50% 600g 50xL 10s 10times 400-3500cm-1 200hole.txt
#Acq. time (s)=	10
#Accumulations=	10
#Range (cm-¹)=	400...3500
#Windows=	3
#Auto scanning=	Off
#Autofocus=	Off
#AutoExposure=	Off
#Spike filter=	Multiple accum.
#Delay time (s)=	0
#Binning=	1
#Readout mode=	Signal
#DeNoise=	Off
#ICS correction=	On
#Dark correction=	Off
#Inst. Process=	Off
#Detector Gain=	Best Dynamic Range
#Detector ADC=	45 kHz
#Detector temperature (°C)=	-60.1
#Instrument=	LabRAM HR Evol
#Detector=	Syncerity OE
#Objective=	x50_VIS_LWD
#Grating=	600 (500nm)
#ND Filter=	50%
#Laser=	532nm_Edge
#Hole=	199.981
#Range=	Visible
#E-Cal_Neon=	0
#StageXY=	75x50mm Scan+
#StageZ=	Z motor
#X (µm)=	0
#Y (µm)=	0
#Z (µm)=	1193
#Spectral res.(cm-¹)=	12.8
#Full time(mm:ss)=	5:19
#AC=	Calibrated 2025-06-30 10:26
#Project=
#Sample=
#Site=
#Title=	D_99
#Remark=
#Date=	30.06.2025 17:10 (India Standard Time)
#Acquired=	30.06.2025 17:10:00 (India Standard Time)
#AxisType[0]=Intens
#AxisUnit[0]=Cnt
#AxisType[1]=Spectr
#AxisUnit[1]=1/cm
400.17	27228.3
403.717	27163.9
407.263	27055.7
410.807	26915.6
414.35	26869.2
417.892	26809.3
421.432	26756.9
424.971	26734.9
428.509	26695.2
432.045	26685.5
435.58	26639.7
439.111	26512.6
442.643	26448.1
446.174	26432.3
449.701	26398.3
453.229	26392.4
456.756	26381.9
460.279	26278.1
463.803	26152.5
467.326	26086.7
470.845	26057.7
474.365	25921.2
477.882	25853.4
481.399	25747.7
484.913	25801.1
488.425	25723.3
491.938	25717.5
495.448	25674.2
498.956	25677.8
502.465	25745.4
505.971	25669.8
509.475	25687
512.981	25680.3
516.482	25820.3
519.983	25612
523.482	25502.7
526.979	25427.1
530.476	25300.8
533.971	25134.3
537.464	25030.6
540.956	24939.4
544.447	24869.8
547.937	24852.2
551.425	24749.6
554.912	24706.9
558.398	24520.6
561.882	24418.2
565.365	24483.9
568.847	24598.6
572.325	24535.2
575.804	24737.9
579.282	24836
582.756	24877.3
586.231	24949.4
589.705	25193.1
593.175	25237.2
596.646	25412.8
600.116	25538.2
603.582	25627.7
607.049	25559.7
610.513	25394.5
613.977	25104.2
617.438	25016.9
620.898	24834.8
624.359	24675.3
627.816	24643.4
631.272	24436.1
634.728	24466
638.181	24420.3
641.633	24496.9
645.084	24452.1
648.535	24309.1
651.983	24190.6
655.43	24161.5
658.875	24049.1
662.319	23972.4
665.762	23937.2
669.203	23898
672.643	23787
676.082	23793.6
679.519	23727.7
682.955	23818.1
686.39	23769.4
689.824	23751.8
693.256	23868.9
696.685	23866.1
700.115	24088.8
703.543	24105.1
706.97	24082.6
710.394	24136.9
713.818	24342.8
717.241	24481.6
720.661	24717.2
724.082	24878.7
727.501	24930.5
730.917	24696.5
734.334	24805.9
737.747	24786.5
741.161	24638.4
744.572	24574.8
747.982	24738
751.392	24658.6
754.799	24746.5
758.205	24806
761.611	24841.9
765.014	24946
768.416	25063.8
771.816	24978.2
775.218	24984.3
778.616	24997.8
782.012	24960.4
785.408	25097.1
788.802	25161.2
792.195	25208.6
795.586	25369.2
798.977	25599.5
802.365	25756.6
805.753	26109.1
809.14	26271.5
812.525	26498.3
815.907	26896.3
819.289	27214.4
822.671	27678.9
826.051	28129.2
829.43	28466.1
832.805	28804.4
836.182	29212.1
839.557	29586.4
842.928	30025.7
846.301	30365.4
849.67	30448
853.04	30393
856.407	30496.6
859.774	30791.3
863.138	31291.9
866.503	31709
869.865	31989.4
873.225	31886.6
876.586	31519.4
879.944	31139.4
883.301	30885.4
886.658	31040.3
890.012	31321.6
893.365	30897.6
896.717	30104.5
900.067	29514.5
903.416	29066.9
906.766	28589
910.112	28403.2
913.458	28291.4
916.802	28286.1
920.145	28214.2
923.484	27994.8
926.825	27663.4
930.164	27488.2
933.501	27252.1
936.838	27073
940.173	26961.8
943.505	26864.6
946.838	26880
950.17	26942.3
953.5	26929.7
956.827	26994.7
960.155	26986.3
963.48	27151
966.805	27159
970.128	27019.9
973.45	26804.3
976.77	26492.3
980.091	26260.9
983.408	26246.4
986.726	26376.5
990.041	26528.5
993.354	26767.9
996.668	27403.1
999.979	28458.2
1003.29	29599.8
1006.6	29821.3
1009.91	29285.1
1013.21	28811.7
1016.52	28578.9
1019.82	28473.5
1023.12	28430.2
1026.43	28289.1
1029.73	28251.5
1033.02	28284.7
1036.32	28271
1039.62	28286.4
1042.91	28392
1046.21	28337.6
1049.5	28521.1
1052.79	28932.2
1056.08	29778
1059.37	30964.8
1062.65	32325.3
1065.94	32798.8
1069.23	32151.2
1072.51	32254.4
1075.79	33066
1079.07	33651.3
1082.35	33607.4
1085.63	33022.5
1088.91	32421
1092.18	31434.6
1095.46	30151.1
1098.73	28962
1102	27900.5
1105.27	27230.3
1108.54	27022.6
1111.81	27386.8
1115.08	27986.1
1118.34	28755.1
1121.61	29365
1124.87	29299.5
1128.13	28424.7
1131.39	27118.2
1134.65	26235.2
1137.91	26029.2
1141.17	26346.4
1144.42	27274.7
1147.68	28333.4
1150.93	30448.1
1154.18	33131
1157.43	34746.9
1160.68	32379.8
1163.93	28750.8
1167.18	26529.5
1170.42	25830.2
1173.67	25468.3
1176.91	25164
1180.15	24766.3
1183.39	24855.3
1186.63	25113.1
1189.87	25266.6
1193.11	25259
1196.34	25011
1199.58	24598
1202.81	24177.7
1206.04	24000.9
1209.27	23957.5
1212.5	23987.5
1215.73	23833.2
1218.95	23557
1222.18	23438.8
1225.4	23425.7
1228.63	23561.4
1231.85	23669.3
1235.07	23944.7
1238.29	24133.1
1241.51	24580.8
1244.72	25050.7
1247.94	25463.7
1251.15	25907.2
1254.37	26388
1257.58	26890.4
1260.79	27327.8
1264	27720.7
1267.21	28063.1
1270.41	28052.8
1273.62	27799.1
1276.82	27576.2
1280.03	27735.3
1283.23	28040.7
1286.43	28531.7
1289.63	29533.2
1292.83	31540.1
1296.03	34395.5
1299.22	36895.8
1302.42	37787.8
1305.61	36814.1
1308.8	34758.1
1311.99	32575.3
1315.18	30454.2
1318.37	28857.1
1321.56	27400.2
1324.74	26279.9
1327.93	25301.8
1331.11	24395.8
1334.3	23829.1
1337.48	23551.9
1340.66	23407
1343.84	23350.4
1347.01	23243.1
1350.19	23064
1353.37	22935.6
1356.54	22656.1
1359.71	22590.4
1362.88	22706.4
1366.05	22756
1369.22	22807.3
1372.39	22517
1375.56	21893.9
1378.72	21464
1381.89	21178.3
1385.05	21016.7
1388.21	20952.9
1391.37	20943.1
1394.53	20991.9
1397.69	21125
1400.85	21183.5
1404	21438
1407.16	21563.6
1410.31	21992.8
1413.46	22847
1416.61	23889.4
1419.76	24853.1
1422.91	25675.2
1426.06	27490.7
1429.21	30947.8
1432.35	36526.6
1435.49	42312.6
1438.64	45521.7
1441.78	45315.1
1444.92	43426
1448.06	41524
1451.2	40193.3
1454.33	39030.3
1457.47	37810.3
1460.6	35797.5
1463.74	33314.8
1466.87	30648.9
1470	28447.6
1473.13	26129.5
1476.26	24325.4
1479.38	23061
1482.51	22276.3
1485.63	21683.8
1488.76	21384.9
1491.88	21181.9
1495	21154.6
1498.12	21156.3
1501.24	21348.7
1504.36	21803.2
1507.47	22516.2
1510.59	23808.5
1513.7	25288.6
1516.81	27127.8
1519.93	28415.3
1523.04	28853.5
1526.15	28053.1
1529.25	25959.2
1532.36	23341.9
1535.47	21361.4
1538.57	20137.8
1541.67	19336.5
1544.78	18885.3
1547.88	18504.2
1550.98	18259
1554.08	18137.9
1557.18	18054.1
1560.27	17918.2
1563.37	17852.2
1566.46	17864.8
1569.55	17803.3
1572.64	17781.2
1575.74	17768.6
1578.83	17780.5
1581.91	17765.8
1585	17782.1
1588.09	17751.2
1591.17	17783.5
1594.25	17799.5
1597.34	17772.5
1600.42	17744
1603.5	17795.9
1606.58	17783.2
1609.65	17737.4
1612.73	17650.2
1615.8	17599.7
1618.88	17606.7
1621.95	17640.6
1625.03	17730.3
1628.1	17845
1631.17	18127.9
1634.23	18465.1
1637.3	18862.1
1640.37	19585.2
1643.43	20369.2
1646.5	22261
1649.56	25118.4
1652.62	27935.3
1655.68	28128
1658.74	25671.2
1661.8	23010
1664.85	21103
1667.91	20290
1670.96	19567
1674.02	18588.3
1677.07	17699.2
1680.12	17161.8
1683.17	16859.7
1686.22	16688
1689.27	16449.4
1692.31	16341.3
1695.36	16296
1698.4	16119.7
1701.45	16032.3
1704.49	15929.3
1707.53	15938.4
1710.57	15921.5
1713.61	15855.3
1716.65	15798.3
1719.68	15870.3
1722.72	16081.8
1725.75	16274.2
1728.78	16638
1731.82	17284.9
1734.84	18119.4
1737.87	19072.1
1740.9	19842.4
1743.93	20451.7
1746.96	20700.8
1749.98	20382.4
1753	19693.9
1756.03	18467.3
1759.05	17411.5
1762.07	16434.1
1765.09	15711.8
1768.11	15405.9
1771.12	15169.1
1774.14	15087.3
1777.15	14919.3
1780.17	14919.7
1783.18	14807.6
1786.19	14855.4
1789.2	14792.8
1792.21	14722.1
1795.22	14663.5
1798.22	14618.3
1801.23	14508
1804.23	14535.3
1807.24	14507.7
1810.24	14490
1813.24	14438
1816.24	14445.2
1819.24	14322.7
1822.24	14348.4
1825.23	14313.4
1828.23	14356.5
1831.22	14247.2
1834.22	14225.9
1837.21	14234.2
1840.2	14216.2
1843.19	14181.8
1846.18	14152.5
1849.17	14127
1852.15	14116.3
1855.14	14070.9
1858.12	14042.7
1861.11	14022.9
1864.09	13965
1867.07	13936.9
1870.05	13974
1873.03	13935.4
1876.01	13962
1878.98	13899.9
1881.96	13780.9
1884.93	13750.4
1887.91	13735.9
1890.88	13780.3
1893.85	13729.6
1896.82	13680.8
1899.79	13639.2
1902.76	13544.5
1905.72	13508.1
1908.69	13379.2
1911.65	13403
1914.62	13316.5
1917.58	13231.2
1920.54	13157.4
1923.5	13079.7
1926.46	13070.8
1929.42	12985.6
1932.37	12972
1935.33	12936.6
1938.28	12825.2
1941.24	12759.8
1944.19	12715.9
1947.14	12701.4
1950.09	12600.1
1953.04	12555.6
1955.99	12453.1
1958.93	12415.4
1961.88	12382.6
1964.82	12307.5
1967.77	12254.4
1970.71	12230.5
1973.65	12170.7
1976.59	12136.5
1979.53	12083.2
1982.47	12061.7
1985.41	12002.7
1988.34	11946.7
1991.28	11903.7
1994.21	11831.3
1997.14	11781.9
2000.07	11756.4
2003.01	11703.1
2005.94	11671.4
2008.86	11625.3
2011.79	11621.3
2014.72	11584.8
2017.64	11542.6
2020.57	11459.3
2023.49	11434.1
2026.41	11410.2
2029.33	11398.7
2032.25	11354.2
2035.17	11316.3
2038.09	11313.6
2041	11276.2
2043.92	11195.3
2045.86	11217.6
2048.79	11210.3
2051.71	11183.4
2054.64	11146.9
2057.56	11144.5
2060.48	11120.8
2063.4	11123.1
2066.32	11061.1
2069.24	11054
2072.16	11073.3
2075.08	11034.5
2077.99	11015.8
2080.91	10975.7
2083.82	11001.2
2086.74	10986.8
2089.65	10925.7
2092.56	10928.9
2095.47	10919.5
2098.38	10964.4
2101.29	10849.3
2104.19	10845.8
2107.1	10803.7
2110	10819.2
2112.91	10783.4
2115.81	10729.9
2118.71	10755.7
2121.61	10760.9
2124.51	10704.4
2127.4	10695
2130.3	10672.8
2133.2	10657.3
2136.09	10653.8
2138.99	10669.5
2141.88	10622.2
2144.77	10612.9
2147.66	10630.3
2150.55	10533.1
2153.44	10541.8
2156.33	10536.6
2159.21	10548.1
2162.1	10534.1
2164.98	10501.7
2167.87	10516.9
2170.75	10507.9
2173.63	10495.4
2176.51	10468.1
2179.39	10484.5
2182.27	10461.6
2185.14	10409.2
2188.02	10359.3
2190.9	10399.3
2193.77	10397.1
2196.64	10297.8
2199.51	10286.2
2202.39	10247.8
2205.25	10263.7
2208.12	10223.4
2210.99	10149.7
2213.86	10170.6
2216.72	10095.7
2219.59	10059.1
2222.45	10071.8
2225.31	10014.5
2228.17	10060.5
2231.03	10006.8
2233.89	10027.3
2236.75	9932.19
2239.61	9927.09
2242.46	9937.02
2245.32	9910.35
2248.17	9847.18
2251.03	9821.72
2253.88	9829.24
2256.73	9770.79
2259.58	9704.66
2262.43	9707.13
2265.28	9660.39
2268.12	9642.86
2270.97	9606.91
2273.81	9573.11
2276.66	9602.67
2279.5	9537.48
2282.34	9529.53
2285.18	9470.66
2288.02	9419.82
2290.86	9458.75
2293.7	9378.26
2296.54	9399.33
2299.37	9341.11
2302.21	9383.91
2305.04	9330.03
2307.87	9311.41
2310.7	9308.2
2313.53	9266.67
2316.36	9260.81
2319.19	9147.22
2322.02	9127.54
2324.85	9160.88
2327.67	9310.65
2330.5	9402.99
2333.32	9119.91
2336.14	9034.31
2338.96	9007.27
2341.78	9049.02
2344.6	8939.81
2347.42	8936.35
2350.24	8911.61
2353.05	8881.85
2355.87	8857.65
2358.68	8828.36
2361.5	8775.71
2364.31	8757.12
2367.12	8766.5
2369.93	8723.12
2372.74	8718.02
2375.55	8665.12
2378.35	8626.12
2381.16	8647.81
2383.96	8628.51
2386.77	8587.63
2389.57	8554.67
2392.37	8558.86
2395.17	8581.39
2397.97	8525.81
2400.77	8540.65
2403.57	8479.72
2406.37	8462.7
2409.16	8472.34
2411.96	8430.04
2414.75	8408.52
2417.55	8402.3
2420.34	8365.62
2423.13	8412.28
2425.92	8366.8
2428.71	8332.51
2431.5	8342.3
2434.28	8286.36
2437.07	8277.75
2439.85	8270.69
2442.64	8228.11
2445.42	8228.67
2448.2	8213.72
2450.98	8196.55
2453.76	8135.14
2456.54	8188.94
2459.32	8117.6
2462.1	8092.54
2464.87	8049.14
2467.65	8100.67
2470.42	8021.32
2473.2	8036.32
2475.97	8015.1
2478.74	8031.05
2481.51	7996.54
2484.28	7949.94
2487.05	7904.68
2489.81	7961.79
2492.58	7928.1
2495.34	7937.89
2498.11	7902.02
2500.87	7828.76
2503.63	7839.74
2506.39	7789.03
2509.15	7842.16
2511.91	7806.36
2514.67	7778.64
2517.43	7769.2
2520.19	7750.18
2522.94	7758.81
2525.7	7738.19
2528.45	7713.64
2531.2	7731.52
2533.95	7730.37
2536.7	7705.71
2539.45	7669.85
2542.2	7636.73
2544.95	7640.3
2547.69	7608.49
2550.44	7595.3
2553.18	7586.75
2555.93	7576.22
2558.67	7537.04
2561.41	7529.84
2564.15	7534.9
2566.89	7493.07
2569.63	7491.37
2572.36	7519.31
2575.1	7502.23
2577.84	7525.44
2580.57	7514.73
2583.31	7489.88
2586.04	7476.7
2588.77	7521.97
2591.5	7510.22
2594.23	7551.38
2596.96	7518.37
2599.69	7469
2602.41	7499.99
2605.14	7512.8
2607.86	7499.78
2610.59	7446.27
2613.31	7472.85
2616.03	7435.55
2618.75	7442.54
2621.48	7416.44
2624.19	7396.29
2626.91	7400.21
2629.63	7366.86
2632.35	7440.68
2635.06	7442.91
2637.77	7383.72
2640.49	7378.4
2643.2	7397.47
2645.91	7406.53
2648.62	7428.08
2651.33	7473.67
2654.04	7435.3
2656.75	7447.1
2659.45	7485.64
2662.16	7452.95
2664.86	7495.14
2667.57	7519
2670.27	7499.24
2672.97	7562.23
2675.67	7522.8
2678.37	7520.58
2681.07	7460.96
2683.77	7491.76
2686.47	7470.17
2689.16	7519.04
2691.86	7493.44
2694.55	7490.31
2697.25	7470.22
2699.94	7510.83
2702.63	7610.19
2705.32	7693.68
2708.01	7734.67
2710.7	7779.94
2713.39	7879.64
2716.07	7890.69
2718.76	7965.66
2721.44	8011.96
2724.12	8047.17
2726.81	8037.47
2729.49	8079.49
2732.17	7992.88
2734.85	7850.48
2737.53	7704.49
2740.21	7573.58
2742.88	7420.5
2745.56	7312.83
2748.24	7223.61
2750.91	7139.93
2753.58	7052.69
2756.25	6981.64
2758.93	6937.59
2761.6	6913.23
2764.27	6892.07
2766.93	6880.59
2769.6	6858.12
2772.27	6825.45
2774.93	6820.14
2777.6	6849.29
2780.26	6787.46
2782.93	6763.42
2785.59	6784.31
2788.25	6782.67
2790.91	6776.27
2793.57	6857.98
2796.23	6860.79
2798.88	6837.8
2801.54	6913.21
2804.2	6906.28
2806.85	6978.84
2809.5	6986.6
2812.16	7068.35
2814.81	7135.8
2817.46	7281.37
2820.11	7403.79
2822.76	7561.81
2825.4	7756.97
2828.05	8044.01
2830.7	8462.45
2833.34	9003.52
2835.99	9844.18
2838.63	11031.5
2841.27	13087.9
2843.91	16294.7
2846.55	20811.6
2849.19	24968.8
2851.83	26864.9
2854.47	26400.1
2857.11	25060.5
2859.74	23717.6
2862.38	22670.7
2865.01	21772.5
2867.65	21389.4
2870.28	21785.8
2872.91	22457.9
2875.54	22898.4
2878.17	23044.7
2880.8	23385.9
2883.42	23942.3
2886.05	24580.1
2888.68	25018.8
2891.3	25280.7
2893.93	25327.6
2896.55	25376.2
2899.17	25287.8
2901.79	25194.2
2904.41	25114.8
2907.03	24877.1
2909.65	24652.1
2912.27	24473
2914.88	24363.1
2917.5	24137.9
2920.11	24075.2
2922.73	24134.9
2925.34	24243.5
2927.95	24312.2
2930.56	24219.4
2933.17	24144.9
2935.78	23698.1
2938.39	22901.7
2941	21510.7
2943.6	19707
2946.21	17945.9
2948.81	16564.7
2951.42	15695.8
2954.02	15076
2956.62	14729.8
2959.22	14413.2
2961.82	14034
2964.42	13428.8
2967.02	12859.8
2969.62	12271.4
2972.21	11507.6
2974.81	10910.9
2977.4	10451.5
2980	9936.27
2982.59	9557.29
2985.18	9219.01
2987.77	8926.75
2990.36	8712.55
2992.95	8547.55
2995.54	8384.42
2998.13	8370.85
3000.72	8379.06
3003.3	8298.12
3005.89	8330.23
3008.47	8214.38
3011.05	7976.43
3013.63	7784.45
3016.22	7523.7
3018.8	7287.2
3021.38	7053.58
3023.95	6879.06
3026.53	6722.05
3029.11	6591.97
3031.68	6534.29
3034.26	6480.81
3036.83	6408.73
3039.4	6395.22
3041.98	6355.09
3044.55	6344.29
3047.12	6324.36
3049.69	6353.39
3052.26	6309.25
3054.82	6334.77
3057.39	6357.07
3059.96	6352.8
3062.52	6378.08
3065.09	6393.96
3067.65	6369.63
3070.21	6362.39
3072.77	6371.52
3075.33	6352.8
3077.89	6283.94
3080.45	6282.51
3083.01	6271.36
3085.57	6253.3
3088.12	6264.92
3090.68	6332.72
3093.23	6293.27
3095.79	6312.1
3098.34	6334.14
3100.89	6332.76
3103.44	6386.46
3105.99	6361.59
3108.54	6432.5
3111.09	6439.6
3113.63	6460
3116.18	6526.63
3118.73	6587.24
3121.27	6613.43
3123.82	6635.48
3126.36	6680.71
3128.9	6725.4
3131.44	6798.15
3133.98	6812.04
3136.52	6857.99
3139.06	6904.83
3141.6	6924.16
3144.13	6987.4
3146.67	7018.95
3149.2	7116.49
3151.74	7140.69
3154.27	7188.28
3156.8	7228.13
3159.34	7276.88
3161.86	7296.32
3164.4	7327.33
3166.92	7406.01
3169.45	7470.55
3171.98	7442.97
3174.5	7459.33
3177.03	7464.03
3179.56	7444.7
3182.08	7460.86
3184.6	7488.63
3187.12	7455.61
3189.64	7508.02
3192.16	7476.81
3194.68	7449.87
3197.2	7467.26
3199.72	7473.38
3202.24	7443.89
3204.75	7461.15
3207.27	7470.17
3209.78	7429.78
3212.29	7444.81
3214.81	7363.96
3217.32	7358.62
3219.83	7383.07
3222.34	7334.27
3224.85	7345.2
3227.35	7318.29
3229.86	7289.38
3232.37	7269.81
3234.87	7240.08
3237.38	7225.54
3239.88	7199.15
3242.38	7170.82
3244.89	7128.45
3247.39	7132.52
3249.89	7098.02
3252.39	7092.47
3254.88	7027.86
3257.38	7011.69
3259.88	6983.86
3262.37	6932.92
3264.87	6923.9
3267.36	6893.63
3269.86	6907.05
3272.35	6881.6
3274.84	6848.06
3277.33	6813.08
3279.82	6769.05
3282.31	6756.85
3284.8	6723.72
3287.29	6701.02
3289.77	6672.31
3292.26	6665.47
3294.15	6630.17
3296.64	6624.14
3299.14	6596.77
3301.63	6578.83
3304.12	6574.66
3306.62	6548.54
3309.11	6546.19
3311.6	6519.39
3314.09	6459.86
3316.58	6457.76
3319.07	6457.5
3321.56	6442.99
3324.04	6435.81
3326.53	6441.78
3329.01	6393.87
3331.5	6384.61
3333.98	6361.78
3336.46	6358.87
3338.94	6362.81
3341.42	6328.93
3343.9	6293.84
3346.38	6253.05
3348.86	6256.9
3351.34	6258.03
3353.82	6206.12
3356.29	6224.02
3358.77	6227.37
3361.24	6203.29
3363.71	6180.08
3366.19	6165.5
3368.66	6169.2
3371.13	6160.69
3373.6	6137.4
3376.07	6129.11
3378.54	6125.76
3381	6082.16
3383.47	6091.7
3385.94	6064.51
3388.4	6081.33
3390.87	6033.38
3393.33	6053.12
3395.79	6024.18
3398.25	6025.85
3400.71	5966.27
3403.17	5941.82
3405.63	5946.1
3408.09	5902.27
3410.55	5937.84
3413	5910.15
3415.46	5867.1
3417.92	5826.23
3420.37	5855.65
3422.82	5799.65
3425.27	5761.5
3427.73	5744.66
3430.18	5728.7
3432.63	5709.55
3435.08	5673.25
3437.53	5676.46
3439.97	5612.6
3442.42	5567.21
3444.86	5513.11
3447.31	5488.28
3449.75	5497.97
3452.2	5450.03
3454.64	5408.52
3457.08	5362.23
3459.52	5354.34
3461.96	5329.06
3464.4	5255.97
3466.84	5267.81
3469.28	5183.15
3471.72	5169.84
3474.15	5062.56
3476.59	5044.01
3479.02	5016.94
3481.45	5003.59
3483.89	4933.26
3486.32	4891.59
3488.75	4808.18
3491.18	4793.11
3493.61	4744.77
3496.04	4693.82
3498.47	4634.7
3499.68	4630.87