File: src/Milk_AI/Amul full cream RT after 24h 532nm 50% 600g 50xL 10s 10times 400-3500cm-1 200hole.txt
#Acq. time (s)=	7
#Accumulations=	20
#Range (cm-¹)=	400...3500
#Windows=	3
#Auto scanning=	Off
#Autofocus=	Off
#AutoExposure=	Off
#Spike filter=	Multiple accum.
#Delay time (s)=	0
#Binning=	1
#Readout mode=	Signal
#DeNoise=	Off
#ICS correction=	On
#Dark correction=	Off
#Inst. Process=	Off
#Detector Gain=	Best Dynamic Range
#Detector ADC=	45 kHz
#Detector temperature (°C)=	-60.1
#Instrument=	LabRAM HR Evol
#Detector=	Syncerity OE
#Objective=	x50_VIS_LWD
#Grating=	600 (500nm)
#ND Filter=	50%
#Laser=	532nm_Edge
#Hole=	199.981
#Range=	Visible
#E-Cal_Neon=	0
#StageXY=	75x50mm Scan+
#StageZ=	Z motor
#X (µm)=	0
#Y (µm)=	0
#Z (µm)=	340.4
#Spectral res.(cm-¹)=	12.8
#Full time(mm:ss)=	7:26
#AC=	Calibrated 2025-07-01 10:31
#Project=
#Sample=
#Site=
#Title=	D_1
#Remark=
#Date=	01.07.2025 12:34 (India Standard Time)
#Acquired=	01.07.2025 12:34:20 (India Standard Time)
#AxisType[0]=Intens
#AxisUnit[0]=Cnt
#AxisType[1]=Spectr
#AxisUnit[1]=1/cm
400.083	15214.7
403.63	15117.6
407.176	15095.4
410.72	15091.8
414.263	15081.8
417.805	15143.2
421.345	15117.7
424.884	15082.5
428.421	15128.8
431.955	15103.7
435.49	15089.1
439.023	15050.9
442.555	14994.9
446.084	15017.9
449.613	14969.8
453.141	14927.7
456.666	14946.4
460.191	14905.2
463.715	14859.3
467.235	14834.2
470.756	14822
474.274	14858.5
477.793	14845.5
481.308	14796.8
484.823	14799.1
488.336	14774
491.847	14779.5
495.358	14795.4
498.867	14776.2
502.374	14810.5
505.881	14843
509.386	14848.9
512.888	14788.6
516.39	14840.9
519.89	14765.1
523.391	14714.5
526.889	14727.1
530.385	14669.3
533.88	14683.1
537.373	14639.1
540.866	14569.5
544.357	14559.6
547.846	14546.3
551.334	14509.3
554.821	14512.2
558.307	14503.1
561.789	14486.4
565.272	14508.2
568.753	14510.6
572.233	14499.4
575.712	14524.4
579.188	14498.5
582.664	14464.5
586.139	14514.2
589.611	14488.4
593.083	14488.7
596.554	14482.3
600.021	14538.7
603.49	14514.4
606.955	14517.7
610.42	14441.7
613.882	14372.8
617.345	14359.4
620.805	14322.2
624.263	14289.1
627.722	14193.1
631.178	14192.7
634.633	14229.3
638.088	14189.5
641.539	14260.7
644.99	14166.5
648.439	14092.8
651.887	14098
655.335	14033.5
658.781	14080.8
662.225	14059.1
665.667	14028.5
669.108	14051.9
672.548	14006.7
675.987	13969.3
679.424	13955.9
682.86	13988.3
686.293	14004.2
689.727	13999.5
693.159	13971.4
696.59	13985.1
700.019	13982.4
703.448	13987.3
706.872	13925.3
710.298	13932.2
713.723	13951.8
717.144	13908.4
720.565	13933.7
723.984	13920.9
727.403	13917.4
730.821	13876.3
734.235	13891.8
737.651	13899.7
741.063	13803.5
744.474	13788.8
747.885	13833.4
751.293	13856.3
754.702	13804.9
758.108	13828.9
761.512	13793.3
764.915	13839.6
768.319	13858.6
771.719	13812.8
775.118	13832.3
778.516	13821.5
781.913	13764.4
785.308	13829.1
788.702	13746
792.095	13821.4
795.486	13737.3
798.876	13788.2
802.265	13805.2
805.653	13789.4
809.039	13805.1
812.424	13748.7
815.808	13759.2
819.191	13809.4
822.572	13887.4
825.95	13958.8
829.329	13964.9
832.706	13979.1
836.08	14020.5
839.455	13988
842.829	14076.6
846.199	14077.2
849.57	14119.8
852.938	14081.7
856.307	14069.7
859.672	14212.6
863.038	14176
866.401	14174.9
869.765	14148.9
873.125	14179.4
876.484	14180.4
879.844	14103.3
883.2	14038.1
886.555	14033.1
889.909	13983.7
893.262	13889.2
896.616	13770.6
899.966	13720.7
903.315	13718.4
906.663	13572.2
910.009	13591.3
913.354	13550.2
916.698	13609
920.041	13552
923.383	13478.6
926.723	13380.5
930.062	13395.3
933.399	13349.2
936.734	13283.6
940.069	13354.6
943.403	13352.4
946.736	13308.2
950.065	13394.2
953.396	13378
956.725	13338.5
960.051	13374.9
963.377	13364.7
966.7	13311.5
970.025	13259.7
973.345	13184.5
976.667	13172.9
979.985	13169.8
983.304	13232.9
986.62	13231.1
989.935	13282.7
993.25	13362.2
996.563	13581.5
999.874	13877.9
1003.19	13925.1
1006.49	13791.8
1009.8	13561.9
1013.11	13397.8
1016.41	13394
1019.72	13318.3
1023.02	13263.8
1026.32	13196.1
1029.62	13181
1032.92	13149.1
1036.22	13122.3
1039.51	13077.8
1042.81	13140.7
1046.1	13053.6
1049.39	13148.4
1052.68	13221.1
1055.97	13345.6
1059.26	13550.6
1062.55	13636.5
1065.83	13485
1069.12	13402.6
1072.4	13423.5
1075.68	13488.2
1078.97	13489.8
1082.24	13465.5
1085.52	13404.1
1088.8	13263.3
1092.08	13106.6
1095.35	13009
1098.62	12909.5
1101.9	12881.4
1105.17	12765.5
1108.44	12757.8
1111.7	12849.7
1114.97	12947.4
1118.23	13000.9
1121.5	13077.3
1124.76	13137.8
1128.03	13015.4
1131.29	12831.9
1134.54	12696.9
1137.8	12708.7
1141.06	12738.8
1144.31	13065.1
1147.57	13522.8
1150.82	14195.2
1154.07	14654.7
1157.32	14411.9
1160.57	13560
1163.82	12892.5
1167.07	12628.7
1170.31	12488.8
1173.56	12428.3
1176.8	12365.9
1180.04	12294.5
1183.28	12333.3
1186.52	12358.7
1189.76	12354.8
1192.99	12312.6
1196.23	12236.5
1199.46	12140.9
1202.7	12038.7
1205.93	12024.6
1209.16	12069.1
1212.39	11992.5
1215.62	11866.1
1218.84	11812.4
1222.07	11799.2
1225.29	11786.9
1228.52	11812.7
1231.74	11831.2
1234.96	11818
1238.18	11868.2
1241.4	11934
1244.61	12007.5
1247.83	12026.5
1251.04	12081.7
1254.25	12117
1257.47	12170.3
1260.68	12146.7
1263.89	12222.6
1267.09	12218.9
1270.3	12155.1
1273.51	12077.6
1276.71	12037.6
1279.91	12072
1283.12	12050.3
1286.32	12108.7
1289.52	12343.6
1292.72	12718.3
1295.91	12980.1
1299.11	12929.5
1302.3	12857.1
1305.5	12651.1
1308.69	12419.5
1311.88	12185.9
1315.07	11943.3
1318.26	11809.7
1321.44	11677.4
1324.63	11528.9
1327.82	11508.7
1331	11426.7
1334.18	11377.3
1337.36	11347.7
1340.54	11335.9
1343.72	11261.6
1346.9	11278.5
1350.07	11262.6
1353.25	11196.9
1356.42	11155.7
1359.6	11132.5
1362.77	11113.6
1365.94	11100.9
1369.11	11079.3
1372.28	10993.9
1375.44	10856.5
1378.61	10807.2
1381.77	10833.6
1384.93	10771.7
1388.1	10814.5
1391.26	10792.4
1394.41	10738.9
1397.57	10726.6
1400.73	10764.7
1403.89	10775.3
1407.04	10807
1410.19	10877.1
1413.35	10985.6
1416.5	11089.8
1419.65	11172.2
1422.8	11325.4
1425.94	11558.3
1429.09	12085.2
1432.23	12678.9
1435.38	13280.2
1438.52	13409.4
1441.66	13263.4
1444.8	13010.1
1447.94	12837.7
1451.08	12651.9
1454.22	12506.4
1457.35	12340
1460.48	12052.5
1463.62	11807.8
1466.75	11464.5
1469.88	11156.1
1473.01	10898.6
1476.14	10692.1
1479.26	10548.9
1482.39	10462.2
1485.51	10416.8
1488.64	10383.2
1491.76	10402.4
1494.88	10483.1
1498	10499.8
1501.12	10636.2
1504.24	10784
1507.35	11052.5
1510.47	11465.4
1513.58	11933
1516.69	12296.7
1519.81	12431.9
1522.92	12309.9
1526.03	11879.6
1529.13	11242.9
1532.24	10711.3
1535.35	10356.4
1538.45	10139.9
1541.55	10004.5
1544.66	9928.71
1547.76	9830.28
1550.86	9806.01
1553.96	9792.84
1557.05	9731.01
1560.15	9705.23
1563.24	9674.54
1566.34	9674.93
1569.43	9703.18
1572.52	9678.16
1575.61	9647.08
1578.7	9651.07
1581.79	9624.49
1584.88	9610.71
1587.96	9645.72
1591.05	9632.75
1594.13	9612.56
1597.21	9596.38
1600.3	9613.89
1603.37	9603.04
1606.45	9583.7
1609.53	9534.89
1612.61	9520.23
1615.68	9488.96
1618.76	9492.81
1621.83	9461.8
1624.9	9443.48
1627.97	9490.42
1631.04	9512.28
1634.11	9583.41
1637.18	9593.69
1640.24	9670.07
1643.31	9819.82
1646.37	10065.7
1649.44	10418.3
1652.5	10556.7
1655.56	10368.6
1658.62	10010.9
1661.67	9753.36
1664.73	9636.6
1667.79	9541.96
1670.84	9405.7
1673.89	9309.38
1676.95	9181.14
1680	9126.72
1683.05	9090
1686.1	9011.94
1689.14	8995.86
1692.19	8890.18
1695.23	8900.97
1698.28	8811.78
1701.32	8771.73
1704.36	8757.09
1707.4	8756.82
1710.44	8716.05
1713.48	8688.75
1716.52	8660.45
1719.56	8681.39
1722.59	8695.66
1725.63	8732.85
1728.66	8744.09
1731.69	8834.99
1734.72	8875.74
1737.75	8989.25
1740.78	9037.19
1743.8	9028.1
1746.83	8953.27
1749.86	8899.98
1752.88	8805.32
1755.9	8619.5
1758.92	8490.48
1761.94	8439.61
1764.96	8394.48
1767.98	8358.39
1771	8305.73
1774.01	8282.7
1777.03	8262.85
1780.04	8273.39
1783.05	8244.83
1786.06	8232.51
1789.07	8240.46
1792.08	8214.64
1795.09	8190.93
1798.1	8134.58
1801.1	8123.38
1804.11	8133.31
1807.11	8120.54
1810.11	8095.52
1813.11	8084.04
1816.11	8070.1
1819.11	8043.2
1822.11	7998.55
1825.11	8020.81
1828.1	7999.15
1831.1	7969.5
1834.09	8002.87
1837.08	7933.72
1840.07	7978.8
1843.06	7963.81
1846.05	7948.28
1849.04	7910
1852.02	7879.93
1855.01	7889.03
1857.99	7889.4
1860.98	7827.42
1863.96	7834.17
1866.94	7818.18
1869.92	7813.36
1872.9	7788.92
1875.88	7803.59
1878.85	7755.2
1881.83	7790.16
1884.8	7709.63
1887.78	7723.27
1890.75	7712.35
1893.72	7700.29
1896.69	7643.31
1899.66	7621.61
1902.63	7573.92
1905.59	7487.86
1908.56	7446.8
1911.52	7407.19
1914.49	7348.49
1917.45	7264.72
1920.41	7215.95
1923.37	7172.99
1926.33	7111.92
1929.29	7080.56
1932.24	7037.92
1935.2	6998.77
1938.15	6917.77
1941.1	6865.67
1944.06	6842.76
1947.01	6787.97
1949.96	6737.85
1952.91	6665.51
1955.86	6609.37
1958.8	6560.28
1961.75	6524.33
1964.69	6477.47
1967.64	6439.11
1970.58	6399.54
1973.52	6371.67
1976.46	6304.68
1979.4	6266.07
1982.34	6235.17
1985.27	6194.31
1988.21	6162.23
1991.14	6100.54
1994.08	6041.4
1997.01	6011.28
1999.94	5959.72
2002.87	5919.71
2005.8	5888.07
2008.73	5863.56
2011.66	5811.06
2014.58	5789.55
2017.51	5760.94
2020.43	5691.35
2023.36	5658.83
2026.28	5616.93
2029.2	5614.09
2032.12	5564.12
2035.04	5540.39
2037.95	5515.95
2040.87	5473.08
2043.78	5450.01
2045.76	5439.97
2048.69	5439.24
2051.61	5412.19
2054.54	5393.27
2057.46	5389.16
2060.38	5387.94
2063.3	5381.27
2066.22	5398.49
2069.14	5356.22
2072.06	5350.76
2074.98	5308.7
2077.89	5325.3
2080.81	5328.86
2083.72	5302.07
2086.63	5281.82
2089.55	5292.07
2092.46	5278.07
2095.37	5266.41
2098.28	5251.82
2101.18	5237.25
2104.09	5210.93
2106.99	5209.72
2109.9	5225.39
2112.8	5205.07
2115.71	5190.81
2118.61	5197.01
2121.51	5170.44
2124.4	5171.15
2127.3	5148.31
2130.2	5133.27
2133.09	5137.84
2135.99	5138.01
2138.88	5124.38
2141.78	5099.83
2144.67	5119.42
2147.56	5100.27
2150.45	5098.14
2153.34	5096.2
2156.22	5074.06
2159.11	5091.81
2162	5086.57
2164.88	5061.69
2167.76	5045.18
2170.64	5059.25
2173.53	5040.61
2176.41	5037.13
2179.29	5013.97
2182.16	5018.47
2185.04	4998.87
2187.92	5001.6
2190.79	4993.24
2193.66	4971.05
2196.54	4954.37
2199.41	4967.29
2202.28	4953.65
2205.15	4928.48
2208.02	4932.09
2210.88	4913.1
2213.75	4905.83
2216.62	4888.56
2219.48	4858.18
2222.34	4848.22
2225.21	4836.85
2228.07	4831.98
2230.93	4823.37
2233.79	4819.58
2236.65	4786.58
2239.5	4787.66
2242.36	4762.95
2245.21	4734.89
2248.07	4739.87
2250.92	4741.38
2253.77	4732.87
2256.62	4701.2
2259.47	4666.88
2262.32	4667.44
2265.17	4633.04
2268.02	4637.4
2270.86	4624.56
2273.71	4611.81
2276.55	4610.43
2279.39	4583.13
2282.24	4556.21
2285.08	4564.78
2287.92	4529.37
2290.75	4560.9
2293.59	4537.77
2296.43	4510.46
2299.26	4512.1
2302.1	4483
2304.93	4477.5
2307.76	4464.96
2310.6	4469.6
2313.43	4448.57
2316.25	4422.17
2319.08	4421.69
2321.91	4433.04
2324.74	4459.65
2327.56	4563.95
2330.39	4518.78
2333.21	4377.21
2336.03	4335.8
2338.85	4329.16
2341.67	4333.99
2344.49	4305.51
2347.31	4305.02
2350.13	4285.69
2352.94	4258.83
2355.76	4256.93
2358.57	4243.41
2361.39	4209.88
2364.2	4210.34
2367.01	4197.26
2369.82	4196.66
2372.63	4173.45
2375.44	4148.52
2378.24	4148.61
2381.05	4145.55
2383.85	4137.77
2386.66	4135.78
2389.46	4145.07
2392.26	4127.25
2395.06	4097.61
2397.86	4085.84
2400.66	4084.44
2403.46	4063.09
2406.26	4049.41
2409.05	4047.68
2411.85	4037.26
2414.64	4007.6
2417.43	4028.84
2420.23	4009.38
2423.02	4015.63
2425.81	3992.2
2428.6	3971.54
2431.38	3975.41
2434.17	3974.41
2436.96	3947.78
2439.74	3947.76
2442.53	3937.88
2445.31	3921.29
2448.09	3935.6
2450.87	3915.1
2453.65	3909.95
2456.43	3882.54
2459.21	3878.17
2461.98	3877.2
2464.76	3854.26
2467.53	3867.34
2470.31	3850.94
2473.08	3834.62
2475.85	3818.31
2478.63	3822.65
2481.39	3795.93
2484.16	3794.41
2486.93	3810.96
2489.7	3786.52
2492.46	3757.7
2495.23	3753.36
2497.99	3753.62
2500.76	3747.18
2503.52	3724.25
2506.28	3724.42
2509.04	3707.69
2511.8	3696.64
2514.56	3694.62
2517.31	3689.48
2520.07	3695.6
2522.82	3675.48
2525.58	3686.65
2528.33	3670.68
2531.09	3683.64
2533.84	3663.38
2536.59	3626.12
2539.34	3637.67
2542.08	3612.45
2544.83	3600.78
2547.58	3607.8
2550.32	3593.37
2553.07	3585.79
2555.81	3564.7
2558.55	3558.9
2561.29	3554.06
2564.03	3583.82
2566.77	3568.8
2569.51	3532.53
2572.25	3543.71
2574.99	3547.47
2577.72	3549.56
2580.46	3533.94
2583.19	3528.96
2585.92	3542.83
2588.65	3523.19
2591.38	3527.97
2594.11	3515.86
2596.84	3531.62
2599.57	3498.73
2602.3	3493.05
2605.02	3499.61
2607.75	3495.23
2610.47	3491.6
2613.19	3494.6
2615.92	3449.88
2618.64	3441.45
2621.36	3473.11
2624.08	3456.6
2626.8	3441.09
2629.51	3433.85
2632.23	3422.55
2634.94	3443.57
2637.66	3415.53
2640.37	3430.48
2643.08	3438.77
2645.79	3428.95
2648.5	3439.19
2651.21	3415.17
2653.92	3429.12
2656.63	3442.28
2659.33	3421.91
2662.04	3418.76
2664.75	3413.72
2667.45	3402.62
2670.15	3423.92
2672.85	3424.83
2675.55	3422.72
2678.25	3389.98
2680.95	3388.01
2683.65	3377.3
2686.35	3370.39
2689.04	3384.1
2691.74	3367.07
2694.43	3390.76
2697.13	3383.16
2699.82	3373.17
2702.51	3394.05
2705.2	3421.79
2707.89	3442.6
2710.58	3441.98
2713.26	3444.37
2715.95	3473.74
2718.64	3465.75
2721.32	3470.42
2724	3468.89
2726.69	3460.98
2729.37	3467.77
2732.05	3416.7
2734.73	3382.13
2737.41	3348.26
2740.09	3284.79
2742.76	3265.87
2745.44	3249.99
2748.11	3218.23
2750.79	3192.54
2753.46	3184.45
2756.13	3161.47
2758.81	3157.44
2761.47	3157.97
2764.14	3126.97
2766.81	3125.91
2769.48	3105.29
2772.15	3103.66
2774.81	3111.53
2777.48	3098.91
2780.14	3069.58
2782.8	3081.07
2785.47	3076.78
2788.13	3082.67
2790.79	3070.09
2793.44	3081.44
2796.1	3090.08
2798.76	3084.94
2801.42	3100.42
2804.07	3087.36
2806.73	3091.19
2809.38	3090.37
2812.03	3127.13
2814.68	3156.75
2817.33	3174.73
2819.98	3195.17
2822.63	3222.5
2825.28	3295.83
2827.93	3390.63
2830.57	3485.78
2833.22	3687.88
2835.86	3937.28
2838.51	4370.03
2841.15	5049.93
2843.79	5942.96
2846.43	6833.32
2849.07	7386.8
2851.71	7434.93
2854.35	7193.2
2856.98	6903.84
2859.62	6649.9
2862.25	6441.86
2864.89	6318.59
2867.52	6335.81
2870.15	6513.86
2872.78	6658.65
2875.41	6831.97
2878.04	7023.41
2880.67	7192.36
2883.3	7206.86
2885.92	7149.64
2888.55	7115.82
2891.18	7128.03
2893.8	7077.37
2896.42	7096.74
2899.04	7042.44
2901.67	7017.16
2904.29	6977.04
2906.9	6926.67
2909.52	6863.71
2912.14	6830.1
2914.76	6782.96
2917.37	6740.78
2919.99	6735.34
2922.6	6718.73
2925.21	6734.33
2927.82	6716.72
2930.44	6712.21
2933.05	6667.68
2935.65	6542.12
2938.26	6315.46
2940.87	5954.05
2943.48	5538.56
2946.08	5197.63
2948.69	4942.79
2951.29	4794.03
2953.89	4711.84
2956.49	4640.33
2959.1	4569.36
2961.7	4450.1
2964.29	4309.58
2966.89	4179.53
2969.49	4029.24
2972.09	3891.96
2974.68	3744.31
2977.28	3654.95
2979.87	3553.56
2982.46	3480.9
2985.05	3430.27
2987.65	3345.82
2990.24	3302.26
2992.82	3305.96
2995.41	3266.03
2998	3270.42
3000.59	3275.03
3003.17	3267.09
3005.76	3246
3008.34	3228.74
3010.92	3177.21
3013.5	3128.34
3016.09	3077.7
3018.67	3025.41
3021.25	2992.82
3023.82	2958.05
3026.4	2933.53
3028.98	2902.47
3031.55	2910.52
3034.13	2897.93
3036.7	2889.13
3039.28	2880.88
3041.85	2889.15
3044.42	2883.46
3046.99	2873.21
3049.56	2882.77
3052.13	2893.03
3054.69	2908.23
3057.26	2900.7
3059.83	2923.92
3062.39	2934.99
3064.95	2935.67
3067.52	2929.17
3070.08	2938.2
3072.64	2920.94
3075.2	2916.3
3077.76	2923.92
3080.32	2943.55
3082.88	2934.28
3085.44	2948.47
3087.99	2973.14
3090.55	2981.23
3093.1	2995.49
3095.65	2994.67
3098.21	2999.81
3100.76	3014.19
3103.31	3022.47
3105.86	3040.93
3108.41	3065.04
3110.96	3081.78
3113.5	3101.49
3116.05	3098.31
3118.59	3105.08
3121.14	3167.97
3123.68	3167.44
3126.23	3205.34
3128.77	3214.46
3131.31	3230.45
3133.85	3260.33
3136.39	3270.72
3138.93	3280.42
3141.46	3290.41
3144	3343.19
3146.54	3337.59
3149.07	3375.34
3151.6	3400.87
3154.14	3424.7
3156.67	3427.9
3159.2	3459.64
3161.73	3462.23
3164.26	3497.88
3166.79	3500.61
3169.32	3484.61
3171.84	3510.74
3174.37	3497.04
3176.9	3521.13
3179.42	3522.71
3181.94	3498.38
3184.47	3542.17
3186.99	3532.25
3189.51	3543.64
3192.03	3544.96
3194.55	3535.05
3197.07	3550.15
3199.58	3539.51
3202.1	3547.19
3204.62	3549.04
3207.13	3553.38
3209.65	3548.85
3212.16	3541.57
3214.67	3542.65
3217.18	3529.09
3219.69	3536.89
3222.2	3520.99
3224.71	3513.34
3227.22	3523.83
3229.73	3508.48
3232.23	3501.92
3234.74	3502.03
3237.24	3483.48
3239.75	3489.3
3242.25	3474.01
3244.75	3463.95
3247.25	3464.33
3249.75	3443.66
3252.25	3443.44
3254.75	3431.26
3257.25	3414.34
3259.74	3406.35
3262.24	3384.83
3264.73	3395.05
3267.23	3378.63
3269.72	3362.45
3272.21	3360.75
3274.7	3362.03
3277.2	3327.16
3279.69	3332.45
3282.17	3323.53
3284.66	3317.14
3287.15	3313.62
3289.64	3303.16
3292.12	3283.9
3293.56	3267.1
3296.05	3277.6
3298.55	3276.87
3301.04	3255.51
3303.54	3253.96
3306.03	3267.39
3308.52	3240.24
3311.01	3247.86
3313.5	3242.79
3315.99	3220.05
3318.48	3217.33
3320.97	3201.3
3323.45	3224.79
3325.94	3210.48
3328.42	3198.08
3330.91	3219.09
3333.39	3196.63
3335.87	3196.36
3338.36	3185.62
3340.84	3186.93
3343.32	3172.15
3345.8	3173.17
3348.27	3191.19
3350.75	3158.74
3353.23	3170.01
3355.7	3175.55
3358.18	3159.79
3360.65	3136.35
3363.13	3137.19
3365.6	3133.12
3368.07	3122.32
3370.54	3133.69
3373.01	3145.42
3375.48	3131.11
3377.95	3126.87
3380.42	3126.28
3382.88	3112.47
3385.35	3102.92
3387.81	3105.48
3390.28	3068.82
3392.74	3098.29
3395.2	3069.6
3397.67	3102.23
3400.13	3100.09
3402.58	3081.48
3405.05	3072.54
3407.5	3060.89
3409.96	3053.73
3412.42	3044.79
3414.87	3039.87
3417.33	3042.09
3419.78	3023.51
3422.23	3004.25
3424.69	3008.26
3427.14	3005.27
3429.59	2996.03
3432.04	2985.54
3434.49	2954.13
3436.94	2963.13
3439.39	2941.06
3441.83	2923.23
3444.28	2912.79
3446.72	2893.25
3449.17	2906.64
3451.61	2858.57
3454.05	2862.65
3456.5	2860.99
3458.94	2827.13
3461.38	2816.87
3463.81	2806.28
3466.25	2790.8
3468.69	2790.32
3471.13	2761.92
3473.56	2716.09
3476	2708.21
3478.43	2694.59
3480.87	2682.4
3483.3	2649.2
3485.73	2627.6
3488.16	2624.2
3490.59	2599.33
3493.02	2585.68
3495.45	2558.19
3497.88	2542.36
3499.09	2539.71