File: src/Milk_AI/Amul toned milk basic 532nm 50% 600g 50xL 10s 10times 400-3500cm-1 200hole.txt
#Acq. time (s)=	10
#Accumulations=	10
#Range (cm-¹)=	400...3500
#Windows=	3
#Auto scanning=	Off
#Autofocus=	Off
#AutoExposure=	Off
#Spike filter=	Multiple accum.
#Delay time (s)=	0
#Binning=	1
#Readout mode=	Signal
#DeNoise=	Off
#ICS correction=	On
#Dark correction=	Off
#Inst. Process=	Off
#Detector Gain=	Best Dynamic Range
#Detector ADC=	45 kHz
#Detector temperature (°C)=	-60.1
#Instrument=	LabRAM HR Evol
#Detector=	Syncerity OE
#Objective=	x50_VIS_LWD
#Grating=	600 (500nm)
#ND Filter=	50%
#Laser=	532nm_Edge
#Hole=	199.981
#Range=	Visible
#E-Cal_Neon=	0
#StageXY=	75x50mm Scan+
#StageZ=	Z motor
#X (µm)=	0
#Y (µm)=	0
#Z (µm)=	633.1
#Spectral res.(cm-¹)=	12.8
#Full time(mm:ss)=	5:19
#AC=	Calibrated 2025-07-01 10:31
#Project=
#Sample=
#Site=
#Title=	D_1
#Remark=
#Date=	01.07.2025 15:35 (India Standard Time)
#Acquired=	01.07.2025 15:35:51 (India Standard Time)
#AxisType[0]=Intens
#AxisUnit[0]=Cnt
#AxisType[1]=Spectr
#AxisUnit[1]=1/cm
400.083	42926.6
403.63	42683.5
407.176	42739.1
410.72	42813.5
414.263	42803.4
417.805	42990.7
421.345	42882.6
424.884	42892.3
428.421	42909.7
431.955	43012.2
435.49	43055.3
439.023	43028.9
442.555	43047
446.084	43019.6
449.613	43018.7
453.141	42925.5
456.666	43065.6
460.191	42966.8
463.715	43021.8
467.235	43085.1
470.756	43034.3
474.274	43082.8
477.793	43085.4
481.308	43116
484.823	43188.6
488.336	43243.5
491.847	43154.2
495.358	43128.1
498.867	43368.5
502.374	43467.6
505.881	43485.3
509.386	43555.3
512.888	43551.7
516.39	43625.6
519.89	43649.9
523.391	43582.7
526.889	43620
530.385	43540.8
533.88	43428
537.373	43506.1
540.866	43411.2
544.357	43450.3
547.846	43454
551.334	43526.9
554.821	43580.7
558.307	43599.6
561.789	43515.1
565.272	43606.3
568.753	43629.4
572.233	43645.4
575.712	43725.4
579.188	43789.9
582.664	43691.9
586.139	43768.8
589.611	43852.1
593.083	43832
596.554	43822.7
600.021	43721.9
603.49	43941.8
606.955	43821.5
610.42	43811.6
613.882	43635.5
617.345	43850.7
620.805	43717.1
624.263	43550.3
627.722	43526.5
631.178	43440.9
634.633	43694.2
638.088	43645.4
641.539	43766.7
644.99	43483.7
648.439	43551.4
651.887	43545.2
655.335	43652
658.781	43705.3
662.225	43598
665.667	43602.9
669.108	43627.8
672.548	43558.1
675.987	43623.3
679.424	43771.9
682.86	43843.3
686.293	43640.9
689.727	43680.8
693.159	43842
696.59	43811.7
700.019	43912.1
703.448	43745.6
706.872	43841.6
710.298	43618.1
713.723	43603.8
717.144	43691.8
720.565	43851.8
723.984	43750.9
727.403	43754
730.821	43676
734.235	43659.1
737.651	43724.7
741.063	43618.4
744.474	43628.6
747.885	43711.3
751.293	43811.8
754.702	43794
758.108	43924
761.512	43797.6
764.915	43825.7
768.319	44052.4
771.719	43949.8
775.118	44043.5
778.516	44028.1
781.913	43992.1
785.308	44065.9
788.702	43922
792.095	43961
795.486	43774.9
798.876	44027.2
802.265	43935.6
805.653	43903.6
809.039	43937.1
812.424	43790.9
815.808	43813
819.191	43828
822.572	43993.1
825.95	44050.4
829.329	44087.5
832.706	44046.6
836.08	44180.6
839.455	44074.1
842.829	44366.7
846.199	44236.4
849.57	44271.8
852.938	44328.8
856.307	44329.4
859.672	44456.3
863.038	44387.9
866.401	44327.7
869.765	44313.3
873.125	44361.8
876.484	44465.7
879.844	44259.9
883.2	44138
886.555	44140
889.909	44200.1
893.262	44104.1
896.616	43885.7
899.966	43859.1
903.315	43903.6
906.663	43710.2
910.009	43645.3
913.354	43776.4
916.698	43667.3
920.041	43627.1
923.383	43700.9
926.723	43523.3
930.062	43668.5
933.399	43486.6
936.734	43442.7
940.069	43618.6
943.403	43638.4
946.736	43544.3
950.065	43669.1
953.396	43572.9
956.725	43523.2
960.051	43672.6
963.377	43765.2
966.7	43607.8
970.025	43500.2
973.345	43528.8
976.667	43417.7
979.985	43479.7
983.304	43492
986.62	43643.1
989.935	43776.2
993.25	43754.2
996.563	44070.1
999.874	44413.1
1003.19	44188.5
1006.49	43927.3
1009.8	43731.3
1013.11	43671
1016.41	43705.1
1019.72	43535.4
1023.02	43504.8
1026.32	43407.5
1029.62	43325.2
1032.92	43433.3
1036.22	43343.2
1039.51	43358
1042.81	43272.4
1046.1	43206.1
1049.39	43277.8
1052.68	43363.2
1055.97	43481.7
1059.26	43661.8
1062.55	43685.2
1065.83	43554.3
1069.12	43534.3
1072.4	43602.9
1075.68	43562.4
1078.97	43578.8
1082.24	43631.3
1085.52	43523.8
1088.8	43327.4
1092.08	43213.2
1095.35	43011.8
1098.62	42857.5
1101.9	42921
1105.17	42736.4
1108.44	42810.9
1111.7	42940.6
1114.97	43016.3
1118.23	43060.1
1121.5	43092.3
1124.76	43095.4
1128.03	42806.8
1131.29	42716
1134.54	42558.1
1137.8	42613.4
1141.06	42694.6
1144.31	43036.6
1147.57	43363.4
1150.82	43930
1154.07	44120
1157.32	43556.2
1160.57	42886.2
1163.82	42536.9
1167.07	42255.7
1170.31	42269.7
1173.56	42156.4
1176.8	42091
1180.04	42068.2
1183.28	42049.3
1186.52	42036.6
1189.76	42029.7
1192.99	41933.4
1196.23	41804
1199.46	41694.7
1202.7	41730.3
1205.93	41714.8
1209.16	41718.1
1212.39	41732.6
1215.62	41569.6
1218.84	41473.6
1222.07	41597.6
1225.29	41587
1228.52	41655.9
1231.74	41514.9
1234.96	41522.5
1238.18	41574.5
1241.4	41659.9
1244.61	41769.8
1247.83	41890.1
1251.04	41676.1
1254.25	41739.7
1257.47	41800.2
1260.68	41770.6
1263.89	41737.9
1267.09	41782.6
1270.3	41635.2
1273.51	41582.9
1276.71	41558
1279.91	41373.1
1283.12	41353.1
1286.32	41382.7
1289.52	41681.6
1292.72	41981.7
1295.91	42152.1
1299.11	41963.1
1302.3	42091.9
1305.5	41812.5
1308.69	41622.7
1311.88	41324.2
1315.07	41032.4
1318.26	41065.8
1321.44	40596.4
1324.63	40793.8
1327.82	40689.9
1331	40700.3
1334.18	40644.1
1337.36	40570.3
1340.54	40590.5
1343.72	40495.8
1346.9	40398.5
1350.07	40400.9
1353.25	40283.5
1356.42	40120.8
1359.6	40054
1362.77	39981.1
1365.94	40072.2
1369.11	39874.1
1372.28	39903.6
1375.44	39607.5
1378.61	39637.5
1381.77	39583.3
1384.93	39467.5
1388.1	39638.5
1391.26	39396.3
1394.41	39402.4
1397.57	39423.3
1400.73	39321.4
1403.89	39382.2
1407.04	39354.2
1410.19	39432.6
1413.35	39480.4
1416.5	39627.3
1419.65	39773.6
1422.8	39709.2
1425.94	40058.2
1429.09	40551.3
1432.23	41184.1
1435.38	41614.1
1438.52	41524.3
1441.66	41403
1444.8	41262.9
1447.94	41116.8
1451.08	40787.7
1454.22	40664.3
1457.35	40386.7
1460.48	40169.7
1463.62	39893
1466.75	39438.3
1469.88	39094.5
1473.01	38753
1476.14	38491.5
1479.26	38269.8
1482.39	38246.7
1485.51	38254.7
1488.64	38290.2
1491.76	38274
1494.88	38337.1
1498	38243.4
1501.12	38422.7
1504.24	38492.1
1507.35	38720.8
1510.47	39018.5
1513.58	39375.3
1516.69	39620.8
1519.81	39526.1
1522.92	39378.7
1526.03	38945.2
1529.13	38362.7
1532.24	37970.6
1535.35	37733
1538.45	37554.5
1541.55	37602.8
1544.66	37404
1547.76	37289.7
1550.86	37246.7
1553.96	37028.1
1557.05	37073.6
1560.15	37085
1563.24	37137.9
1566.34	37160.6
1569.43	37096.6
1572.52	37116.8
1575.61	36944.9
1578.7	36952.5
1581.79	36983
1584.88	36892.7
1587.96	36895.9
1591.05	36782.5
1594.13	36848.9
1597.21	36803.7
1600.3	36952.3
1603.37	36791
1606.45	36730.8
1609.53	36640.9
1612.61	36564.6
1615.68	36440.1
1618.76	36380.9
1621.83	36384.2
1624.9	36379.1
1627.97	36384.8
1631.04	36515
1634.11	36449.6
1637.18	36433
1640.24	36622.1
1643.31	36678.2
1646.37	36949.3
1649.44	37134.2
1652.5	37071.5
1655.56	36833.9
1658.62	36596.8
1661.67	36358.6
1664.73	36195.1
1667.79	36128.7
1670.84	36034.3
1673.89	35954.6
1676.95	35665.3
1680	35491.4
1683.05	35311.3
1686.1	35207.1
1689.14	35147.4
1692.19	35023.5
1695.23	34944
1698.28	34906.4
1701.32	34718.3
1704.36	34580.2
1707.4	34567.8
1710.44	34595.4
1713.48	34392.2
1716.52	34406.7
1719.56	34309.1
1722.59	34337.3
1725.63	34376.4
1728.66	34411.8
1731.69	34378.6
1734.72	34453.8
1737.75	34512.3
1740.78	34477.7
1743.8	34344.2
1746.83	34297.3
1749.86	34174.3
1752.88	34054.9
1755.9	33911.4
1758.92	33800.7
1761.94	33705.7
1764.96	33551.5
1767.98	33588.5
1771	33556
1774.01	33484.2
1777.03	33466.8
1780.04	33499.6
1783.05	33332.4
1786.06	33360.9
1789.07	33359.2
1792.08	33245
1795.09	33236
1798.1	33314.7
1801.1	33064.7
1804.11	33108.3
1807.11	33026.4
1810.11	32970.5
1813.11	32987.5
1816.11	32886.8
1819.11	32772.5
1822.11	32675.2
1825.11	32688
1828.1	32693.8
1831.1	32555
1834.09	32550.8
1837.08	32479
1840.07	32532.9
1843.06	32498.8
1846.05	32447
1849.04	32378.7
1852.02	32348.7
1855.01	32237.7
1857.99	32183.6
1860.98	32130.6
1863.96	32138.3
1866.94	32169.5
1869.92	32060.2
1872.9	31890.9
1875.88	32009.6
1878.85	31983.2
1881.83	31944.9
1884.8	31724.2
1887.78	31709.6
1890.75	31748
1893.72	31665.5
1896.69	31454.9
1899.66	31440.2
1902.63	31276.6
1905.59	31055.9
1908.56	30864.2
1911.52	30628.4
1914.49	30504.2
1917.45	30277.2
1920.41	30088.2
1923.37	29935.8
1926.33	29732.7
1929.29	29674.7
1932.24	29457.6
1935.2	29320.1
1938.15	29071.8
1941.1	28890.3
1944.06	28765.9
1947.01	28609.6
1949.96	28401.2
1952.91	28168.7
1955.86	27975
1958.8	27811.6
1961.75	27695.3
1964.69	27555.8
1967.64	27414.4
1970.58	27236.1
1973.52	27113.5
1976.46	26963.9
1979.4	26782.8
1982.34	26629.6
1985.27	26542
1988.21	26371.9
1991.14	26207.6
1994.08	25978.6
1997.01	25804.8
1999.94	25689.9
2002.87	25502
2005.8	25399.6
2008.73	25319.5
2011.66	25191.4
2014.58	25107
2017.51	24923.3
2020.43	24772.7
2023.36	24578.5
2026.28	24475
2029.2	24407.6
2032.12	24293.2
2035.04	24157.6
2037.95	24035.2
2040.87	23912.3
2043.78	23857.5
2045.76	23805.3
2048.69	23689.2
2051.61	23663.8
2054.54	23622.2
2057.46	23565.9
2060.38	23605.6
2063.3	23566.7
2066.22	23519.4
2069.14	23490.3
2072.06	23438.6
2074.98	23375.4
2077.89	23398.2
2080.81	23305.5
2083.72	23300.3
2086.63	23231.8
2089.55	23157.5
2092.46	23110.6
2095.37	23036.4
2098.28	23102.9
2101.18	23037.3
2104.09	22990.6
2106.99	22933.7
2109.9	22930.9
2112.8	22884.1
2115.71	22851.4
2118.61	22823.2
2121.51	22800.2
2124.4	22786.5
2127.3	22671.6
2130.2	22703.3
2133.09	22698.8
2135.99	22642.2
2138.88	22595.8
2141.78	22578.4
2144.67	22616
2147.56	22603.5
2150.45	22557.6
2153.34	22461.9
2156.22	22432.7
2159.11	22460.7
2162	22460.1
2164.88	22401.6
2167.76	22312.7
2170.64	22334
2173.53	22359
2176.41	22315.2
2179.29	22261.4
2182.16	22203.7
2185.04	22130
2187.92	22111.9
2190.79	22084.5
2193.66	22094
2196.54	21978.7
2199.41	21923.6
2202.28	21954.3
2205.15	21925.2
2208.02	21852.4
2210.88	21757.8
2213.75	21768.8
2216.62	21683.8
2219.48	21662.6
2222.34	21634.4
2225.21	21515.1
2228.07	21553.8
2230.93	21509
2233.79	21496.2
2236.65	21374.6
2239.5	21381.2
2242.36	21267.8
2245.21	21323.6
2248.07	21263.8
2250.92	21237.9
2253.77	21155.2
2256.62	21065.7
2259.47	20967
2262.32	20900.8
2265.17	20888.4
2268.02	20826.7
2270.86	20775.7
2273.71	20696.8
2276.55	20683.7
2279.39	20632.8
2282.24	20575.4
2285.08	20553.6
2287.92	20433.7
2290.75	20446.1
2293.59	20458.1
2296.43	20310.5
2299.26	20287.9
2302.1	20247
2304.93	20140.4
2307.76	20059.2
2310.6	20100.3
2313.43	20040.3
2316.25	20002.8
2319.08	19977
2321.91	19867.6
2324.74	19991.3
2327.56	20132.6
2330.39	19771.8
2333.21	19723.3
2336.03	19651.8
2338.85	19694.7
2341.67	19643.9
2344.49	19587.1
2347.31	19561.1
2350.13	19476.2
2352.94	19350.7
2355.76	19406.6
2358.57	19268.2
2361.39	19298.4
2364.2	19175.8
2367.01	19175.4
2369.82	19103.8
2372.63	19057.3
2375.44	18996.7
2378.24	18982.2
2381.05	18993.2
2383.85	18911.1
2386.66	18929.6
2389.46	18888.2
2392.26	18824.6
2395.06	18796.7
2397.86	18794.6
2400.66	18708.1
2403.46	18649.4
2406.26	18651.3
2409.05	18554.2
2411.85	18528.2
2414.64	18503
2417.43	18456
2420.23	18439.6
2423.02	18445.9
2425.81	18391.1
2428.6	18369.5
2431.38	18327.3
2434.17	18317
2436.96	18256.5
2439.74	18229.2
2442.53	18187.2
2445.31	18108.1
2448.09	18102.9
2450.87	18078.1
2453.65	18018.6
2456.43	17976.3
2459.21	17956.3
2461.98	17914.3
2464.76	17850.6
2467.53	17815.9
2470.31	17828.7
2473.08	17728.6
2475.85	17787.3
2478.63	17711
2481.39	17671.5
2484.16	17596.9
2486.93	17628.9
2489.7	17545.2
2492.46	17531.9
2495.23	17535.3
2497.99	17457.4
2500.76	17497.6
2503.52	17346.2
2506.28	17361.4
2509.04	17267.5
2511.8	17262.1
2514.56	17276.6
2517.31	17210
2520.07	17257.4
2522.82	17152.4
2525.58	17083.6
2528.33	17131
2531.09	17070.9
2533.84	17115.3
2536.59	17023.1
2539.34	17021.9
2542.08	16959.5
2544.83	16969.4
2547.58	16880
2550.32	16859.7
2553.07	16791.3
2555.81	16762.2
2558.55	16766.9
2561.29	16670.1
2564.03	16661.6
2566.77	16664.8
2569.51	16617
2572.25	16639.3
2574.99	16561.2
2577.72	16508.3
2580.46	16562.7
2583.19	16483.2
2585.92	16456.8
2588.65	16482.1
2591.38	16423.4
2594.11	16474.6
2596.84	16429.4
2599.57	16382.7
2602.3	16302.3
2605.02	16316.1
2607.75	16304.9
2610.47	16307.9
2613.19	16250
2615.92	16229.1
2618.64	16172.5
2621.36	16157.5
2624.08	16155.1
2626.8	16089.7
2629.51	16093.9
2632.23	16013.1
2634.94	16013.7
2637.66	15986.4
2640.37	15930.9
2643.08	15920.5
2645.79	15880.1
2648.5	15868.7
2651.21	15887.8
2653.92	15792.3
2656.63	15819.3
2659.33	15765.5
2662.04	15775.7
2664.75	15727.2
2667.45	15720.8
2670.15	15695.4
2672.85	15716.5
2675.55	15656
2678.25	15624.7
2680.95	15537.7
2683.65	15564.5
2686.35	15498.3
2689.04	15471.8
2691.74	15458.3
2694.43	15470
2697.13	15353.1
2699.82	15395.1
2702.51	15404.8
2705.2	15434.1
2707.89	15395.8
2710.58	15384.3
2713.26	15325.3
2715.95	15322.8
2718.64	15269.8
2721.32	15251.1
2724	15221.9
2726.69	15197
2729.37	15213.5
2732.05	15198.3
2734.73	15083.7
2737.41	15033.6
2740.09	14944.1
2742.76	14849.9
2745.44	14888
2748.11	14866.2
2750.79	14800.6
2753.46	14843.7
2756.13	14749.6
2758.81	14679.3
2761.47	14663.6
2764.14	14633.3
2766.81	14625.8
2769.48	14525.6
2772.15	14586.2
2774.81	14521.3
2777.48	14521.4
2780.14	14486.1
2782.8	14420.9
2785.47	14396.5
2788.13	14284.5
2790.79	14314.9
2793.44	14307.7
2796.1	14296
2798.76	14299.5
2801.42	14262.2
2804.07	14226.4
2806.73	14128.4
2809.38	14162.2
2812.03	14171.9
2814.68	14154.9
2817.33	14165
2819.98	14143.6
2822.63	14161.6
2825.28	14157
2827.93	14214.4
2830.57	14239.6
2833.22	14326.2
2835.86	14558.8
2838.51	14756
2841.15	15200.7
2843.79	15676.8
2846.43	16155.6
2849.07	16335.5
2851.71	16361
2854.35	16166
2856.98	16010.5
2859.62	15927.1
2862.25	15756.6
2864.89	15778
2867.52	15882.9
2870.15	15927.9
2872.78	16043.4
2875.41	16092.8
2878.04	16199.2
2880.67	16212.2
2883.3	16235.9
2885.92	16221.7
2888.55	16304
2891.18	16268.1
2893.8	16213.3
2896.42	16224.3
2899.04	16137.1
2901.67	16104.4
2904.29	16114
2906.9	16047.2
2909.52	15968.4
2912.14	16021.1
2914.76	15986.3
2917.37	15935
2919.99	15922
2922.6	15941.7
2925.21	15949
2927.82	15829.8
2930.44	15891.6
2933.05	15831.1
2935.65	15712.2
2938.26	15546.9
2940.87	15276.6
2943.48	14882.3
2946.08	14670.6
2948.69	14553.6
2951.29	14430.8
2953.89	14390.6
2956.49	14265.2
2959.1	14194.7
2961.7	14101.3
2964.29	13972.5
2966.89	13916.8
2969.49	13767.1
2972.09	13679.5
2974.68	13545.2
2977.28	13536.5
2979.87	13465.6
2982.46	13400.1
2985.05	13346.2
2987.65	13220
2990.24	13167.1
2992.82	13115.6
2995.41	13084.2
2998	13039.2
3000.59	13011.5
3003.17	12984
3005.76	12935.3
3008.34	12955
3010.92	12871.7
3013.5	12790.7
3016.09	12830.2
3018.67	12741.4
3021.25	12741.6
3023.82	12750.1
3026.4	12734.1
3028.98	12700.3
3031.55	12678
3034.13	12688.4
3036.7	12671.2
3039.28	12655.4
3041.85	12674.4
3044.42	12643
3046.99	12665.6
3049.56	12721.1
3052.13	12722
3054.69	12749.6
3057.26	12745.7
3059.83	12760.9
3062.39	12773.5
3064.95	12817.5
3067.52	12765.3
3070.08	12817.2
3072.64	12776.4
3075.2	12791.3
3077.76	12819.3
3080.32	12855.4
3082.88	12797.8
3085.44	12794.1
3087.99	12843.5
3090.55	12905.5
3093.1	12922.1
3095.65	12859.1
3098.21	12912.4
3100.76	12897.3
3103.31	12984.4
3105.86	13049.1
3108.41	13048.2
3110.96	13150.7
3113.5	13128.5
3116.05	13157.9
3118.59	13239.3
3121.14	13221
3123.68	13251.7
3126.23	13305
3128.77	13387.4
3131.31	13462.6
3133.85	13447.5
3136.39	13530.2
3138.93	13529.7
3141.46	13584.5
3144	13653.5
3146.54	13648.9
3149.07	13750.6
3151.6	13788.1
3154.14	13811.5
3156.67	13926.6
3159.2	13896
3161.73	13846
3164.26	13977.7
3166.79	13991.6
3169.32	13976.1
3171.84	13968.5
3174.37	13963.2
3176.9	13945.3
3179.42	13927.1
3181.94	13967.4
3184.47	13966.5
3186.99	13910
3189.51	13961.1
3192.03	13948.9
3194.55	13873.5
3197.07	13849.3
3199.58	13878.9
3202.1	13832
3204.62	13891.5
3207.13	13853.5
3209.65	13830.8
3212.16	13766.1
3214.67	13790.8
3217.18	13739.4
3219.69	13706.7
3222.2	13682.4
3224.71	13617.7
3227.22	13638.1
3229.73	13585.9
3232.23	13557.8
3234.74	13552.6
3237.24	13547.5
3239.75	13483.6
3242.25	13463
3244.75	13449.7
3247.25	13378
3249.75	13348.7
3252.25	13305.4
3254.75	13225.9
3257.25	13173.7
3259.74	13130
3262.24	13059
3264.73	13060.4
3267.23	13079.4
3269.72	13022.9
3272.21	13005.9
3274.7	12973.7
3277.2	12914.5
3279.69	12907.5
3282.17	12877.2
3284.66	12798
3287.15	12808.6
3289.64	12739.3
3292.12	12705.7
3293.56	12697.5
3296.05	12685.1
3298.55	12620.1
3301.04	12620.4
3303.54	12575.5
3306.03	12582.2
3308.52	12517
3311.01	12519.9
3313.5	12477.9
3315.99	12402.9
3318.48	12411.1
3320.97	12416.9
3323.45	12436
3325.94	12361.2
3328.42	12342.4
3330.91	12369.5
3333.39	12279.4
3335.87	12256.3
3338.36	12261
3340.84	12207.3
3343.32	12155.7
3345.8	12238.5
3348.27	12142.8
3350.75	12112.9
3353.23	12058.7
3355.7	12104.5
3358.18	12048.5
3360.65	12029.5
3363.13	11990
3365.6	11968.2
3368.07	11921.3
3370.54	11981.9
3373.01	11908.2
3375.48	11882.3
3377.95	11931
3380.42	11862.7
3382.88	11809.7
3385.35	11811.4
3387.81	11771.2
3390.28	11766.6
3392.74	11763.6
3395.2	11703.4
3397.67	11692.3
3400.13	11653.3
3402.58	11622.2
3405.05	11673.9
3407.5	11610.9
3409.96	11569.4
3412.42	11563.3
3414.87	11479.7
3417.33	11488.6
3419.78	11410.8
3422.23	11401.1
3424.69	11312.4
3427.14	11300
3429.59	11193.3
3432.04	11201
3434.49	11165.9
3436.94	11185.1
3439.39	11079.7
3441.83	11060.9
3444.28	10998
3446.72	10936.6
3449.17	10876.9
3451.61	10851.8
3454.05	10825.6
3456.5	10804.7
3458.94	10733.1
3461.38	10675.7
3463.81	10637
3466.25	10574.7
3468.69	10551.6
3471.13	10442.5
3473.56	10376.8
3476	10377.6
3478.43	10281.3
3480.87	10238.6
3483.3	10167.8
3485.73	10116.5
3488.16	10054
3490.59	9975.46
3493.02	9933.63
3495.45	9851.17
3497.88	9743.62
3499.09	9775.26