File: src/Milk_AI/Amul toned milk after heating 532nm 50% 600g 50xL 10s 10times 400-3500cm-1 200hole.txt
#Acq. time (s)=	8
#Accumulations=	15
#Range (cm-¹)=	400...3500
#Windows=	3
#Auto scanning=	Off
#Autofocus=	Off
#AutoExposure=	Off
#Spike filter=	Multiple accum.
#Delay time (s)=	0
#Binning=	1
#Readout mode=	Signal
#DeNoise=	Off
#ICS correction=	On
#Dark correction=	Off
#Inst. Process=	Off
#Detector Gain=	Best Dynamic Range
#Detector ADC=	45 kHz
#Detector temperature (°C)=	-60.1
#Instrument=	LabRAM HR Evol
#Detector=	Syncerity OE
#Objective=	x50_VIS_LWD
#Grating=	600 (500nm)
#ND Filter=	50%
#Laser=	532nm_Edge
#Hole=	199.981
#Range=	Visible
#E-Cal_Neon=	0
#StageXY=	75x50mm Scan+
#StageZ=	Z motor
#X (µm)=	0
#Y (µm)=	0
#Z (µm)=	1158.8
#Spectral res.(cm-¹)=	12.8
#Full time(mm:ss)=	6:22
#AC=	Calibrated 2025-06-30 10:26
#Project=
#Sample=
#Site=
#Title=	D_99
#Remark=
#Date=	30.06.2025 16:40 (India Standard Time)
#Acquired=	30.06.2025 16:40:20 (India Standard Time)
#AxisType[0]=Intens
#AxisUnit[0]=Cnt
#AxisType[1]=Spectr
#AxisUnit[1]=1/cm
400.17	28712.6
403.717	28530.6
407.263	28664
410.807	28675.6
414.35	28657.1
417.892	28780.7
421.432	28740.5
424.971	28775.1
428.509	28798.7
432.045	28851.4
435.58	28877.9
439.111	28818.5
442.643	28931.4
446.174	28909.7
449.701	28867.2
453.229	28884.4
456.756	28895.1
460.279	28862.2
463.803	28814.8
467.326	28860.4
470.845	28845.5
474.365	28861.4
477.882	28894.4
481.399	28950
484.913	28914.2
488.425	28979.6
491.938	28953.3
495.448	28951.6
498.956	29133.3
502.465	29152.4
505.971	29145.6
509.475	29228.5
512.981	29265.8
516.482	29322.2
519.983	29260.8
523.482	29232.3
526.979	29241.2
530.476	29269.3
533.971	29199.9
537.464	29182.8
540.956	29166.7
544.447	29156.4
547.937	29223.6
551.425	29169.2
554.912	29260.9
558.398	29182.5
561.882	29209.2
565.365	29213.2
568.847	29330.4
572.325	29353.4
575.804	29344.5
579.282	29352.7
582.756	29461.4
586.231	29481.7
589.705	29501.7
593.175	29416.9
596.646	29521.7
600.116	29382.6
603.582	29540
607.049	29472.3
610.513	29496.5
613.977	29443.6
617.438	29428.1
620.898	29416.1
624.359	29310.4
627.816	29303
631.272	29221.8
634.728	29254.1
638.181	29239.4
641.633	29406.9
645.084	29250.6
648.535	29246.7
651.983	29195.9
655.43	29238.9
658.875	29293.7
662.319	29264
665.762	29191.6
669.203	29373.6
672.643	29267.8
676.082	29273.4
679.519	29279.2
682.955	29363.7
686.39	29444.6
689.824	29391.5
693.256	29426.5
696.685	29462.3
700.115	29450
703.543	29483.5
706.97	29419.9
710.394	29383.3
713.818	29399.9
717.241	29292
720.661	29419.4
724.082	29319.9
727.501	29372.9
730.917	29321.7
734.334	29283.5
737.747	29324.7
741.161	29299
744.572	29229.1
747.982	29334.3
751.392	29301.8
754.799	29355.9
758.205	29442.6
761.611	29461.1
765.014	29504.6
768.416	29510.5
771.816	29529
775.218	29571.6
778.616	29520.7
782.012	29591.1
785.408	29635.2
788.802	29559.3
792.195	29517.5
795.586	29624.2
798.977	29574.4
802.365	29606.5
805.753	29607.7
809.14	29498.6
812.525	29379.3
815.907	29439.2
819.289	29454.3
822.671	29516.1
826.051	29520.3
829.43	29533
832.805	29495.9
836.182	29382.9
839.557	29401
842.928	29570.8
846.301	29672.1
849.67	29548
853.04	29563.1
856.407	29626
859.774	29712.1
863.138	29642.1
866.503	29551.8
869.865	29535.1
873.225	29672.5
876.586	29683.2
879.944	29633.3
883.301	29547.2
886.658	29574.8
890.012	29625.9
893.365	29541
896.717	29526.1
900.067	29431.9
903.416	29429.8
906.766	29370.6
910.112	29323.6
913.458	29329.9
916.802	29261.9
920.145	29209.7
923.484	29282.8
926.825	29145.3
930.164	29085.5
933.501	29030.5
936.838	29079
940.173	29078.8
943.505	29090.5
946.838	29079.8
950.17	29033.2
953.5	29088.1
956.827	29102.5
960.155	29104.4
963.48	29206.4
966.805	29160.3
970.128	29141.6
973.45	29068.7
976.77	29023.4
980.091	29124.5
983.408	29147.3
986.726	29174.7
990.041	29187.3
993.354	29246.5
996.668	29269.4
999.979	29473.9
1003.29	29588.2
1006.6	29532.4
1009.91	29339.4
1013.21	29283.4
1016.52	29355.8
1019.82	29221.7
1023.12	29149.8
1026.43	29039.5
1029.73	28990.7
1033.02	28961.6
1036.32	28946.5
1039.62	28889.2
1042.91	28908.2
1046.21	28904.1
1049.5	28819.5
1052.79	28863.7
1056.08	28850.9
1059.37	28927.8
1062.65	28962.4
1065.94	28977
1069.23	28874.8
1072.51	28908.1
1075.79	28840
1079.07	28952.6
1082.35	28975.3
1085.63	28896.1
1088.91	28875.2
1092.18	28805.4
1095.46	28658.7
1098.73	28650.8
1102	28602.9
1105.27	28480.7
1108.54	28531.8
1111.81	28544
1115.08	28597.5
1118.34	28657.9
1121.61	28652.3
1124.87	28604.4
1128.13	28548.5
1131.39	28455.2
1134.65	28466.3
1137.91	28241
1141.17	28278.1
1144.42	28423.1
1147.68	28519.9
1150.93	28766.2
1154.18	29015.9
1157.43	29104.1
1160.68	28780.7
1163.93	28418
1167.18	28194.4
1170.42	28060.3
1173.67	28031.6
1176.91	27994.4
1180.15	27884.8
1183.39	27896
1186.63	27909.6
1189.87	27874.1
1193.11	27967.7
1196.34	27881.4
1199.58	27754.8
1202.81	27748.5
1206.04	27753.2
1209.27	27762.7
1212.5	27733.9
1215.73	27659
1218.95	27691.7
1222.18	27589.4
1225.4	27646.1
1228.63	27643.7
1231.85	27614.6
1235.07	27629.6
1238.29	27621.5
1241.51	27652.8
1244.72	27679.7
1247.94	27708.5
1251.15	27657.7
1254.37	27660.7
1257.58	27667.2
1260.79	27711.3
1264	27630.5
1267.21	27641.1
1270.41	27492.2
1273.62	27440.8
1276.82	27369.3
1280.03	27355.6
1283.23	27331.8
1286.43	27299.7
1289.63	27241.7
1292.83	27320.6
1296.03	27497.4
1299.22	27596
1302.42	27619.3
1305.61	27647.8
1308.8	27505.9
1311.99	27372.6
1315.18	27216.4
1318.37	27098.4
1321.56	27024.3
1324.74	27015.5
1327.93	26998.9
1331.11	26950.7
1334.3	26886.5
1337.48	26955.8
1340.66	26953.7
1343.84	26826.3
1347.01	26820.8
1350.19	26838.6
1353.37	26746.5
1356.54	26663.2
1359.71	26542.6
1362.88	26501
1366.05	26513.3
1369.22	26502.6
1372.39	26377.4
1375.56	26215.6
1378.72	26231.6
1381.89	26126.4
1385.05	26082.5
1388.21	26088
1391.37	26063.7
1394.53	25988
1397.69	25920.5
1400.85	25909.9
1404	25842.7
1407.16	25893.8
1410.31	25849.8
1413.46	25856.1
1416.61	26026
1419.76	25966.3
1422.91	25897.1
1426.06	25999.8
1429.21	26136.2
1432.35	26397
1435.49	26727.8
1438.64	26962.2
1441.78	26936.2
1444.92	26835.3
1448.06	26740
1451.2	26637.9
1454.33	26534.9
1457.47	26382.6
1460.6	26322.9
1463.74	26144.6
1466.87	25931.7
1470	25728.5
1473.13	25525.7
1476.26	25405.4
1479.38	25177.3
1482.51	25112.2
1485.63	25132.1
1488.76	25042.5
1491.88	25010.6
1495	25161.7
1498.12	25174.1
1501.24	25059.9
1504.36	25124
1507.47	25134.3
1510.59	25270.8
1513.7	25347.5
1516.81	25546.8
1519.93	25703.6
1523.04	25702.8
1526.15	25511.5
1529.25	25197.6
1532.36	24951
1535.47	24638.9
1538.57	24531.2
1541.67	24480.2
1544.78	24408.2
1547.88	24329
1550.98	24259.4
1554.08	24256.3
1557.18	24307.8
1560.27	24126.3
1563.37	24214.6
1566.46	24169.7
1569.55	24173.7
1572.64	24189.7
1575.74	24103.9
1578.83	24085.4
1581.91	24064.4
1585	24030.9
1588.09	24001.8
1591.17	23998.6
1594.25	23990.9
1597.34	23943.9
1600.42	23990.5
1603.5	23983.2
1606.58	23871.1
1609.65	23841.7
1612.73	23758
1615.8	23754.3
1618.88	23679
1621.95	23632.2
1625.03	23585.1
1628.1	23582.3
1631.17	23599.1
1634.23	23560.8
1637.3	23564.9
1640.37	23584.8
1643.43	23521.3
1646.5	23655.8
1649.56	23807.1
1652.62	23930.2
1655.68	23886.7
1658.74	23751.6
1661.8	23555.9
1664.85	23445.1
1667.91	23368
1670.96	23274.3
1674.02	23256.2
1677.07	23072
1680.12	23004.6
1683.17	22876.8
1686.22	22795.7
1689.27	22707.2
1692.31	22627.2
1695.36	22568.7
1698.4	22559.7
1701.45	22385.6
1704.49	22348.1
1707.53	22330
1710.57	22233.3
1713.61	22141.8
1716.65	22187.6
1719.68	22115.9
1722.72	22085.7
1725.75	22054.2
1728.78	21991.1
1731.82	22030.8
1734.84	22057.1
1737.87	21969.2
1740.9	22053.5
1743.93	21993.4
1746.96	21954
1749.98	21958.5
1753	21856.2
1756.03	21706.9
1759.05	21649.5
1762.07	21550.1
1765.09	21480
1768.11	21503.5
1771.12	21471.2
1774.14	21433.5
1777.15	21406.3
1780.17	21409
1783.18	21327.2
1786.19	21351.3
1789.2	21300.2
1792.21	21258.5
1795.22	21280.8
1798.22	21183.6
1801.23	21147.5
1804.23	21111.1
1807.24	21008.8
1810.24	21070.7
1813.24	21052.8
1816.24	21015.1
1819.24	20928.3
1822.24	20847.4
1825.23	20852.8
1828.23	20835.9
1831.22	20802.2
1834.22	20778.6
1837.21	20746.9
1840.2	20751.1
1843.19	20735.2
1846.18	20673.6
1849.17	20620.2
1852.15	20587.2
1855.14	20538.9
1858.12	20458
1861.11	20502.2
1864.09	20456.4
1867.07	20379.5
1870.05	20332.9
1873.03	20331
1876.01	20315.5
1878.98	20258.1
1881.96	20208.2
1884.93	20126.1
1887.91	20062.2
1890.88	20053.9
1893.85	20054.8
1896.82	19914.3
1899.79	19877.3
1902.76	19760.2
1905.72	19549.6
1908.69	19435.3
1911.65	19280.5
1914.62	19119.3
1917.58	18979.3
1920.54	18858.6
1923.5	18682.1
1926.46	18602.4
1929.42	18466.6
1932.37	18352.5
1935.33	18236.2
1938.28	18069.9
1941.24	17948
1944.19	17803
1947.14	17705.7
1950.09	17565.5
1953.04	17380.7
1955.99	17229.3
1958.93	17057.9
1961.88	17007.2
1964.82	16860.1
1967.77	16749.6
1970.71	16600.7
1973.65	16512.2
1976.59	16404
1979.53	16273.7
1982.47	16196.4
1985.41	16055.6
1988.34	15964.3
1991.28	15804.3
1994.21	15699.2
1997.14	15553.2
2000.07	15469
2003.01	15370.9
2005.94	15249.3
2008.86	15200
2011.79	15097.8
2014.72	15011.3
2017.64	14887.9
2020.57	14783.9
2023.49	14680.7
2026.41	14588.6
2029.33	14511.4
2032.25	14403.4
2035.17	14314.3
2038.09	14265.3
2041	14170.7
2043.92	14091.4
2045.86	14043.6
2048.79	14019.5
2051.71	13962
2054.64	13995.6
2057.56	13969.7
2060.48	13961
2063.4	13925.9
2066.32	13903.6
2069.24	13905
2072.16	13881.3
2075.08	13850.3
2077.99	13828.1
2080.91	13789.4
2083.82	13815.6
2086.74	13759.6
2089.65	13722.3
2092.56	13734.9
2095.47	13647.7
2098.38	13679.5
2101.29	13633.1
2104.19	13627.3
2107.1	13564.9
2110	13564.5
2112.91	13479.9
2115.81	13500.5
2118.71	13468
2121.61	13444.1
2124.51	13415.2
2127.4	13380.5
2130.3	13383.6
2133.2	13410.9
2136.09	13320.3
2138.99	13374.1
2141.88	13323
2144.77	13294.8
2147.66	13274.2
2150.55	13294.1
2153.44	13270.1
2156.33	13230.1
2159.21	13236.5
2162.1	13194.9
2164.98	13188
2167.87	13183.1
2170.75	13204.8
2173.63	13176.8
2176.51	13153.7
2179.39	13075.1
2182.27	13093.8
2185.14	13055.1
2188.02	13010.8
2190.9	13026.2
2193.77	12972.3
2196.64	13002.6
2199.51	12983.1
2202.39	12948.3
2205.25	12937
2208.12	12939.5
2210.99	12897.2
2213.86	12832.9
2216.72	12769.2
2219.59	12778
2222.45	12699
2225.31	12706.7
2228.17	12661.5
2231.03	12644.7
2233.89	12626.5
2236.75	12593
2239.61	12581
2242.46	12532.7
2245.32	12553.1
2248.17	12486.8
2251.03	12474.2
2253.88	12455.8
2256.73	12371.5
2259.58	12369.2
2262.43	12307.4
2265.28	12260.1
2268.12	12243.6
2270.97	12253.1
2273.81	12167.2
2276.66	12163.7
2279.5	12168.8
2282.34	12106.9
2285.18	12052.1
2288.02	12037.5
2290.86	12055.2
2293.7	11994.3
2296.54	11975
2299.37	11936.7
2302.21	11893
2305.04	11849.3
2307.87	11773.8
2310.7	11808.6
2313.53	11800.6
2316.36	11724.6
2319.19	11722.7
2322.02	11635.7
2324.85	11706
2327.67	11820.8
2330.5	11885.6
2333.32	11631.1
2336.14	11533.4
2338.96	11539.4
2341.78	11509.2
2344.6	11469.8
2347.42	11428.7
2350.24	11390.2
2353.05	11373
2355.87	11323.4
2358.68	11318.9
2361.5	11274.5
2364.31	11254.3
2367.12	11257.7
2369.93	11228.2
2372.74	11174.1
2375.55	11148.3
2378.35	11105.4
2381.16	11119.1
2383.96	11081.3
2386.77	11013.5
2389.57	11065.1
2392.37	11051.8
2395.17	11005.3
2397.97	10956.8
2400.77	10966.2
2403.57	10916.9
2406.37	10892.4
2409.16	10849.8
2411.96	10805.2
2414.75	10833.3
2417.55	10809.2
2420.34	10790.4
2423.13	10760.4
2425.92	10717.7
2428.71	10738
2431.5	10704.4
2434.28	10668
2437.07	10622.1
2439.85	10630.7
2442.64	10613
2445.42	10579.6
2448.2	10593.6
2450.98	10575.4
2453.76	10528
2456.54	10505.1
2459.32	10544.8
2462.1	10498.2
2464.87	10428.8
2467.65	10427.8
2470.42	10405.8
2473.2	10353.5
2475.97	10344.7
2478.74	10353.6
2481.51	10328.9
2484.28	10273.9
2487.05	10254.5
2489.81	10255.9
2492.58	10230.2
2495.34	10193.1
2498.11	10165.1
2500.87	10180.4
2503.63	10148.8
2506.39	10109.1
2509.15	10087
2511.91	10099.7
2514.67	10045.4
2517.43	10054.3
2520.19	10029.4
2522.94	9974.91
2525.7	10010.4
2528.45	9972.94
2531.2	9952.1
2533.95	9925.12
2536.7	9926.72
2539.45	9899.96
2542.2	9866.98
2544.95	9851.29
2547.69	9783
2550.44	9728.45
2553.18	9748.04
2555.93	9681.35
2558.67	9751.4
2561.41	9675.28
2564.15	9683.2
2566.89	9637.36
2569.63	9625.51
2572.36	9622.79
2575.1	9623.52
2577.84	9567.07
2580.57	9564.49
2583.31	9553.11
2586.04	9543.46
2588.77	9563.45
2591.5	9505.44
2594.23	9536.44
2596.96	9482.74
2599.69	9443.44
2602.41	9447.6
2605.14	9421.33
2607.86	9470.67
2610.59	9413.87
2613.31	9395.24
2616.03	9379.69
2618.75	9348.38
2621.48	9329.21
2624.19	9317.81
2626.91	9329.07
2629.63	9295.1
2632.35	9264.18
2635.06	9196.94
2637.77	9227.6
2640.49	9186.97
2643.2	9140.4
2645.91	9175.08
2648.62	9131.44
2651.33	9179.3
2654.04	9127.23
2656.75	9109.29
2659.45	9101.01
2662.16	9090
2664.86	9041.03
2667.57	9067.75
2670.27	9021.96
2672.97	9036.46
2675.67	9023.01
2678.37	8956.29
2681.07	8966.84
2683.77	8919.98
2686.47	8908.43
2689.16	8931.57
2691.86	8896.55
2694.55	8887.76
2697.25	8845
2699.94	8864.47
2702.63	8828.02
2705.32	8837.03
2708.01	8828.54
2710.7	8837.08
2713.39	8797.49
2716.07	8775.95
2718.76	8760.32
2721.44	8758.66
2724.12	8722.52
2726.81	8737.54
2729.49	8677.31
2732.17	8729.18
2734.85	8663.71
2737.53	8638.19
2740.21	8565.66
2742.88	8581.92
2745.56	8555
2748.24	8530.74
2750.91	8499.64
2753.58	8478.97
2756.25	8464.97
2758.93	8441.6
2761.6	8409.72
2764.27	8416.76
2766.93	8371.41
2769.6	8365.89
2772.27	8319.04
2774.93	8288.44
2777.6	8294.86
2780.26	8267.39
2782.93	8251.93
2785.59	8189.44
2788.25	8182.76
2790.91	8166.51
2793.57	8163.8
2796.23	8194.09
2798.88	8183.73
2801.54	8151.64
2804.2	8103.83
2806.85	8084.79
2809.5	8074.37
2812.16	8047.41
2814.81	8077.81
2817.46	8052.26
2820.11	8057.03
2822.76	8039.42
2825.4	8054.37
2828.05	8019.5
2830.7	8024.74
2833.34	8041.95
2835.99	8115.75
2838.63	8155.56
2841.27	8223.42
2843.91	8365.01
2846.55	8557.09
2849.19	8774.01
2851.83	8890.97
2854.47	8934.31
2857.11	8835.41
2859.74	8758.71
2862.38	8694.82
2865.01	8632.17
2867.65	8615.04
2870.28	8633.88
2872.91	8677.07
2875.54	8678.3
2878.17	8693.44
2880.8	8727.18
2883.42	8730.96
2886.05	8764.84
2888.68	8778.05
2891.3	8806.33
2893.93	8800.73
2896.55	8772.85
2899.17	8773.69
2901.79	8737.21
2904.41	8722.48
2907.03	8660.53
2909.65	8661.76
2912.27	8629.68
2914.88	8643.81
2917.5	8608.02
2920.11	8596.78
2922.73	8595.2
2925.34	8566.2
2927.95	8553.52
2930.56	8542.58
2933.17	8518.22
2935.78	8486.51
2938.39	8464.02
2941	8342.63
2943.6	8213.15
2946.21	8129.83
2948.81	7988.74
2951.42	7910.46
2954.02	7860.4
2956.62	7816.38
2959.22	7798.46
2961.82	7802.34
2964.42	7725.94
2967.02	7694.81
2969.62	7658.54
2972.21	7581.16
2974.81	7561.15
2977.4	7522.53
2980	7501.39
2982.59	7506.59
2985.18	7458.22
2987.77	7370.4
2990.36	7344.77
2992.95	7322.33
2995.54	7330.02
2998.13	7296.15
3000.72	7287.69
3003.3	7287.56
3005.89	7289
3008.47	7266.26
3011.05	7234.33
3013.63	7227.62
3016.22	7185.51
3018.8	7164.48
3021.38	7214.04
3023.95	7193.33
3026.53	7201.17
3029.11	7160.72
3031.68	7132.36
3034.26	7146.31
3036.83	7137.62
3039.4	7122.33
3041.98	7123.19
3044.55	7153.47
3047.12	7143.4
3049.69	7142.87
3052.26	7153.13
3054.82	7180.84
3057.39	7148.84
3059.96	7192.58
3062.52	7174.56
3065.09	7191.31
3067.65	7203.39
3070.21	7198.29
3072.77	7178
3075.33	7205.06
3077.89	7189.36
3080.45	7203.14
3083.01	7204.51
3085.57	7225.73
3088.12	7203.3
3090.68	7251.83
3093.23	7240.23
3095.79	7234.73
3098.34	7255.48
3100.89	7256.66
3103.44	7271.22
3105.99	7303.64
3108.54	7338.53
3111.09	7335.1
3113.63	7330.32
3116.18	7380.19
3118.73	7371.63
3121.27	7370.73
3123.82	7406.15
3126.36	7450.56
3128.9	7456.3
3131.44	7499.57
3133.98	7563.36
3136.52	7546.98
3139.06	7553.53
3141.6	7544.74
3144.13	7592.5
3146.67	7596.96
3149.2	7658.13
3151.74	7665.83
3154.27	7644.33
3156.8	7699.7
3159.34	7711.52
3161.86	7733.18
3164.4	7713.83
3166.92	7759.96
3169.45	7803.42
3171.98	7799.48
3174.5	7801.62
3177.03	7847.17
3179.56	7837
3182.08	7867.65
3184.6	7884.47
3187.12	7912.79
3189.64	7947.06
3192.16	7971.34
3194.68	7971.34
3197.2	7977.16
3199.72	7976.1
3202.24	8009.63
3204.75	8034.47
3207.27	8046.27
3209.78	8053.84
3212.29	8060.98
3214.81	8054.1
3217.32	8024.74
3219.83	8072.88
3222.34	8085.3
3224.85	8093.65
3227.35	8095.96
3229.86	8099.13
3232.37	8106.99
3234.87	8105.92
3237.38	8101.93
3239.88	8104.07
3242.38	8087.42
3244.89	8091.22
3247.39	8100.63
3249.89	8086.71
3252.39	8085.4
3254.88	8070.59
3257.38	8046.85
3259.88	8046.72
3262.37	8029.73
3264.87	8026.14
3267.36	8035.73
3269.86	8026.87
3272.35	8040.68
3274.84	8030.42
3277.33	7998.34
3279.82	7995.81
3282.31	7985.22
3284.8	7975.36
3287.29	7981.78
3289.77	7952.66
3292.26	7976.01
3294.15	7934.42
3296.64	7928.33
3299.14	7941.17
3301.63	7937.53
3304.12	7912.4
3306.62	7901.41
3309.11	7870.06
3311.6	7882.66
3314.09	7877.51
3316.58	7869.33
3319.07	7837.94
3321.56	7858.95
3324.04	7867.89
3326.53	7864.6
3329.01	7883.19
3331.5	7873.87
3333.98	7826.57
3336.46	7853.49
3338.94	7805.94
3341.42	7798.62
3343.9	7781.96
3346.38	7798.65
3348.86	7777.6
3351.34	7769.65
3353.82	7766.21
3356.29	7780.81
3358.77	7773.5
3361.24	7775.36
3363.71	7743.64
3366.19	7758.81
3368.66	7736.81
3371.13	7745.39
3373.6	7738.33
3376.07	7770
3378.54	7722.14
3381	7724.82
3383.47	7721.93
3385.94	7708.29
3388.4	7692.23
3390.87	7710.15
3393.33	7675.04
3395.79	7695.73
3398.25	7718.46
3400.71	7710.39
3403.17	7667.13
3405.63	7641.03
3408.09	7655.62
3410.55	7670.03
3413	7652.27
3415.46	7633.25
3417.92	7614.71
3420.37	7595.73
3422.82	7613.37
3425.27	7575.37
3427.73	7569.7
3430.18	7599.99
3432.63	7583.8
3435.08	7540.67
3437.53	7561.45
3439.97	7511.32
3442.42	7490.44
3444.86	7480.43
3447.31	7475.34
3449.75	7448.03
3452.2	7436.43
3454.64	7460.92
3457.08	7389.69
3459.52	7385.1
3461.96	7389.93
3464.4	7357.14
3466.84	7334.99
3469.28	7335.33
3471.72	7302.64
3474.15	7262.16
3476.59	7259.35
3479.02	7239.32
3481.45	7203.89
3483.89	7166.13
3486.32	7169.56
3488.75	7108.98
3491.18	7134.46
3493.61	7083.63
3496.04	7109.48
3498.47	7021.78
3499.68	7029.72