File: src/Milk_AI/Amul full cream Cold 532nm 50% 600g 50xL 10s 10times 400-3500cm-1 200hole.txt
#Acq. time (s)=	10
#Accumulations=	10
#Range (cm-¹)=	400...3500
#Windows=	3
#Auto scanning=	Off
#Autofocus=	Off
#AutoExposure=	Off
#Spike filter=	Multiple accum.
#Delay time (s)=	0
#Binning=	1
#Readout mode=	Signal
#DeNoise=	Off
#ICS correction=	On
#Dark correction=	Off
#Inst. Process=	Off
#Detector Gain=	Best Dynamic Range
#Detector ADC=	45 kHz
#Detector temperature (°C)=	-60.1
#Instrument=	LabRAM HR Evol
#Detector=	Syncerity OE
#Objective=	x50_VIS_LWD
#Grating=	600 (500nm)
#ND Filter=	50%
#Laser=	532nm_Edge
#Hole=	199.981
#Range=	Visible
#E-Cal_Neon=	0
#StageXY=	75x50mm Scan+
#StageZ=	Z motor
#X (µm)=	0
#Y (µm)=	0
#Z (µm)=	251
#Spectral res.(cm-¹)=	12.8
#Full time(mm:ss)=	5:19
#AC=	Calibrated 2025-07-01 10:31
#Project=
#Sample=
#Site=
#Title=	D_1
#Remark=
#Date=	01.07.2025 11:43 (India Standard Time)
#Acquired=	01.07.2025 11:43:55 (India Standard Time)
#AxisType[0]=Intens
#AxisUnit[0]=Cnt
#AxisType[1]=Spectr
#AxisUnit[1]=1/cm
400.083	29323
403.63	29128.7
407.176	29063.2
410.72	29065.9
414.263	28978.9
417.805	29140.6
421.345	29098
424.884	28980.8
428.421	29014.9
431.955	28990.9
435.49	28928.7
439.023	28902.6
442.555	28952.2
446.084	28813
449.613	28866
453.141	28790.5
456.666	28751.1
460.191	28678.1
463.715	28632
467.235	28518.1
470.756	28509
474.274	28456.9
477.793	28327
481.308	28335.1
484.823	28338.1
488.336	28349.6
491.847	28280.9
495.358	28321.1
498.867	28350.1
502.374	28411.7
505.881	28428.8
509.386	28408.2
512.888	28444
516.39	28355.9
519.89	28260.6
523.391	28097
526.889	28220.4
530.385	28090.8
533.88	27931.4
537.373	27907.9
540.866	27769.1
544.357	27772.1
547.846	27643.6
551.334	27662.7
554.821	27673.8
558.307	27550.2
561.789	27500.2
565.272	27546.9
568.753	27634.9
572.233	27656.3
575.712	27656.7
579.188	27759.2
582.664	27710.8
586.139	27829.1
589.611	27823.6
593.083	27924.3
596.554	27959.3
600.021	27988
603.49	28087.8
606.955	28111.9
610.42	27856.5
613.882	27611.5
617.345	27614.1
620.805	27485.9
624.263	27410.7
627.722	27298.5
631.178	27310.3
634.633	27273.6
638.088	27330.3
641.539	27359
644.99	27212.2
648.439	27115.5
651.887	27060.5
655.335	26973.4
658.781	27025.2
662.225	26882.5
665.667	26848.9
669.108	26886.4
672.548	26820.7
675.987	26712.1
679.424	26792.5
682.86	26794.3
686.293	26700.8
689.727	26773.9
693.159	26843.3
696.59	26947.1
700.019	26934.4
703.448	26918.3
706.872	26900.9
710.298	26881.7
713.723	27047.9
717.144	26984.7
720.565	27146.2
723.984	27122.9
727.403	27102.3
730.821	27012.5
734.235	26997.8
737.651	26979.1
741.063	26872
744.474	26838.6
747.885	26840.9
751.293	26918
754.702	27086
758.108	27068.5
761.512	26987
764.915	26988.5
768.319	27096.6
771.719	27071.5
775.118	27077.9
778.516	27020.4
781.913	26988.2
785.308	27097.3
788.702	27073.1
792.095	27026.3
795.486	27063.9
798.876	27259.4
802.265	27376.7
805.653	27438.4
809.039	27448
812.424	27530.3
815.808	27712.6
819.191	27824.6
822.572	28083.3
825.95	28327.4
829.329	28527
832.706	28710.3
836.08	28954.7
839.455	29074.2
842.829	29167.5
846.199	29368.1
849.57	29360.3
852.938	29441.6
856.307	29401.1
859.672	29666.9
863.038	29859.6
866.401	29986.9
869.765	30086.7
873.125	30094.9
876.484	29989.7
879.844	29657.7
883.2	29603.5
886.555	29764
889.909	29724.4
893.262	29333.7
896.616	28900.7
899.966	28532.9
903.315	28311.4
906.663	28113.2
910.009	28050.5
913.354	28081.2
916.698	28181.4
920.041	28168
923.383	28052.3
926.723	27704.5
930.062	27617.2
933.399	27489.2
936.734	27327.9
940.069	27398.4
943.403	27375.9
946.736	27509.5
950.065	27511.7
953.396	27464.6
956.725	27429.7
960.051	27614.6
963.377	27518.6
966.7	27457.4
970.025	27386.2
973.345	27210.3
976.667	27067.7
979.985	27033.4
983.304	27025
986.62	27187.6
989.935	27353.2
993.25	27620.6
996.563	28108.6
999.874	28974
1003.19	29536.6
1006.49	29094.9
1009.8	28564.8
1013.11	28161.3
1016.41	28049.6
1019.72	28015.5
1023.02	27861.4
1026.32	27790.7
1029.62	27825
1032.92	27768.8
1036.22	27722.4
1039.51	27762.2
1042.81	27708.4
1046.1	27689.3
1049.39	27930.4
1052.68	28167.7
1055.97	28860.7
1059.26	29786.6
1062.55	30422.7
1065.83	29811.3
1069.12	29407.4
1072.4	29572.8
1075.68	29935.5
1078.97	30207.8
1082.24	30112.5
1085.52	29633.7
1088.8	29366.9
1092.08	28771.9
1095.35	28293.4
1098.62	27768.1
1101.9	27390.4
1105.17	27203.6
1108.44	27101
1111.7	27361.7
1114.97	27747.9
1118.23	28133.7
1121.5	28462.7
1124.76	28678.9
1128.03	28268.5
1131.29	27370.8
1134.54	26658.3
1137.8	26674.6
1141.06	26928.5
1144.31	27488.1
1147.57	28576.6
1150.82	30079.9
1154.07	31855.4
1157.32	31834.3
1160.57	29577.7
1163.82	27505.5
1167.07	26536
1170.31	26358.3
1173.56	26149.4
1176.8	25835.3
1180.04	25790.1
1183.28	25845.9
1186.52	25918.8
1189.76	26069.7
1192.99	25879.2
1196.23	25662.7
1199.46	25444.8
1202.7	25281.6
1205.93	25142.2
1209.16	25144.3
1212.39	25080.9
1215.62	24871.3
1218.84	24785.2
1222.07	24657.4
1225.29	24783
1228.52	24798
1231.74	24867.7
1234.96	25068.8
1238.18	25191.2
1241.4	25442.6
1244.61	25720.7
1247.83	25960.4
1251.04	26090.7
1254.25	26353.2
1257.47	26617.8
1260.68	26695.7
1263.89	26935.6
1267.09	27017.3
1270.3	26903.6
1273.51	26630.4
1276.71	26576.4
1279.91	26586
1283.12	26757.4
1286.32	27046.9
1289.52	27882.2
1292.72	29472.5
1295.91	31033.5
1299.11	31343.6
1302.3	31091.7
1305.5	30236.4
1308.69	29116.4
1311.88	28128.1
1315.07	27115.6
1318.26	26394.4
1321.44	25831.7
1324.63	25299.9
1327.82	24999.8
1331	24652.1
1334.18	24443.6
1337.36	24346.5
1340.54	24264.9
1343.72	24195.6
1346.9	23978.8
1350.07	24050.2
1353.25	23928.4
1356.42	23734.1
1359.6	23592.9
1362.77	23743.2
1365.94	23757
1369.11	23745.9
1372.28	23418.5
1375.44	23080.3
1378.61	22918.1
1381.77	22786.8
1384.93	22647.8
1388.1	22766.3
1391.26	22713
1394.41	22753.6
1397.57	22683.9
1400.73	22819.3
1403.89	22900.3
1407.04	23031
1410.19	23440.4
1413.35	23959.3
1416.5	24365.1
1419.65	24954.9
1422.8	25374.1
1425.94	26367
1429.09	28509.7
1432.23	31612.3
1435.38	34317.5
1438.52	35422.5
1441.66	34727.5
1444.8	33477.1
1447.94	32728
1451.08	32100.5
1454.22	31457.8
1457.35	30808.4
1460.48	29694.8
1463.62	28357.5
1466.75	27007.5
1469.88	25676.6
1473.01	24639.9
1476.14	23697.7
1479.26	23112.7
1482.39	22715.8
1485.51	22528.1
1488.64	22346.8
1491.76	22287.8
1494.88	22383.2
1498	22503.6
1501.12	22634.5
1504.24	23179.4
1507.35	23750.5
1510.47	24677.1
1513.58	25828.5
1516.69	26972.6
1519.81	27607.5
1522.92	27451.2
1526.03	26533.3
1529.13	25006.8
1532.24	23362.4
1535.35	22212.6
1538.45	21571.7
1541.55	21211.5
1544.66	20990.3
1547.76	20825.7
1550.86	20681.7
1553.96	20575.9
1557.05	20476.9
1560.15	20440
1563.24	20477.5
1566.34	20409.8
1569.43	20376
1572.52	20396.5
1575.61	20321.2
1578.7	20333.7
1581.79	20332.7
1584.88	20339.8
1587.96	20345.4
1591.05	20375.5
1594.13	20281.9
1597.21	20390.3
1600.3	20361.8
1603.37	20443.5
1606.45	20348.4
1609.53	20384.8
1612.61	20306.8
1615.68	20240.3
1618.76	20153.5
1621.83	20204.9
1624.9	20241.3
1627.97	20404.5
1631.04	20522.7
1634.11	20719.4
1637.18	20857.2
1640.24	21277.8
1643.31	21855.7
1646.37	23110.1
1649.44	24926.4
1652.5	26017.7
1655.56	25254.6
1658.62	23592.2
1661.67	22264.8
1664.73	21595.1
1667.79	21274.5
1670.84	20828.9
1673.89	20276.5
1676.95	19894.5
1680	19598
1683.05	19421.4
1686.1	19218.8
1689.14	19152.1
1692.19	19028.2
1695.23	18904.3
1698.28	18823.1
1701.32	18690.2
1704.36	18635.1
1707.4	18568.4
1710.44	18540.7
1713.48	18490.9
1716.52	18466.4
1719.56	18512.9
1722.59	18614.7
1725.63	18861.8
1728.66	19048.6
1731.69	19249
1734.72	19709.3
1737.75	20298
1740.78	20603.3
1743.8	20559.3
1746.83	20463.2
1749.86	20140
1752.88	19662.9
1755.9	19114.3
1758.92	18610.4
1761.94	18324.4
1764.96	18021.8
1767.98	17922.7
1771	17798.3
1774.01	17691.2
1777.03	17660.4
1780.04	17695.6
1783.05	17625.6
1786.06	17601.3
1789.07	17598.9
1792.08	17538.3
1795.09	17520.2
1798.1	17510.2
1801.1	17407
1804.11	17369.8
1807.11	17346.8
1810.11	17290.5
1813.11	17325.6
1816.11	17308.1
1819.11	17246.1
1822.11	17249.2
1825.11	17213.2
1828.1	17259.9
1831.1	17170.7
1834.09	17208.2
1837.08	17054.5
1840.07	17099.5
1843.06	17123.2
1846.05	17057.8
1849.04	17031.1
1852.02	16939.6
1855.01	16974
1857.99	16903.2
1860.98	16911.8
1863.96	16910.4
1866.94	16872
1869.92	16868.9
1872.9	16852.2
1875.88	16772.8
1878.85	16809.5
1881.83	16820.7
1884.8	16710
1887.78	16707.7
1890.75	16672.9
1893.72	16609.1
1896.69	16598.9
1899.66	16510.8
1902.63	16457.9
1905.59	16366.5
1908.56	16292.8
1911.52	16194.9
1914.49	16146.6
1917.45	16051.9
1920.41	16026
1923.37	15922.5
1926.33	15904.4
1929.29	15749.2
1932.24	15726.8
1935.2	15679
1938.15	15534.2
1941.1	15412.5
1944.06	15407.7
1947.01	15325.1
1949.96	15267.1
1952.91	15193
1955.86	15059.3
1958.8	14990.6
1961.75	14956.4
1964.69	14892.6
1967.64	14818.8
1970.58	14727
1973.52	14658.9
1976.46	14641.7
1979.4	14579.1
1982.34	14516.2
1985.27	14441
1988.21	14350.9
1991.14	14293.3
1994.08	14218.4
1997.01	14125.8
1999.94	14033.5
2002.87	14026
2005.8	13982.7
2008.73	13909.5
2011.66	13849.9
2014.58	13812.7
2017.51	13712.4
2020.43	13663.2
2023.36	13585.5
2026.28	13541.3
2029.2	13500.6
2032.12	13463.4
2035.04	13397
2037.95	13353.5
2040.87	13322.7
2043.78	13247.6
2045.76	13223.7
2048.69	13225
2051.61	13176.8
2054.54	13130.2
2057.46	13086.6
2060.38	13133.6
2063.3	13097.1
2066.22	13056.9
2069.14	13004.6
2072.06	13003.1
2074.98	13023.9
2077.89	12969.9
2080.81	12950.5
2083.72	12922.4
2086.63	12924
2089.55	12856.7
2092.46	12837.6
2095.37	12850.9
2098.28	12800.8
2101.18	12755.7
2104.09	12723.5
2106.99	12683.5
2109.9	12669.4
2112.8	12709.9
2115.71	12690.3
2118.61	12654
2121.51	12569.5
2124.4	12586
2127.3	12607.7
2130.2	12525.8
2133.09	12523.9
2135.99	12565.8
2138.88	12488.1
2141.78	12508.4
2144.67	12466.5
2147.56	12437.8
2150.45	12472.4
2153.34	12393.4
2156.22	12402.3
2159.11	12417.7
2162	12357.8
2164.88	12367.2
2167.76	12334.8
2170.64	12328.5
2173.53	12310.4
2176.41	12265.3
2179.29	12256.8
2182.16	12263.6
2185.04	12248.4
2187.92	12147
2190.79	12139.9
2193.66	12112.9
2196.54	12099.4
2199.41	12116.3
2202.28	12076.5
2205.15	12080.9
2208.02	12051.7
2210.88	11980.8
2213.75	11939.6
2216.62	11853.3
2219.48	11853.5
2222.34	11863.3
2225.21	11826.9
2228.07	11808
2230.93	11785.2
2233.79	11716.7
2236.65	11733.1
2239.5	11713.2
2242.36	11661.5
2245.21	11619.9
2248.07	11577.5
2250.92	11559.1
2253.77	11514.4
2256.62	11500
2259.47	11439.5
2262.32	11379.2
2265.17	11374.6
2268.02	11312.5
2270.86	11282.6
2273.71	11266.5
2276.55	11213.4
2279.39	11221.8
2282.24	11218
2285.08	11161.7
2287.92	11142.1
2290.75	11098
2293.59	11076.7
2296.43	11063.5
2299.26	11046.5
2302.1	11001.4
2304.93	10943.2
2307.76	10928.4
2310.6	10929.2
2313.43	10890.6
2316.25	10855.1
2319.08	10773.6
2321.91	10838.2
2324.74	10824.2
2327.56	10939.5
2330.39	10962.2
2333.21	10653.5
2336.03	10620.7
2338.85	10590.8
2341.67	10634.5
2344.49	10530.8
2347.31	10518.7
2350.13	10513.5
2352.94	10430.6
2355.76	10432.3
2358.57	10388.5
2361.39	10297.9
2364.2	10337.6
2367.01	10350.6
2369.82	10260.1
2372.63	10261
2375.44	10222
2378.24	10185.1
2381.05	10180
2383.85	10167.5
2386.66	10164.3
2389.46	10142
2392.26	10122
2395.06	10099.1
2397.86	10055.3
2400.66	10080.7
2403.46	9996.58
2406.26	9963.55
2409.05	9943.73
2411.85	9944.89
2414.64	9937.1
2417.43	9899.35
2420.23	9899.78
2423.02	9878.83
2425.81	9839.93
2428.6	9816.11
2431.38	9810.37
2434.17	9812.88
2436.96	9743.58
2439.74	9711.92
2442.53	9741.23
2445.31	9656.64
2448.09	9661.2
2450.87	9669.9
2453.65	9667.94
2456.43	9621.22
2459.21	9623.2
2461.98	9569.31
2464.76	9572.99
2467.53	9517.26
2470.31	9487.35
2473.08	9489.3
2475.85	9474.48
2478.63	9430.24
2481.39	9411.5
2484.16	9418.28
2486.93	9416.52
2489.7	9371.03
2492.46	9345.95
2495.23	9351.99
2497.99	9360.94
2500.76	9310.06
2503.52	9227.78
2506.28	9254.65
2509.04	9225.09
2511.8	9216.13
2514.56	9196.32
2517.31	9152.76
2520.07	9181.71
2522.82	9111.67
2525.58	9139.68
2528.33	9160.69
2531.09	9076.18
2533.84	9057.44
2536.59	9014.82
2539.34	9021.6
2542.08	8991.84
2544.83	9012.97
2547.58	8974.01
2550.32	8923.02
2553.07	8919
2555.81	8912.08
2558.55	8916.46
2561.29	8831.43
2564.03	8842.79
2566.77	8835.43
2569.51	8802.42
2572.25	8838.34
2574.99	8858.32
2577.72	8787.97
2580.46	8825.15
2583.19	8800.65
2585.92	8768.08
2588.65	8814.06
2591.38	8800.96
2594.11	8780.79
2596.84	8789.61
2599.57	8773.97
2602.3	8724.31
2605.02	8697.11
2607.75	8701.59
2610.47	8689.11
2613.19	8663.23
2615.92	8659.22
2618.64	8632.97
2621.36	8651.16
2624.08	8643.9
2626.8	8580.08
2629.51	8605.99
2632.23	8604.63
2634.94	8640.08
2637.66	8524.18
2640.37	8540.11
2643.08	8587.18
2645.79	8570.43
2648.5	8613.77
2651.21	8613.56
2653.92	8582.21
2656.63	8572.09
2659.33	8529.94
2662.04	8597.86
2664.75	8553.13
2667.45	8624.07
2670.15	8553.79
2672.85	8559.55
2675.55	8575.45
2678.25	8522.41
2680.95	8518.29
2683.65	8514.48
2686.35	8501.7
2689.04	8480.63
2691.74	8459.95
2694.43	8447.83
2697.13	8442.87
2699.82	8463.17
2702.51	8559.16
2705.2	8558.28
2707.89	8615.02
2710.58	8614.67
2713.26	8648.42
2715.95	8696.63
2718.64	8693.74
2721.32	8670.22
2724	8690.38
2726.69	8714.62
2729.37	8693.89
2732.05	8622.63
2734.73	8569.11
2737.41	8444.57
2740.09	8354.88
2742.76	8278.12
2745.44	8207.7
2748.11	8154.74
2750.79	8101.05
2753.46	8055.54
2756.13	8051.21
2758.81	7982.48
2761.47	7958.76
2764.14	7935.74
2766.81	7921.47
2769.48	7898.61
2772.15	7936.68
2774.81	7862.94
2777.48	7866.1
2780.14	7866.12
2782.8	7843.73
2785.47	7809.29
2788.13	7803.46
2790.79	7790.07
2793.44	7833.47
2796.1	7835.06
2798.76	7864.05
2801.42	7854.4
2804.07	7823.49
2806.73	7841.59
2809.38	7889.48
2812.03	7888.51
2814.68	7990.08
2817.33	8047.27
2819.98	8122.09
2822.63	8173.59
2825.28	8326.34
2827.93	8495.56
2830.57	8753.08
2833.22	9107.88
2835.86	9677.72
2838.51	10572.6
2841.15	12020.3
2843.79	13990.1
2846.43	16100.8
2849.07	17611
2851.71	17892.7
2854.35	17433
2856.98	16761.9
2859.62	16209.2
2862.25	15777.2
2864.89	15426.1
2867.52	15408.2
2870.15	15752.5
2872.78	16188.6
2875.41	16472.5
2878.04	16918.9
2880.67	17267.5
2883.3	17403.2
2885.92	17293.9
2888.55	17325.7
2891.18	17275.3
2893.8	17197.2
2896.42	17243.6
2899.04	17197
2901.67	17110.9
2904.29	17074.3
2906.9	16950.3
2909.52	16879.3
2912.14	16775.1
2914.76	16741.1
2917.37	16617.4
2919.99	16635.7
2922.6	16640.7
2925.21	16627.4
2927.82	16626.9
2930.44	16627.1
2933.05	16573.2
2935.65	16286
2938.26	15873
2940.87	15059.9
2943.48	14085.1
2946.08	13225.2
2948.69	12577.8
2951.29	12218.5
2953.89	11973.5
2956.49	11777.3
2959.1	11588.5
2961.7	11343.7
2964.29	11027.7
2966.89	10723.2
2969.49	10380.8
2972.09	9975.02
2974.68	9685.93
2977.28	9425.8
2979.87	9228.54
2982.46	9027.36
2985.05	8846.32
2987.65	8737.96
2990.24	8575.44
2992.82	8498.52
2995.41	8483.58
2998	8412.47
3000.59	8407.31
3003.17	8390.8
3005.76	8357.42
3008.34	8225.04
3010.92	8161.74
3013.5	8032.96
3016.09	7897.05
3018.67	7758.73
3021.25	7655.11
3023.82	7573.64
3026.4	7566.88
3028.98	7448.22
3031.55	7436
3034.13	7444.2
3036.7	7427.72
3039.28	7398.33
3041.85	7417.02
3044.42	7383.04
3046.99	7430.89
3049.56	7419.06
3052.13	7434.76
3054.69	7494.59
3057.26	7473.7
3059.83	7495.29
3062.39	7569.74
3064.95	7538.12
3067.52	7568.08
3070.08	7553.27
3072.64	7545.25
3075.2	7591.92
3077.76	7556.83
3080.32	7549.01
3082.88	7606.76
3085.44	7650.49
3087.99	7580.2
3090.55	7647.98
3093.1	7655.33
3095.65	7674.36
3098.21	7701
3100.76	7769.3
3103.31	7796.5
3105.86	7798.49
3108.41	7891.53
3110.96	7970.83
3113.5	7968.99
3116.05	8026.61
3118.59	8102.96
3121.14	8127.76
3123.68	8156.02
3126.23	8223.4
3128.77	8261.4
3131.31	8392.84
3133.85	8384.81
3136.39	8485.26
3138.93	8469.26
3141.46	8529.19
3144	8577.61
3146.54	8624.57
3149.07	8708.48
3151.6	8771.7
3154.14	8857.52
3156.67	8873.44
3159.2	8998.17
3161.73	8947.27
3164.26	9077.92
3166.79	9107.84
3169.32	9056.61
3171.84	9058.37
3174.37	9023.91
3176.9	9076.99
3179.42	9072.03
3181.94	9049.38
3184.47	9086.97
3186.99	9081.85
3189.51	9094.61
3192.03	9078.42
3194.55	9039.63
3197.07	9032.61
3199.58	9035.24
3202.1	9026.32
3204.62	9041.93
3207.13	9005.93
3209.65	8986.22
3212.16	8979.63
3214.67	8914.32
3217.18	8908.25
3219.69	8869.97
3222.2	8864.73
3224.71	8874.2
3227.22	8801.32
3229.73	8799.17
3232.23	8763.11
3234.74	8726.77
3237.24	8713.5
3239.75	8657.62
3242.25	8643.48
3244.75	8634.41
3247.25	8591.25
3249.75	8550.65
3252.25	8502.58
3254.75	8473.57
3257.25	8425.78
3259.74	8363.39
3262.24	8344.66
3264.73	8315.53
3267.23	8319.7
3269.72	8283.4
3272.21	8267.33
3274.7	8234.42
3277.2	8192.03
3279.69	8118.38
3282.17	8107.58
3284.66	8099.74
3287.15	8052.44
3289.64	8039.13
3292.12	8004.57
3293.56	7986.8
3296.05	7964.63
3298.55	7970.79
3301.04	7892.02
3303.54	7927.11
3306.03	7894.23
3308.52	7843.63
3311.01	7853.34
3313.5	7835.55
3315.99	7792.79
3318.48	7783.74
3320.97	7776.02
3323.45	7778.22
3325.94	7734.31
3328.42	7738.13
3330.91	7711.49
3333.39	7734.55
3335.87	7666.06
3338.36	7666.39
3340.84	7632.36
3343.32	7622.71
3345.8	7595.87
3348.27	7575.37
3350.75	7561.99
3353.23	7543.77
3355.7	7544.96
3358.18	7510.58
3360.65	7515.54
3363.13	7494.44
3365.6	7473.09
3368.07	7463.65
3370.54	7455.64
3373.01	7476.35
3375.48	7422.14
3377.95	7443.2
3380.42	7410.5
3382.88	7395.04
3385.35	7366.13
3387.81	7342.15
3390.28	7323.64
3392.74	7345.55
3395.2	7321.03
3397.67	7311.37
3400.13	7301.96
3402.58	7217.19
3405.05	7225.1
3407.5	7216.29
3409.96	7149.02
3412.42	7168.58
3414.87	7173.99
3417.33	7109.28
3419.78	7063.86
3422.23	7063.03
3424.69	7019.05
3427.14	6993.35
3429.59	6982.96
3432.04	6935.18
3434.49	6872.43
3436.94	6849.42
3439.39	6809.33
3441.83	6819.16
3444.28	6729.19
3446.72	6693.76
3449.17	6623.38
3451.61	6659.8
3454.05	6602.62
3456.5	6582.65
3458.94	6527.8
3461.38	6485.83
3463.81	6439.18
3466.25	6403.48
3468.69	6364.01
3471.13	6320.2
3473.56	6212.85
3476	6186.06
3478.43	6094.76
3480.87	6095.8
3483.3	5994.68
3485.73	5967.48
3488.16	5948.66
3490.59	5858.03
3493.02	5796.25
3495.45	5768.69
3497.88	5699.58
3499.09	5666.03