File: src/Milk_AI/Amul toned milk Cold 532nm 50% 600g 50xL 10s 10times 400-3500cm-1 200hole.txt
#Acq. time (s)=	10
#Accumulations=	10
#Range (cm-¹)=	400...3500
#Windows=	3
#Auto scanning=	Off
#Autofocus=	Off
#AutoExposure=	Off
#Spike filter=	Multiple accum.
#Delay time (s)=	0
#Binning=	1
#Readout mode=	Signal
#DeNoise=	Off
#ICS correction=	On
#Dark correction=	Off
#Inst. Process=	Off
#Detector Gain=	Best Dynamic Range
#Detector ADC=	45 kHz
#Detector temperature (°C)=	-60.1
#Instrument=	LabRAM HR Evol
#Detector=	Syncerity OE
#Objective=	x50_VIS_LWD
#Grating=	600 (500nm)
#ND Filter=	50%
#Laser=	532nm_Edge
#Hole=	199.981
#Range=	Visible
#E-Cal_Neon=	0
#StageXY=	75x50mm Scan+
#StageZ=	Z motor
#X (µm)=	0
#Y (µm)=	0
#Z (µm)=	281.7
#Spectral res.(cm-¹)=	12.8
#Full time(mm:ss)=	5:19
#AC=	Calibrated 2025-07-01 10:31
#Project=
#Sample=
#Site=
#Title=	D_1
#Remark=
#Date=	01.07.2025 12:01 (India Standard Time)
#Acquired=	01.07.2025 12:01:19 (India Standard Time)
#AxisType[0]=Intens
#AxisUnit[0]=Cnt
#AxisType[1]=Spectr
#AxisUnit[1]=1/cm
400.083	36461.2
403.63	36286.7
407.176	36370.6
410.72	36384.6
414.263	36396.8
417.805	36482.7
421.345	36459.3
424.884	36468.6
428.421	36566.2
431.955	36579.1
435.49	36666.6
439.023	36592.2
442.555	36653.9
446.084	36639.5
449.613	36607.3
453.141	36644.1
456.666	36643.8
460.191	36570.4
463.715	36741.5
467.235	36722.2
470.756	36725.6
474.274	36779.8
477.793	36800.1
481.308	36778
484.823	36831.9
488.336	36905.2
491.847	36868.6
495.358	36889.3
498.867	37116.4
502.374	37103.5
505.881	37290.7
509.386	37201.9
512.888	37227.9
516.39	37268.1
519.89	37256
523.391	37267.4
526.889	37375.4
530.385	37247.2
533.88	37261.5
537.373	37236.5
540.866	37170.7
544.357	37258.3
547.846	37208.6
551.334	37260.5
554.821	37326.8
558.307	37329.9
561.789	37338.8
565.272	37418
568.753	37500.7
572.233	37525.5
575.712	37443.3
579.188	37575.3
582.664	37550.6
586.139	37590.3
589.611	37605.1
593.083	37558.9
596.554	37708.7
600.021	37668.7
603.49	37682.8
606.955	37650.1
610.42	37646.5
613.882	37652
617.345	37668.9
620.805	37516.6
624.263	37532.4
627.722	37520.1
631.178	37452.3
634.633	37551.1
638.088	37577
641.539	37656.3
644.99	37420.6
648.439	37499
651.887	37473.5
655.335	37505.3
658.781	37617.8
662.225	37534.5
665.667	37521.9
669.108	37737.7
672.548	37615.2
675.987	37578.2
679.424	37636.2
682.86	37719.1
686.293	37828.9
689.727	37809.1
693.159	37691
696.59	37864.7
700.019	37870.8
703.448	37830.2
706.872	37750
710.298	37665.6
713.723	37569.5
717.144	37725.8
720.565	37892.8
723.984	37746.6
727.403	37817.4
730.821	37763.2
734.235	37690.5
737.651	37769.7
741.063	37604.7
744.474	37736
747.885	37684.6
751.293	37792.2
754.702	37848.6
758.108	37947.8
761.512	37843.7
764.915	38001.6
768.319	38036.9
771.719	38030.2
775.118	38121.4
778.516	38002.6
781.913	38154.5
785.308	38102.2
788.702	38139
792.095	38089.2
795.486	38023.1
798.876	38089.1
802.265	38186.8
805.653	38065
809.039	38021.4
812.424	37774.2
815.808	37923.2
819.191	37959.8
822.572	38045.5
825.95	38074
829.329	38023.2
832.706	38028.4
836.08	37937.2
839.455	37988
842.829	38103.5
846.199	38180.6
849.57	38187.1
852.938	38129.7
856.307	38201.7
859.672	38247.9
863.038	38231.6
866.401	38157
869.765	38138.5
873.125	38205.2
876.484	38332.3
879.844	38187.3
883.2	38156.5
886.555	38132.7
889.909	38173.3
893.262	38224
896.616	38072.5
899.966	38068.3
903.315	37995.1
906.663	37954
910.009	37941.1
913.354	37874.1
916.698	37796.6
920.041	37814.4
923.383	37673.1
926.723	37645.4
930.062	37605.1
933.399	37565.8
936.734	37603
940.069	37807.1
943.403	37768.9
946.736	37682.5
950.065	37745.2
953.396	37794.7
956.725	37768.6
960.051	37819.7
963.377	37823.6
966.7	37773.3
970.025	37810.3
973.345	37777.3
976.667	37706.2
979.985	37755.7
983.304	37859.6
986.62	37886.6
989.935	37921.4
993.25	37988.5
996.563	38111.9
999.874	38487.2
1003.19	38437.8
1006.49	38202.9
1009.8	38089.6
1013.11	37909.3
1016.41	38041.4
1019.72	37895.5
1023.02	37814
1026.32	37747.3
1029.62	37743.6
1032.92	37700.3
1036.22	37601.7
1039.51	37621.5
1042.81	37552.8
1046.1	37599.6
1049.39	37585.9
1052.68	37672.5
1055.97	37749.8
1059.26	37801.3
1062.55	37822.1
1065.83	37709.7
1069.12	37655.8
1072.4	37738
1075.68	37656.7
1078.97	37805.2
1082.24	37733.7
1085.52	37761.9
1088.8	37662.7
1092.08	37579.2
1095.35	37421.8
1098.62	37351.5
1101.9	37386.6
1105.17	37227.1
1108.44	37330.3
1111.7	37353.6
1114.97	37502.9
1118.23	37464.4
1121.5	37592.7
1124.76	37443.4
1128.03	37473.1
1131.29	37292.9
1134.54	37290.1
1137.8	37147.1
1141.06	37081.4
1144.31	37305.9
1147.57	37603.2
1150.82	37967.7
1154.07	38295
1157.32	38201.8
1160.57	37630.4
1163.82	37240.1
1167.07	36984.4
1170.31	37000.4
1173.56	36886.7
1176.8	36882.4
1180.04	36731.5
1183.28	36828.1
1186.52	36819.8
1189.76	36847.8
1192.99	36798.4
1196.23	36718.4
1199.46	36630.8
1202.7	36590.7
1205.93	36623
1209.16	36633.4
1212.39	36602.2
1215.62	36489.8
1218.84	36421.8
1222.07	36465.5
1225.29	36515
1228.52	36469.6
1231.74	36455
1234.96	36409.6
1238.18	36429.3
1241.4	36578.2
1244.61	36505.4
1247.83	36690.2
1251.04	36532.6
1254.25	36610.4
1257.47	36566.5
1260.68	36597.6
1263.89	36607.2
1267.09	36609.9
1270.3	36467.6
1273.51	36384
1276.71	36331.8
1279.91	36342.1
1283.12	36217.6
1286.32	36250.1
1289.52	36322.8
1292.72	36367
1295.91	36456.2
1299.11	36456
1302.3	36575.3
1305.5	36484
1308.69	36217.1
1311.88	36267.7
1315.07	36050.1
1318.26	36009.1
1321.44	35920.7
1324.63	35795.4
1327.82	35919.4
1331	35872
1334.18	35822.8
1337.36	35872.7
1340.54	35829.6
1343.72	35747.3
1346.9	35656
1350.07	35768.6
1353.25	35688
1356.42	35564.5
1359.6	35366.3
1362.77	35438.3
1365.94	35434.3
1369.11	35322.4
1372.28	35276.6
1375.44	35022.3
1378.61	35074.3
1381.77	35014.5
1384.93	34840.1
1388.1	35012.7
1391.26	34975.2
1394.41	34887.7
1397.57	34925.5
1400.73	34822.4
1403.89	34774.5
1407.04	34833.4
1410.19	34814.9
1413.35	34865.3
1416.5	35006.6
1419.65	35049.4
1422.8	34984.6
1425.94	35031.7
1429.09	35264.4
1432.23	35583.7
1435.38	36026.3
1438.52	36034
1441.66	35982.4
1444.8	35929.2
1447.94	35742.8
1451.08	35580.8
1454.22	35499.2
1457.35	35413.1
1460.48	35349.6
1463.62	35154.6
1466.75	34880.1
1469.88	34709.9
1473.01	34478.5
1476.14	34306.2
1479.26	34180.6
1482.39	34071.6
1485.51	33961.7
1488.64	34098.5
1491.76	33974.9
1494.88	34156
1498	34108.6
1501.12	34093.3
1504.24	34246.5
1507.35	34228.9
1510.47	34502
1513.58	34809.7
1516.69	34984
1519.81	34994
1522.92	34909.5
1526.03	34695.2
1529.13	34301
1532.24	33920
1535.35	33652.1
1538.45	33682.2
1541.55	33502
1544.66	33477.4
1547.76	33288.3
1550.86	33286.4
1553.96	33351.1
1557.05	33247.6
1560.15	33286.1
1563.24	33317.4
1566.34	33305.5
1569.43	33283.9
1572.52	33207
1575.61	33077.6
1578.7	33185.3
1581.79	33067.8
1584.88	33050.5
1587.96	33069.4
1591.05	33014.9
1594.13	33036.3
1597.21	33042.1
1600.3	33105.8
1603.37	33029.3
1606.45	32947.5
1609.53	32891.9
1612.61	32755.6
1615.68	32659.6
1618.76	32680.7
1621.83	32660
1624.9	32636.9
1627.97	32597.1
1631.04	32650.5
1634.11	32633.4
1637.18	32667
1640.24	32687.9
1643.31	32593.5
1646.37	32821
1649.44	32928.1
1652.5	33022.7
1655.56	32986.4
1658.62	32815.8
1661.67	32621.3
1664.73	32501.6
1667.79	32441.8
1670.84	32285.8
1673.89	32345.4
1676.95	32188.6
1680	32033.6
1683.05	32072.7
1686.1	31929.5
1689.14	31799.6
1692.19	31804.5
1695.23	31650.7
1698.28	31557.5
1701.32	31401.7
1704.36	31303.9
1707.4	31368.5
1710.44	31254
1713.48	31283.1
1716.52	31164.7
1719.56	31204.6
1722.59	31192.9
1725.63	31114.5
1728.66	31091.6
1731.69	31180.9
1734.72	31187.1
1737.75	31186
1740.78	31111.2
1743.8	31160.6
1746.83	31067.8
1749.86	31008.1
1752.88	30851
1755.9	30759.7
1758.92	30744.8
1761.94	30632.4
1764.96	30533
1767.98	30617.6
1771	30627.4
1774.01	30616.7
1777.03	30552.6
1780.04	30509.9
1783.05	30487.7
1786.06	30448.9
1789.07	30511.4
1792.08	30291.7
1795.09	30432.6
1798.1	30218.5
1801.1	30217.7
1804.11	30245.3
1807.11	30215.2
1810.11	30216.8
1813.11	30152.7
1816.11	30120
1819.11	29959.1
1822.11	30001.4
1825.11	30012.3
1828.1	29945.8
1831.1	29933.4
1834.09	29893.3
1837.08	29866.5
1840.07	29897.2
1843.06	29814.1
1846.05	29827.3
1849.04	29756.3
1852.02	29698.5
1855.01	29678.4
1857.99	29614.9
1860.98	29530.3
1863.96	29665.1
1866.94	29528
1869.92	29478.4
1872.9	29534.5
1875.88	29505
1878.85	29439.3
1881.83	29348.7
1884.8	29359.9
1887.78	29231.5
1890.75	29318.4
1893.72	29137
1896.69	29052.8
1899.66	29033
1902.63	28977.9
1905.59	28818.1
1908.56	28694.6
1911.52	28681
1914.49	28591.3
1917.45	28397.6
1920.41	28296.3
1923.37	28227.4
1926.33	28169.1
1929.29	28042.9
1932.24	27972.3
1935.2	27871.8
1938.15	27787.2
1941.1	27663.8
1944.06	27588
1947.01	27499.5
1949.96	27411.7
1952.91	27287.6
1955.86	27163.7
1958.8	27010.8
1961.75	26949.1
1964.69	26923.3
1967.64	26874.4
1970.58	26764.6
1973.52	26603.6
1976.46	26559.9
1979.4	26512.7
1982.34	26383
1985.27	26373.1
1988.21	26187.6
1991.14	26136.4
1994.08	26007.2
1997.01	25856.5
1999.94	25812.1
2002.87	25708.1
2005.8	25692.7
2008.73	25655.5
2011.66	25553.4
2014.58	25539
2017.51	25414.8
2020.43	25316.4
2023.36	25164.7
2026.28	25149.9
2029.2	25110
2032.12	25018.7
2035.04	24888.2
2037.95	24892.7
2040.87	24882.3
2043.78	24732.8
2045.76	24766.8
2048.69	24724.5
2051.61	24606.8
2054.54	24561
2057.46	24613.9
2060.38	24588
2063.3	24515.6
2066.22	24559.2
2069.14	24537.1
2072.06	24476.2
2074.98	24429.7
2077.89	24399.2
2080.81	24414.3
2083.72	24336.7
2086.63	24261.7
2089.55	24213.6
2092.46	24252.7
2095.37	24154.2
2098.28	24208.4
2101.18	24112.2
2104.09	24071.7
2106.99	24009.8
2109.9	24008.1
2112.8	23922.2
2115.71	23895.8
2118.61	23927.1
2121.51	23940.2
2124.4	23856.6
2127.3	23849.4
2130.2	23839.6
2133.09	23730.4
2135.99	23779.9
2138.88	23733.8
2141.78	23683.2
2144.67	23802.8
2147.56	23707.9
2150.45	23594
2153.34	23583
2156.22	23530.9
2159.11	23584
2162	23504.8
2164.88	23557.1
2167.76	23495.7
2170.64	23488.3
2173.53	23503.7
2176.41	23412.1
2179.29	23412.7
2182.16	23371.1
2185.04	23280.6
2187.92	23314.4
2190.79	23227.4
2193.66	23232.2
2196.54	23172.3
2199.41	23152.8
2202.28	23198.9
2205.15	23132.7
2208.02	23160.1
2210.88	22975.7
2213.75	23006
2216.62	22904.1
2219.48	22918.4
2222.34	22787.2
2225.21	22776.7
2228.07	22808.8
2230.93	22745.3
2233.79	22727.8
2236.65	22641.3
2239.5	22611.5
2242.36	22595.9
2245.21	22577.5
2248.07	22477.6
2250.92	22460.1
2253.77	22442.3
2256.62	22368.7
2259.47	22257.7
2262.32	22201.5
2265.17	22099.1
2268.02	22018.5
2270.86	22041.2
2273.71	22005.2
2276.55	22004.8
2279.39	21896.1
2282.24	21927.9
2285.08	21818.8
2287.92	21705.8
2290.75	21743.9
2293.59	21690.9
2296.43	21647.6
2299.26	21570.9
2302.1	21574.8
2304.93	21466.5
2307.76	21408.5
2310.6	21417.9
2313.43	21424.3
2316.25	21279.1
2319.08	21267.1
2321.91	21200.3
2324.74	21251.3
2327.56	21333.2
2330.39	21322.6
2333.21	21102.8
2336.03	21052.2
2338.85	20982
2341.67	20945.6
2344.49	20904.3
2347.31	20867.3
2350.13	20755
2352.94	20752.1
2355.76	20689.4
2358.57	20560.4
2361.39	20572
2364.2	20651.2
2367.01	20543.9
2369.82	20502.2
2372.63	20494.1
2375.44	20400.7
2378.24	20370.9
2381.05	20372.1
2383.85	20326.7
2386.66	20263
2389.46	20277.4
2392.26	20215.1
2395.06	20191
2397.86	20089.6
2400.66	20134.2
2403.46	20103.1
2406.26	20013.7
2409.05	19975.5
2411.85	20019.4
2414.64	19990.1
2417.43	19850.5
2420.23	19907.6
2423.02	19811.3
2425.81	19856.5
2428.6	19821.2
2431.38	19795.4
2434.17	19708.7
2436.96	19704.3
2439.74	19679.3
2442.53	19649.1
2445.31	19602.3
2448.09	19598.6
2450.87	19558.1
2453.65	19475.4
2456.43	19436.1
2459.21	19458.5
2461.98	19353.9
2464.76	19359.1
2467.53	19307.5
2470.31	19312.8
2473.08	19227.2
2475.85	19240.3
2478.63	19206.9
2481.39	19211.9
2484.16	19153.9
2486.93	19127.8
2489.7	19032.2
2492.46	19049.6
2495.23	18985.2
2497.99	18971.9
2500.76	18947.1
2503.52	18917.8
2506.28	18829.7
2509.04	18801.2
2511.8	18795.6
2514.56	18799.2
2517.31	18756.7
2520.07	18771
2522.82	18713.4
2525.58	18735.8
2528.33	18685.3
2531.09	18659.3
2533.84	18646.5
2536.59	18639.1
2539.34	18457.1
2542.08	18488.3
2544.83	18503.3
2547.58	18401
2550.32	18398.8
2553.07	18400.1
2555.81	18275.6
2558.55	18322.5
2561.29	18238.9
2564.03	18210.4
2566.77	18182.4
2569.51	18162.4
2572.25	18210.8
2574.99	18112.9
2577.72	18089.6
2580.46	18153.6
2583.19	18091
2585.92	18129.2
2588.65	18041.5
2591.38	18110.2
2594.11	18068.2
2596.84	18028
2599.57	17977.8
2602.3	17922.1
2605.02	17914.9
2607.75	17959.9
2610.47	17873.9
2613.19	17953.3
2615.92	17820
2618.64	17721.9
2621.36	17839.5
2624.08	17706.2
2626.8	17742.4
2629.51	17707.9
2632.23	17705.3
2634.94	17650
2637.66	17676.2
2640.37	17564
2643.08	17590.8
2645.79	17574.6
2648.5	17589.3
2651.21	17480.9
2653.92	17497.5
2656.63	17485.5
2659.33	17459.8
2662.04	17475.1
2664.75	17410.5
2667.45	17354.8
2670.15	17438.7
2672.85	17366
2675.55	17361.9
2678.25	17281
2680.95	17269.8
2683.65	17239.1
2686.35	17179
2689.04	17267.6
2691.74	17217.5
2694.43	17089.6
2697.13	17119.6
2699.82	17130.3
2702.51	17116.4
2705.2	17129.2
2707.89	17182.9
2710.58	17050.4
2713.26	17046.4
2715.95	17061.2
2718.64	16995.6
2721.32	16993.7
2724	16939.9
2726.69	16909.7
2729.37	16987.3
2732.05	16878.5
2734.73	16787
2737.41	16784.1
2740.09	16727.9
2742.76	16747
2745.44	16678.8
2748.11	16683.8
2750.79	16603.3
2753.46	16595.9
2756.13	16546.1
2758.81	16532.2
2761.47	16539.7
2764.14	16491.2
2766.81	16463.2
2769.48	16394.8
2772.15	16463.2
2774.81	16407
2777.48	16379.4
2780.14	16351.1
2782.8	16262.1
2785.47	16205.3
2788.13	16175.8
2790.79	16218
2793.44	16189.7
2796.1	16163.3
2798.76	16236.9
2801.42	16108.8
2804.07	16109.3
2806.73	16045.1
2809.38	16073.1
2812.03	16070.4
2814.68	16036.4
2817.33	16018
2819.98	16024.2
2822.63	16021.8
2825.28	15993.2
2827.93	16026.2
2830.57	16015.2
2833.22	16063.7
2835.86	16222.3
2838.51	16269.4
2841.15	16568.3
2843.79	16842.8
2846.43	17215
2849.07	17456
2851.71	17490.2
2854.35	17396.2
2856.98	17284.8
2859.62	17201.7
2862.25	17075
2864.89	17010.3
2867.52	17043
2870.15	17156.7
2872.78	17212.2
2875.41	17248.3
2878.04	17299.7
2880.67	17406.1
2883.3	17403.1
2885.92	17420.3
2888.55	17384.5
2891.18	17374.4
2893.8	17341.7
2896.42	17328.6
2899.04	17303.3
2901.67	17266.3
2904.29	17233.6
2906.9	17169
2909.52	17150.6
2912.14	17120.8
2914.76	17099.4
2917.37	17140.2
2919.99	17027.6
2922.6	17004
2925.21	16967
2927.82	16997.8
2930.44	16985.1
2933.05	16996.4
2935.65	16909.1
2938.26	16778.3
2940.87	16624.1
2943.48	16369.6
2946.08	16237.7
2948.69	16078.1
2951.29	15956.4
2953.89	15903
2956.49	15863
2959.1	15738.6
2961.7	15714.6
2964.29	15657.7
2966.89	15567.6
2969.49	15452.2
2972.09	15376.3
2974.68	15312.9
2977.28	15271.7
2979.87	15196.7
2982.46	15108.3
2985.05	15121.2
2987.65	14982.8
2990.24	14927
2992.82	14960.3
2995.41	14859.7
2998	14831.4
3000.59	14760.5
3003.17	14767.9
3005.76	14772
3008.34	14702.4
3010.92	14682.5
3013.5	14582.5
3016.09	14547.2
3018.67	14530.2
3021.25	14560.7
3023.82	14535
3026.4	14422.3
3028.98	14424.1
3031.55	14382.2
3034.13	14427.5
3036.7	14346.5
3039.28	14373.2
3041.85	14347.1
3044.42	14295.1
3046.99	14378.5
3049.56	14335.4
3052.13	14343.8
3054.69	14422.5
3057.26	14303.9
3059.83	14364.2
3062.39	14335.4
3064.95	14354.3
3067.52	14340.7
3070.08	14332.7
3072.64	14314.8
3075.2	14326.9
3077.76	14421.5
3080.32	14372.6
3082.88	14355.8
3085.44	14339.1
3087.99	14366.6
3090.55	14313.2
3093.1	14373.6
3095.65	14278.5
3098.21	14372.7
3100.76	14341.9
3103.31	14402.3
3105.86	14397
3108.41	14417.3
3110.96	14493.7
3113.5	14456.3
3116.05	14469.6
3118.59	14515.8
3121.14	14485.8
3123.68	14562.8
3126.23	14534.2
3128.77	14661.2
3131.31	14675.9
3133.85	14665.4
3136.39	14671.7
3138.93	14701.5
3141.46	14781.7
3144	14751.2
3146.54	14790.2
3149.07	14789.4
3151.6	14809.9
3154.14	14858.2
3156.67	14919.5
3159.2	14910
3161.73	14917.3
3164.26	14881.4
3166.79	14905.2
3169.32	14858.2
3171.84	14891.4
3174.37	14859.4
3176.9	14836.6
3179.42	14783.5
3181.94	14798.7
3184.47	14809.3
3186.99	14727.2
3189.51	14707.7
3192.03	14679.1
3194.55	14618.4
3197.07	14649.7
3199.58	14630.1
3202.1	14596.7
3204.62	14600.9
3207.13	14552.8
3209.65	14497
3212.16	14479
3214.67	14438.5
3217.18	14391.6
3219.69	14385.5
3222.2	14343.5
3224.71	14339.5
3227.22	14268.8
3229.73	14244.4
3232.23	14246.7
3234.74	14160.7
3237.24	14157.8
3239.75	14102
3242.25	14081.6
3244.75	14032.6
3247.25	14019
3249.75	13969.8
3252.25	13952.9
3254.75	13898.9
3257.25	13812.2
3259.74	13751.7
3262.24	13746.8
3264.73	13698.7
3267.23	13722
3269.72	13684.8
3272.21	13644
3274.7	13592.6
3277.2	13600.2
3279.69	13539.9
3282.17	13481.4
3284.66	13445.5
3287.15	13470.6
3289.64	13417.8
3292.12	13370.6
3293.56	13354.9
3296.05	13368.6
3298.55	13300.9
3301.04	13280.6
3303.54	13234.3
3306.03	13214.4
3308.52	13216.9
3311.01	13204
3313.5	13150.1
3315.99	13120.4
3318.48	13118.4
3320.97	13080.8
3323.45	13092.7
3325.94	13047.9
3328.42	13035.7
3330.91	12980.1
3333.39	12996.2
3335.87	12959
3338.36	12932.9
3340.84	12869.6
3343.32	12858.3
3345.8	12835.1
3348.27	12835.3
3350.75	12810.6
3353.23	12787
3355.7	12730.1
3358.18	12719.7
3360.65	12738.8
3363.13	12705.5
3365.6	12684.8
3368.07	12615.2
3370.54	12652.2
3373.01	12657.5
3375.48	12595.6
3377.95	12562.8
3380.42	12555.3
3382.88	12499.2
3385.35	12460.1
3387.81	12475.8
3390.28	12416.2
3392.74	12430.7
3395.2	12417.1
3397.67	12414.3
3400.13	12396.9
3402.58	12290
3405.05	12338.5
3407.5	12296.4
3409.96	12254.2
3412.42	12254.4
3414.87	12195.6
3417.33	12183.6
3419.78	12164.6
3422.23	12159.7
3424.69	12092.7
3427.14	12062.1
3429.59	12039.6
3432.04	12009.1
3434.49	11953.2
3436.94	11912.6
3439.39	11923.5
3441.83	11869.8
3444.28	11805.7
3446.72	11770.1
3449.17	11701.7
3451.61	11692.5
3454.05	11661.6
3456.5	11646.8
3458.94	11583.2
3461.38	11526.4
3463.81	11504.9
3466.25	11468.6
3468.69	11406.9
3471.13	11371.7
3473.56	11303.4
3476	11256.1
3478.43	11202.9
3480.87	11162.5
3483.3	11100.3
3485.73	11027.9
3488.16	11028.4
3490.59	10953.1
3493.02	10926
3495.45	10853.4
3497.88	10796.6
3499.09	10764.7