File: src/Milk_AI/Amul full cream basic 532nm 50% 600g 50xL 10s 10times 400-3500cm-1 200hole.txt
#Acq. time (s)=	10
#Accumulations=	10
#Range (cm-¹)=	400...3500
#Windows=	3
#Auto scanning=	Off
#Autofocus=	Off
#AutoExposure=	Off
#Spike filter=	Multiple accum.
#Delay time (s)=	0
#Binning=	1
#Readout mode=	Signal
#DeNoise=	Off
#ICS correction=	On
#Dark correction=	Off
#Inst. Process=	Off
#Detector Gain=	Best Dynamic Range
#Detector ADC=	45 kHz
#Detector temperature (°C)=	-60.1
#Instrument=	LabRAM HR Evol
#Detector=	Syncerity OE
#Objective=	x50_VIS_LWD
#Grating=	600 (500nm)
#ND Filter=	50%
#Laser=	532nm_Edge
#Hole=	199.981
#Range=	Visible
#E-Cal_Neon=	0
#StageXY=	75x50mm Scan+
#StageZ=	Z motor
#X (µm)=	0
#Y (µm)=	0
#Z (µm)=	642.8
#Spectral res.(cm-¹)=	12.8
#Full time(mm:ss)=	5:19
#AC=	Calibrated 2025-07-01 10:31
#Project=
#Sample=
#Site=
#Title=	D_1
#Remark=
#Date=	01.07.2025 15:45 (India Standard Time)
#Acquired=	01.07.2025 15:45:02 (India Standard Time)
#AxisType[0]=Intens
#AxisUnit[0]=Cnt
#AxisType[1]=Spectr
#AxisUnit[1]=1/cm
400.083	27465.7
403.63	27185.6
407.176	27246.7
410.72	27234.5
414.263	27223.8
417.805	27273.6
421.345	27220.3
424.884	27132.3
428.421	27231.4
431.955	27130.7
435.49	27108.1
439.023	27052.7
442.555	27006.1
446.084	26977.8
449.613	26863.2
453.141	26928.3
456.666	26804.8
460.191	26771.5
463.715	26765.2
467.235	26721.9
470.756	26673.1
474.274	26654.4
477.793	26629.2
481.308	26564.4
484.823	26643.4
488.336	26540.9
491.847	26544.5
495.358	26532.2
498.867	26469.6
502.374	26558.7
505.881	26589.2
509.386	26528.3
512.888	26583
516.39	26546.8
519.89	26409.5
523.391	26408.3
526.889	26312.7
530.385	26296.1
533.88	26212.5
537.373	26097.4
540.866	25992.9
544.357	26084.1
547.846	25957.2
551.334	25946.2
554.821	25902.6
558.307	25832.1
561.789	25868.5
565.272	25852.4
568.753	25910.8
572.233	25869.2
575.712	25843
579.188	25948.3
582.664	25827.1
586.139	25887.7
589.611	25927.6
593.083	25888.6
596.554	25881.5
600.021	25915.9
603.49	25950
606.955	25870.3
610.42	25749.3
613.882	25592.4
617.345	25618.5
620.805	25448
624.263	25393.2
627.722	25366.8
631.178	25281.1
634.633	25347.2
638.088	25341.6
641.539	25368.9
644.99	25250.4
648.439	25142.2
651.887	25078.7
655.335	25143.3
658.781	25099.9
662.225	24966.6
665.667	24984.9
669.108	24935.9
672.548	24916.8
675.987	24822.9
679.424	24848.1
682.86	24888.3
686.293	24845.5
689.727	24839.1
693.159	24868.4
696.59	24848.4
700.019	24887.6
703.448	24881.6
706.872	24780.3
710.298	24694.2
713.723	24740.7
717.144	24800.2
720.565	24834.9
723.984	24775.4
727.403	24753.9
730.821	24640.7
734.235	24711.3
737.651	24664.7
741.063	24638.1
744.474	24567.1
747.885	24576
751.293	24627
754.702	24616.6
758.108	24696.4
761.512	24569.8
764.915	24561.1
768.319	24593.3
771.719	24625.2
775.118	24557.6
778.516	24508.2
781.913	24489.9
785.308	24526.7
788.702	24467.3
792.095	24513.8
795.486	24448.2
798.876	24543.9
802.265	24600.9
805.653	24655.1
809.039	24591.5
812.424	24590.2
815.808	24686.7
819.191	24740.9
822.572	24882.9
825.95	25075.7
829.329	25105.9
832.706	25195.9
836.08	25289.1
839.455	25298.6
842.829	25479.2
846.199	25480.8
849.57	25428.5
852.938	25455.3
856.307	25526.5
859.672	25722.5
863.038	25786.4
866.401	25780.3
869.765	25708
873.125	25744.4
876.484	25590.2
879.844	25434.9
883.2	25424.4
886.555	25422.2
889.909	25249.7
893.262	24993.2
896.616	24764.6
899.966	24599
903.315	24567.1
906.663	24359.5
910.009	24375.3
913.354	24422.5
916.698	24371.4
920.041	24295.8
923.383	24162.9
926.723	23985.2
930.062	23933.9
933.399	23895.8
936.734	23848.1
940.069	23899.9
943.403	23928.9
946.736	23928.2
950.065	23927.8
953.396	23996.6
956.725	24011.2
960.051	23938.6
963.377	23927.5
966.7	23819.1
970.025	23722.1
973.345	23650.6
976.667	23592.9
979.985	23609.1
983.304	23645.7
986.62	23743.8
989.935	23855.7
993.25	24138.4
996.563	24663.5
999.874	25133.1
1003.19	25086.7
1006.49	24573.5
1009.8	24259.9
1013.11	24069.2
1016.41	24078
1019.72	23951.9
1023.02	23885.2
1026.32	23742.2
1029.62	23720.2
1032.92	23707.9
1036.22	23648.4
1039.51	23644.6
1042.81	23663.5
1046.1	23576
1049.39	23783.8
1052.68	24079.5
1055.97	24613.8
1059.26	24961.2
1062.55	24860.5
1065.83	24421.8
1069.12	24468.2
1072.4	24662.3
1075.68	24771.6
1078.97	24746.5
1082.24	24635.6
1085.52	24349.6
1088.8	24069.5
1092.08	23754.3
1095.35	23472.1
1098.62	23298.4
1101.9	23122.4
1105.17	23040.1
1108.44	23061.1
1111.7	23351.5
1114.97	23542.2
1118.23	23749.2
1121.5	23923.1
1124.76	23934.4
1128.03	23477
1131.29	23011.8
1134.54	22883.2
1137.8	22998
1141.06	23391.8
1144.31	24005.2
1147.57	25130.2
1150.82	26586.7
1154.07	27071.9
1157.32	25759
1160.57	23966.6
1163.82	22932.1
1167.07	22592.3
1170.31	22494.3
1173.56	22280
1176.8	22092.8
1180.04	22148
1183.28	22206.6
1186.52	22305.2
1189.76	22272
1192.99	22086.2
1196.23	21864.2
1199.46	21712.4
1202.7	21511.4
1205.93	21529.2
1209.16	21490
1212.39	21360
1215.62	21183.5
1218.84	21047.8
1222.07	21012.1
1225.29	21007.8
1228.52	21113.5
1231.74	21229.5
1234.96	21177
1238.18	21306.8
1241.4	21428.1
1244.61	21557.6
1247.83	21708.3
1251.04	21800.5
1254.25	21917.2
1257.47	22013.7
1260.68	22147
1263.89	22256.9
1267.09	22161.6
1270.3	21962.5
1273.51	21820.8
1276.71	21851.8
1279.91	21866.1
1283.12	21930.1
1286.32	22347.8
1289.52	23077.3
1292.72	23943.6
1295.91	24317.4
1299.11	24151
1302.3	23797.9
1305.5	23285.3
1308.69	22594.7
1311.88	22072.5
1315.07	21594.9
1318.26	21267.2
1321.44	20931.2
1324.63	20747.7
1327.82	20538.9
1331	20437.1
1334.18	20437
1337.36	20296.2
1340.54	20311.4
1343.72	20210.3
1346.9	20068.3
1350.07	20182.1
1353.25	19996.5
1356.42	19913.9
1359.6	19839.6
1362.77	19927.4
1365.94	19815.1
1369.11	19778.5
1372.28	19636.1
1375.44	19405.1
1378.61	19352
1381.77	19257.1
1384.93	19175.8
1388.1	19221.3
1391.26	19202.1
1394.41	19184.7
1397.57	19278.8
1400.73	19255.2
1403.89	19346.1
1407.04	19496.9
1410.19	19624.4
1413.35	19939.5
1416.5	20136.7
1419.65	20446.6
1422.8	20799.1
1425.94	21745.5
1429.09	23221
1432.23	24803.6
1435.38	25882.6
1438.52	25685.9
1441.66	25075.7
1444.8	24546.9
1447.94	24103.9
1451.08	23794.7
1454.22	23429.6
1457.35	22941.9
1460.48	22243.7
1463.62	21567.9
1466.75	20784.8
1469.88	20116
1473.01	19502.5
1476.14	19181.2
1479.26	18900.1
1482.39	18761.8
1485.51	18695.1
1488.64	18620.9
1491.76	18713
1494.88	18837.7
1498	19011
1501.12	19258.4
1504.24	19690.4
1507.35	20354.2
1510.47	21329.2
1513.58	22182.9
1516.69	22806.7
1519.81	22848.4
1522.92	22415.9
1526.03	21246.6
1529.13	19857.3
1532.24	18893.9
1535.35	18278.2
1538.45	17998.4
1541.55	17727.7
1544.66	17603.8
1547.76	17467.6
1550.86	17399.9
1553.96	17297.1
1557.05	17223.5
1560.15	17195.1
1563.24	17187.2
1566.34	17234.3
1569.43	17156.1
1572.52	17213.6
1575.61	17107.9
1578.7	17167.6
1581.79	17119.8
1584.88	17127.3
1587.96	17137.7
1591.05	17064.8
1594.13	17091.4
1597.21	17090.1
1600.3	17070.7
1603.37	17048.4
1606.45	17031.2
1609.53	16925.2
1612.61	16967
1615.68	16896.5
1618.76	16868
1621.83	16885.1
1624.9	16842.8
1627.97	16907.2
1631.04	17092.1
1634.11	17174.6
1637.18	17209.1
1640.24	17517.8
1643.31	17970.8
1646.37	18776.3
1649.44	19521.6
1652.5	19478.4
1655.56	18770.7
1658.62	18000.9
1661.67	17490.1
1664.73	17283.8
1667.79	16981.4
1670.84	16792.2
1673.89	16513
1676.95	16365
1680	16164.7
1683.05	16078.9
1686.1	15971.3
1689.14	15839.1
1692.19	15795.9
1695.23	15737.3
1698.28	15599
1701.32	15565.6
1704.36	15520.6
1707.4	15450.1
1710.44	15406
1713.48	15426.8
1716.52	15309.9
1719.56	15380.2
1722.59	15496.2
1725.63	15543.3
1728.66	15720.5
1731.69	15830.5
1734.72	16109.3
1737.75	16400.7
1740.78	16349.2
1743.8	16236.7
1746.83	16130.7
1749.86	15871.4
1752.88	15615.6
1755.9	15258.1
1758.92	15052.2
1761.94	14909.7
1764.96	14751.3
1767.98	14778.1
1771	14671.5
1774.01	14640.8
1777.03	14621.4
1780.04	14622.4
1783.05	14518.3
1786.06	14562
1789.07	14517.4
1792.08	14420.2
1795.09	14444.3
1798.1	14460
1801.1	14364.5
1804.11	14343.9
1807.11	14246.6
1810.11	14291.1
1813.11	14263.5
1816.11	14227
1819.11	14160
1822.11	14212.8
1825.11	14079.2
1828.1	14174.5
1831.1	14075.3
1834.09	14096.7
1837.08	14064.9
1840.07	14018.1
1843.06	14031.8
1846.05	13959.8
1849.04	13979.7
1852.02	13932.3
1855.01	13870.5
1857.99	13844.6
1860.98	13819.5
1863.96	13881.6
1866.94	13779.2
1869.92	13797.4
1872.9	13726.5
1875.88	13793.9
1878.85	13647.4
1881.83	13714.9
1884.8	13654.9
1887.78	13575.3
1890.75	13578.1
1893.72	13535.1
1896.69	13419.7
1899.66	13463.8
1902.63	13375.8
1905.59	13244.5
1908.56	13233.3
1911.52	13152
1914.49	13023.1
1917.45	12948.7
1920.41	12858.9
1923.37	12769.7
1926.33	12743.6
1929.29	12684.4
1932.24	12573.5
1935.2	12542.6
1938.15	12462.8
1941.1	12330.7
1944.06	12334.6
1947.01	12245.3
1949.96	12154.7
1952.91	12050.2
1955.86	11974.6
1958.8	11921.6
1961.75	11828.8
1964.69	11802.7
1967.64	11715.2
1970.58	11629.4
1973.52	11594
1976.46	11541.8
1979.4	11480.2
1982.34	11441.5
1985.27	11334.7
1988.21	11280.3
1991.14	11241.7
1994.08	11136.7
1997.01	11059
1999.94	10984.1
2002.87	10945.2
2005.8	10913.9
2008.73	10859.9
2011.66	10823.4
2014.58	10785.2
2017.51	10692.7
2020.43	10622.8
2023.36	10576
2026.28	10519.8
2029.2	10474.9
2032.12	10426.4
2035.04	10375.2
2037.95	10331.2
2040.87	10273.4
2043.78	10228.7
2045.76	10235.8
2048.69	10159.7
2051.61	10154.8
2054.54	10172.4
2057.46	10140.6
2060.38	10111.7
2063.3	10102.9
2066.22	10058.3
2069.14	10049.2
2072.06	10081.7
2074.98	10021.2
2077.89	10008.4
2080.81	10011.7
2083.72	9977.97
2086.63	9949.91
2089.55	9980.81
2092.46	9927.24
2095.37	9918.57
2098.28	9890.15
2101.18	9843.01
2104.09	9851.98
2106.99	9835.18
2109.9	9789.76
2112.8	9787.13
2115.71	9770.84
2118.61	9749
2121.51	9738.5
2124.4	9740.9
2127.3	9729.45
2130.2	9641.74
2133.09	9639.54
2135.99	9702.12
2138.88	9679.36
2141.78	9664.63
2144.67	9677.32
2147.56	9650.11
2150.45	9583.41
2153.34	9594.86
2156.22	9604.4
2159.11	9577.14
2162	9583.85
2164.88	9509.39
2167.76	9569.7
2170.64	9516.51
2173.53	9516.92
2176.41	9502.82
2179.29	9493.12
2182.16	9447.33
2185.04	9449.11
2187.92	9434.56
2190.79	9382.48
2193.66	9358.73
2196.54	9351.72
2199.41	9309.14
2202.28	9342.07
2205.15	9257.22
2208.02	9331.99
2210.88	9237.01
2213.75	9230.6
2216.62	9274.55
2219.48	9225.8
2222.34	9183.58
2225.21	9160.42
2228.07	9121.89
2230.93	9095.53
2233.79	9102.32
2236.65	9078.97
2239.5	9013.65
2242.36	9034.46
2245.21	9000.58
2248.07	8971.62
2250.92	8965.13
2253.77	8920.26
2256.62	8929.58
2259.47	8888.52
2262.32	8855.41
2265.17	8814.56
2268.02	8806.23
2270.86	8726.31
2273.71	8722.63
2276.55	8717.2
2279.39	8698.92
2282.24	8713.63
2285.08	8666.64
2287.92	8655.59
2290.75	8586.4
2293.59	8604.48
2296.43	8580.49
2299.26	8581.36
2302.1	8585.9
2304.93	8542.85
2307.76	8493.92
2310.6	8473.72
2313.43	8501.38
2316.25	8403.04
2319.08	8378.51
2321.91	8419.95
2324.74	8552.57
2327.56	8655.92
2330.39	8395.27
2333.21	8294.09
2336.03	8260.52
2338.85	8258.96
2341.67	8228.51
2344.49	8221.95
2347.31	8191.74
2350.13	8181.54
2352.94	8148.26
2355.76	8100.8
2358.57	8086.19
2361.39	8104.97
2364.2	8042.72
2367.01	8024.87
2369.82	8021.04
2372.63	7982.49
2375.44	7973.81
2378.24	7918.47
2381.05	7932.74
2383.85	7952.79
2386.66	7938.5
2389.46	7908.33
2392.26	7915.79
2395.06	7868.56
2397.86	7833.68
2400.66	7847.79
2403.46	7832.74
2406.26	7826.05
2409.05	7795.16
2411.85	7740.65
2414.64	7742.96
2417.43	7715.81
2420.23	7727.05
2423.02	7703.95
2425.81	7686.92
2428.6	7671.73
2431.38	7674.62
2434.17	7627.66
2436.96	7634.93
2439.74	7618.43
2442.53	7585.75
2445.31	7593.59
2448.09	7549.83
2450.87	7550.47
2453.65	7505.59
2456.43	7505.29
2459.21	7516.58
2461.98	7486.05
2464.76	7476.91
2467.53	7467.21
2470.31	7404.84
2473.08	7420.45
2475.85	7408.46
2478.63	7391.2
2481.39	7360.22
2484.16	7371.59
2486.93	7351.15
2489.7	7383.11
2492.46	7318.93
2495.23	7345.68
2497.99	7322.97
2500.76	7298.28
2503.52	7252.63
2506.28	7240.34
2509.04	7222.28
2511.8	7229.4
2514.56	7161.14
2517.31	7172.33
2520.07	7185.26
2522.82	7172.25
2525.58	7154.19
2528.33	7162.54
2531.09	7133.36
2533.84	7076.63
2536.59	7093.21
2539.34	7112.44
2542.08	7039.6
2544.83	7052.58
2547.58	7016.02
2550.32	6997.66
2553.07	7000.01
2555.81	6988.38
2558.55	6970.77
2561.29	6970.52
2564.03	6948.81
2566.77	6938.09
2569.51	6926.12
2572.25	6909.58
2574.99	6905.4
2577.72	6876.43
2580.46	6879.81
2583.19	6893.43
2585.92	6895.31
2588.65	6856.68
2591.38	6907.41
2594.11	6866.76
2596.84	6821.63
2599.57	6832.62
2602.3	6827.28
2605.02	6833.5
2607.75	6826.89
2610.47	6808.48
2613.19	6821.46
2615.92	6756.92
2618.64	6758.82
2621.36	6751.41
2624.08	6729.52
2626.8	6722.38
2629.51	6707.47
2632.23	6738.44
2634.94	6706.23
2637.66	6683.23
2640.37	6694.96
2643.08	6662.25
2645.79	6697.9
2648.5	6709.9
2651.21	6670.77
2653.92	6679.33
2656.63	6659.77
2659.33	6662.37
2662.04	6684.37
2664.75	6680.7
2667.45	6677.01
2670.15	6667.68
2672.85	6660.35
2675.55	6639.47
2678.25	6621.84
2680.95	6625.27
2683.65	6620.07
2686.35	6568.09
2689.04	6568.39
2691.74	6553.6
2694.43	6563.84
2697.13	6558.56
2699.82	6548.08
2702.51	6587.86
2705.2	6583.09
2707.89	6620.98
2710.58	6596.27
2713.26	6618.09
2715.95	6662.04
2718.64	6623.76
2721.32	6626.55
2724	6577.91
2726.69	6635.83
2729.37	6595.64
2732.05	6558.81
2734.73	6477.7
2737.41	6431.71
2740.09	6403.38
2742.76	6357.31
2745.44	6370.85
2748.11	6326.4
2750.79	6277.62
2753.46	6316.02
2756.13	6246.01
2758.81	6230.09
2761.47	6195.77
2764.14	6175.47
2766.81	6208.48
2769.48	6173.53
2772.15	6161.11
2774.81	6204.8
2777.48	6168.65
2780.14	6151.83
2782.8	6147.15
2785.47	6138.28
2788.13	6100.27
2790.79	6079.49
2793.44	6101.86
2796.1	6135.04
2798.76	6102.63
2801.42	6117.01
2804.07	6099
2806.73	6085.82
2809.38	6115.26
2812.03	6148.22
2814.68	6195.12
2817.33	6216.11
2819.98	6203.94
2822.63	6275.26
2825.28	6322.85
2827.93	6430.98
2830.57	6595.89
2833.22	6822.47
2835.86	7168.85
2838.51	7726.13
2841.15	8500.39
2843.79	9478.49
2846.43	10309.8
2849.07	10636.6
2851.71	10526
2854.35	10287.6
2856.98	9950.44
2859.62	9827.1
2862.25	9629.7
2864.89	9544.12
2867.52	9673.21
2870.15	9935.77
2872.78	10061.7
2875.41	10278.3
2878.04	10477.1
2880.67	10606.9
2883.3	10587.9
2885.92	10534.1
2888.55	10616.1
2891.18	10607.6
2893.8	10708
2896.42	10530.6
2899.04	10573.3
2901.67	10471.5
2904.29	10463.7
2906.9	10378.3
2909.52	10393.8
2912.14	10414
2914.76	10357.6
2917.37	10289.9
2919.99	10312.4
2922.6	10332.3
2925.21	10284
2927.82	10328
2930.44	10356.7
2933.05	10224.5
2935.65	10080.4
2938.26	9814.55
2940.87	9406.39
2943.48	8903.89
2946.08	8539.03
2948.69	8302.34
2951.29	8197.18
2953.89	8091.1
2956.49	8011.2
2959.1	7854.79
2961.7	7754.13
2964.29	7600.63
2966.89	7411.88
2969.49	7251.58
2972.09	7085.81
2974.68	6969.98
2977.28	6840.65
2979.87	6734.54
2982.46	6654.65
2985.05	6567.96
2987.65	6471.99
2990.24	6392.4
2992.82	6395.22
2995.41	6394.09
2998	6371.04
3000.59	6340.84
3003.17	6339.08
3005.76	6330.65
3008.34	6298.18
3010.92	6187.6
3013.5	6140.14
3016.09	6079.97
3018.67	6057.02
3021.25	5994.1
3023.82	5933.16
3026.4	5955.12
3028.98	5966.52
3031.55	5931.85
3034.13	5900.58
3036.7	5927.27
3039.28	5928.21
3041.85	5958.37
3044.42	5946.87
3046.99	5952.32
3049.56	5981.58
3052.13	5975.8
3054.69	6051.13
3057.26	5990.83
3059.83	6042.69
3062.39	6093.61
3064.95	6083.12
3067.52	6124.34
3070.08	6115.15
3072.64	6093.06
3075.2	6136.31
3077.76	6118.59
3080.32	6177.78
3082.88	6200.12
3085.44	6210.22
3087.99	6237.45
3090.55	6216.11
3093.1	6284.13
3095.65	6302.37
3098.21	6335.54
3100.76	6364.93
3103.31	6389.83
3105.86	6431.71
3108.41	6472.39
3110.96	6517.05
3113.5	6544.87
3116.05	6603.29
3118.59	6679.3
3121.14	6730.12
3123.68	6737.38
3126.23	6761.33
3128.77	6834.92
3131.31	6875.53
3133.85	6947.17
3136.39	6984.82
3138.93	7050.03
3141.46	7057.23
3144	7140.52
3146.54	7159.06
3149.07	7234.38
3151.6	7277.42
3154.14	7324
3156.67	7393.16
3159.2	7425.6
3161.73	7483.94
3164.26	7504.14
3166.79	7543.63
3169.32	7583.16
3171.84	7592.44
3174.37	7562.31
3176.9	7573.7
3179.42	7580.05
3181.94	7560.24
3184.47	7599.05
3186.99	7592.57
3189.51	7678.92
3192.03	7608.59
3194.55	7632.74
3197.07	7622.38
3199.58	7632.6
3202.1	7621.73
3204.62	7671.22
3207.13	7639.24
3209.65	7626.91
3212.16	7601.34
3214.67	7584.43
3217.18	7565.22
3219.69	7586.33
3222.2	7580.56
3224.71	7524.15
3227.22	7527.18
3229.73	7532.23
3232.23	7509.14
3234.74	7478.13
3237.24	7472.44
3239.75	7428.82
3242.25	7442.74
3244.75	7387.7
3247.25	7371.21
3249.75	7349.74
3252.25	7311.75
3254.75	7308.88
3257.25	7257.19
3259.74	7253.64
3262.24	7212.44
3264.73	7191.59
3267.23	7198.49
3269.72	7148.37
3272.21	7150.12
3274.7	7146.3
3277.2	7112.54
3279.69	7088.56
3282.17	7035.75
3284.66	7037.18
3287.15	7042.53
3289.64	7019.7
3292.12	6976.68
3293.56	7004.67
3296.05	6981.8
3298.55	6911.79
3301.04	6946.23
3303.54	6906.87
3306.03	6934.03
3308.52	6909.38
3311.01	6932
3313.5	6868.85
3315.99	6892.84
3318.48	6870.86
3320.97	6877.85
3323.45	6846.54
3325.94	6862.63
3328.42	6847.66
3330.91	6794.27
3333.39	6815.96
3335.87	6848.92
3338.36	6805.98
3340.84	6754.42
3343.32	6784.3
3345.8	6824.22
3348.27	6782.11
3350.75	6779.29
3353.23	6757.61
3355.7	6777.09
3358.18	6749.86
3360.65	6751.75
3363.13	6752.36
3365.6	6738.02
3368.07	6700.97
3370.54	6753.3
3373.01	6747.61
3375.48	6737.87
3377.95	6722.06
3380.42	6686.8
3382.88	6673.94
3385.35	6703.16
3387.81	6652.11
3390.28	6628.69
3392.74	6636.87
3395.2	6662.86
3397.67	6638.63
3400.13	6632.93
3402.58	6637.14
3405.05	6578.96
3407.5	6592.23
3409.96	6570.36
3412.42	6546.37
3414.87	6528.94
3417.33	6510.24
3419.78	6486.06
3422.23	6481.02
3424.69	6469.71
3427.14	6437.61
3429.59	6384.81
3432.04	6342.84
3434.49	6357.06
3436.94	6355.54
3439.39	6295.05
3441.83	6260.56
3444.28	6267.43
3446.72	6207.87
3449.17	6213.19
3451.61	6144.66
3454.05	6139.02
3456.5	6110.17
3458.94	6010.77
3461.38	6027.8
3463.81	5991.11
3466.25	5956.21
3468.69	5918.61
3471.13	5863.56
3473.56	5823.59
3476	5794.25
3478.43	5766.55
3480.87	5692.04
3483.3	5625.38
3485.73	5599.8
3488.16	5583.23
3490.59	5525.59
3493.02	5467.67
3495.45	5427.6
3497.88	5376.62
3499.09	5346.99