File: src/Milk_AI/Amul toned milk RT after 24h 532nm 50% 600g 50xL 10s 10times 400-3500cm-1 200hole.txt
#Acq. time (s)=	10
#Accumulations=	10
#Range (cm-¹)=	400...3500
#Windows=	3
#Auto scanning=	Off
#Autofocus=	Off
#AutoExposure=	Off
#Spike filter=	Multiple accum.
#Delay time (s)=	0
#Binning=	1
#Readout mode=	Signal
#DeNoise=	Off
#ICS correction=	On
#Dark correction=	Off
#Inst. Process=	Off
#Detector Gain=	Best Dynamic Range
#Detector ADC=	45 kHz
#Detector temperature (°C)=	-60.1
#Instrument=	LabRAM HR Evol
#Detector=	Syncerity OE
#Objective=	x50_VIS_LWD
#Grating=	600 (500nm)
#ND Filter=	50%
#Laser=	532nm_Edge
#Hole=	199.981
#Range=	Visible
#E-Cal_Neon=	0
#StageXY=	75x50mm Scan+
#StageZ=	Z motor
#X (µm)=	0
#Y (µm)=	0
#Z (µm)=	693.5
#Spectral res.(cm-¹)=	12.8
#Full time(mm:ss)=	5:19
#AC=	Calibrated 2025-07-01 10:31
#Project=
#Sample=
#Site=
#Title=	D_1
#Remark=
#Date=	01.07.2025 17:11 (India Standard Time)
#Acquired=	01.07.2025 17:11:28 (India Standard Time)
#AxisType[0]=Intens
#AxisUnit[0]=Cnt
#AxisType[1]=Spectr
#AxisUnit[1]=1/cm
400.083	46495.8
403.63	46163.7
407.176	46338.3
410.72	46323
414.263	46266.1
417.805	46524
421.345	46510.5
424.884	46493.4
428.421	46600.2
431.955	46688.1
435.49	46750.9
439.023	46710.4
442.555	46576.3
446.084	46662.3
449.613	46653.7
453.141	46760.4
456.666	46726.7
460.191	46781.7
463.715	46721.8
467.235	46838.1
470.756	46753.8
474.274	46897.2
477.793	46946
481.308	47034.2
484.823	47104.9
488.336	46970.6
491.847	47109.3
495.358	47256.4
498.867	47410.5
502.374	47446.8
505.881	47549
509.386	47635.5
512.888	47700.5
516.39	47618.2
519.89	47587.4
523.391	47728.8
526.889	47713.1
530.385	47655.9
533.88	47458.7
537.373	47567.3
540.866	47610.8
544.357	47705.2
547.846	47663.6
551.334	47576.8
554.821	47781
558.307	47794.6
561.789	47773.4
565.272	47800.1
568.753	47917.9
572.233	48036.5
575.712	47961.9
579.188	48176.3
582.664	48064.1
586.139	48037.3
589.611	48169.6
593.083	48200.8
596.554	48199.2
600.021	48208.6
603.49	48269.2
606.955	48196.3
610.42	48260.3
613.882	48286.5
617.345	48260.1
620.805	48155.1
624.263	48090.5
627.722	48006.6
631.178	48087
634.633	48141.8
638.088	48309.1
641.539	48446.5
644.99	48076.1
648.439	48106
651.887	48333.9
655.335	48286.6
658.781	48393.4
662.225	48289.5
665.667	48303.9
669.108	48385.1
672.548	48430.1
675.987	48286.6
679.424	48422.5
682.86	48532.8
686.293	48525
689.727	48480.7
693.159	48486.2
696.59	48630
700.019	48622.4
703.448	48597.4
706.872	48586.1
710.298	48514.9
713.723	48472.4
717.144	48595.4
720.565	48631.5
723.984	48593.9
727.403	48669.5
730.821	48751.1
734.235	48576.1
737.651	48648.3
741.063	48566.9
744.474	48742.5
747.885	48677
751.293	48742.7
754.702	48840.5
758.108	48969.3
761.512	48990.5
764.915	49093.1
768.319	49108.9
771.719	49165.7
775.118	49171.1
778.516	49017.6
781.913	49134.6
785.308	49294.2
788.702	49143.1
792.095	49085.7
795.486	48983.5
798.876	49160.4
802.265	49223.2
805.653	49205.8
809.039	49143.2
812.424	48949.7
815.808	49032.6
819.191	49081.6
822.572	49278.2
825.95	49420.9
829.329	49224.3
832.706	49344.6
836.08	49485.4
839.455	49425.3
842.829	49495
846.199	49604.3
849.57	49661.3
852.938	49764.1
856.307	49794
859.672	49843.2
863.038	49827.8
866.401	49797.6
869.765	49802.2
873.125	49782.7
876.484	49941.8
879.844	49715.1
883.2	49526.4
886.555	49633.3
889.909	49623.7
893.262	49502
896.616	49338.5
899.966	49296.7
903.315	49300.3
906.663	49223.7
910.009	49250.1
913.354	49363.8
916.698	49227.2
920.041	49217.6
923.383	49129.2
926.723	49010.5
930.062	49049.9
933.399	48859.9
936.734	48945
940.069	49154.6
943.403	49194.7
946.736	49169.9
950.065	49014
953.396	49140.7
956.725	49245.5
960.051	49313.1
963.377	49262
966.7	49229.5
970.025	49245.7
973.345	49207
976.667	49133.1
979.985	49220.3
983.304	49263.1
986.62	49424.1
989.935	49313.6
993.25	49501.5
996.563	49795.5
999.874	50046.9
1003.19	49830.3
1006.49	49602.9
1009.8	49334.5
1013.11	49409.9
1016.41	49479.1
1019.72	49311.4
1023.02	49197.5
1026.32	49098.2
1029.62	49025.9
1032.92	49148.6
1036.22	49014.6
1039.51	49012.2
1042.81	49050.5
1046.1	48983.6
1049.39	49188.8
1052.68	49224.5
1055.97	49402.8
1059.26	49500.9
1062.55	49536.8
1065.83	49358.3
1069.12	49408.4
1072.4	49495.4
1075.68	49540.3
1078.97	49474.5
1082.24	49316.1
1085.52	49261.3
1088.8	49270.5
1092.08	48959.1
1095.35	48901.1
1098.62	48744.4
1101.9	48743.8
1105.17	48627.6
1108.44	48723.3
1111.7	48869.3
1114.97	48809.1
1118.23	48954.6
1121.5	49056.2
1124.76	48972.8
1128.03	48651.1
1131.29	48528.9
1134.54	48535.9
1137.8	48483.7
1141.06	48507.8
1144.31	48892.4
1147.57	49296.2
1150.82	49924.6
1154.07	50004.6
1157.32	49432.9
1160.57	48745.7
1163.82	48228.6
1167.07	48186.2
1170.31	48168.2
1173.56	48019.5
1176.8	47957.7
1180.04	48009.6
1183.28	47943.2
1186.52	48020.2
1189.76	47983.3
1192.99	47812.5
1196.23	47883.1
1199.46	47707.7
1202.7	47726
1205.93	47683.5
1209.16	47721.1
1212.39	47698
1215.62	47560.5
1218.84	47462.8
1222.07	47456.2
1225.29	47554.1
1228.52	47694.1
1231.74	47514
1234.96	47478.1
1238.18	47547.8
1241.4	47737.6
1244.61	47869.2
1247.83	47774.2
1251.04	47822.8
1254.25	47870.1
1257.47	47885
1260.68	47826.3
1263.89	47853.5
1267.09	47882.8
1270.3	47619
1273.51	47585.7
1276.71	47554.1
1279.91	47490.5
1283.12	47440.8
1286.32	47609.1
1289.52	47868.7
1292.72	48072.5
1295.91	48126.9
1299.11	48034.2
1302.3	48099.8
1305.5	47864
1308.69	47651.3
1311.88	47481.3
1315.07	47085.3
1318.26	47102.6
1321.44	46876.7
1324.63	46942.2
1327.82	46873.3
1331	46819.2
1334.18	46811.7
1337.36	46673.3
1340.54	46841.4
1343.72	46573.5
1346.9	46503.3
1350.07	46495.8
1353.25	46431.1
1356.42	46203.3
1359.6	46054.9
1362.77	46227.2
1365.94	46248.6
1369.11	46076.2
1372.28	46045.5
1375.44	45679.4
1378.61	45615.2
1381.77	45508.9
1384.93	45469.6
1388.1	45583.8
1391.26	45461.9
1394.41	45685.1
1397.57	45460.9
1400.73	45531.3
1403.89	45565.9
1407.04	45539.3
1410.19	45666.4
1413.35	45786.3
1416.5	45773.8
1419.65	45926.1
1422.8	45910
1425.94	46349.1
1429.09	46690.2
1432.23	47421.4
1435.38	47699.8
1438.52	47700.3
1441.66	47453.6
1444.8	47371.4
1447.94	47309
1451.08	46982.7
1454.22	46878.4
1457.35	46635.3
1460.48	46322
1463.62	46121.2
1466.75	45600.3
1469.88	45324
1473.01	44973.3
1476.14	44744.7
1479.26	44525.4
1482.39	44385.7
1485.51	44351.4
1488.64	44375.9
1491.76	44351.9
1494.88	44500.3
1498	44597.3
1501.12	44603.4
1504.24	44716.2
1507.35	45029
1510.47	45260.5
1513.58	45611.9
1516.69	45928.2
1519.81	45768.2
1522.92	45615.6
1526.03	45027.5
1529.13	44522.4
1532.24	44119.6
1535.35	43851.1
1538.45	43848.5
1541.55	43872.1
1544.66	43674
1547.76	43555.1
1550.86	43600.3
1553.96	43457.6
1557.05	43289.3
1560.15	43274
1563.24	43444.1
1566.34	43370
1569.43	43402.2
1572.52	43354.9
1575.61	43157.4
1578.7	43333.9
1581.79	43364.3
1584.88	43115.1
1587.96	43192.7
1591.05	43127.6
1594.13	43131
1597.21	43062.1
1600.3	43243.5
1603.37	43119.9
1606.45	42924.1
1609.53	42885.4
1612.61	42733.5
1615.68	42754
1618.76	42708.7
1621.83	42627.8
1624.9	42634.4
1627.97	42732.1
1631.04	42762.9
1634.11	42740.9
1637.18	42647.2
1640.24	42897.3
1643.31	42922.2
1646.37	43293
1649.44	43529
1652.5	43519.7
1655.56	43211.7
1658.62	42884.2
1661.67	42665.7
1664.73	42541.5
1667.79	42450.7
1670.84	42350.9
1673.89	42224.2
1676.95	42038.2
1680	41733.7
1683.05	41718.1
1686.1	41497.2
1689.14	41391.7
1692.19	41353.4
1695.23	41265.2
1698.28	41135.1
1701.32	40943.1
1704.36	40874.9
1707.4	40910.3
1710.44	40780.8
1713.48	40721
1716.52	40647.5
1719.56	40545.8
1722.59	40645.6
1725.63	40626.3
1728.66	40553.9
1731.69	40740.5
1734.72	40766.5
1737.75	40780.2
1740.78	40746.9
1743.8	40716.7
1746.83	40675.7
1749.86	40575
1752.88	40345.4
1755.9	40159.5
1758.92	40135
1761.94	40061.1
1764.96	39807
1767.98	39867.8
1771	39748.2
1774.01	39799.9
1777.03	39787.8
1780.04	39716.2
1783.05	39602
1786.06	39567
1789.07	39711.8
1792.08	39564.4
1795.09	39509.2
1798.1	39450.9
1801.1	39334.3
1804.11	39384.3
1807.11	39244.6
1810.11	39164.7
1813.11	39284.2
1816.11	39160.9
1819.11	39029.6
1822.11	38989.7
1825.11	38945.1
1828.1	38988.2
1831.1	38885.8
1834.09	38845.3
1837.08	38895.6
1840.07	38762.1
1843.06	38793.1
1846.05	38678.1
1849.04	38696.9
1852.02	38560
1855.01	38553.2
1857.99	38421.1
1860.98	38451.4
1863.96	38400.7
1866.94	38399.7
1869.92	38381
1872.9	38255.8
1875.88	38369.6
1878.85	38181.9
1881.83	38145.3
1884.8	37980.6
1887.78	37960.6
1890.75	37967.3
1893.72	37936.9
1896.69	37716.3
1899.66	37688.1
1902.63	37509.8
1905.59	37213.5
1908.56	37065.6
1911.52	36855.8
1914.49	36625
1917.45	36381.9
1920.41	36190.6
1923.37	36040.9
1926.33	35856.8
1929.29	35688.3
1932.24	35385.6
1935.2	35270.2
1938.15	35036.6
1941.1	34813.3
1944.06	34723.8
1947.01	34473.4
1949.96	34270.9
1952.91	34005.4
1955.86	33810.9
1958.8	33608.6
1961.75	33451.9
1964.69	33331.4
1967.64	33080
1970.58	32892.6
1973.52	32696.1
1976.46	32541.5
1979.4	32441.7
1982.34	32280.9
1985.27	32076.3
1988.21	31940.9
1991.14	31695.3
1994.08	31467.4
1997.01	31334.8
1999.94	31068.8
2002.87	30984
2005.8	30757.3
2008.73	30753.8
2011.66	30585.8
2014.58	30405.3
2017.51	30246.4
2020.43	30090.7
2023.36	29867.9
2026.28	29710
2029.2	29618.1
2032.12	29446.3
2035.04	29318
2037.95	29172.5
2040.87	29061.1
2043.78	28902.3
2045.76	28847.3
2048.69	28806.2
2051.61	28758.4
2054.54	28704.5
2057.46	28656.6
2060.38	28613.6
2063.3	28579.3
2066.22	28557
2069.14	28530.3
2072.06	28404.6
2074.98	28417.2
2077.89	28343.4
2080.81	28312.2
2083.72	28222.5
2086.63	28189.2
2089.55	28155.1
2092.46	28115.4
2095.37	28117.8
2098.28	27992.7
2101.18	27959
2104.09	27915.8
2106.99	27818.3
2109.9	27876.2
2112.8	27800.8
2115.71	27659.7
2118.61	27770
2121.51	27721.7
2124.4	27639.2
2127.3	27613
2130.2	27549.7
2133.09	27545
2135.99	27518.5
2138.88	27552.3
2141.78	27498.2
2144.67	27470.5
2147.56	27336.5
2150.45	27337.2
2153.34	27302
2156.22	27313.9
2159.11	27248.6
2162	27262
2164.88	27206.6
2167.76	27219.2
2170.64	27224.4
2173.53	27192.7
2176.41	27079.6
2179.29	27067.1
2182.16	27005.8
2185.04	26934.1
2187.92	26882
2190.79	26864.9
2193.66	26764.3
2196.54	26791.1
2199.41	26739.6
2202.28	26684.3
2205.15	26722.8
2208.02	26634.6
2210.88	26515.3
2213.75	26458.9
2216.62	26368.1
2219.48	26365.8
2222.34	26281.4
2225.21	26242.7
2228.07	26193.2
2230.93	26160.2
2233.79	26132.8
2236.65	26028
2239.5	25970.8
2242.36	25957.5
2245.21	25943.6
2248.07	25788.3
2250.92	25782.5
2253.77	25734
2256.62	25672.8
2259.47	25511.9
2262.32	25441.3
2265.17	25432.7
2268.02	25282.1
2270.86	25226.2
2273.71	25160
2276.55	25139.6
2279.39	25090.3
2282.24	24977.4
2285.08	24933.3
2287.92	24837.1
2290.75	24847.9
2293.59	24770.4
2296.43	24802.9
2299.26	24776.9
2302.1	24658.7
2304.93	24516.4
2307.76	24521.3
2310.6	24485.4
2313.43	24478.4
2316.25	24402.9
2319.08	24339.8
2321.91	24215.3
2324.74	24413.3
2327.56	24463.5
2330.39	24068.4
2333.21	23979.2
2336.03	23962.4
2338.85	23882.9
2341.67	23899.8
2344.49	23797.4
2347.31	23743.3
2350.13	23672.1
2352.94	23648.9
2355.76	23590.2
2358.57	23460
2361.39	23436.5
2364.2	23454.4
2367.01	23412.8
2369.82	23282
2372.63	23181.4
2375.44	23235.8
2378.24	23126.4
2381.05	23157.5
2383.85	23083.3
2386.66	23066.8
2389.46	23001.4
2392.26	22950.5
2395.06	22869.8
2397.86	22856.1
2400.66	22866.7
2403.46	22775.2
2406.26	22702.3
2409.05	22648.7
2411.85	22561.8
2414.64	22593.8
2417.43	22544.4
2420.23	22469.7
2423.02	22448.7
2425.81	22387.5
2428.6	22322.9
2431.38	22340.2
2434.17	22319.4
2436.96	22154.1
2439.74	22224.4
2442.53	22137.5
2445.31	22076.8
2448.09	22085.9
2450.87	22021.3
2453.65	21981.8
2456.43	21994.1
2459.21	21851.9
2461.98	21871.6
2464.76	21783.1
2467.53	21782.4
2470.31	21706.7
2473.08	21681.5
2475.85	21661.1
2478.63	21599.5
2481.39	21522.7
2484.16	21486
2486.93	21439.2
2489.7	21375.2
2492.46	21396.1
2495.23	21339.4
2497.99	21305.2
2500.76	21261.4
2503.52	21178.5
2506.28	21170.8
2509.04	21041.5
2511.8	21085.8
2514.56	21038.4
2517.31	20999
2520.07	20956.6
2522.82	20882.5
2525.58	20934.9
2528.33	20900.4
2531.09	20760.4
2533.84	20815.2
2536.59	20740.4
2539.34	20803.2
2542.08	20589.7
2544.83	20607.3
2547.58	20607.6
2550.32	20464.2
2553.07	20401.6
2555.81	20352.8
2558.55	20380.1
2561.29	20314.6
2564.03	20310
2566.77	20229.9
2569.51	20164.6
2572.25	20140.4
2574.99	20150.8
2577.72	20133.2
2580.46	20129.4
2583.19	20176.7
2585.92	20111.2
2588.65	20057.9
2591.38	19979.8
2594.11	20035.4
2596.84	19920.5
2599.57	19893.7
2602.3	19805.3
2605.02	19862.9
2607.75	19842.4
2610.47	19826.5
2613.19	19768.3
2615.92	19683.7
2618.64	19603.3
2621.36	19629.3
2624.08	19582.2
2626.8	19583.8
2629.51	19538
2632.23	19498.6
2634.94	19439.1
2637.66	19430.2
2640.37	19370.2
2643.08	19361.8
2645.79	19353.9
2648.5	19313.7
2651.21	19296
2653.92	19236.9
2656.63	19204.5
2659.33	19188.5
2662.04	19176.2
2664.75	19121.4
2667.45	19038.9
2670.15	19044.7
2672.85	18991.7
2675.55	19024.8
2678.25	18923.9
2680.95	18918.1
2683.65	18854.7
2686.35	18865.9
2689.04	18864.3
2691.74	18718.8
2694.43	18750.3
2697.13	18714
2699.82	18745.9
2702.51	18693.1
2705.2	18655.3
2707.89	18622.6
2710.58	18638.9
2713.26	18588.8
2715.95	18530
2718.64	18541.2
2721.32	18476.8
2724	18400.4
2726.69	18381.2
2729.37	18339.2
2732.05	18306.5
2734.73	18222.1
2737.41	18199.4
2740.09	18129
2742.76	18104.5
2745.44	18054.9
2748.11	17959.1
2750.79	17889.8
2753.46	17887.8
2756.13	17894.8
2758.81	17859
2761.47	17790.5
2764.14	17763.6
2766.81	17777.6
2769.48	17694.1
2772.15	17653.3
2774.81	17558
2777.48	17581.5
2780.14	17523
2782.8	17491.4
2785.47	17368
2788.13	17337.5
2790.79	17330.8
2793.44	17359.1
2796.1	17326.1
2798.76	17332.7
2801.42	17289.4
2804.07	17205.9
2806.73	17176.9
2809.38	17175.7
2812.03	17156.5
2814.68	17110.6
2817.33	17062
2819.98	17081.8
2822.63	17112.9
2825.28	17074.2
2827.93	17146.9
2830.57	17146.8
2833.22	17211.5
2835.86	17376.9
2838.51	17619.7
2841.15	18052.6
2843.79	18486.9
2846.43	18848.9
2849.07	18980.1
2851.71	18926.8
2854.35	18814.7
2856.98	18690.7
2859.62	18571.8
2862.25	18478.2
2864.89	18428.6
2867.52	18461.4
2870.15	18555.5
2872.78	18628
2875.41	18671.3
2878.04	18838.5
2880.67	18798.6
2883.3	18752.4
2885.92	18808.3
2888.55	18766.2
2891.18	18815.5
2893.8	18786.1
2896.42	18680.8
2899.04	18687.1
2901.67	18548.9
2904.29	18518.6
2906.9	18478.7
2909.52	18488.9
2912.14	18449.8
2914.76	18407.1
2917.37	18341.6
2919.99	18369.3
2922.6	18312.3
2925.21	18280.6
2927.82	18228
2930.44	18186.4
2933.05	18211.4
2935.65	18032.2
2938.26	17900.1
2940.87	17515.3
2943.48	17277
2946.08	17066.5
2948.69	16952.5
2951.29	16819.1
2953.89	16788.4
2956.49	16716.7
2959.1	16598.1
2961.7	16547.4
2964.29	16408.1
2966.89	16344.7
2969.49	16244.7
2972.09	16173.8
2974.68	16005.4
2977.28	16005.7
2979.87	15984.4
2982.46	15823.6
2985.05	15765.5
2987.65	15730.5
2990.24	15671.3
2992.82	15658.2
2995.41	15536.4
2998	15565.2
3000.59	15493.5
3003.17	15469
3005.76	15498.4
3008.34	15397.3
3010.92	15362.9
3013.5	15247.1
3016.09	15264.2
3018.67	15240
3021.25	15212.5
3023.82	15188.9
3026.4	15198
3028.98	15093.9
3031.55	15178.2
3034.13	15110
3036.7	15140.8
3039.28	15140.9
3041.85	15142.3
3044.42	15177.8
3046.99	15130.3
3049.56	15198.8
3052.13	15169.6
3054.69	15177.9
3057.26	15137.8
3059.83	15210.8
3062.39	15191.7
3064.95	15205
3067.52	15230.7
3070.08	15147.1
3072.64	15148.8
3075.2	15156.3
3077.76	15231.4
3080.32	15216.7
3082.88	15228.7
3085.44	15178.9
3087.99	15242.6
3090.55	15250.2
3093.1	15261.9
3095.65	15254.5
3098.21	15279.3
3100.76	15224
3103.31	15300.5
3105.86	15331.1
3108.41	15416.5
3110.96	15453
3113.5	15456.9
3116.05	15506.7
3118.59	15507
3121.14	15567.2
3123.68	15562.3
3126.23	15632.4
3128.77	15630
3131.31	15695.5
3133.85	15731.4
3136.39	15823.7
3138.93	15801.5
3141.46	15847.9
3144	15885
3146.54	15904.3
3149.07	15956.6
3151.6	15998.8
3154.14	16019.9
3156.67	16130.5
3159.2	16128.5
3161.73	16072.2
3164.26	16162.4
3166.79	16203
3169.32	16137.9
3171.84	16177.4
3174.37	16143
3176.9	16144
3179.42	16108.4
3181.94	16187.7
3184.47	16148
3186.99	16124.9
3189.51	16174
3192.03	16099.1
3194.55	16122.8
3197.07	16112.6
3199.58	16115.3
3202.1	16099.6
3204.62	16101.8
3207.13	16126.3
3209.65	16042.3
3212.16	16039.9
3214.67	15984.8
3217.18	15968.1
3219.69	15934.8
3222.2	15944.8
3224.71	15940.7
3227.22	15913.4
3229.73	15893.6
3232.23	15854.6
3234.74	15815.5
3237.24	15793.1
3239.75	15703.5
3242.25	15711.8
3244.75	15660
3247.25	15675.5
3249.75	15587.6
3252.25	15551.2
3254.75	15506.4
3257.25	15472.3
3259.74	15411.1
3262.24	15364.1
3264.73	15357.8
3267.23	15352.9
3269.72	15319.9
3272.21	15291
3274.7	15233.3
3277.2	15173.3
3279.69	15122.3
3282.17	15111
3284.66	15085.5
3287.15	15039.4
3289.64	14996.4
3292.12	14958.1
3293.56	14939.9
3296.05	14864.1
3298.55	14891.2
3301.04	14770.1
3303.54	14783.1
3306.03	14750.3
3308.52	14724.6
3311.01	14714.2
3313.5	14638.1
3315.99	14574.3
3318.48	14600
3320.97	14560.3
3323.45	14580.8
3325.94	14498.3
3328.42	14522
3330.91	14479.3
3333.39	14443.6
3335.87	14426.9
3338.36	14359
3340.84	14300.7
3343.32	14278.5
3345.8	14268.6
3348.27	14234.3
3350.75	14173.8
3353.23	14181
3355.7	14173.6
3358.18	14126.1
3360.65	14046.1
3363.13	14076.9
3365.6	14089.9
3368.07	13989.7
3370.54	13998.4
3373.01	13994.6
3375.48	13975
3377.95	13921.6
3380.42	13882.2
3382.88	13852.2
3385.35	13806.9
3387.81	13759.5
3390.28	13706.6
3392.74	13783.4
3395.2	13728.7
3397.67	13719.4
3400.13	13656.3
3402.58	13664.4
3405.05	13601.7
3407.5	13580.5
3409.96	13491.1
3412.42	13480.6
3414.87	13483.4
3417.33	13451.5
3419.78	13410.9
3422.23	13314
3424.69	13334.1
3427.14	13272
3429.59	13241.9
3432.04	13150.3
3434.49	13121.2
3436.94	13096.4
3439.39	13026.5
3441.83	12974.1
3444.28	12948.2
3446.72	12826.1
3449.17	12819.6
3451.61	12797.7
3454.05	12766.3
3456.5	12744.3
3458.94	12650.3
3461.38	12597.2
3463.81	12566.8
3466.25	12528.2
3468.69	12433
3471.13	12399.7
3473.56	12333.4
3476	12262.8
3478.43	12194.3
3480.87	12160.6
3483.3	12047.1
3485.73	12036.1
3488.16	11955.6
3490.59	11904.6
3493.02	11894.1
3495.45	11770.4
3497.88	11700.1
3499.09	11703