File: src/Milk_AI/Amul toned milk RT 532nm 50% 600g 50xL 10s 10times 400-3500cm-1 200hole.txt
#Acq. time (s)=	10
#Accumulations=	10
#Range (cm-¹)=	400...3500
#Windows=	3
#Auto scanning=	Off
#Autofocus=	Off
#AutoExposure=	Off
#Spike filter=	Multiple accum.
#Delay time (s)=	0
#Binning=	1
#Readout mode=	Signal
#DeNoise=	Off
#ICS correction=	On
#Dark correction=	Off
#Inst. Process=	Off
#Detector Gain=	Best Dynamic Range
#Detector ADC=	45 kHz
#Detector temperature (°C)=	-60.1
#Instrument=	LabRAM HR Evol
#Detector=	Syncerity OE
#Objective=	x50_VIS_LWD
#Grating=	600 (500nm)
#ND Filter=	50%
#Laser=	532nm_Edge
#Hole=	199.981
#Range=	Visible
#E-Cal_Neon=	0
#StageXY=	75x50mm Scan+
#StageZ=	Z motor
#X (µm)=	0
#Y (µm)=	0
#Z (µm)=	847.2
#Spectral res.(cm-¹)=	12.8
#Full time(mm:ss)=	5:20
#AC=	Calibrated 2025-06-30 10:26
#Project=
#Sample=
#Site=
#Title=	D_99
#Remark=
#Date=	30.06.2025 11:50 (India Standard Time)
#Acquired=	30.06.2025 11:50:28 (India Standard Time)
#AxisType[0]=Intens
#AxisUnit[0]=Cnt
#AxisType[1]=Spectr
#AxisUnit[1]=1/cm
400.17	40425.2
403.717	40278.1
407.263	40347.1
410.807	40439.4
414.35	40343.2
417.892	40537.1
421.432	40542.1
424.971	40471.9
428.509	40683
432.045	40607.1
435.58	40708.4
439.111	40580.9
442.643	40556.7
446.174	40568.4
449.701	40537.9
453.229	40731.1
456.756	40567.7
460.279	40579.7
463.803	40482.3
467.326	40539.5
470.845	40546.1
474.365	40519.2
477.882	40599.9
481.399	40555.2
484.913	40593.5
488.425	40601.1
491.938	40563.3
495.448	40715.4
498.956	40779.6
502.465	40753.5
505.971	40803.3
509.475	40922.3
512.981	40941.6
516.482	40953.4
519.983	40994.6
523.482	40928.1
526.979	40956.5
530.476	40875.5
533.971	40803.2
537.464	40772
540.956	40647.2
544.447	40694.2
547.937	40671.7
551.425	40693.5
554.912	40724.9
558.398	40736.3
561.882	40658.9
565.365	40724.6
568.847	40817.2
572.325	40872.9
575.804	40884.8
579.282	40939.5
582.756	40863.9
586.231	40890.2
589.705	41000.9
593.175	41011.4
596.646	41159.3
600.116	41100.7
603.582	41223.5
607.049	41096.9
610.513	41074.1
613.977	41018.9
617.438	40988.1
620.898	40968.9
624.359	40846
627.816	40754.5
631.272	40622.7
634.728	40659.9
638.181	40764.7
641.633	40997.8
645.084	40736.4
648.535	40663.9
651.983	40587.8
655.43	40593
658.875	40668.1
662.319	40641.1
665.762	40596.1
669.203	40651.2
672.643	40663.4
676.082	40759.6
679.519	40680.7
682.955	40768.6
686.39	40812
689.824	40767.7
693.256	40871.5
696.685	40888
700.115	41001.5
703.543	40936.3
706.97	40966.9
710.394	40916.1
713.818	40863.1
717.241	40905.3
720.661	41047.7
724.082	40955.7
727.501	40888.4
730.917	40878.7
734.334	40835.3
737.747	40871
741.161	40836.1
744.572	40807.9
747.982	40826.8
751.392	40831.4
754.799	40983.3
758.205	41090.5
761.611	41035.8
765.014	41149.6
768.416	41188.9
771.816	41290.1
775.218	41218.3
778.616	41290.1
782.012	41264.7
785.408	41342.5
788.802	41169.4
792.195	41210.1
795.586	41190.7
798.977	41206.7
802.365	41422.7
805.753	41399.1
809.14	41365.7
812.525	41206.8
815.907	41426.4
819.289	41533.1
822.671	41622.4
826.051	41916.7
829.43	41824
832.805	41945
836.182	41935.4
839.557	41916.7
842.928	42155.5
846.301	42268.1
849.67	42300.2
853.04	42401.5
856.407	42393.7
859.774	42429.4
863.138	42450.4
866.503	42402.5
869.865	42462.3
873.225	42541.3
876.586	42571.4
879.944	42550.3
883.301	42385.3
886.658	42386.3
890.012	42468.4
893.365	42338
896.717	42180.4
900.067	42042.6
903.416	41888.2
906.766	41716.2
910.112	41637.4
913.458	41774.7
916.802	41615.2
920.145	41619.3
923.484	41667.4
926.825	41418.3
930.164	41349.6
933.501	41408.7
936.838	41344.9
940.173	41460.8
943.505	41452.1
946.838	41368.6
950.17	41306.7
953.5	41392.5
956.827	41338.1
960.155	41419.8
963.48	41576.3
966.805	41333.8
970.128	41314.6
973.45	41247.5
976.77	41144.8
980.091	41359.5
983.408	41335
986.726	41395.7
990.041	41428
993.354	41554.3
996.668	41617.8
999.979	42405
1003.29	42755.4
1006.6	42319.9
1009.91	41835.3
1013.21	41721.9
1016.52	41658.8
1019.82	41562.6
1023.12	41576.2
1026.43	41444
1029.73	41542.7
1033.02	41585
1036.32	41418.2
1039.62	41510.3
1042.91	41454.1
1046.21	41347
1049.5	41368.4
1052.79	41493.8
1056.08	41583.4
1059.37	41781.2
1062.65	42054.7
1065.94	42046.5
1069.23	41880
1072.51	42069.1
1075.79	42225.9
1079.07	42361.6
1082.35	42329.4
1085.63	42191
1088.91	41982.6
1092.18	41819.4
1095.46	41412.4
1098.73	41188.1
1102	40996.7
1105.27	40769.6
1108.54	40765.4
1111.81	40881
1115.08	40960.1
1118.34	41116.5
1121.61	41241.2
1124.87	41286.6
1128.13	41054.7
1131.39	40730.6
1134.65	40356.6
1137.91	40017.5
1141.17	40127.8
1144.42	40199.5
1147.68	40358.5
1150.93	40699.8
1154.18	41031.9
1157.43	41159.8
1160.68	40698.4
1163.93	40196.9
1167.18	39877
1170.42	39905
1173.67	39743.4
1176.91	39680.3
1180.15	39538.5
1183.39	39549.5
1186.63	39574.6
1189.87	39590.5
1193.11	39670.2
1196.34	39579.6
1199.58	39583.2
1202.81	39680.5
1206.04	39641.3
1209.27	39757
1212.5	39694.6
1215.73	39529
1218.95	39534.4
1222.18	39494.1
1225.4	39655.7
1228.63	39738.9
1231.85	39776
1235.07	39793.5
1238.29	39905.6
1241.51	40088.2
1244.72	40269.7
1247.94	40361.1
1251.15	40381.5
1254.37	40434.3
1257.58	40483
1260.79	40534.8
1264	40531.5
1267.21	40489.1
1270.41	40390.6
1273.62	40328.7
1276.82	40288.1
1280.03	40037.7
1283.23	40102.2
1286.43	40121.3
1289.63	40400.6
1292.83	40742.5
1296.03	41288.5
1299.22	41849
1302.42	42025.9
1305.61	41807.4
1308.8	41386.6
1311.99	41000.5
1315.18	40507.5
1318.37	40125.8
1321.56	39864.7
1324.74	39756.3
1327.93	39573.5
1331.11	39482.9
1334.3	39279.3
1337.48	39371.3
1340.66	39319.2
1343.84	39174.2
1347.01	39154.7
1350.19	39046.1
1353.37	38876.7
1356.54	38667.8
1359.71	38594.4
1362.88	38532.7
1366.05	38470.4
1369.22	38385.1
1372.39	38229.9
1375.56	37899.2
1378.72	37927.9
1381.89	37736.6
1385.05	37668.5
1388.21	37728.7
1391.37	37815.5
1394.53	37805
1397.69	37681
1400.85	37640.4
1404	37703.3
1407.16	37710.9
1410.31	37768.7
1413.46	37899.5
1416.61	38213.8
1419.76	38398.5
1422.91	38453
1426.06	38757.4
1429.21	39560.3
1432.35	40962.3
1435.49	42209.4
1438.64	42943.6
1441.78	42891.9
1444.92	42611.8
1448.06	42334.7
1451.2	42015.5
1454.33	41658.7
1457.47	41211.5
1460.6	40847.2
1463.74	40140
1466.87	39580.6
1470	38862.5
1473.13	38162.3
1476.26	37566.3
1479.38	37090.4
1482.51	36864
1485.63	36694.7
1488.76	36482.7
1491.88	36366.8
1495	36391
1498.12	36425.8
1501.24	36298.3
1504.36	36366.1
1507.47	36386.9
1510.59	36512.9
1513.7	36722.5
1516.81	36897.7
1519.93	37019.1
1523.04	37060
1526.15	36856.3
1529.25	36595.2
1532.36	36181.6
1535.47	35967.3
1538.57	35775.4
1541.67	35869.1
1544.78	35684.6
1547.88	35674.1
1550.98	35481
1554.08	35584.8
1557.18	35477.6
1560.27	35437.8
1563.37	35511
1566.46	35503.9
1569.55	35370.3
1572.64	35433.6
1575.74	35327.6
1578.83	35434.9
1581.91	35448.7
1585	35402.6
1588.09	35448.1
1591.17	35344.1
1594.25	35369.6
1597.34	35444.1
1600.42	35602.2
1603.5	35662.4
1606.58	35548.7
1609.65	35630.5
1612.73	35541.6
1615.8	35467.3
1618.88	35473.9
1621.95	35273.4
1625.03	35365.8
1628.1	35338.2
1631.17	35423
1634.23	35502.5
1637.3	35595.6
1640.37	35729.8
1643.43	35881.8
1646.5	36366.7
1649.56	37065.5
1652.62	37617.7
1655.68	37666.3
1658.74	37052.5
1661.8	36448.7
1664.85	36113.8
1667.91	35977.5
1670.96	35867.5
1674.02	35572.3
1677.07	35233.5
1680.12	34898.6
1683.17	34759.4
1686.22	34562.8
1689.27	34351.3
1692.31	34268
1695.36	33956.1
1698.4	33882.6
1701.45	33635.3
1704.49	33546
1707.53	33456.7
1710.57	33320.7
1713.61	33395
1716.65	33208.5
1719.68	33152.8
1722.72	33134
1725.75	33180.8
1728.78	33349.8
1731.82	33321
1734.84	33559.5
1737.87	33516.8
1740.9	33658.2
1743.93	33706.5
1746.96	33734.9
1749.98	33677.9
1753	33540.6
1756.03	33174.2
1759.05	32921
1762.07	32701.6
1765.09	32543.3
1768.11	32476.3
1771.12	32463.8
1774.14	32393.7
1777.15	32356
1780.17	32353.7
1783.18	32260.9
1786.19	32317.5
1789.2	32438.2
1792.21	32179.4
1795.22	32228.8
1798.22	32180.7
1801.23	32093.4
1804.23	32021
1807.24	31994.9
1810.24	32011.3
1813.24	32013
1816.24	31928.7
1819.24	31864.9
1822.24	31814.9
1825.23	31777.9
1828.23	31801.7
1831.22	31809.3
1834.22	31697.4
1837.21	31679.6
1840.2	31690.8
1843.19	31660.3
1846.18	31707.8
1849.17	31631
1852.15	31522.5
1855.14	31425.6
1858.12	31417.2
1861.11	31430.6
1864.09	31353.9
1867.07	31320.8
1870.05	31392.3
1873.03	31190.3
1876.01	31301.7
1878.98	31235.5
1881.96	31211
1884.93	31104.4
1887.91	31042.4
1890.88	31045.8
1893.85	31001.8
1896.82	30904.7
1899.79	30867.3
1902.76	30655.5
1905.72	30479.4
1908.69	30390.9
1911.65	30183.3
1914.62	30098.9
1917.58	29977.9
1920.54	29783.5
1923.5	29650.5
1926.46	29641.2
1929.42	29443.4
1932.37	29345.6
1935.33	29222.3
1938.28	29038.6
1941.24	28873.3
1944.19	28792.6
1947.14	28688.6
1950.09	28540.8
1953.04	28283.2
1955.99	28200
1958.93	27996.1
1961.88	27903.4
1964.82	27823.4
1967.77	27660.8
1970.71	27553.4
1973.65	27448.6
1976.59	27336.8
1979.53	27242.3
1982.47	27122.8
1985.41	27025.6
1988.34	26877.2
1991.28	26709.5
1994.21	26563.9
1997.14	26427.9
2000.07	26289.8
2003.01	26213.8
2005.94	26078.9
2008.86	26013
2011.79	25905
2014.72	25866.2
2017.64	25733.2
2020.57	25591.1
2023.49	25467.2
2026.41	25379.2
2029.33	25303.8
2032.25	25241.5
2035.17	25069.4
2038.09	25095.5
2041	24939.3
2043.92	24814.1
2045.86	24772
2048.79	24816.1
2051.71	24708.4
2054.64	24733.4
2057.56	24656.7
2060.48	24641
2063.4	24597.4
2066.32	24604.3
2069.24	24576.3
2072.16	24548.3
2075.08	24519.2
2077.99	24446.6
2080.91	24386.8
2083.82	24399.7
2086.74	24300
2089.65	24327.8
2092.56	24317
2095.47	24321.5
2098.38	24230.5
2101.29	24123.8
2104.19	24082.6
2107.1	24114.5
2110	24106.7
2112.91	23974.3
2115.81	23954.2
2118.71	23971.1
2121.61	23955.7
2124.51	23892.2
2127.4	23827.5
2130.3	23777.5
2133.2	23777.3
2136.09	23728
2138.99	23755.5
2141.88	23635.3
2144.77	23738.7
2147.66	23680.8
2150.55	23612.3
2153.44	23617.9
2156.33	23589.2
2159.21	23595.5
2162.1	23546.6
2164.98	23528.9
2167.87	23473.5
2170.75	23470
2173.63	23488.6
2176.51	23444.8
2179.39	23424
2182.27	23298.1
2185.14	23338.8
2188.02	23204.9
2190.9	23284.7
2193.77	23225
2196.64	23171.9
2199.51	23120.2
2202.39	23111.3
2205.25	23093.9
2208.12	23044.3
2210.99	23021.4
2213.86	22923.8
2216.72	22848.3
2219.59	22792.5
2222.45	22834.2
2225.31	22711.3
2228.17	22718
2231.03	22717
2233.89	22657.5
2236.75	22605.6
2239.61	22571.1
2242.46	22545.4
2245.32	22502.9
2248.17	22450
2251.03	22425.8
2253.88	22429.3
2256.73	22273.9
2259.58	22120.5
2262.43	22118.5
2265.28	21995.3
2268.12	21951.7
2270.97	21949.1
2273.81	21843.3
2276.66	21834.3
2279.5	21802.7
2282.34	21744.8
2285.18	21679.6
2288.02	21655.3
2290.86	21566.2
2293.7	21556.7
2296.54	21506.1
2299.37	21492.1
2302.21	21426.1
2305.04	21357.7
2307.87	21290.4
2310.7	21316.3
2313.53	21212
2316.36	21202.3
2319.19	21167.4
2322.02	21110.6
2324.85	21080.8
2327.67	21224.8
2330.5	21287.5
2333.32	20961.2
2336.14	20777.8
2338.96	20843.5
2341.78	20812.2
2344.6	20759
2347.42	20694.1
2350.24	20689.5
2353.05	20549.3
2355.87	20512.2
2358.68	20418.9
2361.5	20459.1
2364.31	20386.8
2367.12	20424.6
2369.93	20363.2
2372.74	20211.6
2375.55	20159.1
2378.35	20128.4
2381.16	20176.1
2383.96	20071.4
2386.77	20067.7
2389.57	20085.9
2392.37	20009.6
2395.17	20017.2
2397.97	19953.3
2400.77	19890.8
2403.57	19876.1
2406.37	19818.8
2409.16	19817.3
2411.96	19750.7
2414.75	19714.9
2417.55	19668
2420.34	19624.2
2423.13	19576.4
2425.92	19634.5
2428.71	19559.6
2431.5	19486.5
2434.28	19522.5
2437.07	19359
2439.85	19436.5
2442.64	19316.5
2445.42	19352.1
2448.2	19324.2
2450.98	19253.3
2453.76	19236.3
2456.54	19203.9
2459.32	19207.8
2462.1	19108.7
2464.87	19079.2
2467.65	19065.1
2470.42	18992.6
2473.2	18978.2
2475.97	18945.6
2478.74	18898.7
2481.51	18894.2
2484.28	18879.7
2487.05	18847.1
2489.81	18835.7
2492.58	18825.7
2495.34	18743
2498.11	18744.4
2500.87	18629.5
2503.63	18645.8
2506.39	18567.9
2509.15	18534.5
2511.91	18543.2
2514.67	18440
2517.43	18486.8
2520.19	18353.8
2522.94	18385.1
2525.7	18391.6
2528.45	18375.4
2531.2	18294.5
2533.95	18286.1
2536.7	18273.8
2539.45	18232.1
2542.2	18214
2544.95	18084.7
2547.69	18108.7
2550.44	18053.8
2553.18	17996.5
2555.93	17898
2558.67	17983.9
2561.41	17935.5
2564.15	17890.4
2566.89	17843.7
2569.63	17865.3
2572.36	17813
2575.1	17847.1
2577.84	17778.1
2580.57	17770.9
2583.31	17731.9
2586.04	17726
2588.77	17692.9
2591.5	17771
2594.23	17742.3
2596.96	17686
2599.69	17655
2602.41	17582.7
2605.14	17565.2
2607.86	17544
2610.59	17594.6
2613.31	17561
2616.03	17470.1
2618.75	17398.1
2621.48	17462.5
2624.19	17360.6
2626.91	17355.6
2629.63	17364.2
2632.35	17300.8
2635.06	17279.6
2637.77	17281
2640.49	17265.8
2643.2	17190
2645.91	17211.1
2648.62	17201.5
2651.33	17186.3
2654.04	17155.6
2656.75	17153
2659.45	17024.6
2662.16	17064.8
2664.86	17054.9
2667.57	17047
2670.27	17023.7
2672.97	17001.8
2675.67	16973.9
2678.37	16903.3
2681.07	16880.6
2683.77	16886.6
2686.47	16848.7
2689.16	16847.8
2691.86	16833
2694.55	16838.7
2697.25	16748.1
2699.94	16749.3
2702.63	16790.4
2705.32	16829
2708.01	16793.9
2710.7	16842.9
2713.39	16759.5
2716.07	16776.6
2718.76	16785.7
2721.44	16708.7
2724.12	16724
2726.81	16707.5
2729.49	16736.6
2732.17	16634.9
2734.85	16588.2
2737.53	16523.5
2740.21	16428.5
2742.88	16359.4
2745.56	16367.8
2748.24	16273.7
2750.91	16170.9
2753.58	16207.7
2756.25	16168.9
2758.93	16087.4
2761.6	16065.6
2764.27	16025
2766.93	16022.6
2769.6	15973.2
2772.27	15922
2774.93	15926.7
2777.6	15859.9
2780.26	15803.4
2782.93	15818
2785.59	15740.4
2788.25	15691.4
2790.91	15670.7
2793.57	15710.2
2796.23	15714.6
2798.88	15717.6
2801.54	15651
2804.2	15638.6
2806.85	15574
2809.5	15561
2812.16	15600.8
2814.81	15636.4
2817.46	15568.9
2820.11	15689.3
2822.76	15681.4
2825.4	15708.7
2828.05	15779.8
2830.7	15850.2
2833.34	16038.2
2835.99	16265.4
2838.63	16620.8
2841.27	17174.7
2843.91	18101.2
2846.55	19310.4
2849.19	20391.2
2851.83	20866.8
2854.47	20722.4
2857.11	20404.7
2859.74	20153.2
2862.38	19739.6
2865.01	19686
2867.65	19655.8
2870.28	19797.6
2872.91	20041.4
2875.54	20129.1
2878.17	20246.9
2880.8	20366.7
2883.42	20461.7
2886.05	20644.4
2888.68	20793.5
2891.3	20800.7
2893.93	20839.1
2896.55	20772.5
2899.17	20816.8
2901.79	20711.5
2904.41	20683.8
2907.03	20719.1
2909.65	20644.6
2912.27	20588.7
2914.88	20701.8
2917.5	20621
2920.11	20661.3
2922.73	20604.7
2925.34	20672.8
2927.95	20732.6
2930.56	20801.8
2933.17	20732.6
2935.78	20587.1
2938.39	20326.9
2941	19955.2
2943.6	19276.2
2946.21	18798.4
2948.81	18286.4
2951.42	17923.8
2954.02	17690.7
2956.62	17533.9
2959.22	17344.3
2961.82	17225.5
2964.42	17061.8
2967.02	16833
2969.62	16624.1
2972.21	16431.4
2974.81	16142.5
2977.4	15980
2980	15877.7
2982.59	15700.3
2985.18	15517.3
2987.77	15398.7
2990.36	15250.3
2992.95	15192
2995.54	14977.3
2998.13	14964.8
3000.72	14894.7
3003.3	14841.8
3005.89	14778.7
3008.47	14673.3
3011.05	14608
3013.63	14428.2
3016.22	14321.1
3018.8	14209.7
3021.38	14154.1
3023.95	14125.3
3026.53	14054.9
3029.11	13979.9
3031.68	13922.6
3034.26	13879.1
3036.83	13914.6
3039.4	13848.7
3041.98	13835.4
3044.55	13863.2
3047.12	13891
3049.69	13828.8
3052.26	13862.6
3054.82	13832.3
3057.39	13912.8
3059.96	13924.7
3062.52	13971.5
3065.09	13950.7
3067.65	13913.8
3070.21	13844.5
3072.77	13879.6
3075.33	13866.6
3077.89	13786.7
3080.45	13787.5
3083.01	13772.7
3085.57	13760.7
3088.12	13716.2
3090.68	13789.1
3093.23	13740.4
3095.79	13754.5
3098.34	13785.6
3100.89	13759.1
3103.44	13767.1
3105.99	13809.4
3108.54	13867.3
3111.09	13864.7
3113.63	13887.6
3116.18	13891.6
3118.73	13914.6
3121.27	13959.3
3123.82	13979.3
3126.36	13980.3
3128.9	14067.8
3131.44	14069.8
3133.98	14133.7
3136.52	14193.9
3139.06	14188
3141.6	14185.3
3144.13	14202.8
3146.67	14235.9
3149.2	14280.3
3151.74	14333.8
3154.27	14376.7
3156.8	14420.1
3159.34	14437.7
3161.86	14461.7
3164.4	14457.2
3166.92	14472.3
3169.45	14521.9
3171.98	14484.1
3174.5	14427.9
3177.03	14482.8
3179.56	14430.8
3182.08	14445.5
3184.6	14443.8
3187.12	14425.8
3189.64	14403.9
3192.16	14404.3
3194.68	14370.7
3197.2	14321.5
3199.72	14318
3202.24	14327.2
3204.75	14349.9
3207.27	14336.1
3209.78	14264.3
3212.29	14218.2
3214.81	14161.7
3217.32	14151.5
3219.83	14109.8
3222.34	14123.3
3224.85	14081.3
3227.35	14068.8
3229.86	14062.8
3232.37	14026.5
3234.87	13991.1
3237.38	13947.3
3239.88	13918.8
3242.38	13924.6
3244.89	13840.7
3247.39	13833.6
3249.89	13772
3252.39	13764.1
3254.88	13689.6
3257.38	13645.3
3259.88	13607
3262.37	13552.8
3264.87	13507.8
3267.36	13530.2
3269.86	13487.4
3272.35	13488.2
3274.84	13456.8
3277.33	13373.5
3279.82	13342.2
3282.31	13335.7
3284.8	13274.6
3287.29	13236.9
3289.77	13204
3292.26	13196.3
3294.15	13165.8
3296.64	13138.9
3299.14	13064.4
3301.63	13109.6
3304.12	13057
3306.62	13036.8
3309.11	13001.9
3311.6	13008.3
3314.09	12930.8
3316.58	12947.9
3319.07	12898.1
3321.56	12918.3
3324.04	12907.6
3326.53	12857.4
3329.01	12826.6
3331.5	12825.3
3333.98	12776.8
3336.46	12721.6
3338.94	12734.2
3341.42	12670.1
3343.9	12629.5
3346.38	12611
3348.86	12587
3351.34	12575.2
3353.82	12548.3
3356.29	12563.1
3358.77	12488.1
3361.24	12478.6
3363.71	12455.9
3366.19	12447.9
3368.66	12418.5
3371.13	12398
3373.6	12439.5
3376.07	12320.7
3378.54	12383.9
3381	12357.1
3383.47	12307.9
3385.94	12249.9
3388.4	12273.8
3390.87	12210
3393.33	12268.1
3395.79	12213.5
3398.25	12215.4
3400.71	12200.4
3403.17	12118
3405.63	12108.5
3408.09	12091.6
3410.55	12049.1
3413	11998.6
3415.46	11978.7
3417.92	11976.3
3420.37	11924.7
3422.82	11885
3425.27	11849.1
3427.73	11801.2
3430.18	11768.2
3432.63	11711.7
3435.08	11780.9
3437.53	11698.8
3439.97	11678.8
3442.42	11569.6
3444.86	11553.6
3447.31	11558.7
3449.75	11476.8
3452.2	11465.1
3454.64	11372.5
3457.08	11310.5
3459.52	11321.4
3461.96	11244.3
3464.4	11219.1
3466.84	11194.2
3469.28	11183.3
3471.72	11121.5
3474.15	11033.1
3476.59	10985.1
3479.02	10892.8
3481.45	10831
3483.89	10849.5
3486.32	10759.1
3488.75	10764.3
3491.18	10710.4
3493.61	10631.7
3496.04	10576.6
3498.47	10509.5
3499.68	10521.8