File: src/Milk_AI/Amul full cream RT 532nm 50% 600g 50xL 10s 10times 400-3500cm-1 200hole.txt
#Acq. time (s)=	10
#Accumulations=	10
#Range (cm-¹)=	400...3500
#Windows=	3
#Auto scanning=	Off
#Autofocus=	Off
#AutoExposure=	Off
#Spike filter=	Multiple accum.
#Delay time (s)=	0
#Binning=	1
#Readout mode=	Signal
#DeNoise=	Off
#ICS correction=	On
#Dark correction=	Off
#Inst. Process=	Off
#Detector Gain=	Best Dynamic Range
#Detector ADC=	45 kHz
#Detector temperature (°C)=	-60.1
#Instrument=	LabRAM HR Evol
#Detector=	Syncerity OE
#Objective=	x50_VIS_LWD
#Grating=	600 (500nm)
#ND Filter=	50%
#Laser=	532nm_Edge
#Hole=	199.981
#Range=	Visible
#E-Cal_Neon=	0
#StageXY=	75x50mm Scan+
#StageZ=	Z motor
#X (µm)=	0
#Y (µm)=	0
#Z (µm)=	861.5
#Spectral res.(cm-¹)=	12.8
#Full time(mm:ss)=	5:19
#AC=	Calibrated 2025-06-30 10:26
#Project=
#Sample=
#Site=
#Title=	D_99
#Remark=
#Date=	30.06.2025 14:29 (India Standard Time)
#Acquired=	30.06.2025 14:29:15 (India Standard Time)
#AxisType[0]=Intens
#AxisUnit[0]=Cnt
#AxisType[1]=Spectr
#AxisUnit[1]=1/cm
400.17	20007.5
403.717	19858.3
407.263	19839.6
410.807	19843.3
414.35	19835.7
417.892	19881.5
421.432	19819
424.971	19783.5
428.509	19840
432.045	19832.8
435.58	19877.4
439.111	19804.3
442.643	19705.9
446.174	19662.2
449.701	19678.8
453.229	19719.9
456.756	19627.5
460.279	19575.4
463.803	19511.6
467.326	19506.1
470.845	19488.9
474.365	19448.1
477.882	19429.9
481.399	19410
484.913	19416.9
488.425	19383.4
491.938	19331.5
495.448	19383.6
498.956	19414.4
502.465	19398.1
505.971	19402
509.475	19465.7
512.981	19406
516.482	19384.6
519.983	19368.7
523.482	19327.2
526.979	19244
530.476	19190.2
533.971	19111.3
537.464	19094.4
540.956	19048.5
544.447	19021.8
547.937	18977.2
551.425	18973.1
554.912	18949.1
558.398	18949.6
561.882	18882.1
565.365	18900.8
568.847	18890.3
572.325	18918.9
575.804	18961.2
579.282	18954.4
582.756	18924.5
586.231	18971.8
589.705	18997.4
593.175	19040.8
596.646	19106.1
600.116	19070.6
603.582	19096.3
607.049	19152
610.513	19053.5
613.977	18873
617.438	18860.9
620.898	18791.6
624.359	18721.2
627.816	18625.3
631.272	18593.4
634.728	18614.7
638.181	18548.1
641.633	18638
645.084	18555.8
648.535	18523.8
651.983	18442
655.43	18393.9
658.875	18373
662.319	18370.7
665.762	18359.5
669.203	18363.8
672.643	18317.2
676.082	18290
679.519	18283.2
682.955	18268.8
686.39	18305.6
689.824	18295.1
693.256	18292.6
696.685	18353.1
700.115	18335.9
703.543	18349.8
706.97	18300.7
710.394	18296.7
713.818	18284
717.241	18357
720.661	18396.3
724.082	18368.7
727.501	18318
730.917	18255.7
734.334	18262.2
737.747	18303.1
741.161	18196.5
744.572	18148.2
747.982	18183.7
751.392	18202.8
754.799	18237.3
758.205	18200
761.611	18228.2
765.014	18248.8
768.416	18281.8
771.816	18276.9
775.218	18249
778.616	18198
782.012	18249.7
785.408	18273.7
788.802	18266.7
792.195	18276.8
795.586	18261.5
798.977	18358.4
802.365	18295.6
805.753	18421.5
809.14	18416.6
812.525	18392.3
815.907	18409.8
819.289	18580.1
822.671	18692.8
826.051	18783.4
829.43	18870.8
832.805	18915.9
836.182	19035.1
839.557	19111
842.928	19167.8
846.301	19270.2
849.67	19279.8
853.04	19256.7
856.407	19313.5
859.774	19418.6
863.138	19483.9
866.503	19482
869.865	19653
873.225	19560.6
876.586	19584.1
879.944	19362.4
883.301	19363.1
886.658	19460.4
890.012	19425.9
893.365	19202.9
896.717	18998.8
900.067	18757.7
903.416	18694.7
906.766	18545.1
910.112	18463.7
913.458	18459.3
916.802	18491.9
920.145	18493.2
923.484	18456.2
926.825	18257.2
930.164	18178.9
933.501	18116.2
936.838	17949.9
940.173	17969.7
943.505	18033.2
946.838	18078.8
950.17	18032.3
953.5	18081.3
956.827	18121.5
960.155	18113.9
963.48	18187.6
966.805	18097.7
970.128	18051.4
973.45	17936.7
976.77	17819.4
980.091	17837
983.408	17842.3
986.726	17898.5
990.041	17962.8
993.354	18064.7
996.668	18363.7
999.979	18959.2
1003.29	19401.4
1006.6	19337
1009.91	18948.2
1013.21	18567
1016.52	18446.9
1019.82	18389.6
1023.12	18327.9
1026.43	18126.2
1029.73	18101.3
1033.02	18119.1
1036.32	17993
1039.62	18027.8
1042.91	18020.1
1046.21	18009.8
1049.5	18003.2
1052.79	18151.1
1056.08	18410.9
1059.37	18924.2
1062.65	19403.1
1065.94	19256.1
1069.23	18903.7
1072.51	18907.9
1075.79	18968.5
1079.07	19154.6
1082.35	19195.3
1085.63	19017.3
1088.91	18779.6
1092.18	18544.1
1095.46	18235.9
1098.73	17987.4
1102	17788.4
1105.27	17650.2
1108.54	17560.5
1111.81	17661.9
1115.08	17821.6
1118.34	18073.5
1121.61	18220.8
1124.87	18489.1
1128.13	18433.7
1131.39	18003.2
1134.65	17619
1137.91	17445.7
1141.17	17567.2
1144.42	17998.2
1147.68	18713
1150.93	19971.9
1154.18	21460.5
1157.43	21923.8
1160.68	20578.6
1163.93	18711.2
1167.18	17717.5
1170.42	17352.1
1173.67	17213.9
1176.91	17091.2
1180.15	16875.6
1183.39	16997.6
1186.63	17036
1189.87	17092.1
1193.11	17108.1
1196.34	16962.6
1199.58	16679
1202.81	16540.8
1206.04	16432.6
1209.27	16413.4
1212.5	16418.2
1215.73	16279.2
1218.95	16105
1222.18	16003.5
1225.4	15932.6
1228.63	15985.3
1231.85	15952.7
1235.07	16057.2
1238.29	16103
1241.51	16272.5
1244.72	16372.2
1247.94	16469.5
1251.15	16576.9
1254.37	16700.3
1257.58	16833.8
1260.79	16952.2
1264	17003.6
1267.21	17080.6
1270.41	17061.1
1273.62	16913.2
1276.82	16883
1280.03	16791.1
1283.23	16812
1286.43	17026.8
1289.63	17380.9
1292.83	18165.7
1296.03	19044.1
1299.22	19464.1
1302.42	19306.3
1305.61	18869.5
1308.8	18289.5
1311.99	17712
1315.18	17162.2
1318.37	16699.2
1321.56	16389.3
1324.74	16137.2
1327.93	15890.5
1331.11	15713.3
1334.3	15521.2
1337.48	15503.3
1340.66	15479.4
1343.84	15360.9
1347.01	15361.2
1350.19	15385.5
1353.37	15304.4
1356.54	15164.3
1359.71	15131.5
1362.88	15141.6
1366.05	15185.3
1369.22	15108.3
1372.39	15009.8
1375.56	14891.3
1378.72	14757.1
1381.89	14624
1385.05	14580.5
1388.21	14600.2
1391.37	14583.1
1394.53	14551.3
1397.69	14507.7
1400.85	14597.5
1404	14558
1407.16	14708.6
1410.31	14836.2
1413.46	15060.5
1416.61	15321.9
1419.76	15588.2
1422.91	15802.6
1426.06	16229.2
1429.21	17194.1
1432.35	18731
1435.49	20368
1438.64	21269.4
1441.78	21194.9
1444.92	20584.3
1448.06	20045.3
1451.2	19645.9
1454.33	19293.5
1457.47	18925.8
1460.6	18433.1
1463.74	17703.4
1466.87	16951.2
1470	16333.8
1473.13	15603
1476.26	15184.2
1479.38	14779
1482.51	14545.8
1485.63	14469
1488.76	14378.3
1491.88	14389.4
1495	14439.7
1498.12	14576.4
1501.24	14655.7
1504.36	15020.8
1507.47	15495.7
1510.59	16253.8
1513.7	17145.5
1516.81	18162.6
1519.93	18814
1523.04	18906.5
1526.15	18354.8
1529.25	17223.7
1532.36	15877.6
1535.47	14814.4
1538.57	14125.5
1541.67	13830.5
1544.78	13541.6
1547.88	13351
1550.98	13222.3
1554.08	13186.9
1557.18	13175.5
1560.27	13062.7
1563.37	13050.7
1566.46	13074.6
1569.55	13001.8
1572.64	12955.8
1575.74	12966.2
1578.83	12955.8
1581.91	12978.8
1585	12953
1588.09	12933.2
1591.17	12940
1594.25	12943.4
1597.34	12964.1
1600.42	12901
1603.5	12893.9
1606.58	12865
1609.65	12871.9
1612.73	12762.9
1615.8	12720.4
1618.88	12683.4
1621.95	12704.3
1625.03	12699.2
1628.1	12741.5
1631.17	12810.7
1634.23	12886.6
1637.3	12952.9
1640.37	13129.4
1643.43	13320.6
1646.5	13899
1649.56	14784
1652.62	15372
1655.68	15318.5
1658.74	14612.3
1661.8	13867.6
1664.85	13419.1
1667.91	13166
1670.96	13036.7
1674.02	12757.3
1677.07	12440.9
1680.12	12273.7
1683.17	12168.6
1686.22	12103.6
1689.27	12024.2
1692.31	11973.1
1695.36	11978.8
1698.4	11881.1
1701.45	11802.9
1704.49	11792
1707.53	11756.6
1710.57	11675.4
1713.61	11665.9
1716.65	11642.1
1719.68	11655.2
1722.72	11697.1
1725.75	11829.3
1728.78	11964.8
1731.82	12040.6
1734.84	12182.6
1737.87	12476.6
1740.9	12718.2
1743.93	12714
1746.96	12660.4
1749.98	12567.5
1753	12318.4
1756.03	11990.8
1759.05	11741
1762.07	11545.4
1765.09	11399.3
1768.11	11320
1771.12	11216.8
1774.14	11219.1
1777.15	11171.9
1780.17	11163.3
1783.18	11080
1786.19	11133.5
1789.2	11095.2
1792.21	11003.1
1795.22	11066.6
1798.22	11008.8
1801.23	10960.7
1804.23	10938.7
1807.24	10910.5
1810.24	10892.4
1813.24	10925.8
1816.24	10830.3
1819.24	10842.7
1822.24	10833.6
1825.23	10759.8
1828.23	10768.5
1831.22	10793.6
1834.22	10756.7
1837.21	10788.5
1840.2	10780.2
1843.19	10747.5
1846.18	10724.4
1849.17	10675.6
1852.15	10642
1855.14	10637.7
1858.12	10617.2
1861.11	10599.5
1864.09	10622.6
1867.07	10568.9
1870.05	10614.6
1873.03	10519.1
1876.01	10561.3
1878.98	10537.7
1881.96	10473.1
1884.93	10477.4
1887.91	10410.6
1890.88	10402.7
1893.85	10353.1
1896.82	10307
1899.79	10299.9
1902.76	10312.4
1905.72	10156.1
1908.69	10150.8
1911.65	10083.2
1914.62	10031.3
1917.58	9973.62
1920.54	9934.8
1923.5	9834.32
1926.46	9802.12
1929.42	9772.76
1932.37	9729.68
1935.33	9656.42
1938.28	9619.4
1941.24	9557.27
1944.19	9528.91
1947.14	9466.31
1950.09	9429.97
1953.04	9355.78
1955.99	9306.28
1958.93	9243
1961.88	9194.61
1964.82	9152.99
1967.77	9136.92
1970.71	9089.3
1973.65	9053.63
1976.59	8992.68
1979.53	8947.44
1982.47	8943.21
1985.41	8881.94
1988.34	8861.4
1991.28	8795.64
1994.21	8724.17
1997.14	8680.83
2000.07	8638.3
2003.01	8620.38
2005.94	8566
2008.86	8560.13
2011.79	8528.77
2014.72	8475.88
2017.64	8443.79
2020.57	8390.52
2023.49	8373.06
2026.41	8337.32
2029.33	8297.51
2032.25	8262.84
2035.17	8227.3
2038.09	8196.34
2041	8196.44
2043.92	8180.07
2045.86	8175.01
2048.79	8157.07
2051.71	8130.75
2054.64	8144.2
2057.56	8085.17
2060.48	8044.07
2063.4	8093.15
2066.32	8044.16
2069.24	8054.15
2072.16	8050.45
2075.08	8070.82
2077.99	8018.37
2080.91	8002.29
2083.82	7992.42
2086.74	7976.24
2089.65	7981.41
2092.56	7958.99
2095.47	7953.28
2098.38	7947.46
2101.29	7917.66
2104.19	7919.83
2107.1	7889.53
2110	7862.31
2112.91	7876.32
2115.81	7828.38
2118.71	7798.15
2121.61	7844.19
2124.51	7808.94
2127.4	7779.91
2130.3	7789.17
2133.2	7744.42
2136.09	7772.06
2138.99	7739.17
2141.88	7753.92
2144.77	7733.77
2147.66	7719.91
2150.55	7706.01
2153.44	7719.47
2156.33	7701.3
2159.21	7728.06
2162.1	7667.84
2164.98	7676.21
2167.87	7676.84
2170.75	7690.6
2173.63	7672.9
2176.51	7645.8
2179.39	7655.72
2182.27	7638.8
2185.14	7595.7
2188.02	7597.73
2190.9	7584.53
2193.77	7594.34
2196.64	7569.13
2199.51	7564.65
2202.39	7543.12
2205.25	7498.39
2208.12	7489.11
2210.99	7461.68
2213.86	7453.01
2216.72	7400.8
2219.59	7424.32
2222.45	7415.4
2225.31	7369.79
2228.17	7352.13
2231.03	7352.23
2233.89	7299.07
2236.75	7277.04
2239.61	7280.56
2242.46	7280.64
2245.32	7255.05
2248.17	7201.19
2251.03	7200.83
2253.88	7212.16
2256.73	7193.85
2259.58	7139.83
2262.43	7114.17
2265.28	7110.18
2268.12	7082.24
2270.97	7093.41
2273.81	7040.48
2276.66	7046.97
2279.5	7006.32
2282.34	7024.68
2285.18	7001.47
2288.02	6969.15
2290.86	6974.62
2293.7	6966.59
2296.54	6941.71
2299.37	6953.12
2302.21	6901.4
2305.04	6858.83
2307.87	6875.05
2310.7	6867.32
2313.53	6843.24
2316.36	6821.49
2319.19	6791.28
2322.02	6774.27
2324.85	6846.92
2327.67	6935.67
2330.5	7033.32
2333.32	6756.06
2336.14	6670.34
2338.96	6694.59
2341.78	6625.72
2344.6	6648.03
2347.42	6604.13
2350.24	6576.57
2353.05	6595.88
2355.87	6581.33
2358.68	6531.5
2361.5	6527.88
2364.31	6503.57
2367.12	6496.58
2369.93	6444.65
2372.74	6459.15
2375.55	6426.98
2378.35	6416.91
2381.16	6443.96
2383.96	6379.82
2386.77	6376.54
2389.57	6382.33
2392.37	6335.73
2395.17	6329.09
2397.97	6340.02
2400.77	6335.7
2403.57	6293.04
2406.37	6293.11
2409.16	6263.91
2411.96	6235.44
2414.75	6239.13
2417.55	6254.86
2420.34	6257.04
2423.13	6201.52
2425.92	6251.76
2428.71	6236.81
2431.5	6177.65
2434.28	6146.78
2437.07	6146.51
2439.85	6132.32
2442.64	6148.56
2445.42	6120.69
2448.2	6128.86
2450.98	6093.78
2453.76	6067.23
2456.54	6100.24
2459.32	6095.98
2462.1	6036.04
2464.87	6046.13
2467.65	6020.2
2470.42	6008.95
2473.2	5995.54
2475.97	5950.27
2478.74	5953.44
2481.51	5952.68
2484.28	5946.85
2487.05	5937.73
2489.81	5932.77
2492.58	5902.07
2495.34	5884.74
2498.11	5894.95
2500.87	5867.24
2503.63	5851.06
2506.39	5834.39
2509.15	5841.4
2511.91	5825.69
2514.67	5809.77
2517.43	5801.2
2520.19	5823.91
2522.94	5767.41
2525.7	5806.25
2528.45	5767.25
2531.2	5739
2533.95	5743.82
2536.7	5744.75
2539.45	5731.47
2542.2	5703.48
2544.95	5707.27
2547.69	5685.91
2550.44	5636.17
2553.18	5642.71
2555.93	5634.55
2558.67	5644.38
2561.41	5616.3
2564.15	5615.02
2566.89	5618.36
2569.63	5594.46
2572.36	5631.65
2575.1	5599.83
2577.84	5636.73
2580.57	5587.82
2583.31	5610.12
2586.04	5599.61
2588.77	5649.67
2591.5	5604.53
2594.23	5620.65
2596.96	5620.81
2599.69	5603.6
2602.41	5590.92
2605.14	5573.75
2607.86	5611.11
2610.59	5572.8
2613.31	5596.63
2616.03	5560.48
2618.75	5526.03
2621.48	5519.98
2624.19	5553.54
2626.91	5518.12
2629.63	5559.68
2632.35	5530.74
2635.06	5495.81
2637.77	5539.07
2640.49	5520.92
2643.2	5520.33
2645.91	5547.83
2648.62	5532.82
2651.33	5541.72
2654.04	5546.15
2656.75	5554.14
2659.45	5554.58
2662.16	5562.46
2664.86	5546.94
2667.57	5558.02
2670.27	5569.22
2672.97	5592.24
2675.67	5565.42
2678.37	5564.44
2681.07	5554.14
2683.77	5547.85
2686.47	5583.16
2689.16	5566.67
2691.86	5575.71
2694.55	5554.31
2697.25	5555.89
2699.94	5585.75
2702.63	5623.97
2705.32	5637.9
2708.01	5669.93
2710.7	5761.7
2713.39	5794.74
2716.07	5808.26
2718.76	5852.62
2721.44	5907.65
2724.12	5916.3
2726.81	5928.11
2729.49	5902.29
2732.17	5814.42
2734.85	5753.97
2737.53	5676.33
2740.21	5553.14
2742.88	5476.95
2745.56	5428.99
2748.24	5404.99
2750.91	5318.9
2753.58	5247.24
2756.25	5239.64
2758.93	5223.22
2761.6	5202.83
2764.27	5139.14
2766.93	5132.97
2769.6	5135.33
2772.27	5151.11
2774.93	5105.1
2777.6	5120.01
2780.26	5084.06
2782.93	5106.09
2785.59	5117.46
2788.25	5091.52
2790.91	5080.18
2793.57	5119.87
2796.23	5152.88
2798.88	5160.39
2801.54	5159.15
2804.2	5146.09
2806.85	5211.44
2809.5	5195.19
2812.16	5262.33
2814.81	5318.69
2817.46	5404.04
2820.11	5450.82
2822.76	5556.02
2825.4	5704.07
2828.05	5913.14
2830.7	6144.83
2833.34	6514.15
2835.99	7074.34
2838.63	7937.69
2841.27	9359.3
2843.91	11400
2846.55	13926
2849.19	15959.5
2851.83	16683.9
2854.47	16299.7
2857.11	15466.8
2859.74	14779.1
2862.38	14187.1
2865.01	13673.4
2867.65	13527.2
2870.28	13763.2
2872.91	14177.7
2875.54	14565.3
2878.17	14973.5
2880.8	15420.3
2883.42	15712.1
2886.05	15688.5
2888.68	15672.9
2891.3	15555.3
2893.93	15536.2
2896.55	15502.7
2899.17	15409.6
2901.79	15305.8
2904.41	15216.8
2907.03	15077.5
2909.65	14954.3
2912.27	14822.8
2914.88	14696.8
2917.5	14560.6
2920.11	14509.1
2922.73	14376.2
2925.34	14426.7
2927.95	14456.3
2930.56	14434.2
2933.17	14347.7
2935.78	14104.3
2938.39	13715.4
2941	12920.7
2943.6	11899
2946.21	10875.4
2948.81	10167.8
2951.42	9667.16
2954.02	9397.84
2956.62	9221.25
2959.22	9042.91
2961.82	8850.08
2964.42	8522.25
2967.02	8186
2969.62	7817.96
2972.21	7447.89
2974.81	7077.34
2977.4	6828.96
2980	6551.7
2982.59	6371.86
2985.18	6192.92
2987.77	6041.26
2990.36	5928.55
2992.95	5885.84
2995.54	5827.04
2998.13	5800.47
3000.72	5801.09
3003.3	5870.25
3005.89	5840.85
3008.47	5797.83
3011.05	5691.38
3013.63	5555.02
3016.22	5405.4
3018.8	5288.71
3021.38	5173.22
3023.95	5051.6
3026.53	5003.49
3029.11	4924.97
3031.68	4878.43
3034.26	4864.56
3036.83	4827.95
3039.4	4782.03
3041.98	4817.31
3044.55	4775.86
3047.12	4751.15
3049.69	4767.14
3052.26	4793.32
3054.82	4800.32
3057.39	4783.93
3059.96	4769.53
3062.52	4809.4
3065.09	4809.14
3067.65	4794.14
3070.21	4780.48
3072.77	4784.36
3075.33	4817.72
3077.89	4835.46
3080.45	4797.05
3083.01	4794.57
3085.57	4740.3
3088.12	4771.23
3090.68	4813.16
3093.23	4804.29
3095.79	4777.15
3098.34	4796.57
3100.89	4832.54
3103.44	4825.22
3105.99	4874.42
3108.54	4910.04
3111.09	4882.57
3113.63	4890.98
3116.18	4979.05
3118.73	4965.33
3121.27	4984.12
3123.82	5009.46
3126.36	4989.25
3128.9	5075.71
3131.44	5072
3133.98	5086.61
3136.52	5128.75
3139.06	5146.52
3141.6	5165.8
3144.13	5178.59
3146.67	5222.39
3149.2	5261.83
3151.74	5289.05
3154.27	5291.88
3156.8	5363.67
3159.34	5359.7
3161.86	5347.25
3164.4	5385.14
3166.92	5409.1
3169.45	5424.16
3171.98	5491.38
3174.5	5461.68
3177.03	5464.94
3179.56	5467.42
3182.08	5465
3184.6	5468.83
3187.12	5480.97
3189.64	5522.56
3192.16	5524.53
3194.68	5480.59
3197.2	5512.36
3199.72	5480.78
3202.24	5508.04
3204.75	5523.2
3207.27	5530.43
3209.78	5506.7
3212.29	5496.56
3214.81	5490.42
3217.32	5495.67
3219.83	5499.44
3222.34	5471.96
3224.85	5486.2
3227.35	5473.33
3229.86	5482.96
3232.37	5454.49
3234.87	5467.82
3237.38	5462.47
3239.88	5439.41
3242.38	5449.78
3244.89	5422.24
3247.39	5412.21
3249.89	5395.14
3252.39	5393.4
3254.88	5370.43
3257.38	5359.91
3259.88	5332.34
3262.37	5336.9
3264.87	5318.32
3267.36	5305.21
3269.86	5305.61
3272.35	5324.25
3274.84	5303.77
3277.33	5273.94
3279.82	5263.1
3282.31	5271.9
3284.8	5250
3287.29	5251.06
3289.77	5221.29
3292.26	5222.42
3294.15	5211.36
3296.64	5213.83
3299.14	5189.94
3301.63	5196.62
3304.12	5182.54
3306.62	5159.98
3309.11	5165.3
3311.6	5180.25
3314.09	5127.53
3316.58	5154.58
3319.07	5171.3
3321.56	5146.15
3324.04	5159.42
3326.53	5151.67
3329.01	5128.75
3331.5	5118.9
3333.98	5123.16
3336.46	5133.2
3338.94	5143.86
3341.42	5105.45
3343.9	5091.21
3346.38	5115.59
3348.86	5094.64
3351.34	5121.25
3353.82	5068.33
3356.29	5103.89
3358.77	5056.21
3361.24	5053.5
3363.71	5069.74
3366.19	5052.28
3368.66	5076.95
3371.13	5081.65
3373.6	5083.77
3376.07	5080.56
3378.54	5030.37
3381	5052.09
3383.47	5068.35
3385.94	5043.15
3388.4	5029.83
3390.87	5026.68
3393.33	5032.61
3395.79	5032.35
3398.25	5031.27
3400.71	5029.26
3403.17	4990.73
3405.63	5012.15
3408.09	5020.62
3410.55	4991.19
3413	4978.09
3415.46	4956.17
3417.92	4980.88
3420.37	4965.04
3422.82	4953.46
3425.27	4931.42
3427.73	4916.05
3430.18	4906.05
3432.63	4906.24
3435.08	4881.77
3437.53	4895.7
3439.97	4859.62
3442.42	4856.01
3444.86	4811.25
3447.31	4815.18
3449.75	4779.87
3452.2	4799.02
3454.64	4759.3
3457.08	4755.51
3459.52	4732.55
3461.96	4698.07
3464.4	4676.15
3466.84	4682.73
3469.28	4633.76
3471.72	4622.48
3474.15	4596.54
3476.59	4594.05
3479.02	4527.63
3481.45	4528.97
3483.89	4492.56
3486.32	4470.84
3488.75	4450.27
3491.18	4399.21
3493.61	4388.01
3496.04	4393.77
3498.47	4336.32
3499.68	4314.23