File: src/Milk_AI/Heritage special 532nm 50% 600g 50xL 10s 10times 400-3500cm-1 200hole after heating.txt
#Acq. time (s)=	10
#Accumulations=	10
#Range (cm-¹)=	400...3500
#Windows=	3
#Auto scanning=	Off
#Autofocus=	Off
#AutoExposure=	Off
#Spike filter=	Multiple accum.
#Delay time (s)=	0
#Binning=	1
#Readout mode=	Signal
#DeNoise=	Off
#ICS correction=	On
#Dark correction=	Off
#Inst. Process=	Off
#Detector Gain=	Best Dynamic Range
#Detector ADC=	45 kHz
#Detector temperature (°C)=	-60.1
#Instrument=	LabRAM HR Evol
#Detector=	Syncerity OE
#Objective=	x50_VIS_LWD
#Grating=	600 (500nm)
#ND Filter=	50%
#Laser=	532nm_Edge
#Hole=	199.981
#Range=	Visible
#E-Cal_Neon=	0
#StageXY=	75x50mm Scan+
#StageZ=	Z motor
#X (µm)=	0
#Y (µm)=	0
#Z (µm)=	332.2
#Spectral res.(cm-¹)=	12.8
#Full time(mm:ss)=	5:19
#AC=	Calibrated 2025-07-01 10:31
#Project=
#Sample=
#Site=
#Title=	D_1
#Remark=
#Date=	01.07.2025 14:54 (India Standard Time)
#Acquired=	01.07.2025 14:54:54 (India Standard Time)
#AxisType[0]=Intens
#AxisUnit[0]=Cnt
#AxisType[1]=Spectr
#AxisUnit[1]=1/cm
400.083	30573.2
403.63	30388.3
407.176	30467.4
410.72	30511
414.263	30587.2
417.805	30582.3
421.345	30531.5
424.884	30536.2
428.421	30614.2
431.955	30651
435.49	30732.2
439.023	30655.6
442.555	30564.8
446.084	30691.7
449.613	30601.8
453.141	30618.8
456.666	30556.4
460.191	30643.9
463.715	30646.2
467.235	30682.5
470.756	30692.1
474.274	30674.3
477.793	30754.9
481.308	30737.5
484.823	30785
488.336	30716.9
491.847	30763.2
495.358	30802
498.867	30887.8
502.374	30946.2
505.881	30953.4
509.386	31008.1
512.888	31087.4
516.39	31031.7
519.89	30953.6
523.391	30929
526.889	31026.7
530.385	30980.2
533.88	30973.7
537.373	30962.3
540.866	30918.3
544.357	30934.2
547.846	30959.5
551.334	30912.9
554.821	30980.8
558.307	30963.7
561.789	30944.6
565.272	31007.7
568.753	31039
572.233	31103.6
575.712	31064.9
579.188	31118.3
582.664	31077.6
586.139	31148.6
589.611	31158.9
593.083	31124.8
596.554	31109.6
600.021	31140.4
603.49	31126.1
606.955	31124.2
610.42	31162.2
613.882	31051.1
617.345	31097.2
620.805	31114.3
624.263	30992.4
627.722	31003.1
631.178	30951.6
634.633	30977.6
638.088	31040.5
641.539	31040.2
644.99	30958.2
648.439	30921.3
651.887	30890.5
655.335	31007.9
658.781	30970.1
662.225	31019.8
665.667	30967.5
669.108	31006.8
672.548	30963.1
675.987	31035.1
679.424	31093.7
682.86	31067.8
686.293	31045
689.727	31027.4
693.159	31144.2
696.59	31084.1
700.019	31068
703.448	31130.6
706.872	31003.4
710.298	31025.6
713.723	30993.6
717.144	30945.3
720.565	31094
723.984	31030.7
727.403	30967.3
730.821	30905
734.235	30901.9
737.651	30992
741.063	30903.7
744.474	30895.4
747.885	30974
751.293	30984
754.702	31050.1
758.108	31158.3
761.512	31089.4
764.915	31102.6
768.319	31152.2
771.719	31085
775.118	31181.1
778.516	31186.4
781.913	31141.2
785.308	31172.4
788.702	31139.6
792.095	31095.9
795.486	31005.9
798.876	31024.8
802.265	31121.1
805.653	31136.4
809.039	31000
812.424	30931.2
815.808	30934.7
819.191	30978.1
822.572	31021.8
825.95	31205.7
829.329	31029.5
832.706	31107.6
836.08	31042.3
839.455	31032.2
842.829	31240.8
846.199	31203.8
849.57	31181.1
852.938	31203.5
856.307	31121.4
859.672	31323.1
863.038	31242.2
866.401	31214.3
869.765	31173.1
873.125	31280
876.484	31302.9
879.844	31143.7
883.2	31156.3
886.555	31066.5
889.909	31041.2
893.262	30947.2
896.616	30906.5
899.966	30842.6
903.315	30917.3
906.663	30770.2
910.009	30756.1
913.354	30754.3
916.698	30713
920.041	30652.2
923.383	30620.9
926.723	30517.9
930.062	30503.7
933.399	30475.6
936.734	30529.6
940.069	30583
943.403	30629.3
946.736	30512.9
950.065	30494.3
953.396	30547.5
956.725	30517.2
960.051	30592.2
963.377	30634.5
966.7	30583.8
970.025	30510.5
973.345	30564.2
976.667	30476.4
979.985	30533.8
983.304	30523.4
986.62	30541.1
989.935	30573.1
993.25	30572.2
996.563	30753.7
999.874	30895.6
1003.19	30723.6
1006.49	30714.1
1009.8	30515.7
1013.11	30513.9
1016.41	30608.3
1019.72	30470.2
1023.02	30384.3
1026.32	30434.5
1029.62	30369.5
1032.92	30287.5
1036.22	30344.7
1039.51	30271.9
1042.81	30236.8
1046.1	30256.7
1049.39	30264.4
1052.68	30267.6
1055.97	30360
1059.26	30362.5
1062.55	30470.5
1065.83	30341.9
1069.12	30436.1
1072.4	30440.7
1075.68	30412.3
1078.97	30377.7
1082.24	30423.7
1085.52	30413.4
1088.8	30225.2
1092.08	30188.7
1095.35	30054.1
1098.62	29994.2
1101.9	29844.6
1105.17	29744.9
1108.44	29875.4
1111.7	29932.6
1114.97	29956.8
1118.23	29944.1
1121.5	29948
1124.76	29877.6
1128.03	29742.5
1131.29	29681.2
1134.54	29669.3
1137.8	29608.8
1141.06	29554.9
1144.31	29746.6
1147.57	29867.6
1150.82	30036.2
1154.07	30241.6
1157.32	30029.8
1160.57	29703.5
1163.82	29459.2
1167.07	29403.7
1170.31	29303.4
1173.56	29257.9
1176.8	29256.5
1180.04	29120.8
1183.28	29230.9
1186.52	29174.6
1189.76	29214.4
1192.99	29115
1196.23	29032.1
1199.46	29044.7
1202.7	29014.9
1205.93	29015
1209.16	29010.5
1212.39	29035.9
1215.62	28868
1218.84	28827.3
1222.07	28882.6
1225.29	28852.8
1228.52	28931.5
1231.74	28944.5
1234.96	28859.4
1238.18	28845.9
1241.4	28943.1
1244.61	29015.8
1247.83	29041.5
1251.04	28935
1254.25	28996.6
1257.47	28967.1
1260.68	29008
1263.89	28984.9
1267.09	28956.3
1270.3	28829.2
1273.51	28781.5
1276.71	28717.2
1279.91	28668.3
1283.12	28693.4
1286.32	28659.5
1289.52	28700.4
1292.72	28906.5
1295.91	28991.2
1299.11	28959.1
1302.3	29004.8
1305.5	28895.5
1308.69	28707.4
1311.88	28671.4
1315.07	28479.7
1318.26	28429.6
1321.44	28249.8
1324.63	28242.2
1327.82	28290.3
1331	28203.8
1334.18	28274.3
1337.36	28169
1340.54	28203.7
1343.72	28066.3
1346.9	28049.2
1350.07	28089.2
1353.25	27980.9
1356.42	27911.5
1359.6	27852.7
1362.77	27799.1
1365.94	27814.8
1369.11	27762.4
1372.28	27657.8
1375.44	27492.3
1378.61	27466.6
1381.77	27469.1
1384.93	27387
1388.1	27399.3
1391.26	27510.6
1394.41	27395
1397.57	27355.6
1400.73	27337.9
1403.89	27218.4
1407.04	27215.2
1410.19	27336.9
1413.35	27417.4
1416.5	27473.1
1419.65	27480
1422.8	27455.9
1425.94	27709.3
1429.09	27903.8
1432.23	28213.9
1435.38	28543.6
1438.52	28444.1
1441.66	28412.8
1444.8	28184
1447.94	28139.7
1451.08	28024.6
1454.22	27920.5
1457.35	27706.3
1460.48	27575.3
1463.62	27445.4
1466.75	27177.6
1469.88	27080.5
1473.01	26908.8
1476.14	26671.2
1479.26	26528.2
1482.39	26499.4
1485.51	26468.9
1488.64	26489.7
1491.76	26441
1494.88	26569
1498	26500.8
1501.12	26485.2
1504.24	26518.5
1507.35	26557.7
1510.47	26671.7
1513.58	26806.7
1516.69	26944.6
1519.81	26816.3
1522.92	26807
1526.03	26602.4
1529.13	26344
1532.24	26098
1535.35	26019
1538.45	26080.3
1541.55	26043.9
1544.66	25906.6
1547.76	25925.7
1550.86	25774.9
1553.96	25804.4
1557.05	25736.5
1560.15	25767.5
1563.24	25785.7
1566.34	25751.5
1569.43	25678.6
1572.52	25715.9
1575.61	25646.8
1578.7	25680.8
1581.79	25703.2
1584.88	25606.5
1587.96	25529.2
1591.05	25572.9
1594.13	25573.3
1597.21	25528.8
1600.3	25615.5
1603.37	25575.8
1606.45	25493.4
1609.53	25525.9
1612.61	25397.5
1615.68	25330.8
1618.76	25328
1621.83	25229.7
1624.9	25231.8
1627.97	25191.8
1631.04	25233.8
1634.11	25276.2
1637.18	25230.3
1640.24	25295.5
1643.31	25423
1646.37	25559.8
1649.44	25640.8
1652.5	25574.1
1655.56	25531.6
1658.62	25314
1661.67	25209.3
1664.73	25135.1
1667.79	25009.2
1670.84	24970.8
1673.89	24894.6
1676.95	24820.8
1680	24579.8
1683.05	24609.3
1686.1	24477.7
1689.14	24456.9
1692.19	24375.6
1695.23	24347.2
1698.28	24244.4
1701.32	24147.3
1704.36	24066.2
1707.4	24018.1
1710.44	23990.9
1713.48	23895.5
1716.52	23956.1
1719.56	23829.5
1722.59	23883.3
1725.63	23875.3
1728.66	23862
1731.69	23860.5
1734.72	23961.9
1737.75	23946.7
1740.78	23850.2
1743.8	23868.9
1746.83	23791.5
1749.86	23742.9
1752.88	23690.8
1755.9	23620.8
1758.92	23520
1761.94	23356.8
1764.96	23394.6
1767.98	23345
1771	23330.3
1774.01	23326.8
1777.03	23238.9
1780.04	23252.3
1783.05	23207.3
1786.06	23198.4
1789.07	23118
1792.08	23138
1795.09	23113.9
1798.1	23125.2
1801.1	22994.4
1804.11	23016.1
1807.11	22921.2
1810.11	22922
1813.11	22912.7
1816.11	22867.5
1819.11	22809.6
1822.11	22823.9
1825.11	22706.4
1828.1	22741.6
1831.1	22676.9
1834.09	22702.4
1837.08	22657.8
1840.07	22650.6
1843.06	22600.7
1846.05	22616.5
1849.04	22573.4
1852.02	22503.4
1855.01	22429.6
1857.99	22414.8
1860.98	22437.3
1863.96	22380.1
1866.94	22335.8
1869.92	22342.1
1872.9	22269.6
1875.88	22274.2
1878.85	22279
1881.83	22230.5
1884.8	22125.1
1887.78	22081.8
1890.75	22103.3
1893.72	21914.3
1896.69	21903.9
1899.66	21829.9
1902.63	21787.6
1905.59	21709.2
1908.56	21638.8
1911.52	21489.8
1914.49	21413.2
1917.45	21259.8
1920.41	21163.9
1923.37	21032.1
1926.33	21062.3
1929.29	20896.4
1932.24	20796.6
1935.2	20747.7
1938.15	20566.8
1941.1	20501.5
1944.06	20423.3
1947.01	20371.7
1949.96	20220
1952.91	20074.3
1955.86	19997.3
1958.8	19868.1
1961.75	19764
1964.69	19679.1
1967.64	19584.4
1970.58	19543
1973.52	19466
1976.46	19381.5
1979.4	19274.1
1982.34	19215.8
1985.27	19144.4
1988.21	19031
1991.14	18942.4
1994.08	18837.6
1997.01	18775.3
1999.94	18623.8
2002.87	18569.8
2005.8	18473.1
2008.73	18433.6
2011.66	18365.5
2014.58	18322.2
2017.51	18219.3
2020.43	18128.7
2023.36	18025.6
2026.28	17980.9
2029.2	17927.1
2032.12	17837.9
2035.04	17785.5
2037.95	17720.7
2040.87	17643.9
2043.78	17629.2
2045.76	17603.2
2048.69	17575.1
2051.61	17427
2054.54	17525.8
2057.46	17455.8
2060.38	17435.4
2063.3	17405.7
2066.22	17379.5
2069.14	17352.2
2072.06	17365.5
2074.98	17339.8
2077.89	17209.7
2080.81	17251.6
2083.72	17259.6
2086.63	17182.7
2089.55	17136.5
2092.46	17144
2095.37	17076.6
2098.28	17072.8
2101.18	17004.6
2104.09	17025.8
2106.99	16975.9
2109.9	16927.8
2112.8	16940.2
2115.71	16918.5
2118.61	16923.9
2121.51	16839.8
2124.4	16750.5
2127.3	16837
2130.2	16792.9
2133.09	16809.7
2135.99	16732.7
2138.88	16746.2
2141.78	16734.2
2144.67	16731.4
2147.56	16668.6
2150.45	16601.4
2153.34	16615.3
2156.22	16567.5
2159.11	16584.9
2162	16625.8
2164.88	16556.9
2167.76	16531
2170.64	16512.6
2173.53	16550.2
2176.41	16443.6
2179.29	16409.2
2182.16	16353.1
2185.04	16400.3
2187.92	16392.8
2190.79	16311.3
2193.66	16290.4
2196.54	16321.6
2199.41	16274.8
2202.28	16267.9
2205.15	16229.5
2208.02	16218.3
2210.88	16132.2
2213.75	16122.2
2216.62	16065
2219.48	15986.3
2222.34	15993.4
2225.21	15974
2228.07	15936
2230.93	15943.7
2233.79	15827.6
2236.65	15871.1
2239.5	15795.8
2242.36	15829.4
2245.21	15782.4
2248.07	15695.6
2250.92	15688.7
2253.77	15603.7
2256.62	15591.5
2259.47	15500.7
2262.32	15482.3
2265.17	15424.3
2268.02	15376.8
2270.86	15351.3
2273.71	15299.6
2276.55	15250.2
2279.39	15203.5
2282.24	15222
2285.08	15153.7
2287.92	15138.7
2290.75	15115.8
2293.59	15055.8
2296.43	15022.7
2299.26	15020.3
2302.1	14965.1
2304.93	14938.8
2307.76	14878.8
2310.6	14940.7
2313.43	14823.6
2316.25	14786.2
2319.08	14743.9
2321.91	14724
2324.74	14831.4
2327.56	14960.6
2330.39	14668.8
2333.21	14587
2336.03	14579.2
2338.85	14502.2
2341.67	14520
2344.49	14501.1
2347.31	14449.3
2350.13	14332.3
2352.94	14342
2355.76	14332
2358.57	14189.6
2361.39	14231.9
2364.2	14192.4
2367.01	14146
2369.82	14133
2372.63	14118.2
2375.44	14135.8
2378.24	14097.7
2381.05	14037.3
2383.85	14005.3
2386.66	13981
2389.46	13975.3
2392.26	13907.4
2395.06	13931.2
2397.86	13895.1
2400.66	13839.8
2403.46	13800.6
2406.26	13771.4
2409.05	13820.8
2411.85	13737.5
2414.64	13726.5
2417.43	13706.8
2420.23	13664.8
2423.02	13624.9
2425.81	13637.9
2428.6	13633.7
2431.38	13569.5
2434.17	13552
2436.96	13493.7
2439.74	13457.9
2442.53	13444
2445.31	13413.7
2448.09	13413.2
2450.87	13369.1
2453.65	13301.2
2456.43	13358
2459.21	13326
2461.98	13277.4
2464.76	13262.6
2467.53	13241.8
2470.31	13170.6
2473.08	13113.8
2475.85	13167.3
2478.63	13094.4
2481.39	13073.6
2484.16	13053.6
2486.93	13036
2489.7	13019.8
2492.46	12972.1
2495.23	12966.3
2497.99	12939.7
2500.76	12920.9
2503.52	12877.3
2506.28	12858.8
2509.04	12831
2511.8	12806.8
2514.56	12761.5
2517.31	12752.8
2520.07	12714.2
2522.82	12728.8
2525.58	12672.9
2528.33	12642.9
2531.09	12635.8
2533.84	12641.2
2536.59	12618.4
2539.34	12580.1
2542.08	12578.8
2544.83	12455.8
2547.58	12469.7
2550.32	12454.1
2553.07	12433.4
2555.81	12424.8
2558.55	12437.6
2561.29	12364.1
2564.03	12372.5
2566.77	12364.7
2569.51	12298.5
2572.25	12306.8
2574.99	12289.3
2577.72	12312.4
2580.46	12251.1
2583.19	12228.9
2585.92	12255.9
2588.65	12229.1
2591.38	12154.2
2594.11	12191.5
2596.84	12151.5
2599.57	12148.4
2602.3	12074
2605.02	12069.6
2607.75	12055.3
2610.47	12032.7
2613.19	12100.4
2615.92	11980.6
2618.64	11962.9
2621.36	11993.6
2624.08	11900.5
2626.8	12027
2629.51	11906.5
2632.23	11854.6
2634.94	11884.5
2637.66	11835.7
2640.37	11843.5
2643.08	11866.5
2645.79	11802.3
2648.5	11806.8
2651.21	11794.8
2653.92	11800.7
2656.63	11726.9
2659.33	11658.1
2662.04	11734.8
2664.75	11715.5
2667.45	11677.2
2670.15	11662.3
2672.85	11685.7
2675.55	11622.1
2678.25	11604.5
2680.95	11589.3
2683.65	11535.5
2686.35	11543.2
2689.04	11569.2
2691.74	11548.8
2694.43	11467.1
2697.13	11499.1
2699.82	11492
2702.51	11530.6
2705.2	11495.2
2707.89	11434.8
2710.58	11395.4
2713.26	11414.8
2715.95	11411
2718.64	11323.1
2721.32	11334.5
2724	11348.7
2726.69	11340.2
2729.37	11345.4
2732.05	11312.5
2734.73	11283.5
2737.41	11220.6
2740.09	11141.4
2742.76	11151.5
2745.44	11141.3
2748.11	11120.8
2750.79	11030.7
2753.46	11065.3
2756.13	10993.7
2758.81	10994.6
2761.47	10966.2
2764.14	10947.2
2766.81	10958.6
2769.48	10921.1
2772.15	10871.7
2774.81	10843.9
2777.48	10850.4
2780.14	10794.7
2782.8	10819.3
2785.47	10738.3
2788.13	10731.9
2790.79	10714.6
2793.44	10718.6
2796.1	10706.7
2798.76	10738.4
2801.42	10690.9
2804.07	10660.8
2806.73	10608.2
2809.38	10621
2812.03	10597.4
2814.68	10673.7
2817.33	10637.3
2819.98	10644.3
2822.63	10602.4
2825.28	10599.3
2827.93	10665.9
2830.57	10661.3
2833.22	10686.4
2835.86	10856.5
2838.51	10997.8
2841.15	11332.3
2843.79	11713.1
2846.43	12099.3
2849.07	12283.7
2851.71	12303.2
2854.35	12186.1
2856.98	12046.2
2859.62	11980.7
2862.25	11849.6
2864.89	11845.6
2867.52	11894.3
2870.15	11932.7
2872.78	11986.9
2875.41	12017
2878.04	12025.8
2880.67	12138
2883.3	12180.5
2885.92	12225.1
2888.55	12294.3
2891.18	12242.8
2893.8	12266.8
2896.42	12249.1
2899.04	12203.5
2901.67	12205.1
2904.29	12169.9
2906.9	12167.7
2909.52	12051.1
2912.14	12066.1
2914.76	12072.5
2917.37	12057.5
2919.99	12023.8
2922.6	12010.5
2925.21	11970.2
2927.82	12022.3
2930.44	11983.1
2933.05	11961.5
2935.65	11876.2
2938.26	11704
2940.87	11559.2
2943.48	11329.3
2946.08	11132.7
2948.69	11029.8
2951.29	10877.4
2953.89	10804
2956.49	10799.5
2959.1	10727.8
2961.7	10597.2
2964.29	10562.4
2966.89	10504.8
2969.49	10389.8
2972.09	10292.2
2974.68	10210.1
2977.28	10176
2979.87	10140.8
2982.46	10082
2985.05	10016.7
2987.65	9969.98
2990.24	9912.47
2992.82	9844.92
2995.41	9875.32
2998	9802.68
3000.59	9777.28
3003.17	9777.9
3005.76	9739.12
3008.34	9682.3
3010.92	9659.9
3013.5	9623.28
3016.09	9610.96
3018.67	9593.49
3021.25	9511.86
3023.82	9514.4
3026.4	9514.66
3028.98	9465.04
3031.55	9446.1
3034.13	9460.42
3036.7	9465.35
3039.28	9475.19
3041.85	9445.55
3044.42	9441.31
3046.99	9495.28
3049.56	9464.87
3052.13	9444.18
3054.69	9493.66
3057.26	9482.73
3059.83	9510.1
3062.39	9496.65
3064.95	9503.15
3067.52	9520.28
3070.08	9527.53
3072.64	9491.21
3075.2	9518.63
3077.76	9512.61
3080.32	9450.44
3082.88	9476.92
3085.44	9522.79
3087.99	9514.93
3090.55	9530.15
3093.1	9569.63
3095.65	9522.48
3098.21	9566.23
3100.76	9567.87
3103.31	9627.03
3105.86	9572.46
3108.41	9664.46
3110.96	9700.41
3113.5	9715.75
3116.05	9745.71
3118.59	9774.64
3121.14	9754.55
3123.68	9799.9
3126.23	9844.72
3128.77	9826
3131.31	9881.12
3133.85	9956.68
3136.39	9949.27
3138.93	9965.68
3141.46	9974.82
3144	9990.15
3146.54	10053.2
3149.07	10099.5
3151.6	10124.4
3154.14	10107.5
3156.67	10192.8
3159.2	10241.5
3161.73	10239.4
3164.26	10222.4
3166.79	10262.5
3169.32	10197
3171.84	10257.1
3174.37	10219.8
3176.9	10193.1
3179.42	10171.3
3181.94	10134.9
3184.47	10163
3186.99	10103.2
3189.51	10148.8
3192.03	10121.1
3194.55	10096.7
3197.07	10083.1
3199.58	10083.4
3202.1	10109.1
3204.62	10041.1
3207.13	10050.9
3209.65	10004.2
3212.16	10014
3214.67	9934.93
3217.18	9933.85
3219.69	9911.85
3222.2	9867.01
3224.71	9889.7
3227.22	9845.28
3229.73	9818.68
3232.23	9805.02
3234.74	9785.54
3237.24	9760.97
3239.75	9714.1
3242.25	9686.94
3244.75	9658.3
3247.25	9651.88
3249.75	9612.69
3252.25	9602.7
3254.75	9534.3
3257.25	9502.31
3259.74	9459.1
3262.24	9432.08
3264.73	9408.55
3267.23	9380.75
3269.72	9367.79
3272.21	9330.74
3274.7	9318.39
3277.2	9270.35
3279.69	9276.4
3282.17	9214.78
3284.66	9179.58
3287.15	9206.27
3289.64	9127.23
3292.12	9121.09
3293.56	9125.56
3296.05	9100.46
3298.55	9045.05
3301.04	9069.67
3303.54	9039.52
3306.03	9039.9
3308.52	8995.05
3311.01	9005.23
3313.5	8931.49
3315.99	8911.71
3318.48	8909.11
3320.97	8914.66
3323.45	8870.21
3325.94	8884.47
3328.42	8826.86
3330.91	8835.24
3333.39	8853.51
3335.87	8865.31
3338.36	8778.18
3340.84	8767.06
3343.32	8736.78
3345.8	8718.05
3348.27	8717.05
3350.75	8678.95
3353.23	8682.6
3355.7	8682.55
3358.18	8617.7
3360.65	8605.07
3363.13	8626.82
3365.6	8613.48
3368.07	8589.49
3370.54	8556.04
3373.01	8574.41
3375.48	8548.16
3377.95	8529.59
3380.42	8483.38
3382.88	8507.14
3385.35	8468.52
3387.81	8449.45
3390.28	8391.36
3392.74	8445.54
3395.2	8396.81
3397.67	8383.33
3400.13	8384.69
3402.58	8383.16
3405.05	8302.03
3407.5	8331.09
3409.96	8261.92
3412.42	8238.01
3414.87	8210.84
3417.33	8224.11
3419.78	8193.21
3422.23	8116.2
3424.69	8151.13
3427.14	8132.33
3429.59	8073.75
3432.04	8061.94
3434.49	7970.74
3436.94	7945.65
3439.39	7943.5
3441.83	7928.32
3444.28	7875.92
3446.72	7809.64
3449.17	7777.02
3451.61	7764.29
3454.05	7727.87
3456.5	7688
3458.94	7683.69
3461.38	7613.2
3463.81	7602.7
3466.25	7536.87
3468.69	7504.48
3471.13	7450.29
3473.56	7419.17
3476	7352.37
3478.43	7294.08
3480.87	7297.63
3483.3	7222.53
3485.73	7149.18
3488.16	7098.96
3490.59	7084.33
3493.02	7045.89
3495.45	6972.52
3497.88	6919.25
3499.09	6901.94