File: src/Milk_AI/Heritage toned RT 532nm 50% 600g 50xL 10s 10times 400-3500cm-1 200hole.txt
#Acq. time (s)=	10
#Accumulations=	10
#Range (cm-¹)=	400...3500
#Windows=	3
#Auto scanning=	Off
#Autofocus=	Off
#AutoExposure=	Off
#Spike filter=	Multiple accum.
#Delay time (s)=	0
#Binning=	1
#Readout mode=	Signal
#DeNoise=	Off
#ICS correction=	On
#Dark correction=	Off
#Inst. Process=	Off
#Detector Gain=	Best Dynamic Range
#Detector ADC=	45 kHz
#Detector temperature (°C)=	-60.1
#Instrument=	LabRAM HR Evol
#Detector=	Syncerity OE
#Objective=	x50_VIS_LWD
#Grating=	600 (500nm)
#ND Filter=	50%
#Laser=	532nm_Edge
#Hole=	199.981
#Range=	Visible
#E-Cal_Neon=	0
#StageXY=	75x50mm Scan+
#StageZ=	Z motor
#X (µm)=	0
#Y (µm)=	0
#Z (µm)=	830.8
#Spectral res.(cm-¹)=	12.8
#Full time(mm:ss)=	5:19
#AC=	Calibrated 2025-06-30 10:26
#Project=
#Sample=
#Site=
#Title=	D_99
#Remark=
#Date=	30.06.2025 14:12 (India Standard Time)
#Acquired=	30.06.2025 14:12:45 (India Standard Time)
#AxisType[0]=Intens
#AxisUnit[0]=Cnt
#AxisType[1]=Spectr
#AxisUnit[1]=1/cm
400.17	23022.2
403.717	22906.4
407.263	23007.1
410.807	22935.8
414.35	22920.4
417.892	22891.5
421.432	22897.3
424.971	22877.5
428.509	22920.2
432.045	22907.4
435.58	22831.8
439.111	22851.6
442.643	22834.7
446.174	22798.4
449.701	22719
453.229	22771.7
456.756	22737.2
460.279	22673.2
463.803	22652
467.326	22585.3
470.845	22523
474.365	22543.1
477.882	22536.6
481.399	22535.8
484.913	22497.4
488.425	22469
491.938	22409.8
495.448	22453.4
498.956	22486.7
502.465	22485.2
505.971	22536.1
509.475	22537.9
512.981	22569.2
516.482	22558.8
519.983	22437.4
523.482	22383.1
526.979	22427.5
530.476	22407.2
533.971	22316.6
537.464	22292.4
540.956	22226.9
544.447	22140.1
547.937	22205.1
551.425	22117.5
554.912	22110.8
558.398	22082.2
561.882	22094.5
565.365	22118.9
568.847	22086.9
572.325	22073.1
575.804	22084
579.282	22070.5
582.756	22058.2
586.231	22134.3
589.705	22060
593.175	21999
596.646	21995.5
600.116	21987.5
603.582	22012.8
607.049	21943.1
610.513	21959.2
613.977	21851.1
617.438	21832.6
620.898	21699.2
624.359	21705.3
627.816	21643.9
631.272	21447.3
634.728	21573.3
638.181	21541.1
641.633	21627.6
645.084	21472.6
648.535	21428.2
651.983	21340
655.43	21378.6
658.875	21355.4
662.319	21388.9
665.762	21319.9
669.203	21351.2
672.643	21235.8
676.082	21275.7
679.519	21264.2
682.955	21282.5
686.39	21289.8
689.824	21194.1
693.256	21221.3
696.685	21212.1
700.115	21226
703.543	21220
706.97	21140.2
710.394	21120.7
713.818	21032.5
717.241	21021.2
720.661	21056.4
724.082	21003.1
727.501	21000.2
730.917	20904.3
734.334	20844.7
737.747	20864.7
741.161	20767.9
744.572	20755.1
747.982	20708.2
751.392	20779.6
754.799	20780.3
758.205	20781.7
761.611	20743.3
765.014	20842.8
768.416	20776.6
771.816	20837.1
775.218	20773.6
778.616	20780.2
782.012	20740.8
785.408	20774.3
788.802	20687.7
792.195	20675.8
795.586	20670.9
798.977	20642.5
802.365	20584.4
805.753	20668.6
809.14	20600.8
812.525	20468.8
815.907	20492.3
819.289	20448.1
822.671	20504
826.051	20588.9
829.43	20542.6
832.805	20461.7
836.182	20472.8
839.557	20440.5
842.928	20464.4
846.301	20534.9
849.67	20544.8
853.04	20452
856.407	20513.5
859.774	20504.2
863.138	20514.6
866.503	20491
869.865	20354.6
873.225	20425.5
876.586	20491.9
879.944	20357.4
883.301	20328.5
886.658	20300.9
890.012	20264.3
893.365	20206.4
896.717	20161.1
900.067	20018.2
903.416	20024.7
906.766	19900.8
910.112	19840.1
913.458	19830.7
916.802	19782.6
920.145	19770.9
923.484	19757.3
926.825	19612.7
930.164	19563.8
933.501	19494.3
936.838	19445.8
940.173	19585.5
943.505	19520.4
946.838	19563.6
950.17	19513.8
953.5	19483.7
956.827	19465.7
960.155	19480.4
963.48	19500
966.805	19455
970.128	19428.3
973.45	19359.2
976.77	19278.1
980.091	19324.9
983.408	19361.3
986.726	19363.3
990.041	19374.7
993.354	19362.8
996.668	19466.9
999.979	19680
1003.29	19884.9
1006.6	19835.3
1009.91	19562.5
1013.21	19442.7
1016.52	19361.2
1019.82	19216.1
1023.12	19209.9
1026.43	19096.8
1029.73	19089.3
1033.02	18971.7
1036.32	19006.1
1039.62	19004.4
1042.91	18912.3
1046.21	18871
1049.5	18864
1052.79	18847.6
1056.08	18942.6
1059.37	18935.5
1062.65	19048.3
1065.94	18983.1
1069.23	18882.7
1072.51	18891.7
1075.79	18851.9
1079.07	18974.4
1082.35	18938.9
1085.63	18893.9
1088.91	18873.6
1092.18	18642.4
1095.46	18597.2
1098.73	18488.5
1102	18492.7
1105.27	18414.2
1108.54	18382.8
1111.81	18437.7
1115.08	18473.9
1118.34	18483.8
1121.61	18499.5
1124.87	18569.4
1128.13	18499.6
1131.39	18429.1
1134.65	18267
1137.91	18213.8
1141.17	18182.8
1144.42	18325.8
1147.68	18557.9
1150.93	19104.4
1154.18	19574.1
1157.43	19681.3
1160.68	19190.6
1163.93	18501.9
1167.18	18014.7
1170.42	17891.7
1173.67	17798.5
1176.91	17759.3
1180.15	17670.2
1183.39	17632.1
1186.63	17729.4
1189.87	17724
1193.11	17695
1196.34	17601.8
1199.58	17534.9
1202.81	17385
1206.04	17362.7
1209.27	17398.2
1212.5	17339.8
1215.73	17240.2
1218.95	17191.2
1222.18	17137.9
1225.4	17162.9
1228.63	17178.4
1231.85	17120.1
1235.07	17140.4
1238.29	17026
1241.51	17139.4
1244.72	17224.1
1247.94	17190.4
1251.15	17172.7
1254.37	17208.8
1257.58	17212.9
1260.79	17206.8
1264	17230.8
1267.21	17231.2
1270.41	17109.7
1273.62	17046.8
1276.82	17046.1
1280.03	16968.4
1283.23	16965.5
1286.43	16825
1289.63	16920.9
1292.83	17102.2
1296.03	17230.4
1299.22	17341.7
1302.42	17299.5
1305.61	17275.3
1308.8	17073.3
1311.99	16932.8
1315.18	16782.3
1318.37	16658.7
1321.56	16574.6
1324.74	16551.9
1327.93	16420.7
1331.11	16399.6
1334.3	16414.6
1337.48	16363.6
1340.66	16402.4
1343.84	16272.8
1347.01	16240.2
1350.19	16179.9
1353.37	16211.5
1356.54	16119.2
1359.71	16039.4
1362.88	15997.6
1366.05	15960.7
1369.22	15959.6
1372.39	15907.4
1375.56	15769.5
1378.72	15758.3
1381.89	15630.4
1385.05	15619.9
1388.21	15638.4
1391.37	15574.8
1394.53	15589.4
1397.69	15490.6
1400.85	15502.5
1404	15504.6
1407.16	15439.3
1410.31	15522.3
1413.46	15634.2
1416.61	15613
1419.76	15610.5
1422.91	15643.6
1426.06	15704
1429.21	15927.9
1432.35	16278.1
1435.49	16704.7
1438.64	16852
1441.78	16905.3
1444.92	16767.2
1448.06	16567.5
1451.2	16486.2
1454.33	16432.8
1457.47	16380.8
1460.6	16160
1463.74	15948.2
1466.87	15749.4
1470	15535.1
1473.13	15322.9
1476.26	15131.8
1479.38	14951.6
1482.51	14883
1485.63	14835.1
1488.76	14788.3
1491.88	14801.4
1495	14845.2
1498.12	14906.4
1501.24	14923
1504.36	14965.8
1507.47	15129.5
1510.59	15456.6
1513.7	15768.5
1516.81	16147.4
1519.93	16348.9
1523.04	16340.6
1526.15	16095.2
1529.25	15589.6
1532.36	15074.7
1535.47	14712.9
1538.57	14491.1
1541.67	14349.3
1544.78	14275.3
1547.88	14183.1
1550.98	14104.6
1554.08	14084.7
1557.18	14143.4
1560.27	14000.9
1563.37	14063.8
1566.46	13928
1569.55	13967.3
1572.64	13928.8
1575.74	13940.8
1578.83	13935.6
1581.91	13925.2
1585	13922.3
1588.09	13855.6
1591.17	13844.9
1594.25	13853.5
1597.34	13902.6
1600.42	13791.1
1603.5	13769
1606.58	13806.7
1609.65	13791.1
1612.73	13708.5
1615.8	13698.5
1618.88	13632.8
1621.95	13611
1625.03	13630.4
1628.1	13596.7
1631.17	13645.8
1634.23	13651
1637.3	13614.8
1640.37	13650.1
1643.43	13635.1
1646.5	13799.3
1649.56	13908.7
1652.62	14074.5
1655.68	14054.6
1658.74	13900.3
1661.8	13670.7
1664.85	13576.9
1667.91	13457.7
1670.96	13406.4
1674.02	13283.6
1677.07	13230.1
1680.12	13101.1
1683.17	13026.7
1686.22	12909
1689.27	12887.1
1692.31	12853
1695.36	12726
1698.4	12724.8
1701.45	12649.6
1704.49	12611.6
1707.53	12611.6
1710.57	12531.3
1713.61	12507.6
1716.65	12401.1
1719.68	12437.4
1722.72	12368
1725.75	12318.5
1728.78	12366.5
1731.82	12396.8
1734.84	12382.3
1737.87	12421.8
1740.9	12433.8
1743.93	12462.9
1746.96	12409.8
1749.98	12367
1753	12262.7
1756.03	12167.4
1759.05	12098.9
1762.07	11985.2
1765.09	12001.2
1768.11	11938.9
1771.12	11907
1774.14	11876.5
1777.15	11855
1780.17	11844.5
1783.18	11775.3
1786.19	11773.6
1789.2	11774.4
1792.21	11692.8
1795.22	11764.4
1798.22	11662.4
1801.23	11671.3
1804.23	11665.4
1807.24	11605
1810.24	11577.4
1813.24	11582
1816.24	11508.3
1819.24	11519
1822.24	11483.3
1825.23	11451.6
1828.23	11464.4
1831.22	11421.9
1834.22	11438.3
1837.21	11379
1840.2	11380.7
1843.19	11356.7
1846.18	11333.7
1849.17	11299.8
1852.15	11264.6
1855.14	11218.3
1858.12	11211
1861.11	11177.4
1864.09	11191.5
1867.07	11132.7
1870.05	11140.3
1873.03	11071.1
1876.01	11087
1878.98	11030.3
1881.96	11015
1884.93	10953.6
1887.91	10985.3
1890.88	10922.2
1893.85	10966.8
1896.82	10797.8
1899.79	10811.4
1902.76	10739.2
1905.72	10652.9
1908.69	10599.7
1911.65	10512.6
1914.62	10447.6
1917.58	10323.4
1920.54	10252.7
1923.5	10212.9
1926.46	10125.1
1929.42	10103.7
1932.37	10014
1935.33	9925.35
1938.28	9862.64
1941.24	9746.98
1944.19	9745.6
1947.14	9660.9
1950.09	9589.47
1953.04	9502.98
1955.99	9420.93
1958.93	9343.43
1961.88	9275.93
1964.82	9249.29
1967.77	9178.97
1970.71	9124.34
1973.65	9056.59
1976.59	9026.44
1979.53	8946.35
1982.47	8885.73
1985.41	8834.16
1988.34	8777.43
1991.28	8736.33
1994.21	8656.38
1997.14	8595.45
2000.07	8525.66
2003.01	8479.88
2005.94	8455.63
2008.86	8412.25
2011.79	8363.7
2014.72	8290.12
2017.64	8251
2020.57	8166.61
2023.49	8126.69
2026.41	8108.89
2029.33	8079.71
2032.25	8020.79
2035.17	7941.12
2038.09	7925.27
2041	7891.35
2043.92	7848.47
2045.86	7837.61
2048.79	7843.38
2051.71	7778.29
2054.64	7773.37
2057.56	7777.96
2060.48	7784.71
2063.4	7748.05
2066.32	7747.39
2069.24	7738.96
2072.16	7715.72
2075.08	7700.16
2077.99	7680.99
2080.91	7665.85
2083.82	7617.76
2086.74	7626.75
2089.65	7640.57
2092.56	7586.27
2095.47	7588.58
2098.38	7566.37
2101.29	7557.51
2104.19	7521.81
2107.1	7495.14
2110	7518.67
2112.91	7529.72
2115.81	7468.89
2118.71	7468.58
2121.61	7424.51
2124.51	7451.67
2127.4	7419.42
2130.3	7382.91
2133.2	7372.99
2136.09	7368.48
2138.99	7374.32
2141.88	7357.81
2144.77	7359.41
2147.66	7318.1
2150.55	7343.69
2153.44	7288.96
2156.33	7272.01
2159.21	7255.14
2162.1	7304.26
2164.98	7269.07
2167.87	7240.67
2170.75	7231.34
2173.63	7229.44
2176.51	7226.45
2179.39	7200.19
2182.27	7198.44
2185.14	7157.23
2188.02	7150.39
2190.9	7140.32
2193.77	7109.22
2196.64	7088.27
2199.51	7092.58
2202.39	7094.25
2205.25	7075.78
2208.12	7078.22
2210.99	6993.94
2213.86	6994.7
2216.72	6956.64
2219.59	6966.25
2222.45	6964.21
2225.31	6932.06
2228.17	6939.81
2231.03	6910.89
2233.89	6892.9
2236.75	6873.07
2239.61	6845
2242.46	6858.41
2245.32	6806.27
2248.17	6762.54
2251.03	6759.4
2253.88	6782.43
2256.73	6710.41
2259.58	6723.5
2262.43	6693.1
2265.28	6638.79
2268.12	6665.85
2270.97	6630.32
2273.81	6601.88
2276.66	6567.6
2279.5	6547.47
2282.34	6533.16
2285.18	6546.49
2288.02	6497.35
2290.86	6527.67
2293.7	6454.04
2296.54	6469.51
2299.37	6474.38
2302.21	6444.86
2305.04	6433.43
2307.87	6408.02
2310.7	6390.14
2313.53	6382.25
2316.36	6356.71
2319.19	6309.4
2322.02	6317.72
2324.85	6336.71
2327.67	6491.33
2330.5	6567.3
2333.32	6286.7
2336.14	6206.47
2338.96	6207.33
2341.78	6181.75
2344.6	6188.87
2347.42	6137.8
2350.24	6103.8
2353.05	6107.38
2355.87	6065.11
2358.68	6059.53
2361.5	6023.24
2364.31	6022.68
2367.12	6010.88
2369.93	6005.27
2372.74	5991.97
2375.55	5939.86
2378.35	5970.64
2381.16	5954.53
2383.96	5912.44
2386.77	5929.22
2389.57	5918.13
2392.37	5895.42
2395.17	5878.74
2397.97	5816.66
2400.77	5835.2
2403.57	5824.26
2406.37	5808.23
2409.16	5788.55
2411.96	5789.83
2414.75	5795.52
2417.55	5766.47
2420.34	5729.24
2423.13	5716.24
2425.92	5719.79
2428.71	5716
2431.5	5723.29
2434.28	5675.46
2437.07	5643.9
2439.85	5669.7
2442.64	5639.83
2445.42	5619.08
2448.2	5619.81
2450.98	5616.87
2453.76	5583.39
2456.54	5577.16
2459.32	5553.09
2462.1	5540.52
2464.87	5549.03
2467.65	5510.33
2470.42	5488.88
2473.2	5485.83
2475.97	5492.23
2478.74	5467.89
2481.51	5461.8
2484.28	5448.13
2487.05	5425.89
2489.81	5397.86
2492.58	5389.39
2495.34	5398.51
2498.11	5371.32
2500.87	5373.03
2503.63	5324.41
2506.39	5324.72
2509.15	5313.17
2511.91	5273.28
2514.67	5245.42
2517.43	5294
2520.19	5265.66
2522.94	5244.28
2525.7	5249.24
2528.45	5233.14
2531.2	5225.42
2533.95	5219.21
2536.7	5173.8
2539.45	5153.94
2542.2	5176.2
2544.95	5172.21
2547.69	5130.75
2550.44	5120.85
2553.18	5126.25
2555.93	5077.07
2558.67	5088.11
2561.41	5088.71
2564.15	5057.24
2566.89	5038.67
2569.63	5058.09
2572.36	5022.98
2575.1	5047.77
2577.84	5008.34
2580.57	5007.18
2583.31	4984.83
2586.04	4994.82
2588.77	4984.73
2591.5	4970.27
2594.23	5005.45
2596.96	4998.19
2599.69	4984.2
2602.41	4962.05
2605.14	4920.96
2607.86	4932.67
2610.59	4928.77
2613.31	4890.85
2616.03	4877.6
2618.75	4871.59
2621.48	4851.1
2624.19	4853.14
2626.91	4856.82
2629.63	4847.58
2632.35	4837.87
2635.06	4862.47
2637.77	4795.05
2640.49	4822.18
2643.2	4787.6
2645.91	4790.83
2648.62	4796.66
2651.33	4788.87
2654.04	4771.52
2656.75	4735.3
2659.45	4752.26
2662.16	4772.36
2664.86	4730.48
2667.57	4724.18
2670.27	4741.8
2672.97	4699.94
2675.67	4702.07
2678.37	4709.76
2681.07	4684.83
2683.77	4675.2
2686.47	4683.78
2689.16	4676.1
2691.86	4630.69
2694.55	4637.73
2697.25	4623.95
2699.94	4615.33
2702.63	4610.57
2705.32	4636.94
2708.01	4629.17
2710.7	4618.84
2713.39	4624.14
2716.07	4616.87
2718.76	4618.09
2721.44	4591.49
2724.12	4593.63
2726.81	4595.42
2729.49	4594.67
2732.17	4579.02
2734.85	4533.67
2737.53	4538.38
2740.21	4508.35
2742.88	4500.92
2745.56	4449.6
2748.24	4424.06
2750.91	4427.62
2753.58	4418.92
2756.25	4396.65
2758.93	4386.75
2761.6	4386.46
2764.27	4386.3
2766.93	4351.39
2769.6	4382.17
2772.27	4325.34
2774.93	4331.17
2777.6	4315.39
2780.26	4280
2782.93	4334.39
2785.59	4271.56
2788.25	4284.08
2790.91	4244.46
2793.57	4270.96
2796.23	4273.18
2798.88	4279.43
2801.54	4254.9
2804.2	4229.52
2806.85	4239.28
2809.5	4220.78
2812.16	4208.39
2814.81	4217.73
2817.46	4217.76
2820.11	4235.3
2822.76	4289.93
2825.4	4275.29
2828.05	4283.22
2830.7	4281.47
2833.34	4323.15
2835.99	4400.99
2838.63	4498.38
2841.27	4665.47
2843.91	4935.27
2846.55	5248.08
2849.19	5520.87
2851.83	5624.24
2854.47	5597.74
2857.11	5519.15
2859.74	5430.25
2862.38	5374.23
2865.01	5317.29
2867.65	5297.05
2870.28	5303.66
2872.91	5433.56
2875.54	5482.15
2878.17	5542.47
2880.8	5602.7
2883.42	5649.39
2886.05	5660.47
2888.68	5706.06
2891.3	5664.81
2893.93	5658.43
2896.55	5672.15
2899.17	5661.57
2901.79	5650.63
2904.41	5608.94
2907.03	5638.68
2909.65	5601.09
2912.27	5594.16
2914.88	5594.29
2917.5	5551.89
2920.11	5557.16
2922.73	5590.78
2925.34	5567.09
2927.95	5540.06
2930.56	5578.46
2933.17	5592.36
2935.78	5517.82
2938.39	5473.45
2941	5358.29
2943.6	5221.99
2946.21	5078.47
2948.81	4956.69
2951.42	4834.98
2954.02	4790.27
2956.62	4751.88
2959.22	4722.92
2961.82	4680.17
2964.42	4648.9
2967.02	4569.49
2969.62	4526.43
2972.21	4438.65
2974.81	4415.22
2977.4	4371.8
2980	4288.62
2982.59	4282.22
2985.18	4236.85
2987.77	4216.93
2990.36	4198.91
2992.95	4161.36
2995.54	4125.61
2998.13	4116.04
3000.72	4103.22
3003.3	4085.42
3005.89	4090.78
3008.47	4045.19
3011.05	4069.5
3013.63	4016.75
3016.22	4017.16
3018.8	3983.96
3021.38	3976.53
3023.95	3950.82
3026.53	3991.88
3029.11	3952.98
3031.68	3942.59
3034.26	3936.82
3036.83	3953.28
3039.4	3975.64
3041.98	3956.57
3044.55	3954.4
3047.12	3963.99
3049.69	3990.09
3052.26	3990.37
3054.82	4012.67
3057.39	4020.34
3059.96	3999.82
3062.52	4045.77
3065.09	4063.75
3067.65	4057.41
3070.21	4059.87
3072.77	4089.35
3075.33	4088.79
3077.89	4103.55
3080.45	4070.22
3083.01	4104.51
3085.57	4099.7
3088.12	4132.48
3090.68	4137.63
3093.23	4166.7
3095.79	4156.1
3098.34	4182.62
3100.89	4217.74
3103.44	4237.74
3105.99	4241.89
3108.54	4262.66
3111.09	4298.47
3113.63	4325.2
3116.18	4344.08
3118.73	4355.97
3121.27	4395.19
3123.82	4419.31
3126.36	4476.97
3128.9	4456.04
3131.44	4499.05
3133.98	4527.67
3136.52	4565.57
3139.06	4597.99
3141.6	4617.72
3144.13	4611.29
3146.67	4659.78
3149.2	4713.02
3151.74	4709.08
3154.27	4737.76
3156.8	4794.13
3159.34	4772.07
3161.86	4839.68
3164.4	4832.83
3166.92	4871.55
3169.45	4923.97
3171.98	4918.09
3174.5	4962.8
3177.03	4945.24
3179.56	4955.42
3182.08	4962.03
3184.6	4972.97
3187.12	4996.45
3189.64	5003.68
3192.16	4985.76
3194.68	5011.37
3197.2	4986.24
3199.72	5004.96
3202.24	5000.67
3204.75	5048.08
3207.27	5031.27
3209.78	5023.09
3212.29	5007.68
3214.81	5025.72
3217.32	4995.26
3219.83	5015.37
3222.34	5002.74
3224.85	4988.15
3227.35	4991.35
3229.86	5000.43
3232.37	5013.59
3234.87	4982.56
3237.38	4988.4
3239.88	4965.73
3242.38	4965.37
3244.89	4955.31
3247.39	4942.31
3249.89	4951.7
3252.39	4920.23
3254.88	4920.71
3257.38	4891.93
3259.88	4863.15
3262.37	4884.53
3264.87	4862.36
3267.36	4846.79
3269.86	4842.65
3272.35	4838.19
3274.84	4840.79
3277.33	4823.48
3279.82	4804.06
3282.31	4770.29
3284.8	4796.43
3287.29	4780.97
3289.77	4779.02
3292.26	4771.47
3294.15	4753.64
3296.64	4733.35
3299.14	4744.23
3301.63	4715.9
3304.12	4767.43
3306.62	4714.04
3309.11	4750.62
3311.6	4718.04
3314.09	4701.92
3316.58	4698.68
3319.07	4696.77
3321.56	4718.05
3324.04	4688.55
3326.53	4708.17
3329.01	4690.54
3331.5	4681.32
3333.98	4664.67
3336.46	4671.35
3338.94	4672.28
3341.42	4662.72
3343.9	4678.64
3346.38	4674.91
3348.86	4653.34
3351.34	4663
3353.82	4635.45
3356.29	4669.69
3358.77	4626.44
3361.24	4655.81
3363.71	4632.79
3366.19	4624.86
3368.66	4648.9
3371.13	4643.55
3373.6	4652.6
3376.07	4645.19
3378.54	4647.52
3381	4634.31
3383.47	4610.86
3385.94	4623.16
3388.4	4598.97
3390.87	4597.24
3393.33	4609.25
3395.79	4599.24
3398.25	4624.48
3400.71	4587.24
3403.17	4575.74
3405.63	4560.47
3408.09	4567.68
3410.55	4555.17
3413	4570.47
3415.46	4531.5
3417.92	4530.88
3420.37	4520.27
3422.82	4537.75
3425.27	4517.68
3427.73	4480.96
3430.18	4500.02
3432.63	4476.97
3435.08	4492.61
3437.53	4462.3
3439.97	4439.1
3442.42	4384.89
3444.86	4389.01
3447.31	4369.31
3449.75	4372.45
3452.2	4349.57
3454.64	4325.4
3457.08	4318.67
3459.52	4298.19
3461.96	4277.37
3464.4	4255.79
3466.84	4255.86
3469.28	4213.25
3471.72	4185.85
3474.15	4128.69
3476.59	4147.57
3479.02	4081.15
3481.45	4076.23
3483.89	4025.72
3486.32	4054.89
3488.75	4013.34
3491.18	3956.83
3493.61	3949.58
3496.04	3926.94
3498.47	3872.12
3499.68	3871.48