File: src/Milk_AI/Heritage full cream basic 532nm 50% 600g 50xL 10s 10times 400-3500cm-1 200hole.txt
#Acq. time (s)=	10
#Accumulations=	10
#Range (cm-¹)=	400...3500
#Windows=	3
#Auto scanning=	Off
#Autofocus=	Off
#AutoExposure=	Off
#Spike filter=	Multiple accum.
#Delay time (s)=	0
#Binning=	1
#Readout mode=	Signal
#DeNoise=	Off
#ICS correction=	On
#Dark correction=	Off
#Inst. Process=	Off
#Detector Gain=	Best Dynamic Range
#Detector ADC=	45 kHz
#Detector temperature (°C)=	-60.1
#Instrument=	LabRAM HR Evol
#Detector=	Syncerity OE
#Objective=	x50_VIS_LWD
#Grating=	600 (500nm)
#ND Filter=	50%
#Laser=	532nm_Edge
#Hole=	199.981
#Range=	Visible
#E-Cal_Neon=	0
#StageXY=	75x50mm Scan+
#StageZ=	Z motor
#X (µm)=	0
#Y (µm)=	0
#Z (µm)=	425.1
#Spectral res.(cm-¹)=	12.8
#Full time(mm:ss)=	5:19
#AC=	Calibrated 2025-07-01 10:31
#Project=
#Sample=
#Site=
#Title=	D_1
#Remark=
#Date=	01.07.2025 15:23 (India Standard Time)
#Acquired=	01.07.2025 15:23:45 (India Standard Time)
#AxisType[0]=Intens
#AxisUnit[0]=Cnt
#AxisType[1]=Spectr
#AxisUnit[1]=1/cm
400.083	17276
403.63	17109.3
407.176	17129.5
410.72	17140.7
414.263	17110.8
417.805	17189.5
421.345	17117
424.884	17116.9
428.421	17110.3
431.955	17089.7
435.49	17174
439.023	17081.9
442.555	17049.2
446.084	17008.1
449.613	16974.8
453.141	17007.2
456.666	16920.2
460.191	16948.9
463.715	16882.1
467.235	16923.1
470.756	16909.9
474.274	16799
477.793	16896.3
481.308	16784.4
484.823	16809.3
488.336	16802.5
491.847	16844.2
495.358	16725.5
498.867	16841.9
502.374	16818.2
505.881	16816.5
509.386	16815.8
512.888	16855.6
516.39	16775.4
519.89	16735
523.391	16721.3
526.889	16734.7
530.385	16705
533.88	16605.2
537.373	16621.1
540.866	16563.8
544.357	16561.8
547.846	16577
551.334	16545.4
554.821	16490.7
558.307	16435.9
561.789	16452.1
565.272	16479.8
568.753	16506
572.233	16477.2
575.712	16537.7
579.188	16476.7
582.664	16501
586.139	16481.7
589.611	16490.7
593.083	16447.1
596.554	16534.9
600.021	16477.8
603.49	16471.9
606.955	16473.2
610.42	16418
613.882	16399.7
617.345	16410.3
620.805	16348.9
624.263	16222.6
627.722	16202.9
631.178	16142.9
634.633	16246.6
638.088	16240
641.539	16251.8
644.99	16165.3
648.439	16120.1
651.887	16105.4
655.335	16092.9
658.781	16072.1
662.225	16126.2
665.667	16072.4
669.108	16098.6
672.548	16033.2
675.987	15996.5
679.424	15986.2
682.86	16021.6
686.293	15992.8
689.727	15925.8
693.159	15989
696.59	16029.6
700.019	16068.3
703.448	16032.7
706.872	16015.9
710.298	15955.1
713.723	15926.5
717.144	15966.4
720.565	15995.3
723.984	15983.9
727.403	15917.8
730.821	15927.3
734.235	15953.3
737.651	15919
741.063	15872.7
744.474	15884.9
747.885	15901.7
751.293	15931.8
754.702	15921.1
758.108	15931.3
761.512	15943.8
764.915	15905.5
768.319	15955.3
771.719	15902.8
775.118	15983.8
778.516	15904.1
781.913	15888.6
785.308	15917.5
788.702	15897.2
792.095	15868.5
795.486	15846.7
798.876	15835.3
802.265	15908
805.653	15871.4
809.039	15885.8
812.424	15948.9
815.808	15909.5
819.191	15945.3
822.572	16008.2
825.95	16155.7
829.329	16129.4
832.706	16158.7
836.08	16171.1
839.455	16171.5
842.829	16230.1
846.199	16280.7
849.57	16276.1
852.938	16348.6
856.307	16363.2
859.672	16387.8
863.038	16422.7
866.401	16384
869.765	16351.2
873.125	16425.4
876.484	16418.2
879.844	16295.3
883.2	16280.2
886.555	16290.2
889.909	16239.5
893.262	16115.6
896.616	15971.6
899.966	15866.3
903.315	15853.1
906.663	15745.9
910.009	15759.4
913.354	15787.7
916.698	15760.7
920.041	15754.6
923.383	15636.9
926.723	15604.9
930.062	15575.8
933.399	15559.5
936.734	15576.9
940.069	15590.9
943.403	15626
946.736	15653.2
950.065	15652.2
953.396	15643.1
956.725	15630.2
960.051	15613.4
963.377	15657.3
966.7	15597
970.025	15548
973.345	15528
976.667	15490.5
979.985	15484.1
983.304	15576.8
986.62	15615.3
989.935	15762.5
993.25	15865
996.563	16210.5
999.874	16484.8
1003.19	16375
1006.49	16119.7
1009.8	15935
1013.11	15715.2
1016.41	15740.9
1019.72	15696.1
1023.02	15645.5
1026.32	15556
1029.62	15586.8
1032.92	15541.3
1036.22	15503.6
1039.51	15542.3
1042.81	15507.5
1046.1	15529
1049.39	15522.6
1052.68	15686.7
1055.97	15863.9
1059.26	15964.1
1062.55	16029.2
1065.83	15854.8
1069.12	15858.2
1072.4	15974.7
1075.68	16033.2
1078.97	16016.8
1082.24	15913.9
1085.52	15851.6
1088.8	15755.1
1092.08	15588.3
1095.35	15487
1098.62	15316.8
1101.9	15287.7
1105.17	15198.8
1108.44	15308.9
1111.7	15400.1
1114.97	15522.5
1118.23	15590.3
1121.5	15636
1124.76	15647.7
1128.03	15504.1
1131.29	15276.7
1134.54	15285.6
1137.8	15338.4
1141.06	15536.7
1144.31	15931.7
1147.57	16590.9
1150.82	17514.6
1154.07	17790.3
1157.32	17031.9
1160.57	15984.5
1163.82	15454.5
1167.07	15129.6
1170.31	15096.5
1173.56	14972.6
1176.8	14943.3
1180.04	14936.3
1183.28	14993.6
1186.52	15042.6
1189.76	15018.8
1192.99	14884.5
1196.23	14807.3
1199.46	14662.8
1202.7	14709.1
1205.93	14626.7
1209.16	14620.3
1212.39	14611.1
1215.62	14437
1218.84	14349.7
1222.07	14363.2
1225.29	14419.2
1228.52	14383.1
1231.74	14417.4
1234.96	14557.6
1238.18	14599.5
1241.4	14611.5
1244.61	14665.1
1247.83	14713.3
1251.04	14795.3
1254.25	14855.6
1257.47	14893.8
1260.68	14906.1
1263.89	15011.1
1267.09	14880.4
1270.3	14835.2
1273.51	14761.4
1276.71	14746.8
1279.91	14793.8
1283.12	14785.9
1286.32	14892
1289.52	15243.9
1292.72	15595.7
1295.91	15716.1
1299.11	15701.1
1302.3	15551.9
1305.5	15317.7
1308.69	15105.1
1311.88	14904.2
1315.07	14628.2
1318.26	14548.2
1321.44	14398.2
1324.63	14342.8
1327.82	14241.7
1331	14224.6
1334.18	14125.1
1337.36	14143.3
1340.54	14148.9
1343.72	14059.1
1346.9	14073.4
1350.07	14031.1
1353.25	13986.4
1356.42	13964.5
1359.6	13889.1
1362.77	13879
1365.94	13890.8
1369.11	13809.9
1372.28	13791.5
1375.44	13652.9
1378.61	13648.1
1381.77	13628.1
1384.93	13568.1
1388.1	13642.7
1391.26	13625.1
1394.41	13598.8
1397.57	13537
1400.73	13562.8
1403.89	13576.6
1407.04	13661
1410.19	13732.4
1413.35	13912.3
1416.5	13966.5
1419.65	14097.3
1422.8	14179.3
1425.94	14622.1
1429.09	15189.7
1432.23	15942.2
1435.38	16357.3
1438.52	16376.5
1441.66	16170.2
1444.8	15936.6
1447.94	15761
1451.08	15587
1454.22	15435.2
1457.35	15198.2
1460.48	14941.4
1463.62	14647.1
1466.75	14256.5
1469.88	14000.5
1473.01	13675.2
1476.14	13555.8
1479.26	13406.2
1482.39	13297.1
1485.51	13297.8
1488.64	13301.1
1491.76	13313.5
1494.88	13461.8
1498	13557.2
1501.12	13688.8
1504.24	14000.7
1507.35	14420.3
1510.47	14967.3
1513.58	15498
1516.69	15881.1
1519.81	15936
1522.92	15653.8
1526.03	14928.6
1529.13	14197.1
1532.24	13541.2
1535.35	13281.6
1538.45	13059.6
1541.55	12977.9
1544.66	12875.2
1547.76	12786.3
1550.86	12788.6
1553.96	12745.7
1557.05	12674.1
1560.15	12647.5
1563.24	12691.4
1566.34	12653.5
1569.43	12658.8
1572.52	12670.6
1575.61	12647.5
1578.7	12667.6
1581.79	12700
1584.88	12716.7
1587.96	12664.1
1591.05	12702.4
1594.13	12706.1
1597.21	12714.6
1600.3	12698.4
1603.37	12695.8
1606.45	12647.1
1609.53	12738.5
1612.61	12629.1
1615.68	12593.5
1618.76	12586.3
1621.83	12598.3
1624.9	12606.5
1627.97	12627.8
1631.04	12655.2
1634.11	12734.2
1637.18	12726.7
1640.24	12850.8
1643.31	13071.5
1646.37	13348.4
1649.44	13694.4
1652.5	13641.7
1655.56	13337.7
1658.62	13073.4
1661.67	12877.3
1664.73	12769.3
1667.79	12678.5
1670.84	12603.9
1673.89	12429.3
1676.95	12310
1680	12263.3
1683.05	12187.4
1686.1	12101.4
1689.14	12097.2
1692.19	11989.2
1695.23	11941.1
1698.28	11874.1
1701.32	11824.2
1704.36	11828.6
1707.4	11734.9
1710.44	11765.5
1713.48	11694.2
1716.52	11710.8
1719.56	11682.5
1722.59	11743.8
1725.63	11732.2
1728.66	11844.4
1731.69	11853.8
1734.72	11972.4
1737.75	12047.5
1740.78	12099.9
1743.8	12034.2
1746.83	12025
1749.86	11942
1752.88	11771
1755.9	11623.8
1758.92	11526
1761.94	11451.4
1764.96	11392.4
1767.98	11419.1
1771	11383.4
1774.01	11367.3
1777.03	11356.4
1780.04	11297.6
1783.05	11306.4
1786.06	11276.1
1789.07	11329.1
1792.08	11284.5
1795.09	11266.8
1798.1	11258.8
1801.1	11216.3
1804.11	11233.8
1807.11	11128.3
1810.11	11182.2
1813.11	11172.3
1816.11	11167.3
1819.11	11077.4
1822.11	11078.6
1825.11	11106
1828.1	11123.4
1831.1	11076.2
1834.09	11038.4
1837.08	11053.9
1840.07	11066.3
1843.06	11060.6
1846.05	11058.5
1849.04	10992.5
1852.02	11028.3
1855.01	10986.9
1857.99	10988.9
1860.98	10905.5
1863.96	10969.3
1866.94	10920.9
1869.92	10966.1
1872.9	10906.6
1875.88	10908.3
1878.85	10891.6
1881.83	10873.3
1884.8	10877.8
1887.78	10796.3
1890.75	10790.1
1893.72	10815.1
1896.69	10748.9
1899.66	10741
1902.63	10697.6
1905.59	10654.2
1908.56	10589.3
1911.52	10577.6
1914.49	10457.2
1917.45	10430.1
1920.41	10346.5
1923.37	10331.6
1926.33	10302.8
1929.29	10269.1
1932.24	10200.6
1935.2	10126.3
1938.15	10100.3
1941.1	10036.8
1944.06	9999.41
1947.01	9954.13
1949.96	9913.68
1952.91	9861.85
1955.86	9781.01
1958.8	9746.4
1961.75	9726.94
1964.69	9688.79
1967.64	9637.44
1970.58	9618.99
1973.52	9554.14
1976.46	9528.65
1979.4	9496.99
1982.34	9425.31
1985.27	9407.07
1988.21	9357.56
1991.14	9352.98
1994.08	9269.98
1997.01	9232.59
1999.94	9165.8
2002.87	9156.56
2005.8	9105.53
2008.73	9095.1
2011.66	9051.2
2014.58	9034.89
2017.51	8995.01
2020.43	8969.18
2023.36	8920.43
2026.28	8874.06
2029.2	8852.85
2032.12	8808.87
2035.04	8787.76
2037.95	8777.34
2040.87	8747.78
2043.78	8712.2
2045.76	8681.79
2048.69	8713.95
2051.61	8675.25
2054.54	8664.94
2057.46	8670.79
2060.38	8669.18
2063.3	8594.45
2066.22	8623.43
2069.14	8583.45
2072.06	8635.54
2074.98	8594.54
2077.89	8550.92
2080.81	8579.44
2083.72	8586.4
2086.63	8562.92
2089.55	8539.55
2092.46	8582.2
2095.37	8525.28
2098.28	8508.51
2101.18	8519.37
2104.09	8530.43
2106.99	8486.58
2109.9	8506.16
2112.8	8448.4
2115.71	8473.1
2118.61	8460.53
2121.51	8470.95
2124.4	8440.08
2127.3	8415.64
2130.2	8390.42
2133.09	8444.73
2135.99	8430.55
2138.88	8399.2
2141.78	8411.41
2144.67	8407.46
2147.56	8384.48
2150.45	8401.03
2153.34	8388.59
2156.22	8396.59
2159.11	8395.34
2162	8362.08
2164.88	8413.18
2167.76	8356.17
2170.64	8308.82
2173.53	8362.31
2176.41	8365.9
2179.29	8326.75
2182.16	8302.42
2185.04	8314.12
2187.92	8257.42
2190.79	8292.77
2193.66	8307.24
2196.54	8255.21
2199.41	8266.92
2202.28	8266.55
2205.15	8255.76
2208.02	8226.45
2210.88	8169.2
2213.75	8207.18
2216.62	8172.57
2219.48	8152.26
2222.34	8173.35
2225.21	8140.44
2228.07	8146.08
2230.93	8080.22
2233.79	8097.84
2236.65	8112.38
2239.5	8075.27
2242.36	8073.85
2245.21	8057.77
2248.07	8018.25
2250.92	8020.49
2253.77	8009.15
2256.62	8002.78
2259.47	7983.24
2262.32	7906.1
2265.17	7930.81
2268.02	7905.07
2270.86	7879.38
2273.71	7881.17
2276.55	7873.61
2279.39	7887.22
2282.24	7843.68
2285.08	7837.78
2287.92	7809.76
2290.75	7814.22
2293.59	7772.93
2296.43	7788.81
2299.26	7786.77
2302.1	7795.98
2304.93	7780.83
2307.76	7741.05
2310.6	7720.22
2313.43	7744.71
2316.25	7666.53
2319.08	7678.21
2321.91	7719.75
2324.74	7841.1
2327.56	7979.14
2330.39	7680.51
2333.21	7581.68
2336.03	7530.25
2338.85	7591.54
2341.67	7545.6
2344.49	7536.77
2347.31	7517.7
2350.13	7489.36
2352.94	7501.99
2355.76	7473.69
2358.57	7444.9
2361.39	7477.91
2364.2	7409.72
2367.01	7420.11
2369.82	7376.26
2372.63	7415.73
2375.44	7388.1
2378.24	7407.17
2381.05	7398.93
2383.85	7367.06
2386.66	7343.23
2389.46	7362.57
2392.26	7359.61
2395.06	7327.79
2397.86	7339.62
2400.66	7314.6
2403.46	7290.34
2406.26	7311.56
2409.05	7276.57
2411.85	7293.28
2414.64	7274.84
2417.43	7258.12
2420.23	7272.21
2423.02	7254.84
2425.81	7232.89
2428.6	7228.55
2431.38	7213.36
2434.17	7186.03
2436.96	7161.25
2439.74	7153.04
2442.53	7159.71
2445.31	7141.36
2448.09	7178.51
2450.87	7118.59
2453.65	7117.75
2456.43	7136.42
2459.21	7118.93
2461.98	7081.12
2464.76	7081.03
2467.53	7069.37
2470.31	7050.06
2473.08	7083.08
2475.85	7076.69
2478.63	7045.28
2481.39	7069.3
2484.16	7032.26
2486.93	7017.35
2489.7	7016.82
2492.46	6996.63
2495.23	6996
2497.99	6993.72
2500.76	6976.95
2503.52	6926.75
2506.28	6967.91
2509.04	6962.41
2511.8	6940.93
2514.56	6923.71
2517.31	6935.77
2520.07	6902.88
2522.82	6913.8
2525.58	6896.96
2528.33	6907.16
2531.09	6889.85
2533.84	6873.99
2536.59	6878.93
2539.34	6854.56
2542.08	6869.34
2544.83	6841.65
2547.58	6835.89
2550.32	6838.93
2553.07	6811.93
2555.81	6786.51
2558.55	6801.26
2561.29	6766.28
2564.03	6794.4
2566.77	6771.72
2569.51	6777.46
2572.25	6774.55
2574.99	6771.21
2577.72	6772.58
2580.46	6810.29
2583.19	6754.63
2585.92	6802.86
2588.65	6741.55
2591.38	6813.59
2594.11	6738.46
2596.84	6767.38
2599.57	6778.01
2602.3	6749.29
2605.02	6742.85
2607.75	6784.65
2610.47	6765.38
2613.19	6749.77
2615.92	6717.24
2618.64	6685.73
2621.36	6705.69
2624.08	6725.38
2626.8	6731.56
2629.51	6709.11
2632.23	6699.12
2634.94	6721.23
2637.66	6721.9
2640.37	6720.13
2643.08	6691.86
2645.79	6699.63
2648.5	6706.93
2651.21	6707.68
2653.92	6695.05
2656.63	6706.34
2659.33	6707.36
2662.04	6727.63
2664.75	6709.48
2667.45	6706.27
2670.15	6733.15
2672.85	6735.79
2675.55	6709.4
2678.25	6683.44
2680.95	6641.98
2683.65	6706.06
2686.35	6677.59
2689.04	6666.5
2691.74	6682.54
2694.43	6651.13
2697.13	6683.13
2699.82	6657
2702.51	6653.74
2705.2	6717.6
2707.89	6701.29
2710.58	6743.6
2713.26	6730.96
2715.95	6744.54
2718.64	6720.4
2721.32	6728.82
2724	6729.66
2726.69	6729.41
2729.37	6714.89
2732.05	6679.47
2734.73	6631.37
2737.41	6651.53
2740.09	6590.79
2742.76	6581.9
2745.44	6573.33
2748.11	6541.4
2750.79	6504.04
2753.46	6513.71
2756.13	6517.77
2758.81	6455.01
2761.47	6437.42
2764.14	6464.28
2766.81	6473.86
2769.48	6444.57
2772.15	6451.63
2774.81	6412.28
2777.48	6455.71
2780.14	6424.48
2782.8	6440.02
2785.47	6436.31
2788.13	6395.1
2790.79	6436.63
2793.44	6438.06
2796.1	6440.64
2798.76	6477.31
2801.42	6435.77
2804.07	6441.89
2806.73	6426.7
2809.38	6437.7
2812.03	6495.21
2814.68	6526.24
2817.33	6521.45
2819.98	6574.31
2822.63	6594.46
2825.28	6647.58
2827.93	6726.02
2830.57	6853.11
2833.22	7037.35
2835.86	7305.49
2838.51	7675.68
2841.15	8345.95
2843.79	9070.46
2846.43	9772.67
2849.07	10073.7
2851.71	10029.4
2854.35	9839.58
2856.98	9557.69
2859.62	9434.95
2862.25	9291.72
2864.89	9261.02
2867.52	9325.34
2870.15	9528.74
2872.78	9650.1
2875.41	9762.62
2878.04	9951.04
2880.67	10071.1
2883.3	10087.1
2885.92	10102.8
2888.55	10102.9
2891.18	10100.4
2893.8	10113.6
2896.42	10087.7
2899.04	10067.5
2901.67	10058.8
2904.29	9987.26
2906.9	10004.9
2909.52	9960.87
2912.14	9943.2
2914.76	9902.9
2917.37	9902.9
2919.99	9900.81
2922.6	9880.44
2925.21	9913.78
2927.82	9919.07
2930.44	9908.64
2933.05	9841.09
2935.65	9741.41
2938.26	9440.6
2940.87	9190.99
2943.48	8808.19
2946.08	8512.52
2948.69	8361.46
2951.29	8238.5
2953.89	8165.06
2956.49	8060.64
2959.1	8044.74
2961.7	7917.93
2964.29	7792.11
2966.89	7706.05
2969.49	7555.29
2972.09	7440.42
2974.68	7343.17
2977.28	7253.92
2979.87	7163.63
2982.46	7128.32
2985.05	7008.94
2987.65	6982.52
2990.24	6937.52
2992.82	6906.69
2995.41	6923.69
2998	6870.83
3000.59	6878.99
3003.17	6863.56
3005.76	6845.02
3008.34	6837.18
3010.92	6779.27
3013.5	6742.83
3016.09	6705.18
3018.67	6674.13
3021.25	6650.47
3023.82	6620.54
3026.4	6638.28
3028.98	6596.51
3031.55	6586.29
3034.13	6597.33
3036.7	6595.42
3039.28	6621.87
3041.85	6634.21
3044.42	6615.03
3046.99	6624.67
3049.56	6651.62
3052.13	6674.43
3054.69	6733.15
3057.26	6721.36
3059.83	6728.8
3062.39	6745.58
3064.95	6773.55
3067.52	6769.35
3070.08	6779.97
3072.64	6788.92
3075.2	6794.5
3077.76	6840.28
3080.32	6845.87
3082.88	6851.1
3085.44	6857.27
3087.99	6887.4
3090.55	6904.7
3093.1	6924.92
3095.65	6935.03
3098.21	6944.2
3100.76	7005.77
3103.31	7021.45
3105.86	7097.1
3108.41	7099.06
3110.96	7130.59
3113.5	7194.84
3116.05	7207.14
3118.59	7229.97
3121.14	7267.67
3123.68	7292.93
3126.23	7356.29
3128.77	7401.84
3131.31	7442.67
3133.85	7444.78
3136.39	7510.56
3138.93	7547.18
3141.46	7558.95
3144	7617.33
3146.54	7669.36
3149.07	7720.85
3151.6	7740.38
3154.14	7785.14
3156.67	7873.65
3159.2	7863.73
3161.73	7872.61
3164.26	7938.76
3166.79	7967.76
3169.32	7965.48
3171.84	7994.35
3174.37	8053.31
3176.9	8033.27
3179.42	8006.59
3181.94	8017.34
3184.47	8085.67
3186.99	8075.29
3189.51	8156.05
3192.03	8122.17
3194.55	8125.6
3197.07	8129.93
3199.58	8127.61
3202.1	8168.81
3204.62	8140.28
3207.13	8179.8
3209.65	8167.58
3212.16	8189.25
3214.67	8166.05
3217.18	8148.19
3219.69	8170.86
3222.2	8161.12
3224.71	8165.39
3227.22	8150.68
3229.73	8144.2
3232.23	8159.96
3234.74	8154.57
3237.24	8148.42
3239.75	8143.51
3242.25	8137.5
3244.75	8091.76
3247.25	8117.86
3249.75	8083.32
3252.25	8091.08
3254.75	8046.69
3257.25	8065.61
3259.74	8029.57
3262.24	8027.26
3264.73	8019.13
3267.23	8007.42
3269.72	8021.69
3272.21	7985.7
3274.7	7992.89
3277.2	7970.06
3279.69	7966.75
3282.17	7952.68
3284.66	7957.65
3287.15	7925.84
3289.64	7928.93
3292.12	7928.03
3293.56	7915.97
3296.05	7926.15
3298.55	7929.02
3301.04	7902.8
3303.54	7897.51
3306.03	7894.71
3308.52	7910.73
3311.01	7874.64
3313.5	7843.93
3315.99	7868.18
3318.48	7863.24
3320.97	7885.25
3323.45	7870.11
3325.94	7896.83
3328.42	7874.68
3330.91	7836.12
3333.39	7895.12
3335.87	7890.76
3338.36	7885.2
3340.84	7863.61
3343.32	7888.37
3345.8	7869.6
3348.27	7893.25
3350.75	7888.28
3353.23	7855.96
3355.7	7865.52
3358.18	7840.29
3360.65	7883.84
3363.13	7849.19
3365.6	7851.05
3368.07	7856.81
3370.54	7886.56
3373.01	7900.88
3375.48	7900.5
3377.95	7899.02
3380.42	7865.72
3382.88	7882.83
3385.35	7869.3
3387.81	7857.01
3390.28	7880.35
3392.74	7827.98
3395.2	7873.3
3397.67	7886.85
3400.13	7895.07
3402.58	7912.63
3405.05	7846.52
3407.5	7819.67
3409.96	7829.17
3412.42	7781.07
3414.87	7830.9
3417.33	7779.24
3419.78	7810.28
3422.23	7790.05
3424.69	7773.14
3427.14	7774.71
3429.59	7725.44
3432.04	7727.51
3434.49	7740.06
3436.94	7702.93
3439.39	7702.42
3441.83	7688.51
3444.28	7638.07
3446.72	7616.82
3449.17	7588.61
3451.61	7600.43
3454.05	7566.56
3456.5	7514.12
3458.94	7521
3461.38	7497.99
3463.81	7467.31
3466.25	7468.03
3468.69	7448.39
3471.13	7375.41
3473.56	7348.78
3476	7356.47
3478.43	7300.65
3480.87	7300.52
3483.3	7211.36
3485.73	7212.47
3488.16	7186.66
3490.59	7111.57
3493.02	7107.86
3495.45	7076.59
3497.88	7032.85
3499.09	7029.84