File: src/Milk_AI/Heritage full cream RT 633nm 100% 600g 50xL 10s 10times 400-3500cm-1.txt
#Acq. time (s)=	10
#Accumulations=	10
#Range (cm-¹)=	400...3500
#Windows=	3
#Auto scanning=	Off
#Autofocus=	Off
#AutoExposure=	Off
#Spike filter=	Multiple accum.
#Delay time (s)=	0
#Binning=	1
#Readout mode=	Signal
#DeNoise=	Off
#ICS correction=	On
#Dark correction=	Off
#Inst. Process=	Off
#Detector Gain=	Best Dynamic Range
#Detector ADC=	45 kHz
#Detector temperature (°C)=	-60.1
#Instrument=	LabRAM HR Evol
#Detector=	Syncerity OE
#Objective=	x50_VIS_LWD
#Grating=	600 (500nm)
#ND Filter=	100%
#Laser=	532nm_Edge
#Hole=	199.981
#Range=	Visible
#E-Cal_Neon=	0
#StageXY=	75x50mm Scan+
#StageZ=	Z motor
#X (µm)=	0
#Y (µm)=	0
#Z (µm)=	310.3
#Spectral res.(cm-¹)=	12.8
#Full time(mm:ss)=	5:19
#AC=	Calibrated 2025-06-30 10:26
#Project=
#Sample=
#Site=
#Title=	D_102
#Remark=
#Date=	30.06.2025 10:51 (India Standard Time)
#Acquired=	30.06.2025 10:51:57 (India Standard Time)
#AxisType[0]=Intens
#AxisUnit[0]=Cnt
#AxisType[1]=Spectr
#AxisUnit[1]=1/cm
400.17	26494.5
403.717	26332.6
407.263	26418.9
410.807	26393.6
414.35	26365.4
417.892	26380.5
421.432	26390.4
424.971	26401.8
428.509	26390.8
432.045	26418.2
435.58	26434.6
439.111	26335.5
442.643	26348.1
446.174	26379.6
449.701	26365.7
453.229	26316.6
456.756	26280.6
460.279	26268.5
463.803	26161.3
467.326	26185.5
470.845	26194.6
474.365	26136.2
477.882	26157.7
481.399	26138.9
484.913	26117.4
488.425	26119.1
491.938	26127
495.448	26057
498.956	26218.7
502.465	26310.2
505.971	26253.1
509.475	26280.2
512.981	26300.4
516.482	26376.7
519.983	26223.6
523.482	26207.5
526.979	26158.8
530.476	26088.3
533.971	26085
537.464	26056.4
540.956	25956.5
544.447	26007.3
547.937	26149.4
551.425	25962.4
554.912	25977.4
558.398	25917.7
561.882	25906.9
565.365	25940.5
568.847	25990.3
572.325	26003.1
575.804	25955.6
579.282	26009.3
582.756	25996.1
586.231	26037
589.705	26100.2
593.175	26165.6
596.646	26177.5
600.116	26159.3
603.582	26305.4
607.049	26217.5
610.513	26165.3
613.977	26075.8
617.438	26098
620.898	26022.8
624.359	25918.7
627.816	25834.8
631.272	25758.5
634.728	25831.9
638.181	25859.1
641.633	25915.1
645.084	25853.6
648.535	25763.4
651.983	25722.5
655.43	25820.9
658.875	25763
662.319	25665
665.762	25701
669.203	25721.8
672.643	25669.9
676.082	25649.1
679.519	25692.6
682.955	25730.8
686.39	25771.9
689.824	25757.6
693.256	25834
696.685	25821.8
700.115	25857.5
703.543	25833.5
706.97	25793.5
710.394	25798.5
713.818	25810.2
717.241	25801.5
720.661	25968.2
724.082	25928.5
727.501	25906.9
730.917	25815.8
734.334	25844.6
737.747	25817.1
741.161	25759.7
744.572	25820
747.982	25787.1
751.392	25830.3
754.799	25863.8
758.205	25949.7
761.611	26004.7
765.014	26012.6
768.416	25961.6
771.816	26061.5
775.218	26038.4
778.616	26021.6
782.012	26033.9
785.408	26066
788.802	26017.4
792.195	26005.6
795.586	25972.2
798.977	26056.4
802.365	26157.5
805.753	26195.1
809.14	26158.6
812.525	26192.5
815.907	26219.1
819.289	26357.2
822.671	26504.4
826.051	26619.9
829.43	26752.1
832.805	26812.1
836.182	26757.8
839.557	26874.7
842.928	27077.2
846.301	27165.8
849.67	27168.2
853.04	27223.1
856.407	27225
859.774	27386.4
863.138	27316
866.503	27431.2
869.865	27405.4
873.225	27503
876.586	27422.7
879.944	27337.2
883.301	27288.5
886.658	27319.2
890.012	27425.7
893.365	27151.9
896.717	26935.8
900.067	26833.3
903.416	26760.2
906.766	26549.2
910.112	26536.3
913.458	26532.5
916.802	26459
920.145	26526.2
923.484	26401.4
926.825	26285.3
930.164	26236.8
933.501	26152.2
936.838	26168.8
940.173	26209.2
943.505	26189.9
946.838	26151.4
950.17	26141.2
953.5	26169.8
956.827	26209.1
960.155	26223.6
963.48	26244.3
966.805	26183.8
970.128	26159.3
973.45	26092.7
976.77	26020.3
980.091	26035.3
983.408	26011.1
986.726	26020.5
990.041	26074.2
993.354	26171.3
996.668	26467.9
999.979	27016.5
1003.29	27384.3
1006.6	27161.2
1009.91	26792.6
1013.21	26544.6
1016.52	26523.9
1019.82	26470.8
1023.12	26422.4
1026.43	26323.1
1029.73	26438.7
1033.02	26493.2
1036.32	26353.5
1039.62	26358.5
1042.91	26381.6
1046.21	26249.1
1049.5	26355.5
1052.79	26424
1056.08	26742.2
1059.37	27070.9
1062.65	27457.8
1065.94	27280.9
1069.23	27135.3
1072.51	27165.7
1075.79	27348
1079.07	27475.2
1082.35	27442
1085.63	27292.5
1088.91	27139.3
1092.18	26827.9
1095.46	26546
1098.73	26328.7
1102	26087
1105.27	25990.8
1108.54	25921.4
1111.81	25986.1
1115.08	26195.3
1118.34	26386.7
1121.61	26579.7
1124.87	26620.7
1128.13	26446.3
1131.39	26049.8
1134.65	25643.9
1137.91	25522
1141.17	25471
1144.42	25806.2
1147.68	26047.1
1150.93	26673.3
1154.18	27403.7
1157.43	27646.7
1160.68	26889.2
1163.93	26040.5
1167.18	25523.8
1170.42	25354
1173.67	25246.8
1176.91	25227.4
1180.15	25035.4
1183.39	25116.4
1186.63	25205.2
1189.87	25189.7
1193.11	25157
1196.34	25104.9
1199.58	25078.7
1202.81	25000.5
1206.04	24963.1
1209.27	25060.4
1212.5	24980.4
1215.73	24803.1
1218.95	24806.9
1222.18	24782.2
1225.4	24891.2
1228.63	24923.6
1231.85	24991
1235.07	24998.3
1238.29	25161.8
1241.51	25272.2
1244.72	25386
1247.94	25533.2
1251.15	25628.1
1254.37	25688.1
1257.58	25776.3
1260.79	25908.3
1264	25822.7
1267.21	25985.9
1270.41	25843.2
1273.62	25789
1276.82	25723
1280.03	25674.4
1283.23	25692.4
1286.43	25864.8
1289.63	26097
1292.83	26816
1296.03	27531.6
1299.22	27934.1
1302.42	27967.4
1305.61	27655.9
1308.8	27135.4
1311.99	26598.8
1315.18	26186.4
1318.37	25818.3
1321.56	25546
1324.74	25297.9
1327.93	25022.6
1331.11	24923.7
1334.3	24842.8
1337.48	24811.4
1340.66	24764.8
1343.84	24716.5
1347.01	24707.8
1350.19	24563.6
1353.37	24548.8
1356.54	24526.7
1359.71	24311.9
1362.88	24344.7
1366.05	24362
1369.22	24280.6
1372.39	24108.7
1375.56	23927.4
1378.72	23943.5
1381.89	23722.3
1385.05	23751.7
1388.21	23764.2
1391.37	23750
1394.53	23756.2
1397.69	23749.5
1400.85	23814.6
1404	23802.1
1407.16	23871.8
1410.31	24020.1
1413.46	24246.6
1416.61	24429.4
1419.76	24673.9
1422.91	24921.8
1426.06	25268.3
1429.21	26119
1432.35	27623.8
1435.49	29022.1
1438.64	29775.8
1441.78	29742.5
1444.92	29253.3
1448.06	28870
1451.2	28535.1
1454.33	28224.5
1457.47	27901.3
1460.6	27383.1
1463.74	26698.4
1466.87	26050.8
1470	25351.2
1473.13	24653.8
1476.26	24166.8
1479.38	23750.7
1482.51	23603.3
1485.63	23349.1
1488.76	23297.3
1491.88	23245.8
1495	23229.4
1498.12	23311.1
1501.24	23288.8
1504.36	23423.1
1507.47	23611.6
1510.59	23974.4
1513.7	24363.6
1516.81	24770.7
1519.93	25090.2
1523.04	25163.8
1526.15	24945.7
1529.25	24421
1532.36	23655
1535.47	23208.5
1538.57	22920.5
1541.67	22769.8
1544.78	22555.2
1547.88	22557.9
1550.98	22543.6
1554.08	22556.7
1557.18	22542.6
1560.27	22388.8
1563.37	22396.7
1566.46	22273
1569.55	22321.8
1572.64	22286.8
1575.74	22289.1
1578.83	22269.8
1581.91	22292.2
1585	22322.7
1588.09	22303.1
1591.17	22296.4
1594.25	22246.5
1597.34	22373.9
1600.42	22408.9
1603.5	22362.8
1606.58	22387.3
1609.65	22380.1
1612.73	22313.2
1615.8	22316.2
1618.88	22218.6
1621.95	22208.9
1625.03	22222.3
1628.1	22259.5
1631.17	22323.8
1634.23	22370.8
1637.3	22532.1
1640.37	22692.2
1643.43	22952
1646.5	23425.4
1649.56	24153.4
1652.62	24815.5
1655.68	24657.5
1658.74	24086
1661.8	23457.2
1664.85	23086.6
1667.91	22954.3
1670.96	22841.7
1674.02	22543.1
1677.07	22218.1
1680.12	22079.7
1683.17	21929.4
1686.22	21843.3
1689.27	21668.1
1692.31	21613.2
1695.36	21485.4
1698.4	21403.4
1701.45	21270.4
1704.49	21233.1
1707.53	21157.7
1710.57	21102.2
1713.61	21107.1
1716.65	21040.3
1719.68	21079.6
1722.72	21085.6
1725.75	21195.8
1728.78	21313.7
1731.82	21388.3
1734.84	21544.8
1737.87	21796.6
1740.9	21882.6
1743.93	22022.7
1746.96	21919.8
1749.98	21887.1
1753	21683.7
1756.03	21423.5
1759.05	21088.4
1762.07	20941.3
1765.09	20761.3
1768.11	20716.8
1771.12	20719.3
1774.14	20628.7
1777.15	20683
1780.17	20609.5
1783.18	20539.5
1786.19	20554.6
1789.2	20571.9
1792.21	20549.8
1795.22	20503.2
1798.22	20519.4
1801.23	20492.4
1804.23	20431.6
1807.24	20464.2
1810.24	20420.7
1813.24	20453.9
1816.24	20366.9
1819.24	20335.6
1822.24	20318.5
1825.23	20337.6
1828.23	20292.4
1831.22	20323.6
1834.22	20264.7
1837.21	20203.5
1840.2	20247.4
1843.19	20206
1846.18	20244.6
1849.17	20191.5
1852.15	20173
1855.14	20101.1
1858.12	20089.6
1861.11	20160.9
1864.09	20098.8
1867.07	20133.2
1870.05	20063.6
1873.03	20083.6
1876.01	20065.8
1878.98	20019.1
1881.96	20018.1
1884.93	19980
1887.91	19931.7
1890.88	19953.5
1893.85	19945.3
1896.82	19803.7
1899.79	19834.7
1902.76	19743.7
1905.72	19679.1
1908.69	19658.2
1911.65	19613.1
1914.62	19564.6
1917.58	19509.5
1920.54	19395.4
1923.5	19435.3
1926.46	19416.4
1929.42	19368
1932.37	19313.2
1935.33	19260.3
1938.28	19177.2
1941.24	19153.8
1944.19	19150.6
1947.14	19058.5
1950.09	19007
1953.04	18936.1
1955.99	18884
1958.93	18800.3
1961.88	18830.2
1964.82	18819.1
1967.77	18755.5
1970.71	18716
1973.65	18635.3
1976.59	18600.9
1979.53	18604.2
1982.47	18555.4
1985.41	18546.4
1988.34	18450.6
1991.28	18418.2
1994.21	18353.5
1997.14	18264.2
2000.07	18197
2003.01	18168.6
2005.94	18190.4
2008.86	18136.8
2011.79	18143.5
2014.72	18129.3
2017.64	18054.8
2020.57	18020.1
2023.49	17943.1
2026.41	17936.5
2029.33	17929.4
2032.25	17907.7
2035.17	17861.2
2038.09	17855.9
2041	17806.1
2043.92	17759.8
2045.86	17767.1
2048.79	17733.5
2051.71	17695.5
2054.64	17718
2057.56	17688.2
2060.48	17657
2063.4	17584.6
2066.32	17627.9
2069.24	17663.2
2072.16	17621.8
2075.08	17608.8
2077.99	17568
2080.91	17552.4
2083.82	17541
2086.74	17503.8
2089.65	17488
2092.56	17411.8
2095.47	17422.9
2098.38	17381.8
2101.29	17370.5
2104.19	17352.9
2107.1	17332.5
2110	17285.6
2112.91	17275.1
2115.81	17209.4
2118.71	17268.5
2121.61	17250.7
2124.51	17226.1
2127.4	17206.8
2130.3	17189.7
2133.2	17130.1
2136.09	17189.2
2138.99	17162.7
2141.88	17100.3
2144.77	17163.5
2147.66	17142.8
2150.55	17136.1
2153.44	17133.2
2156.33	17075.1
2159.21	17103.9
2162.1	16985.4
2164.98	17064.7
2167.87	17035.5
2170.75	16998.6
2173.63	17050.9
2176.51	16977.7
2179.39	17020.8
2182.27	17012
2185.14	16934.6
2188.02	16942.2
2190.9	16917.5
2193.77	16878.3
2196.64	16832.5
2199.51	16862.2
2202.39	16840.1
2205.25	16816.4
2208.12	16862.9
2210.99	16771.3
2213.86	16684.1
2216.72	16672.4
2219.59	16634.5
2222.45	16628.7
2225.31	16600.5
2228.17	16589.3
2231.03	16563.6
2233.89	16566.7
2236.75	16501.2
2239.61	16458.9
2242.46	16494.2
2245.32	16403.4
2248.17	16405.5
2251.03	16293.8
2253.88	16323
2256.73	16230.6
2259.58	16176
2262.43	16127.1
2265.28	16144.3
2268.12	16056.9
2270.97	16034.6
2273.81	16042.9
2276.66	16011.9
2279.5	16006.8
2282.34	15924.4
2285.18	15882.8
2288.02	15856.4
2290.86	15825.8
2293.7	15819
2296.54	15828.8
2299.37	15832.6
2302.21	15784.1
2305.04	15722.2
2307.87	15613.7
2310.7	15660.6
2313.53	15689.7
2316.36	15615.4
2319.19	15561.8
2322.02	15539.8
2324.85	15569
2327.67	15841.1
2330.5	16059.9
2333.32	15545.9
2336.14	15383.4
2338.96	15366
2341.78	15357.1
2344.6	15328.1
2347.42	15241.4
2350.24	15168.5
2353.05	15169
2355.87	15163.1
2358.68	15096
2361.5	15071.2
2364.31	14973.9
2367.12	15039.2
2369.93	15024.4
2372.74	14936.1
2375.55	14905.3
2378.35	14925.2
2381.16	14919.7
2383.96	14845.8
2386.77	14848.8
2389.57	14889.9
2392.37	14826.8
2395.17	14822.6
2397.97	14801.2
2400.77	14787.6
2403.57	14687.9
2406.37	14706.8
2409.16	14714.6
2411.96	14661.1
2414.75	14697.8
2417.55	14610.8
2420.34	14626.7
2423.13	14632.2
2425.92	14555
2428.71	14558.2
2431.5	14542.4
2434.28	14521.4
2437.07	14486.2
2439.85	14483.4
2442.64	14441
2445.42	14484.2
2448.2	14463.1
2450.98	14376.5
2453.76	14446.1
2456.54	14363.6
2459.32	14325.7
2462.1	14288.9
2464.87	14343.7
2467.65	14251.2
2470.42	14298.1
2473.2	14208.9
2475.97	14208.3
2478.74	14181.5
2481.51	14167
2484.28	14164.9
2487.05	14139
2489.81	14160.8
2492.58	14145.5
2495.34	14090.7
2498.11	14081.8
2500.87	14013.8
2503.63	14012.5
2506.39	14002.3
2509.15	13988.5
2511.91	13945.7
2514.67	13934.1
2517.43	13927.1
2520.19	13921.1
2522.94	13898.5
2525.7	13914.6
2528.45	13910.8
2531.2	13881.3
2533.95	13897.1
2536.7	13854.2
2539.45	13864
2542.2	13781.5
2544.95	13798.4
2547.69	13784.8
2550.44	13657.8
2553.18	13710.5
2555.93	13741.2
2558.67	13676.2
2561.41	13662.7
2564.15	13645.1
2566.89	13616.2
2569.63	13613.9
2572.36	13588.1
2575.1	13668.9
2577.84	13576.1
2580.57	13603.3
2583.31	13604.7
2586.04	13601.5
2588.77	13613.5
2591.5	13579
2594.23	13638.8
2596.96	13626.4
2599.69	13613.8
2602.41	13537.8
2605.14	13623.1
2607.86	13631.3
2610.59	13581.9
2613.31	13574.2
2616.03	13511.6
2618.75	13511.7
2621.48	13524.5
2624.19	13462.5
2626.91	13551.7
2629.63	13468.1
2632.35	13465.3
2635.06	13460
2637.77	13492.6
2640.49	13408.4
2643.2	13424.1
2645.91	13436.8
2648.62	13453.8
2651.33	13466
2654.04	13487.6
2656.75	13453.3
2659.45	13485.6
2662.16	13457.6
2664.86	13426.9
2667.57	13475
2670.27	13499.6
2672.97	13472.4
2675.67	13424.6
2678.37	13437.8
2681.07	13445.1
2683.77	13417
2686.47	13465.3
2689.16	13460.4
2691.86	13424.2
2694.55	13432.5
2697.25	13429.7
2699.94	13473.8
2702.63	13492.9
2705.32	13533.7
2708.01	13596.3
2710.7	13619
2713.39	13646.7
2716.07	13703
2718.76	13744
2721.44	13796.9
2724.12	13761.1
2726.81	13797.1
2729.49	13745.5
2732.17	13748.6
2734.85	13589.5
2737.53	13530.8
2740.21	13390.6
2742.88	13293.9
2745.56	13232.9
2748.24	13204.7
2750.91	13071.7
2753.58	13065.2
2756.25	13016.9
2758.93	13004.2
2761.6	12922.7
2764.27	12886.7
2766.93	12880.1
2769.6	12886.3
2772.27	12898.3
2774.93	12828.5
2777.6	12834.1
2780.26	12828
2782.93	12818.5
2785.59	12769.1
2788.25	12765.1
2790.91	12786.7
2793.57	12833
2796.23	12890.4
2798.88	12868.9
2801.54	12849.8
2804.2	12866.2
2806.85	12821.4
2809.5	12904.2
2812.16	12957.3
2814.81	13022.4
2817.46	13082.8
2820.11	13164.6
2822.76	13254.2
2825.4	13396.7
2828.05	13600.4
2830.7	13899.7
2833.34	14266.3
2835.99	14866.4
2838.63	15687.4
2841.27	17130.4
2843.91	19246.5
2846.55	22022.6
2849.19	24415
2851.83	25415
2854.47	25061.5
2857.11	24339
2859.74	23602.1
2862.38	22943.9
2865.01	22533.3
2867.65	22412.7
2870.28	22734.9
2872.91	23228.9
2875.54	23654.8
2878.17	23973.6
2880.8	24436.7
2883.42	24776.7
2886.05	24899.3
2888.68	25001.2
2891.3	25130.1
2893.93	25076.1
2896.55	25116.6
2899.17	25029.4
2901.79	24945.2
2904.41	24886.7
2907.03	24762.1
2909.65	24646.6
2912.27	24603
2914.88	24511.1
2917.5	24445.4
2920.11	24431.4
2922.73	24428.4
2925.34	24412.6
2927.95	24509.4
2930.56	24577.3
2933.17	24464.2
2935.78	24240.7
2938.39	23783
2941	22850.5
2943.6	21638.2
2946.21	20485.8
2948.81	19563
2951.42	18906
2954.02	18567.7
2956.62	18358.1
2959.22	18043.9
2961.82	17807.1
2964.42	17430.5
2967.02	17006.9
2969.62	16554.6
2972.21	16130.6
2974.81	15674.9
2977.4	15372.7
2980	15029.7
2982.59	14753.8
2985.18	14520.3
2987.77	14236.5
2990.36	14017.3
2992.95	13920.5
2995.54	13783.4
2998.13	13684.8
3000.72	13657.8
3003.3	13608.2
3005.89	13516.5
3008.47	13426.2
3011.05	13263.8
3013.63	13045.4
3016.22	12943.6
3018.8	12728.7
3021.38	12633.6
3023.95	12466.3
3026.53	12353.9
3029.11	12259.6
3031.68	12211
3034.26	12148
3036.83	12135
3039.4	12090
3041.98	12117.4
3044.55	12076
3047.12	12053.6
3049.69	12071.5
3052.26	12022.8
3054.82	12091.5
3057.39	12097.2
3059.96	12088.6
3062.52	12115.7
3065.09	12114.6
3067.65	12091.8
3070.21	12081.6
3072.77	12056.3
3075.33	12036.1
3077.89	11941.4
3080.45	11923.8
3083.01	11903.5
3085.57	11943.5
3088.12	11932.1
3090.68	11912.7
3093.23	11917.6
3095.79	11929.3
3098.34	11905.1
3100.89	11916.2
3103.44	11931.6
3105.99	11969.2
3108.54	12002.3
3111.09	11998
3113.63	12048.4
3116.18	12053.5
3118.73	12060.9
3121.27	12061.1
3123.82	12133.2
3126.36	12205.5
3128.9	12214.1
3131.44	12232.3
3133.98	12264.4
3136.52	12278.9
3139.06	12345.4
3141.6	12343.4
3144.13	12379.9
3146.67	12376.6
3149.2	12411
3151.74	12436.8
3154.27	12471.6
3156.8	12530
3159.34	12569.7
3161.86	12576.9
3164.4	12638.9
3166.92	12682.1
3169.45	12665.1
3171.98	12720.9
3174.5	12664.8
3177.03	12690.3
3179.56	12699.9
3182.08	12705.2
3184.6	12729.7
3187.12	12670
3189.64	12741.4
3192.16	12758.9
3194.68	12713.2
3197.2	12755.2
3199.72	12773.4
3202.24	12803.5
3204.75	12788.9
3207.27	12760.3
3209.78	12804.7
3212.29	12761.1
3214.81	12755.1
3217.32	12745.6
3219.83	12705.1
3222.34	12708.8
3224.85	12704.3
3227.35	12752.6
3229.86	12730.6
3232.37	12703.5
3234.87	12708.3
3237.38	12707.7
3239.88	12707.8
3242.38	12660.7
3244.89	12648.3
3247.39	12642.8
3249.89	12631.1
3252.39	12624.7
3254.88	12586.5
3257.38	12538.7
3259.88	12533
3262.37	12520.1
3264.87	12517.4
3267.36	12512.8
3269.86	12507.9
3272.35	12487.1
3274.84	12492.5
3277.33	12480.3
3279.82	12452.8
3282.31	12435
3284.8	12423.3
3287.29	12421.1
3289.77	12381.2
3292.26	12366
3294.15	12362.5
3296.64	12316.8
3299.14	12308.4
3301.63	12360.3
3304.12	12339.6
3306.62	12287.8
3309.11	12280.4
3311.6	12253.8
3314.09	12257.4
3316.58	12279.6
3319.07	12226
3321.56	12270.7
3324.04	12256.8
3326.53	12255.5
3329.01	12209.7
3331.5	12189.9
3333.98	12210.6
3336.46	12243.4
3338.94	12178.5
3341.42	12177
3343.9	12151.9
3346.38	12204.6
3348.86	12187.2
3351.34	12138.2
3353.82	12115.4
3356.29	12127.3
3358.77	12102.4
3361.24	12132.4
3363.71	12129.9
3366.19	12093
3368.66	12081
3371.13	12102.6
3373.6	12160.9
3376.07	12108.2
3378.54	12112.7
3381	12097.6
3383.47	12108.7
3385.94	12045.4
3388.4	12078
3390.87	12057
3393.33	12054.3
3395.79	12029.9
3398.25	12068.1
3400.71	12051.3
3403.17	12016.1
3405.63	12006.5
3408.09	12037.9
3410.55	12026.6
3413	12015.4
3415.46	11974.3
3417.92	11964.6
3420.37	11936.5
3422.82	11973.8
3425.27	11913.7
3427.73	11886.8
3430.18	11857.6
3432.63	11847
3435.08	11819
3437.53	11820.3
3439.97	11743.1
3442.42	11749.8
3444.86	11745
3447.31	11692.7
3449.75	11656.3
3452.2	11582.1
3454.64	11591.5
3457.08	11567.3
3459.52	11541
3461.96	11517.2
3464.4	11487.6
3466.84	11466.4
3469.28	11425
3471.72	11384.9
3474.15	11297.5
3476.59	11270.8
3479.02	11219.6
3481.45	11197.7
3483.89	11124.2
3486.32	11103.5
3488.75	11060.2
3491.18	10993.8
3493.61	10961.1
3496.04	10916.8
3498.47	10836.1
3499.68	10888.4