File: src/Milk_AI/Heritage toned RT after 24h 532nm 50% 600g 50xL 10s 10times 400-3500cm-1 200hole.txt
#Acq. time (s)=	7
#Accumulations=	20
#Range (cm-¹)=	400...3500
#Windows=	3
#Auto scanning=	Off
#Autofocus=	Off
#AutoExposure=	Off
#Spike filter=	Multiple accum.
#Delay time (s)=	0
#Binning=	1
#Readout mode=	Signal
#DeNoise=	Off
#ICS correction=	On
#Dark correction=	Off
#Inst. Process=	Off
#Detector Gain=	Best Dynamic Range
#Detector ADC=	45 kHz
#Detector temperature (°C)=	-60.1
#Instrument=	LabRAM HR Evol
#Detector=	Syncerity OE
#Objective=	x50_VIS_LWD
#Grating=	600 (500nm)
#ND Filter=	50%
#Laser=	532nm_Edge
#Hole=	199.981
#Range=	Visible
#E-Cal_Neon=	0
#StageXY=	75x50mm Scan+
#StageZ=	Z motor
#X (µm)=	0
#Y (µm)=	0
#Z (µm)=	338.3
#Spectral res.(cm-¹)=	12.8
#Full time(mm:ss)=	7:26
#AC=	Calibrated 2025-07-01 10:31
#Project=
#Sample=
#Site=
#Title=	D_1
#Remark=
#Date=	01.07.2025 12:45 (India Standard Time)
#Acquired=	01.07.2025 12:45:18 (India Standard Time)
#AxisType[0]=Intens
#AxisUnit[0]=Cnt
#AxisType[1]=Spectr
#AxisUnit[1]=1/cm
400.083	14581.5
403.63	14462
407.176	14490.5
410.72	14477.1
414.263	14456.3
417.805	14510.5
421.345	14472.2
424.884	14433
428.421	14471.1
431.955	14453.1
435.49	14488.6
439.023	14444.1
442.555	14372.9
446.084	14409.4
449.613	14345.5
453.141	14366.4
456.666	14291.8
460.191	14309.3
463.715	14283.6
467.235	14290.6
470.756	14295.5
474.274	14260.3
477.793	14216
481.308	14212.6
484.823	14234.1
488.336	14238.4
491.847	14227.2
495.358	14206.9
498.867	14234.4
502.374	14269
505.881	14278.4
509.386	14247.6
512.888	14262.9
516.39	14228.5
519.89	14193.2
523.391	14163.3
526.889	14166.2
530.385	14129.9
533.88	14091.4
537.373	14108.8
540.866	14046.7
544.357	14057.3
547.846	14022
551.334	14026.3
554.821	14031.2
558.307	13978.1
561.789	13977.5
565.272	13998.1
568.753	13969.2
572.233	13972.8
575.712	13978.4
579.188	13985.9
582.664	13928.4
586.139	13935.3
589.611	13932.7
593.083	13915.3
596.554	13957.7
600.021	13884.7
603.49	13876.9
606.955	13916.5
610.42	13888.5
613.882	13819.2
617.345	13822.7
620.805	13772
624.263	13747
627.722	13675.6
631.178	13669
634.633	13675.3
638.088	13677.3
641.539	13694.7
644.99	13629.5
648.439	13630.9
651.887	13556.9
655.335	13586.1
658.781	13593.3
662.225	13537.6
665.667	13540.8
669.108	13553.7
672.548	13494.7
675.987	13480.2
679.424	13478.3
682.86	13500.9
686.293	13521.5
689.727	13450.3
693.159	13445
696.59	13486.1
700.019	13480.1
703.448	13453.4
706.872	13448.3
710.298	13366.1
713.723	13369.3
717.144	13370.4
720.565	13354.8
723.984	13365.3
727.403	13293.7
730.821	13282.4
734.235	13276.7
737.651	13278.3
741.063	13230.6
744.474	13221.2
747.885	13242.2
751.293	13239.1
754.702	13224.5
758.108	13251.8
761.512	13228.8
764.915	13243
768.319	13242.3
771.719	13236.3
775.118	13265
778.516	13189.2
781.913	13178.7
785.308	13181.5
788.702	13179.7
792.095	13144.5
795.486	13116.6
798.876	13082.7
802.265	13116.4
805.653	13089.1
809.039	13063
812.424	13008.2
815.808	13050.6
819.191	13033.5
822.572	13052.3
825.95	13083
829.329	13025.4
832.706	13059.5
836.08	13044.2
839.455	13008.9
842.829	13082.5
846.199	13056
849.57	13083.7
852.938	13044.2
856.307	13047.1
859.672	13107.8
863.038	13035.5
866.401	13041.6
869.765	12992.9
873.125	13017
876.484	13056.1
879.844	12982.7
883.2	12929.1
886.555	12919.7
889.909	12924.5
893.262	12838.2
896.616	12782
899.966	12743.1
903.315	12707
906.663	12644.1
910.009	12647.9
913.354	12644
916.698	12613.8
920.041	12602.2
923.383	12554.9
926.723	12501.7
930.062	12491.6
933.399	12450.6
936.734	12426.8
940.069	12474.5
943.403	12483.4
946.736	12466.2
950.065	12448.3
953.396	12448
956.725	12472.1
960.051	12439.5
963.377	12450.7
966.7	12385.1
970.025	12392.4
973.345	12293.8
976.667	12303.2
979.985	12328.5
983.304	12328.3
986.62	12359.2
989.935	12364.8
993.25	12398.1
996.563	12528.7
999.874	12679.7
1003.19	12654.2
1006.49	12547.9
1009.8	12408
1013.11	12319.5
1016.41	12336.9
1019.72	12278.4
1023.02	12223.5
1026.32	12179.8
1029.62	12148.3
1032.92	12117.3
1036.22	12135.7
1039.51	12096.2
1042.81	12092.3
1046.1	12087.6
1049.39	12079.6
1052.68	12077.1
1055.97	12142.7
1059.26	12217.1
1062.55	12193.8
1065.83	12125.9
1069.12	12112.1
1072.4	12087.8
1075.68	12135.2
1078.97	12122.1
1082.24	12107.5
1085.52	12091.8
1088.8	12018.6
1092.08	11928.8
1095.35	11893
1098.62	11837.4
1101.9	11808.1
1105.17	11760
1108.44	11751.3
1111.7	11784.9
1114.97	11835.5
1118.23	11857.8
1121.5	11891
1124.76	11884.7
1128.03	11838.8
1131.29	11727.7
1134.54	11687.9
1137.8	11636.7
1141.06	11698.5
1144.31	11834
1147.57	12052
1150.82	12349
1154.07	12581.5
1157.32	12417.9
1160.57	12015.5
1163.82	11696.2
1167.07	11535.2
1170.31	11494.7
1173.56	11454.7
1176.8	11396.3
1180.04	11397
1183.28	11386.7
1186.52	11366.6
1189.76	11391.1
1192.99	11338
1196.23	11296.6
1199.46	11236.7
1202.7	11204.5
1205.93	11220.1
1209.16	11206.6
1212.39	11175.3
1215.62	11102.6
1218.84	11072.1
1222.07	11071.6
1225.29	11024.1
1228.52	11055.5
1231.74	11041
1234.96	11023.9
1238.18	11025.4
1241.4	11080.3
1244.61	11058.2
1247.83	11101.8
1251.04	11114.1
1254.25	11091.4
1257.47	11122.1
1260.68	11113
1263.89	11133
1267.09	11119.4
1270.3	11017.1
1273.51	11005.8
1276.71	10941.1
1279.91	10965.4
1283.12	10951.7
1286.32	10942.4
1289.52	11004.4
1292.72	11094.8
1295.91	11212.6
1299.11	11170.5
1302.3	11152
1305.5	11072.5
1308.69	10974.3
1311.88	10933.5
1315.07	10774.1
1318.26	10753.7
1321.44	10697
1324.63	10663.8
1327.82	10632
1331	10622.4
1334.18	10609.3
1337.36	10602.4
1340.54	10611.6
1343.72	10550.7
1346.9	10537.8
1350.07	10544.5
1353.25	10479
1356.42	10435.1
1359.6	10371.1
1362.77	10387.1
1365.94	10361.9
1369.11	10347.3
1372.28	10303.8
1375.44	10240.2
1378.61	10215.5
1381.77	10211.1
1384.93	10160.9
1388.1	10165.5
1391.26	10177.8
1394.41	10121.1
1397.57	10135.7
1400.73	10131.7
1403.89	10105.7
1407.04	10096.7
1410.19	10130.4
1413.35	10105
1416.5	10176.3
1419.65	10206.1
1422.8	10216.7
1425.94	10312.7
1429.09	10455.8
1432.23	10683.8
1435.38	10871.8
1438.52	10941.6
1441.66	10870.5
1444.8	10788.8
1447.94	10742.5
1451.08	10660.4
1454.22	10590.1
1457.35	10513.1
1460.48	10463
1463.62	10314.6
1466.75	10196.8
1469.88	10059.8
1473.01	9933.91
1476.14	9838.44
1479.26	9751.83
1482.39	9731.3
1485.51	9662.19
1488.64	9702.06
1491.76	9677.55
1494.88	9733.88
1498	9738.69
1501.12	9768.89
1504.24	9858.67
1507.35	9981.42
1510.47	10156.9
1513.58	10378.6
1516.69	10542.2
1519.81	10582.1
1522.92	10542.8
1526.03	10314.7
1529.13	9978.36
1532.24	9690.88
1535.35	9553.74
1538.45	9474.71
1541.55	9424.35
1544.66	9364.62
1547.76	9320.39
1550.86	9312.44
1553.96	9295.24
1557.05	9229.75
1560.15	9220.45
1563.24	9225.88
1566.34	9227.87
1569.43	9240.49
1572.52	9221.55
1575.61	9177.89
1578.7	9179.87
1581.79	9188.44
1584.88	9142.07
1587.96	9167.07
1591.05	9165.66
1594.13	9164.38
1597.21	9148.67
1600.3	9133.42
1603.37	9130.94
1606.45	9107.66
1609.53	9089.64
1612.61	9059.04
1615.68	9037.34
1618.76	9016.68
1621.83	9003.34
1624.9	9005.17
1627.97	8998.71
1631.04	9021.04
1634.11	9023.57
1637.18	9003.2
1640.24	9034.07
1643.31	9059.03
1646.37	9172.49
1649.44	9274.6
1652.5	9291.97
1655.56	9256.28
1658.62	9124.98
1661.67	9008.16
1664.73	8953.1
1667.79	8912.2
1670.84	8844.68
1673.89	8831.01
1676.95	8771.9
1680	8684.74
1683.05	8700.89
1686.1	8639.18
1689.14	8593.9
1692.19	8539.11
1695.23	8511.57
1698.28	8449.85
1701.32	8439.85
1704.36	8389.57
1707.4	8394.79
1710.44	8353.28
1713.48	8333.88
1716.52	8319.28
1719.56	8294.45
1722.59	8270.83
1725.63	8311.43
1728.66	8302.97
1731.69	8320.1
1734.72	8320.57
1737.75	8329.46
1740.78	8334.85
1743.8	8318.16
1746.83	8292.25
1749.86	8248.42
1752.88	8178.96
1755.9	8109.57
1758.92	8087.5
1761.94	8065.77
1764.96	7984.76
1767.98	8076.68
1771	8008.13
1774.01	8013.39
1777.03	7999.55
1780.04	7955.23
1783.05	7937.61
1786.06	7941.26
1789.07	7933.07
1792.08	7914.06
1795.09	7882.77
1798.1	7877.64
1801.1	7854.66
1804.11	7846.58
1807.11	7856.05
1810.11	7822.09
1813.11	7795.2
1816.11	7791.34
1819.11	7749.27
1822.11	7757.78
1825.11	7732.03
1828.1	7735.6
1831.1	7709.19
1834.09	7714.87
1837.08	7677.64
1840.07	7706.52
1843.06	7684.15
1846.05	7667.97
1849.04	7656.18
1852.02	7605.68
1855.01	7597.46
1857.99	7583.65
1860.98	7551.48
1863.96	7563.62
1866.94	7545.87
1869.92	7539.01
1872.9	7525.45
1875.88	7519.76
1878.85	7513.75
1881.83	7500.13
1884.8	7441.6
1887.78	7402.78
1890.75	7433.9
1893.72	7399.36
1896.69	7363.37
1899.66	7360.54
1902.63	7282.12
1905.59	7234.19
1908.56	7190.65
1911.52	7165.17
1914.49	7090.16
1917.45	7023.38
1920.41	6971.96
1923.37	6929.75
1926.33	6876.05
1929.29	6829.5
1932.24	6765.41
1935.2	6764
1938.15	6691.84
1941.1	6656.39
1944.06	6603.22
1947.01	6567.6
1949.96	6509.01
1952.91	6444.47
1955.86	6400.23
1958.8	6321.05
1961.75	6287.39
1964.69	6277.99
1967.64	6237.64
1970.58	6163.55
1973.52	6123.9
1976.46	6081.36
1979.4	6045.53
1982.34	5995.83
1985.27	5968.16
1988.21	5919.52
1991.14	5873.78
1994.08	5816.62
1997.01	5779.01
1999.94	5745.53
2002.87	5710.54
2005.8	5673.11
2008.73	5632.34
2011.66	5604.57
2014.58	5568.54
2017.51	5543.68
2020.43	5492.93
2023.36	5446.91
2026.28	5434.76
2029.2	5386.23
2032.12	5358.63
2035.04	5321.6
2037.95	5287.07
2040.87	5263.11
2043.78	5232.54
2045.76	5234.63
2048.69	5206.87
2051.61	5181.64
2054.54	5192.67
2057.46	5197.02
2060.38	5175.36
2063.3	5159.19
2066.22	5168.7
2069.14	5133.92
2072.06	5119.94
2074.98	5113.08
2077.89	5106.16
2080.81	5097.09
2083.72	5102.89
2086.63	5082.85
2089.55	5080.94
2092.46	5060.38
2095.37	5043.3
2098.28	5054.28
2101.18	5007.97
2104.09	5001.98
2106.99	4970.97
2109.9	4985.3
2112.8	4993.71
2115.71	4989.49
2118.61	4977.7
2121.51	4963.96
2124.4	4966.14
2127.3	4934.72
2130.2	4909.65
2133.09	4930.52
2135.99	4917.84
2138.88	4898.48
2141.78	4901.63
2144.67	4888.87
2147.56	4885.16
2150.45	4902.25
2153.34	4852.98
2156.22	4864.42
2159.11	4857.19
2162	4862.67
2164.88	4844.17
2167.76	4840.82
2170.64	4852.52
2173.53	4830.4
2176.41	4806.65
2179.29	4794.84
2182.16	4819.29
2185.04	4776.65
2187.92	4767.12
2190.79	4772.33
2193.66	4749.25
2196.54	4721.4
2199.41	4729.13
2202.28	4720.29
2205.15	4705.7
2208.02	4709.65
2210.88	4674.01
2213.75	4676.76
2216.62	4663.6
2219.48	4642.36
2222.34	4630.79
2225.21	4613.42
2228.07	4600.68
2230.93	4630.11
2233.79	4597.25
2236.65	4593.77
2239.5	4549.52
2242.36	4543.32
2245.21	4546.54
2248.07	4544.76
2250.92	4521.03
2253.77	4500.62
2256.62	4487.72
2259.47	4452.57
2262.32	4443.02
2265.17	4456.54
2268.02	4442.19
2270.86	4421.43
2273.71	4401.67
2276.55	4410.75
2279.39	4372.71
2282.24	4373.03
2285.08	4355.87
2287.92	4354.11
2290.75	4320.1
2293.59	4313.69
2296.43	4316.65
2299.26	4310.21
2302.1	4281.74
2304.93	4295.35
2307.76	4256.28
2310.6	4268.65
2313.43	4253.14
2316.25	4224.15
2319.08	4212.29
2321.91	4210.44
2324.74	4274.52
2327.56	4365.84
2330.39	4297.84
2333.21	4162.32
2336.03	4152.9
2338.85	4151.1
2341.67	4127.42
2344.49	4104.27
2347.31	4095.58
2350.13	4060.47
2352.94	4081.88
2355.76	4057.24
2358.57	4042.7
2361.39	4020.43
2364.2	4024.31
2367.01	4003.03
2369.82	4006.68
2372.63	4003.16
2375.44	3966.18
2378.24	3970.97
2381.05	3945.98
2383.85	3951.03
2386.66	3916.17
2389.46	3939.39
2392.26	3936.76
2395.06	3914.71
2397.86	3895
2400.66	3884.84
2403.46	3884.74
2406.26	3851.45
2409.05	3881.74
2411.85	3865.86
2414.64	3848.6
2417.43	3850.74
2420.23	3831.28
2423.02	3810.09
2425.81	3819.72
2428.6	3800.44
2431.38	3792.43
2434.17	3782.26
2436.96	3797.93
2439.74	3779.28
2442.53	3764.71
2445.31	3726.38
2448.09	3759.24
2450.87	3736.05
2453.65	3738.11
2456.43	3715.93
2459.21	3721.52
2461.98	3699.3
2464.76	3688.5
2467.53	3669.34
2470.31	3665.72
2473.08	3656.63
2475.85	3651.73
2478.63	3650.73
2481.39	3644.95
2484.16	3645.82
2486.93	3621.67
2489.7	3606.58
2492.46	3603.11
2495.23	3592.58
2497.99	3597.73
2500.76	3573.92
2503.52	3584.07
2506.28	3566.96
2509.04	3542.58
2511.8	3560.51
2514.56	3524.91
2517.31	3521.17
2520.07	3522.24
2522.82	3510.29
2525.58	3514.43
2528.33	3514.07
2531.09	3505.58
2533.84	3487.4
2536.59	3487.93
2539.34	3466.14
2542.08	3448.12
2544.83	3435.57
2547.58	3444.48
2550.32	3436.42
2553.07	3407.41
2555.81	3410.14
2558.55	3415.08
2561.29	3389.47
2564.03	3396.03
2566.77	3382.36
2569.51	3378.88
2572.25	3363.88
2574.99	3355.86
2577.72	3360.45
2580.46	3344.67
2583.19	3368.39
2585.92	3348.58
2588.65	3328.63
2591.38	3323.71
2594.11	3328.69
2596.84	3328.98
2599.57	3335.48
2602.3	3315.24
2605.02	3286.98
2607.75	3306.11
2610.47	3286.04
2613.19	3294.74
2615.92	3285.67
2618.64	3263.55
2621.36	3271.49
2624.08	3261.88
2626.8	3288.77
2629.51	3233.55
2632.23	3252.85
2634.94	3243.67
2637.66	3212.61
2640.37	3211.92
2643.08	3220.5
2645.79	3221.44
2648.5	3212.3
2651.21	3217.57
2653.92	3193.55
2656.63	3189.32
2659.33	3191.14
2662.04	3201.77
2664.75	3193.26
2667.45	3186.47
2670.15	3167.06
2672.85	3163.1
2675.55	3168.27
2678.25	3161.03
2680.95	3163.95
2683.65	3119.93
2686.35	3143.63
2689.04	3129.94
2691.74	3143.67
2694.43	3117.98
2697.13	3112.52
2699.82	3117.97
2702.51	3129.65
2705.2	3128.09
2707.89	3104.73
2710.58	3117.91
2713.26	3113.59
2715.95	3112.46
2718.64	3105.29
2721.32	3112.82
2724	3080.56
2726.69	3086.95
2729.37	3082.02
2732.05	3088.93
2734.73	3041.08
2737.41	3035.64
2740.09	3021.71
2742.76	3011.79
2745.44	3008.49
2748.11	2986.36
2750.79	2979.79
2753.46	2950.07
2756.13	2937.44
2758.81	2955.85
2761.47	2957.98
2764.14	2945.7
2766.81	2932.39
2769.48	2919.43
2772.15	2938.1
2774.81	2921.76
2777.48	2898.4
2780.14	2903.15
2782.8	2887.15
2785.47	2872.35
2788.13	2856.99
2790.79	2877.66
2793.44	2876.94
2796.1	2885.64
2798.76	2865.51
2801.42	2876.15
2804.07	2873.59
2806.73	2848.77
2809.38	2850.45
2812.03	2848.73
2814.68	2875.14
2817.33	2868.26
2819.98	2857.97
2822.63	2886.91
2825.28	2872.11
2827.93	2884.48
2830.57	2915.11
2833.22	2950.43
2835.86	3026.84
2838.51	3126.74
2841.15	3276.16
2843.79	3462.6
2846.43	3684.2
2849.07	3811.59
2851.71	3841.92
2854.35	3780.54
2856.98	3741.85
2859.62	3661.73
2862.25	3624.37
2864.89	3627.11
2867.52	3616.44
2870.15	3671.95
2872.78	3731.43
2875.41	3772.69
2878.04	3829.98
2880.67	3868.53
2883.3	3842.81
2885.92	3854.27
2888.55	3865.96
2891.18	3878.03
2893.8	3849.38
2896.42	3856.22
2899.04	3846.97
2901.67	3851.3
2904.29	3813.86
2906.9	3794.21
2909.52	3807.71
2912.14	3805.95
2914.76	3809.33
2917.37	3798.1
2919.99	3780.64
2922.6	3780.64
2925.21	3778.01
2927.82	3783.23
2930.44	3781.29
2933.05	3755.17
2935.65	3722.98
2938.26	3685.01
2940.87	3601.73
2943.48	3478.91
2946.08	3367.98
2948.69	3303.91
2951.29	3272.45
2953.89	3232.05
2956.49	3243.79
2959.1	3194.78
2961.7	3140.55
2964.29	3114.4
2966.89	3082.84
2969.49	3038.66
2972.09	3005.13
2974.68	2968.85
2977.28	2941.13
2979.87	2906.54
2982.46	2900.81
2985.05	2863.8
2987.65	2835.71
2990.24	2819.55
2992.82	2832.25
2995.41	2817.88
2998	2788.64
3000.59	2802.23
3003.17	2775.84
3005.76	2767.09
3008.34	2764.85
3010.92	2750.44
3013.5	2718.43
3016.09	2728.79
3018.67	2696.07
3021.25	2704.76
3023.82	2704.03
3026.4	2702.86
3028.98	2683.13
3031.55	2686.06
3034.13	2698.75
3036.7	2683.6
3039.28	2705.99
3041.85	2693.7
3044.42	2704.89
3046.99	2709.66
3049.56	2739.28
3052.13	2732.25
3054.69	2750.38
3057.26	2764.94
3059.83	2756.25
3062.39	2774.36
3064.95	2776.21
3067.52	2784.43
3070.08	2794.09
3072.64	2795.56
3075.2	2812.54
3077.76	2816.28
3080.32	2809.65
3082.88	2816.36
3085.44	2834.23
3087.99	2845.76
3090.55	2847.09
3093.1	2870.29
3095.65	2871.77
3098.21	2894.12
3100.76	2909.12
3103.31	2919.99
3105.86	2925.76
3108.41	2967.35
3110.96	2957.34
3113.5	2989.94
3116.05	2993.85
3118.59	3035.16
3121.14	3037.49
3123.68	3059.26
3126.23	3089.33
3128.77	3098.94
3131.31	3130.63
3133.85	3143.5
3136.39	3164.38
3138.93	3182.4
3141.46	3192.43
3144	3222.9
3146.54	3241.71
3149.07	3274.36
3151.6	3274.77
3154.14	3304
3156.67	3304.5
3159.2	3333.44
3161.73	3347.86
3164.26	3350.74
3166.79	3392.72
3169.32	3389.32
3171.84	3400.13
3174.37	3390.72
3176.9	3399.9
3179.42	3408.38
3181.94	3405.76
3184.47	3422.65
3186.99	3424.52
3189.51	3413.1
3192.03	3417.82
3194.55	3418.66
3197.07	3420.51
3199.58	3426.43
3202.1	3423.63
3204.62	3435.7
3207.13	3440.13
3209.65	3418.96
3212.16	3415.85
3214.67	3417.34
3217.18	3405.45
3219.69	3414.92
3222.2	3400.02
3224.71	3396.39
3227.22	3407.53
3229.73	3403.06
3232.23	3382.23
3234.74	3384.22
3237.24	3376.28
3239.75	3370.16
3242.25	3354.56
3244.75	3354.67
3247.25	3345.7
3249.75	3345.73
3252.25	3332.41
3254.75	3320.87
3257.25	3303.68
3259.74	3286.29
3262.24	3276.54
3264.73	3271.89
3267.23	3262.64
3269.72	3267.35
3272.21	3261.97
3274.7	3245.89
3277.2	3236.76
3279.69	3237.28
3282.17	3225.32
3284.66	3213.61
3287.15	3206.75
3289.64	3208.59
3292.12	3182.77
3293.56	3179.34
3296.05	3179.32
3298.55	3171.24
3301.04	3169.36
3303.54	3161.47
3306.03	3165.79
3308.52	3166.83
3311.01	3143.08
3313.5	3136.25
3315.99	3130.82
3318.48	3138.63
3320.97	3142.61
3323.45	3136.96
3325.94	3140.33
3328.42	3131.91
3330.91	3114.69
3333.39	3122.57
3335.87	3125.98
3338.36	3105.96
3340.84	3110.96
3343.32	3109.46
3345.8	3085.99
3348.27	3094.84
3350.75	3097.68
3353.23	3084.31
3355.7	3056.93
3358.18	3083.51
3360.65	3077.68
3363.13	3072.78
3365.6	3057.77
3368.07	3078.64
3370.54	3060.16
3373.01	3062.4
3375.48	3072.39
3377.95	3069.29
3380.42	3059.18
3382.88	3062.71
3385.35	3040.55
3387.81	3032.33
3390.28	3028.43
3392.74	3037.76
3395.2	3011.29
3397.67	3025.46
3400.13	3017.03
3402.58	3023.92
3405.05	3025.96
3407.5	3017.02
3409.96	3012.27
3412.42	2992.95
3414.87	2981.95
3417.33	2981.99
3419.78	2974.07
3422.23	2968.71
3424.69	2947.23
3427.14	2932.88
3429.59	2934.53
3432.04	2931.21
3434.49	2915.97
3436.94	2914.23
3439.39	2894.37
3441.83	2884.45
3444.28	2865.67
3446.72	2851.78
3449.17	2819.52
3451.61	2811.25
3454.05	2823.91
3456.5	2823.68
3458.94	2799.68
3461.38	2782.41
3463.81	2760.53
3466.25	2741.98
3468.69	2732.63
3471.13	2723.56
3473.56	2684.37
3476	2682.16
3478.43	2663.38
3480.87	2640.37
3483.3	2621.67
3485.73	2604.32
3488.16	2578.08
3490.59	2563.46
3493.02	2549.5
3495.45	2537.37
3497.88	2508.78
3499.09	2480.36