File: src/Milk_AI/Heritage special RT 532nm 50% 600g 50xL 10s 10times 400-3500cm-1 200hole.txt
#Acq. time (s)=	10
#Accumulations=	10
#Range (cm-¹)=	400...3500
#Windows=	3
#Auto scanning=	Off
#Autofocus=	Off
#AutoExposure=	Off
#Spike filter=	Multiple accum.
#Delay time (s)=	0
#Binning=	1
#Readout mode=	Signal
#DeNoise=	Off
#ICS correction=	On
#Dark correction=	Off
#Inst. Process=	Off
#Detector Gain=	Best Dynamic Range
#Detector ADC=	45 kHz
#Detector temperature (°C)=	-60.1
#Instrument=	LabRAM HR Evol
#Detector=	Syncerity OE
#Objective=	x50_VIS_LWD
#Grating=	600 (500nm)
#ND Filter=	50%
#Laser=	532nm_Edge
#Hole=	199.981
#Range=	Visible
#E-Cal_Neon=	0
#StageXY=	75x50mm Scan+
#StageZ=	Z motor
#X (µm)=	0
#Y (µm)=	0
#Z (µm)=	114.3
#Spectral res.(cm-¹)=	12.8
#Full time(mm:ss)=	5:19
#AC=	Calibrated 2025-07-01 10:31
#Project=
#Sample=
#Site=
#Title=	D_1
#Remark=
#Date=	01.07.2025 11:10 (India Standard Time)
#Acquired=	01.07.2025 11:10:58 (India Standard Time)
#AxisType[0]=Intens
#AxisUnit[0]=Cnt
#AxisType[1]=Spectr
#AxisUnit[1]=1/cm
400.083	21830.9
403.63	21738.3
407.176	21819.3
410.72	21843.7
414.263	21797.6
417.805	21845.9
421.345	21876
424.884	21839.9
428.421	21883.9
431.955	21870.8
435.49	22016.8
439.023	21904.3
442.555	21901.6
446.084	21883.9
449.613	21943.7
453.141	21913.8
456.666	21932.4
460.191	21901
463.715	21916.5
467.235	21886.2
470.756	21938.3
474.274	21962.6
477.793	21985.6
481.308	22005.7
484.823	21939.7
488.336	22005.2
491.847	22017.8
495.358	21971.2
498.867	22068.7
502.374	22174.2
505.881	22180.1
509.386	22178.4
512.888	22215.4
516.39	22261
519.89	22213.5
523.391	22220.3
526.889	22201.6
530.385	22112
533.88	22198.7
537.373	22172.3
540.866	22087.6
544.357	22117.2
547.846	22168.2
551.334	22146.2
554.821	22147.9
558.307	22174.9
561.789	22134.6
565.272	22197.8
568.753	22228.8
572.233	22219.6
575.712	22277.2
579.188	22347.2
582.664	22272.2
586.139	22267.4
589.611	22338.5
593.083	22329.4
596.554	22356.6
600.021	22296.4
603.49	22377.3
606.955	22332
610.42	22383.4
613.882	22258.7
617.345	22309.2
620.805	22223.5
624.263	22222.2
627.722	22222.9
631.178	22107.3
634.633	22192
638.088	22191.6
641.539	22259.7
644.99	22087.8
648.439	22089.4
651.887	22128.5
655.335	22166.1
658.781	22199.9
662.225	22154.7
665.667	22166.8
669.108	22127.5
672.548	22206.4
675.987	22182.4
679.424	22184.7
682.86	22260.7
686.293	22281.4
689.727	22223.4
693.159	22216
696.59	22318.4
700.019	22277.5
703.448	22281.3
706.872	22216.8
710.298	22247.7
713.723	22231.4
717.144	22147.9
720.565	22282.5
723.984	22212.1
727.403	22203.3
730.821	22158.2
734.235	22197.2
737.651	22199.3
741.063	22152.1
744.474	22154.3
747.885	22191
751.293	22244.9
754.702	22258.1
758.108	22312.3
761.512	22229.9
764.915	22299.7
768.319	22389.5
771.719	22385.7
775.118	22424.4
778.516	22363.7
781.913	22390
785.308	22377.9
788.702	22364
792.095	22334.7
795.486	22367.4
798.876	22379.4
802.265	22384.6
805.653	22360.5
809.039	22384
812.424	22232.9
815.808	22277.2
819.191	22331.4
822.572	22300.7
825.95	22405.7
829.329	22338.3
832.706	22304.1
836.08	22271.5
839.455	22336.2
842.829	22357.7
846.199	22402.8
849.57	22381.1
852.938	22402.9
856.307	22382.1
859.672	22506.1
863.038	22359.4
866.401	22415.7
869.765	22301.5
873.125	22467.7
876.484	22491.8
879.844	22396.4
883.2	22353.8
886.555	22376.7
889.909	22374.2
893.262	22332.5
896.616	22278.9
899.966	22194.3
903.315	22202.5
906.663	22136.1
910.009	22135.8
913.354	22110.7
916.698	22094.8
920.041	22043.2
923.383	21987.2
926.723	22011.3
930.062	21949.3
933.399	21867.6
936.734	21929.2
940.069	22030.2
943.403	21958.3
946.736	21895.3
950.065	21967.3
953.396	21927.9
956.725	21812.2
960.051	21946.1
963.377	21981.2
966.7	21983.7
970.025	21986.2
973.345	21936.8
976.667	21916.5
979.985	21963.3
983.304	21875.2
986.62	21916.2
989.935	21989.2
993.25	21961.2
996.563	22012.7
999.874	22201.1
1003.19	22218.5
1006.49	22114.6
1009.8	22012
1013.11	21950.1
1016.41	21904.5
1019.72	21968.8
1023.02	21907.1
1026.32	21846.9
1029.62	21763.8
1032.92	21825
1036.22	21820.1
1039.51	21824.8
1042.81	21801.9
1046.1	21775.4
1049.39	21663.3
1052.68	21739.1
1055.97	21797
1059.26	21827.8
1062.55	21950.4
1065.83	21868.4
1069.12	21864.2
1072.4	21814.5
1075.68	21866.3
1078.97	21892.9
1082.24	21887.7
1085.52	21841.4
1088.8	21797.2
1092.08	21691.2
1095.35	21575.4
1098.62	21511.3
1101.9	21522.3
1105.17	21406.1
1108.44	21428.1
1111.7	21506.9
1114.97	21591.2
1118.23	21580.4
1121.5	21585.8
1124.76	21520.9
1128.03	21475.1
1131.29	21408.4
1134.54	21322.3
1137.8	21181.5
1141.06	21226.9
1144.31	21309.7
1147.57	21392.5
1150.82	21557.7
1154.07	21743.6
1157.32	21715.5
1160.57	21437
1163.82	21215.8
1167.07	21159.4
1170.31	21176.4
1173.56	21026.9
1176.8	20956.4
1180.04	20921
1183.28	20967.8
1186.52	20928.6
1189.76	20956.3
1192.99	20983.5
1196.23	20917.7
1199.46	20862.4
1202.7	20809.3
1205.93	20851.4
1209.16	20834.2
1212.39	20845.5
1215.62	20786.4
1218.84	20711.1
1222.07	20757.1
1225.29	20765.2
1228.52	20723.1
1231.74	20776.3
1234.96	20734.3
1238.18	20786.5
1241.4	20894.3
1244.61	20816.6
1247.83	20879.4
1251.04	20856.6
1254.25	20893
1257.47	20887.2
1260.68	20819.1
1263.89	20922.5
1267.09	20874.2
1270.3	20722.2
1273.51	20767.4
1276.71	20640.6
1279.91	20653.8
1283.12	20729.3
1286.32	20600.8
1289.52	20775.5
1292.72	20745.8
1295.91	20907
1299.11	20954.9
1302.3	21063.9
1305.5	21035.8
1308.69	20822.7
1311.88	20793.2
1315.07	20557
1318.26	20513.7
1321.44	20460.3
1324.63	20383.3
1327.82	20446.5
1331	20391.1
1334.18	20354.5
1337.36	20256.9
1340.54	20328
1343.72	20292.5
1346.9	20291.9
1350.07	20224.1
1353.25	20183.7
1356.42	20075.4
1359.6	20115.7
1362.77	20082.7
1365.94	20058.5
1369.11	20044.8
1372.28	19987.1
1375.44	19809.1
1378.61	19823.3
1381.77	19780.7
1384.93	19745.1
1388.1	19755.1
1391.26	19770.3
1394.41	19700.1
1397.57	19715.9
1400.73	19620.9
1403.89	19656.4
1407.04	19625.2
1410.19	19601.5
1413.35	19693
1416.5	19746.4
1419.65	19794.3
1422.8	19817.7
1425.94	19796.8
1429.09	20101.8
1432.23	20392.4
1435.38	20585.9
1438.52	20768.5
1441.66	20724.6
1444.8	20626.3
1447.94	20591.7
1451.08	20531.6
1454.22	20361.7
1457.35	20276.7
1460.48	20077.6
1463.62	19966.1
1466.75	19821.5
1469.88	19650.2
1473.01	19467.9
1476.14	19291.7
1479.26	19172.2
1482.39	19110.1
1485.51	19112.6
1488.64	19148
1491.76	19106.9
1494.88	19116.2
1498	19100.4
1501.12	19088.2
1504.24	19140.7
1507.35	19139.6
1510.47	19203.5
1513.58	19279.2
1516.69	19446.7
1519.81	19447.1
1522.92	19440.6
1526.03	19258.3
1529.13	19192.4
1532.24	18987.4
1535.35	18805
1538.45	18777.6
1541.55	18694.8
1544.66	18665.4
1547.76	18628.2
1550.86	18592.3
1553.96	18620.8
1557.05	18590.9
1560.15	18558
1563.24	18623
1566.34	18537.2
1569.43	18580.1
1572.52	18594.4
1575.61	18459.1
1578.7	18458.8
1581.79	18498.2
1584.88	18489.8
1587.96	18498.3
1591.05	18417.6
1594.13	18441
1597.21	18487.2
1600.3	18465.8
1603.37	18369.6
1606.45	18341.3
1609.53	18354.3
1612.61	18284.8
1615.68	18280.7
1618.76	18202.8
1621.83	18254.3
1624.9	18221.6
1627.97	18226.6
1631.04	18265.4
1634.11	18209.2
1637.18	18202
1640.24	18250.2
1643.31	18285.7
1646.37	18370.2
1649.44	18505.8
1652.5	18530.4
1655.56	18522.7
1658.62	18390.8
1661.67	18259.2
1664.73	18174.2
1667.79	18082
1670.84	17991
1673.89	17989.3
1676.95	17908.9
1680	17847.4
1683.05	17759.3
1686.1	17763.8
1689.14	17664.5
1692.19	17699.4
1695.23	17570.2
1698.28	17501
1701.32	17458.7
1704.36	17418.3
1707.4	17343.5
1710.44	17369.8
1713.48	17395.7
1716.52	17299.5
1719.56	17319.5
1722.59	17281.3
1725.63	17263.6
1728.66	17281.2
1731.69	17265.8
1734.72	17322.5
1737.75	17357
1740.78	17324.1
1743.8	17336.7
1746.83	17289.7
1749.86	17196.4
1752.88	17240
1755.9	17089.2
1758.92	17119.1
1761.94	17006.7
1764.96	16923.1
1767.98	16943.8
1771	16892.3
1774.01	16907.9
1777.03	16926.7
1780.04	16875.3
1783.05	16810.5
1786.06	16887.4
1789.07	16838.9
1792.08	16746
1795.09	16784.9
1798.1	16766.8
1801.1	16698.1
1804.11	16666
1807.11	16640.8
1810.11	16639.6
1813.11	16684.8
1816.11	16575
1819.11	16550.4
1822.11	16602.1
1825.11	16577.5
1828.1	16540.1
1831.1	16460.3
1834.09	16539.6
1837.08	16465.9
1840.07	16470.2
1843.06	16452.4
1846.05	16439.7
1849.04	16374.5
1852.02	16391.5
1855.01	16320.9
1857.99	16337.9
1860.98	16350.1
1863.96	16313.5
1866.94	16250.5
1869.92	16296.2
1872.9	16229.9
1875.88	16176.9
1878.85	16218.1
1881.83	16144.3
1884.8	16139.8
1887.78	16035.3
1890.75	16137.2
1893.72	16097.7
1896.69	16003.1
1899.66	15978.2
1902.63	15935
1905.59	15811.3
1908.56	15738.9
1911.52	15714.7
1914.49	15651
1917.45	15518.7
1920.41	15518.7
1923.37	15405.3
1926.33	15399.3
1929.29	15320.1
1932.24	15271.8
1935.2	15191
1938.15	15117.9
1941.1	15078.4
1944.06	15003.5
1947.01	15011.8
1949.96	14865.4
1952.91	14773.6
1955.86	14708.9
1958.8	14630.1
1961.75	14589
1964.69	14548
1967.64	14474.6
1970.58	14426
1973.52	14355.9
1976.46	14309.6
1979.4	14271.2
1982.34	14198.5
1985.27	14160.9
1988.21	14076.4
1991.14	14035.3
1994.08	13950.8
1997.01	13898
1999.94	13814.5
2002.87	13783.9
2005.8	13729.4
2008.73	13699
2011.66	13666.9
2014.58	13614.3
2017.51	13562.7
2020.43	13522
2023.36	13455.9
2026.28	13407.7
2029.2	13363.5
2032.12	13333.4
2035.04	13262.8
2037.95	13252.8
2040.87	13198.1
2043.78	13181
2045.76	13133.6
2048.69	13126.1
2051.61	13092.4
2054.54	13115.4
2057.46	13077.4
2060.38	13021.7
2063.3	13047.6
2066.22	13083.9
2069.14	13004
2072.06	12967.7
2074.98	12963.9
2077.89	12977.2
2080.81	12922.8
2083.72	12914.2
2086.63	12890.8
2089.55	12895.8
2092.46	12883.5
2095.37	12838.3
2098.28	12834.9
2101.18	12781.5
2104.09	12778.9
2106.99	12780.9
2109.9	12788.3
2112.8	12738.1
2115.71	12703.8
2118.61	12689
2121.51	12717.8
2124.4	12634.2
2127.3	12648.2
2130.2	12624.8
2133.09	12602
2135.99	12607.8
2138.88	12604.8
2141.78	12583.6
2144.67	12589.2
2147.56	12590.6
2150.45	12511.3
2153.34	12521.7
2156.22	12521.2
2159.11	12530.6
2162	12462.1
2164.88	12505.1
2167.76	12520.7
2170.64	12485.5
2173.53	12427.9
2176.41	12421.8
2179.29	12425.4
2182.16	12414.9
2185.04	12369.9
2187.92	12381
2190.79	12356.4
2193.66	12361.9
2196.54	12347.6
2199.41	12340.8
2202.28	12318.6
2205.15	12284.8
2208.02	12283.8
2210.88	12265.8
2213.75	12162.8
2216.62	12221.5
2219.48	12169.2
2222.34	12095.5
2225.21	12085.7
2228.07	12043.2
2230.93	12106.7
2233.79	12032.9
2236.65	12034.4
2239.5	12008.5
2242.36	12005.1
2245.21	11972
2248.07	11932
2250.92	11927.6
2253.77	11896
2256.62	11856.1
2259.47	11824
2262.32	11780.9
2265.17	11756.4
2268.02	11755.1
2270.86	11703.1
2273.71	11685.9
2276.55	11625.5
2279.39	11605.1
2282.24	11602.5
2285.08	11565.4
2287.92	11578.1
2290.75	11515.8
2293.59	11506.3
2296.43	11460.4
2299.26	11488.1
2302.1	11437.5
2304.93	11369.8
2307.76	11349.7
2310.6	11405.2
2313.43	11323.9
2316.25	11305.1
2319.08	11266.2
2321.91	11255.1
2324.74	11291.3
2327.56	11480.3
2330.39	11490.7
2333.21	11145.6
2336.03	11167.2
2338.85	11086.5
2341.67	11143.8
2344.49	11084.6
2347.31	11046.2
2350.13	11033.2
2352.94	11014.9
2355.76	11016
2358.57	10906.9
2361.39	10920
2364.2	10902.4
2367.01	10882.1
2369.82	10893.5
2372.63	10860
2375.44	10824
2378.24	10846.5
2381.05	10795.7
2383.85	10785.7
2386.66	10715.4
2389.46	10747.6
2392.26	10750.4
2395.06	10714
2397.86	10666.1
2400.66	10689.4
2403.46	10674
2406.26	10661.2
2409.05	10614.4
2411.85	10608.9
2414.64	10593.5
2417.43	10597.6
2420.23	10538.3
2423.02	10458.3
2425.81	10482.7
2428.6	10466
2431.38	10493.2
2434.17	10473.1
2436.96	10433.4
2439.74	10428.7
2442.53	10415.6
2445.31	10416.9
2448.09	10428.3
2450.87	10320.8
2453.65	10361.1
2456.43	10334.2
2459.21	10270.6
2461.98	10278.6
2464.76	10236.4
2467.53	10271.3
2470.31	10256.7
2473.08	10220.3
2475.85	10216
2478.63	10179.6
2481.39	10193.2
2484.16	10171.4
2486.93	10169.4
2489.7	10103.4
2492.46	10128.7
2495.23	10072
2497.99	10076.8
2500.76	10055.3
2503.52	10034.1
2506.28	10036.7
2509.04	10011.6
2511.8	10000.1
2514.56	9979.72
2517.31	9940.82
2520.07	9973.16
2522.82	9937.07
2525.58	9913.73
2528.33	9873.05
2531.09	9865
2533.84	9885.05
2536.59	9873.74
2539.34	9852.8
2542.08	9831.28
2544.83	9808.85
2547.58	9790.08
2550.32	9755.87
2553.07	9768.06
2555.81	9739.39
2558.55	9733.23
2561.29	9702.21
2564.03	9710.63
2566.77	9706.52
2569.51	9652.96
2572.25	9679.17
2574.99	9670.75
2577.72	9622.05
2580.46	9666.01
2583.19	9589.96
2585.92	9631.48
2588.65	9608.54
2591.38	9575.09
2594.11	9601.14
2596.84	9612.67
2599.57	9541.8
2602.3	9560.63
2605.02	9523.06
2607.75	9560.58
2610.47	9529.92
2613.19	9507.71
2615.92	9442.34
2618.64	9492.01
2621.36	9461.72
2624.08	9466.32
2626.8	9434.04
2629.51	9431.67
2632.23	9403
2634.94	9429.56
2637.66	9367.91
2640.37	9361.76
2643.08	9361.19
2645.79	9347.7
2648.5	9361.61
2651.21	9368.58
2653.92	9345.89
2656.63	9296.35
2659.33	9301.2
2662.04	9304.07
2664.75	9274.65
2667.45	9324.97
2670.15	9320.06
2672.85	9278.59
2675.55	9257.23
2678.25	9231.11
2680.95	9242.98
2683.65	9224.7
2686.35	9174.11
2689.04	9192.76
2691.74	9211.86
2694.43	9171.21
2697.13	9197.53
2699.82	9140.6
2702.51	9166.95
2705.2	9200.24
2707.89	9125.96
2710.58	9172.06
2713.26	9127.43
2715.95	9153.17
2718.64	9118.87
2721.32	9121.07
2724	9059.91
2726.69	9109.17
2729.37	9084.31
2732.05	9082.65
2734.73	9041.29
2737.41	8980.81
2740.09	8995.75
2742.76	9027.86
2745.44	8951.58
2748.11	8915.11
2750.79	8878.8
2753.46	8844.04
2756.13	8876.89
2758.81	8840.11
2761.47	8859.43
2764.14	8825.56
2766.81	8789.09
2769.48	8814.42
2772.15	8771.33
2774.81	8725.17
2777.48	8717.27
2780.14	8677.24
2782.8	8694.36
2785.47	8684.95
2788.13	8689.59
2790.79	8695.54
2793.44	8668.88
2796.1	8690.98
2798.76	8683.75
2801.42	8646.22
2804.07	8631.69
2806.73	8613.14
2809.38	8600.56
2812.03	8620.2
2814.68	8593.4
2817.33	8633.19
2819.98	8611.07
2822.63	8605.36
2825.28	8628.49
2827.93	8667.27
2830.57	8679.14
2833.22	8732.15
2835.86	8821.65
2838.51	8954.11
2841.15	9149.52
2843.79	9478.65
2846.43	9870.02
2849.07	10157.9
2851.71	10257.9
2854.35	10202.2
2856.98	10079.1
2859.62	9980.16
2862.25	9863.32
2864.89	9848.1
2867.52	9844.46
2870.15	9880.73
2872.78	9941.5
2875.41	9999.46
2878.04	10056.7
2880.67	10090.5
2883.3	10115.8
2885.92	10167.1
2888.55	10252.3
2891.18	10238.8
2893.8	10268.1
2896.42	10254.9
2899.04	10214
2901.67	10217
2904.29	10179.4
2906.9	10178.9
2909.52	10164.9
2912.14	10110
2914.76	10121.8
2917.37	10060.7
2919.99	10060.5
2922.6	10041.5
2925.21	10091.7
2927.82	10106.9
2930.44	10084.9
2933.05	10058.4
2935.65	9966.34
2938.26	9853.85
2940.87	9768.96
2943.48	9517.1
2946.08	9356.32
2948.69	9198.14
2951.29	9140.13
2953.89	9091.29
2956.49	9035.48
2959.1	8988.08
2961.7	8949.02
2964.29	8849.54
2966.89	8766.67
2969.49	8700.1
2972.09	8643.22
2974.68	8569.1
2977.28	8480.19
2979.87	8441.58
2982.46	8392.32
2985.05	8313.32
2987.65	8310.8
2990.24	8262.38
2992.82	8243.73
2995.41	8209.74
2998	8152.63
3000.59	8145.12
3003.17	8140.79
3005.76	8090.13
3008.34	8055.39
3010.92	8035.22
3013.5	8016.42
3016.09	8003.79
3018.67	7980.77
3021.25	7960.82
3023.82	7872.94
3026.4	7887.03
3028.98	7867.28
3031.55	7840.23
3034.13	7862.73
3036.7	7833.54
3039.28	7803.98
3041.85	7807.48
3044.42	7818.73
3046.99	7850.02
3049.56	7847.34
3052.13	7859.55
3054.69	7859.79
3057.26	7871.62
3059.83	7846.1
3062.39	7856.69
3064.95	7836.73
3067.52	7872.24
3070.08	7839.47
3072.64	7848.06
3075.2	7863.24
3077.76	7856.78
3080.32	7874.15
3082.88	7848.65
3085.44	7824.89
3087.99	7863.45
3090.55	7856.42
3093.1	7894.64
3095.65	7861.82
3098.21	7884.15
3100.76	7880.24
3103.31	7885.09
3105.86	7927.13
3108.41	7909.5
3110.96	7965.87
3113.5	7962.29
3116.05	7989.71
3118.59	7993.56
3121.14	8040.04
3123.68	8004.11
3126.23	8043.46
3128.77	8098.89
3131.31	8096.03
3133.85	8126.55
3136.39	8135.51
3138.93	8124.1
3141.46	8148.11
3144	8195.54
3146.54	8194.87
3149.07	8258.35
3151.6	8310.07
3154.14	8267.76
3156.67	8360.35
3159.2	8304.79
3161.73	8350.18
3164.26	8337.63
3166.79	8345.47
3169.32	8339.2
3171.84	8358.31
3174.37	8333.64
3176.9	8319.96
3179.42	8330
3181.94	8372.79
3184.47	8317.53
3186.99	8309.02
3189.51	8337.28
3192.03	8287.09
3194.55	8268.96
3197.07	8220.27
3199.58	8286.77
3202.1	8280.83
3204.62	8290.69
3207.13	8217.66
3209.65	8215.26
3212.16	8220.46
3214.67	8191.78
3217.18	8178.9
3219.69	8162.56
3222.2	8160.07
3224.71	8149.05
3227.22	8158.06
3229.73	8121.1
3232.23	8146.13
3234.74	8085.4
3237.24	8085.05
3239.75	8059.78
3242.25	8055
3244.75	8019.69
3247.25	8000.58
3249.75	8004.66
3252.25	7974.06
3254.75	7943.62
3257.25	7912.72
3259.74	7862.4
3262.24	7858.99
3264.73	7863.62
3267.23	7842.18
3269.72	7835.58
3272.21	7816.14
3274.7	7798.2
3277.2	7766.11
3279.69	7747.97
3282.17	7715.09
3284.66	7721.57
3287.15	7684.74
3289.64	7663.61
3292.12	7665.09
3293.56	7651.92
3296.05	7624.47
3298.55	7625.2
3301.04	7601.13
3303.54	7601.6
3306.03	7589.54
3308.52	7593.53
3311.01	7564
3313.5	7540.42
3315.99	7526.84
3318.48	7529.98
3320.97	7518.6
3323.45	7521.46
3325.94	7507.48
3328.42	7460.47
3330.91	7451.27
3333.39	7480.36
3335.87	7495.4
3338.36	7454.84
3340.84	7407.27
3343.32	7414.4
3345.8	7411.37
3348.27	7358.24
3350.75	7368.73
3353.23	7381.41
3355.7	7383.02
3358.18	7364.7
3360.65	7360.6
3363.13	7288.31
3365.6	7344.28
3368.07	7308.15
3370.54	7318.43
3373.01	7300.18
3375.48	7312.41
3377.95	7304.08
3380.42	7264.23
3382.88	7251.68
3385.35	7255.48
3387.81	7230.55
3390.28	7211.17
3392.74	7207.04
3395.2	7190.08
3397.67	7187.24
3400.13	7178.58
3402.58	7165.8
3405.05	7191.58
3407.5	7158.57
3409.96	7109.68
3412.42	7163.62
3414.87	7097.54
3417.33	7082.89
3419.78	7067.51
3422.23	7042.02
3424.69	7039.68
3427.14	7033.35
3429.59	6999.94
3432.04	6984.31
3434.49	6938.09
3436.94	6933.06
3439.39	6915.69
3441.83	6847.35
3444.28	6863.65
3446.72	6843.74
3449.17	6797.31
3451.61	6794.7
3454.05	6744.5
3456.5	6771.53
3458.94	6693.32
3461.38	6654.13
3463.81	6628.48
3466.25	6602.97
3468.69	6567.54
3471.13	6551.12
3473.56	6513.41
3476	6477.96
3478.43	6458.52
3480.87	6410.25
3483.3	6373.95
3485.73	6387.75
3488.16	6319.35
3490.59	6290.19
3493.02	6243.72
3495.45	6222.24
3497.88	6162.89
3499.09	6127.95