File: src/Milk_AI/Heritage special RT 532nm 50% 600g 50xL 10s 10times 400-3500cm-1 200hole_Re.txt
#Acq. time (s)=	10
#Accumulations=	10
#Range (cm-¹)=	400...3500
#Windows=	3
#Auto scanning=	Off
#Autofocus=	Off
#AutoExposure=	Off
#Spike filter=	Multiple accum.
#Delay time (s)=	0
#Binning=	1
#Readout mode=	Signal
#DeNoise=	Off
#ICS correction=	On
#Dark correction=	Off
#Inst. Process=	Off
#Detector Gain=	Best Dynamic Range
#Detector ADC=	45 kHz
#Detector temperature (°C)=	-60.1
#Instrument=	LabRAM HR Evol
#Detector=	Syncerity OE
#Objective=	x50_VIS_LWD
#Grating=	600 (500nm)
#ND Filter=	50%
#Laser=	532nm_Edge
#Hole=	199.981
#Range=	Visible
#E-Cal_Neon=	0
#StageXY=	75x50mm Scan+
#StageZ=	Z motor
#X (µm)=	0
#Y (µm)=	0
#Z (µm)=	242.4
#Spectral res.(cm-¹)=	12.8
#Full time(mm:ss)=	5:19
#AC=	Calibrated 2025-07-01 10:31
#Project=
#Sample=
#Site=
#Title=	D_2
#Remark=
#Date=	01.07.2025 11:18 (India Standard Time)
#Acquired=	01.07.2025 11:18:00 (India Standard Time)
#AxisType[0]=Intens
#AxisUnit[0]=Cnt
#AxisType[1]=Spectr
#AxisUnit[1]=1/cm
400.083	24989.3
403.63	24879.7
407.176	24960.5
410.72	24979
414.263	24920.5
417.805	25066.6
421.345	24979.4
424.884	25038.3
428.421	25070.8
431.955	25044.7
435.49	25160.3
439.023	25088.9
442.555	25021
446.084	24991.7
449.613	25030.4
453.141	24979.5
456.666	25004.6
460.191	24994.8
463.715	24939.6
467.235	24969.4
470.756	25016.5
474.274	24976.1
477.793	25011.4
481.308	24946.2
484.823	24977.3
488.336	24994.4
491.847	25000.3
495.358	24990.8
498.867	25134.8
502.374	25185.7
505.881	25198.4
509.386	25191.5
512.888	25254.6
516.39	25226.4
519.89	25174.2
523.391	25064.5
526.889	25177.8
530.385	25172.2
533.88	25108.3
537.373	25088.1
540.866	25054.3
544.357	25072.6
547.846	25059.8
551.334	25043.9
554.821	25072.9
558.307	25063.1
561.789	25042.4
565.272	25099.1
568.753	25128.1
572.233	25139.9
575.712	25115.5
579.188	25155.9
582.664	25167
586.139	25151.8
589.611	25164.6
593.083	25275.4
596.554	25208.5
600.021	25191.6
603.49	25220.4
606.955	25282.9
610.42	25187.7
613.882	25156.5
617.345	25174.1
620.805	25133.9
624.263	25130
627.722	24957.8
631.178	24996.7
634.633	24962.1
638.088	24962.6
641.539	25096.7
644.99	24914
648.439	24935.1
651.887	24873.9
655.335	24986.1
658.781	24976.5
662.225	24882.3
665.667	24907.6
669.108	24892
672.548	24965.3
675.987	24887
679.424	24926.2
682.86	24974.3
686.293	24948.6
689.727	24983.6
693.159	24975.8
696.59	25021.8
700.019	25028.4
703.448	25040.8
706.872	24953.9
710.298	24939
713.723	25022.8
717.144	24976.4
720.565	25130.4
723.984	25006.2
727.403	24932.5
730.821	24916.4
734.235	24997.8
737.651	24916.9
741.063	24873.2
744.474	24842.8
747.885	24895.8
751.293	24941.3
754.702	24928.2
758.108	25052
761.512	25027.7
764.915	25003.1
768.319	25198.7
771.719	25061.1
775.118	25112.7
778.516	25072.3
781.913	25122.6
785.308	25227.6
788.702	25147.5
792.095	25076
795.486	25139.4
798.876	25115.5
802.265	25139.2
805.653	25090.7
809.039	25162.3
812.424	25074.6
815.808	25046.4
819.191	25151.8
822.572	25323.9
825.95	25347.1
829.329	25372.8
832.706	25381.4
836.08	25351.9
839.455	25432.6
842.829	25530.9
846.199	25541.5
849.57	25632.8
852.938	25704.9
856.307	25782.5
859.672	25789.4
863.038	25765.6
866.401	25664.7
869.765	25651.8
873.125	25675.2
876.484	25950.9
879.844	25680.9
883.2	25551.8
886.555	25590.5
889.909	25516
893.262	25485.2
896.616	25383.8
899.966	25311.7
903.315	25281.9
906.663	25184
910.009	25135.1
913.354	25119
916.698	25057.2
920.041	25047.6
923.383	24971.1
926.723	24936.5
930.062	24941.1
933.399	24872.7
936.734	24823.8
940.069	24860.5
943.403	24817.2
946.736	24805.3
950.065	24827.4
953.396	24802
956.725	24768.7
960.051	24791.3
963.377	24831
966.7	24799.7
970.025	24841.4
973.345	24773.7
976.667	24676.8
979.985	24710.1
983.304	24714.8
986.62	24794.7
989.935	24796.3
993.25	24858.6
996.563	24940.4
999.874	25233.2
1003.19	25332.3
1006.49	25137.1
1009.8	24951.7
1013.11	24882.7
1016.41	24911.7
1019.72	24859.2
1023.02	24805.9
1026.32	24841.2
1029.62	24809.6
1032.92	24719.2
1036.22	24777.6
1039.51	24648.3
1042.81	24640.2
1046.1	24665.8
1049.39	24707.2
1052.68	24747.9
1055.97	24880.9
1059.26	25027.2
1062.55	25018.8
1065.83	25093.6
1069.12	24992.5
1072.4	25125.1
1075.68	25147.1
1078.97	25229.6
1082.24	25231.3
1085.52	25121.9
1088.8	24983
1092.08	24781
1095.35	24641.7
1098.62	24503
1101.9	24348.7
1105.17	24289.2
1108.44	24236.4
1111.7	24309.9
1114.97	24395.5
1118.23	24515.2
1121.5	24551.5
1124.76	24407.1
1128.03	24303.7
1131.29	24102.4
1134.54	23927.2
1137.8	23825.8
1141.06	23818.8
1144.31	23938.4
1147.57	24053.8
1150.82	24131.3
1154.07	24403.9
1157.32	24367.4
1160.57	24036.1
1163.82	23838.1
1167.07	23745.9
1170.31	23632.4
1173.56	23581.3
1176.8	23511.5
1180.04	23519.3
1183.28	23467.5
1186.52	23412.9
1189.76	23519.4
1192.99	23469.7
1196.23	23402.9
1199.46	23454.9
1202.7	23375.8
1205.93	23435.9
1209.16	23396
1212.39	23385.4
1215.62	23334.8
1218.84	23284
1222.07	23308.6
1225.29	23413.8
1228.52	23421.6
1231.74	23401.7
1234.96	23438.8
1238.18	23487
1241.4	23616.1
1244.61	23569.7
1247.83	23727.8
1251.04	23728.5
1254.25	23806.3
1257.47	23772.3
1260.68	23793.5
1263.89	23827
1267.09	23819.4
1270.3	23619
1273.51	23661.9
1276.71	23537.3
1279.91	23611.1
1283.12	23640.4
1286.32	23611.2
1289.52	23820.2
1292.72	24035.3
1295.91	24462
1299.11	24574.3
1302.3	24626.5
1305.5	24488.7
1308.69	24206.7
1311.88	23992.7
1315.07	23716.1
1318.26	23476.7
1321.44	23317.8
1324.63	23177.2
1327.82	23160.3
1331	23046.3
1334.18	22949.1
1337.36	22953
1340.54	22988.4
1343.72	22917.9
1346.9	22869.9
1350.07	22770.6
1353.25	22707.4
1356.42	22603.4
1359.6	22555.2
1362.77	22542.1
1365.94	22525.8
1369.11	22419.5
1372.28	22397.9
1375.44	22283.6
1378.61	22211.8
1381.77	22082.2
1384.93	22015.6
1388.1	22142.7
1391.26	22080.8
1394.41	22071.8
1397.57	22127
1400.73	22097
1403.89	22103
1407.04	22071
1410.19	22135.2
1413.35	22264.6
1416.5	22383.9
1419.65	22490
1422.8	22572.1
1425.94	22796.5
1429.09	23349.7
1432.23	24113.6
1435.38	24811.7
1438.52	25067
1441.66	24980
1444.8	24788.2
1447.94	24522.6
1451.08	24375.9
1454.22	24115
1457.35	23938.4
1460.48	23565.7
1463.62	23263.2
1466.75	22878.4
1469.88	22502.7
1473.01	22100.1
1476.14	21786.2
1479.26	21606.4
1482.39	21465.7
1485.51	21334.4
1488.64	21346.8
1491.76	21288.7
1494.88	21232.6
1498	21219.5
1501.12	21215.3
1504.24	21256.2
1507.35	21250.9
1510.47	21345.4
1513.58	21455.1
1516.69	21585.5
1519.81	21623.3
1522.92	21599.7
1526.03	21419.9
1529.13	21293.4
1532.24	21033.6
1535.35	20898.9
1538.45	20823
1541.55	20817.4
1544.66	20798.8
1547.76	20699.5
1550.86	20668.3
1553.96	20703.3
1557.05	20688.8
1560.15	20566.9
1563.24	20632.1
1566.34	20633.7
1569.43	20586.4
1572.52	20650.1
1575.61	20547.9
1578.7	20468.1
1581.79	20516.3
1584.88	20524.2
1587.96	20558
1591.05	20523.9
1594.13	20526.1
1597.21	20515.3
1600.3	20576.9
1603.37	20608.8
1606.45	20499.7
1609.53	20458.5
1612.61	20433.1
1615.68	20388.5
1618.76	20388.3
1621.83	20396.3
1624.9	20322.2
1627.97	20412
1631.04	20418.5
1634.11	20455.6
1637.18	20492.9
1640.24	20562.8
1643.31	20681.6
1646.37	21019.7
1649.44	21355.2
1652.5	21583.3
1655.56	21458.8
1658.62	21109.8
1661.67	20802.6
1664.73	20638.3
1667.79	20535.9
1670.84	20440.8
1673.89	20358.8
1676.95	20174.1
1680	19975.7
1683.05	19942.6
1686.1	19831.8
1689.14	19738.6
1692.19	19672.4
1695.23	19562.4
1698.28	19444.9
1701.32	19358.7
1704.36	19362.7
1707.4	19267.3
1710.44	19243.9
1713.48	19235.4
1716.52	19213
1719.56	19153.1
1722.59	19186
1725.63	19230.9
1728.66	19251
1731.69	19254.8
1734.72	19376.5
1737.75	19419.5
1740.78	19481.2
1743.8	19499.7
1746.83	19491.9
1749.86	19472.7
1752.88	19252.4
1755.9	19150.5
1758.92	18980.2
1761.94	18837.4
1764.96	18755.2
1767.98	18718.4
1771	18751
1774.01	18758.5
1777.03	18667.1
1780.04	18634.2
1783.05	18595.7
1786.06	18565.7
1789.07	18646.6
1792.08	18533.8
1795.09	18611.2
1798.1	18483
1801.1	18456.6
1804.11	18437.1
1807.11	18411.8
1810.11	18399.5
1813.11	18386
1816.11	18348.8
1819.11	18339.4
1822.11	18244.6
1825.11	18288.5
1828.1	18295.7
1831.1	18243.1
1834.09	18309
1837.08	18183.4
1840.07	18237.3
1843.06	18182.4
1846.05	18164.7
1849.04	18157.8
1852.02	18107.7
1855.01	18101.7
1857.99	18037.4
1860.98	18002.8
1863.96	18093.4
1866.94	18051.3
1869.92	17930.9
1872.9	17917.6
1875.88	17943.4
1878.85	17930
1881.83	17902.3
1884.8	17837.7
1887.78	17784.3
1890.75	17740
1893.72	17757.6
1896.69	17683.9
1899.66	17690.9
1902.63	17546.7
1905.59	17468.9
1908.56	17391.1
1911.52	17315.5
1914.49	17243.8
1917.45	17146.7
1920.41	17075.6
1923.37	16999.4
1926.33	16937.2
1929.29	16883.5
1932.24	16857
1935.2	16699.1
1938.15	16660.3
1941.1	16575.3
1944.06	16514.8
1947.01	16423
1949.96	16322.9
1952.91	16243.4
1955.86	16116.1
1958.8	16063.4
1961.75	15974.6
1964.69	15997.6
1967.64	15840.5
1970.58	15812.3
1973.52	15712.3
1976.46	15693.3
1979.4	15623.6
1982.34	15584.8
1985.27	15544
1988.21	15425.1
1991.14	15339.9
1994.08	15235.8
1997.01	15184.6
1999.94	15102.4
2002.87	15030.3
2005.8	14989.6
2008.73	14947.1
2011.66	14888.6
2014.58	14872
2017.51	14785.1
2020.43	14719.7
2023.36	14635.7
2026.28	14565.4
2029.2	14540.2
2032.12	14491.7
2035.04	14444.7
2037.95	14398.9
2040.87	14371.8
2043.78	14291.7
2045.76	14271.9
2048.69	14254
2051.61	14237
2054.54	14266.1
2057.46	14187.8
2060.38	14136.3
2063.3	14156.7
2066.22	14114.2
2069.14	14155.5
2072.06	14113.7
2074.98	14058.5
2077.89	14075
2080.81	14096.4
2083.72	13987.2
2086.63	14051.8
2089.55	13973.3
2092.46	13977.1
2095.37	13933.4
2098.28	13949.4
2101.18	13917.2
2104.09	13840
2106.99	13790.5
2109.9	13806.5
2112.8	13775.6
2115.71	13762.9
2118.61	13690.9
2121.51	13699.2
2124.4	13731.5
2127.3	13676.7
2130.2	13676.4
2133.09	13629.8
2135.99	13670.7
2138.88	13608.9
2141.78	13604.9
2144.67	13604.3
2147.56	13572
2150.45	13528.2
2153.34	13502.6
2156.22	13535.7
2159.11	13519.5
2162	13500.4
2164.88	13494.2
2167.76	13515.3
2170.64	13427.2
2173.53	13417.9
2176.41	13412.2
2179.29	13369.3
2182.16	13332.8
2185.04	13376.9
2187.92	13351.7
2190.79	13346.3
2193.66	13311.1
2196.54	13251.3
2199.41	13209.9
2202.28	13243.5
2205.15	13218.3
2208.02	13235.2
2210.88	13145.7
2213.75	13169.2
2216.62	13098.6
2219.48	13084.6
2222.34	13045.3
2225.21	13011.8
2228.07	13009.4
2230.93	12989.9
2233.79	12938.7
2236.65	12932.6
2239.5	12904.2
2242.36	12870.4
2245.21	12872
2248.07	12807
2250.92	12797.3
2253.77	12778.9
2256.62	12740.2
2259.47	12681.3
2262.32	12631.8
2265.17	12565.4
2268.02	12541.6
2270.86	12500.3
2273.71	12535.4
2276.55	12458.1
2279.39	12483.8
2282.24	12374.9
2285.08	12371.4
2287.92	12325.7
2290.75	12380.3
2293.59	12309.5
2296.43	12249.2
2299.26	12245.4
2302.1	12209.1
2304.93	12155
2307.76	12172.4
2310.6	12166.4
2313.43	12107.3
2316.25	12091.4
2319.08	12012.7
2321.91	12026.7
2324.74	12082.6
2327.56	12214.2
2330.39	12216.2
2333.21	11943.6
2336.03	11888.3
2338.85	11842.9
2341.67	11836.4
2344.49	11839.8
2347.31	11812.7
2350.13	11802.5
2352.94	11676.2
2355.76	11686.1
2358.57	11593.3
2361.39	11607.1
2364.2	11589.8
2367.01	11567.6
2369.82	11522.7
2372.63	11496.4
2375.44	11486.9
2378.24	11498.5
2381.05	11471
2383.85	11454.3
2386.66	11400.3
2389.46	11424.6
2392.26	11375.9
2395.06	11324.8
2397.86	11348.2
2400.66	11317.5
2403.46	11273.2
2406.26	11237
2409.05	11282.6
2411.85	11259.9
2414.64	11208.5
2417.43	11203.9
2420.23	11158.2
2423.02	11159.4
2425.81	11087.6
2428.6	11117.8
2431.38	11092.7
2434.17	11075.6
2436.96	11052.2
2439.74	11051.8
2442.53	10992.9
2445.31	10992.4
2448.09	10997.6
2450.87	10967.6
2453.65	10931.1
2456.43	10963.7
2459.21	10888.5
2461.98	10870.9
2464.76	10834.3
2467.53	10829.5
2470.31	10827.3
2473.08	10743.3
2475.85	10735.5
2478.63	10823.3
2481.39	10733.4
2484.16	10693.5
2486.93	10737.6
2489.7	10698
2492.46	10617.3
2495.23	10624
2497.99	10637.4
2500.76	10593.7
2503.52	10537.5
2506.28	10494.1
2509.04	10463.9
2511.8	10458.1
2514.56	10485.6
2517.31	10410.5
2520.07	10458.1
2522.82	10460.5
2525.58	10384.6
2528.33	10374.8
2531.09	10386.5
2533.84	10383.8
2536.59	10369.6
2539.34	10344.6
2542.08	10298.2
2544.83	10259.8
2547.58	10287.1
2550.32	10218.6
2553.07	10198.9
2555.81	10201.8
2558.55	10196.3
2561.29	10166.4
2564.03	10185.3
2566.77	10169.7
2569.51	10148.8
2572.25	10101.7
2574.99	10094.8
2577.72	10081.8
2580.46	10132.4
2583.19	10086.5
2585.92	10090.7
2588.65	10032.3
2591.38	10029.6
2594.11	10067.7
2596.84	10028.1
2599.57	10027.4
2602.3	9986.84
2605.02	9986.21
2607.75	9978.58
2610.47	9983.79
2613.19	9910.02
2615.92	9877.17
2618.64	9855.62
2621.36	9881.02
2624.08	9858.4
2626.8	9869.71
2629.51	9835.22
2632.23	9828.24
2634.94	9813.31
2637.66	9776.38
2640.37	9759.8
2643.08	9774.22
2645.79	9760.76
2648.5	9774.15
2651.21	9729.52
2653.92	9713.34
2656.63	9695.16
2659.33	9707.44
2662.04	9676.78
2664.75	9686.72
2667.45	9649.6
2670.15	9671.82
2672.85	9639.68
2675.55	9623.36
2678.25	9617.05
2680.95	9564.63
2683.65	9598.22
2686.35	9596.15
2689.04	9568.78
2691.74	9592.9
2694.43	9569.63
2697.13	9523.82
2699.82	9538.81
2702.51	9525.26
2705.2	9514.37
2707.89	9513.29
2710.58	9566.96
2713.26	9543.5
2715.95	9543.98
2718.64	9514.53
2721.32	9541.28
2724	9524.76
2726.69	9519.48
2729.37	9556.1
2732.05	9508.37
2734.73	9456.27
2737.41	9396.65
2740.09	9308.55
2742.76	9299.84
2745.44	9231.76
2748.11	9206.69
2750.79	9202
2753.46	9181.4
2756.13	9109.98
2758.81	9096.36
2761.47	9094.04
2764.14	9088.36
2766.81	9085.23
2769.48	9038.09
2772.15	9000.15
2774.81	8999.62
2777.48	8992.41
2780.14	8921.86
2782.8	8918.07
2785.47	8907.01
2788.13	8912.28
2790.79	8874.94
2793.44	8932.36
2796.1	8900.82
2798.76	8899.36
2801.42	8865.6
2804.07	8907.67
2806.73	8869.56
2809.38	8831.99
2812.03	8868.05
2814.68	8849.01
2817.33	8889.56
2819.98	8902.58
2822.63	8914.22
2825.28	8969.6
2827.93	9033.52
2830.57	9101.73
2833.22	9242.62
2835.86	9442.51
2838.51	9720.57
2841.15	10183.1
2843.79	10995.8
2846.43	11935.8
2849.07	12707.7
2851.71	12960.5
2854.35	12799.7
2856.98	12538.6
2859.62	12329.4
2862.25	12052.5
2864.89	11959.4
2867.52	11913.9
2870.15	12044.5
2872.78	12270.6
2875.41	12323.7
2878.04	12354.9
2880.67	12459.5
2883.3	12624.7
2885.92	12732.7
2888.55	12832.8
2891.18	12901
2893.8	12841.3
2896.42	12883
2899.04	12812.8
2901.67	12804.8
2904.29	12795.7
2906.9	12750
2909.52	12724.1
2912.14	12678
2914.76	12680
2917.37	12644.4
2919.99	12690.9
2922.6	12650.9
2925.21	12665.3
2927.82	12654.4
2930.44	12692.9
2933.05	12646.5
2935.65	12529.1
2938.26	12478.8
2940.87	11967.5
2943.48	11566.6
2946.08	11089.6
2948.69	10836.9
2951.29	10602.4
2953.89	10496.2
2956.49	10375.6
2959.1	10246.2
2961.7	10149.2
2964.29	9993.53
2966.89	9820.59
2969.49	9662.58
2972.09	9502.54
2974.68	9357.78
2977.28	9236.84
2979.87	9105.03
2982.46	9058.78
2985.05	8927.13
2987.65	8798.28
2990.24	8732.04
2992.82	8655.01
2995.41	8647.86
2998	8604.33
3000.59	8534.74
3003.17	8553.61
3005.76	8506.19
3008.34	8458.49
3010.92	8368.83
3013.5	8317.13
3016.09	8247.4
3018.67	8169.42
3021.25	8124.55
3023.82	8114.37
3026.4	8055.14
3028.98	7992.54
3031.55	8004.62
3034.13	7979.22
3036.7	7940.85
3039.28	7985.55
3041.85	7913.75
3044.42	7960.72
3046.99	7920.02
3049.56	7936.6
3052.13	7933.14
3054.69	8020.7
3057.26	8013.31
3059.83	8006.39
3062.39	8026.04
3064.95	8006.78
3067.52	8033.49
3070.08	7992.74
3072.64	7964.62
3075.2	8003.45
3077.76	7985.61
3080.32	7952.69
3082.88	7946.84
3085.44	7971.39
3087.99	7954.86
3090.55	7968.23
3093.1	7962.72
3095.65	7977.63
3098.21	8002.32
3100.76	7949.63
3103.31	8040.76
3105.86	8067.43
3108.41	8078.72
3110.96	8086.03
3113.5	8114.86
3116.05	8130.59
3118.59	8180.91
3121.14	8158.27
3123.68	8162.78
3126.23	8236.41
3128.77	8261.5
3131.31	8274.96
3133.85	8313.2
3136.39	8339.34
3138.93	8359.22
3141.46	8390.94
3144	8395.35
3146.54	8433.69
3149.07	8467.28
3151.6	8502.51
3154.14	8476.27
3156.67	8557.6
3159.2	8575.7
3161.73	8582.64
3164.26	8621.75
3166.79	8621.21
3169.32	8625
3171.84	8651.34
3174.37	8665.85
3176.9	8647.46
3179.42	8672.21
3181.94	8620.23
3184.47	8693.33
3186.99	8654.02
3189.51	8672.13
3192.03	8649.4
3194.55	8661.34
3197.07	8676.7
3199.58	8655.12
3202.1	8680.32
3204.62	8658.17
3207.13	8691.24
3209.65	8659.56
3212.16	8651.5
3214.67	8644.9
3217.18	8618.95
3219.69	8629.34
3222.2	8623.55
3224.71	8586.28
3227.22	8611.5
3229.73	8596.69
3232.23	8574.79
3234.74	8560.38
3237.24	8537.03
3239.75	8515.54
3242.25	8521.02
3244.75	8510.05
3247.25	8505.39
3249.75	8481.48
3252.25	8426.06
3254.75	8458.3
3257.25	8401.58
3259.74	8386.53
3262.24	8368.88
3264.73	8336.07
3267.23	8321.9
3269.72	8354.72
3272.21	8310.92
3274.7	8307.09
3277.2	8276.92
3279.69	8239.28
3282.17	8215.91
3284.66	8205.63
3287.15	8196.31
3289.64	8185.52
3292.12	8160.93
3293.56	8145.88
3296.05	8135.34
3298.55	8128.23
3301.04	8139.28
3303.54	8112.97
3306.03	8077.45
3308.52	8120.09
3311.01	8101.72
3313.5	8055.61
3315.99	8012.65
3318.48	8013.84
3320.97	8000.96
3323.45	7997.76
3325.94	8005.88
3328.42	7995.55
3330.91	8014.48
3333.39	7945.05
3335.87	7967.39
3338.36	7937.97
3340.84	7910.37
3343.32	7937.04
3345.8	7893.25
3348.27	7920.25
3350.75	7880.23
3353.23	7845.1
3355.7	7893.2
3358.18	7835.13
3360.65	7854.76
3363.13	7839.62
3365.6	7822.15
3368.07	7818.04
3370.54	7813.69
3373.01	7846.74
3375.48	7792.08
3377.95	7796.4
3380.42	7772.99
3382.88	7762.79
3385.35	7749.12
3387.81	7759.53
3390.28	7679.03
3392.74	7696.62
3395.2	7705.24
3397.67	7743.95
3400.13	7696.1
3402.58	7660.61
3405.05	7664.6
3407.5	7690.05
3409.96	7654.08
3412.42	7603.58
3414.87	7604.53
3417.33	7546.08
3419.78	7579
3422.23	7521.07
3424.69	7530.23
3427.14	7503.31
3429.59	7479.59
3432.04	7488.24
3434.49	7403.3
3436.94	7432.99
3439.39	7395.97
3441.83	7367.02
3444.28	7367.27
3446.72	7292.92
3449.17	7280.36
3451.61	7254.42
3454.05	7238.91
3456.5	7215.37
3458.94	7173.85
3461.38	7143.99
3463.81	7112.01
3466.25	7062.17
3468.69	7050.59
3471.13	7010.28
3473.56	6970.35
3476	6960.21
3478.43	6948.03
3480.87	6910.66
3483.3	6847.38
3485.73	6783.75
3488.16	6797.13
3490.59	6700.36
3493.02	6706.67
3495.45	6650.21
3497.88	6618.84
3499.09	6588.74