File: src/Milk_AI/Heritage toned basic 532nm 50% 600g 50xL 10s 10times 400-3500cm-1 200hole.txt
#Acq. time (s)=	10
#Accumulations=	10
#Range (cm-¹)=	400...3500
#Windows=	3
#Auto scanning=	Off
#Autofocus=	Off
#AutoExposure=	Off
#Spike filter=	Multiple accum.
#Delay time (s)=	0
#Binning=	1
#Readout mode=	Signal
#DeNoise=	Off
#ICS correction=	On
#Dark correction=	Off
#Inst. Process=	Off
#Detector Gain=	Best Dynamic Range
#Detector ADC=	45 kHz
#Detector temperature (°C)=	-60.1
#Instrument=	LabRAM HR Evol
#Detector=	Syncerity OE
#Objective=	x50_VIS_LWD
#Grating=	600 (500nm)
#ND Filter=	50%
#Laser=	532nm_Edge
#Hole=	199.981
#Range=	Visible
#E-Cal_Neon=	0
#StageXY=	75x50mm Scan+
#StageZ=	Z motor
#X (µm)=	0
#Y (µm)=	0
#Z (µm)=	676.8
#Spectral res.(cm-¹)=	12.8
#Full time(mm:ss)=	5:19
#AC=	Calibrated 2025-07-01 10:31
#Project=
#Sample=
#Site=
#Title=	D_1
#Remark=
#Date=	01.07.2025 16:09 (India Standard Time)
#Acquired=	01.07.2025 16:09:11 (India Standard Time)
#AxisType[0]=Intens
#AxisUnit[0]=Cnt
#AxisType[1]=Spectr
#AxisUnit[1]=1/cm
400.083	19408
403.63	19330.2
407.176	19326.4
410.72	19300.4
414.263	19281.3
417.805	19350.8
421.345	19271.2
424.884	19249
428.421	19267.8
431.955	19244.5
435.49	19252.2
439.023	19228.9
442.555	19120.9
446.084	19137
449.613	19021.9
453.141	19004
456.666	18962.5
460.191	18940.4
463.715	18854.4
467.235	18838.9
470.756	18787.2
474.274	18737
477.793	18665.8
481.308	18647.2
484.823	18609.6
488.336	18582
491.847	18522
495.358	18493.3
498.867	18503.5
502.374	18517.5
505.881	18545.6
509.386	18555.7
512.888	18505.5
516.39	18437.9
519.89	18325.2
523.391	18287.8
526.889	18250
530.385	18189.9
533.88	18210
537.373	18065.5
540.866	17997.1
544.357	17979.3
547.846	17966.2
551.334	17928.5
554.821	17917.7
558.307	17890.5
561.789	17832
565.272	17812.5
568.753	17885.2
572.233	17839.4
575.712	17845.8
579.188	17833.8
582.664	17823.5
586.139	17795.7
589.611	17798
593.083	17765.6
596.554	17888.6
600.021	17838.4
603.49	17836.6
606.955	17796.4
610.42	17606.2
613.882	17590.7
617.345	17536
620.805	17472.5
624.263	17387.7
627.722	17242.8
631.178	17299.5
634.633	17363.8
638.088	17385.1
641.539	17345.8
644.99	17215.4
648.439	17179.3
651.887	17157.6
655.335	17144.4
658.781	17133.1
662.225	17091.3
665.667	17000.2
669.108	16985.9
672.548	16935.1
675.987	16860.1
679.424	16850.1
682.86	16862.9
686.293	16889.4
689.727	16882.5
693.159	16829.6
696.59	16865.1
700.019	16904.3
703.448	16855.5
706.872	16860.7
710.298	16857.8
713.723	16813.7
717.144	16797.2
720.565	16859.5
723.984	16836.1
727.403	16741.6
730.821	16729.7
734.235	16649.2
737.651	16730
741.063	16630.4
744.474	16580.2
747.885	16661.3
751.293	16598.3
754.702	16666.5
758.108	16717.4
761.512	16651
764.915	16615.5
768.319	16639
771.719	16605.6
775.118	16595.8
778.516	16566.1
781.913	16516.7
785.308	16561
788.702	16504.8
792.095	16480.2
795.486	16396.4
798.876	16486.9
802.265	16517.7
805.653	16596.5
809.039	16553.4
812.424	16566.1
815.808	16595.2
819.191	16715
822.572	16784.7
825.95	16871.7
829.329	16910.3
832.706	16998.1
836.08	17053.2
839.455	17096
842.829	17201.7
846.199	17169.7
849.57	17211.5
852.938	17218.3
856.307	17263.2
859.672	17368.4
863.038	17342
866.401	17370.7
869.765	17292.4
873.125	17353.8
876.484	17336.6
879.844	17236.5
883.2	17182.5
886.555	17216.8
889.909	17080.7
893.262	16841.7
896.616	16674.9
899.966	16620.8
903.315	16462
906.663	16431.4
910.009	16373.9
913.354	16353.2
916.698	16337.7
920.041	16310.3
923.383	16256.2
926.723	16103
930.062	16056.9
933.399	15957.9
936.734	15901.3
940.069	15993.8
943.403	16014.1
946.736	15966
950.065	15977.2
953.396	15969.4
956.725	15960.5
960.051	15934.2
963.377	15934.1
966.7	15837.2
970.025	15873.8
973.345	15799.7
976.667	15691.1
979.985	15695
983.304	15766.8
986.62	15800.1
989.935	15873.7
993.25	15976.2
996.563	16363.1
999.874	16635.2
1003.19	16474.9
1006.49	16289.6
1009.8	16104.6
1013.11	16043.1
1016.41	16063.2
1019.72	16023.3
1023.02	16009.7
1026.32	15932.3
1029.62	15902.9
1032.92	15891.1
1036.22	15910.3
1039.51	15956.3
1042.81	15910.1
1046.1	15952.7
1049.39	16026.9
1052.68	16208.8
1055.97	16610.1
1059.26	16918.2
1062.55	16861.4
1065.83	16565.5
1069.12	16590.4
1072.4	16786.6
1075.68	16901.4
1078.97	16884.6
1082.24	16798.4
1085.52	16635.7
1088.8	16394.9
1092.08	16161.3
1095.35	15927.3
1098.62	15734.1
1101.9	15635.9
1105.17	15517.7
1108.44	15619.9
1111.7	15810.5
1114.97	15952.9
1118.23	16106.2
1121.5	16244.4
1124.76	16131.2
1128.03	15775.6
1131.29	15344.3
1134.54	15253.5
1137.8	15177.2
1141.06	15395.9
1144.31	15697
1147.57	16159.3
1150.82	16872
1154.07	17027.1
1157.32	16412.6
1160.57	15537.9
1163.82	15144.1
1167.07	14896
1170.31	14852.4
1173.56	14711.4
1176.8	14655.7
1180.04	14533.9
1183.28	14652.9
1186.52	14645.5
1189.76	14679.6
1192.99	14593.5
1196.23	14432.7
1199.46	14395.8
1202.7	14399.7
1205.93	14353.5
1209.16	14331.9
1212.39	14296.8
1215.62	14175.1
1218.84	14158
1222.07	14178.1
1225.29	14216.2
1228.52	14328.1
1231.74	14370.2
1234.96	14373.7
1238.18	14509.3
1241.4	14539.2
1244.61	14693.8
1247.83	14814.5
1251.04	14870.8
1254.25	14936.7
1257.47	15030.3
1260.68	15066
1263.89	15098.2
1267.09	15012.3
1270.3	14927.2
1273.51	14880.7
1276.71	14839.9
1279.91	14914
1283.12	14996
1286.32	15223.5
1289.52	15750.8
1292.72	16457.3
1295.91	16650.6
1299.11	16632.2
1302.3	16333.7
1305.5	15961.6
1308.69	15583.7
1311.88	15156.6
1315.07	14788.5
1318.26	14584.2
1321.44	14365.2
1324.63	14265.1
1327.82	14139.6
1331	13998.1
1334.18	14008.5
1337.36	13961.9
1340.54	13957.4
1343.72	13890.2
1346.9	13850
1350.07	13774.8
1353.25	13676.6
1356.42	13639.7
1359.6	13589.2
1362.77	13637.5
1365.94	13658.2
1369.11	13607.5
1372.28	13442.2
1375.44	13285.7
1378.61	13288.2
1381.77	13207.4
1384.93	13083
1388.1	13156.6
1391.26	13137.5
1394.41	13153.7
1397.57	13155.8
1400.73	13174.4
1403.89	13208.7
1407.04	13297.1
1410.19	13524.2
1413.35	13713.3
1416.5	13836.1
1419.65	14033.6
1422.8	14248.5
1425.94	14892.5
1429.09	15988
1432.23	17140.7
1435.38	17845.5
1438.52	17835.1
1441.66	17339.3
1444.8	16999
1447.94	16717.2
1451.08	16505.2
1454.22	16262
1457.35	15896.6
1460.48	15355.6
1463.62	14838.3
1466.75	14259.6
1469.88	13808.1
1473.01	13298
1476.14	12998.7
1479.26	12799.1
1482.39	12677.2
1485.51	12565.3
1488.64	12524.9
1491.76	12530.1
1494.88	12628.6
1498	12628.7
1501.12	12734.1
1504.24	12894.3
1507.35	13183.3
1510.47	13597.8
1513.58	14020.7
1516.69	14245.1
1519.81	14326.7
1522.92	14019
1526.03	13558.5
1529.13	12936.3
1532.24	12518.4
1535.35	12263.6
1538.45	12134.5
1541.55	12053.3
1544.66	11943.5
1547.76	11931.5
1550.86	11913.8
1553.96	11836.7
1557.05	11840.4
1560.15	11799
1563.24	11762.4
1566.34	11790.1
1569.43	11777.2
1572.52	11778.8
1575.61	11735.5
1578.7	11814.6
1581.79	11828.1
1584.88	11802.6
1587.96	11794.6
1591.05	11839.1
1594.13	11855.7
1597.21	11877.7
1600.3	11967.4
1603.37	11872.8
1606.45	11926.9
1609.53	11889.3
1612.61	11844.9
1615.68	11839.7
1618.76	11891.9
1621.83	11812.7
1624.9	11869.8
1627.97	11933.6
1631.04	12023
1634.11	12098.2
1637.18	12193.5
1640.24	12375.7
1643.31	12612.6
1646.37	13225.9
1649.44	13756.4
1652.5	13681.7
1655.56	13215.8
1658.62	12628
1661.67	12324.8
1664.73	12122.2
1667.79	11920.6
1670.84	11753.6
1673.89	11569.8
1676.95	11418.7
1680	11237.5
1683.05	11155.8
1686.1	11073.9
1689.14	10980.7
1692.19	10896.6
1695.23	10816.9
1698.28	10728
1701.32	10704.3
1704.36	10602
1707.4	10585.8
1710.44	10562.9
1713.48	10523.5
1716.52	10459.8
1719.56	10495.9
1722.59	10518
1725.63	10592.1
1728.66	10672.9
1731.69	10793.2
1734.72	10950.7
1737.75	11109.7
1740.78	11167.7
1743.8	11052.9
1746.83	10971.8
1749.86	10785.5
1752.88	10574.3
1755.9	10375.6
1758.92	10240.2
1761.94	10092.9
1764.96	10001.5
1767.98	9990.82
1771	9935.75
1774.01	9926.69
1777.03	9881.75
1780.04	9877.68
1783.05	9840.74
1786.06	9827.48
1789.07	9813.86
1792.08	9763.76
1795.09	9738.36
1798.1	9752.7
1801.1	9773.41
1804.11	9677.12
1807.11	9631.24
1810.11	9619.49
1813.11	9607.56
1816.11	9600.09
1819.11	9622.25
1822.11	9580.39
1825.11	9556.05
1828.1	9564.74
1831.1	9529.44
1834.09	9539.61
1837.08	9483.9
1840.07	9472.61
1843.06	9433.58
1846.05	9461.45
1849.04	9421.58
1852.02	9461.42
1855.01	9394.5
1857.99	9344.55
1860.98	9343.01
1863.96	9342.11
1866.94	9380.72
1869.92	9301.48
1872.9	9281.51
1875.88	9301.93
1878.85	9274.15
1881.83	9216.49
1884.8	9220.74
1887.78	9137.14
1890.75	9180.69
1893.72	9176.68
1896.69	9133.88
1899.66	9111.62
1902.63	9011.12
1905.59	8929.28
1908.56	8903.23
1911.52	8861.08
1914.49	8777.6
1917.45	8681.97
1920.41	8618.32
1923.37	8611.8
1926.33	8512.88
1929.29	8441.09
1932.24	8377.34
1935.2	8362.05
1938.15	8298.43
1941.1	8253.38
1944.06	8147.25
1947.01	8092.97
1949.96	8049.09
1952.91	8005.38
1955.86	7861.46
1958.8	7830.42
1961.75	7768.29
1964.69	7764.04
1967.64	7696.61
1970.58	7651.15
1973.52	7622.83
1976.46	7561.95
1979.4	7523.91
1982.34	7462.99
1985.27	7438.31
1988.21	7370.6
1991.14	7313.31
1994.08	7280.22
1997.01	7214.11
1999.94	7169.74
2002.87	7108.94
2005.8	7097.76
2008.73	7065.11
2011.66	7035.54
2014.58	6964.27
2017.51	6932.35
2020.43	6885.84
2023.36	6856.75
2026.28	6831.3
2029.2	6779.12
2032.12	6755.49
2035.04	6689.54
2037.95	6682.2
2040.87	6642.3
2043.78	6624.01
2045.76	6601.09
2048.69	6584.13
2051.61	6568.44
2054.54	6580.17
2057.46	6551.76
2060.38	6551.43
2063.3	6533.71
2066.22	6510.95
2069.14	6543
2072.06	6541.17
2074.98	6475.88
2077.89	6497.68
2080.81	6512.68
2083.72	6503.2
2086.63	6479.13
2089.55	6470.3
2092.46	6459.42
2095.37	6435.4
2098.28	6447.82
2101.18	6471.62
2104.09	6441.47
2106.99	6406.39
2109.9	6440.24
2112.8	6402.59
2115.71	6424.32
2118.61	6351.69
2121.51	6405.73
2124.4	6373.02
2127.3	6374.35
2130.2	6331.64
2133.09	6352.53
2135.99	6361
2138.88	6360.03
2141.78	6341.64
2144.67	6367.87
2147.56	6350.73
2150.45	6322.29
2153.34	6330.98
2156.22	6339.36
2159.11	6319.04
2162	6294.67
2164.88	6308.21
2167.76	6311.71
2170.64	6278.88
2173.53	6288.47
2176.41	6274.29
2179.29	6255.74
2182.16	6275.14
2185.04	6246.76
2187.92	6238.6
2190.79	6268.48
2193.66	6206.54
2196.54	6218.49
2199.41	6211.71
2202.28	6191.07
2205.15	6220.08
2208.02	6234.92
2210.88	6170.17
2213.75	6163.47
2216.62	6144.45
2219.48	6112.67
2222.34	6113.63
2225.21	6107.62
2228.07	6106.62
2230.93	6090.54
2233.79	6112.36
2236.65	6076.2
2239.5	6089.46
2242.36	6059.6
2245.21	6087.02
2248.07	6049.16
2250.92	6031.58
2253.77	6029.92
2256.62	6019.35
2259.47	5988.4
2262.32	5951.5
2265.17	5978.89
2268.02	5936.81
2270.86	5907.71
2273.71	5944.82
2276.55	5893.17
2279.39	5906.09
2282.24	5899.85
2285.08	5864.05
2287.92	5850.37
2290.75	5871.13
2293.59	5864.5
2296.43	5852.31
2299.26	5836.08
2302.1	5843.02
2304.93	5838.17
2307.76	5806.02
2310.6	5789.33
2313.43	5776.28
2316.25	5755.76
2319.08	5760.42
2321.91	5795.35
2324.74	5886.82
2327.56	6046.66
2330.39	5772.01
2333.21	5725.96
2336.03	5701.59
2338.85	5678.25
2341.67	5729.1
2344.49	5694.71
2347.31	5676.47
2350.13	5668.33
2352.94	5644.75
2355.76	5630.75
2358.57	5623.5
2361.39	5605.44
2364.2	5614.81
2367.01	5600.83
2369.82	5600.18
2372.63	5568.59
2375.44	5571.58
2378.24	5573.93
2381.05	5571.86
2383.85	5559.34
2386.66	5543.14
2389.46	5580.17
2392.26	5546.95
2395.06	5524.93
2397.86	5501.65
2400.66	5545.1
2403.46	5515.6
2406.26	5515.24
2409.05	5501.44
2411.85	5472.22
2414.64	5514.67
2417.43	5500.15
2420.23	5508.26
2423.02	5460.24
2425.81	5476.49
2428.6	5488.68
2431.38	5485.29
2434.17	5432.85
2436.96	5410.43
2439.74	5434.77
2442.53	5417.87
2445.31	5431.79
2448.09	5403.41
2450.87	5443.71
2453.65	5391.17
2456.43	5398.82
2459.21	5409.08
2461.98	5376.95
2464.76	5397.53
2467.53	5367.55
2470.31	5364.92
2473.08	5355.48
2475.85	5335.96
2478.63	5354.95
2481.39	5346.59
2484.16	5358.07
2486.93	5333.82
2489.7	5322.21
2492.46	5358.69
2495.23	5340.53
2497.99	5338.99
2500.76	5299.95
2503.52	5309.45
2506.28	5291.38
2509.04	5301.14
2511.8	5251.53
2514.56	5270.89
2517.31	5276.25
2520.07	5265.47
2522.82	5263.55
2525.58	5276.09
2528.33	5293.46
2531.09	5220.25
2533.84	5273.76
2536.59	5242.63
2539.34	5230.13
2542.08	5227.57
2544.83	5206.05
2547.58	5190.41
2550.32	5198.07
2553.07	5177.62
2555.81	5190.71
2558.55	5238.03
2561.29	5187.82
2564.03	5161.58
2566.77	5152.24
2569.51	5176.72
2572.25	5144.83
2574.99	5179.4
2577.72	5156.2
2580.46	5160.92
2583.19	5148.99
2585.92	5162.35
2588.65	5175.27
2591.38	5169.37
2594.11	5158.21
2596.84	5169.38
2599.57	5160.11
2602.3	5139.25
2605.02	5140.11
2607.75	5157.98
2610.47	5154.27
2613.19	5136.91
2615.92	5103.68
2618.64	5110.92
2621.36	5089.23
2624.08	5078.12
2626.8	5149.71
2629.51	5123.82
2632.23	5087.33
2634.94	5098
2637.66	5117.19
2640.37	5107.79
2643.08	5116.6
2645.79	5119.29
2648.5	5096.82
2651.21	5083.12
2653.92	5105.59
2656.63	5054.75
2659.33	5100.94
2662.04	5078.08
2664.75	5088.02
2667.45	5094.58
2670.15	5064.65
2672.85	5101.67
2675.55	5074
2678.25	5074.9
2680.95	5084.73
2683.65	5062.79
2686.35	5084.23
2689.04	5083.27
2691.74	5107.47
2694.43	5077.29
2697.13	5043.26
2699.82	5063.24
2702.51	5053.11
2705.2	5087.32
2707.89	5069.64
2710.58	5101.68
2713.26	5088.87
2715.95	5119.89
2718.64	5101.98
2721.32	5097.4
2724	5095.51
2726.69	5061.5
2729.37	5109.89
2732.05	5068.67
2734.73	5026.5
2737.41	5000
2740.09	4988.24
2742.76	4934.1
2745.44	4915.66
2748.11	4946.02
2750.79	4882.67
2753.46	4899.33
2756.13	4863.55
2758.81	4908.2
2761.47	4849.75
2764.14	4829.13
2766.81	4882.61
2769.48	4840.02
2772.15	4831.21
2774.81	4817.82
2777.48	4775.79
2780.14	4786.23
2782.8	4764.06
2785.47	4814.33
2788.13	4752.92
2790.79	4792.98
2793.44	4780.59
2796.1	4827.1
2798.76	4798.84
2801.42	4797.53
2804.07	4797.46
2806.73	4777.5
2809.38	4771.32
2812.03	4794.39
2814.68	4835
2817.33	4843.62
2819.98	4858.5
2822.63	4910.15
2825.28	4905.01
2827.93	4961.93
2830.57	5085.25
2833.22	5202.9
2835.86	5403.35
2838.51	5703.17
2841.15	6143.66
2843.79	6733.36
2846.43	7203.13
2849.07	7369.72
2851.71	7324.75
2854.35	7196.1
2856.98	7032.41
2859.62	6964.27
2862.25	6854.92
2864.89	6884.93
2867.52	6974.9
2870.15	7062.49
2872.78	7219.39
2875.41	7305.44
2878.04	7463.8
2880.67	7518.49
2883.3	7542.21
2885.92	7550.46
2888.55	7610.59
2891.18	7645.08
2893.8	7595.77
2896.42	7603.35
2899.04	7647.62
2901.67	7567
2904.29	7553.68
2906.9	7593.58
2909.52	7552.79
2912.14	7530.38
2914.76	7561.85
2917.37	7481.66
2919.99	7536.04
2922.6	7555.1
2925.21	7526.7
2927.82	7576.79
2930.44	7587.65
2933.05	7511.51
2935.65	7441.29
2938.26	7226.17
2940.87	7038.61
2943.48	6766.65
2946.08	6564.22
2948.69	6376.35
2951.29	6299.02
2953.89	6218.49
2956.49	6130.35
2959.1	6061.07
2961.7	5957.81
2964.29	5873.03
2966.89	5751.42
2969.49	5631.55
2972.09	5587.97
2974.68	5474.2
2977.28	5405.07
2979.87	5354.46
2982.46	5306.98
2985.05	5219.25
2987.65	5144.58
2990.24	5147.25
2992.82	5094.69
2995.41	5068.18
2998	5062.07
3000.59	5061.17
3003.17	5042.91
3005.76	4992.29
3008.34	4960.4
3010.92	4913.72
3013.5	4884.33
3016.09	4853.3
3018.67	4871.22
3021.25	4839.13
3023.82	4843.26
3026.4	4876.29
3028.98	4820.88
3031.55	4838.21
3034.13	4836.43
3036.7	4892.33
3039.28	4894.93
3041.85	4886.96
3044.42	4898.6
3046.99	4925.7
3049.56	4976.39
3052.13	5009.46
3054.69	5044.32
3057.26	5064.51
3059.83	5105.57
3062.39	5148.34
3064.95	5136.23
3067.52	5182.99
3070.08	5161.12
3072.64	5227.65
3075.2	5213.2
3077.76	5269.12
3080.32	5266.84
3082.88	5345.09
3085.44	5348.81
3087.99	5388.37
3090.55	5441.68
3093.1	5475.3
3095.65	5558.56
3098.21	5555.25
3100.76	5627.19
3103.31	5674.88
3105.86	5727.22
3108.41	5786.02
3110.96	5867.81
3113.5	5928.57
3116.05	5986.81
3118.59	6025.09
3121.14	6108.44
3123.68	6163.48
3126.23	6251.66
3128.77	6290.91
3131.31	6410.21
3133.85	6442.25
3136.39	6534.14
3138.93	6571.78
3141.46	6647.97
3144	6713.58
3146.54	6810.73
3149.07	6889.85
3151.6	6948.44
3154.14	7015.46
3156.67	7084.08
3159.2	7178.33
3161.73	7237.64
3164.26	7281.48
3166.79	7307.16
3169.32	7364.41
3171.84	7398.35
3174.37	7407.14
3176.9	7451.04
3179.42	7467.28
3181.94	7474.18
3184.47	7503.86
3186.99	7534.52
3189.51	7507.81
3192.03	7564.16
3194.55	7556.43
3197.07	7541.54
3199.58	7572.77
3202.1	7545.95
3204.62	7617.26
3207.13	7573.81
3209.65	7570.72
3212.16	7534.91
3214.67	7526.37
3217.18	7508.26
3219.69	7508.34
3222.2	7510.89
3224.71	7506.27
3227.22	7477.24
3229.73	7477.6
3232.23	7435.51
3234.74	7437.85
3237.24	7391.27
3239.75	7335.34
3242.25	7336.51
3244.75	7323.84
3247.25	7306.29
3249.75	7288.8
3252.25	7223.03
3254.75	7215.87
3257.25	7158.57
3259.74	7115.14
3262.24	7125.42
3264.73	7105.21
3267.23	7046.23
3269.72	7059.7
3272.21	7056.78
3274.7	7027.12
3277.2	6994.6
3279.69	6945.22
3282.17	6936.55
3284.66	6939.23
3287.15	6922.06
3289.64	6863.79
3292.12	6857.81
3293.56	6849.61
3296.05	6856.59
3298.55	6861.57
3301.04	6837.98
3303.54	6780.92
3306.03	6809.49
3308.52	6786.09
3311.01	6774.99
3313.5	6767.9
3315.99	6758.85
3318.48	6758.09
3320.97	6743.84
3323.45	6765.48
3325.94	6712.77
3328.42	6741.35
3330.91	6732.85
3333.39	6740.94
3335.87	6722.3
3338.36	6695.59
3340.84	6683.44
3343.32	6683.41
3345.8	6684.04
3348.27	6677.82
3350.75	6671.8
3353.23	6686.61
3355.7	6676.09
3358.18	6680.07
3360.65	6662.41
3363.13	6632.03
3365.6	6612.34
3368.07	6620.96
3370.54	6623.73
3373.01	6662.08
3375.48	6614.95
3377.95	6637.77
3380.42	6615.85
3382.88	6593.89
3385.35	6610.75
3387.81	6550.21
3390.28	6564.26
3392.74	6570.55
3395.2	6567.78
3397.67	6559.1
3400.13	6524.59
3402.58	6523.25
3405.05	6532.59
3407.5	6503.76
3409.96	6483.75
3412.42	6448.86
3414.87	6438.34
3417.33	6437.66
3419.78	6404.98
3422.23	6357.97
3424.69	6351.1
3427.14	6361.63
3429.59	6318.46
3432.04	6280.5
3434.49	6270.88
3436.94	6219.02
3439.39	6189.11
3441.83	6154.74
3444.28	6150.98
3446.72	6078.09
3449.17	6009.81
3451.61	5981.75
3454.05	5973.86
3456.5	5952.38
3458.94	5897.92
3461.38	5853.05
3463.81	5838.74
3466.25	5746.19
3468.69	5714.74
3471.13	5674.81
3473.56	5630.29
3476	5566.79
3478.43	5502.34
3480.87	5456.61
3483.3	5425.09
3485.73	5357.48
3488.16	5324.03
3490.59	5284.92
3493.02	5229.35
3495.45	5155.71
3497.88	5108.03
3499.09	5087.88