File: src/Milk_AI/Heritage special RT after 24 h 532nm 50% 600g 50xL 10s 10times 400-3500cm-1 200hole.txt
#Acq. time (s)=	10
#Accumulations=	10
#Range (cm-¹)=	400...3500
#Windows=	3
#Auto scanning=	Off
#Autofocus=	Off
#AutoExposure=	Off
#Spike filter=	Multiple accum.
#Delay time (s)=	0
#Binning=	1
#Readout mode=	Signal
#DeNoise=	Off
#ICS correction=	On
#Dark correction=	Off
#Inst. Process=	Off
#Detector Gain=	Best Dynamic Range
#Detector ADC=	45 kHz
#Detector temperature (°C)=	-60.1
#Instrument=	LabRAM HR Evol
#Detector=	Syncerity OE
#Objective=	x50_VIS_LWD
#Grating=	600 (500nm)
#ND Filter=	50%
#Laser=	532nm_Edge
#Hole=	199.981
#Range=	Visible
#E-Cal_Neon=	0
#StageXY=	75x50mm Scan+
#StageZ=	Z motor
#X (µm)=	0
#Y (µm)=	0
#Z (µm)=	705.1
#Spectral res.(cm-¹)=	12.8
#Full time(mm:ss)=	5:19
#AC=	Calibrated 2025-07-01 10:31
#Project=
#Sample=
#Site=
#Title=	D_1
#Remark=
#Date=	01.07.2025 17:20 (India Standard Time)
#Acquired=	01.07.2025 17:20:10 (India Standard Time)
#AxisType[0]=Intens
#AxisUnit[0]=Cnt
#AxisType[1]=Spectr
#AxisUnit[1]=1/cm
400.083	35208.4
403.63	34928.8
407.176	35057.4
410.72	35158.7
414.263	35164.9
417.805	35234.2
421.345	35094.7
424.884	35165.7
428.421	35226.5
431.955	35177.2
435.49	35186.3
439.023	35170.8
442.555	35114.1
446.084	35214.1
449.613	35155.6
453.141	35054.1
456.666	35129.4
460.191	35011.6
463.715	35095.3
467.235	35104
470.756	35172
474.274	35139.4
477.793	35069.4
481.308	35136.8
484.823	35062.4
488.336	35176.2
491.847	35218.9
495.358	35110
498.867	35290.2
502.374	35450.5
505.881	35431.1
509.386	35436.1
512.888	35461.4
516.39	35406.9
519.89	35383.5
523.391	35308.9
526.889	35293.4
530.385	35340.2
533.88	35226.6
537.373	35198
540.866	35135.2
544.357	35179.2
547.846	35165.7
551.334	35175.9
554.821	35202.8
558.307	35227.7
561.789	35187.7
565.272	35318.6
568.753	35267.4
572.233	35245.9
575.712	35350.9
579.188	35359.7
582.664	35368.4
586.139	35458
589.611	35390.5
593.083	35320.6
596.554	35512.8
600.021	35407.3
603.49	35484.3
606.955	35380.5
610.42	35351.5
613.882	35327.1
617.345	35421.9
620.805	35281
624.263	35170.6
627.722	35251.4
631.178	35033.9
634.633	35289.4
638.088	35226
641.539	35363.6
644.99	35265.4
648.439	35053.4
651.887	35097.6
655.335	35189.4
658.781	35161.4
662.225	35035.5
665.667	35122.3
669.108	35221.3
672.548	35093.4
675.987	35064.2
679.424	35143.3
682.86	35172.5
686.293	35227
689.727	35177.8
693.159	35181.2
696.59	35252.9
700.019	35294.2
703.448	35310.7
706.872	35128.9
710.298	35160.6
713.723	35189.1
717.144	35186.1
720.565	35250.7
723.984	35215.9
727.403	35252.7
730.821	35193.2
734.235	35214.9
737.651	35245
741.063	35113
744.474	35124.2
747.885	35317.6
751.293	35373.1
754.702	35329.1
758.108	35396.5
761.512	35340.1
764.915	35443.3
768.319	35458.6
771.719	35444.8
775.118	35465.4
778.516	35440.3
781.913	35367
785.308	35466.4
788.702	35375.5
792.095	35374.2
795.486	35408.7
798.876	35452.1
802.265	35484.4
805.653	35539.6
809.039	35490.6
812.424	35463.9
815.808	35557.6
819.191	35665.2
822.572	35860.7
825.95	35915.4
829.329	35921.6
832.706	35916.4
836.08	36049.5
839.455	36009.5
842.829	36345.7
846.199	36332.2
849.57	36263.8
852.938	36388.2
856.307	36382.9
859.672	36486.7
863.038	36508
866.401	36518.3
869.765	36425.7
873.125	36436.9
876.484	36611.8
879.844	36351
883.2	36240.7
886.555	36221.7
889.909	36258.8
893.262	35995.5
896.616	35929.9
899.966	35731.3
903.315	35690.6
906.663	35588.1
910.009	35556
913.354	35524.5
916.698	35452.7
920.041	35446.9
923.383	35425.9
926.723	35246.5
930.062	35244.5
933.399	35261.3
936.734	35200.9
940.069	35222.5
943.403	35238
946.736	35202.5
950.065	35112.8
953.396	35128.6
956.725	35163.9
960.051	35243.8
963.377	35300.2
966.7	35235.1
970.025	35203.5
973.345	35149.2
976.667	35074.9
979.985	35121.5
983.304	35132.3
986.62	35152.9
989.935	35187
993.25	35280.6
996.563	35539.3
999.874	35919.6
1003.19	35771.5
1006.49	35495.1
1009.8	35438.2
1013.11	35318.8
1016.41	35441.8
1019.72	35306.3
1023.02	35301.7
1026.32	35187.4
1029.62	35267.2
1032.92	35265.7
1036.22	35232.5
1039.51	35216.2
1042.81	35197.9
1046.1	35134.9
1049.39	35332.9
1052.68	35360.7
1055.97	35689.9
1059.26	35835.8
1062.55	35975
1065.83	35729.9
1069.12	35828.5
1072.4	36122.7
1075.68	36116.3
1078.97	36083.4
1082.24	36045
1085.52	35840.5
1088.8	35598
1092.08	35309.3
1095.35	35014.8
1098.62	34756.7
1101.9	34783.7
1105.17	34603.8
1108.44	34761.5
1111.7	34872.4
1114.97	35004.3
1118.23	35099.6
1121.5	34994.5
1124.76	34831.7
1128.03	34422.7
1131.29	34247
1134.54	34233.8
1137.8	34156.5
1141.06	34175
1144.31	34473.8
1147.57	34727.3
1150.82	35102.8
1154.07	35287.7
1157.32	34805.1
1160.57	34275
1163.82	33931.4
1167.07	33864.5
1170.31	33762.5
1173.56	33645.4
1176.8	33648.6
1180.04	33496.9
1183.28	33595.8
1186.52	33552
1189.76	33663.2
1192.99	33503.3
1196.23	33429.7
1199.46	33376.9
1202.7	33381.4
1205.93	33358.4
1209.16	33388.5
1212.39	33297.7
1215.62	33141.9
1218.84	33152.4
1222.07	33270.6
1225.29	33304.9
1228.52	33362.2
1231.74	33377.4
1234.96	33410
1238.18	33428.6
1241.4	33550.6
1244.61	33698.9
1247.83	33846.9
1251.04	33825.2
1254.25	34011
1257.47	33966
1260.68	33983.1
1263.89	34033.3
1267.09	34000.5
1270.3	33783.8
1273.51	33826.7
1276.71	33667.2
1279.91	33699.4
1283.12	33899.1
1286.32	33887.2
1289.52	34291.5
1292.72	34743.1
1295.91	35219.6
1299.11	35335.1
1302.3	35257
1305.5	34849.2
1308.69	34397.7
1311.88	34007.9
1315.07	33568.4
1318.26	33330
1321.44	33128.5
1324.63	33002.8
1327.82	32844.3
1331	32801.4
1334.18	32688.2
1337.36	32702.8
1340.54	32713
1343.72	32599.7
1346.9	32527.3
1350.07	32421.4
1353.25	32387.1
1356.42	32219.4
1359.6	32127.7
1362.77	32200.6
1365.94	32144.2
1369.11	32062.2
1372.28	31998.4
1375.44	31659
1378.61	31617.7
1381.77	31557.2
1384.93	31501.8
1388.1	31552.9
1391.26	31599.4
1394.41	31544.8
1397.57	31571.4
1400.73	31567.4
1403.89	31561.4
1407.04	31618.6
1410.19	31711
1413.35	31962.3
1416.5	32145.3
1419.65	32296.3
1422.8	32527.8
1425.94	33174.2
1429.09	34223.2
1432.23	35497.4
1435.38	36005.3
1438.52	35941.9
1441.66	35588.5
1444.8	35259.4
1447.94	35003
1451.08	34642.5
1454.22	34334.6
1457.35	33896.3
1460.48	33459
1463.62	32891.8
1466.75	32245.8
1469.88	31839.5
1473.01	31268.1
1476.14	30951.8
1479.26	30692.6
1482.39	30568.1
1485.51	30533.1
1488.64	30444.1
1491.76	30452
1494.88	30551.6
1498	30488.8
1501.12	30498
1504.24	30520.2
1507.35	30710.2
1510.47	30960.3
1513.58	31168.5
1516.69	31374.7
1519.81	31302.7
1522.92	31112
1526.03	30808.6
1529.13	30433.7
1532.24	30139.5
1535.35	29929.2
1538.45	29832.3
1541.55	29824.2
1544.66	29680.7
1547.76	29660.9
1550.86	29629.2
1553.96	29493
1557.05	29401.3
1560.15	29617.9
1563.24	29463.2
1566.34	29447.6
1569.43	29534.5
1572.52	29497.8
1575.61	29401.8
1578.7	29506.5
1581.79	29440.2
1584.88	29333.2
1587.96	29321.8
1591.05	29366.8
1594.13	29326.2
1597.21	29425
1600.3	29499.4
1603.37	29439.6
1606.45	29330.3
1609.53	29439.9
1612.61	29237.8
1615.68	29170.3
1618.76	29139.5
1621.83	29151.4
1624.9	29178.2
1627.97	29185.3
1631.04	29277.9
1634.11	29392.7
1637.18	29378.8
1640.24	29635.7
1643.31	29843
1646.37	30479.3
1649.44	30933
1652.5	30939.5
1655.56	30454.2
1658.62	29980.8
1661.67	29453.7
1664.73	29437.1
1667.79	29150.9
1670.84	28972.3
1673.89	28895.2
1676.95	28671.6
1680	28455.4
1683.05	28353.7
1686.1	28158.5
1689.14	28069.4
1692.19	27981.5
1695.23	27894.5
1698.28	27802
1701.32	27654.7
1704.36	27652.8
1707.4	27581.9
1710.44	27408.6
1713.48	27451
1716.52	27403.6
1719.56	27350.2
1722.59	27424.1
1725.63	27476.6
1728.66	27497.4
1731.69	27631.7
1734.72	27720.8
1737.75	27859.6
1740.78	27844.8
1743.8	27889.4
1746.83	27864
1749.86	27725.1
1752.88	27474
1755.9	27127.9
1758.92	27035.6
1761.94	26853.6
1764.96	26797.7
1767.98	26746.2
1771	26662.3
1774.01	26668.9
1777.03	26591.7
1780.04	26582.4
1783.05	26469.8
1786.06	26529
1789.07	26520.1
1792.08	26437.9
1795.09	26506.6
1798.1	26473.3
1801.1	26223
1804.11	26299.3
1807.11	26127.8
1810.11	26204.3
1813.11	26155.2
1816.11	26111.5
1819.11	26106.5
1822.11	26033.1
1825.11	26021.6
1828.1	26035.9
1831.1	25985.1
1834.09	25984.5
1837.08	25912.3
1840.07	25904.5
1843.06	25904.7
1846.05	25874
1849.04	25803.7
1852.02	25667.6
1855.01	25641.3
1857.99	25697.6
1860.98	25606.1
1863.96	25666.1
1866.94	25668.1
1869.92	25628.1
1872.9	25557.7
1875.88	25531.6
1878.85	25448.5
1881.83	25426.7
1884.8	25362.9
1887.78	25301.8
1890.75	25324.6
1893.72	25327.5
1896.69	25150.7
1899.66	25013.2
1902.63	24982.6
1905.59	24803.6
1908.56	24652.2
1911.52	24626.6
1914.49	24506.1
1917.45	24315.4
1920.41	24228.7
1923.37	24076.6
1926.33	24037.9
1929.29	23902.9
1932.24	23758.3
1935.2	23681.1
1938.15	23533.9
1941.1	23393
1944.06	23324.8
1947.01	23226.3
1949.96	23058.5
1952.91	22911.1
1955.86	22801
1958.8	22661.6
1961.75	22623.3
1964.69	22505.2
1967.64	22354
1970.58	22281.1
1973.52	22202.5
1976.46	22050
1979.4	21954.8
1982.34	21894.2
1985.27	21767.9
1988.21	21676.3
1991.14	21515.4
1994.08	21458.4
1997.01	21311.6
1999.94	21191.8
2002.87	21083.5
2005.8	21003.2
2008.73	20961.8
2011.66	20892.1
2014.58	20777.2
2017.51	20685.4
2020.43	20542.9
2023.36	20472
2026.28	20361.6
2029.2	20310.4
2032.12	20215.9
2035.04	20140.9
2037.95	20024.6
2040.87	19988.1
2043.78	19891.4
2045.76	19839.9
2048.69	19817.2
2051.61	19758.9
2054.54	19751.8
2057.46	19752.6
2060.38	19689.9
2063.3	19651.7
2066.22	19662.2
2069.14	19647.2
2072.06	19580
2074.98	19520.9
2077.89	19484.1
2080.81	19451.7
2083.72	19454.8
2086.63	19394.4
2089.55	19385.3
2092.46	19362.2
2095.37	19364.4
2098.28	19263
2101.18	19185.2
2104.09	19185.2
2106.99	19152.1
2109.9	19135.5
2112.8	19068.8
2115.71	19066.3
2118.61	19059.3
2121.51	18962.6
2124.4	18998.6
2127.3	18952.8
2130.2	18878.9
2133.09	18880.3
2135.99	18886.2
2138.88	18873.2
2141.78	18857.6
2144.67	18865.3
2147.56	18801.5
2150.45	18773.4
2153.34	18780.5
2156.22	18754.3
2159.11	18756.5
2162	18705.8
2164.88	18713.3
2167.76	18649.5
2170.64	18645.1
2173.53	18624.1
2176.41	18574.3
2179.29	18575.6
2182.16	18558.4
2185.04	18489.2
2187.92	18423.4
2190.79	18400.4
2193.66	18410.4
2196.54	18368.8
2199.41	18312.9
2202.28	18340.2
2205.15	18312.8
2208.02	18231.2
2210.88	18195.3
2213.75	18115.7
2216.62	18075.8
2219.48	18075
2222.34	18019
2225.21	17942.9
2228.07	17909.1
2230.93	17878.2
2233.79	17968.5
2236.65	17911.5
2239.5	17832.9
2242.36	17713.6
2245.21	17734.1
2248.07	17666.1
2250.92	17651.9
2253.77	17648.9
2256.62	17525.9
2259.47	17441.6
2262.32	17417.5
2265.17	17356.5
2268.02	17291.3
2270.86	17267.9
2273.71	17196.7
2276.55	17169.2
2279.39	17176.2
2282.24	17086.2
2285.08	17011.5
2287.92	17021.7
2290.75	17037.6
2293.59	16984.6
2296.43	16942.3
2299.26	16928.8
2302.1	16842
2304.93	16790.7
2307.76	16746.2
2310.6	16722.1
2313.43	16737.6
2316.25	16585.9
2319.08	16606.2
2321.91	16567.6
2324.74	16732.9
2327.56	16805
2330.39	16497.6
2333.21	16382.1
2336.03	16374.4
2338.85	16332.2
2341.67	16294.8
2344.49	16286.9
2347.31	16214.6
2350.13	16124.7
2352.94	16078.7
2355.76	16084.9
2358.57	15972.1
2361.39	15982.8
2364.2	15974.2
2367.01	15938
2369.82	15941.9
2372.63	15853
2375.44	15821.9
2378.24	15779.3
2381.05	15787
2383.85	15793
2386.66	15665.9
2389.46	15717
2392.26	15670.9
2395.06	15610.7
2397.86	15598.3
2400.66	15544.2
2403.46	15533.4
2406.26	15522.3
2409.05	15495.4
2411.85	15447.1
2414.64	15367.8
2417.43	15398.7
2420.23	15312.2
2423.02	15311.9
2425.81	15347.7
2428.6	15237.6
2431.38	15252.1
2434.17	15234.5
2436.96	15130.9
2439.74	15119.6
2442.53	15074
2445.31	15090.3
2448.09	15061.6
2450.87	14997.6
2453.65	14951
2456.43	14921.7
2459.21	14919.8
2461.98	14877.1
2464.76	14845.2
2467.53	14819.8
2470.31	14815.2
2473.08	14776
2475.85	14732
2478.63	14710
2481.39	14718.6
2484.16	14679.4
2486.93	14649.4
2489.7	14611.4
2492.46	14611.9
2495.23	14550.6
2497.99	14521.6
2500.76	14461.6
2503.52	14456.7
2506.28	14390.8
2509.04	14370.6
2511.8	14316
2514.56	14301.1
2517.31	14288.5
2520.07	14288
2522.82	14263.8
2525.58	14233.7
2528.33	14219.9
2531.09	14204.5
2533.84	14169.6
2536.59	14095.7
2539.34	14118.7
2542.08	14107.6
2544.83	14017.2
2547.58	13963.5
2550.32	13953.8
2553.07	13982.9
2555.81	13903.7
2558.55	13894.4
2561.29	13880.9
2564.03	13876.3
2566.77	13840
2569.51	13796
2572.25	13798.4
2574.99	13768.5
2577.72	13762.2
2580.46	13707.5
2583.19	13732.9
2585.92	13682.7
2588.65	13682.2
2591.38	13641.3
2594.11	13648.1
2596.84	13633.6
2599.57	13558.2
2602.3	13503.8
2605.02	13582.8
2607.75	13595
2610.47	13497.1
2613.19	13517
2615.92	13392.7
2618.64	13463
2621.36	13449.5
2624.08	13332.8
2626.8	13371.1
2629.51	13290.5
2632.23	13328.8
2634.94	13298.2
2637.66	13254.1
2640.37	13283.1
2643.08	13277.2
2645.79	13194.3
2648.5	13198.1
2651.21	13174.2
2653.92	13183.4
2656.63	13089.7
2659.33	13118.9
2662.04	13129.7
2664.75	13098.1
2667.45	13046.2
2670.15	13060
2672.85	13107.6
2675.55	13038.5
2678.25	12987.5
2680.95	12917.3
2683.65	12891.1
2686.35	12903.2
2689.04	12906.8
2691.74	12880.7
2694.43	12833.2
2697.13	12823.1
2699.82	12789.8
2702.51	12814.8
2705.2	12844.9
2707.89	12832.2
2710.58	12826.1
2713.26	12762.7
2715.95	12791.8
2718.64	12767.2
2721.32	12716.5
2724	12666.2
2726.69	12700.5
2729.37	12687.7
2732.05	12604.3
2734.73	12577.5
2737.41	12501
2740.09	12448.9
2742.76	12444.2
2745.44	12422.6
2748.11	12374.7
2750.79	12352.3
2753.46	12292.9
2756.13	12280.9
2758.81	12360.4
2761.47	12251.2
2764.14	12201.2
2766.81	12162.8
2769.48	12174.7
2772.15	12114.1
2774.81	12093
2777.48	12096.9
2780.14	12013.5
2782.8	12000
2785.47	11966.9
2788.13	11907.3
2790.79	11933.3
2793.44	11975.9
2796.1	11957.9
2798.76	11935.1
2801.42	11901.8
2804.07	11860.6
2806.73	11839
2809.38	11846.9
2812.03	11797.4
2814.68	11834.6
2817.33	11852.3
2819.98	11799.7
2822.63	11864.5
2825.28	11853.2
2827.93	11876.5
2830.57	11936.9
2833.22	12027.6
2835.86	12169.3
2838.51	12431
2841.15	12915.2
2843.79	13506.3
2846.43	13936.8
2849.07	14187.3
2851.71	14081.4
2854.35	13987.3
2856.98	13821.6
2859.62	13743.7
2862.25	13556.7
2864.89	13546.5
2867.52	13617.5
2870.15	13729.9
2872.78	13778.3
2875.41	13815.8
2878.04	13896.2
2880.67	13915.7
2883.3	13999.1
2885.92	14058.6
2888.55	14103.8
2891.18	14167.5
2893.8	14116.6
2896.42	14100.8
2899.04	14067.8
2901.67	14042.3
2904.29	13955.1
2906.9	13956.3
2909.52	13953.7
2912.14	13895.5
2914.76	13912.5
2917.37	13893.9
2919.99	13919.4
2922.6	13852.4
2925.21	13879.5
2927.82	13829
2930.44	13807
2933.05	13790.1
2935.65	13610.6
2938.26	13409.7
2940.87	13108.9
2943.48	12832.6
2946.08	12590
2948.69	12427
2951.29	12355.4
2953.89	12235.1
2956.49	12206.3
2959.1	12107.8
2961.7	12008.9
2964.29	11879.2
2966.89	11793.3
2969.49	11714.5
2972.09	11576.9
2974.68	11427.1
2977.28	11390.8
2979.87	11340.4
2982.46	11297.5
2985.05	11177.7
2987.65	11102.1
2990.24	11039.3
2992.82	11037.6
2995.41	11011.9
2998	10909.3
3000.59	10901.6
3003.17	10891.5
3005.76	10847.6
3008.34	10818.7
3010.92	10766.1
3013.5	10751.5
3016.09	10708.1
3018.67	10584.5
3021.25	10651.8
3023.82	10618.3
3026.4	10536.6
3028.98	10490.5
3031.55	10548.9
3034.13	10512.8
3036.7	10521.5
3039.28	10523.8
3041.85	10527.8
3044.42	10567.6
3046.99	10535.9
3049.56	10549
3052.13	10523.2
3054.69	10600.3
3057.26	10604.9
3059.83	10526.1
3062.39	10577.5
3064.95	10640.6
3067.52	10580
3070.08	10596.7
3072.64	10582
3075.2	10621
3077.76	10596.5
3080.32	10614.2
3082.88	10587.2
3085.44	10641.1
3087.99	10646.4
3090.55	10665.7
3093.1	10648.5
3095.65	10675.5
3098.21	10730
3100.76	10705.9
3103.31	10720.7
3105.86	10780.6
3108.41	10836.5
3110.96	10875.6
3113.5	10850.8
3116.05	10883.2
3118.59	10927.9
3121.14	10956.9
3123.68	10989.5
3126.23	11064.6
3128.77	11084.5
3131.31	11148.9
3133.85	11157.3
3136.39	11200.7
3138.93	11249.8
3141.46	11219.8
3144	11297.6
3146.54	11365.7
3149.07	11421.6
3151.6	11432
3154.14	11454.4
3156.67	11477.7
3159.2	11520.2
3161.73	11517.9
3164.26	11552.7
3166.79	11602.9
3169.32	11622.4
3171.84	11571.8
3174.37	11564.9
3176.9	11565.1
3179.42	11566.6
3181.94	11548.9
3184.47	11548.9
3186.99	11521.6
3189.51	11539.2
3192.03	11507.6
3194.55	11453.5
3197.07	11503.6
3199.58	11459.8
3202.1	11458.7
3204.62	11479.6
3207.13	11452.6
3209.65	11401.4
3212.16	11342.8
3214.67	11329.7
3217.18	11290
3219.69	11271.9
3222.2	11307.6
3224.71	11269.8
3227.22	11230.1
3229.73	11209.1
3232.23	11172.9
3234.74	11103.4
3237.24	11124.1
3239.75	11083.7
3242.25	11052.1
3244.75	11019
3247.25	11018.9
3249.75	10989.2
3252.25	10892.6
3254.75	10897.1
3257.25	10819.7
3259.74	10774.6
3262.24	10772.4
3264.73	10718.1
3267.23	10712.4
3269.72	10704.7
3272.21	10681.8
3274.7	10647.4
3277.2	10566.4
3279.69	10567.2
3282.17	10512.9
3284.66	10478.2
3287.15	10470.8
3289.64	10428.9
3292.12	10386.4
3293.56	10364.8
3296.05	10368.1
3298.55	10366.5
3301.04	10313.2
3303.54	10306.1
3306.03	10276.6
3308.52	10254.5
3311.01	10244.5
3313.5	10199.9
3315.99	10174.7
3318.48	10132.6
3320.97	10117.3
3323.45	10145.9
3325.94	10126.5
3328.42	10139
3330.91	10085.4
3333.39	10039.9
3335.87	10071.1
3338.36	10060.7
3340.84	10017.8
3343.32	9971.28
3345.8	9983.25
3348.27	9953.65
3350.75	9909.43
3353.23	9882.08
3355.7	9867.51
3358.18	9871.87
3360.65	9851.21
3363.13	9849.56
3365.6	9836.41
3368.07	9821.86
3370.54	9789.65
3373.01	9820.21
3375.48	9793.35
3377.95	9775.12
3380.42	9771.1
3382.88	9726.71
3385.35	9684.34
3387.81	9691.67
3390.28	9656.4
3392.74	9614.9
3395.2	9653.35
3397.67	9635.11
3400.13	9575.85
3402.58	9568.52
3405.05	9551.02
3407.5	9493.33
3409.96	9491.96
3412.42	9478.88
3414.87	9425.33
3417.33	9396.08
3419.78	9374.42
3422.23	9372.78
3424.69	9308.41
3427.14	9275.16
3429.59	9246.67
3432.04	9205.45
3434.49	9183.8
3436.94	9176.01
3439.39	9136.65
3441.83	9101.06
3444.28	9064.78
3446.72	9008.35
3449.17	8953.79
3451.61	8924.02
3454.05	8916.31
3456.5	8894.24
3458.94	8830.02
3461.38	8746.54
3463.81	8741.01
3466.25	8679.01
3468.69	8649.87
3471.13	8602.55
3473.56	8570.37
3476	8473.15
3478.43	8432.38
3480.87	8388.74
3483.3	8325.62
3485.73	8293.49
3488.16	8240.92
3490.59	8162.51
3493.02	8129.42
3495.45	8122.01
3497.88	8020.84
3499.09	7977.39