File: src/Milk_AI/Heritage special acidic 532nm 50% 600g 50xL 10s 10times 400-3500cm-1 200hole.txt
#Acq. time (s)=	10
#Accumulations=	10
#Range (cm-¹)=	400...3500
#Windows=	3
#Auto scanning=	Off
#Autofocus=	Off
#AutoExposure=	Off
#Spike filter=	Multiple accum.
#Delay time (s)=	0
#Binning=	1
#Readout mode=	Signal
#DeNoise=	Off
#ICS correction=	On
#Dark correction=	Off
#Inst. Process=	Off
#Detector Gain=	Best Dynamic Range
#Detector ADC=	45 kHz
#Detector temperature (°C)=	-60.1
#Instrument=	LabRAM HR Evol
#Detector=	Syncerity OE
#Objective=	x50_VIS_LWD
#Grating=	600 (500nm)
#ND Filter=	50%
#Laser=	532nm_Edge
#Hole=	199.981
#Range=	Visible
#E-Cal_Neon=	0
#StageXY=	75x50mm Scan+
#StageZ=	Z motor
#X (µm)=	0
#Y (µm)=	0
#Z (µm)=	416.6
#Spectral res.(cm-¹)=	12.8
#Full time(mm:ss)=	5:19
#AC=	Calibrated 2025-07-01 10:31
#Project=
#Sample=
#Site=
#Title=	D_1
#Remark=
#Date=	01.07.2025 15:12 (India Standard Time)
#Acquired=	01.07.2025 15:12:52 (India Standard Time)
#AxisType[0]=Intens
#AxisUnit[0]=Cnt
#AxisType[1]=Spectr
#AxisUnit[1]=1/cm
400.083	13134.8
403.63	13077.7
407.176	13116
410.72	13118.4
414.263	13121.9
417.805	13136.5
421.345	13180.1
424.884	13159.4
428.421	13179.8
431.955	13192.5
435.49	13187.1
439.023	13158
442.555	13146.9
446.084	13092.9
449.613	13155.2
453.141	13137.3
456.666	13093.4
460.191	13124.4
463.715	13030.8
467.235	13102.2
470.756	13097.9
474.274	13114.6
477.793	13136.8
481.308	13051.7
484.823	13093.9
488.336	13139.2
491.847	13059.3
495.358	13075.7
498.867	13132
502.374	13188.7
505.881	13187.4
509.386	13197.1
512.888	13218.5
516.39	13166
519.89	13122
523.391	13113
526.889	13098.8
530.385	13159.9
533.88	13125.9
537.373	13049.7
540.866	13062.9
544.357	13075.9
547.846	13043.7
551.334	13084.2
554.821	13089.6
558.307	13058.2
561.789	13021.5
565.272	13103.2
568.753	13101.9
572.233	13078.1
575.712	13068.3
579.188	13072
582.664	13084.6
586.139	13105.4
589.611	13077.2
593.083	13056.7
596.554	13054.8
600.021	13021.1
603.49	13096.4
606.955	13067.7
610.42	13059.4
613.882	13044.8
617.345	13036.9
620.805	12996.3
624.263	12979.2
627.722	12956.2
631.178	12971.8
634.633	12942.5
638.088	12977.5
641.539	12987.6
644.99	12961.4
648.439	12995.8
651.887	12954.1
655.335	12939.2
658.781	12947.1
662.225	12941.5
665.667	12909.7
669.108	12921.9
672.548	12869.3
675.987	12930.1
679.424	12874.8
682.86	12877.1
686.293	12855.6
689.727	12829.9
693.159	12889.2
696.59	12957.2
700.019	12919.5
703.448	12906.3
706.872	12845.1
710.298	12826
713.723	12817.4
717.144	12763.6
720.565	12807.5
723.984	12823.5
727.403	12736.5
730.821	12822.9
734.235	12826.5
737.651	12802.6
741.063	12765.1
744.474	12718.9
747.885	12753.6
751.293	12807.4
754.702	12790.7
758.108	12830.8
761.512	12789.1
764.915	12779.2
768.319	12792.7
771.719	12776.3
775.118	12823.5
778.516	12744.6
781.913	12801.7
785.308	12737.7
788.702	12780.5
792.095	12740
795.486	12704.9
798.876	12721.3
802.265	12697.6
805.653	12727.4
809.039	12651.8
812.424	12664.5
815.808	12652.9
819.191	12669.2
822.572	12696.6
825.95	12650.8
829.329	12641.7
832.706	12675.3
836.08	12644.9
839.455	12622.3
842.829	12695.1
846.199	12721.5
849.57	12697.9
852.938	12728
856.307	12753.6
859.672	12758.2
863.038	12788.9
866.401	12707.8
869.765	12714.6
873.125	12802.4
876.484	12776.7
879.844	12730.3
883.2	12711
886.555	12673.3
889.909	12655.1
893.262	12622.2
896.616	12519.1
899.966	12532
903.315	12492.4
906.663	12386.1
910.009	12403.4
913.354	12433.9
916.698	12373.6
920.041	12396.1
923.383	12392.1
926.723	12358.4
930.062	12305.2
933.399	12236.1
936.734	12208.3
940.069	12291.2
943.403	12207.9
946.736	12238.1
950.065	12198.8
953.396	12151.9
956.725	12137
960.051	12192.8
963.377	12159.6
966.7	12151.7
970.025	12169.9
973.345	12199.6
976.667	12105.2
979.985	12165.4
983.304	12111.9
986.62	12163.2
989.935	12142.7
993.25	12170.9
996.563	12164.3
999.874	12286.3
1003.19	12164.9
1006.49	12164.5
1009.8	12107.9
1013.11	12133.3
1016.41	12124.4
1019.72	12126.5
1023.02	12105.3
1026.32	12077.5
1029.62	12044.4
1032.92	12064.9
1036.22	12092.2
1039.51	12041
1042.81	12033.8
1046.1	12031.9
1049.39	12040.1
1052.68	12031.8
1055.97	12088.9
1059.26	12080.8
1062.55	12137.4
1065.83	12081.7
1069.12	12145.5
1072.4	12174.4
1075.68	12168.7
1078.97	12225.5
1082.24	12120.6
1085.52	12112.1
1088.8	12023.1
1092.08	11939.5
1095.35	11927.9
1098.62	11858.6
1101.9	11821.2
1105.17	11817.2
1108.44	11836.8
1111.7	11867
1114.97	11886.3
1118.23	11864.2
1121.5	11881.9
1124.76	11823.9
1128.03	11745.5
1131.29	11678.9
1134.54	11689.5
1137.8	11639.5
1141.06	11603.9
1144.31	11591.1
1147.57	11642.8
1150.82	11596
1154.07	11649.2
1157.32	11539.7
1160.57	11517.5
1163.82	11490.7
1167.07	11506.8
1170.31	11458.1
1173.56	11433.8
1176.8	11404.7
1180.04	11394.3
1183.28	11390.1
1186.52	11360
1189.76	11397.5
1192.99	11346.7
1196.23	11377.8
1199.46	11313.6
1202.7	11325.3
1205.93	11315.8
1209.16	11299
1212.39	11297.3
1215.62	11300
1218.84	11293.1
1222.07	11295.8
1225.29	11301.3
1228.52	11268.7
1231.74	11295.6
1234.96	11290.5
1238.18	11278.7
1241.4	11308.4
1244.61	11346.9
1247.83	11358.2
1251.04	11322.8
1254.25	11389.1
1257.47	11348.5
1260.68	11389.3
1263.89	11325.2
1267.09	11343.4
1270.3	11234.1
1273.51	11250
1276.71	11217.7
1279.91	11185.6
1283.12	11184.4
1286.32	11142.1
1289.52	11218.3
1292.72	11264
1295.91	11283.9
1299.11	11289.4
1302.3	11255.3
1305.5	11260.4
1308.69	11183.4
1311.88	11162.2
1315.07	11130.5
1318.26	11059.4
1321.44	11081.1
1324.63	11052.5
1327.82	11023.9
1331	11056.5
1334.18	11026.9
1337.36	11039.4
1340.54	11019.1
1343.72	10964.7
1346.9	10980.1
1350.07	10961.1
1353.25	10909.2
1356.42	10876.7
1359.6	10869.3
1362.77	10857
1365.94	10862.4
1369.11	10846.9
1372.28	10814.5
1375.44	10751.4
1378.61	10706.8
1381.77	10679.1
1384.93	10702.7
1388.1	10751.3
1391.26	10699.2
1394.41	10722
1397.57	10704.1
1400.73	10708.1
1403.89	10682.4
1407.04	10697.4
1410.19	10693.8
1413.35	10743.6
1416.5	10765.2
1419.65	10771.9
1422.8	10752.2
1425.94	10745
1429.09	10838.9
1432.23	10958.1
1435.38	11034.7
1438.52	11014.1
1441.66	11020.6
1444.8	10955
1447.94	10877.3
1451.08	10850
1454.22	10853.9
1457.35	10757.4
1460.48	10703.3
1463.62	10657.2
1466.75	10525.5
1469.88	10470.8
1473.01	10402
1476.14	10349.1
1479.26	10245
1482.39	10241.8
1485.51	10231.6
1488.64	10178.5
1491.76	10211
1494.88	10205.6
1498	10155.2
1501.12	10178.4
1504.24	10105.7
1507.35	10098.9
1510.47	10146
1513.58	10155.5
1516.69	10128.8
1519.81	10132.3
1522.92	10158
1526.03	10103.4
1529.13	10088.4
1532.24	10011.8
1535.35	9987.64
1538.45	10041.9
1541.55	9981.01
1544.66	10015
1547.76	9978.67
1550.86	10058.8
1553.96	10041.7
1557.05	9918.92
1560.15	9938.82
1563.24	9953.78
1566.34	9931.38
1569.43	9980.72
1572.52	9932.9
1575.61	9940.69
1578.7	9919.8
1581.79	9930.73
1584.88	9926.06
1587.96	9921.55
1591.05	9947.95
1594.13	9906.26
1597.21	9933.56
1600.3	9965.03
1603.37	9930.02
1606.45	9937.7
1609.53	9922.77
1612.61	9886.07
1615.68	9887.53
1618.76	9880.94
1621.83	9827.85
1624.9	9849.28
1627.97	9883.79
1631.04	9866.92
1634.11	9841.65
1637.18	9836.18
1640.24	9879.72
1643.31	9904.63
1646.37	9915.85
1649.44	9958.24
1652.5	9959.39
1655.56	9945.7
1658.62	9905.42
1661.67	9789.6
1664.73	9811.78
1667.79	9775.5
1670.84	9693.7
1673.89	9745.38
1676.95	9629.85
1680	9604.34
1683.05	9556.38
1686.1	9460.86
1689.14	9458.97
1692.19	9399.73
1695.23	9405.14
1698.28	9354.48
1701.32	9361.31
1704.36	9341.83
1707.4	9331.91
1710.44	9262.55
1713.48	9261.36
1716.52	9260.99
1719.56	9222.62
1722.59	9233
1725.63	9187.21
1728.66	9221.01
1731.69	9189.63
1734.72	9201.01
1737.75	9175.42
1740.78	9195.5
1743.8	9156.97
1746.83	9159.59
1749.86	9109.89
1752.88	9053.84
1755.9	9013.07
1758.92	8985.9
1761.94	8964.63
1764.96	8930.37
1767.98	8977.01
1771	8937.73
1774.01	8943.15
1777.03	8941.15
1780.04	8917.98
1783.05	8884.03
1786.06	8922.53
1789.07	8876.41
1792.08	8894.44
1795.09	8850.87
1798.1	8835.39
1801.1	8832.28
1804.11	8852.03
1807.11	8774.02
1810.11	8794
1813.11	8768.01
1816.11	8731.09
1819.11	8731.24
1822.11	8757.63
1825.11	8744.15
1828.1	8692.61
1831.1	8724.21
1834.09	8663.88
1837.08	8682.25
1840.07	8663.09
1843.06	8674.61
1846.05	8685.81
1849.04	8628.88
1852.02	8645.41
1855.01	8599.79
1857.99	8574.78
1860.98	8549.96
1863.96	8587.19
1866.94	8564.96
1869.92	8539.92
1872.9	8535.45
1875.88	8570.38
1878.85	8556.25
1881.83	8501.73
1884.8	8502.68
1887.78	8483.05
1890.75	8451.2
1893.72	8425.8
1896.69	8422.52
1899.66	8438.9
1902.63	8364.31
1905.59	8334.57
1908.56	8305.68
1911.52	8252.76
1914.49	8194.87
1917.45	8131.43
1920.41	8125.65
1923.37	8043.59
1926.33	7995.84
1929.29	7976.81
1932.24	7963.91
1935.2	7926.92
1938.15	7887.73
1941.1	7834.3
1944.06	7825.44
1947.01	7744.52
1949.96	7740.67
1952.91	7691.69
1955.86	7637.82
1958.8	7609.49
1961.75	7600.8
1964.69	7536.86
1967.64	7493.04
1970.58	7471.04
1973.52	7435.09
1976.46	7403.64
1979.4	7385.27
1982.34	7334.76
1985.27	7319.19
1988.21	7255.36
1991.14	7242.39
1994.08	7194.85
1997.01	7145.09
1999.94	7094.81
2002.87	7089.48
2005.8	7039.45
2008.73	7028.15
2011.66	7002.65
2014.58	6991.17
2017.51	6963.29
2020.43	6896.21
2023.36	6879.12
2026.28	6878.32
2029.2	6836.05
2032.12	6790.65
2035.04	6763.68
2037.95	6761.7
2040.87	6760.54
2043.78	6694.83
2045.76	6659.57
2048.69	6662.34
2051.61	6641.14
2054.54	6671.25
2057.46	6636.2
2060.38	6590.77
2063.3	6625.92
2066.22	6608.35
2069.14	6624.12
2072.06	6626.01
2074.98	6597
2077.89	6581.69
2080.81	6594.43
2083.72	6602.22
2086.63	6593.66
2089.55	6529.85
2092.46	6540.18
2095.37	6509.37
2098.28	6541.79
2101.18	6512.64
2104.09	6493.01
2106.99	6472.39
2109.9	6482.26
2112.8	6435.73
2115.71	6397.23
2118.61	6434.25
2121.51	6428.31
2124.4	6429.72
2127.3	6393.69
2130.2	6366.6
2133.09	6379.85
2135.99	6427.85
2138.88	6389.53
2141.78	6363.67
2144.67	6385.08
2147.56	6359.01
2150.45	6317.45
2153.34	6341.06
2156.22	6344.89
2159.11	6330.8
2162	6316.65
2164.88	6312.23
2167.76	6296.39
2170.64	6293.83
2173.53	6281.32
2176.41	6302.3
2179.29	6288.9
2182.16	6238.17
2185.04	6223.16
2187.92	6242.44
2190.79	6258.66
2193.66	6256.17
2196.54	6232.69
2199.41	6188.33
2202.28	6212.94
2205.15	6172.48
2208.02	6171.66
2210.88	6115.59
2213.75	6130.02
2216.62	6116.1
2219.48	6078.56
2222.34	6126.3
2225.21	6102.25
2228.07	6065.15
2230.93	6071.15
2233.79	6033.4
2236.65	6027.7
2239.5	6032.91
2242.36	6019
2245.21	5997.02
2248.07	5967.98
2250.92	5986.08
2253.77	5986.48
2256.62	5906.14
2259.47	5913.67
2262.32	5872.19
2265.17	5910.52
2268.02	5866.29
2270.86	5846.87
2273.71	5828.81
2276.55	5826.14
2279.39	5812.11
2282.24	5786.82
2285.08	5790.48
2287.92	5745.01
2290.75	5747.03
2293.59	5718.29
2296.43	5717.33
2299.26	5721.19
2302.1	5726.99
2304.93	5699.86
2307.76	5643.19
2310.6	5658.19
2313.43	5687.4
2316.25	5600.26
2319.08	5586.17
2321.91	5640.08
2324.74	5751.17
2327.56	5909.26
2330.39	5651.18
2333.21	5528.6
2336.03	5526.53
2338.85	5542.39
2341.67	5540.16
2344.49	5521.02
2347.31	5497.86
2350.13	5441.64
2352.94	5420.59
2355.76	5449.13
2358.57	5402.04
2361.39	5405.58
2364.2	5394.98
2367.01	5400.23
2369.82	5367.97
2372.63	5354.3
2375.44	5325.52
2378.24	5362.05
2381.05	5312.58
2383.85	5320.1
2386.66	5294.82
2389.46	5297.43
2392.26	5294.72
2395.06	5286.77
2397.86	5259.79
2400.66	5240.4
2403.46	5251.18
2406.26	5223.49
2409.05	5261
2411.85	5253.23
2414.64	5229.41
2417.43	5185.21
2420.23	5205.3
2423.02	5193.8
2425.81	5165.28
2428.6	5103.42
2431.38	5171.47
2434.17	5167.02
2436.96	5136.44
2439.74	5111.74
2442.53	5084.05
2445.31	5099.04
2448.09	5085.58
2450.87	5088.35
2453.65	5062.45
2456.43	5066.16
2459.21	5036.04
2461.98	5015.22
2464.76	5017
2467.53	5024.83
2470.31	5006.08
2473.08	4965.83
2475.85	4986.52
2478.63	4970.15
2481.39	4958.58
2484.16	4989.99
2486.93	4977.36
2489.7	4927
2492.46	4915.73
2495.23	4928.37
2497.99	4956.46
2500.76	4896.45
2503.52	4905.29
2506.28	4860.41
2509.04	4835.25
2511.8	4842.45
2514.56	4836
2517.31	4828.14
2520.07	4844.82
2522.82	4815.92
2525.58	4833.72
2528.33	4807.75
2531.09	4808.5
2533.84	4818.63
2536.59	4789.41
2539.34	4758.81
2542.08	4758.52
2544.83	4729.32
2547.58	4705.99
2550.32	4709.83
2553.07	4703.62
2555.81	4714.14
2558.55	4705.39
2561.29	4679.47
2564.03	4668.02
2566.77	4673.66
2569.51	4652.02
2572.25	4650.2
2574.99	4640.54
2577.72	4649.73
2580.46	4655.74
2583.19	4606.84
2585.92	4603.31
2588.65	4622.44
2591.38	4619.32
2594.11	4601.73
2596.84	4609.14
2599.57	4592.51
2602.3	4577.94
2605.02	4573.6
2607.75	4587.99
2610.47	4578.28
2613.19	4553.97
2615.92	4543.02
2618.64	4527.93
2621.36	4531.2
2624.08	4535.39
2626.8	4524.16
2629.51	4487.34
2632.23	4497.79
2634.94	4479.15
2637.66	4482.97
2640.37	4483.12
2643.08	4455.59
2645.79	4458.04
2648.5	4452.61
2651.21	4469.54
2653.92	4425.69
2656.63	4427.73
2659.33	4407.63
2662.04	4437.19
2664.75	4407.53
2667.45	4421.47
2670.15	4397.29
2672.85	4419.11
2675.55	4412.68
2678.25	4406.83
2680.95	4395.14
2683.65	4386.91
2686.35	4387.06
2689.04	4367.3
2691.74	4377.49
2694.43	4354.64
2697.13	4326.49
2699.82	4345.92
2702.51	4366.69
2705.2	4352.81
2707.89	4347.45
2710.58	4326.18
2713.26	4363.56
2715.95	4328.04
2718.64	4308.76
2721.32	4307.38
2724	4298.44
2726.69	4317.38
2729.37	4301.59
2732.05	4300.96
2734.73	4293.93
2737.41	4264.18
2740.09	4247.56
2742.76	4239.48
2745.44	4209.58
2748.11	4203.32
2750.79	4230.29
2753.46	4183.55
2756.13	4164.43
2758.81	4149.89
2761.47	4191.62
2764.14	4159.25
2766.81	4181.54
2769.48	4172.03
2772.15	4156.85
2774.81	4132.93
2777.48	4114.03
2780.14	4120.17
2782.8	4089.8
2785.47	4085.29
2788.13	4099.97
2790.79	4091.48
2793.44	4083.25
2796.1	4085.61
2798.76	4073.05
2801.42	4079.88
2804.07	4054.79
2806.73	4049.03
2809.38	4074.47
2812.03	4076.22
2814.68	4062.1
2817.33	4072.2
2819.98	4055.45
2822.63	4061.57
2825.28	4066.04
2827.93	4083.16
2830.57	4104.73
2833.22	4103.47
2835.86	4145.16
2838.51	4247.63
2841.15	4397.47
2843.79	4550.52
2846.43	4688.94
2849.07	4768.87
2851.71	4795.29
2854.35	4762.36
2856.98	4720.53
2859.62	4667.2
2862.25	4650.29
2864.89	4643.6
2867.52	4690.75
2870.15	4731.25
2872.78	4753.32
2875.41	4772.07
2878.04	4824.46
2880.67	4859.54
2883.3	4888.9
2885.92	4908.83
2888.55	4948.2
2891.18	4989.56
2893.8	5022.11
2896.42	4996.1
2899.04	4990.59
2901.67	4988.25
2904.29	4942.09
2906.9	4943.97
2909.52	4943.7
2912.14	4980.98
2914.76	4965.27
2917.37	4949.01
2919.99	4935.54
2922.6	4961.33
2925.21	4988.55
2927.82	4974.02
2930.44	4975.46
2933.05	4966.44
2935.65	4945.44
2938.26	4871.74
2940.87	4823.6
2943.48	4726.05
2946.08	4619.76
2948.69	4549.24
2951.29	4489.24
2953.89	4444.17
2956.49	4407.42
2959.1	4382.74
2961.7	4331.5
2964.29	4304.92
2966.89	4256.43
2969.49	4216.73
2972.09	4164.95
2974.68	4127.13
2977.28	4133.94
2979.87	4100.12
2982.46	4051.8
2985.05	4022.15
2987.65	3987.12
2990.24	3981.74
2992.82	3982.25
2995.41	3957.24
2998	3908.69
3000.59	3907.59
3003.17	3905.78
3005.76	3903.95
3008.34	3876.76
3010.92	3845.8
3013.5	3840.5
3016.09	3825.01
3018.67	3839.42
3021.25	3824.5
3023.82	3816.61
3026.4	3837.99
3028.98	3828.08
3031.55	3801.94
3034.13	3809.36
3036.7	3824.46
3039.28	3829.95
3041.85	3859.11
3044.42	3841.02
3046.99	3860.08
3049.56	3878.06
3052.13	3877.87
3054.69	3900
3057.26	3904.03
3059.83	3920.98
3062.39	3934.01
3064.95	3967.64
3067.52	3947.41
3070.08	3959.29
3072.64	3970.8
3075.2	3997.21
3077.76	4007.59
3080.32	4014.22
3082.88	4033.11
3085.44	4051.49
3087.99	4061.96
3090.55	4096.21
3093.1	4091.91
3095.65	4112.14
3098.21	4119.24
3100.76	4163.56
3103.31	4194.23
3105.86	4230.43
3108.41	4237.18
3110.96	4257.29
3113.5	4282.07
3116.05	4343.28
3118.59	4376.72
3121.14	4350.25
3123.68	4384.06
3126.23	4443.08
3128.77	4492.6
3131.31	4528.7
3133.85	4567.84
3136.39	4583.71
3138.93	4583.56
3141.46	4640.74
3144	4676.13
3146.54	4686.97
3149.07	4736.21
3151.6	4762.28
3154.14	4782.26
3156.67	4844.45
3159.2	4909.7
3161.73	4894.89
3164.26	4908.15
3166.79	4956.62
3169.32	4967.99
3171.84	4979.42
3174.37	4998.46
3176.9	4989.33
3179.42	5012.04
3181.94	5028.04
3184.47	5039.75
3186.99	5023.8
3189.51	5069.96
3192.03	5066.04
3194.55	5069.42
3197.07	5049.9
3199.58	5065.89
3202.1	5094.76
3204.62	5114.54
3207.13	5094.02
3209.65	5117.2
3212.16	5092.03
3214.67	5064.77
3217.18	5068.1
3219.69	5055.54
3222.2	5068.78
3224.71	5071.32
3227.22	5065.24
3229.73	5058.2
3232.23	5036.84
3234.74	5042.47
3237.24	5033.04
3239.75	5009.75
3242.25	5010.93
3244.75	5009.41
3247.25	4993.04
3249.75	4977.19
3252.25	4954.37
3254.75	4934.98
3257.25	4920.85
3259.74	4899.91
3262.24	4900.1
3264.73	4880.22
3267.23	4878.45
3269.72	4877.33
3272.21	4863.4
3274.7	4841
3277.2	4828.43
3279.69	4806.19
3282.17	4791.68
3284.66	4816.91
3287.15	4785.98
3289.64	4751.15
3292.12	4762.41
3293.56	4744.65
3296.05	4764.64
3298.55	4766.75
3301.04	4728.5
3303.54	4712.52
3306.03	4720.39
3308.52	4723.46
3311.01	4727.38
3313.5	4712.61
3315.99	4683.92
3318.48	4702.83
3320.97	4681.67
3323.45	4711.03
3325.94	4693.94
3328.42	4663.52
3330.91	4687.83
3333.39	4706.82
3335.87	4666.95
3338.36	4672.94
3340.84	4672.74
3343.32	4635.5
3345.8	4671.76
3348.27	4649.92
3350.75	4646.93
3353.23	4626.51
3355.7	4647.1
3358.18	4654.58
3360.65	4635.85
3363.13	4602.92
3365.6	4611.64
3368.07	4642.25
3370.54	4629.89
3373.01	4638.98
3375.48	4644.48
3377.95	4617.86
3380.42	4628.93
3382.88	4618.59
3385.35	4601.73
3387.81	4613.67
3390.28	4600.25
3392.74	4598.49
3395.2	4622.8
3397.67	4569.58
3400.13	4596.71
3402.58	4597.32
3405.05	4606.32
3407.5	4568.2
3409.96	4530.66
3412.42	4537.28
3414.87	4515.53
3417.33	4540.71
3419.78	4522.3
3422.23	4495.41
3424.69	4457.23
3427.14	4470.81
3429.59	4445.42
3432.04	4431.84
3434.49	4411.05
3436.94	4389.71
3439.39	4358.62
3441.83	4370.41
3444.28	4325.04
3446.72	4303.74
3449.17	4288.13
3451.61	4266.62
3454.05	4260.17
3456.5	4240.96
3458.94	4186.39
3461.38	4185.44
3463.81	4167.17
3466.25	4112.39
3468.69	4087.36
3471.13	4078.35
3473.56	4055.28
3476	3982.84
3478.43	3951.11
3480.87	3924.7
3483.3	3890.17
3485.73	3861.88
3488.16	3820.55
3490.59	3818.39
3493.02	3784.43
3495.45	3726.94
3497.88	3688.94
3499.09	3672.16