File: src/Milk_AI/Heritage full cream RT 532nm 50% 600g 50xL 10s 10times 400-3500cm-1 100hole.txt
#Acq. time (s)=	10
#Accumulations=	10
#Range (cm-¹)=	400...3500
#Windows=	3
#Auto scanning=	Off
#Autofocus=	Off
#AutoExposure=	Off
#Spike filter=	Multiple accum.
#Delay time (s)=	0
#Binning=	1
#Readout mode=	Signal
#DeNoise=	Off
#ICS correction=	On
#Dark correction=	Off
#Inst. Process=	Off
#Detector Gain=	Best Dynamic Range
#Detector ADC=	45 kHz
#Detector temperature (°C)=	-60.1
#Instrument=	LabRAM HR Evol
#Detector=	Syncerity OE
#Objective=	x50_VIS_LWD
#Grating=	600 (500nm)
#ND Filter=	50%
#Laser=	532nm_Edge
#Hole=	199.981
#Range=	Visible
#E-Cal_Neon=	0
#StageXY=	75x50mm Scan+
#StageZ=	Z motor
#X (µm)=	0
#Y (µm)=	0
#Z (µm)=	681
#Spectral res.(cm-¹)=	12.8
#Full time(mm:ss)=	5:20
#AC=	Calibrated 2025-06-30 10:26
#Project=
#Sample=
#Site=
#Title=	D_104
#Remark=
#Date=	30.06.2025 11:14 (India Standard Time)
#Acquired=	30.06.2025 11:14:32 (India Standard Time)
#AxisType[0]=Intens
#AxisUnit[0]=Cnt
#AxisType[1]=Spectr
#AxisUnit[1]=1/cm
400.17	27558.9
403.717	27449
407.263	27394.3
410.807	27468.3
414.35	27373.3
417.892	27545.7
421.432	27380
424.971	27377.7
428.509	27456
432.045	27422.8
435.58	27450.3
439.111	27336.2
442.643	27383.1
446.174	27304.1
449.701	27251.5
453.229	27232.1
456.756	27259.1
460.279	27116.7
463.803	27134.9
467.326	27062.7
470.845	27014.9
474.365	27026.7
477.882	27038.2
481.399	26912.7
484.913	26966.4
488.425	26985.8
491.938	26900
495.448	26926.7
498.956	27036.8
502.465	27028.5
505.971	27055.6
509.475	27065.4
512.981	27037.9
516.482	27042.3
519.983	26982.3
523.482	27001.4
526.979	26893.2
530.476	26824.6
533.971	26684.2
537.464	26711.4
540.956	26624
544.447	26595.4
547.937	26563.3
551.425	26561.9
554.912	26560.6
558.398	26431.6
561.882	26481.4
565.365	26480.6
568.847	26496.6
572.325	26511.6
575.804	26530.9
579.282	26576.9
582.756	26646
586.231	26620.2
589.705	26574.3
593.175	26624.7
596.646	26717
600.116	26733
603.582	26755
607.049	26782.8
610.513	26615.5
613.977	26539.8
617.438	26510
620.898	26397
624.359	26339.2
627.816	26202.6
631.272	26152.9
634.728	26139.7
638.181	26207.7
641.633	26263
645.084	26064.8
648.535	26084.1
651.983	26007.8
655.43	26009.9
658.875	25980
662.319	25912
665.762	25907.2
669.203	25920.8
672.643	25893.1
676.082	25888
679.519	25793.7
682.955	25946.3
686.39	25882.1
689.824	25878
693.256	25894.3
696.685	26016.9
700.115	25947.7
703.543	25875.6
706.97	25910.5
710.394	25922.1
713.818	25853.7
717.241	25938.8
720.661	26020.7
724.082	25929.3
727.501	25973.1
730.917	25805
734.334	25902.9
737.747	25868.6
741.161	25802.4
744.572	25647.2
747.982	25729.5
751.392	25774
754.799	25881
758.205	25944.2
761.611	25899.6
765.014	25957.7
768.416	25917.3
771.816	25866
775.218	25903.7
778.616	26011.8
782.012	25952.4
785.408	25997
788.802	25908.1
792.195	25937.6
795.586	25918.6
798.977	25960.8
802.365	26010.2
805.753	26053.3
809.14	26154.4
812.525	26027.7
815.907	26117.1
819.289	26205.5
822.671	26413.5
826.051	26588.7
829.43	26612.9
832.805	26674.8
836.182	26714
839.557	26815.1
842.928	26962.9
846.301	27071.9
849.67	27165.9
853.04	27043.5
856.407	27149
859.774	27289.9
863.138	27383
866.503	27398.4
869.865	27430.5
873.225	27430.3
876.586	27431.9
879.944	27250.7
883.301	27137.8
886.658	27150.3
890.012	27273.5
893.365	27090.8
896.717	26833.8
900.067	26576.3
903.416	26520.4
906.766	26353.7
910.112	26218.6
913.458	26274.5
916.802	26237.9
920.145	26311.2
923.484	26208.1
926.825	26015.4
930.164	25902.3
933.501	25764.9
936.838	25787.4
940.173	25924.3
943.505	25769.3
946.838	25803.4
950.17	25836.6
953.5	25834.6
956.827	25800.6
960.155	25948
963.48	25938.5
966.805	25806.1
970.128	25781.8
973.45	25744
976.77	25510.8
980.091	25616.1
983.408	25597
986.726	25612.3
990.041	25817
993.354	25937.4
996.668	26264.8
999.979	26807.6
1003.29	27362.1
1006.6	27107.1
1009.91	26518.7
1013.21	26344.9
1016.52	26255.6
1019.82	26125.1
1023.12	25999.7
1026.43	25973.1
1029.73	25920.4
1033.02	25842.3
1036.32	25851.3
1039.62	25743.5
1042.91	25737.7
1046.21	25783.6
1049.5	25827.3
1052.79	25992.4
1056.08	26286.1
1059.37	26631.5
1062.65	27167.2
1065.94	26981.1
1069.23	26605.5
1072.51	26709.9
1075.79	26827.2
1079.07	26910.5
1082.35	26982.5
1085.63	26835.3
1088.91	26587.3
1092.18	26327.5
1095.46	26039.6
1098.73	25806.5
1102	25566.7
1105.27	25300.3
1108.54	25376.1
1111.81	25353.9
1115.08	25629.4
1118.34	25752.3
1121.61	26015.4
1124.87	26133.8
1128.13	26068.5
1131.39	25569.8
1134.65	25087.4
1137.91	24928.4
1141.17	25083.1
1144.42	25531.6
1147.68	26116.1
1150.93	27219.8
1154.18	28519.3
1157.43	28814.7
1160.68	27520
1163.93	25978.7
1167.18	25010.3
1170.42	24814.5
1173.67	24628.6
1176.91	24479.6
1180.15	24349.2
1183.39	24385.4
1186.63	24472.5
1189.87	24500
1193.11	24448.6
1196.34	24312.3
1199.58	24149.2
1202.81	24008.3
1206.04	24014.3
1209.27	23979
1212.5	23912.4
1215.73	23695.5
1218.95	23616.2
1222.18	23531.9
1225.4	23540
1228.63	23614.1
1231.85	23644.9
1235.07	23687.9
1238.29	23748.8
1241.51	23926.2
1244.72	24094.1
1247.94	24246.7
1251.15	24354
1254.37	24487.2
1257.58	24527.2
1260.79	24586.2
1264	24715.2
1267.21	24835.6
1270.41	24596.2
1273.62	24527
1276.82	24471.4
1280.03	24431.2
1283.23	24487
1286.43	24596.5
1289.63	24938.7
1292.83	25652
1296.03	26588.2
1299.22	26942
1302.42	26911.7
1305.61	26456
1308.8	25816.7
1311.99	25346.1
1315.18	24735.5
1318.37	24335.6
1321.56	23938.8
1324.74	23706.7
1327.93	23462
1331.11	23230.6
1334.3	23065.6
1337.48	23086.4
1340.66	23029.2
1343.84	23050.7
1347.01	22887.5
1350.19	22797.4
1353.37	22666.9
1356.54	22539.1
1359.71	22463.7
1362.88	22486.4
1366.05	22535
1369.22	22480.8
1372.39	22288.7
1375.56	22047.9
1378.72	21949.4
1381.89	21826.1
1385.05	21722.8
1388.21	21733.8
1391.37	21745.2
1394.53	21738.1
1397.69	21743.1
1400.85	21738
1404	21750.9
1407.16	21797.4
1410.31	21982.8
1413.46	22196.8
1416.61	22511.3
1419.76	22808.1
1422.91	23064
1426.06	23490.1
1429.21	24406.5
1432.35	26081
1435.49	27686.6
1438.64	28566.3
1441.78	28527.3
1444.92	27939.3
1448.06	27384.8
1451.2	27002.4
1454.33	26640.9
1457.47	26274.4
1460.6	25697.5
1463.74	25028.3
1466.87	24241
1470	23455
1473.13	22737.7
1476.26	22109.9
1479.38	21680.2
1482.51	21479.6
1485.63	21274.9
1488.76	21200.9
1491.88	21190.2
1495	21233.8
1498.12	21266.8
1501.24	21349.6
1504.36	21637.2
1507.47	22004.4
1510.59	22746.8
1513.7	23538.6
1516.81	24359.3
1519.93	24817.7
1523.04	24935.3
1526.15	24364.9
1529.25	23332.4
1532.36	22070.7
1535.47	21166.5
1538.57	20623.1
1541.67	20433.5
1544.78	20146
1547.88	19936.5
1550.98	19874.3
1554.08	19845.9
1557.18	19776.9
1560.27	19734.8
1563.37	19703.2
1566.46	19644
1569.55	19695.5
1572.64	19643.8
1575.74	19616.9
1578.83	19664.9
1581.91	19627
1585	19562.8
1588.09	19603.6
1591.17	19571.9
1594.25	19542.7
1597.34	19565.9
1600.42	19648.2
1603.5	19585.5
1606.58	19527.7
1609.65	19522.9
1612.73	19509.5
1615.8	19402.8
1618.88	19388.4
1621.95	19307.1
1625.03	19336.4
1628.1	19423.7
1631.17	19450.4
1634.23	19536.3
1637.3	19640.9
1640.37	19838.1
1643.43	20026.1
1646.5	20547.7
1649.56	21482.8
1652.62	22108.2
1655.68	22076.9
1658.74	21416.9
1661.8	20543.1
1664.85	20156.8
1667.91	19882.7
1670.96	19649.1
1674.02	19320
1677.07	18980.9
1680.12	18847.6
1683.17	18715.8
1686.22	18551.5
1689.27	18479.5
1692.31	18318.2
1695.36	18210.7
1698.4	18070.5
1701.45	18002.8
1704.49	17935.4
1707.53	17891.6
1710.57	17826
1713.61	17786.8
1716.65	17776.3
1719.68	17743
1722.72	17817.1
1725.75	17884.5
1728.78	17995.5
1731.82	18102.4
1734.84	18335.7
1737.87	18580.3
1740.9	18746.4
1743.93	18743.1
1746.96	18739.9
1749.98	18634.9
1753	18396.2
1756.03	17977
1759.05	17689.9
1762.07	17389.9
1765.09	17308.6
1768.11	17152.3
1771.12	17138.4
1774.14	17090.9
1777.15	16976.1
1780.17	16957.1
1783.18	16899.3
1786.19	16961.6
1789.2	16967.3
1792.21	16895.9
1795.22	16945.3
1798.22	16791.6
1801.23	16796
1804.23	16758
1807.24	16699.4
1810.24	16696.4
1813.24	16667.2
1816.24	16578
1819.24	16565.7
1822.24	16548.5
1825.23	16547.2
1828.23	16508.4
1831.22	16506.1
1834.22	16471.7
1837.21	16480
1840.2	16412.3
1843.19	16349.5
1846.18	16363.1
1849.17	16381.6
1852.15	16219.4
1855.14	16293.1
1858.12	16222.4
1861.11	16202.4
1864.09	16256.3
1867.07	16187.2
1870.05	16101.2
1873.03	16138.2
1876.01	16098.3
1878.98	16077
1881.96	16075.6
1884.93	15883.9
1887.91	15952.6
1890.88	15873.1
1893.85	15877.4
1896.82	15815.7
1899.79	15798.4
1902.76	15716.9
1905.72	15571.4
1908.69	15511.8
1911.65	15446.8
1914.62	15327.7
1917.58	15311.5
1920.54	15205.9
1923.5	15168.2
1926.46	15117.8
1929.42	15030.4
1932.37	14969.2
1935.33	14906.8
1938.28	14794.5
1941.24	14744.7
1944.19	14690.8
1947.14	14558
1950.09	14537.4
1953.04	14409
1955.99	14304.7
1958.93	14259.3
1961.88	14168.5
1964.82	14146.6
1967.77	14096.4
1970.71	14019.4
1973.65	13956.2
1976.59	13929.7
1979.53	13857.4
1982.47	13760.5
1985.41	13709.4
1988.34	13671.1
1991.28	13587.3
1994.21	13498.7
1997.14	13420.6
2000.07	13355.9
2003.01	13281.5
2005.94	13259
2008.86	13213.2
2011.79	13167.3
2014.72	13106.9
2017.64	13045.4
2020.57	13006.8
2023.49	12929.8
2026.41	12875.8
2029.33	12819.4
2032.25	12785.1
2035.17	12745.4
2038.09	12683
2041	12681.9
2043.92	12603.5
2045.86	12579.5
2048.79	12600.7
2051.71	12534.1
2054.64	12528.3
2057.56	12536.3
2060.48	12465
2063.4	12499.3
2066.32	12449.4
2069.24	12446.4
2072.16	12389.1
2075.08	12382.9
2077.99	12377.5
2080.91	12328.2
2083.82	12365.4
2086.74	12302.5
2089.65	12295.5
2092.56	12230.5
2095.47	12236.2
2098.38	12216.9
2101.29	12208.1
2104.19	12144
2107.1	12189.6
2110	12143.9
2112.91	12051.4
2115.81	12056.9
2118.71	12043.6
2121.61	12054.3
2124.51	12043.3
2127.4	11990.3
2130.3	11981.3
2133.2	11977.4
2136.09	11925.8
2138.99	11912.7
2141.88	11908.2
2144.77	11895.2
2147.66	11871.3
2150.55	11859.3
2153.44	11830.3
2156.33	11840.3
2159.21	11813.5
2162.1	11812
2164.98	11844.1
2167.87	11727.9
2170.75	11788.8
2173.63	11744.9
2176.51	11719.2
2179.39	11735.2
2182.27	11737.4
2185.14	11672.2
2188.02	11617.4
2190.9	11615.3
2193.77	11601.6
2196.64	11566.1
2199.51	11571.6
2202.39	11527.6
2205.25	11528.1
2208.12	11483.1
2210.99	11422
2213.86	11452.1
2216.72	11403.4
2219.59	11351
2222.45	11377.7
2225.31	11276.9
2228.17	11331.9
2231.03	11273.1
2233.89	11227.7
2236.75	11198.5
2239.61	11194.4
2242.46	11164.7
2245.32	11182.1
2248.17	11106.2
2251.03	11047.8
2253.88	11056
2256.73	11007.1
2259.58	10947.1
2262.43	10936.1
2265.28	10923.6
2268.12	10856.7
2270.97	10819.3
2273.81	10808.3
2276.66	10759
2279.5	10745.6
2282.34	10711.5
2285.18	10709.2
2288.02	10692.4
2290.86	10686.8
2293.7	10622.9
2296.54	10603.9
2299.37	10581.4
2302.21	10557.4
2305.04	10547.5
2307.87	10466.5
2310.7	10523.3
2313.53	10476.5
2316.36	10432.8
2319.19	10387.2
2322.02	10381.2
2324.85	10394.6
2327.67	10534.6
2330.5	10589.3
2333.32	10305.1
2336.14	10206.2
2338.96	10207.9
2341.78	10161.2
2344.6	10139.6
2347.42	10099.5
2350.24	10067.4
2353.05	10104.8
2355.87	10020.1
2358.68	9993.93
2361.5	9977.47
2364.31	9945.6
2367.12	9936.25
2369.93	9918.26
2372.74	9845.48
2375.55	9827.07
2378.35	9788.93
2381.16	9796.06
2383.96	9781.22
2386.77	9763.42
2389.57	9794.36
2392.37	9703.54
2395.17	9727.31
2397.97	9676
2400.77	9635.24
2403.57	9609.33
2406.37	9593.83
2409.16	9601.34
2411.96	9580.81
2414.75	9540.41
2417.55	9569.65
2420.34	9523.92
2423.13	9493.77
2425.92	9448.45
2428.71	9495.09
2431.5	9398.79
2434.28	9410.27
2437.07	9401.27
2439.85	9427.52
2442.64	9337.16
2445.42	9375.99
2448.2	9311.81
2450.98	9288.02
2453.76	9244.38
2456.54	9254.31
2459.32	9265.24
2462.1	9215.12
2464.87	9184.31
2467.65	9180.42
2470.42	9130.13
2473.2	9133.1
2475.97	9105.56
2478.74	9117.33
2481.51	9138.25
2484.28	9081.6
2487.05	9016
2489.81	9028.01
2492.58	9011.03
2495.34	8970.05
2498.11	8966.69
2500.87	8898.68
2503.63	8947.41
2506.39	8890.75
2509.15	8882.04
2511.91	8891.7
2514.67	8878.67
2517.43	8801.59
2520.19	8834.7
2522.94	8809.88
2525.7	8821.66
2528.45	8777.39
2531.2	8758.78
2533.95	8766.65
2536.7	8787.1
2539.45	8748.68
2542.2	8711.99
2544.95	8647.12
2547.69	8619.82
2550.44	8665.95
2553.18	8595.15
2555.93	8588.58
2558.67	8594.36
2561.41	8562.63
2564.15	8546.08
2566.89	8512.46
2569.63	8479.76
2572.36	8510.25
2575.1	8506.33
2577.84	8492.54
2580.57	8478
2583.31	8502.35
2586.04	8454.78
2588.77	8483.31
2591.5	8470.4
2594.23	8483.94
2596.96	8462.96
2599.69	8453.61
2602.41	8451.52
2605.14	8388.14
2607.86	8372.27
2610.59	8385.68
2613.31	8374.1
2616.03	8361.77
2618.75	8355.38
2621.48	8303.42
2624.19	8278.06
2626.91	8326.81
2629.63	8296.36
2632.35	8278.27
2635.06	8305.83
2637.77	8288.67
2640.49	8243.27
2643.2	8258.28
2645.91	8266.95
2648.62	8232.82
2651.33	8251.84
2654.04	8219.5
2656.75	8215.53
2659.45	8223.25
2662.16	8219.75
2664.86	8187.6
2667.57	8209.6
2670.27	8237.14
2672.97	8214.44
2675.67	8177.45
2678.37	8211.99
2681.07	8135.88
2683.77	8143.32
2686.47	8161.7
2689.16	8136.1
2691.86	8112.08
2694.55	8140.57
2697.25	8101.66
2699.94	8125.45
2702.63	8091.92
2705.32	8176.58
2708.01	8161.42
2710.7	8189.1
2713.39	8181.11
2716.07	8219.43
2718.76	8218.48
2721.44	8243.07
2724.12	8242.64
2726.81	8254.87
2729.49	8242.26
2732.17	8186.34
2734.85	8107.71
2737.53	8058.89
2740.21	7988.49
2742.88	7903.04
2745.56	7858.83
2748.24	7806.67
2750.91	7754.61
2753.58	7726.39
2756.25	7711.81
2758.93	7664.45
2761.6	7668.55
2764.27	7637.88
2766.93	7655.58
2769.6	7610.09
2772.27	7573.14
2774.93	7609.44
2777.6	7549.4
2780.26	7535.95
2782.93	7515.73
2785.59	7504.54
2788.25	7468.32
2790.91	7539.49
2793.57	7508.57
2796.23	7527.25
2798.88	7513.64
2801.54	7540.89
2804.2	7518.84
2806.85	7534.91
2809.5	7509.73
2812.16	7555.5
2814.81	7561.32
2817.46	7618.4
2820.11	7636.02
2822.76	7710.82
2825.4	7764.29
2828.05	7922.95
2830.7	8061.02
2833.34	8260.92
2835.99	8593.37
2838.63	9161.06
2841.27	9984.02
2843.91	11287.8
2846.55	12845.3
2849.19	14136.5
2851.83	14759.4
2854.47	14517.5
2857.11	14091.6
2859.74	13604.4
2862.38	13295.8
2865.01	12990.5
2867.65	12972.9
2870.28	13120.9
2872.91	13435.4
2875.54	13674.9
2878.17	13891.5
2880.8	14139.3
2883.42	14371.5
2886.05	14388.1
2888.68	14400.5
2891.3	14383.1
2893.93	14389.1
2896.55	14332.8
2899.17	14332.2
2901.79	14263.3
2904.41	14227
2907.03	14185
2909.65	14110.8
2912.27	14102.6
2914.88	14001.5
2917.5	13944.7
2920.11	13942.8
2922.73	13926.3
2925.34	13897.6
2927.95	14004.5
2930.56	13996.4
2933.17	13909.3
2935.78	13817.7
2938.39	13527.7
2941	12979.5
2943.6	12300.4
2946.21	11657.7
2948.81	11124.4
2951.42	10730.7
2954.02	10528.8
2956.62	10374.3
2959.22	10272.6
2961.82	10070.3
2964.42	9914.29
2967.02	9624.51
2969.62	9380.41
2972.21	9143.83
2974.81	8894.19
2977.4	8704.12
2980	8524.4
2982.59	8372.73
2985.18	8205.43
2987.77	8098.05
2990.36	8000.23
2992.95	7924.27
2995.54	7825.99
2998.13	7809.78
3000.72	7759.55
3003.3	7779.26
3005.89	7753.72
3008.47	7689.24
3011.05	7596.14
3013.63	7480.48
3016.22	7399.87
3018.8	7315.74
3021.38	7254.25
3023.95	7173.12
3026.53	7112.1
3029.11	7058.34
3031.68	7006.11
3034.26	7026.08
3036.83	6979.73
3039.4	7005.95
3041.98	6981.73
3044.55	6995.18
3047.12	6966.79
3049.69	7002.7
3052.26	7029.37
3054.82	7030.23
3057.39	7046.3
3059.96	7094.23
3062.52	7073.29
3065.09	7083.37
3067.65	7060.41
3070.21	7086.67
3072.77	7025.04
3075.33	6988.2
3077.89	7009.21
3080.45	7011.65
3083.01	6975.6
3085.57	7032.52
3088.12	7034.95
3090.68	7046.96
3093.23	7061.56
3095.79	7084.28
3098.34	7100.31
3100.89	7055.12
3103.44	7102.08
3105.99	7184.38
3108.54	7187.98
3111.09	7210.91
3113.63	7257.5
3116.18	7270.41
3118.73	7281.38
3121.27	7318.76
3123.82	7326.44
3126.36	7361.02
3128.9	7388
3131.44	7414.92
3133.98	7473.83
3136.52	7527.97
3139.06	7521.51
3141.6	7541.77
3144.13	7571.61
3146.67	7604.48
3149.2	7641.45
3151.74	7673.25
3154.27	7718.45
3156.8	7753.91
3159.34	7812.61
3161.86	7816.03
3164.4	7848.83
3166.92	7898.33
3169.45	7925.7
3171.98	7924.21
3174.5	7893.83
3177.03	7947.58
3179.56	7954.58
3182.08	7986.33
3184.6	8019.43
3187.12	8006.78
3189.64	8015.6
3192.16	7994.98
3194.68	7984.2
3197.2	8058.74
3199.72	8026.71
3202.24	8019.19
3204.75	8047.62
3207.27	8047.54
3209.78	8044.35
3212.29	8021.06
3214.81	7993.72
3217.32	8025.06
3219.83	8005.67
3222.34	8017.45
3224.85	8000.48
3227.35	8032.83
3229.86	8016.58
3232.37	7991.92
3234.87	7992.07
3237.38	7984.76
3239.88	7967.38
3242.38	7964.12
3244.89	7929.96
3247.39	7933.54
3249.89	7905.59
3252.39	7911.35
3254.88	7908.63
3257.38	7881.23
3259.88	7853.1
3262.37	7851.65
3264.87	7831.5
3267.36	7823.41
3269.86	7826.02
3272.35	7788.34
3274.84	7811.5
3277.33	7774.59
3279.82	7741.08
3282.31	7736.76
3284.8	7723.12
3287.29	7725.57
3289.77	7702.56
3292.26	7699.16
3294.15	7650.87
3296.64	7645.71
3299.14	7692.25
3301.63	7664.91
3304.12	7632.07
3306.62	7630.93
3309.11	7626.55
3311.6	7595.14
3314.09	7604.35
3316.58	7585.79
3319.07	7609.01
3321.56	7588.49
3324.04	7616.52
3326.53	7578.61
3329.01	7586.67
3331.5	7544.57
3333.98	7551.63
3336.46	7562.13
3338.94	7588.63
3341.42	7576.57
3343.9	7511.33
3346.38	7526.95
3348.86	7530.35
3351.34	7515.25
3353.82	7494.53
3356.29	7499.06
3358.77	7469.72
3361.24	7505.63
3363.71	7486.45
3366.19	7516.77
3368.66	7499.27
3371.13	7521.72
3373.6	7513.47
3376.07	7534.43
3378.54	7506.9
3381	7515.39
3383.47	7458.24
3385.94	7473.25
3388.4	7471.38
3390.87	7460.05
3393.33	7467.53
3395.79	7470.61
3398.25	7440.02
3400.71	7451.29
3403.17	7428.5
3405.63	7452.53
3408.09	7426.76
3410.55	7415.29
3413	7441.1
3415.46	7389.04
3417.92	7403.54
3420.37	7354.27
3422.82	7358.3
3425.27	7353.6
3427.73	7287.78
3430.18	7309.36
3432.63	7299.89
3435.08	7297.42
3437.53	7234.5
3439.97	7252.15
3442.42	7216.89
3444.86	7196.22
3447.31	7214.03
3449.75	7166
3452.2	7132.77
3454.64	7136.14
3457.08	7099.85
3459.52	7078.89
3461.96	7040.44
3464.4	7023.98
3466.84	7013.72
3469.28	6978.29
3471.72	6975.37
3474.15	6926.24
3476.59	6888.44
3479.02	6861.99
3481.45	6829.98
3483.89	6783.73
3486.32	6771.1
3488.75	6705.11
3491.18	6679.33
3493.61	6650.12
3496.04	6608.64
3498.47	6606.87
3499.68	6583.59