File: src/Milk_AI/Heritage full cream RT after 24h 532nm 50% 600g 50xL 10s 10times 400-3500cm-1 200hole.txt
#Acq. time (s)=	10
#Accumulations=	10
#Range (cm-¹)=	400...3500
#Windows=	3
#Auto scanning=	Off
#Autofocus=	Off
#AutoExposure=	Off
#Spike filter=	Multiple accum.
#Delay time (s)=	0
#Binning=	1
#Readout mode=	Signal
#DeNoise=	Off
#ICS correction=	On
#Dark correction=	Off
#Inst. Process=	Off
#Detector Gain=	Best Dynamic Range
#Detector ADC=	45 kHz
#Detector temperature (°C)=	-60.1
#Instrument=	LabRAM HR Evol
#Detector=	Syncerity OE
#Objective=	x50_VIS_LWD
#Grating=	600 (500nm)
#ND Filter=	50%
#Laser=	532nm_Edge
#Hole=	199.981
#Range=	Visible
#E-Cal_Neon=	0
#StageXY=	75x50mm Scan+
#StageZ=	Z motor
#X (µm)=	0
#Y (µm)=	0
#Z (µm)=	701.5
#Spectral res.(cm-¹)=	12.8
#Full time(mm:ss)=	5:19
#AC=	Calibrated 2025-07-01 10:31
#Project=
#Sample=
#Site=
#Title=	D_1
#Remark=
#Date=	01.07.2025 16:54 (India Standard Time)
#Acquired=	01.07.2025 16:54:08 (India Standard Time)
#AxisType[0]=Intens
#AxisUnit[0]=Cnt
#AxisType[1]=Spectr
#AxisUnit[1]=1/cm
400.083	28864
403.63	28574.4
407.176	28588.8
410.72	28618.3
414.263	28641.8
417.805	28683.6
421.345	28641.9
424.884	28664.9
428.421	28666.1
431.955	28642.3
435.49	28696.1
439.023	28556
442.555	28448
446.084	28504
449.613	28447.7
453.141	28470.2
456.666	28420.2
460.191	28388
463.715	28339.3
467.235	28352
470.756	28319.7
474.274	28300.7
477.793	28308
481.308	28248.5
484.823	28257.6
488.336	28318.3
491.847	28256
495.358	28245.3
498.867	28224.6
502.374	28346.4
505.881	28402.1
509.386	28423
512.888	28389.3
516.39	28294.2
519.89	28234.8
523.391	28254.6
526.889	28169.5
530.385	28162.4
533.88	27998.8
537.373	27984.8
540.866	27948.3
544.357	27966.3
547.846	27877.4
551.334	27888
554.821	27980.2
558.307	27900
561.789	27922
565.272	27926.1
568.753	27975.9
572.233	27927.6
575.712	27972.9
579.188	27896.9
582.664	27989.6
586.139	27943.9
589.611	27982.6
593.083	28039.5
596.554	28040.6
600.021	28050.6
603.49	28085.8
606.955	27965.3
610.42	27855.6
613.882	27817.9
617.345	27806.3
620.805	27728.5
624.263	27642.5
627.722	27581.7
631.178	27530
634.633	27652.9
638.088	27665.1
641.539	27732.9
644.99	27585.5
648.439	27518.1
651.887	27440.3
655.335	27478.4
658.781	27454.1
662.225	27440
665.667	27473.8
669.108	27431
672.548	27429.9
675.987	27296.2
679.424	27398.6
682.86	27335.7
686.293	27298.7
689.727	27301.7
693.159	27373
696.59	27374.5
700.019	27386.3
703.448	27455.9
706.872	27328
710.298	27395.9
713.723	27344.1
717.144	27394.8
720.565	27489.9
723.984	27467.3
727.403	27434
730.821	27296.7
734.235	27404.7
737.651	27304.1
741.063	27321.9
744.474	27281.9
747.885	27285.9
751.293	27391.5
754.702	27410.5
758.108	27474.2
761.512	27382
764.915	27431.5
768.319	27448.9
771.719	27412.5
775.118	27382.5
778.516	27369.1
781.913	27391.5
785.308	27459.9
788.702	27388.2
792.095	27320.5
795.486	27371.8
798.876	27396.4
802.265	27469.5
805.653	27478.5
809.039	27497.7
812.424	27516
815.808	27642.4
819.191	27630.4
822.572	27880.9
825.95	27987.5
829.329	28107.3
832.706	28172
836.08	28204.7
839.455	28340
842.829	28386.9
846.199	28429.2
849.57	28494.3
852.938	28498
856.307	28539.7
859.672	28720.7
863.038	28715.1
866.401	28787.3
869.765	28742.6
873.125	28728.4
876.484	28716.5
879.844	28464.3
883.2	28574.6
886.555	28566.4
889.909	28441.9
893.262	28245.6
896.616	27960.5
899.966	27779.4
903.315	27765.1
906.663	27636.6
910.009	27683.7
913.354	27723.1
916.698	27707.4
920.041	27684.1
923.383	27510.3
926.723	27399.7
930.062	27312.2
933.399	27245.5
936.734	27174
940.069	27377.3
943.403	27377.9
946.736	27491.9
950.065	27363.5
953.396	27397.8
956.725	27323.7
960.051	27340.5
963.377	27405.5
966.7	27311.4
970.025	27280
973.345	27213.1
976.667	27142.8
979.985	27168.9
983.304	27226.3
986.62	27364.3
989.935	27474.1
993.25	27782.8
996.563	28199.8
999.874	28774.6
1003.19	28531
1006.49	28164.9
1009.8	27824.2
1013.11	27734.2
1016.41	27699.6
1019.72	27526.6
1023.02	27517.9
1026.32	27455.8
1029.62	27432.6
1032.92	27385.1
1036.22	27391.3
1039.51	27368.9
1042.81	27309.2
1046.1	27437.8
1049.39	27566.3
1052.68	27774.4
1055.97	28272.7
1059.26	28706.7
1062.55	28604.9
1065.83	28280.2
1069.12	28200.1
1072.4	28451.6
1075.68	28576.1
1078.97	28554.9
1082.24	28380.5
1085.52	28167.7
1088.8	27936.1
1092.08	27689.5
1095.35	27414.1
1098.62	27309.8
1101.9	27073.5
1105.17	26983.9
1108.44	27075.3
1111.7	27318.5
1114.97	27525.1
1118.23	27783.1
1121.5	27931.7
1124.76	27858
1128.03	27443.3
1131.29	26936.8
1134.54	26879.6
1137.8	26947.7
1141.06	27228.3
1144.31	27867.4
1147.57	28840.6
1150.82	30052.9
1154.07	30454.7
1157.32	29323.8
1160.57	27791
1163.82	26974.1
1167.07	26711
1170.31	26621.9
1173.56	26468.6
1176.8	26331.2
1180.04	26422.5
1183.28	26437.1
1186.52	26479.3
1189.76	26437.4
1192.99	26287.8
1196.23	26167.4
1199.46	26008.7
1202.7	25882.2
1205.93	25860.4
1209.16	25877.4
1212.39	25816.9
1215.62	25633.8
1218.84	25585.2
1222.07	25584.5
1225.29	25628.8
1228.52	25647.7
1231.74	25773.1
1234.96	25786.5
1238.18	25874
1241.4	26097.6
1244.61	26149.6
1247.83	26298
1251.04	26346.5
1254.25	26396.8
1257.47	26500.7
1260.68	26714.9
1263.89	26734.8
1267.09	26703.6
1270.3	26579
1273.51	26480.7
1276.71	26399.5
1279.91	26442.5
1283.12	26528.9
1286.32	26813.5
1289.52	27612.3
1292.72	28519.4
1295.91	28773.4
1299.11	28623.2
1302.3	28305.5
1305.5	27792.5
1308.69	27231.4
1311.88	26706.4
1315.07	26322.4
1318.26	25965.6
1321.44	25740.3
1324.63	25574.5
1327.82	25405.4
1331	25286.1
1334.18	25275.4
1337.36	25227.9
1340.54	25200.3
1343.72	25087.9
1346.9	25077.7
1350.07	25014.7
1353.25	24898.7
1356.42	24921
1359.6	24823.4
1362.77	24826.4
1365.94	24853
1369.11	24706.3
1372.28	24577.4
1375.44	24395.3
1378.61	24295.5
1381.77	24295.1
1384.93	24147.2
1388.1	24261.9
1391.26	24223.6
1394.41	24325.2
1397.57	24211.7
1400.73	24327.6
1403.89	24336.9
1407.04	24460.2
1410.19	24650.8
1413.35	24908.2
1416.5	25179
1419.65	25386.5
1422.8	25766.2
1425.94	26636
1429.09	27984.4
1432.23	29531.5
1435.38	30341.5
1438.52	30309
1441.66	29771.7
1444.8	29373.9
1447.94	28977.8
1451.08	28719.3
1454.22	28311.7
1457.35	27869.6
1460.48	27181
1463.62	26520.1
1466.75	25873.5
1469.88	25245
1473.01	24722.8
1476.14	24374.1
1479.26	24108.1
1482.39	23986.5
1485.51	23845.1
1488.64	23869.1
1491.76	23922.7
1494.88	24077.6
1498	24102.7
1501.12	24385.6
1504.24	24774.6
1507.35	25416.1
1510.47	26088.7
1513.58	26866.9
1516.69	27390.2
1519.81	27535.5
1522.92	27003.6
1526.03	25976.5
1529.13	25002.1
1532.24	24039.6
1535.35	23585.9
1538.45	23278.2
1541.55	23225.2
1544.66	23060.2
1547.76	22890.7
1550.86	22846
1553.96	22810.8
1557.05	22744.4
1560.15	22718.6
1563.24	22769.4
1566.34	22799.7
1569.43	22730.7
1572.52	22740
1575.61	22661.3
1578.7	22674.4
1581.79	22778.6
1584.88	22667.7
1587.96	22723.3
1591.05	22756.1
1594.13	22676
1597.21	22653.5
1600.3	22755.2
1603.37	22732.9
1606.45	22613
1609.53	22662.9
1612.61	22632.4
1615.68	22569.3
1618.76	22563.8
1621.83	22516.3
1624.9	22511.4
1627.97	22659.9
1631.04	22774.1
1634.11	22827.2
1637.18	22923.4
1640.24	23187.2
1643.31	23526.4
1646.37	24385.2
1649.44	24929.7
1652.5	25033.9
1655.56	24351.5
1658.62	23631
1661.67	23155.6
1664.73	22968.5
1667.79	22849.2
1670.84	22590
1673.89	22452.7
1676.95	22142.7
1680	21988.5
1683.05	21870.9
1686.1	21732.9
1689.14	21691.9
1692.19	21657.2
1695.23	21516.2
1698.28	21463.3
1701.32	21397.3
1704.36	21255.3
1707.4	21333.1
1710.44	21368.8
1713.48	21187.7
1716.52	21202.1
1719.56	21230.9
1722.59	21333.2
1725.63	21408
1728.66	21534.4
1731.69	21639.2
1734.72	21898.7
1737.75	22086.7
1740.78	22081.1
1743.8	22009.9
1746.83	21945.8
1749.86	21732
1752.88	21374.6
1755.9	21139.3
1758.92	20978.2
1761.94	20867.7
1764.96	20752.6
1767.98	20805.4
1771	20702.9
1774.01	20659.7
1777.03	20593.7
1780.04	20628.7
1783.05	20589.4
1786.06	20532.4
1789.07	20619.9
1792.08	20550.2
1795.09	20457.3
1798.1	20478
1801.1	20431.5
1804.11	20373.2
1807.11	20407
1810.11	20394.4
1813.11	20365.1
1816.11	20252.8
1819.11	20275
1822.11	20289.6
1825.11	20227.7
1828.1	20249.1
1831.1	20161.1
1834.09	20172.4
1837.08	20076.8
1840.07	20124.5
1843.06	20129.1
1846.05	20167.5
1849.04	20053.8
1852.02	20081.5
1855.01	20046.7
1857.99	20035.5
1860.98	20010
1863.96	19952.5
1866.94	19989.8
1869.92	19969.2
1872.9	19917
1875.88	19914.3
1878.85	19908.2
1881.83	19880.9
1884.8	19828.9
1887.78	19730.1
1890.75	19736.1
1893.72	19706.2
1896.69	19741.7
1899.66	19647.3
1902.63	19569.3
1905.59	19433
1908.56	19453
1911.52	19302.7
1914.49	19243.8
1917.45	19126.7
1920.41	19060.1
1923.37	18985.8
1926.33	18924.6
1929.29	18823.4
1932.24	18755.5
1935.2	18676.5
1938.15	18573.1
1941.1	18477
1944.06	18499.9
1947.01	18379.8
1949.96	18309
1952.91	18216.1
1955.86	18099.3
1958.8	18010.1
1961.75	17927.1
1964.69	17869.9
1967.64	17810.9
1970.58	17714.6
1973.52	17677.9
1976.46	17597.3
1979.4	17536.5
1982.34	17487.8
1985.27	17420.9
1988.21	17335.3
1991.14	17242.5
1994.08	17157.9
1997.01	17046.8
1999.94	17006.6
2002.87	16943.1
2005.8	16880.5
2008.73	16859.1
2011.66	16829.6
2014.58	16715.6
2017.51	16639.5
2020.43	16561.6
2023.36	16508.4
2026.28	16433.6
2029.2	16377.7
2032.12	16339.7
2035.04	16274.2
2037.95	16219.7
2040.87	16165.4
2043.78	16118.6
2045.76	16070.7
2048.69	16055.3
2051.61	15986.8
2054.54	16012.6
2057.46	15968.7
2060.38	15955.2
2063.3	15941.6
2066.22	15928.5
2069.14	15887.1
2072.06	15908.6
2074.98	15840.7
2077.89	15826.1
2080.81	15805.7
2083.72	15797.7
2086.63	15804.2
2089.55	15748.2
2092.46	15718.8
2095.37	15681.2
2098.28	15629.8
2101.18	15628.6
2104.09	15655.3
2106.99	15647.1
2109.9	15579.2
2112.8	15525
2115.71	15513.5
2118.61	15466.8
2121.51	15537.3
2124.4	15510.9
2127.3	15451.6
2130.2	15453
2133.09	15336.9
2135.99	15444.8
2138.88	15418
2141.78	15346.7
2144.67	15374.4
2147.56	15374.1
2150.45	15347.2
2153.34	15344.2
2156.22	15350.5
2159.11	15333.7
2162	15299.5
2164.88	15273.2
2167.76	15260.5
2170.64	15253.1
2173.53	15261.6
2176.41	15189.9
2179.29	15177.8
2182.16	15129.5
2185.04	15116.4
2187.92	15092
2190.79	15086
2193.66	15031
2196.54	15024.4
2199.41	15002.3
2202.28	14942.6
2205.15	14939.8
2208.02	14942.8
2210.88	14921
2213.75	14810
2216.62	14803.3
2219.48	14780.4
2222.34	14743.9
2225.21	14718.3
2228.07	14696.7
2230.93	14675.2
2233.79	14671.5
2236.65	14613.8
2239.5	14601.3
2242.36	14565.1
2245.21	14511
2248.07	14453.3
2250.92	14478
2253.77	14431.8
2256.62	14373.4
2259.47	14296.8
2262.32	14298.7
2265.17	14240
2268.02	14236.2
2270.86	14259.6
2273.71	14163.9
2276.55	14152.4
2279.39	14116.9
2282.24	14092.9
2285.08	14021.7
2287.92	13990.9
2290.75	13959.1
2293.59	13944.6
2296.43	13982.8
2299.26	13902.9
2302.1	13877.8
2304.93	13823.6
2307.76	13821.9
2310.6	13787.5
2313.43	13732.5
2316.25	13697.9
2319.08	13663.6
2321.91	13652.7
2324.74	13746.1
2327.56	13889.5
2330.39	13618.7
2333.21	13504.5
2336.03	13482.6
2338.85	13459.3
2341.67	13420.7
2344.49	13429.5
2347.31	13401.7
2350.13	13302.7
2352.94	13303.8
2355.76	13297.3
2358.57	13146.4
2361.39	13229.5
2364.2	13188
2367.01	13180
2369.82	13124.9
2372.63	13080.4
2375.44	13061.3
2378.24	13063.6
2381.05	13056.5
2383.85	13029.8
2386.66	12987.3
2389.46	12979.4
2392.26	12964.6
2395.06	12913.2
2397.86	12848.5
2400.66	12861.6
2403.46	12834.1
2406.26	12746.9
2409.05	12860.7
2411.85	12793.6
2414.64	12761.5
2417.43	12655.3
2420.23	12690.5
2423.02	12630.5
2425.81	12657.5
2428.6	12611.4
2431.38	12647.4
2434.17	12594.9
2436.96	12545
2439.74	12550.6
2442.53	12537.7
2445.31	12500.7
2448.09	12455.4
2450.87	12433.1
2453.65	12404.1
2456.43	12401.7
2459.21	12373.5
2461.98	12322.8
2464.76	12329.7
2467.53	12291.5
2470.31	12230.4
2473.08	12229.7
2475.85	12253.9
2478.63	12268
2481.39	12217.2
2484.16	12168.8
2486.93	12134.8
2489.7	12125.2
2492.46	12081.5
2495.23	12115.1
2497.99	12074.9
2500.76	12016.3
2503.52	12037.3
2506.28	11986.2
2509.04	11948.1
2511.8	11968.2
2514.56	11906
2517.31	11896.6
2520.07	11909.9
2522.82	11887.5
2525.58	11841.3
2528.33	11840.5
2531.09	11796.1
2533.84	11807.6
2536.59	11802.6
2539.34	11772.1
2542.08	11768.4
2544.83	11703.9
2547.58	11634.3
2550.32	11644.6
2553.07	11618.2
2555.81	11600.6
2558.55	11629.2
2561.29	11546.7
2564.03	11557.4
2566.77	11566.3
2569.51	11520.5
2572.25	11506.3
2574.99	11523.3
2577.72	11447.4
2580.46	11502.6
2583.19	11492.8
2585.92	11463.8
2588.65	11407.4
2591.38	11450.8
2594.11	11454.5
2596.84	11461.3
2599.57	11396.5
2602.3	11366.8
2605.02	11381
2607.75	11341.8
2610.47	11379.5
2613.19	11360.5
2615.92	11285
2618.64	11198.7
2621.36	11201.3
2624.08	11260.3
2626.8	11289.8
2629.51	11258.5
2632.23	11216.9
2634.94	11143.8
2637.66	11229.3
2640.37	11172.5
2643.08	11154
2645.79	11158.3
2648.5	11177.8
2651.21	11108.1
2653.92	11122.4
2656.63	11100.2
2659.33	11153.1
2662.04	11136.3
2664.75	11110.2
2667.45	11074.7
2670.15	11093.4
2672.85	11077.3
2675.55	11053.2
2678.25	10987.3
2680.95	11032.2
2683.65	10981.5
2686.35	10968.9
2689.04	10990.6
2691.74	10951.1
2694.43	10905.8
2697.13	10967.8
2699.82	10934.4
2702.51	10983.6
2705.2	10900.7
2707.89	10906.4
2710.58	10957.9
2713.26	10924.3
2715.95	10962.5
2718.64	10948.5
2721.32	10948.9
2724	10896
2726.69	10898.7
2729.37	10916.1
2732.05	10865.7
2734.73	10750.7
2737.41	10716.2
2740.09	10655.6
2742.76	10603.2
2745.44	10624.6
2748.11	10501.9
2750.79	10533.9
2753.46	10470
2756.13	10482.2
2758.81	10447.6
2761.47	10404.5
2764.14	10415.2
2766.81	10349.8
2769.48	10343.1
2772.15	10347.6
2774.81	10289.6
2777.48	10295.9
2780.14	10271.6
2782.8	10273.1
2785.47	10240.2
2788.13	10255.7
2790.79	10220.2
2793.44	10267.1
2796.1	10247.6
2798.76	10260.5
2801.42	10228.8
2804.07	10165.9
2806.73	10164.3
2809.38	10216.2
2812.03	10250.3
2814.68	10277.6
2817.33	10280.4
2819.98	10303.1
2822.63	10350
2825.28	10410.2
2827.93	10520.7
2830.57	10694.4
2833.22	10908.2
2835.86	11351.7
2838.51	11905.8
2841.15	12830
2843.79	13909.3
2846.43	14756.4
2849.07	15052.5
2851.71	14909.3
2854.35	14637.7
2856.98	14332.9
2859.62	14091.6
2862.25	13921.9
2864.89	13861.7
2867.52	13992.2
2870.15	14176.6
2872.78	14374.8
2875.41	14635.5
2878.04	14876.6
2880.67	14954.6
2883.3	14920.5
2885.92	14909.1
2888.55	14941
2891.18	14889.4
2893.8	14884.9
2896.42	14872.3
2899.04	14794.4
2901.67	14724.9
2904.29	14655.6
2906.9	14616.5
2909.52	14565.4
2912.14	14526.2
2914.76	14521.6
2917.37	14481
2919.99	14417.4
2922.6	14426.1
2925.21	14434.9
2927.82	14418
2930.44	14381.1
2933.05	14277.7
2935.65	14151.6
2938.26	13711.2
2940.87	13272.5
2943.48	12806.3
2946.08	12401.3
2948.69	12171.3
2951.29	11973.7
2953.89	11929.5
2956.49	11821.5
2959.1	11661.6
2961.7	11546.5
2964.29	11303.4
2966.89	11183.6
2969.49	10999.2
2972.09	10798.5
2974.68	10653.7
2977.28	10529.9
2979.87	10396.2
2982.46	10295.7
2985.05	10201.3
2987.65	10132.3
2990.24	10113.8
2992.82	10056.1
2995.41	10001.7
2998	9944.78
3000.59	9903.98
3003.17	9949.59
3005.76	9910.29
3008.34	9796.84
3010.92	9773.49
3013.5	9669.25
3016.09	9616.36
3018.67	9545.79
3021.25	9547.9
3023.82	9497.19
3026.4	9477.07
3028.98	9438.43
3031.55	9427.58
3034.13	9366.32
3036.7	9385.49
3039.28	9389.8
3041.85	9399.39
3044.42	9402.97
3046.99	9433.52
3049.56	9433.91
3052.13	9469.17
3054.69	9484.32
3057.26	9477.41
3059.83	9461.45
3062.39	9470.26
3064.95	9517.5
3067.52	9475.55
3070.08	9516.08
3072.64	9496.9
3075.2	9509.22
3077.76	9492.29
3080.32	9476.68
3082.88	9529.4
3085.44	9573.1
3087.99	9554.36
3090.55	9621.68
3093.1	9595.72
3095.65	9593.32
3098.21	9622.82
3100.76	9646.26
3103.31	9670.83
3105.86	9736.51
3108.41	9811.57
3110.96	9817.87
3113.5	9866.38
3116.05	9886.96
3118.59	9907.06
3121.14	9975.63
3123.68	9991.25
3126.23	10052
3128.77	10060.4
3131.31	10121.6
3133.85	10181.4
3136.39	10196
3138.93	10231.5
3141.46	10226.5
3144	10299.4
3146.54	10321.7
3149.07	10402.7
3151.6	10469.6
3154.14	10524.1
3156.67	10517.7
3159.2	10560.9
3161.73	10578.7
3164.26	10634.3
3166.79	10644.6
3169.32	10656.2
3171.84	10717.4
3174.37	10645.1
3176.9	10644.2
3179.42	10718.5
3181.94	10673.3
3184.47	10712.5
3186.99	10680.4
3189.51	10684.9
3192.03	10715.4
3194.55	10704.1
3197.07	10688.7
3199.58	10681.9
3202.1	10715.1
3204.62	10729.8
3207.13	10690.8
3209.65	10680.8
3212.16	10625.4
3214.67	10635.7
3217.18	10622.7
3219.69	10621
3222.2	10602.6
3224.71	10601.5
3227.22	10582.8
3229.73	10545.8
3232.23	10533.5
3234.74	10517.6
3237.24	10499
3239.75	10474.4
3242.25	10471.6
3244.75	10430.7
3247.25	10409
3249.75	10362.5
3252.25	10355.9
3254.75	10305.1
3257.25	10293.7
3259.74	10267.6
3262.24	10239.6
3264.73	10226
3267.23	10148.5
3269.72	10168.6
3272.21	10149.7
3274.7	10155.6
3277.2	10124.7
3279.69	10082.6
3282.17	10046.2
3284.66	10017.7
3287.15	10036.9
3289.64	9973.8
3292.12	9936.88
3293.56	9912.87
3296.05	9909.34
3298.55	9899.7
3301.04	9845.41
3303.54	9911.5
3306.03	9866.18
3308.52	9855.66
3311.01	9857.64
3313.5	9772.39
3315.99	9788.52
3318.48	9776.62
3320.97	9808.12
3323.45	9787.06
3325.94	9734.68
3328.42	9744.31
3330.91	9724.2
3333.39	9696.38
3335.87	9689.71
3338.36	9698.37
3340.84	9653.64
3343.32	9667.02
3345.8	9652.44
3348.27	9623.16
3350.75	9637.19
3353.23	9587.26
3355.7	9584.33
3358.18	9599.86
3360.65	9559.47
3363.13	9558.91
3365.6	9544.09
3368.07	9484.13
3370.54	9543.24
3373.01	9510.65
3375.48	9509.48
3377.95	9453.06
3380.42	9482.31
3382.88	9469.18
3385.35	9444.98
3387.81	9410.58
3390.28	9408.65
3392.74	9416.67
3395.2	9370.53
3397.67	9410.44
3400.13	9376.25
3402.58	9347.69
3405.05	9337.21
3407.5	9321.35
3409.96	9274.6
3412.42	9269.85
3414.87	9271.15
3417.33	9261.39
3419.78	9206.87
3422.23	9182.67
3424.69	9174.38
3427.14	9103.93
3429.59	9071.39
3432.04	9061.45
3434.49	9036.23
3436.94	9037.47
3439.39	8987.66
3441.83	8936.31
3444.28	8921.3
3446.72	8852.45
3449.17	8839.2
3451.61	8815.29
3454.05	8792.35
3456.5	8765.36
3458.94	8724.75
3461.38	8688.47
3463.81	8640.64
3466.25	8627.16
3468.69	8575.36
3471.13	8530.8
3473.56	8457.06
3476	8441.29
3478.43	8352.33
3480.87	8332.06
3483.3	8256.19
3485.73	8218.61
3488.16	8161.88
3490.59	8144.13
3493.02	8093.86
3495.45	8040.08
3497.88	7974.96
3499.09	7979.61