File: src/Milk_AI/Heritage toned Cold 532nm 50% 600g 50xL 10s 10times 400-3500cm-1 200hole.txt
#Acq. time (s)=	10
#Accumulations=	10
#Range (cm-¹)=	400...3500
#Windows=	3
#Auto scanning=	Off
#Autofocus=	Off
#AutoExposure=	Off
#Spike filter=	Multiple accum.
#Delay time (s)=	0
#Binning=	1
#Readout mode=	Signal
#DeNoise=	Off
#ICS correction=	On
#Dark correction=	Off
#Inst. Process=	Off
#Detector Gain=	Best Dynamic Range
#Detector ADC=	45 kHz
#Detector temperature (°C)=	-60.1
#Instrument=	LabRAM HR Evol
#Detector=	Syncerity OE
#Objective=	x50_VIS_LWD
#Grating=	600 (500nm)
#ND Filter=	50%
#Laser=	532nm_Edge
#Hole=	199.981
#Range=	Visible
#E-Cal_Neon=	0
#StageXY=	75x50mm Scan+
#StageZ=	Z motor
#X (µm)=	0
#Y (µm)=	0
#Z (µm)=	250.6
#Spectral res.(cm-¹)=	12.8
#Full time(mm:ss)=	5:19
#AC=	Calibrated 2025-07-01 10:31
#Project=
#Sample=
#Site=
#Title=	D_1
#Remark=
#Date=	01.07.2025 11:52 (India Standard Time)
#Acquired=	01.07.2025 11:52:33 (India Standard Time)
#AxisType[0]=Intens
#AxisUnit[0]=Cnt
#AxisType[1]=Spectr
#AxisUnit[1]=1/cm
400.083	22963.3
403.63	22819.5
407.176	22870.7
410.72	22892
414.263	22862.1
417.805	22951.9
421.345	22876.1
424.884	22867.1
428.421	22907
431.955	22859.1
435.49	22925.3
439.023	22787.4
442.555	22760.4
446.084	22752.2
449.613	22712.3
453.141	22678.5
456.666	22633.2
460.191	22641.3
463.715	22579.8
467.235	22631.7
470.756	22590.7
474.274	22478.8
477.793	22547.4
481.308	22482.3
484.823	22504.4
488.336	22533.1
491.847	22477.7
495.358	22422.5
498.867	22514.7
502.374	22605.1
505.881	22567.2
509.386	22505
512.888	22555.7
516.39	22491.9
519.89	22523.8
523.391	22427.9
526.889	22443.4
530.385	22362.8
533.88	22313.8
537.373	22247.4
540.866	22206.6
544.357	22219.3
547.846	22183.4
551.334	22164.1
554.821	22156.3
558.307	22200.7
561.789	22169.1
565.272	22153.1
568.753	22096.3
572.233	22140.2
575.712	22037.4
579.188	22075.6
582.664	22049.3
586.139	22085.2
589.611	22095.6
593.083	21994.5
596.554	22091.9
600.021	22029.4
603.49	22021.2
606.955	21984.4
610.42	21947.4
613.882	21933.7
617.345	21824.2
620.805	21749.3
624.263	21718.4
627.722	21687.3
631.178	21704.8
634.633	21649.1
638.088	21718
641.539	21748.3
644.99	21575.2
648.439	21597
651.887	21490
655.335	21507.8
658.781	21541.8
662.225	21458.8
665.667	21496.7
669.108	21428.2
672.548	21416.2
675.987	21357.5
679.424	21316
682.86	21415.7
686.293	21403
689.727	21333.2
693.159	21406.9
696.59	21426.3
700.019	21345.1
703.448	21298.5
706.872	21249.1
710.298	21201.6
713.723	21238.4
717.144	21104.9
720.565	21269
723.984	21153.1
727.403	21195.8
730.821	20989.3
734.235	21077.8
737.651	21053
741.063	21016.1
744.474	20974
747.885	21013.5
751.293	21016.1
754.702	20996.8
758.108	21015.5
761.512	21005.9
764.915	20962.3
768.319	21025.8
771.719	21023.9
775.118	20986.3
778.516	21057.8
781.913	20967
785.308	20956.7
788.702	20892.9
792.095	20829.5
795.486	20722.9
798.876	20843.4
802.265	20863.9
805.653	20732.5
809.039	20778
812.424	20701.6
815.808	20647.2
819.191	20691.9
822.572	20743.6
825.95	20798.2
829.329	20725.2
832.706	20738.3
836.08	20733.5
839.455	20743.8
842.829	20834.4
846.199	20777.4
849.57	20716.4
852.938	20746.5
856.307	20784.8
859.672	20814.8
863.038	20838.2
866.401	20741.9
869.765	20746.3
873.125	20817
876.484	20815.4
879.844	20647.1
883.2	20606.4
886.555	20550.2
889.909	20572.4
893.262	20506.1
896.616	20393.2
899.966	20295.6
903.315	20241.6
906.663	20240.5
910.009	20229.4
913.354	20133.7
916.698	20110
920.041	20101.1
923.383	20061.4
926.723	20010.7
930.062	19875.9
933.399	19861.9
936.734	19877.6
940.069	19907.6
943.403	19924.8
946.736	19828.5
950.065	19836.1
953.396	19820
956.725	19843.4
960.051	19856.7
963.377	19857.7
966.7	19729.9
970.025	19776.3
973.345	19690.5
976.667	19630.1
979.985	19611.8
983.304	19666.1
986.62	19741.7
989.935	19783.7
993.25	19845
996.563	19964.2
999.874	20228
1003.19	20232
1006.49	20080.1
1009.8	19928.1
1013.11	19766.1
1016.41	19710
1019.72	19666.9
1023.02	19600
1026.32	19533.5
1029.62	19503.1
1032.92	19429.6
1036.22	19375.8
1039.51	19383.4
1042.81	19339.4
1046.1	19313
1049.39	19331.1
1052.68	19365.8
1055.97	19457.2
1059.26	19502.4
1062.55	19549.6
1065.83	19519.9
1069.12	19427.2
1072.4	19431.4
1075.68	19381.9
1078.97	19480.2
1082.24	19409.7
1085.52	19362.9
1088.8	19319.4
1092.08	19192.6
1095.35	19122.7
1098.62	19011.3
1101.9	18932.4
1105.17	18841.8
1108.44	18914.3
1111.7	18957.6
1114.97	18994.8
1118.23	19061.1
1121.5	19125.8
1124.76	19084.1
1128.03	18962
1131.29	18872.9
1134.54	18732.5
1137.8	18714.6
1141.06	18745.2
1144.31	18953
1147.57	19323.1
1150.82	19827.1
1154.07	20233.3
1157.32	20087.7
1160.57	19418.1
1163.82	18817.1
1167.07	18481.6
1170.31	18477
1173.56	18399.4
1176.8	18251
1180.04	18251.9
1183.28	18272.6
1186.52	18239.1
1189.76	18305.9
1192.99	18223.6
1196.23	18139.2
1199.46	18041.3
1202.7	17998.7
1205.93	18026.1
1209.16	17984.9
1212.39	17958.4
1215.62	17893.5
1218.84	17762.9
1222.07	17745.6
1225.29	17752.6
1228.52	17769.8
1231.74	17715
1234.96	17682.3
1238.18	17725.9
1241.4	17754.6
1244.61	17900.4
1247.83	17851.6
1251.04	17849
1254.25	17883.6
1257.47	17892.5
1260.68	17893.7
1263.89	17925
1267.09	17887.7
1270.3	17769.2
1273.51	17699.2
1276.71	17652.4
1279.91	17642.2
1283.12	17593.7
1286.32	17636.8
1289.52	17763
1292.72	17855.4
1295.91	18078.1
1299.11	18032.1
1302.3	18046.6
1305.5	17949.6
1308.69	17772.4
1311.88	17587.5
1315.07	17477.3
1318.26	17343
1321.44	17227.2
1324.63	17167.2
1327.82	17199.3
1331	17134.9
1334.18	17040.5
1337.36	17105.3
1340.54	17024.7
1343.72	17008.9
1346.9	16955.4
1350.07	16925.1
1353.25	16906.7
1356.42	16753.1
1359.6	16814.9
1362.77	16732.9
1365.94	16710.2
1369.11	16675.8
1372.28	16622.1
1375.44	16439.1
1378.61	16460.2
1381.77	16458.2
1384.93	16334.7
1388.1	16442.1
1391.26	16430.2
1394.41	16356
1397.57	16353.2
1400.73	16316.8
1403.89	16320.8
1407.04	16350.6
1410.19	16322.9
1413.35	16402
1416.5	16405.6
1419.65	16481.8
1422.8	16529.5
1425.94	16618.1
1429.09	16913.6
1432.23	17285.9
1435.38	17588.6
1438.52	17755
1441.66	17679.7
1444.8	17519
1447.94	17385.3
1451.08	17284.9
1454.22	17234.3
1457.35	17143.3
1460.48	16955.9
1463.62	16717.8
1466.75	16507.6
1469.88	16288.6
1473.01	16117.5
1476.14	15947
1479.26	15811.4
1482.39	15697
1485.51	15737.4
1488.64	15629.2
1491.76	15687.1
1494.88	15789.1
1498	15795.1
1501.12	15825.6
1504.24	15949.1
1507.35	16224.6
1510.47	16527
1513.58	16798.3
1516.69	17116
1519.81	17199.1
1522.92	17130.1
1526.03	16736.8
1529.13	16250.5
1532.24	15859.7
1535.35	15454.5
1538.45	15371.8
1541.55	15250.4
1544.66	15180.4
1547.76	15089.4
1550.86	15061.6
1553.96	15057.2
1557.05	15031.5
1560.15	14945.8
1563.24	14974.4
1566.34	14957.6
1569.43	14922.2
1572.52	14970
1575.61	14906.7
1578.7	14894.5
1581.79	14921.6
1584.88	14886
1587.96	14875.5
1591.05	14926.9
1594.13	14839.7
1597.21	14841.5
1600.3	14880.3
1603.37	14904.3
1606.45	14757.7
1609.53	14785
1612.61	14776.9
1615.68	14717.8
1618.76	14716.6
1621.83	14650.7
1624.9	14653.3
1627.97	14653.9
1631.04	14684
1634.11	14656.8
1637.18	14683.1
1640.24	14744.2
1643.31	14765.2
1646.37	14951.7
1649.44	15054.9
1652.5	15076.5
1655.56	15103.3
1658.62	14896.1
1661.67	14702.7
1664.73	14600.7
1667.79	14534.7
1670.84	14507.1
1673.89	14439.4
1676.95	14316.1
1680	14227
1683.05	14145.5
1686.1	13977.9
1689.14	13932.1
1692.19	13934.2
1695.23	13855.3
1698.28	13810.8
1701.32	13740.4
1704.36	13706.5
1707.4	13654.7
1710.44	13656.7
1713.48	13539.5
1716.52	13550.3
1719.56	13495.9
1722.59	13547.5
1725.63	13533.5
1728.66	13544.8
1731.69	13513.4
1734.72	13611.3
1737.75	13614.3
1740.78	13634.9
1743.8	13595
1746.83	13512
1749.86	13525.4
1752.88	13428.4
1755.9	13331.1
1758.92	13256.1
1761.94	13242.1
1764.96	13073.5
1767.98	13121.1
1771	13129.7
1774.01	13082.4
1777.03	13058
1780.04	13067.3
1783.05	12970.7
1786.06	13004.9
1789.07	12978.9
1792.08	13027.6
1795.09	12970.3
1798.1	12890.4
1801.1	12851.5
1804.11	12869.4
1807.11	12838.2
1810.11	12818
1813.11	12779.3
1816.11	12786.7
1819.11	12700.5
1822.11	12724.9
1825.11	12672.1
1828.1	12695.9
1831.1	12658.8
1834.09	12614.5
1837.08	12627.4
1840.07	12581.5
1843.06	12570.4
1846.05	12605.7
1849.04	12555.7
1852.02	12508.3
1855.01	12543.2
1857.99	12473.1
1860.98	12425.6
1863.96	12449.8
1866.94	12361.3
1869.92	12416.3
1872.9	12312
1875.88	12385.3
1878.85	12350.3
1881.83	12282.4
1884.8	12284.1
1887.78	12192.8
1890.75	12244.1
1893.72	12158.5
1896.69	12168
1899.66	12083.2
1902.63	12046.1
1905.59	11899.4
1908.56	11920.1
1911.52	11821.2
1914.49	11740.1
1917.45	11675.9
1920.41	11615.5
1923.37	11550.3
1926.33	11497.6
1929.29	11455.3
1932.24	11366.8
1935.2	11322.8
1938.15	11250.9
1941.1	11166.3
1944.06	11113.8
1947.01	11107.9
1949.96	10997.1
1952.91	10918.3
1955.86	10833.7
1958.8	10817.1
1961.75	10740.3
1964.69	10657.1
1967.64	10640
1970.58	10568.2
1973.52	10512.5
1976.46	10452.8
1979.4	10444
1982.34	10349.4
1985.27	10344.6
1988.21	10274
1991.14	10186.7
1994.08	10142
1997.01	10061.3
1999.94	9975.6
2002.87	9938.02
2005.8	9889.42
2008.73	9885.05
2011.66	9833.07
2014.58	9766.4
2017.51	9745.55
2020.43	9697.65
2023.36	9623.39
2026.28	9589.24
2029.2	9523.52
2032.12	9510.1
2035.04	9456.73
2037.95	9394.89
2040.87	9389.78
2043.78	9361.94
2045.76	9314.69
2048.69	9299.01
2051.61	9304.44
2054.54	9221.24
2057.46	9206.11
2060.38	9187.95
2063.3	9169.92
2066.22	9181.79
2069.14	9182.82
2072.06	9149.46
2074.98	9145.84
2077.89	9152.03
2080.81	9092.92
2083.72	9082.78
2086.63	9111.87
2089.55	9065.06
2092.46	9061.45
2095.37	8959.57
2098.28	8989.61
2101.18	8959.47
2104.09	8991.1
2106.99	8974.89
2109.9	8924.95
2112.8	8891.65
2115.71	8866.66
2118.61	8894.02
2121.51	8865.92
2124.4	8835.93
2127.3	8816.06
2130.2	8796.08
2133.09	8805.17
2135.99	8767.94
2138.88	8753.96
2141.78	8748.17
2144.67	8722.54
2147.56	8751.14
2150.45	8706.89
2153.34	8702.04
2156.22	8676.93
2159.11	8653.06
2162	8648.48
2164.88	8674.06
2167.76	8656.02
2170.64	8650.62
2173.53	8628.43
2176.41	8581.44
2179.29	8564.06
2182.16	8563.59
2185.04	8559.89
2187.92	8540.24
2190.79	8496.65
2193.66	8470.96
2196.54	8455.42
2199.41	8460.64
2202.28	8457.43
2205.15	8442
2208.02	8394.23
2210.88	8364.48
2213.75	8341.81
2216.62	8354.93
2219.48	8315.09
2222.34	8298.91
2225.21	8253.48
2228.07	8257.31
2230.93	8228.08
2233.79	8198.23
2236.65	8202.3
2239.5	8175.78
2242.36	8101.98
2245.21	8130.07
2248.07	8067.14
2250.92	8104.62
2253.77	8078.81
2256.62	8048.8
2259.47	8042.63
2262.32	7963.99
2265.17	7944.76
2268.02	7921.65
2270.86	7923.68
2273.71	7853.24
2276.55	7853.66
2279.39	7829.53
2282.24	7848.13
2285.08	7796.35
2287.92	7785.86
2290.75	7754.27
2293.59	7734.32
2296.43	7735.84
2299.26	7661.79
2302.1	7669.21
2304.93	7673.98
2307.76	7631.59
2310.6	7623.32
2313.43	7613.28
2316.25	7598.75
2319.08	7544.99
2321.91	7533.71
2324.74	7591.06
2327.56	7742.03
2330.39	7732.69
2333.21	7440.82
2336.03	7417.71
2338.85	7393.87
2341.67	7395.09
2344.49	7354.29
2347.31	7360.39
2350.13	7312.09
2352.94	7248.11
2355.76	7260.37
2358.57	7248.56
2361.39	7215.25
2364.2	7225.14
2367.01	7200.66
2369.82	7156.22
2372.63	7134.89
2375.44	7122.33
2378.24	7136.93
2381.05	7094.37
2383.85	7102.58
2386.66	7062.59
2389.46	7057.83
2392.26	7040.19
2395.06	7058.73
2397.86	7011.28
2400.66	6976.27
2403.46	6983.87
2406.26	6931.11
2409.05	6971.53
2411.85	6939.25
2414.64	6914.47
2417.43	6869.68
2420.23	6888.88
2423.02	6866.69
2425.81	6865.55
2428.6	6852.91
2431.38	6852.63
2434.17	6834.47
2436.96	6783.18
2439.74	6769.66
2442.53	6717.77
2445.31	6734.49
2448.09	6758.04
2450.87	6706.13
2453.65	6680.5
2456.43	6683.21
2459.21	6694.56
2461.98	6648.23
2464.76	6633.04
2467.53	6620.17
2470.31	6597.81
2473.08	6613.89
2475.85	6571.04
2478.63	6577.62
2481.39	6558.1
2484.16	6527.96
2486.93	6513.42
2489.7	6529.54
2492.46	6495.44
2495.23	6454.4
2497.99	6483.19
2500.76	6489.11
2503.52	6428.2
2506.28	6422.32
2509.04	6383.22
2511.8	6363.39
2514.56	6376.07
2517.31	6356.17
2520.07	6334.17
2522.82	6328.26
2525.58	6301.03
2528.33	6323.31
2531.09	6291.22
2533.84	6261.32
2536.59	6265.98
2539.34	6241.48
2542.08	6229.93
2544.83	6239.47
2547.58	6186.16
2550.32	6164.41
2553.07	6172.16
2555.81	6143.45
2558.55	6153.14
2561.29	6125.08
2564.03	6076.51
2566.77	6088.92
2569.51	6071.62
2572.25	6066.94
2574.99	6062.81
2577.72	6045.58
2580.46	6047.21
2583.19	6032.02
2585.92	6034.69
2588.65	6009.35
2591.38	6017.5
2594.11	6017.91
2596.84	6023.17
2599.57	5978.2
2602.3	5960.44
2605.02	5956.63
2607.75	5992
2610.47	5930.58
2613.19	5956.57
2615.92	5917.91
2618.64	5891.93
2621.36	5903.28
2624.08	5895.09
2626.8	5887.04
2629.51	5861.34
2632.23	5836.34
2634.94	5847.05
2637.66	5830.57
2640.37	5831.18
2643.08	5823.18
2645.79	5842.43
2648.5	5786.21
2651.21	5780.36
2653.92	5776.39
2656.63	5802.04
2659.33	5767.35
2662.04	5774.11
2664.75	5747.53
2667.45	5758.45
2670.15	5734.15
2672.85	5705.73
2675.55	5723.83
2678.25	5697.14
2680.95	5694.66
2683.65	5702.35
2686.35	5666.75
2689.04	5678.87
2691.74	5643.91
2694.43	5644.42
2697.13	5644.26
2699.82	5640.49
2702.51	5649.93
2705.2	5668.64
2707.89	5661.29
2710.58	5624.06
2713.26	5642.2
2715.95	5629.73
2718.64	5640.95
2721.32	5622.58
2724	5585.82
2726.69	5581.1
2729.37	5581.34
2732.05	5598.04
2734.73	5516.94
2737.41	5524.43
2740.09	5494.12
2742.76	5493.29
2745.44	5461.6
2748.11	5404.83
2750.79	5388.48
2753.46	5398.77
2756.13	5387.23
2758.81	5368.8
2761.47	5342.27
2764.14	5346.46
2766.81	5319.82
2769.48	5297.78
2772.15	5270.96
2774.81	5316.61
2777.48	5278.77
2780.14	5248.79
2782.8	5229.12
2785.47	5207.79
2788.13	5208.97
2790.79	5219.28
2793.44	5214.27
2796.1	5233.75
2798.76	5222.66
2801.42	5235.96
2804.07	5190.55
2806.73	5167.97
2809.38	5174.88
2812.03	5192.17
2814.68	5214.44
2817.33	5208.57
2819.98	5213.84
2822.63	5210.67
2825.28	5251.08
2827.93	5274.67
2830.57	5310.54
2833.22	5357.42
2835.86	5521.66
2838.51	5630.54
2841.15	5936.63
2843.79	6262.85
2846.43	6692.79
2849.07	6925.08
2851.71	6990.48
2854.35	6913.63
2856.98	6801.22
2859.62	6699.42
2862.25	6600.08
2864.89	6592.63
2867.52	6594.24
2870.15	6668.83
2872.78	6790.68
2875.41	6837.57
2878.04	6988.14
2880.67	7013.84
2883.3	7025.6
2885.92	7034.64
2888.55	7033.43
2891.18	7059.19
2893.8	7018.53
2896.42	7037.75
2899.04	7018.89
2901.67	7043.69
2904.29	7024.19
2906.9	6961.25
2909.52	6946.72
2912.14	6944.13
2914.76	6923.64
2917.37	6923.83
2919.99	6925.49
2922.6	6912.58
2925.21	6930.71
2927.82	6886.63
2930.44	6954.67
2933.05	6922.14
2935.65	6886.25
2938.26	6775.98
2940.87	6587.66
2943.48	6395.99
2946.08	6212.16
2948.69	6120.52
2951.29	6029.05
2953.89	5898.95
2956.49	5896.3
2959.1	5863.71
2961.7	5793.88
2964.29	5712.66
2966.89	5656.86
2969.49	5586.63
2972.09	5512.03
2974.68	5452.85
2977.28	5386.52
2979.87	5328.33
2982.46	5276.92
2985.05	5242.53
2987.65	5165.98
2990.24	5142.99
2992.82	5126.84
2995.41	5117.32
2998	5073.59
3000.59	5072.81
3003.17	5028.17
3005.76	5052.77
3008.34	5015.96
3010.92	4995.38
3013.5	4956.95
3016.09	4937.69
3018.67	4926.27
3021.25	4896.23
3023.82	4905.29
3026.4	4866.58
3028.98	4844.96
3031.55	4872.99
3034.13	4876.02
3036.7	4852.94
3039.28	4881.41
3041.85	4871.1
3044.42	4893.84
3046.99	4907.38
3049.56	4919.03
3052.13	4952.88
3054.69	4969.98
3057.26	4971.74
3059.83	4999.16
3062.39	5003.43
3064.95	5035.42
3067.52	5024.28
3070.08	5030.82
3072.64	5017.17
3075.2	5054.13
3077.76	5057.66
3080.32	5058.75
3082.88	5101.06
3085.44	5087.64
3087.99	5114.39
3090.55	5117.46
3093.1	5163.54
3095.65	5137.8
3098.21	5197.91
3100.76	5224.36
3103.31	5228.03
3105.86	5290.35
3108.41	5328.29
3110.96	5383.2
3113.5	5386.83
3116.05	5403.04
3118.59	5445.63
3121.14	5476.32
3123.68	5528.12
3126.23	5535.19
3128.77	5582.54
3131.31	5577.17
3133.85	5667.62
3136.39	5674.33
3138.93	5729.06
3141.46	5752.93
3144	5813.98
3146.54	5839.35
3149.07	5883.12
3151.6	5927.32
3154.14	5968.97
3156.67	5965.02
3159.2	6041.16
3161.73	5999.54
3164.26	6076.44
3166.79	6116.34
3169.32	6127.03
3171.84	6130.76
3174.37	6134.54
3176.9	6153.48
3179.42	6157.58
3181.94	6180.29
3184.47	6193.5
3186.99	6171.22
3189.51	6216.79
3192.03	6228.96
3194.55	6226.21
3197.07	6218.2
3199.58	6246.73
3202.1	6210.45
3204.62	6233.74
3207.13	6239.9
3209.65	6248.97
3212.16	6223.44
3214.67	6216.01
3217.18	6219.65
3219.69	6208.11
3222.2	6187.77
3224.71	6183.32
3227.22	6176.62
3229.73	6183.69
3232.23	6171.41
3234.74	6189.89
3237.24	6159.11
3239.75	6137.93
3242.25	6134.05
3244.75	6117.71
3247.25	6097.01
3249.75	6082.32
3252.25	6072.27
3254.75	6038.63
3257.25	6020.53
3259.74	5990.52
3262.24	5981.42
3264.73	5988.83
3267.23	5966.14
3269.72	5953.74
3272.21	5960.99
3274.7	5922.51
3277.2	5892.21
3279.69	5885.99
3282.17	5878.32
3284.66	5888.74
3287.15	5863.74
3289.64	5850.3
3292.12	5844.48
3293.56	5836.64
3296.05	5819.72
3298.55	5794.14
3301.04	5791.24
3303.54	5804.1
3306.03	5774.7
3308.52	5767.68
3311.01	5782.85
3313.5	5745.21
3315.99	5755.39
3318.48	5731.63
3320.97	5701.8
3323.45	5727.01
3325.94	5711.25
3328.42	5720.37
3330.91	5684.61
3333.39	5708.07
3335.87	5700.11
3338.36	5661.98
3340.84	5664.48
3343.32	5666.04
3345.8	5673.85
3348.27	5689.72
3350.75	5656.36
3353.23	5647.89
3355.7	5606.44
3358.18	5632.11
3360.65	5630.54
3363.13	5646.54
3365.6	5610.14
3368.07	5614.61
3370.54	5611.79
3373.01	5648.82
3375.48	5620.14
3377.95	5617.61
3380.42	5594.28
3382.88	5608.48
3385.35	5578.47
3387.81	5584.08
3390.28	5549.25
3392.74	5563.13
3395.2	5562.92
3397.67	5581.8
3400.13	5543.44
3402.58	5564.58
3405.05	5530.44
3407.5	5514.93
3409.96	5485.48
3412.42	5493.99
3414.87	5492.25
3417.33	5480.37
3419.78	5466.52
3422.23	5428.43
3424.69	5414.07
3427.14	5380.58
3429.59	5377.34
3432.04	5367.36
3434.49	5355.42
3436.94	5348.31
3439.39	5322.36
3441.83	5266.46
3444.28	5223.92
3446.72	5214.15
3449.17	5200.59
3451.61	5184.27
3454.05	5145.93
3456.5	5148.77
3458.94	5108.58
3461.38	5052.17
3463.81	5068.69
3466.25	5014.35
3468.69	4975.43
3471.13	4944.87
3473.56	4908.54
3476	4872.29
3478.43	4842.26
3480.87	4801.85
3483.3	4791.73
3485.73	4730.44
3488.16	4715.69
3490.59	4644.73
3493.02	4640.66
3495.45	4599.05
3497.88	4550.56
3499.09	4519.15