File: src/Milk_AI/Heritage special basic 532nm 50% 600g 50xL 10s 10times 400-3500cm-1 200hole.txt
#Acq. time (s)=	10
#Accumulations=	10
#Range (cm-¹)=	400...3500
#Windows=	3
#Auto scanning=	Off
#Autofocus=	Off
#AutoExposure=	Off
#Spike filter=	Multiple accum.
#Delay time (s)=	0
#Binning=	1
#Readout mode=	Signal
#DeNoise=	Off
#ICS correction=	On
#Dark correction=	Off
#Inst. Process=	Off
#Detector Gain=	Best Dynamic Range
#Detector ADC=	45 kHz
#Detector temperature (°C)=	-60.1
#Instrument=	LabRAM HR Evol
#Detector=	Syncerity OE
#Objective=	x50_VIS_LWD
#Grating=	600 (500nm)
#ND Filter=	50%
#Laser=	532nm_Edge
#Hole=	199.981
#Range=	Visible
#E-Cal_Neon=	0
#StageXY=	75x50mm Scan+
#StageZ=	Z motor
#X (µm)=	0
#Y (µm)=	0
#Z (µm)=	693.7
#Spectral res.(cm-¹)=	12.8
#Full time(mm:ss)=	5:19
#AC=	Calibrated 2025-07-01 10:31
#Project=
#Sample=
#Site=
#Title=	D_1
#Remark=
#Date=	01.07.2025 16:33 (India Standard Time)
#Acquired=	01.07.2025 16:33:22 (India Standard Time)
#AxisType[0]=Intens
#AxisUnit[0]=Cnt
#AxisType[1]=Spectr
#AxisUnit[1]=1/cm
400.083	24547.7
403.63	24447.5
407.176	24394.1
410.72	24482.8
414.263	24454.4
417.805	24570.5
421.345	24542.4
424.884	24407.6
428.421	24572.9
431.955	24597.7
435.49	24564.6
439.023	24541.7
442.555	24555.7
446.084	24493.5
449.613	24513.7
453.141	24487.1
456.666	24464.4
460.191	24530.5
463.715	24487.1
467.235	24463.4
470.756	24501.3
474.274	24478.8
477.793	24623.5
481.308	24513.8
484.823	24541.1
488.336	24608.8
491.847	24567.7
495.358	24613.8
498.867	24636.9
502.374	24713.5
505.881	24732.4
509.386	24684.8
512.888	24773.3
516.39	24808.6
519.89	24676.1
523.391	24669.1
526.889	24732.3
530.385	24650.4
533.88	24612
537.373	24630.4
540.866	24605.2
544.357	24675.4
547.846	24626
551.334	24606.9
554.821	24660.4
558.307	24662.1
561.789	24654.8
565.272	24697.9
568.753	24702.7
572.233	24718.6
575.712	24740.5
579.188	24699.1
582.664	24764.6
586.139	24716
589.611	24759.9
593.083	24733.6
596.554	24749
600.021	24658.6
603.49	24779.6
606.955	24819.6
610.42	24720
613.882	24705.4
617.345	24694.1
620.805	24702.7
624.263	24623.1
627.722	24627
631.178	24591.7
634.633	24680.8
638.088	24616.1
641.539	24737.6
644.99	24550.2
648.439	24540.8
651.887	24576.6
655.335	24621.2
658.781	24608
662.225	24599.2
665.667	24566.5
669.108	24668.4
672.548	24559
675.987	24604.9
679.424	24592.6
682.86	24535.8
686.293	24632.8
689.727	24600.1
693.159	24605.2
696.59	24584.9
700.019	24709
703.448	24633.1
706.872	24564.3
710.298	24590.2
713.723	24553.9
717.144	24513.9
720.565	24618.5
723.984	24578.6
727.403	24543.3
730.821	24569.6
734.235	24558
737.651	24571
741.063	24512.7
744.474	24551.8
747.885	24540
751.293	24564.8
754.702	24573.1
758.108	24631
761.512	24563.2
764.915	24739.1
768.319	24665.6
771.719	24656.4
775.118	24691.1
778.516	24678
781.913	24625.4
785.308	24619
788.702	24611.9
792.095	24567.9
795.486	24539.1
798.876	24619.9
802.265	24596.8
805.653	24580.2
809.039	24597.4
812.424	24459.1
815.808	24590.6
819.191	24562.9
822.572	24627.6
825.95	24625
829.329	24639.9
832.706	24722.8
836.08	24670.2
839.455	24603.2
842.829	24693.1
846.199	24814.6
849.57	24744.4
852.938	24793.8
856.307	24743.4
859.672	24828.5
863.038	24795.7
866.401	24781.4
869.765	24672.2
873.125	24761.3
876.484	24761.7
879.844	24691.4
883.2	24666.8
886.555	24620.1
889.909	24581.7
893.262	24552
896.616	24551.4
899.966	24397.8
903.315	24447.7
906.663	24333
910.009	24341.4
913.354	24288
916.698	24371.2
920.041	24295.1
923.383	24240.8
926.723	24145.3
930.062	24139.7
933.399	24168.2
936.734	24081.4
940.069	24231.1
943.403	24200.3
946.736	24244.3
950.065	24187.4
953.396	24201.6
956.725	24181.7
960.051	24224.1
963.377	24185.7
966.7	24189.9
970.025	24081.5
973.345	24210.8
976.667	24113.5
979.985	24140.4
983.304	24149.3
986.62	24182.9
989.935	24252.6
993.25	24189
996.563	24324.8
999.874	24374.1
1003.19	24311.8
1006.49	24205.4
1009.8	24171.6
1013.11	24141.5
1016.41	24152.8
1019.72	24105.5
1023.02	24075.6
1026.32	24064.5
1029.62	24068.5
1032.92	23965.8
1036.22	23975.5
1039.51	24036.4
1042.81	24002.2
1046.1	23928.2
1049.39	24012.8
1052.68	24017.3
1055.97	24100.1
1059.26	24050.6
1062.55	24108.1
1065.83	24044.6
1069.12	24187.2
1072.4	24194
1075.68	24154.6
1078.97	24176.5
1082.24	24081.7
1085.52	24025.2
1088.8	23943.7
1092.08	23827
1095.35	23778.2
1098.62	23707.1
1101.9	23639.1
1105.17	23656
1108.44	23621.5
1111.7	23735.9
1114.97	23784.2
1118.23	23733.7
1121.5	23743.3
1124.76	23667.9
1128.03	23597
1131.29	23486.5
1134.54	23439
1137.8	23418.1
1141.06	23467
1144.31	23607
1147.57	23715.1
1150.82	23947.3
1154.07	23991.6
1157.32	23730.2
1160.57	23498.4
1163.82	23312.5
1167.07	23298.9
1170.31	23219.6
1173.56	23107.1
1176.8	23159
1180.04	23113.5
1183.28	23075.7
1186.52	23124.3
1189.76	23166.3
1192.99	23024.3
1196.23	22957.8
1199.46	22943.7
1202.7	22954.7
1205.93	22976.6
1209.16	22950.5
1212.39	22944.4
1215.62	22806.1
1218.84	22902.1
1222.07	22878.3
1225.29	22832.3
1228.52	22877.3
1231.74	22910
1234.96	22892.5
1238.18	22818.3
1241.4	22966.4
1244.61	22983.6
1247.83	23009.8
1251.04	22973.2
1254.25	22993.7
1257.47	22962.7
1260.68	23019.8
1263.89	23001.2
1267.09	22929.4
1270.3	22803.7
1273.51	22837.8
1276.71	22780.9
1279.91	22793.8
1283.12	22797.9
1286.32	22766.4
1289.52	22895.4
1292.72	22965.8
1295.91	23045.2
1299.11	23067.7
1302.3	23011.2
1305.5	22950
1308.69	22853.5
1311.88	22719.7
1315.07	22592
1318.26	22488.7
1321.44	22391.4
1324.63	22347.8
1327.82	22381.9
1331	22412.9
1334.18	22397.3
1337.36	22351.1
1340.54	22393.5
1343.72	22263.8
1346.9	22274.3
1350.07	22216.7
1353.25	22148.8
1356.42	22081.8
1359.6	22096
1362.77	22066.6
1365.94	22024.5
1369.11	21980.8
1372.28	21905.1
1375.44	21756.7
1378.61	21816.1
1381.77	21795
1384.93	21626.6
1388.1	21717.4
1391.26	21663.2
1394.41	21726.6
1397.57	21639.1
1400.73	21654.4
1403.89	21694.8
1407.04	21675.2
1410.19	21735.5
1413.35	21710.6
1416.5	21789.6
1419.65	21877.9
1422.8	21848.3
1425.94	22013.4
1429.09	22309.6
1432.23	22628.3
1435.38	22741.4
1438.52	22743.1
1441.66	22607.8
1444.8	22473.7
1447.94	22471.7
1451.08	22291.2
1454.22	22151.7
1457.35	22110.8
1460.48	21926.9
1463.62	21723.8
1466.75	21502.3
1469.88	21433.1
1473.01	21232.1
1476.14	21131.3
1479.26	20988.4
1482.39	20934.3
1485.51	20973.3
1488.64	20972.3
1491.76	21001.1
1494.88	20993.6
1498	20937.9
1501.12	20954.6
1504.24	21000.6
1507.35	21102.3
1510.47	21163.6
1513.58	21269.8
1516.69	21308.7
1519.81	21354.2
1522.92	21241.5
1526.03	21097.2
1529.13	20915.9
1532.24	20712.3
1535.35	20650.7
1538.45	20562.6
1541.55	20542.1
1544.66	20554.5
1547.76	20508.8
1550.86	20480.9
1553.96	20391.9
1557.05	20391
1560.15	20307
1563.24	20359.9
1566.34	20413.5
1569.43	20399.4
1572.52	20354.5
1575.61	20295.2
1578.7	20288.1
1581.79	20294.1
1584.88	20262.3
1587.96	20212.6
1591.05	20241
1594.13	20253.8
1597.21	20230.6
1600.3	20266.1
1603.37	20237
1606.45	20175.5
1609.53	20228.6
1612.61	20096.2
1615.68	20027
1618.76	20039
1621.83	20049.1
1624.9	19982.5
1627.97	20080.4
1631.04	20053.8
1634.11	19988.1
1637.18	19993.5
1640.24	20116.7
1643.31	20121.1
1646.37	20242
1649.44	20335.1
1652.5	20337.1
1655.56	20266.9
1658.62	20046.5
1661.67	19959.5
1664.73	19926.3
1667.79	19791.8
1670.84	19730.1
1673.89	19698.1
1676.95	19544.5
1680	19465
1683.05	19419.4
1686.1	19379.5
1689.14	19308
1692.19	19221.4
1695.23	19218.2
1698.28	19125.9
1701.32	19010.9
1704.36	18966.8
1707.4	18982.6
1710.44	18936.3
1713.48	18979.8
1716.52	18836.5
1719.56	18810.7
1722.59	18878.7
1725.63	18784.6
1728.66	18808.4
1731.69	18850.3
1734.72	18869.3
1737.75	18901.3
1740.78	18899.6
1743.8	18743.1
1746.83	18750.2
1749.86	18744.9
1752.88	18643.9
1755.9	18531.2
1758.92	18448.1
1761.94	18408
1764.96	18349.7
1767.98	18375.8
1771	18338.5
1774.01	18320.3
1777.03	18309.8
1780.04	18350.5
1783.05	18244.2
1786.06	18274.9
1789.07	18230.7
1792.08	18226.8
1795.09	18214.8
1798.1	18159.7
1801.1	18136
1804.11	18048
1807.11	17985.9
1810.11	17992
1813.11	18030.9
1816.11	17979
1819.11	17902.6
1822.11	17911.6
1825.11	17836.6
1828.1	17896.3
1831.1	17814.6
1834.09	17815.5
1837.08	17763.5
1840.07	17763
1843.06	17746.3
1846.05	17725.2
1849.04	17706.4
1852.02	17603.1
1855.01	17628.6
1857.99	17546.7
1860.98	17552.7
1863.96	17530
1866.94	17513.5
1869.92	17467.1
1872.9	17466.5
1875.88	17496.9
1878.85	17425
1881.83	17410.9
1884.8	17313
1887.78	17223.4
1890.75	17279.9
1893.72	17223.2
1896.69	17218.2
1899.66	17178.1
1902.63	17031.3
1905.59	16958.6
1908.56	16930.2
1911.52	16806.3
1914.49	16778.7
1917.45	16651.7
1920.41	16593.2
1923.37	16535.4
1926.33	16498.6
1929.29	16426.1
1932.24	16357.9
1935.2	16306
1938.15	16220.9
1941.1	16143.4
1944.06	16131.9
1947.01	16042.2
1949.96	15984
1952.91	15822.9
1955.86	15777.9
1958.8	15689
1961.75	15626.1
1964.69	15627.9
1967.64	15519.9
1970.58	15452.6
1973.52	15395.1
1976.46	15329.8
1979.4	15305.2
1982.34	15253.2
1985.27	15202.7
1988.21	15128.5
1991.14	15073.9
1994.08	14984.9
1997.01	14906.7
1999.94	14832.9
2002.87	14769.1
2005.8	14772.3
2008.73	14723.7
2011.66	14666.8
2014.58	14620.5
2017.51	14567
2020.43	14467.4
2023.36	14437.8
2026.28	14385
2029.2	14359
2032.12	14319.6
2035.04	14269.7
2037.95	14247
2040.87	14212.5
2043.78	14175.3
2045.76	14129.5
2048.69	14075.3
2051.61	14070.9
2054.54	14024.7
2057.46	14029.4
2060.38	14041.8
2063.3	13979.1
2066.22	14005.6
2069.14	13956.2
2072.06	13932.9
2074.98	13919.9
2077.89	13914.2
2080.81	13906.2
2083.72	13896
2086.63	13899.1
2089.55	13754.3
2092.46	13867.4
2095.37	13764.6
2098.28	13737.1
2101.18	13774.2
2104.09	13772.2
2106.99	13657.3
2109.9	13674.3
2112.8	13644.5
2115.71	13625.9
2118.61	13605
2121.51	13609
2124.4	13602.3
2127.3	13595.9
2130.2	13554.6
2133.09	13551.3
2135.99	13545.2
2138.88	13612.7
2141.78	13474.2
2144.67	13488.7
2147.56	13521
2150.45	13506.1
2153.34	13399.1
2156.22	13441.6
2159.11	13438.2
2162	13415.9
2164.88	13426.4
2167.76	13415.5
2170.64	13392.2
2173.53	13405
2176.41	13346.2
2179.29	13306.8
2182.16	13302.4
2185.04	13250.2
2187.92	13273.2
2190.79	13287.4
2193.66	13249.3
2196.54	13266.9
2199.41	13214.1
2202.28	13231
2205.15	13169.5
2208.02	13170.9
2210.88	13085.4
2213.75	13085.2
2216.62	13071
2219.48	13049.3
2222.34	13000.1
2225.21	12963.8
2228.07	12947.6
2230.93	12954
2233.79	12968.7
2236.65	12912
2239.5	12886.3
2242.36	12868.9
2245.21	12820
2248.07	12812.1
2250.92	12732
2253.77	12693.7
2256.62	12684.5
2259.47	12678.1
2262.32	12578
2265.17	12610.1
2268.02	12530.4
2270.86	12488.8
2273.71	12510.7
2276.55	12502.8
2279.39	12510.6
2282.24	12448.5
2285.08	12398.8
2287.92	12390.2
2290.75	12368.1
2293.59	12362.7
2296.43	12301.7
2299.26	12286.3
2302.1	12272.5
2304.93	12220.8
2307.76	12171.7
2310.6	12159.2
2313.43	12179.9
2316.25	12110
2319.08	12102.6
2321.91	12120.5
2324.74	12259.2
2327.56	12402.6
2330.39	12053.3
2333.21	11961.1
2336.03	11935.4
2338.85	11997.2
2341.67	11951
2344.49	11915.7
2347.31	11879.7
2350.13	11854.2
2352.94	11855.1
2355.76	11811.3
2358.57	11718.4
2361.39	11760
2364.2	11717.2
2367.01	11700.7
2369.82	11689.7
2372.63	11648.3
2375.44	11611.1
2378.24	11584.4
2381.05	11581.7
2383.85	11600.6
2386.66	11530.9
2389.46	11582.1
2392.26	11541.9
2395.06	11534.9
2397.86	11507.3
2400.66	11425.8
2403.46	11464.1
2406.26	11424.8
2409.05	11355.3
2411.85	11414.2
2414.64	11401.4
2417.43	11334.3
2420.23	11313.1
2423.02	11317.4
2425.81	11333.1
2428.6	11265.4
2431.38	11250.9
2434.17	11287.6
2436.96	11217.6
2439.74	11214.3
2442.53	11198.2
2445.31	11197.1
2448.09	11127
2450.87	11156.2
2453.65	11111.9
2456.43	11096.3
2459.21	11072.4
2461.98	11037.5
2464.76	10989.1
2467.53	11032.9
2470.31	11000.4
2473.08	10995.6
2475.85	10973.1
2478.63	10955.8
2481.39	10950.2
2484.16	10911.9
2486.93	10919.8
2489.7	10853.9
2492.46	10864.9
2495.23	10855.6
2497.99	10858.2
2500.76	10822.2
2503.52	10782.3
2506.28	10772.6
2509.04	10742.2
2511.8	10715.3
2514.56	10697.7
2517.31	10745.6
2520.07	10681.9
2522.82	10639.7
2525.58	10677.6
2528.33	10680.2
2531.09	10608.1
2533.84	10658.5
2536.59	10616.1
2539.34	10597.6
2542.08	10561.5
2544.83	10552.6
2547.58	10532.6
2550.32	10520.5
2553.07	10488.9
2555.81	10489.1
2558.55	10513.5
2561.29	10470.1
2564.03	10413.5
2566.77	10435.1
2569.51	10427.7
2572.25	10402.4
2574.99	10377.4
2577.72	10392.3
2580.46	10390.6
2583.19	10370.5
2585.92	10332.2
2588.65	10342.4
2591.38	10362.1
2594.11	10329
2596.84	10339.2
2599.57	10259.3
2602.3	10294.7
2605.02	10274.1
2607.75	10303.9
2610.47	10291.2
2613.19	10277.3
2615.92	10209.6
2618.64	10227.3
2621.36	10192.8
2624.08	10160.7
2626.8	10213.3
2629.51	10192
2632.23	10139.5
2634.94	10121.2
2637.66	10163.2
2640.37	10144.8
2643.08	10116.6
2645.79	10111.3
2648.5	10075.3
2651.21	10105.6
2653.92	10071.7
2656.63	10017.3
2659.33	10030.3
2662.04	10072.3
2664.75	10062.1
2667.45	10083.1
2670.15	10003.3
2672.85	9992.94
2675.55	9974.46
2678.25	10022.7
2680.95	9973.08
2683.65	9933.33
2686.35	9976.63
2689.04	9923.07
2691.74	9907.29
2694.43	9897.41
2697.13	9897.32
2699.82	9921.26
2702.51	9976.73
2705.2	9914.78
2707.89	9897.73
2710.58	9902.09
2713.26	9884.27
2715.95	9868.96
2718.64	9887.06
2721.32	9852.26
2724	9831.59
2726.69	9837.2
2729.37	9814.45
2732.05	9823.04
2734.73	9773.75
2737.41	9742.97
2740.09	9681.23
2742.76	9713.05
2745.44	9687.88
2748.11	9650.64
2750.79	9647.77
2753.46	9638.29
2756.13	9626.86
2758.81	9607.68
2761.47	9586.39
2764.14	9551.54
2766.81	9567.98
2769.48	9577.56
2772.15	9536.26
2774.81	9508.21
2777.48	9477.22
2780.14	9481.75
2782.8	9473.58
2785.47	9425.04
2788.13	9393.52
2790.79	9386.31
2793.44	9444.3
2796.1	9440.14
2798.76	9440.97
2801.42	9379.22
2804.07	9442.62
2806.73	9343
2809.38	9373.98
2812.03	9394.81
2814.68	9372.76
2817.33	9387.95
2819.98	9377.68
2822.63	9391.07
2825.28	9406.11
2827.93	9464.72
2830.57	9509
2833.22	9554
2835.86	9620.19
2838.51	9788.99
2841.15	10065.1
2843.79	10419.1
2846.43	10707.7
2849.07	10872.4
2851.71	10821.6
2854.35	10767.8
2856.98	10652.8
2859.62	10526.1
2862.25	10442.9
2864.89	10499.7
2867.52	10503.5
2870.15	10601.1
2872.78	10632
2875.41	10661.4
2878.04	10707.9
2880.67	10739.7
2883.3	10762.1
2885.92	10850.7
2888.55	10849.7
2891.18	10892.2
2893.8	10906
2896.42	10866.2
2899.04	10869.9
2901.67	10847.6
2904.29	10825.8
2906.9	10798.9
2909.52	10783
2912.14	10786.5
2914.76	10768.5
2917.37	10736.2
2919.99	10739
2922.6	10756.1
2925.21	10765.8
2927.82	10726.8
2930.44	10770.5
2933.05	10699.7
2935.65	10655.4
2938.26	10565.1
2940.87	10398.1
2943.48	10202.8
2946.08	10055.9
2948.69	9966.37
2951.29	9861.78
2953.89	9825.64
2956.49	9720.84
2959.1	9712.05
2961.7	9656.05
2964.29	9555.15
2966.89	9523.92
2969.49	9464.97
2972.09	9424.59
2974.68	9277.16
2977.28	9245.27
2979.87	9286.51
2982.46	9148.1
2985.05	9172.22
2987.65	9073.9
2990.24	9041.56
2992.82	8956.37
2995.41	8958.48
2998	8938.19
3000.59	8979.08
3003.17	8889.64
3005.76	8894.45
3008.34	8853.62
3010.92	8860.48
3013.5	8773.51
3016.09	8833.4
3018.67	8751.88
3021.25	8742.65
3023.82	8738.89
3026.4	8713.52
3028.98	8685.69
3031.55	8677.5
3034.13	8630.93
3036.7	8647.69
3039.28	8657.4
3041.85	8677.58
3044.42	8687.36
3046.99	8640.42
3049.56	8687.47
3052.13	8678
3054.69	8697.19
3057.26	8642.65
3059.83	8719.5
3062.39	8697.38
3064.95	8700.49
3067.52	8713.68
3070.08	8674.14
3072.64	8659.02
3075.2	8679.67
3077.76	8674.62
3080.32	8681.75
3082.88	8685.39
3085.44	8707.73
3087.99	8715.96
3090.55	8683.53
3093.1	8735.86
3095.65	8737.38
3098.21	8745.91
3100.76	8728.59
3103.31	8755.13
3105.86	8780
3108.41	8798.33
3110.96	8847.55
3113.5	8852.31
3116.05	8862.39
3118.59	8888.98
3121.14	8945.92
3123.68	8901.42
3126.23	8965.72
3128.77	8972.2
3131.31	9027.51
3133.85	8991.26
3136.39	9076.2
3138.93	9091.02
3141.46	9109.09
3144	9109.43
3146.54	9142.52
3149.07	9226.99
3151.6	9204.27
3154.14	9198.58
3156.67	9256.96
3159.2	9243.25
3161.73	9248.4
3164.26	9267.19
3166.79	9234.63
3169.32	9247.79
3171.84	9266.71
3174.37	9170.05
3176.9	9175.83
3179.42	9163.5
3181.94	9108.39
3184.47	9137.57
3186.99	9071.64
3189.51	9077.98
3192.03	9013.81
3194.55	9003.54
3197.07	8978.66
3199.58	8950.87
3202.1	8926.35
3204.62	8899.1
3207.13	8901.35
3209.65	8868.63
3212.16	8822.91
3214.67	8743.83
3217.18	8736.86
3219.69	8728.19
3222.2	8693.91
3224.71	8673.38
3227.22	8619.03
3229.73	8630.25
3232.23	8580.27
3234.74	8513.94
3237.24	8511.19
3239.75	8453.08
3242.25	8431.82
3244.75	8404.99
3247.25	8390.96
3249.75	8345.08
3252.25	8321.46
3254.75	8262.32
3257.25	8236.66
3259.74	8206.65
3262.24	8175.13
3264.73	8120.11
3267.23	8095.43
3269.72	8089.71
3272.21	8081.75
3274.7	8067.78
3277.2	8028.62
3279.69	7971.7
3282.17	7949.48
3284.66	7918.2
3287.15	7921.65
3289.64	7888.45
3292.12	7867.02
3293.56	7843.82
3296.05	7854.68
3298.55	7820.88
3301.04	7801.45
3303.54	7770.16
3306.03	7794.95
3308.52	7762.7
3311.01	7736.02
3313.5	7696.69
3315.99	7716.34
3318.48	7696.32
3320.97	7673.85
3323.45	7705.52
3325.94	7649.46
3328.42	7644.08
3330.91	7602.1
3333.39	7622.55
3335.87	7625.06
3338.36	7594.31
3340.84	7543.07
3343.32	7537.87
3345.8	7549.6
3348.27	7557.05
3350.75	7497.49
3353.23	7498.62
3355.7	7510.51
3358.18	7471.74
3360.65	7450.66
3363.13	7444.96
3365.6	7421.24
3368.07	7415.45
3370.54	7420.6
3373.01	7423.04
3375.48	7376.81
3377.95	7356.93
3380.42	7333.6
3382.88	7362.29
3385.35	7322.34
3387.81	7317.78
3390.28	7301.38
3392.74	7305.91
3395.2	7289
3397.67	7302.82
3400.13	7227.8
3402.58	7215.72
3405.05	7206.38
3407.5	7184.11
3409.96	7146.74
3412.42	7118.08
3414.87	7143.82
3417.33	7102.77
3419.78	7081.62
3422.23	7060.86
3424.69	6983.47
3427.14	6938.19
3429.59	6954.22
3432.04	6946.89
3434.49	6942.96
3436.94	6903.59
3439.39	6839.02
3441.83	6821.25
3444.28	6759.09
3446.72	6732.08
3449.17	6708.92
3451.61	6668.27
3454.05	6643.42
3456.5	6615.95
3458.94	6596.05
3461.38	6546.93
3463.81	6514.5
3466.25	6484.5
3468.69	6470.85
3471.13	6373.14
3473.56	6344.41
3476	6307.21
3478.43	6235.32
3480.87	6212.58
3483.3	6152.46
3485.73	6139.13
3488.16	6072.55
3490.59	6016.94
3493.02	5997.83
3495.45	5942.08
3497.88	5890.53
3499.09	5889.33