File: src/Milk_AI/Heritage full cream RT 532nm 50% 600g 50xL 10s 10times 400-3500cm-1 100hole after heating.txt
#Acq. time (s)=	10
#Accumulations=	10
#Range (cm-¹)=	400...3500
#Windows=	3
#Auto scanning=	Off
#Autofocus=	Off
#AutoExposure=	Off
#Spike filter=	Multiple accum.
#Delay time (s)=	0
#Binning=	1
#Readout mode=	Signal
#DeNoise=	Off
#ICS correction=	On
#Dark correction=	Off
#Inst. Process=	Off
#Detector Gain=	Best Dynamic Range
#Detector ADC=	45 kHz
#Detector temperature (°C)=	-60.1
#Instrument=	LabRAM HR Evol
#Detector=	Syncerity OE
#Objective=	x50_VIS_LWD
#Grating=	600 (500nm)
#ND Filter=	50%
#Laser=	532nm_Edge
#Hole=	199.981
#Range=	Visible
#E-Cal_Neon=	0
#StageXY=	75x50mm Scan+
#StageZ=	Z motor
#X (µm)=	0
#Y (µm)=	0
#Z (µm)=	855.9
#Spectral res.(cm-¹)=	12.8
#Full time(mm:ss)=	5:19
#AC=	Calibrated 2025-06-30 10:26
#Project=
#Sample=
#Site=
#Title=	D_99
#Remark=
#Date=	30.06.2025 13:50 (India Standard Time)
#Acquired=	30.06.2025 13:50:43 (India Standard Time)
#AxisType[0]=Intens
#AxisUnit[0]=Cnt
#AxisType[1]=Spectr
#AxisUnit[1]=1/cm
400.17	20917.1
403.717	20710.4
407.263	20786.7
410.807	20821.6
414.35	20753.3
417.892	20846.9
421.432	20876.2
424.971	20805.3
428.509	20828.4
432.045	20805
435.58	20830.3
439.111	20852.5
442.643	20816.4
446.174	20753.3
449.701	20704.5
453.229	20723.9
456.756	20729.9
460.279	20709.2
463.803	20669.9
467.326	20585.9
470.845	20599
474.365	20697.8
477.882	20643.4
481.399	20646.9
484.913	20591.9
488.425	20631.1
491.938	20595.1
495.448	20609.9
498.956	20670.4
502.465	20689.7
505.971	20718.6
509.475	20706.1
512.981	20736.1
516.482	20703.9
519.983	20695.6
523.482	20637
526.979	20579.7
530.476	20603
533.971	20540.7
537.464	20537.7
540.956	20537.9
544.447	20464.8
547.937	20461.2
551.425	20504
554.912	20445.5
558.398	20462
561.882	20459.7
565.365	20417
568.847	20488.3
572.325	20479.1
575.804	20482.2
579.282	20454.1
582.756	20426.1
586.231	20544.5
589.705	20467.3
593.175	20440
596.646	20528.2
600.116	20436.2
603.582	20471.3
607.049	20481.9
610.513	20434
613.977	20404.3
617.438	20358.7
620.898	20376.8
624.359	20285.5
627.816	20202.5
631.272	20176
634.728	20202.6
638.181	20142.3
641.633	20222.8
645.084	20088.5
648.535	20064.8
651.983	20117.5
655.43	20080.4
658.875	20137.3
662.319	20017.5
665.762	20061.7
669.203	20122.1
672.643	20033.4
676.082	19991.5
679.519	20014.9
682.955	20041.4
686.39	20080.1
689.824	20055.1
693.256	20088
696.685	20081
700.115	20116.6
703.543	20120.2
706.97	20042.9
710.394	19971.5
713.818	19969.3
717.241	19963.7
720.661	20019.3
724.082	19993.9
727.501	19886.9
730.917	19871
734.334	19891.7
737.747	19926.8
741.161	19866.2
744.572	19844.5
747.982	19855.4
751.392	19837.3
754.799	19886.7
758.205	19941.7
761.611	19929.7
765.014	19888.2
768.416	19969
771.816	19858.5
775.218	19879
778.616	19947.1
782.012	19928.4
785.408	19933.9
788.802	19984.6
792.195	19873.2
795.586	19867.9
798.977	19911.3
802.365	19888.2
805.753	19867.2
809.14	19839.6
812.525	19824.9
815.907	19808.3
819.289	19752
822.671	19905.9
826.051	19896.6
829.43	19874.4
832.805	19882.3
836.182	19877
839.557	19864.8
842.928	19933
846.301	19942.7
849.67	19918.3
853.04	19939.6
856.407	19990.9
859.774	20044.5
863.138	19973.8
866.503	19957.1
869.865	19951
873.225	19993.8
876.586	19946.4
879.944	19931.1
883.301	19835.4
886.658	19849
890.012	19820.4
893.365	19868
896.717	19767
900.067	19650.9
903.416	19673.6
906.766	19576.5
910.112	19489.9
913.458	19539.3
916.802	19515
920.145	19428.8
923.484	19441.5
926.825	19337.7
930.164	19349.6
933.501	19243.4
936.838	19195.3
940.173	19338.3
943.505	19329.2
946.838	19314.7
950.17	19286.5
953.5	19245.9
956.827	19264
960.155	19311
963.48	19377.8
966.805	19283.1
970.128	19274.5
973.45	19254.2
976.77	19146.5
980.091	19242.3
983.408	19245.1
986.726	19303.6
990.041	19325.9
993.354	19358.4
996.668	19416.6
999.979	19684.4
1003.29	19876.6
1006.6	19768.8
1009.91	19470.7
1013.21	19423
1016.52	19403.2
1019.82	19336.3
1023.12	19257.9
1026.43	19192.8
1029.73	19170.6
1033.02	19107.2
1036.32	19113.6
1039.62	19041.7
1042.91	19034.4
1046.21	18986.2
1049.5	18983
1052.79	19032.4
1056.08	19057.6
1059.37	19084.6
1062.65	19229.7
1065.94	19167.7
1069.23	19104
1072.51	19257.7
1075.79	19147.2
1079.07	19290.2
1082.35	19201.2
1085.63	19124.7
1088.91	19072.8
1092.18	19042
1095.46	18844.8
1098.73	18753.7
1102	18729.2
1105.27	18647.1
1108.54	18660.9
1111.81	18663.2
1115.08	18725.6
1118.34	18815
1121.61	18860.1
1124.87	18857.3
1128.13	18798.3
1131.39	18678.3
1134.65	18573.3
1137.91	18551.2
1141.17	18645.7
1144.42	18769.2
1147.68	18979.9
1150.93	19484
1154.18	20038.1
1157.43	20180.7
1160.68	19684.4
1163.93	18972.6
1167.18	18557.2
1170.42	18468.2
1173.67	18356.6
1176.91	18250.1
1180.15	18219
1183.39	18286.5
1186.63	18269.8
1189.87	18213.9
1193.11	18236
1196.34	18236.2
1199.58	18095.5
1202.81	17953.5
1206.04	17983.3
1209.27	18029
1212.5	17981.9
1215.73	17844
1218.95	17868.5
1222.18	17747.4
1225.4	17773
1228.63	17826.3
1231.85	17826.1
1235.07	17799.8
1238.29	17781.4
1241.51	17825.5
1244.72	17887.7
1247.94	17896.5
1251.15	17906.3
1254.37	17876.6
1257.58	17944.1
1260.79	17938.3
1264	17998.1
1267.21	17967.8
1270.41	17912
1273.62	17833.3
1276.82	17854.3
1280.03	17743.1
1283.23	17748.8
1286.43	17678.4
1289.63	17741
1292.83	17907.7
1296.03	18019.1
1299.22	18229.6
1302.42	18271.2
1305.61	18186.8
1308.8	18042.1
1311.99	17933.9
1315.18	17700.6
1318.37	17553.7
1321.56	17457.5
1324.74	17407
1327.93	17343.2
1331.11	17355.6
1334.3	17257.1
1337.48	17262.1
1340.66	17266.1
1343.84	17184.7
1347.01	17162.4
1350.19	17157.8
1353.37	17120.5
1356.54	16984
1359.71	16954.4
1362.88	16962.4
1366.05	16952.4
1369.22	16921.2
1372.39	16872.9
1375.56	16699.5
1378.72	16736.7
1381.89	16642.7
1385.05	16600.8
1388.21	16599.2
1391.37	16634.9
1394.53	16593.4
1397.69	16507.8
1400.85	16535.9
1404	16477.9
1407.16	16514.3
1410.31	16500.7
1413.46	16580.9
1416.61	16619
1419.76	16638.7
1422.91	16705.9
1426.06	16757.1
1429.21	17076.3
1432.35	17485.4
1435.49	17810.9
1438.64	18076.1
1441.78	18037.9
1444.92	17891.8
1448.06	17806.2
1451.2	17679.2
1454.33	17539.6
1457.47	17471.7
1460.6	17318.6
1463.74	17092.4
1466.87	16854.7
1470	16626.3
1473.13	16427.5
1476.26	16290.8
1479.38	16161.2
1482.51	16070.9
1485.63	16006.5
1488.76	15937.8
1491.88	15988.1
1495	16032.8
1498.12	16049.7
1501.24	16052.9
1504.36	16225.4
1507.47	16277.3
1510.59	16629.2
1513.7	16942.3
1516.81	17269.3
1519.93	17521.2
1523.04	17487.5
1526.15	17308.5
1529.25	16815.1
1532.36	16302.3
1535.47	15904.1
1538.57	15679.4
1541.67	15607.8
1544.78	15463.3
1547.88	15411
1550.98	15355.7
1554.08	15362.5
1557.18	15365.5
1560.27	15252.9
1563.37	15267
1566.46	15294.1
1569.55	15244.1
1572.64	15213.2
1575.74	15167.1
1578.83	15155.2
1581.91	15150.1
1585	15166.7
1588.09	15127.8
1591.17	15111.1
1594.25	15102
1597.34	15116.9
1600.42	15128.3
1603.5	15099.3
1606.58	15069.6
1609.65	14974.8
1612.73	14903.3
1615.8	14924.3
1618.88	14911.1
1621.95	14852.4
1625.03	14849
1628.1	14862.4
1631.17	14894.2
1634.23	14834
1637.3	14920.1
1640.37	14956.8
1643.43	14926.9
1646.5	15057.2
1649.56	15233.9
1652.62	15454.6
1655.68	15380.7
1658.74	15169.6
1661.8	14966.2
1664.85	14841.7
1667.91	14780.5
1670.96	14741.5
1674.02	14645.7
1677.07	14605.1
1680.12	14432
1683.17	14393.1
1686.22	14319.3
1689.27	14260.9
1692.31	14231.9
1695.36	14175.9
1698.4	14134.8
1701.45	14064.5
1704.49	14003.7
1707.53	13984.3
1710.57	13942.6
1713.61	13937.4
1716.65	13866.6
1719.68	13885.2
1722.72	13856.7
1725.75	13912.4
1728.78	13813.8
1731.82	13848.2
1734.84	13896.5
1737.87	13886.4
1740.9	13930.6
1743.93	13936.7
1746.96	13974.5
1749.98	13899.6
1753	13825.7
1756.03	13702.6
1759.05	13656.1
1762.07	13571.5
1765.09	13474.7
1768.11	13428.3
1771.12	13467.8
1774.14	13445.1
1777.15	13392.3
1780.17	13393.4
1783.18	13299.6
1786.19	13338.7
1789.2	13350.5
1792.21	13238.7
1795.22	13283.8
1798.22	13235.9
1801.23	13189.6
1804.23	13161.7
1807.24	13204
1810.24	13168.9
1813.24	13110.6
1816.24	13096.5
1819.24	13089.3
1822.24	13025.6
1825.23	13048.1
1828.23	13004.2
1831.22	13001.9
1834.22	12992.6
1837.21	12975.8
1840.2	12951.7
1843.19	12960.6
1846.18	12973.1
1849.17	12882.8
1852.15	12835.3
1855.14	12812.8
1858.12	12815.3
1861.11	12776.6
1864.09	12748.9
1867.07	12747.4
1870.05	12744.4
1873.03	12676.6
1876.01	12652.6
1878.98	12688.7
1881.96	12639
1884.93	12576.4
1887.91	12559.6
1890.88	12563.3
1893.85	12503.5
1896.82	12492.5
1899.79	12453
1902.76	12383.6
1905.72	12367.9
1908.69	12334
1911.65	12253.6
1914.62	12212.9
1917.58	12121.1
1920.54	12092.8
1923.5	12050.1
1926.46	11988
1929.42	11966.6
1932.37	11915.9
1935.33	11853.4
1938.28	11796.7
1941.24	11736.3
1944.19	11727.8
1947.14	11697.6
1950.09	11633.7
1953.04	11586.1
1955.99	11471.5
1958.93	11436.4
1961.88	11433.5
1964.82	11375.9
1967.77	11317.3
1970.71	11305.2
1973.65	11237.7
1976.59	11236.2
1979.53	11187.6
1982.47	11118.4
1985.41	11110.3
1988.34	11053.1
1991.28	10994.4
1994.21	10966.7
1997.14	10901.6
2000.07	10863.8
2003.01	10848.7
2005.94	10809.9
2008.86	10795
2011.79	10741.3
2014.72	10735.5
2017.64	10703.3
2020.57	10657.5
2023.49	10594.2
2026.41	10568.8
2029.33	10541
2032.25	10518.1
2035.17	10530.1
2038.09	10455.6
2041	10434
2043.92	10399.7
2045.86	10380.5
2048.79	10414.5
2051.71	10376.2
2054.64	10375.7
2057.56	10361
2060.48	10309.6
2063.4	10308.1
2066.32	10321.2
2069.24	10295.1
2072.16	10325
2075.08	10270
2077.99	10261.2
2080.91	10222.5
2083.82	10222.9
2086.74	10176.7
2089.65	10213.6
2092.56	10192.5
2095.47	10150.1
2098.38	10181.5
2101.29	10118.2
2104.19	10116.6
2107.1	10107.3
2110	10067.9
2112.91	10043.3
2115.81	10056
2118.71	10030.5
2121.61	10022.1
2124.51	10015.8
2127.4	9929.71
2130.3	9966.6
2133.2	9931.57
2136.09	9925.62
2138.99	9949.47
2141.88	9909.16
2144.77	9896.21
2147.66	9888.07
2150.55	9886.38
2153.44	9816.67
2156.33	9866.04
2159.21	9883.64
2162.1	9837.41
2164.98	9878.25
2167.87	9810.88
2170.75	9804.82
2173.63	9796.61
2176.51	9816.57
2179.39	9796.99
2182.27	9795.86
2185.14	9740.29
2188.02	9688.67
2190.9	9698.95
2193.77	9668.73
2196.64	9717.91
2199.51	9665.55
2202.39	9659.06
2205.25	9641.82
2208.12	9630.51
2210.99	9583.71
2213.86	9596.72
2216.72	9544.49
2219.59	9563.93
2222.45	9536.92
2225.31	9442.21
2228.17	9505.21
2231.03	9473.69
2233.89	9435.28
2236.75	9415.53
2239.61	9427.19
2242.46	9457.74
2245.32	9421.54
2248.17	9356.93
2251.03	9364.85
2253.88	9309.02
2256.73	9272.03
2259.58	9291.88
2262.43	9248.7
2265.28	9173.44
2268.12	9171.14
2270.97	9162.68
2273.81	9131.59
2276.66	9112.34
2279.5	9107.01
2282.34	9077.81
2285.18	9058.69
2288.02	9077.25
2290.86	9006.86
2293.7	9033.77
2296.54	9029.97
2299.37	8944.44
2302.21	8923.76
2305.04	8906.86
2307.87	8883.8
2310.7	8875.65
2313.53	8847.6
2316.36	8814.03
2319.19	8822.64
2322.02	8786.04
2324.85	8796.58
2327.67	8957.77
2330.5	9039.53
2333.32	8810.07
2336.14	8686.52
2338.96	8743.28
2341.78	8659.6
2344.6	8637.14
2347.42	8651.68
2350.24	8627.28
2353.05	8571.42
2355.87	8572.8
2358.68	8526.99
2361.5	8536.13
2364.31	8478.33
2367.12	8490.46
2369.93	8490.41
2372.74	8470.53
2375.55	8432.2
2378.35	8464.09
2381.16	8418.83
2383.96	8401.56
2386.77	8388.97
2389.57	8371
2392.37	8372.84
2395.17	8303
2397.97	8354.83
2400.77	8339.19
2403.57	8289.2
2406.37	8225.01
2409.16	8254.49
2411.96	8263.17
2414.75	8219.8
2417.55	8227.78
2420.34	8181.18
2423.13	8192.01
2425.92	8203.58
2428.71	8141.1
2431.5	8210.34
2434.28	8164.43
2437.07	8124.89
2439.85	8108.33
2442.64	8091.55
2445.42	8113.15
2448.2	8070.94
2450.98	8087.97
2453.76	8040.8
2456.54	8064.46
2459.32	8031.94
2462.1	8007.13
2464.87	8027.36
2467.65	7950.4
2470.42	7996.35
2473.2	7967.17
2475.97	7953.8
2478.74	7953.49
2481.51	7936.31
2484.28	7877.17
2487.05	7871.02
2489.81	7855.72
2492.58	7869.8
2495.34	7837.61
2498.11	7845.07
2500.87	7838
2503.63	7831.52
2506.39	7816.78
2509.15	7740.51
2511.91	7771.45
2514.67	7714.32
2517.43	7724.82
2520.19	7756.39
2522.94	7725.23
2525.7	7722.75
2528.45	7721.76
2531.2	7720.33
2533.95	7674.65
2536.7	7685.3
2539.45	7633.66
2542.2	7644.02
2544.95	7658.25
2547.69	7618.09
2550.44	7608.87
2553.18	7583.25
2555.93	7560.37
2558.67	7545.5
2561.41	7555.35
2564.15	7527.23
2566.89	7545.65
2569.63	7541.41
2572.36	7557.59
2575.1	7467.14
2577.84	7493.86
2580.57	7487.52
2583.31	7523.93
2586.04	7474.42
2588.77	7519.17
2591.5	7499.15
2594.23	7512.76
2596.96	7477.74
2599.69	7453.44
2602.41	7456.54
2605.14	7415.13
2607.86	7443.62
2610.59	7449.35
2613.31	7399.76
2616.03	7386
2618.75	7368.48
2621.48	7424.82
2624.19	7368.58
2626.91	7389.98
2629.63	7360.95
2632.35	7367.09
2635.06	7336.21
2637.77	7378.4
2640.49	7319.04
2643.2	7348.09
2645.91	7346.15
2648.62	7359.28
2651.33	7307.98
2654.04	7334.85
2656.75	7308.05
2659.45	7272.06
2662.16	7322.31
2664.86	7327.04
2667.57	7341.54
2670.27	7335.84
2672.97	7310.45
2675.67	7291.91
2678.37	7315.06
2681.07	7307.78
2683.77	7280.17
2686.47	7268.38
2689.16	7266.4
2691.86	7269.34
2694.55	7249.41
2697.25	7231.07
2699.94	7272.81
2702.63	7280.43
2705.32	7276.35
2708.01	7263.72
2710.7	7317.6
2713.39	7287.08
2716.07	7292.89
2718.76	7297.46
2721.44	7265.38
2724.12	7266.96
2726.81	7250.55
2729.49	7259.57
2732.17	7249.53
2734.85	7212.73
2737.53	7183.79
2740.21	7146.99
2742.88	7132.31
2745.56	7117.82
2748.24	7083.95
2750.91	7058.87
2753.58	7029.95
2756.25	7006.82
2758.93	7038.39
2761.6	6996.2
2764.27	7030.69
2766.93	6986.25
2769.6	7002.69
2772.27	6970.37
2774.93	6978.53
2777.6	6958.97
2780.26	6935.87
2782.93	6916.56
2785.59	6908.23
2788.25	6920.24
2790.91	6903.09
2793.57	6943.03
2796.23	6913.1
2798.88	6917.31
2801.54	6857.25
2804.2	6898.65
2806.85	6882.83
2809.5	6910.08
2812.16	6896.68
2814.81	6929.28
2817.46	6926.18
2820.11	6957.24
2822.76	6965.23
2825.4	7000.13
2828.05	7052.87
2830.7	7099.04
2833.34	7184.82
2835.99	7362.41
2838.63	7497.52
2841.27	7807.32
2843.91	8309.86
2846.55	9053.39
2849.19	9647.85
2851.83	9949.53
2854.47	9969.06
2857.11	9717.77
2859.74	9572.84
2862.38	9384.77
2865.01	9211.17
2867.65	9213.23
2870.28	9296.02
2872.91	9386.83
2875.54	9470.5
2878.17	9490.86
2880.8	9611.05
2883.42	9718.41
2886.05	9827.56
2888.68	9924.84
2891.3	9982.08
2893.93	9959.86
2896.55	10002.7
2899.17	9934.07
2901.79	9952.01
2904.41	9914.2
2907.03	9862.84
2909.65	9825.36
2912.27	9809.19
2914.88	9799.47
2917.5	9793.75
2920.11	9749.28
2922.73	9762.37
2925.34	9768.47
2927.95	9730.39
2930.56	9793.15
2933.17	9752.54
2935.78	9719.82
2938.39	9554.57
2941	9365.46
2943.6	9078.34
2946.21	8762.25
2948.81	8513.07
2951.42	8375.22
2954.02	8273.84
2956.62	8235.38
2959.22	8114.65
2961.82	8106.21
2964.42	7968.19
2967.02	7854.13
2969.62	7758.01
2972.21	7625.06
2974.81	7527.89
2977.4	7422.8
2980	7368.13
2982.59	7258.7
2985.18	7242.36
2987.77	7150.18
2990.36	7125.3
2992.95	7059.59
2995.54	7065.76
2998.13	6986.7
3000.72	6996.41
3003.3	7015.37
3005.89	6965.93
3008.47	6990.77
3011.05	6914.36
3013.63	6854.68
3016.22	6841.32
3018.8	6764.44
3021.38	6789.8
3023.95	6737.95
3026.53	6730.01
3029.11	6666.92
3031.68	6692.79
3034.26	6666.89
3036.83	6643.78
3039.4	6665.89
3041.98	6675.21
3044.55	6660.28
3047.12	6642.54
3049.69	6685.63
3052.26	6682.98
3054.82	6682.39
3057.39	6708.84
3059.96	6698.09
3062.52	6691.06
3065.09	6700.69
3067.65	6708.18
3070.21	6684.99
3072.77	6715.7
3075.33	6717.74
3077.89	6716.94
3080.45	6715.3
3083.01	6716.43
3085.57	6714.72
3088.12	6721.49
3090.68	6731.11
3093.23	6721.17
3095.79	6707.86
3098.34	6748.09
3100.89	6733.91
3103.44	6757.58
3105.99	6796.67
3108.54	6831.19
3111.09	6833.97
3113.63	6828.17
3116.18	6876.44
3118.73	6859.6
3121.27	6886.43
3123.82	6904.65
3126.36	6941.51
3128.9	6977.67
3131.44	6974.17
3133.98	7004.49
3136.52	7014.52
3139.06	7029.33
3141.6	7027.51
3144.13	7071.29
3146.67	7107.36
3149.2	7137.62
3151.74	7159.48
3154.27	7140.95
3156.8	7180.05
3159.34	7173.25
3161.86	7166.18
3164.4	7253.63
3166.92	7259.22
3169.45	7271.42
3171.98	7261.78
3174.5	7277.64
3177.03	7294.08
3179.56	7268.8
3182.08	7271.93
3184.6	7292.33
3187.12	7298.83
3189.64	7311.48
3192.16	7306.49
3194.68	7285.94
3197.2	7299.77
3199.72	7302.97
3202.24	7318.62
3204.75	7315.27
3207.27	7307.34
3209.78	7310.86
3212.29	7325.98
3214.81	7322.65
3217.32	7280.39
3219.83	7304.59
3222.34	7295.43
3224.85	7277.26
3227.35	7287.38
3229.86	7291.37
3232.37	7285.22
3234.87	7263.56
3237.38	7285.86
3239.88	7259.48
3242.38	7258.87
3244.89	7244.96
3247.39	7242.93
3249.89	7226.91
3252.39	7222.42
3254.88	7204.28
3257.38	7192.57
3259.88	7170.54
3262.37	7161.09
3264.87	7158.36
3267.36	7152.15
3269.86	7164.73
3272.35	7140.02
3274.84	7140.91
3277.33	7114.29
3279.82	7099.32
3282.31	7083.2
3284.8	7105.51
3287.29	7103.82
3289.77	7073.65
3292.26	7070.25
3294.15	7054.21
3296.64	7031.88
3299.14	7054.36
3301.63	7005.61
3304.12	7053.63
3306.62	7029.97
3309.11	7033.02
3311.6	7008.77
3314.09	7030.81
3316.58	7016.45
3319.07	7011.42
3321.56	7016.44
3324.04	7004.76
3326.53	7009.45
3329.01	7003.49
3331.5	6988.16
3333.98	6976.51
3336.46	6971.15
3338.94	7002.15
3341.42	6999.1
3343.9	6972.11
3346.38	6995.57
3348.86	6963.53
3351.34	6995.31
3353.82	6971.53
3356.29	6970.11
3358.77	6951.54
3361.24	6979.6
3363.71	6955.26
3366.19	6951.45
3368.66	6949.78
3371.13	6953.09
3373.6	6955.14
3376.07	6960.92
3378.54	6966.36
3381	6970.56
3383.47	6943.94
3385.94	6966.11
3388.4	6951.03
3390.87	6958.52
3393.33	6923.29
3395.79	6963.43
3398.25	6959.52
3400.71	6939.8
3403.17	6931.05
3405.63	6903.65
3408.09	6927.95
3410.55	6943.72
3413	6944.85
3415.46	6912.44
3417.92	6906.25
3420.37	6927.16
3422.82	6878.54
3425.27	6861.98
3427.73	6872.26
3430.18	6867.91
3432.63	6824.34
3435.08	6820.94
3437.53	6814.91
3439.97	6860.82
3442.42	6826.48
3444.86	6779.06
3447.31	6757.22
3449.75	6772.57
3452.2	6750.76
3454.64	6720.54
3457.08	6724.74
3459.52	6731.81
3461.96	6684.34
3464.4	6682.83
3466.84	6640.89
3469.28	6637.6
3471.72	6631.97
3474.15	6580.25
3476.59	6551.13
3479.02	6536.53
3481.45	6517.56
3483.89	6475.47
3486.32	6495.72
3488.75	6446.52
3491.18	6436.76
3493.61	6408.68
3496.04	6405.68
3498.47	6356.77
3499.68	6351.59