File: src/Milk_AI/Heritage toned after heating 532nm 50% 600g 50xL 10s 10times 400-3500cm-1 200hole.txt
#Acq. time (s)=	10
#Accumulations=	10
#Range (cm-¹)=	400...3500
#Windows=	3
#Auto scanning=	Off
#Autofocus=	Off
#AutoExposure=	Off
#Spike filter=	Multiple accum.
#Delay time (s)=	0
#Binning=	1
#Readout mode=	Signal
#DeNoise=	Off
#ICS correction=	On
#Dark correction=	Off
#Inst. Process=	Off
#Detector Gain=	Best Dynamic Range
#Detector ADC=	45 kHz
#Detector temperature (°C)=	-60.1
#Instrument=	LabRAM HR Evol
#Detector=	Syncerity OE
#Objective=	x50_VIS_LWD
#Grating=	600 (500nm)
#ND Filter=	50%
#Laser=	532nm_Edge
#Hole=	199.981
#Range=	Visible
#E-Cal_Neon=	0
#StageXY=	75x50mm Scan+
#StageZ=	Z motor
#X (µm)=	0
#Y (µm)=	0
#Z (µm)=	1167.5
#Spectral res.(cm-¹)=	12.8
#Full time(mm:ss)=	5:19
#AC=	Calibrated 2025-06-30 10:26
#Project=
#Sample=
#Site=
#Title=	D_99
#Remark=
#Date=	30.06.2025 16:50 (India Standard Time)
#Acquired=	30.06.2025 16:50:05 (India Standard Time)
#AxisType[0]=Intens
#AxisUnit[0]=Cnt
#AxisType[1]=Spectr
#AxisUnit[1]=1/cm
400.17	24791.8
403.717	24659.6
407.263	24677.9
410.807	24653
414.35	24703.8
417.892	24659.7
421.432	24673.5
424.971	24615.7
428.509	24645.1
432.045	24619
435.58	24697.5
439.111	24647.8
442.643	24532.4
446.174	24547.8
449.701	24465.6
453.229	24461.4
456.756	24452.7
460.279	24412.3
463.803	24367.4
467.326	24345.5
470.845	24283.2
474.365	24230.6
477.882	24267
481.399	24214.2
484.913	24288.9
488.425	24165.3
491.938	24181.8
495.448	24130.5
498.956	24177.2
502.465	24278.1
505.971	24181.6
509.475	24270.4
512.981	24256.4
516.482	24232.4
519.983	24181.5
523.482	24115.1
526.979	24062.9
530.476	24039.8
533.971	23946.9
537.464	23924.1
540.956	23885.7
544.447	23758
547.937	23836.3
551.425	23812.4
554.912	23815.5
558.398	23691.6
561.882	23733.5
565.365	23724.2
568.847	23742
572.325	23696
575.804	23734.9
579.282	23740.6
582.756	23742.5
586.231	23695.6
589.705	23788
593.175	23748.7
596.646	23809.2
600.116	23787.4
603.582	23787.4
607.049	23718.1
610.513	23653
613.977	23585
617.438	23498.7
620.898	23486
624.359	23339.7
627.816	23355.5
631.272	23229.4
634.728	23286.8
638.181	23259.6
641.633	23320.2
645.084	23134
648.535	23061.5
651.983	23090.4
655.43	23126.6
658.875	23101.9
662.319	23041.8
665.762	22985
669.203	23003.3
672.643	22931.1
676.082	22925.3
679.519	22943.4
682.955	22947.1
686.39	22954.8
689.824	22949.4
693.256	23007.1
696.685	22936.4
700.115	22965.7
703.543	22950.8
706.97	22872.6
710.394	22832.7
713.818	22871
717.241	22843.9
720.661	22954.2
724.082	22914.7
727.501	22753.3
730.917	22800.3
734.334	22752.8
737.747	22739.3
741.161	22687.6
744.572	22624.5
747.982	22665.7
751.392	22685
754.799	22720.7
758.205	22718
761.611	22720.2
765.014	22728.2
768.416	22759.1
771.816	22763.3
775.218	22723.1
778.616	22754.6
782.012	22695.4
785.408	22742.5
788.802	22689.1
792.195	22681.2
795.586	22699.5
798.977	22701.2
802.365	22742.3
805.753	22746.8
809.14	22725.5
812.525	22654.9
815.907	22732.7
819.289	22807.7
822.671	22866.6
826.051	22976.1
829.43	22999.1
832.805	23010.7
836.182	22999.6
839.557	23109.9
842.928	23198.9
846.301	23279.9
849.67	23245.4
853.04	23282.6
856.407	23273.1
859.774	23475.9
863.138	23378.4
866.503	23439
869.865	23382.8
873.225	23462.1
876.586	23463.9
879.944	23242.4
883.301	23174.3
886.658	23195
890.012	23161
893.365	23121.3
896.717	22915.8
900.067	22763.5
903.416	22668
906.766	22481.1
910.112	22432.5
913.458	22425.7
916.802	22317.7
920.145	22344.7
923.484	22237.1
926.825	22124.2
930.164	22068
933.501	21998.6
936.838	21907.2
940.173	21944.6
943.505	21953.3
946.838	21948.8
950.17	21954.5
953.5	21922.7
956.827	21862.9
960.155	21917.5
963.48	21971.8
966.805	21922.1
970.128	21834
973.45	21742.4
976.77	21645.8
980.091	21644.8
983.408	21668.5
986.726	21740.1
990.041	21715
993.354	21817.1
996.668	22033.5
999.979	22459.1
1003.29	22823.7
1006.6	22641.8
1009.91	22378.4
1013.21	22133.2
1016.52	22071.9
1019.82	22014
1023.12	22011.5
1026.43	21766.4
1029.73	21750.4
1033.02	21750.7
1036.32	21683.2
1039.62	21708.7
1042.91	21699
1046.21	21639.5
1049.5	21628.6
1052.79	21698.5
1056.08	21869.4
1059.37	22022.4
1062.65	22230.3
1065.94	22189.7
1069.23	22182.2
1072.51	22143.8
1075.79	22256.3
1079.07	22443.8
1082.35	22343.8
1085.63	22266
1088.91	22062.1
1092.18	21845.1
1095.46	21582.8
1098.73	21384.1
1102	21153.1
1105.27	20960.7
1108.54	21038.2
1111.81	21089.7
1115.08	21222.1
1118.34	21399.7
1121.61	21488.5
1124.87	21486.6
1128.13	21309.2
1131.39	20963.7
1134.65	20873.6
1137.91	20711.5
1141.17	20866.3
1144.42	21110.9
1147.68	21522.7
1150.93	22208.7
1154.18	23067.1
1157.43	23365
1160.68	22471.4
1163.93	21359.6
1167.18	20753.7
1170.42	20531.3
1173.67	20358.7
1176.91	20210.8
1180.15	20115.4
1183.39	20125
1186.63	20179.8
1189.87	20207.1
1193.11	20198.4
1196.34	20071
1199.58	19963.7
1202.81	19839.8
1206.04	19733.2
1209.27	19781.2
1212.5	19730.6
1215.73	19642.8
1218.95	19513.3
1222.18	19421.8
1225.4	19506.1
1228.63	19450.8
1231.85	19503.4
1235.07	19490.2
1238.29	19501.9
1241.51	19667.3
1244.72	19756.8
1247.94	19862.4
1251.15	19855.4
1254.37	19921
1257.58	19948.6
1260.79	20011.9
1264	20102.9
1267.21	20210.1
1270.41	20076.4
1273.62	19959.7
1276.82	19955.3
1280.03	19895.3
1283.23	19870.3
1286.43	19933.2
1289.63	20120
1292.83	20374.8
1296.03	20833.3
1299.22	21277.2
1302.42	21424.7
1305.61	21260.4
1308.8	20843.1
1311.99	20477.6
1315.18	20126.1
1318.37	19760.1
1321.56	19554.4
1324.74	19286.4
1327.93	19167.7
1331.11	18964.7
1334.3	18918.9
1337.48	18878.9
1340.66	18812.2
1343.84	18720.5
1347.01	18718.6
1350.19	18614
1353.37	18582.1
1356.54	18497.5
1359.71	18377.6
1362.88	18357
1366.05	18392.9
1369.22	18360.2
1372.39	18264.5
1375.56	18042.7
1378.72	17964
1381.89	17863.9
1385.05	17845.2
1388.21	17848
1391.37	17804.5
1394.53	17770.3
1397.69	17729.7
1400.85	17763.8
1404	17747.9
1407.16	17757.4
1410.31	17835.3
1413.46	18003
1416.61	18156.5
1419.76	18316.6
1422.91	18412
1426.06	18754.1
1429.21	19393.4
1432.35	20426.9
1435.49	21338.2
1438.64	21953.5
1441.78	21820.5
1444.92	21576
1448.06	21239.2
1451.2	20964.9
1454.33	20691.4
1457.47	20496.4
1460.6	20121
1463.74	19679.7
1466.87	19076
1470	18710.7
1473.13	18208.7
1476.26	17835.4
1479.38	17508.2
1482.51	17338.3
1485.63	17223.2
1488.76	17127
1491.88	17101.6
1495	17178
1498.12	17206.8
1501.24	17322
1504.36	17492
1507.47	17738.9
1510.59	18192.3
1513.7	18689
1516.81	19288.5
1519.93	19558.4
1523.04	19555.4
1526.15	19247.1
1529.25	18522.7
1532.36	17728.3
1535.47	17037.4
1538.57	16733.5
1541.67	16484.7
1544.78	16313.2
1547.88	16294
1550.98	16139.7
1554.08	16081.5
1557.18	16160.7
1560.27	15997.2
1563.37	16022.5
1566.46	16014.1
1569.55	15916.9
1572.64	15997.8
1575.74	15931.6
1578.83	15964.1
1581.91	15901.1
1585	15863.5
1588.09	15869.6
1591.17	15877.1
1594.25	15878.6
1597.34	15885.3
1600.42	15868.1
1603.5	15852.4
1606.58	15802.6
1609.65	15792.4
1612.73	15711.3
1615.8	15678.6
1618.88	15674
1621.95	15628.2
1625.03	15623.7
1628.1	15664.7
1631.17	15707.4
1634.23	15783.6
1637.3	15761.5
1640.37	15868.5
1643.43	16013.2
1646.5	16387.3
1649.56	16933.2
1652.62	17331.6
1655.68	17315.1
1658.74	16891.1
1661.8	16296.1
1664.85	16005.1
1667.91	15809.4
1670.96	15741
1674.02	15472.2
1677.07	15281.1
1680.12	15141.4
1683.17	15071.5
1686.22	14914.5
1689.27	14847.2
1692.31	14768.1
1695.36	14664.2
1698.4	14617.6
1701.45	14500.3
1704.49	14406.6
1707.53	14365.6
1710.57	14356.9
1713.61	14280
1716.65	14266.2
1719.68	14252.3
1722.72	14272.3
1725.75	14304.9
1728.78	14350
1731.82	14448
1734.84	14579.1
1737.87	14712.7
1740.9	14819.3
1743.93	14880.2
1746.96	14887.4
1749.98	14858.7
1753	14656.7
1756.03	14355.9
1759.05	14154
1762.07	14041.4
1765.09	13824.2
1768.11	13770.7
1771.12	13709.3
1774.14	13670.6
1777.15	13620.3
1780.17	13609.5
1783.18	13565.3
1786.19	13582.6
1789.2	13552.9
1792.21	13457
1795.22	13528.9
1798.22	13449.8
1801.23	13397.2
1804.23	13379
1807.24	13351.2
1810.24	13348.2
1813.24	13293.1
1816.24	13305.9
1819.24	13248.9
1822.24	13220.1
1825.23	13213.8
1828.23	13198.9
1831.22	13106.6
1834.22	13108.2
1837.21	13101.8
1840.2	13066.7
1843.19	13034.6
1846.18	13047.5
1849.17	12999
1852.15	13004
1855.14	12987.7
1858.12	12933.6
1861.11	12898.1
1864.09	12919
1867.07	12870.8
1870.05	12816.9
1873.03	12765.3
1876.01	12787.2
1878.98	12744.7
1881.96	12694.2
1884.93	12657.6
1887.91	12650.8
1890.88	12640.6
1893.85	12576.9
1896.82	12559.6
1899.79	12497.1
1902.76	12425.3
1905.72	12357.8
1908.69	12313.7
1911.65	12175.7
1914.62	12168.1
1917.58	12030.8
1920.54	11946.5
1923.5	11893
1926.46	11817.7
1929.42	11736.4
1932.37	11703.4
1935.33	11645.8
1938.28	11573.6
1941.24	11493
1944.19	11383.1
1947.14	11312.5
1950.09	11245.7
1953.04	11161.1
1955.99	11062.9
1958.93	10989.3
1961.88	10976.1
1964.82	10895
1967.77	10830.6
1970.71	10793.6
1973.65	10691.7
1976.59	10655.8
1979.53	10626.7
1982.47	10568.4
1985.41	10493.5
1988.34	10450.3
1991.28	10367.5
1994.21	10278.4
1997.14	10218.2
2000.07	10160.7
2003.01	10106
2005.94	10048.8
2008.86	9983.22
2011.79	9958.03
2014.72	9924.28
2017.64	9854.97
2020.57	9812.74
2023.49	9762.51
2026.41	9680.2
2029.33	9653.83
2032.25	9608.48
2035.17	9578.34
2038.09	9546.37
2041	9508.1
2043.92	9412.67
2045.86	9408.53
2048.79	9401.99
2051.71	9400.64
2054.64	9365.18
2057.56	9336.73
2060.48	9317.21
2063.4	9297.58
2066.32	9322.4
2069.24	9275.38
2072.16	9221.63
2075.08	9246.54
2077.99	9213.46
2080.91	9207.66
2083.82	9228.32
2086.74	9195.14
2089.65	9145.31
2092.56	9090.52
2095.47	9051.79
2098.38	9089.74
2101.29	9057.77
2104.19	9066.75
2107.1	9099.03
2110	9016.55
2112.91	9029.42
2115.81	8980.79
2118.71	8964.35
2121.61	8952.95
2124.51	8916.16
2127.4	8890.21
2130.3	8899.03
2133.2	8841.75
2136.09	8861.16
2138.99	8847.58
2141.88	8852.33
2144.77	8862.23
2147.66	8766.69
2150.55	8803.24
2153.44	8774.27
2156.33	8784.15
2159.21	8740.62
2162.1	8740.82
2164.98	8732.98
2167.87	8730.48
2170.75	8707.06
2173.63	8657.33
2176.51	8685.83
2179.39	8675.96
2182.27	8617.84
2185.14	8609.65
2188.02	8601.49
2190.9	8592.27
2193.77	8587.77
2196.64	8564.88
2199.51	8545.31
2202.39	8529.24
2205.25	8497.99
2208.12	8502.62
2210.99	8473.14
2213.86	8390.68
2216.72	8421.33
2219.59	8407.81
2222.45	8356.39
2225.31	8342.28
2228.17	8325.76
2231.03	8308.93
2233.89	8274.56
2236.75	8266.12
2239.61	8269.49
2242.46	8207.48
2245.32	8170.71
2248.17	8190.53
2251.03	8147.73
2253.88	8149.89
2256.73	8085.28
2259.58	8072.53
2262.43	8008.63
2265.28	8010.84
2268.12	7977.71
2270.97	7940.95
2273.81	7971.46
2276.66	7922.37
2279.5	7905.89
2282.34	7887.41
2285.18	7845.19
2288.02	7824.34
2290.86	7808.85
2293.7	7778.75
2296.54	7784.92
2299.37	7765.11
2302.21	7765.36
2305.04	7687.85
2307.87	7664.06
2310.7	7698.83
2313.53	7681.68
2316.36	7617.44
2319.19	7628.78
2322.02	7582.7
2324.85	7634.84
2327.67	7751.01
2330.5	7863.41
2333.32	7585.45
2336.14	7484.9
2338.96	7445.18
2341.78	7509.69
2344.6	7429.11
2347.42	7361.08
2350.24	7372.58
2353.05	7343.4
2355.87	7321.26
2358.68	7277.64
2361.5	7262.13
2364.31	7259.03
2367.12	7253.62
2369.93	7244.88
2372.74	7182.81
2375.55	7203.21
2378.35	7129.78
2381.16	7138.96
2383.96	7122.36
2386.77	7112.64
2389.57	7115.22
2392.37	7046.33
2395.17	7054.15
2397.97	7090.24
2400.77	7032.85
2403.57	7003.06
2406.37	6987.69
2409.16	6974.61
2411.96	6936.11
2414.75	6938.92
2417.55	6930.66
2420.34	6870.1
2423.13	6893.75
2425.92	6870.38
2428.71	6893.19
2431.5	6840.29
2434.28	6854.67
2437.07	6815.49
2439.85	6805.71
2442.64	6758.83
2445.42	6762.08
2448.2	6778.26
2450.98	6744.57
2453.76	6747.75
2456.54	6709.6
2459.32	6676.44
2462.1	6653.69
2464.87	6667.36
2467.65	6626.06
2470.42	6602.95
2473.2	6593.01
2475.97	6580.91
2478.74	6549.72
2481.51	6556.78
2484.28	6563.62
2487.05	6519.73
2489.81	6513.27
2492.58	6493.93
2495.34	6470.92
2498.11	6495.9
2500.87	6435.83
2503.63	6460.4
2506.39	6402.95
2509.15	6383.3
2511.91	6390.73
2514.67	6374.25
2517.43	6356.6
2520.19	6354.44
2522.94	6336.72
2525.7	6337.11
2528.45	6313.34
2531.2	6267.17
2533.95	6280.06
2536.7	6284.3
2539.45	6248.17
2542.2	6229.71
2544.95	6198.98
2547.69	6172.08
2550.44	6152.98
2553.18	6175.69
2555.93	6162.69
2558.67	6147.99
2561.41	6121.75
2564.15	6106.67
2566.89	6084.89
2569.63	6092.86
2572.36	6071.64
2575.1	6054.86
2577.84	6071.34
2580.57	6045.18
2583.31	6027.33
2586.04	6000.52
2588.77	6001.71
2591.5	5992.7
2594.23	6000.47
2596.96	5986.52
2599.69	5992.24
2602.41	5950.79
2605.14	5982.35
2607.86	5958.44
2610.59	5994.99
2613.31	5900.87
2616.03	5898.38
2618.75	5900.15
2621.48	5898.27
2624.19	5904.28
2626.91	5864.77
2629.63	5855.4
2632.35	5821.67
2635.06	5826.19
2637.77	5826.78
2640.49	5754.46
2643.2	5831.53
2645.91	5799.35
2648.62	5844
2651.33	5793.1
2654.04	5778.09
2656.75	5751.99
2659.45	5732.53
2662.16	5729.19
2664.86	5723.9
2667.57	5733.55
2670.27	5756.94
2672.97	5718.86
2675.67	5713.65
2678.37	5686.39
2681.07	5676.1
2683.77	5666.56
2686.47	5677.51
2689.16	5633.24
2691.86	5641.25
2694.55	5607.05
2697.25	5614.4
2699.94	5615.9
2702.63	5631.06
2705.32	5631.2
2708.01	5625.44
2710.7	5613.31
2713.39	5602.88
2716.07	5613.95
2718.76	5591.29
2721.44	5602.57
2724.12	5587.89
2726.81	5579
2729.49	5559.24
2732.17	5539.02
2734.85	5525.16
2737.53	5482.08
2740.21	5485.93
2742.88	5427.66
2745.56	5409.47
2748.24	5385.15
2750.91	5357.31
2753.58	5343.29
2756.25	5310.7
2758.93	5334.2
2761.6	5280.27
2764.27	5317
2766.93	5279.41
2769.6	5261.3
2772.27	5242.46
2774.93	5229.81
2777.6	5231.69
2780.26	5183.79
2782.93	5191.89
2785.59	5154.82
2788.25	5153.78
2790.91	5152.45
2793.57	5176.04
2796.23	5168.35
2798.88	5191.46
2801.54	5119.62
2804.2	5143.98
2806.85	5095.9
2809.5	5146.48
2812.16	5125.24
2814.81	5150.58
2817.46	5146.87
2820.11	5166.24
2822.76	5162.97
2825.4	5166.81
2828.05	5239.39
2830.7	5243.47
2833.34	5321.53
2835.99	5421.85
2838.63	5559.08
2841.27	5776.78
2843.91	6171.39
2846.55	6703.9
2849.19	7191.28
2851.83	7454.69
2854.47	7394.78
2857.11	7208.36
2859.74	7086.72
2862.38	6968.32
2865.01	6858.52
2867.65	6854.85
2870.28	6885.65
2872.91	6993.57
2875.54	7104.98
2878.17	7093.7
2880.8	7146.58
2883.42	7244.15
2886.05	7299.65
2888.68	7376.92
2891.3	7409.59
2893.93	7406.68
2896.55	7403.15
2899.17	7430.03
2901.79	7395.27
2904.41	7387.43
2907.03	7365.64
2909.65	7326.35
2912.27	7319.28
2914.88	7279.57
2917.5	7279.17
2920.11	7264.81
2922.73	7290.32
2925.34	7324.59
2927.95	7306.45
2930.56	7276.71
2933.17	7272.97
2935.78	7209.95
2938.39	7094.42
2941	6990.56
2943.6	6707.4
2946.21	6440
2948.81	6329.76
2951.42	6132.86
2954.02	6085.37
2956.62	6050.86
2959.22	5977.85
2961.82	5859.19
2964.42	5822.52
2967.02	5742.17
2969.62	5631.67
2972.21	5568.9
2974.81	5470.74
2977.4	5383.45
2980	5286.59
2982.59	5261.01
2985.18	5191.53
2987.77	5141.06
2990.36	5098.33
2992.95	5056.07
2995.54	5014.16
2998.13	4985.35
3000.72	5012.6
3003.3	4988.27
3005.89	4973.13
3008.47	4927.73
3011.05	4920.68
3013.63	4830.02
3016.22	4860.65
3018.8	4809.34
3021.38	4792.59
3023.95	4769.51
3026.53	4741.97
3029.11	4723.91
3031.68	4698.81
3034.26	4721.31
3036.83	4720.05
3039.4	4716.55
3041.98	4717.54
3044.55	4709.33
3047.12	4752.76
3049.69	4747.98
3052.26	4728.66
3054.82	4765.33
3057.39	4776.53
3059.96	4809.86
3062.52	4799.75
3065.09	4806.53
3067.65	4822.85
3070.21	4831.41
3072.77	4801.35
3075.33	4808.72
3077.89	4849.05
3080.45	4823.85
3083.01	4851.71
3085.57	4853.04
3088.12	4888.71
3090.68	4889.99
3093.23	4881.01
3095.79	4919.24
3098.34	4931.29
3100.89	4957.02
3103.44	4955.15
3105.99	5011.46
3108.54	5016.34
3111.09	5082.36
3113.63	5057.28
3116.18	5100.17
3118.73	5128.14
3121.27	5213.83
3123.82	5204.5
3126.36	5259.65
3128.9	5275.23
3131.44	5312.62
3133.98	5328.54
3136.52	5344.07
3139.06	5411.02
3141.6	5418.33
3144.13	5441.09
3146.67	5482.52
3149.2	5538.38
3151.74	5571.71
3154.27	5567.42
3156.8	5656.56
3159.34	5668.66
3161.86	5664.61
3164.4	5680.58
3166.92	5777.32
3169.45	5759.15
3171.98	5783.17
3174.5	5816.29
3177.03	5826.88
3179.56	5776.43
3182.08	5807.35
3184.6	5828.25
3187.12	5869.2
3189.64	5869.08
3192.16	5854.41
3194.68	5857.33
3197.2	5850.39
3199.72	5871.32
3202.24	5862.54
3204.75	5892.91
3207.27	5868.67
3209.78	5861.85
3212.29	5856.31
3214.81	5845.28
3217.32	5843.23
3219.83	5837.16
3222.34	5830.01
3224.85	5818.69
3227.35	5816.43
3229.86	5834.4
3232.37	5817.12
3234.87	5804.52
3237.38	5790.74
3239.88	5787.02
3242.38	5787.32
3244.89	5754.39
3247.39	5740.76
3249.89	5721.5
3252.39	5711.84
3254.88	5700.91
3257.38	5677.16
3259.88	5648.19
3262.37	5653.18
3264.87	5610.94
3267.36	5623.56
3269.86	5620.92
3272.35	5599.71
3274.84	5583.58
3277.33	5577.04
3279.82	5553.67
3282.31	5535.38
3284.8	5523.21
3287.29	5522.83
3289.77	5510.12
3292.26	5498.38
3294.15	5477.48
3296.64	5465.8
3299.14	5486.89
3301.63	5464.47
3304.12	5465.94
3306.62	5433.26
3309.11	5411.89
3311.6	5444.2
3314.09	5396.19
3316.58	5410.32
3319.07	5403.2
3321.56	5377.63
3324.04	5409.2
3326.53	5414
3329.01	5381.83
3331.5	5369.01
3333.98	5365.74
3336.46	5354.74
3338.94	5365.38
3341.42	5359.47
3343.9	5319.82
3346.38	5323.73
3348.86	5321.64
3351.34	5323.57
3353.82	5267.4
3356.29	5309.16
3358.77	5306.66
3361.24	5303.65
3363.71	5329.64
3366.19	5298.77
3368.66	5287.94
3371.13	5287.98
3373.6	5284.69
3376.07	5286.29
3378.54	5259.07
3381	5272.01
3383.47	5251.02
3385.94	5253.91
3388.4	5234.81
3390.87	5250.8
3393.33	5274.28
3395.79	5245.55
3398.25	5241.44
3400.71	5244.48
3403.17	5204.77
3405.63	5189.07
3408.09	5191.52
3410.55	5212.32
3413	5204.75
3415.46	5200.39
3417.92	5173.93
3420.37	5154.22
3422.82	5134.38
3425.27	5108.47
3427.73	5071.38
3430.18	5087.07
3432.63	5034.59
3435.08	5070.54
3437.53	5054.04
3439.97	4995.48
3442.42	4963.77
3444.86	4959.48
3447.31	4947.75
3449.75	4927.93
3452.2	4872.41
3454.64	4872.99
3457.08	4831.79
3459.52	4828.88
3461.96	4816.88
3464.4	4790.14
3466.84	4755.74
3469.28	4742.15
3471.72	4708.58
3474.15	4671.43
3476.59	4647.38
3479.02	4608.09
3481.45	4571.26
3483.89	4512.12
3486.32	4512.94
3488.75	4470.07
3491.18	4473.09
3493.61	4418.78
3496.04	4387.12
3498.47	4346.89
3499.68	4354.77