File: src/Milk_AI/Heritage full cream Cold 532nm 50% 600g 50xL 10s 10times 400-3500cm-1 100hole.txt
#Acq. time (s)=	10
#Accumulations=	10
#Range (cm-¹)=	400...3500
#Windows=	3
#Auto scanning=	Off
#Autofocus=	Off
#AutoExposure=	Off
#Spike filter=	Multiple accum.
#Delay time (s)=	0
#Binning=	1
#Readout mode=	Signal
#DeNoise=	Off
#ICS correction=	On
#Dark correction=	Off
#Inst. Process=	Off
#Detector Gain=	Best Dynamic Range
#Detector ADC=	45 kHz
#Detector temperature (°C)=	-60.1
#Instrument=	LabRAM HR Evol
#Detector=	Syncerity OE
#Objective=	x50_VIS_LWD
#Grating=	600 (500nm)
#ND Filter=	50%
#Laser=	532nm_Edge
#Hole=	199.981
#Range=	Visible
#E-Cal_Neon=	0
#StageXY=	75x50mm Scan+
#StageZ=	Z motor
#X (µm)=	0
#Y (µm)=	0
#Z (µm)=	245.6
#Spectral res.(cm-¹)=	12.8
#Full time(mm:ss)=	5:18
#AC=	Calibrated 2025-07-01 10:31
#Project=
#Sample=
#Site=
#Title=	D_4
#Remark=
#Date=	01.07.2025 11:36 (India Standard Time)
#Acquired=	01.07.2025 11:36:20 (India Standard Time)
#AxisType[0]=Intens
#AxisUnit[0]=Cnt
#AxisType[1]=Spectr
#AxisUnit[1]=1/cm
400.083	26571.2
403.63	26340.2
407.176	26437.2
410.72	26422.1
414.263	26407.1
417.805	26452.2
421.345	26332.6
424.884	26426.7
428.421	26399.3
431.955	26475.5
435.49	26405.6
439.023	26399.6
442.555	26328.8
446.084	26337
449.613	26274.7
453.141	26152
456.666	26260.6
460.191	26305.2
463.715	26267.5
467.235	26155.1
470.756	26136.8
474.274	26153.2
477.793	26139.9
481.308	26111.3
484.823	26132.3
488.336	26084.8
491.847	26160.3
495.358	26061.4
498.867	26218.3
502.374	26210.8
505.881	26225.8
509.386	26238.5
512.888	26240.7
516.39	26307.8
519.89	26105.1
523.391	26144.6
526.889	26085.6
530.385	26061.6
533.88	26023.1
537.373	25989.1
540.866	25947.7
544.357	25966.5
547.846	25944.6
551.334	25874.9
554.821	25930.1
558.307	25865.2
561.789	25889.2
565.272	25887.1
568.753	25857.6
572.233	25847.7
575.712	25953.8
579.188	25917.9
582.664	25918.4
586.139	25841.1
589.611	25954.6
593.083	25845
596.554	25889.9
600.021	25942.7
603.49	25883.3
606.955	25882.3
610.42	25856.7
613.882	25752.6
617.345	25730.9
620.805	25625.7
624.263	25611.8
627.722	25523.7
631.178	25545.5
634.633	25508.9
638.088	25531.7
641.539	25670.5
644.99	25408.9
648.439	25428
651.887	25391.1
655.335	25371.2
658.781	25423.8
662.225	25364.6
665.667	25374.3
669.108	25362.7
672.548	25349.7
675.987	25226
679.424	25356.8
682.86	25392.8
686.293	25353.2
689.727	25373.4
693.159	25408.8
696.59	25459.6
700.019	25380.6
703.448	25389.6
706.872	25282
710.298	25244.4
713.723	25262.7
717.144	25263.6
720.565	25326.8
723.984	25279.2
727.403	25290.1
730.821	25200
734.235	25180.3
737.651	25120.5
741.063	25064.2
744.474	25051.8
747.885	25108.4
751.293	25082.4
754.702	25222.2
758.108	25198.9
761.512	25133.7
764.915	25151.7
768.319	25165.3
771.719	25222.5
775.118	25180.1
778.516	25162.5
781.913	25238.7
785.308	25290.7
788.702	25249.3
792.095	25081.8
795.486	25119.9
798.876	25221.9
802.265	25167.6
805.653	25175
809.039	25093.4
812.424	25091
815.808	24985.9
819.191	25084.5
822.572	25195
825.95	25280.3
829.329	25199
832.706	25279.8
836.08	25242.4
839.455	25244.6
842.829	25347.8
846.199	25400.5
849.57	25388
852.938	25363.4
856.307	25360.2
859.672	25459.5
863.038	25461.8
866.401	25461.1
869.765	25395.6
873.125	25465.9
876.484	25517.3
879.844	25393.5
883.2	25324.7
886.555	25330.7
889.909	25376.1
893.262	25230.7
896.616	25135.3
899.966	25076.3
903.315	24979.2
906.663	24856.6
910.009	24811.7
913.354	24787.2
916.698	24762.9
920.041	24787.9
923.383	24752.7
926.723	24601.2
930.062	24523.6
933.399	24462.6
936.734	24510.8
940.069	24526.7
943.403	24658.4
946.736	24626.1
950.065	24574.5
953.396	24637.1
956.725	24593.4
960.051	24619.7
963.377	24690.2
966.7	24597.7
970.025	24500.4
973.345	24498.3
976.667	24447.1
979.985	24477.6
983.304	24570.8
986.62	24614.6
989.935	24627.7
993.25	24761.9
996.563	25061.3
999.874	25398
1003.19	25507.7
1006.49	25301.7
1009.8	24996.8
1013.11	24802.5
1016.41	24695.1
1019.72	24722.5
1023.02	24591.3
1026.32	24537.9
1029.62	24464
1032.92	24442.3
1036.22	24389.6
1039.51	24305.9
1042.81	24294.3
1046.1	24272.3
1049.39	24291.6
1052.68	24326
1055.97	24495.2
1059.26	24689
1062.55	24781
1065.83	24630
1069.12	24570.6
1072.4	24661
1075.68	24639.4
1078.97	24644.9
1082.24	24652.6
1085.52	24582.7
1088.8	24487.6
1092.08	24347.2
1095.35	24169.7
1098.62	24130.2
1101.9	23983.8
1105.17	23897.2
1108.44	23971.1
1111.7	24017.2
1114.97	24134.5
1118.23	24191.1
1121.5	24283.5
1124.76	24294.8
1128.03	24252.1
1131.29	24079.6
1134.54	23936.9
1137.8	23888.5
1141.06	23989.6
1144.31	24320.4
1147.57	24842.5
1150.82	25774.7
1154.07	26559.4
1157.32	26325.5
1160.57	25277.1
1163.82	24328.2
1167.07	23831.9
1170.31	23634.2
1173.56	23531.9
1176.8	23434.3
1180.04	23385.7
1183.28	23417.7
1186.52	23461
1189.76	23606.2
1192.99	23475.8
1196.23	23297.5
1199.46	23155.9
1202.7	23057.2
1205.93	23043.4
1209.16	23053.5
1212.39	22955.3
1215.62	22916.4
1218.84	22795.8
1222.07	22765.9
1225.29	22746
1228.52	22785.5
1231.74	22705
1234.96	22698.3
1238.18	22782
1241.4	22871.6
1244.61	22876.2
1247.83	22959.4
1251.04	22952.8
1254.25	23032.9
1257.47	23070.7
1260.68	23051.3
1263.89	23116.4
1267.09	23097.2
1270.3	22991.1
1273.51	22872.2
1276.71	22813.9
1279.91	22848.3
1283.12	22734.5
1286.32	22782.3
1289.52	22962.2
1292.72	23257.8
1295.91	23600.5
1299.11	23537.8
1302.3	23527.4
1305.5	23360.2
1308.69	23093.3
1311.88	22872.1
1315.07	22622.3
1318.26	22504.9
1321.44	22309.5
1324.63	22216
1327.82	22155.6
1331	22048
1334.18	22070.6
1337.36	22027.9
1340.54	21993.6
1343.72	21968.2
1346.9	21838.4
1350.07	21896.1
1353.25	21829.9
1356.42	21746.3
1359.6	21750.5
1362.77	21650.4
1365.94	21630.9
1369.11	21503.5
1372.28	21486
1375.44	21359.3
1378.61	21279.7
1381.77	21186.9
1384.93	21211.2
1388.1	21151.4
1391.26	21142.6
1394.41	21133.2
1397.57	21090.1
1400.73	21043.5
1403.89	21043.5
1407.04	21061.9
1410.19	21099.2
1413.35	21201.4
1416.5	21299.4
1419.65	21498.4
1422.8	21438.8
1425.94	21729.8
1429.09	22092.2
1432.23	22687.3
1435.38	23333.9
1438.52	23518
1441.66	23371.4
1444.8	23123.2
1447.94	22944.5
1451.08	22814.7
1454.22	22600.6
1457.35	22475.6
1460.48	22224.3
1463.62	21927.9
1466.75	21638.6
1469.88	21295
1473.01	21008.9
1476.14	20760.7
1479.26	20537.4
1482.39	20428.6
1485.51	20359.2
1488.64	20405.3
1491.76	20393.5
1494.88	20481.4
1498	20555.8
1501.12	20672.6
1504.24	20909.4
1507.35	21208.9
1510.47	21683.4
1513.58	22279.1
1516.69	22821.2
1519.81	23029
1522.92	22929.5
1526.03	22394.5
1529.13	21542.1
1532.24	20824.3
1535.35	20189.2
1538.45	19987.3
1541.55	19828.8
1544.66	19644.8
1547.76	19557.5
1550.86	19432.3
1553.96	19425.9
1557.05	19328.4
1560.15	19278.3
1563.24	19353.7
1566.34	19356.9
1569.43	19278.5
1572.52	19272.6
1575.61	19222.6
1578.7	19222.9
1581.79	19277.2
1584.88	19145.5
1587.96	19134.7
1591.05	19197.1
1594.13	19106.6
1597.21	19195.1
1600.3	19180.4
1603.37	19098.8
1606.45	19006.7
1609.53	18992.6
1612.61	18884.5
1615.68	18870.7
1618.76	18877
1621.83	18805
1624.9	18764.1
1627.97	18786.9
1631.04	18781
1634.11	18876.9
1637.18	18800.3
1640.24	18915.7
1643.31	19039.8
1646.37	19214.9
1649.44	19533.7
1652.5	19648.1
1655.56	19532.1
1658.62	19172.5
1661.67	18947.3
1664.73	18809.6
1667.79	18731
1670.84	18563.8
1673.89	18490.1
1676.95	18311
1680	18185.2
1683.05	18083.4
1686.1	18020.9
1689.14	17902.4
1692.19	17827.6
1695.23	17854.5
1698.28	17696.2
1701.32	17633.3
1704.36	17628.8
1707.4	17540.9
1710.44	17444.9
1713.48	17452.4
1716.52	17410.6
1719.56	17355.2
1722.59	17290
1725.63	17379.3
1728.66	17347.6
1731.69	17377.3
1734.72	17512.3
1737.75	17532
1740.78	17570.7
1743.8	17541.4
1746.83	17468.4
1749.86	17408.3
1752.88	17275.7
1755.9	17087.1
1758.92	17002.8
1761.94	16859.4
1764.96	16817.3
1767.98	16771
1771	16750.3
1774.01	16766.9
1777.03	16669.9
1780.04	16628.4
1783.05	16616.7
1786.06	16627
1789.07	16648.6
1792.08	16534.9
1795.09	16551
1798.1	16486.7
1801.1	16451.8
1804.11	16381.1
1807.11	16390.3
1810.11	16344.4
1813.11	16309.3
1816.11	16301.7
1819.11	16246.3
1822.11	16238.4
1825.11	16133.9
1828.1	16120.8
1831.1	16118.8
1834.09	16123.5
1837.08	16066.9
1840.07	16028.1
1843.06	16068
1846.05	15979.5
1849.04	15973.6
1852.02	15875.2
1855.01	15878.8
1857.99	15830.5
1860.98	15834.2
1863.96	15841.2
1866.94	15775.5
1869.92	15792.2
1872.9	15720.4
1875.88	15740.1
1878.85	15666.7
1881.83	15637.7
1884.8	15552.3
1887.78	15501.8
1890.75	15521.8
1893.72	15434.9
1896.69	15384.8
1899.66	15362.9
1902.63	15335.3
1905.59	15142
1908.56	15131.2
1911.52	15049.7
1914.49	14905
1917.45	14852.5
1920.41	14794.8
1923.37	14654.8
1926.33	14632.7
1929.29	14558.4
1932.24	14491.6
1935.2	14424.6
1938.15	14309.4
1941.1	14245.5
1944.06	14205.1
1947.01	14089.8
1949.96	14041.6
1952.91	13915.7
1955.86	13829
1958.8	13733.9
1961.75	13706.6
1964.69	13656
1967.64	13575.9
1970.58	13487.5
1973.52	13412.4
1976.46	13360.4
1979.4	13341.3
1982.34	13246.4
1985.27	13153.8
1988.21	13121.5
1991.14	13037.9
1994.08	12967.7
1997.01	12881.2
1999.94	12818.3
2002.87	12744.5
2005.8	12709.7
2008.73	12670
2011.66	12621.3
2014.58	12578.6
2017.51	12510.5
2020.43	12435.7
2023.36	12359.3
2026.28	12323.6
2029.2	12287.9
2032.12	12241.1
2035.04	12179.4
2037.95	12130
2040.87	12124.3
2043.78	12072.7
2045.76	12053.1
2048.69	11994.7
2051.61	11982.2
2054.54	11991.6
2057.46	11936.2
2060.38	11904.9
2063.3	11925.4
2066.22	11904.4
2069.14	11855.8
2072.06	11827.2
2074.98	11817.5
2077.89	11839.6
2080.81	11782.9
2083.72	11769.9
2086.63	11784.5
2089.55	11716.4
2092.46	11716.8
2095.37	11667.3
2098.28	11654.7
2101.18	11580.8
2104.09	11615.2
2106.99	11580.9
2109.9	11557
2112.8	11515.1
2115.71	11517
2118.61	11531.3
2121.51	11525.1
2124.4	11502.4
2127.3	11466
2130.2	11420.4
2133.09	11398.2
2135.99	11391.4
2138.88	11429.5
2141.78	11377.7
2144.67	11335.6
2147.56	11358.9
2150.45	11343.2
2153.34	11262.7
2156.22	11303
2159.11	11335.4
2162	11261
2164.88	11230.2
2167.76	11282.4
2170.64	11255.8
2173.53	11231.2
2176.41	11166.3
2179.29	11162.9
2182.16	11166.8
2185.04	11182.3
2187.92	11080.7
2190.79	11130.5
2193.66	11046.3
2196.54	11052.7
2199.41	11033.8
2202.28	10978.7
2205.15	11004.6
2208.02	10964.6
2210.88	10954.8
2213.75	10916.1
2216.62	10908.5
2219.48	10836.8
2222.34	10817.8
2225.21	10759.5
2228.07	10746.7
2230.93	10784.7
2233.79	10718.4
2236.65	10741.9
2239.5	10726
2242.36	10643.1
2245.21	10654.7
2248.07	10637.7
2250.92	10608.7
2253.77	10583.4
2256.62	10532.9
2259.47	10462.7
2262.32	10444.3
2265.17	10422.3
2268.02	10364.8
2270.86	10364.6
2273.71	10326.4
2276.55	10302.1
2279.39	10328.1
2282.24	10328
2285.08	10241.9
2287.92	10242.5
2290.75	10176.4
2293.59	10202.4
2296.43	10125.4
2299.26	10128.5
2302.1	10071.6
2304.93	10098.5
2307.76	10086.2
2310.6	10068
2313.43	10007.7
2316.25	10016.4
2319.08	9935.43
2321.91	9966.19
2324.74	9986.12
2327.56	10118.4
2330.39	10118.6
2333.21	9850.03
2336.03	9814.16
2338.85	9731.03
2341.67	9793.01
2344.49	9723.92
2347.31	9741.46
2350.13	9670.94
2352.94	9673.14
2355.76	9632.42
2358.57	9585.78
2361.39	9577.38
2364.2	9511.66
2367.01	9537.65
2369.82	9510.73
2372.63	9467.73
2375.44	9404.02
2378.24	9460.23
2381.05	9421.87
2383.85	9403.69
2386.66	9414.6
2389.46	9382.4
2392.26	9374.93
2395.06	9352.06
2397.86	9315.63
2400.66	9299.17
2403.46	9274.19
2406.26	9338.78
2409.05	9270.93
2411.85	9221.63
2414.64	9184.25
2417.43	9185.35
2420.23	9167.7
2423.02	9150.4
2425.81	9097.8
2428.6	9107.85
2431.38	9082.93
2434.17	9093.69
2436.96	9054.92
2439.74	9040.39
2442.53	9016.78
2445.31	9025.67
2448.09	9009.97
2450.87	8908.98
2453.65	8949.61
2456.43	8938.97
2459.21	8932.36
2461.98	8882.3
2464.76	8830.19
2467.53	8861.58
2470.31	8817.55
2473.08	8824.12
2475.85	8821.7
2478.63	8807.32
2481.39	8776.84
2484.16	8748.89
2486.93	8783
2489.7	8735.95
2492.46	8679.83
2495.23	8720.16
2497.99	8689.48
2500.76	8616.12
2503.52	8632.52
2506.28	8619.83
2509.04	8611.6
2511.8	8549.23
2514.56	8568.06
2517.31	8547.79
2520.07	8518.22
2522.82	8563.4
2525.58	8481.03
2528.33	8520.87
2531.09	8513.22
2533.84	8456.11
2536.59	8458.36
2539.34	8423.19
2542.08	8406.01
2544.83	8400.99
2547.58	8341.81
2550.32	8355.8
2553.07	8322.42
2555.81	8296.84
2558.55	8288.03
2561.29	8302.18
2564.03	8313.03
2566.77	8244.45
2569.51	8238.12
2572.25	8227.42
2574.99	8224.51
2577.72	8217.78
2580.46	8242.82
2583.19	8220.82
2585.92	8199.97
2588.65	8230.79
2591.38	8204.72
2594.11	8143.67
2596.84	8156.73
2599.57	8155.99
2602.3	8129.11
2605.02	8128.73
2607.75	8152.15
2610.47	8118.46
2613.19	8080.65
2615.92	8079.5
2618.64	8074.03
2621.36	8062.04
2624.08	8051.67
2626.8	8036.25
2629.51	8039.33
2632.23	8020.18
2634.94	7993.06
2637.66	8056.66
2640.37	7959.41
2643.08	7957.57
2645.79	8003.43
2648.5	7983.43
2651.21	7948.17
2653.92	7938.21
2656.63	7936.34
2659.33	7936.56
2662.04	7949.56
2664.75	7920.6
2667.45	7892.67
2670.15	7950.19
2672.85	7920.11
2675.55	7903.6
2678.25	7883.62
2680.95	7864.91
2683.65	7823.84
2686.35	7819.34
2689.04	7854.59
2691.74	7843.44
2694.43	7764.02
2697.13	7817.39
2699.82	7790.68
2702.51	7846.6
2705.2	7831.65
2707.89	7809.85
2710.58	7829.26
2713.26	7821.87
2715.95	7848.05
2718.64	7824.9
2721.32	7867.18
2724	7828.45
2726.69	7854.04
2729.37	7833.82
2732.05	7776.38
2734.73	7744.84
2737.41	7685.75
2740.09	7584.53
2742.76	7613.6
2745.44	7585.9
2748.11	7554.54
2750.79	7536.66
2753.46	7544.12
2756.13	7473.5
2758.81	7513.97
2761.47	7430.32
2764.14	7464.35
2766.81	7434.83
2769.48	7453.43
2772.15	7388.05
2774.81	7377.83
2777.48	7389.3
2780.14	7349.15
2782.8	7355.19
2785.47	7315.89
2788.13	7336.03
2790.79	7295.55
2793.44	7308.8
2796.1	7310.53
2798.76	7340.31
2801.42	7291.65
2804.07	7311.02
2806.73	7276.99
2809.38	7314.98
2812.03	7341.52
2814.68	7350.6
2817.33	7354.63
2819.98	7394.04
2822.63	7391.98
2825.28	7452.38
2827.93	7519.23
2830.57	7584.87
2833.22	7713.68
2835.86	7936.13
2838.51	8319.26
2841.15	8871
2843.79	9605.3
2846.43	10373
2849.07	11005.2
2851.71	11036.4
2854.35	10893.8
2856.98	10624.6
2859.62	10478.6
2862.25	10276
2864.89	10195.6
2867.52	10146.7
2870.15	10286.5
2872.78	10477.7
2875.41	10633.8
2878.04	10856.3
2880.67	11019
2883.3	11046.1
2885.92	10972.6
2888.55	11065.6
2891.18	11002.9
2893.8	10979.3
2896.42	10978.8
2899.04	10948.1
2901.67	10917
2904.29	10853.8
2906.9	10820.3
2909.52	10807.9
2912.14	10753.9
2914.76	10707.5
2917.37	10693.2
2919.99	10631.5
2922.6	10665.1
2925.21	10659.2
2927.82	10652
2930.44	10671.9
2933.05	10609.5
2935.65	10552.4
2938.26	10333.3
2940.87	10045
2943.48	9657.78
2946.08	9303.81
2948.69	9085.83
2951.29	8900.21
2953.89	8800.46
2956.49	8740.91
2959.1	8642.5
2961.7	8524.1
2964.29	8416.7
2966.89	8276.7
2969.49	8169.34
2972.09	8015.05
2974.68	7855.68
2977.28	7789.57
2979.87	7697.87
2982.46	7631.34
2985.05	7501.29
2987.65	7431.69
2990.24	7368.4
2992.82	7333.45
2995.41	7316.02
2998	7264.58
3000.59	7311.74
3003.17	7252.22
3005.76	7251.35
3008.34	7180.67
3010.92	7122.58
3013.5	7123.39
3016.09	7020.8
3018.67	7021.18
3021.25	6941.73
3023.82	6965.45
3026.4	6900.87
3028.98	6885.26
3031.55	6827.64
3034.13	6821.6
3036.7	6883.51
3039.28	6836.32
3041.85	6838.2
3044.42	6846.64
3046.99	6860.29
3049.56	6849.01
3052.13	6904.14
3054.69	6884
3057.26	6889.66
3059.83	6924.53
3062.39	6920.27
3064.95	6939.15
3067.52	6962.04
3070.08	6965.69
3072.64	6922.37
3075.2	6956.34
3077.76	6937.71
3080.32	6967.5
3082.88	6917.15
3085.44	6951.06
3087.99	7002.06
3090.55	7008.48
3093.1	7007.19
3095.65	7009.83
3098.21	7044.25
3100.76	7045.92
3103.31	7104
3105.86	7104.33
3108.41	7131.91
3110.96	7164.53
3113.5	7181.86
3116.05	7239.76
3118.59	7269.7
3121.14	7273.34
3123.68	7293.84
3126.23	7289.08
3128.77	7364.2
3131.31	7413.17
3133.85	7437.79
3136.39	7457.74
3138.93	7496.02
3141.46	7511.01
3144	7564.8
3146.54	7597.4
3149.07	7631.34
3151.6	7622.56
3154.14	7696.62
3156.67	7710.71
3159.2	7784.11
3161.73	7794.32
3164.26	7843.12
3166.79	7826.47
3169.32	7872.82
3171.84	7836.8
3174.37	7862.84
3176.9	7882.99
3179.42	7880.98
3181.94	7867.66
3184.47	7910.95
3186.99	7885.87
3189.51	7930.22
3192.03	7922.33
3194.55	7899.4
3197.07	7912.89
3199.58	7909.37
3202.1	7902.58
3204.62	7908.02
3207.13	7925.95
3209.65	7917.01
3212.16	7934.61
3214.67	7909.79
3217.18	7866.01
3219.69	7887.43
3222.2	7873.87
3224.71	7866.14
3227.22	7875.68
3229.73	7875.93
3232.23	7848.9
3234.74	7854.76
3237.24	7837.3
3239.75	7821.38
3242.25	7835.98
3244.75	7788.71
3247.25	7802.11
3249.75	7776.39
3252.25	7758.49
3254.75	7731.53
3257.25	7713.7
3259.74	7678.41
3262.24	7658.13
3264.73	7666.97
3267.23	7658.05
3269.72	7664.69
3272.21	7644.13
3274.7	7614.53
3277.2	7589.79
3279.69	7606.08
3282.17	7556.72
3284.66	7539.61
3287.15	7584.61
3289.64	7523.66
3292.12	7536.13
3293.56	7533.29
3296.05	7502.35
3298.55	7480.81
3301.04	7515.64
3303.54	7495.98
3306.03	7469.86
3308.52	7470.99
3311.01	7454.66
3313.5	7439.03
3315.99	7440.62
3318.48	7412.99
3320.97	7419.67
3323.45	7447.8
3325.94	7436.14
3328.42	7406.86
3330.91	7397.99
3333.39	7427.57
3335.87	7414.41
3338.36	7360.59
3340.84	7388.32
3343.32	7352.53
3345.8	7408.27
3348.27	7341.73
3350.75	7343.61
3353.23	7331.47
3355.7	7360.19
3358.18	7353.94
3360.65	7328.18
3363.13	7297.84
3365.6	7361.2
3368.07	7323.57
3370.54	7312.57
3373.01	7331.14
3375.48	7357.02
3377.95	7320.73
3380.42	7323.76
3382.88	7288.51
3385.35	7317.31
3387.81	7269.8
3390.28	7268.11
3392.74	7272.49
3395.2	7296.07
3397.67	7260.92
3400.13	7288.83
3402.58	7289.87
3405.05	7227.99
3407.5	7274.5
3409.96	7226.38
3412.42	7237.4
3414.87	7185.66
3417.33	7228.67
3419.78	7209.76
3422.23	7128.62
3424.69	7138.45
3427.14	7126.47
3429.59	7099.19
3432.04	7104.94
3434.49	7060.75
3436.94	7064.59
3439.39	7053.52
3441.83	6965.1
3444.28	6960.55
3446.72	6951.86
3449.17	6963.4
3451.61	6916.41
3454.05	6889.92
3456.5	6896.17
3458.94	6822.75
3461.38	6816.79
3463.81	6820.31
3466.25	6769
3468.69	6750.6
3471.13	6729.04
3473.56	6672.73
3476	6632.05
3478.43	6612.92
3480.87	6553.71
3483.3	6548.67
3485.73	6488.85
3488.16	6483.32
3490.59	6441.59
3493.02	6420.72
3495.45	6374.66
3497.88	6308.68
3499.09	6295.78