File: src/Milk_AI/Heritage full cream RT 785nm 100% 600g 50xL 10s 10times 400-3500cm-1.txt
#Acq. time (s)=	10
#Accumulations=	10
#Range (cm-¹)=	400...3500
#Windows=	6
#Auto scanning=	Off
#Autofocus=	Off
#AutoExposure=	Off
#Spike filter=	Multiple accum.
#Delay time (s)=	0
#Binning=	1
#Readout mode=	Signal
#DeNoise=	Off
#ICS correction=	On
#Dark correction=	Off
#Inst. Process=	Off
#Detector Gain=	Best Dynamic Range
#Detector ADC=	45 kHz
#Detector temperature (°C)=	-60.1
#Instrument=	LabRAM HR Evol
#Detector=	Syncerity OE
#Objective=	x50_VIS_LWD
#Grating=	600 (500nm)
#ND Filter=	100%
#Laser=	785nm_Edge
#Hole=	199.981
#Range=	Visible
#E-Cal_Neon=	0
#StageXY=	75x50mm Scan+
#StageZ=	Z motor
#X (µm)=	0
#Y (µm)=	0
#Z (µm)=	112.1
#Spectral res.(cm-¹)=	5.9
#Full time(mm:ss)=	10:39
#AC=	Calibrated 2025-06-30 10:26
#Project=
#Sample=
#Site=
#Title=	D_101
#Remark=
#Date=	30.06.2025 10:37 (India Standard Time)
#Acquired=	30.06.2025 10:37:34 (India Standard Time)
#AxisType[0]=Intens
#AxisUnit[0]=Cnt
#AxisType[1]=Spectr
#AxisUnit[1]=1/cm
400.049	470.4
403.164	475.438
406.278	464.956
409.39	473.865
412.499	463.128
415.608	458.601
418.715	457.899
421.819	457.222
424.923	438.766
428.024	453.794
431.124	454.944
434.223	452.575
437.319	444.868
440.413	443.009
443.507	449.13
446.598	434.115
449.688	438.148
452.776	438.864
455.862	431.489
458.947	424.532
462.03	430.11
465.111	416.802
468.191	423.461
471.269	415.729
474.345	407.377
477.419	406.405
480.493	409.251
483.564	394.878
486.633	398.242
489.702	381.014
492.767	382.848
495.832	379.799
498.896	379.751
501.956	369.925
505.017	372.609
508.074	378.63
511.131	367.197
514.185	384.416
517.239	366.874
520.289	370.47
523.339	356.339
526.387	365.418
529.433	358.092
532.478	356.701
535.521	350.972
538.563	354.248
541.603	347.135
544.641	338.339
547.677	334.099
550.712	332.261
553.746	330.826
556.776	325.278
559.807	326.252
562.835	320.794
565.861	315.006
568.886	317.05
571.91	324.233
574.932	323.205
577.951	325.3
580.97	311.136
583.987	317.749
587.002	321.644
590.015	325.388
593.027	324.523
596.038	331.448
599.046	337.095
602.054	333.997
605.059	345.464
608.063	336.661
611.065	342.782
614.066	320.259
617.065	316.241
620.062	320.118
623.057	325.613
626.052	312.67
629.044	306.35
632.035	304.694
635.024	296.089
638.012	305.178
640.998	310.53
643.982	314.954
646.965	299.862
649.946	303.061
652.926	292.675
655.904	298.065
658.88	289.29
661.855	279.021
664.829	294.167
667.8	282.485
670.77	282.565
673.738	274.659
676.705	268.481
679.67	271.148
682.634	277.589
685.596	275.647
688.556	265.068
691.515	262.633
694.472	270.471
697.428	269.225
700.382	273.807
703.335	282.654
706.285	276.807
709.234	280.24
712.182	282.291
715.128	285.778
718.073	288.523
721.016	290.025
723.958	305.311
726.897	294.125
729.836	307.701
732.772	286.722
735.707	292.335
738.641	291.302
741.573	296.178
744.503	294.095
747.432	295.274
750.359	289.14
753.285	295.996
756.209	282.661
759.132	300.247
762.052	293.811
764.972	294.842
767.89	292.354
770.806	292.326
773.721	290.645
776.634	289.678
779.546	277.782
782.456	279.914
785.364	286.063
788.271	284.285
791.177	285.037
794.08	278.565
796.983	279.326
799.884	286.234
802.783	290.697
805.681	302.707
808.577	307.278
811.471	317.098
814.364	322.424
817.256	335.283
820.145	351.757
823.034	353.554
825.921	378.31
828.806	383.636
831.69	399.949
834.572	412.497
837.452	430.53
840.332	444.433
843.209	441.048
846.086	452.309
848.96	459.834
851.833	456.028
854.705	458.646
857.575	455.208
860.443	464.333
863.31	475.111
866.176	481.044
869.039	486.158
871.901	487.482
874.762	487.497
877.622	493.235
880.48	483.947
883.336	466.508
886.19	460.367
889.044	484.518
891.896	478.101
894.745	458.459
897.594	429.076
900.442	407.821
903.287	398.975
906.131	376.335
908.974	381.336
911.815	361.941
914.655	371.752
917.493	367.787
920.33	385.858
923.165	377.831
925.998	369.748
928.831	355.183
931.661	331.216
934.49	345.179
937.318	336.998
940.144	322.693
942.968	324.175
945.792	316.89
948.613	316.783
951.433	324.878
954.252	310.896
957.069	304.112
959.885	298.873
962.699	310.554
965.512	287.323
968.322	289.647
971.133	284.338
973.941	287.559
976.748	282.596
979.552	276.582
982.356	268.264
985.159	280.576
987.96	267.566
990.759	268.783
993.557	265.535
996.353	274.567
999.148	283.826
1001.94	325.454
1004.73	376.813
1007.52	316.547
1010.31	297.516
1013.1	311.755
1015.89	310.11
1018.67	308.383
1021.45	311.251
1024.24	308.14
1027.02	312.67
1029.79	332.879
1032.57	329.837
1035.35	329.906
1038.12	344.372
1040.89	326.187
1043.67	342.57
1046.44	334.594
1049.2	337.5
1051.97	341.29
1054.74	354.423
1057.5	375.805
1060.26	417.751
1063.03	461.486
1065.78	461.731
1068.54	432.178
1071.3	415.294
1074.06	431.292
1076.81	457.636
1079.56	454.685
1082.31	462.107
1085.06	427.348
1087.81	419.515
1090.56	394.251
1093.3	358.835
1096.05	341.381
1098.79	315.462
1101.53	295.895
1104.27	284.246
1107.01	271.294
1109.74	264.63
1112.48	265.314
1115.21	271.069
1117.95	280.412
1120.68	289.037
1123.41	292.28
1126.13	290.623
1128.86	283.656
1131.59	251.353
1134.31	231.641
1137.03	223.598
1139.75	222.178
1142.47	223.208
1145.08	221.506
1147.81	220.381
1150.54	230.128
1153.27	216.605
1156	228.356
1158.73	221.997
1161.45	219.638
1164.18	217.626
1166.9	219.63
1169.62	221.112
1172.34	212.465
1175.06	217.869
1177.78	211.62
1180.5	210.83
1183.21	220.512
1185.92	210.09
1188.64	209.557
1191.35	209.78
1194.06	204.589
1196.76	211.02
1199.47	214.442
1202.17	220.182
1204.88	214.135
1207.58	226.839
1210.28	219.625
1212.98	219.261
1215.68	210.949
1218.38	212.213
1221.07	226.715
1223.76	214.983
1226.46	221.16
1229.15	228.913
1231.84	226.439
1234.53	232.636
1237.21	232.174
1239.9	233.901
1242.58	233.429
1245.26	236.41
1247.95	242.79
1250.63	249.356
1253.3	251.081
1255.98	251.384
1258.66	257.013
1261.33	260.168
1264.01	267.586
1266.68	264.167
1269.35	267.641
1272.02	251.847
1274.68	264.669
1277.35	262.065
1280.02	262.772
1282.68	263.261
1285.34	255.027
1288	264.289
1290.66	269.749
1293.32	298.384
1295.98	323.345
1298.63	329.652
1301.29	346.774
1303.94	341.168
1306.59	337.509
1309.24	323.903
1311.89	294.467
1314.54	289.32
1317.18	281.334
1319.83	264.703
1322.47	260.346
1325.11	257.927
1327.75	254.971
1330.39	243.043
1333.03	246.027
1335.66	242.839
1338.3	236.711
1340.93	237.489
1343.57	233.11
1346.2	234.41
1348.83	225.784
1351.45	228.451
1354.08	224.422
1356.71	224.783
1359.33	224.48
1361.96	220.036
1364.58	223.066
1367.2	225.993
1369.82	227.926
1372.43	224.294
1375.05	218.394
1377.67	216.953
1380.28	216.261
1382.89	210.852
1385.5	199.066
1388.11	208.97
1390.72	214.658
1393.33	206.667
1395.93	208.786
1398.54	205.348
1401.14	214.28
1403.74	204.804
1406.34	206.013
1408.94	215.084
1411.54	221.98
1414.14	219.562
1416.73	217.285
1419.32	227.62
1421.92	243.742
1424.51	244.2
1427.1	253.801
1429.69	273.891
1432.27	304.065
1434.86	347.581
1437.44	373.349
1440.03	400.852
1442.61	417.403
1445.19	375.764
1447.77	367.77
1450.35	358.966
1452.92	354.444
1455.5	347.884
1458.07	339.172
1460.65	318.835
1463.22	312.653
1465.79	288.806
1468.36	278.082
1470.93	262.377
1473.49	247.605
1476.06	235.308
1478.62	219.137
1481.18	210.34
1483.74	201.241
1486.3	200.271
1488.86	182.577
1491.42	190.487
1493.97	192.564
1496.53	186.371
1499.08	186.522
1501.64	180.654
1504.19	183.171
1506.74	179.165
1509.28	170.996
1511.83	174.938
1514.38	171.683
1516.92	167.141
1519.46	172.222
1522.01	179.977
1524.55	172.195
1527.08	181.9
1529.62	176.939
1532.16	175.934
1534.69	172.403
1537.23	180.682
1539.76	170.289
1542.29	167.586
1544.82	168.783
1547.35	164.329
1549.88	173.083
1552.41	176.437
1554.93	187.395
1557.45	193.06
1559.98	174.296
1562.5	170.489
1565.02	158.975
1567.54	166.49
1570.06	155.927
1572.57	161.322
1575.09	172.18
1577.6	160.294
1580.11	171.103
1582.62	160.224
1585.13	165.486
1587.64	163.194
1590.15	161.535
1592.66	167.316
1595.16	162.484
1597.66	157.79
1600.17	177.44
1602.67	170.999
1605.17	161.735
1607.66	177.502
1610.16	165.69
1612.66	166.888
1615.15	169.706
1617.65	181.536
1620.14	156.005
1622.63	175.333
1625.12	167.033
1627.61	167.147
1630.1	171.321
1632.58	173.474
1635.07	158.543
1637.55	166.909
1640.03	172.504
1642.51	181.996
1644.99	186.445
1647.47	195.953
1649.95	201.317
1652.42	220.433
1654.9	232.784
1657.37	240.033
1659.85	212.583
1662.32	193.894
1664.79	185.055
1667.26	184.222
1669.72	183.931
1672.19	182.056
1674.65	172.225
1677.12	174.191
1679.58	168.145
1682.04	165.619
1684.5	157.293
1686.96	160.246
1689.42	153.56
1691.87	152.646
1694.33	141.571
1696.78	147.246
1699.23	144.438
1701.69	150.168
1704.14	150.429
1706.58	146.65
1709.03	140.413
1711.48	140.398
1713.92	142.657
1716.37	145.668
1718.81	139.068
1721.25	140.616
1723.69	138.045
1726.13	150.616
1728.57	143.471
1731.01	148.003
1733.44	144.741
1735.88	158.539
1738.31	154.68
1740.39	157.168
1742.84	161.309
1745.28	155.162
1747.72	152.76
1750.17	157.743
1752.61	158.616
1755.05	159.028
1757.49	147.531
1759.92	153.363
1762.36	139.584
1764.8	132.839
1767.23	130.344
1769.66	148.673
1772.09	147.854
1774.52	142.866
1776.95	140.465
1779.38	138.751
1781.81	139.206
1784.23	140.189
1786.66	134.745
1789.08	130.009
1791.5	138.899
1793.92	134.734
1796.34	138.503
1798.76	127.388
1801.18	146.852
1803.6	131.865
1806.01	140.938
1808.42	141.302
1810.84	141.638
1813.25	125.134
1815.66	134.668
1818.07	130.589
1820.48	141.872
1822.88	130.626
1825.29	136.001
1827.69	133.907
1830.1	137.045
1832.5	130.362
1834.9	128.734
1837.3	140.771
1839.7	128.592
1842.09	136.181
1844.49	142.539
1846.88	156.129
1849.28	128.859
1851.67	142.527
1854.06	128.249
1856.45	130.041
1858.84	130.673
1861.23	133.364
1863.62	126.046
1866	133.636
1868.39	132.593
1870.77	137.403
1873.15	124.615
1875.53	130.437
1877.91	130.409
1880.29	143.067
1882.67	138.726
1885.04	126.132
1887.42	131.113
1889.79	131.963
1892.17	138.723
1894.54	135.031
1896.91	132.492
1899.28	125.827
1901.65	139.176
1904.01	128.206
1906.38	133.628
1908.74	122.033
1911.11	132.522
1913.47	133.546
1915.83	137.741
1918.19	136.303
1920.55	138.085
1922.91	129.664
1925.26	138.471
1927.62	132.606
1929.97	138.33
1932.33	128.612
1934.68	135.738
1937.03	133.077
1939.38	132.853
1941.73	130.587
1944.08	127.246
1946.42	125.827
1948.77	132.083
1951.11	126.407
1953.46	148.28
1955.8	128.598
1958.14	128.463
1960.48	128.409
1962.82	137.87
1965.15	124.884
1967.49	134.126
1969.82	129.558
1972.16	131.081
1974.49	128.915
1976.82	133.28
1979.15	122.72
1981.48	137.208
1983.81	136.217
1986.14	132.402
1988.46	123.756
1990.79	129.41
1993.11	129.435
1995.43	144.123
1997.76	131.259
2000.08	127.456
2002.4	137.338
2004.71	131.49
2007.03	133.712
2009.35	136.689
2011.66	132.295
2013.98	133.126
2016.29	129.78
2018.6	129.78
2020.91	122.824
2023.22	122.799
2025.53	143.296
2027.83	137.337
2030.14	133.129
2032.44	132.91
2034.75	127.085
2037.05	131.837
2039.35	129.008
2041.65	132.432
2043.95	132.856
2046.25	135.346
2048.55	150.678
2050.84	137.279
2053.14	138.543
2055.43	137.883
2057.72	138.101
2060.01	128.223
2062.3	140.628
2064.59	132.412
2066.88	135.86
2069.17	142.641
2071.45	131.703
2073.74	131.883
2076.02	131.109
2078.3	144.736
2080.59	127.977
2082.87	138.758
2085.14	128.521
2087.42	139.178
2089.7	136.763
2091.98	136.282
2094.25	129.293
2096.52	132.703
2098.8	135.491
2101.07	135.252
2103.34	131.845
2105.61	146.627
2107.88	143.752
2110.14	132.272
2112.41	138.335
2114.67	135.895
2116.94	146.125
2119.2	138.356
2121.46	141.244
2123.72	132.881
2125.98	135.411
2128.24	145.419
2130.5	126.142
2132.75	149.044
2135.01	146.367
2137.26	138.616
2139.52	142.696
2141.77	135.647
2144.02	126.908
2146.27	139.516
2148.52	144.884
2150.76	141.719
2153.01	134.144
2155.26	139.483
2157.5	140.733
2159.74	141.011
2161.99	141.633
2164.23	136.975
2166.47	136.872
2168.71	127.538
2170.94	146.499
2173.18	137.833
2175.42	135.59
2177.65	133.669
2179.89	154.254
2182.12	136.636
2184.35	147.531
2186.58	130.858
2188.81	132.285
2191.04	139.299
2193.26	142.037
2195.49	138.717
2197.72	147.052
2199.94	141.948
2202.16	137.034
2204.38	134.758
2206.6	135.821
2208.82	140.751
2211.04	144.817
2213.26	139.179
2215.48	143.825
2217.69	137.276
2219.91	142.043
2222.12	152.648
2224.33	128.487
2226.54	143.786
2228.75	130.712
2230.96	143.135
2233.17	133.128
2235.38	139.232
2237.58	141.012
2239.79	145.146
2241.99	138.75
2244.2	134.636
2246.4	141.848
2248.6	138.768
2250.8	142.207
2253	141.063
2255.19	142.185
2257.39	134.57
2259.59	134.461
2261.78	128.47
2263.97	141.036
2266.17	139.581
2268.36	148.589
2270.55	137.837
2272.74	144.735
2274.68	125.504
2276.88	146.646
2279.08	127.528
2281.28	144.169
2283.48	125.097
2285.68	155.843
2287.87	141.432
2290.07	138.735
2292.26	134.033
2294.46	132.81
2296.65	149.507
2298.84	143.627
2301.03	152.435
2303.22	131.88
2305.41	139.349
2307.59	152.442
2309.78	142.26
2311.96	150.949
2314.15	122.994
2316.33	153.963
2318.51	149.25
2320.69	145.003
2322.87	146.277
2325.05	150.991
2327.23	163.26
2329.41	168.803
2331.58	210.971
2333.76	131.523
2335.93	167.919
2338.1	143.776
2340.28	155.975
2342.45	141.7
2344.62	135.68
2346.78	144.609
2348.95	149.757
2351.12	133.079
2353.28	151.642
2355.45	151.255
2357.61	161.645
2359.77	147.293
2361.94	149.17
2364.1	151.767
2366.26	164.123
2368.42	156.851
2370.57	147.584
2372.73	161.468
2374.88	164.247
2377.04	155.781
2379.19	152.156
2381.34	165.146
2383.5	150.738
2385.65	155.884
2387.8	134.572
2389.94	170.223
2392.09	137.535
2394.24	153.923
2396.38	146.668
2398.53	156.083
2400.67	148.202
2402.81	157.791
2404.96	151.296
2407.1	171.481
2409.24	149.99
2411.37	154.964
2413.51	153.211
2415.65	156.052
2417.78	161.078
2419.92	173.222
2422.05	165.529
2424.18	165.665
2426.31	153.283
2428.44	157.876
2430.57	162.287
2432.7	171.745
2434.83	162.921
2436.96	158.719
2439.08	160.316
2441.21	158.171
2443.33	157.33
2445.45	162.801
2447.57	164.92
2449.69	157.156
2451.81	169.236
2453.93	160.659
2456.05	171.522
2458.17	154.192
2460.28	182.753
2462.4	177.034
2464.51	166.286
2466.62	179.592
2468.74	172.75
2470.85	176.885
2472.96	167.342
2475.06	157.806
2477.17	184.179
2479.28	188.9
2481.38	179.068
2483.49	170.438
2485.59	168.222
2487.7	203.353
2489.8	173.466
2491.9	186.205
2494	175.09
2496.1	184.229
2498.2	165.848
2500.29	182.561
2502.39	158.861
2504.48	167.14
2506.58	157.709
2508.67	187.366
2510.76	159.197
2512.86	192.778
2514.95	156.897
2517.03	186.752
2519.12	177.271
2521.21	173.507
2523.3	195.884
2525.38	185.569
2527.47	179.098
2529.55	181.275
2531.63	184.75
2533.71	190.918
2535.79	194.153
2537.87	176.612
2539.95	189.491
2542.03	192.051
2544.11	197.41
2546.18	199.678
2548.26	177.14
2550.33	203.31
2552.4	191.877
2554.48	189.917
2556.55	200.496
2558.62	185.83
2560.69	200.319
2562.75	193.461
2564.82	194.435
2566.89	208.77
2568.95	181.624
2571.02	202.851
2573.08	197.756
2575.14	202.628
2577.2	207.852
2579.26	205.919
2581.32	203.51
2583.38	199.275
2585.44	186.494
2587.5	233.809
2589.55	191.038
2591.61	205.843
2593.66	192.657
2595.71	187.137
2597.76	207.221
2599.82	216.149
2601.87	195.662
2603.91	198.028
2605.96	228.405
2608.01	242.514
2610.06	206.465
2612.1	200.889
2614.15	205.246
2616.19	201.344
2618.23	198.377
2620.27	187.081
2622.31	220.687
2624.35	197.955
2626.39	222.72
2628.43	212.627
2630.47	213.887
2632.5	166.013
2634.54	230.183
2636.57	213.256
2638.6	216.285
2640.64	208.504
2642.67	238.106
2644.7	194.098
2646.73	245.809
2648.75	222.095
2650.78	246.5
2652.81	219.663
2654.83	209.927
2656.86	223.632
2658.88	222.094
2660.91	210.383
2662.93	243.9
2664.95	204.502
2666.97	227.108
2668.99	232.763
2671.01	225.5
2673.02	207.392
2675.04	239.847
2677.05	234.356
2679.07	229.17
2681.08	233.599
2683.09	224.966
2685.11	227.62
2687.12	238.955
2689.13	236.604
2691.14	226.39
2693.14	237.813
2695.15	236.767
2697.16	241.824
2699.16	232.76
2701.17	238.533
2703.17	239.604
2705.17	238.231
2707.17	241.073
2709.17	260.913
2711.17	247.001
2713.17	260.051
2715.17	244.855
2717.17	231.209
2719.16	266.02
2721.16	220.149
2723.15	254.291
2725.14	222.843
2727.14	238.048
2729.13	224.964
2731.12	250.635
2733.11	231.659
2735.1	257.023
2737.09	239.442
2739.07	252.101
2741.06	237.296
2743.04	261.801
2745.03	237.28
2747.01	295.352
2748.99	255.287
2750.97	267.823
2752.95	264.743
2754.93	262.455
2756.81	270.668
2758.8	264.963
2760.79	272.507
2762.78	273.569
2764.77	274.419
2766.76	265.499
2768.74	286.434
2770.73	244.137
2772.71	257.925
2774.7	238.807
2776.68	264.471
2778.66	262.79
2780.64	276.002
2782.63	301.753
2784.6	254.788
2786.58	277.712
2788.56	307.515
2790.54	273.482
2792.51	278.93
2794.49	249.68
2796.46	277.179
2798.44	270.916
2800.41	300.145
2802.38	304.43
2804.35	357.728
2806.32	289.216
2808.29	336.511
2810.26	259.261
2812.23	317.383
2814.19	307.156
2816.16	292.739
2818.12	275.872
2820.09	326.056
2822.05	296.91
2824.01	315.112
2825.97	280.771
2827.93	302.588
2829.89	258.061
2831.85	287.394
2833.81	284.966
2835.76	302.526
2837.72	286.973
2839.67	313.189
2841.63	318.32
2843.58	355.181
2845.53	335.705
2847.48	339.264
2849.44	340.345
2851.39	361.005
2853.33	393.385
2855.28	358.101
2857.23	443.777
2859.18	342.887
2861.12	345.054
2863.06	329.622
2865.01	381.302
2866.95	362.889
2868.89	357.721
2870.83	360.2
2872.77	380.085
2874.71	361.266
2876.65	344.298
2878.59	341.87
2880.52	348.408
2882.46	370.032
2884.4	350.945
2886.33	387.274
2888.26	358.721
2890.2	365.962
2892.13	345.026
2894.06	370.529
2895.99	396.247
2897.92	380.121
2899.84	371.325
2901.77	380.003
2903.7	327.474
2905.62	390.92
2907.55	318.672
2909.47	396.04
2911.39	435.263
2913.31	369.775
2915.24	409.122
2917.16	364.496
2919.08	356.524
2920.99	423.908
2922.91	402.947
2924.83	400.068
2926.74	339.975
2928.66	379.112
2930.57	369.555
2932.49	400.102
2934.4	348.452
2936.31	365.37
2938.22	408.82
2940.13	407.555
2942.04	358.216
2943.95	376.962
2945.86	403.076
2947.76	422.389
2949.67	363.486
2951.57	383.61
2953.48	329.783
2955.38	371.941
2957.28	347.595
2959.18	382.786
2961.08	390.457
2962.98	375.398
2964.88	384.417
2966.78	382.436
2968.68	339.792
2970.57	367.227
2972.47	350.007
2974.37	389.343
2976.26	378.111
2978.15	371.933
2980.04	376.377
2981.94	335.363
2983.83	365.206
2985.72	341.21
2987.6	365.923
2989.49	337.814
2991.38	405.252
2993.27	388.078
2995.15	386.344
2997.04	344.272
2998.92	388.894
3000.8	371.453
3002.68	433.555
3004.57	387.08
3006.45	368.458
3008.33	384.79
3010.2	415.179
3012.08	410.217
3013.96	413.769
3015.84	384.471
3017.71	429.143
3019.59	388.001
3021.46	439.965
3023.33	443.97
3025.2	438.763
3027.08	438.282
3028.95	444.854
3030.82	455.526
3032.68	381.236
3034.55	460.82
3036.42	384.25
3038.29	488.305
3040.15	398.299
3042.02	424.842
3043.88	411.082
3045.74	421.22
3047.6	392.093
3049.47	469.501
3051.33	434.401
3053.19	453.945
3055.04	432.522
3056.9	452.851
3058.76	383.464
3060.62	408.028
3062.47	467.115
3064.33	460.854
3066.18	450.69
3068.03	483.261
3069.89	504.122
3071.74	457.95
3073.59	571.055
3075.44	474.556
3077.29	514.734
3079.13	473.489
3080.98	593.887
3082.83	434.55
3084.67	593.283
3086.52	497.675
3088.36	544.677
3090.21	497.005
3092.05	521.13
3093.89	542.966
3095.73	555.961
3097.57	541.23
3099.41	570.045
3101.25	503.394
3103.09	600.833
3104.92	533.71
3106.76	609.891
3108.59	545.925
3110.43	600.943
3112.26	585.786
3114.09	513.137
3115.93	484.437
3117.76	550.15
3119.59	563.988
3121.42	615.469
3123.24	623.054
3125.07	621.894
3126.9	551.166
3128.73	632.379
3130.55	633.116
3132.38	646.616
3134.2	602.16
3136.02	621.938
3137.84	628.846
3139.67	674.422
3141.49	700.228
3143.31	552.023
3145.13	666.159
3146.94	729.976
3148.76	701.806
3150.58	640.199
3152.39	637.047
3154.21	730.421
3156.02	680.665
3157.84	711.898
3159.65	654.753
3161.46	725.073
3163.27	723.757
3165.08	634.658
3166.89	748.303
3168.7	756.182
3170.51	753.769
3172.31	701.122
3174.12	743.003
3175.92	693.105
3177.73	713.038
3179.53	748.711
3181.34	844.551
3183.14	747.832
3184.94	837.471
3186.74	815.849
3188.54	763.511
3190.34	790.403
3192.14	880.17
3193.57	678.182
3195.38	820.706
3197.19	686.116
3199	736.709
3200.81	722.574
3202.61	799.42
3204.42	778.397
3206.22	846.175
3208.03	796.936
3209.83	925.436
3211.63	792.739
3213.43	875.42
3215.23	881.045
3217.03	740.29
3218.83	841.552
3220.63	897.81
3222.43	909.484
3224.23	844.396
3226.02	973.278
3227.82	863.825
3229.61	877.398
3231.41	828.746
3233.2	940.224
3234.99	903.525
3236.78	936.991
3238.58	775.486
3240.37	912.28
3242.16	881.267
3243.94	1026.61
3245.73	954.481
3247.52	924.663
3249.31	965.893
3251.09	1009.9
3252.87	933.609
3254.66	890.666
3256.44	844.052
3258.22	988.633
3260	880.41
3261.79	908.574
3263.57	994.233
3265.35	820.917
3267.12	917.94
3268.9	867.837
3270.68	939.575
3272.45	903.897
3274.23	920.918
3276.01	905.42
3277.78	907.804
3279.55	1007.52
3281.32	922.285
3283.1	984.889
3284.87	949.379
3286.64	1028.42
3288.41	1147.35
3290.17	1006.61
3291.94	1006.63
3293.71	1080.4
3295.48	1021.41
3297.24	1022.88
3299.01	1048.35
3300.77	1007.17
3302.53	1167.46
3304.3	1161.11
3306.06	1143.06
3307.82	1200.67
3309.58	1158.19
3311.34	1049.75
3313.1	1108.97
3314.85	988.748
3316.61	1004.86
3318.37	1050.3
3320.12	990.417
3321.88	1037.4
3323.63	1060.86
3325.39	1015.3
3327.14	1146.39
3328.89	1003.81
3330.64	1106.21
3332.39	1007.57
3334.14	1101.42
3335.89	1114.15
3337.64	1087.53
3339.39	1135.7
3341.13	1140.87
3342.88	1123.24
3344.62	1232.44
3346.37	1115.48
3348.11	1180.3
3349.85	1189.81
3351.6	1164.91
3353.34	1213.59
3355.08	1094.43
3356.82	1189.91
3358.56	1154.62
3360.3	1180.71
3362.03	1223.79
3363.77	1060.52
3365.51	1226.95
3367.24	1333.47
3368.98	1171.54
3370.71	1210.29
3372.44	1210.99
3374.18	1304.73
3375.91	1277.09
3377.64	1123.5
3379.37	1449.57
3381.1	1212.34
3382.83	1273.98
3384.56	1253.89
3386.28	1141.53
3388.01	1333.14
3389.73	1398.53
3391.46	1336.8
3393.18	1351.7
3394.91	1157.85
3396.63	1368.81
3398.35	1284.09
3400.07	1246.97
3401.79	1171.37
3403.51	1402.71
3405.23	1260.23
3406.95	1336.31
3408.67	1186.14
3410.39	1452.99
3412.1	1148.81
3413.82	1393.19
3415.53	1189.84
3417.25	1297.65
3418.96	1345.23
3420.67	1419.03
3422.38	1351.43
3424.09	1284.32
3425.81	1333.5
3427.51	1354.09
3429.22	1328.93
3430.93	1450.1
3432.64	1353.77
3434.35	1365.21
3436.05	1537.07
3437.76	1276.55
3439.46	1442.9
3441.17	1414.6
3442.87	1484.72
3444.57	1314.35
3446.27	1457.75
3447.97	1374.1
3449.67	1371.35
3451.37	1222.05
3453.07	1657.72
3454.77	1065.63
3456.47	1303.85
3458.16	1391.3
3459.86	1534.44
3461.55	1437.71
3463.25	1383.08
3464.94	1568.15
3466.63	1533.76
3468.33	1382.92
3470.02	1516.52
3471.71	1426.65
3473.4	1697.45
3475.09	1511.72
3476.78	1526.14
3478.46	1304.55
3480.15	1450.9
3481.84	1680.43
3483.52	1496.31
3485.21	1584.72
3486.89	1577.32
3488.58	1508.03
3490.26	1464.63
3491.94	1534.01
3493.62	1315.7
3495.3	1636.84
3496.98	1545.67
3498.66	1576.05
3499.92	1369.45