File: src/Milk_AI/Nandani toned milk RT 532nm 50% 600g 50xL 10s 10times 400-3500cm-1 200hole after heating.txt
#Acq. time (s)=	10
#Accumulations=	10
#Range (cm-¹)=	400...3500
#Windows=	3
#Auto scanning=	Off
#Autofocus=	Off
#AutoExposure=	Off
#Spike filter=	Multiple accum.
#Delay time (s)=	0
#Binning=	1
#Readout mode=	Signal
#DeNoise=	Off
#ICS correction=	On
#Dark correction=	Off
#Inst. Process=	Off
#Detector Gain=	Best Dynamic Range
#Detector ADC=	45 kHz
#Detector temperature (°C)=	-60.1
#Instrument=	LabRAM HR Evol
#Detector=	Syncerity OE
#Objective=	x50_VIS_LWD
#Grating=	600 (500nm)
#ND Filter=	50%
#Laser=	532nm_Edge
#Hole=	199.981
#Range=	Visible
#E-Cal_Neon=	0
#StageXY=	75x50mm Scan+
#StageZ=	Z motor
#X (µm)=	0
#Y (µm)=	0
#Z (µm)=	815.5
#Spectral res.(cm-¹)=	12.8
#Full time(mm:ss)=	5:19
#AC=	Calibrated 2025-06-30 10:26
#Project=
#Sample=
#Site=
#Title=	D_100
#Remark=
#Date=	30.06.2025 14:01 (India Standard Time)
#Acquired=	30.06.2025 14:01:53 (India Standard Time)
#AxisType[0]=Intens
#AxisUnit[0]=Cnt
#AxisType[1]=Spectr
#AxisUnit[1]=1/cm
400.17	21528.5
403.717	21438.4
407.263	21425.7
410.807	21399.8
414.35	21351.6
417.892	21417.7
421.432	21409.8
424.971	21344.3
428.509	21423.2
432.045	21395.7
435.58	21449.2
439.111	21376.2
442.643	21304.7
446.174	21241.2
449.701	21262.3
453.229	21269.3
456.756	21176.2
460.279	21140.3
463.803	21133.2
467.326	21071.3
470.845	21043.4
474.365	21055.5
477.882	21040.2
481.399	21017.1
484.913	20974.2
488.425	20977.1
491.938	20915.2
495.448	20895.9
498.956	20990.9
502.465	20993.4
505.971	20998.4
509.475	20974.3
512.981	20952.1
516.482	20982.8
519.983	20969.6
523.482	20936.4
526.979	20842.4
530.476	20780.4
533.971	20676.7
537.464	20670.3
540.956	20610.4
544.447	20560.7
547.937	20606.6
551.425	20501.2
554.912	20566
558.398	20505.2
561.882	20459.9
565.365	20500.3
568.847	20454.8
572.325	20450.6
575.804	20488.3
579.282	20517.7
582.756	20460.5
586.231	20507.8
589.705	20508.7
593.175	20484.4
596.646	20494.2
600.116	20485.4
603.582	20547.9
607.049	20450.9
610.513	20416.2
613.977	20340.6
617.438	20332.9
620.898	20261.3
624.359	20106.6
627.816	20081.2
631.272	19990.4
634.728	20024.5
638.181	19970.4
641.633	20032
645.084	19974.3
648.535	19853.6
651.983	19877.7
655.43	19831.4
658.875	19852.2
662.319	19820.1
665.762	19808
669.203	19766.2
672.643	19720.4
676.082	19706.8
679.519	19697.5
682.955	19726.7
686.39	19702.3
689.824	19707.1
693.256	19691.4
696.685	19661.5
700.115	19745.9
703.543	19706.2
706.97	19673.1
710.394	19642.5
713.818	19581.6
717.241	19629.4
720.661	19607.3
724.082	19557.4
727.501	19562.3
730.917	19516.7
734.334	19463.1
737.747	19433.3
741.161	19372.5
744.572	19383.2
747.982	19423.3
751.392	19340.9
754.799	19414.5
758.205	19498.7
761.611	19395
765.014	19433.8
768.416	19432
771.816	19436.5
775.218	19367.8
778.616	19405.9
782.012	19424
785.408	19447.7
788.802	19380.7
792.195	19373.7
795.586	19345.8
798.977	19313.7
802.365	19342.2
805.753	19411.7
809.14	19366.3
812.525	19307.7
815.907	19285.4
819.289	19381.1
822.671	19402.3
826.051	19479.9
829.43	19454.1
832.805	19509.6
836.182	19505.9
839.557	19555.1
842.928	19642.2
846.301	19647.8
849.67	19692.1
853.04	19639.3
856.407	19724.1
859.774	19769.9
863.138	19791.1
866.503	19810.1
869.865	19851.6
873.225	19813.8
876.586	19779.1
879.944	19656.8
883.301	19570.4
886.658	19573.6
890.012	19591
893.365	19514.7
896.717	19351.2
900.067	19191.4
903.416	19138.4
906.766	19056.1
910.112	18921.8
913.458	18952.6
916.802	18811.8
920.145	18862.5
923.484	18771.9
926.825	18678.5
930.164	18629.3
933.501	18560
936.838	18546.8
940.173	18552.7
943.505	18542.3
946.838	18620.2
950.17	18598.5
953.5	18620.1
956.827	18665.6
960.155	18649.6
963.48	18620.9
966.805	18536.7
970.128	18487.6
973.45	18439.9
976.77	18314.4
980.091	18356.8
983.408	18320.1
986.726	18366.2
990.041	18491.5
993.354	18555.5
996.668	18798.2
999.979	19168.5
1003.29	19532.3
1006.6	19466.5
1009.91	19091.8
1013.21	18874.3
1016.52	18654.7
1019.82	18562.8
1023.12	18566.4
1026.43	18365
1029.73	18302.1
1033.02	18266
1036.32	18209
1039.62	18189.3
1042.91	18157.4
1046.21	18088.3
1049.5	18115.6
1052.79	18069.9
1056.08	18280.9
1059.37	18351.2
1062.65	18567.9
1065.94	18607.6
1069.23	18386.8
1072.51	18544.5
1075.79	18594.6
1079.07	18740.2
1082.35	18665.9
1085.63	18581.5
1088.91	18390.6
1092.18	18253
1095.46	18029.2
1098.73	17888.7
1102	17718.4
1105.27	17560.1
1108.54	17552.1
1111.81	17605.1
1115.08	17791.3
1118.34	17912.8
1121.61	17944.7
1124.87	18009.2
1128.13	17856.7
1131.39	17692.4
1134.65	17596.9
1137.91	17565.1
1141.17	17681.9
1144.42	18051.8
1147.68	18555.9
1150.93	19479.6
1154.18	20600.2
1157.43	21128.2
1160.68	20035.7
1163.93	18536.3
1167.18	17728.3
1170.42	17572.6
1173.67	17340.4
1176.91	17107
1180.15	16997.2
1183.39	17066.6
1186.63	17105.4
1189.87	17205.8
1193.11	17196.4
1196.34	17033.6
1199.58	16907.6
1202.81	16674.5
1206.04	16583.7
1209.27	16643.6
1212.5	16626.5
1215.73	16477.3
1218.95	16354.3
1222.18	16254.4
1225.4	16252.7
1228.63	16220
1231.85	16228.4
1235.07	16190.4
1238.29	16210.6
1241.51	16312.6
1244.72	16389.7
1247.94	16418.3
1251.15	16470.7
1254.37	16457.1
1257.58	16566.5
1260.79	16658.8
1264	16716.3
1267.21	16829.6
1270.41	16645.7
1273.62	16599.3
1276.82	16500.9
1280.03	16417.2
1283.23	16446.4
1286.43	16504.8
1289.63	16623.2
1292.83	16873
1296.03	17245.9
1299.22	17516.9
1302.42	17677.6
1305.61	17501.6
1308.8	17151.7
1311.99	16946.8
1315.18	16559.2
1318.37	16267.8
1321.56	16026.2
1324.74	15899
1327.93	15849.4
1331.11	15647.3
1334.3	15586.5
1337.48	15546.2
1340.66	15500.6
1343.84	15464.7
1347.01	15438.4
1350.19	15443.6
1353.37	15398.2
1356.54	15289.2
1359.71	15174.7
1362.88	15168.3
1366.05	15174.4
1369.22	15115.9
1372.39	15043.9
1375.56	14851.8
1378.72	14881.1
1381.89	14730.9
1385.05	14695.8
1388.21	14819.8
1391.37	14741.2
1394.53	14713.2
1397.69	14575.4
1400.85	14659.1
1404	14630.5
1407.16	14638.8
1410.31	14744.8
1413.46	14709
1416.61	14937.6
1419.76	15021.3
1422.91	15192.5
1426.06	15348.5
1429.21	15905.6
1432.35	16762.5
1435.49	17570.6
1438.64	18050.3
1441.78	17994.7
1444.92	17754.1
1448.06	17498.8
1451.2	17274.5
1454.33	17068
1457.47	16865.2
1460.6	16489.7
1463.74	16132.5
1466.87	15725.1
1470	15288.5
1473.13	14888.4
1476.26	14654.8
1479.38	14408.7
1482.51	14266.1
1485.63	14226.8
1488.76	14242.7
1491.88	14219.4
1495	14333.2
1498.12	14373.4
1501.24	14505.9
1504.36	14754.8
1507.47	15044.9
1510.59	15684.3
1513.7	16454.6
1516.81	17191.2
1519.93	17727
1523.04	17725.9
1526.15	17316.9
1529.25	16395.6
1532.36	15297.8
1535.47	14513.4
1538.57	14047.5
1541.67	13721.3
1544.78	13483.1
1547.88	13421.5
1550.98	13308.9
1554.08	13296
1557.18	13316.8
1560.27	13159.6
1563.37	13159.9
1566.46	13080.2
1569.55	13094.8
1572.64	13132.8
1575.74	13077.6
1578.83	13084.7
1581.91	13056.1
1585	13000.8
1588.09	13001.3
1591.17	12983.3
1594.25	12978.5
1597.34	12959
1600.42	12951.4
1603.5	12981.8
1606.58	12891.5
1609.65	12886.6
1612.73	12841.5
1615.8	12764.8
1618.88	12785.7
1621.95	12717.7
1625.03	12736.3
1628.1	12755.3
1631.17	12742.2
1634.23	12756.9
1637.3	12874.1
1640.37	12953.4
1643.43	12975.2
1646.5	13235.5
1649.56	13767
1652.62	14071.5
1655.68	14048.4
1658.74	13662.4
1661.8	13218
1664.85	12916.7
1667.91	12814.3
1670.96	12713.9
1674.02	12551.6
1677.07	12365.9
1680.12	12265.8
1683.17	12186.6
1686.22	12073.2
1689.27	11982.7
1692.31	11950.6
1695.36	11843.7
1698.4	11866.3
1701.45	11747.3
1704.49	11755.9
1707.53	11686.5
1710.57	11632.2
1713.61	11616.3
1716.65	11620.1
1719.68	11547.8
1722.72	11559
1725.75	11542.8
1728.78	11567.4
1731.82	11645.1
1734.84	11746.5
1737.87	11849
1740.9	11964.7
1743.93	11981.3
1746.96	12000.9
1749.98	11941.4
1753	11763.3
1756.03	11605.5
1759.05	11437.2
1762.07	11285.8
1765.09	11194.2
1768.11	11139
1771.12	11100.8
1774.14	11071.8
1777.15	10992.7
1780.17	11051
1783.18	10983.8
1786.19	10967
1789.2	10943.3
1792.21	10856.1
1795.22	10945.1
1798.22	10845.1
1801.23	10853.6
1804.23	10831.4
1807.24	10773.4
1810.24	10820
1813.24	10763.7
1816.24	10768.8
1819.24	10647.2
1822.24	10672.8
1825.23	10669.8
1828.23	10635.3
1831.22	10636.9
1834.22	10607
1837.21	10521
1840.2	10530
1843.19	10528.3
1846.18	10559.7
1849.17	10472.6
1852.15	10410.8
1855.14	10430.2
1858.12	10399.4
1861.11	10414.4
1864.09	10388
1867.07	10341.3
1870.05	10315.8
1873.03	10335
1876.01	10320.1
1878.98	10263.5
1881.96	10231.9
1884.93	10220.6
1887.91	10149.4
1890.88	10121.1
1893.85	10129.2
1896.82	10092.4
1899.79	10034.9
1902.76	9993.46
1905.72	9872.52
1908.69	9845.38
1911.65	9773.31
1914.62	9732.18
1917.58	9625.63
1920.54	9555.31
1923.5	9458.06
1926.46	9456.39
1929.42	9373.12
1932.37	9264.93
1935.33	9238.96
1938.28	9177.95
1941.24	9111.08
1944.19	9054.14
1947.14	9017.89
1950.09	8943.7
1953.04	8854.51
1955.99	8770.39
1958.93	8722.03
1961.88	8676.79
1964.82	8600.64
1967.77	8525.36
1970.71	8474.98
1973.65	8445.98
1976.59	8404.25
1979.53	8333.08
1982.47	8288.88
1985.41	8254.54
1988.34	8187.5
1991.28	8106.14
1994.21	8056.41
1997.14	7999.79
2000.07	7941.96
2003.01	7901.65
2005.94	7866.75
2008.86	7815.08
2011.79	7788.13
2014.72	7735.22
2017.64	7679.67
2020.57	7626.56
2023.49	7564.59
2026.41	7521.79
2029.33	7493.58
2032.25	7488.85
2035.17	7416.47
2038.09	7390.81
2041	7345.58
2043.92	7343.17
2045.86	7269.88
2048.79	7247.3
2051.71	7260.34
2054.64	7256.53
2057.56	7247.91
2060.48	7210.84
2063.4	7208.57
2066.32	7148.49
2069.24	7191.66
2072.16	7129.69
2075.08	7121.52
2077.99	7144.83
2080.91	7126.92
2083.82	7141.52
2086.74	7102.95
2089.65	7097.81
2092.56	7070.75
2095.47	7040.94
2098.38	7029.37
2101.29	7045.01
2104.19	6993.93
2107.1	7008.57
2110	6968.65
2112.91	6987.14
2115.81	6948.71
2118.71	6930.6
2121.61	6889.66
2124.51	6941.08
2127.4	6894.68
2130.3	6887.32
2133.2	6855.13
2136.09	6873.84
2138.99	6848.73
2141.88	6873.86
2144.77	6807.32
2147.66	6826.05
2150.55	6772.53
2153.44	6767.24
2156.33	6816.69
2159.21	6790.91
2162.1	6760.16
2164.98	6752.51
2167.87	6746.69
2170.75	6762.48
2173.63	6755.15
2176.51	6669.81
2179.39	6684.41
2182.27	6678.19
2185.14	6657.23
2188.02	6678.31
2190.9	6634.86
2193.77	6606.75
2196.64	6600.93
2199.51	6582.26
2202.39	6570.43
2205.25	6541.46
2208.12	6556.62
2210.99	6531.16
2213.86	6498.8
2216.72	6476.28
2219.59	6445.35
2222.45	6445.1
2225.31	6417.77
2228.17	6420.33
2231.03	6368.18
2233.89	6354.27
2236.75	6328.14
2239.61	6342.52
2242.46	6330.41
2245.32	6270.24
2248.17	6307.86
2251.03	6279.14
2253.88	6243.91
2256.73	6191.65
2259.58	6185.9
2262.43	6146.23
2265.28	6122.99
2268.12	6133.69
2270.97	6082.62
2273.81	6084.89
2276.66	6087.88
2279.5	6046.38
2282.34	6039.61
2285.18	6004.17
2288.02	5995.01
2290.86	5987.88
2293.7	5976.31
2296.54	5972.77
2299.37	5957.15
2302.21	5932.86
2305.04	5926.44
2307.87	5911.08
2310.7	5892.96
2313.53	5861.87
2316.36	5830.53
2319.19	5811.53
2322.02	5786.56
2324.85	5832.83
2327.67	5979.03
2330.5	6058.08
2333.32	5817.14
2336.14	5716.6
2338.96	5706.79
2341.78	5676.58
2344.6	5703.86
2347.42	5656.58
2350.24	5608.94
2353.05	5624.1
2355.87	5578.54
2358.68	5556.33
2361.5	5564.24
2364.31	5550.18
2367.12	5547.95
2369.93	5514.96
2372.74	5490.7
2375.55	5488.23
2378.35	5457.46
2381.16	5435.32
2383.96	5425.81
2386.77	5412.59
2389.57	5420.3
2392.37	5420.42
2395.17	5354.24
2397.97	5351.27
2400.77	5338.53
2403.57	5350.43
2406.37	5309.61
2409.16	5326.97
2411.96	5311.47
2414.75	5299.66
2417.55	5285.16
2420.34	5243.12
2423.13	5225.32
2425.92	5241.69
2428.71	5205.34
2431.5	5251.8
2434.28	5192.71
2437.07	5169.43
2439.85	5181.28
2442.64	5141.36
2445.42	5145.85
2448.2	5126.46
2450.98	5112.96
2453.76	5092.76
2456.54	5084.3
2459.32	5079.65
2462.1	5073.23
2464.87	5046.86
2467.65	5042.94
2470.42	5033.4
2473.2	5022.49
2475.97	5004.35
2478.74	5024.92
2481.51	4970.92
2484.28	4979.43
2487.05	4962.95
2489.81	4981.28
2492.58	4957.04
2495.34	4923.74
2498.11	4921.16
2500.87	4895.68
2503.63	4920.39
2506.39	4862.05
2509.15	4820.59
2511.91	4836.88
2514.67	4818.72
2517.43	4793.97
2520.19	4814.21
2522.94	4798.44
2525.7	4815.03
2528.45	4799.41
2531.2	4785.14
2533.95	4776.39
2536.7	4747.71
2539.45	4750.02
2542.2	4701.07
2544.95	4700.43
2547.69	4732.88
2550.44	4672.27
2553.18	4683.58
2555.93	4650.41
2558.67	4662.41
2561.41	4645.17
2564.15	4626.42
2566.89	4616.16
2569.63	4622.92
2572.36	4593.9
2575.1	4608.88
2577.84	4586.2
2580.57	4594.62
2583.31	4594.17
2586.04	4579.03
2588.77	4572.8
2591.5	4586.23
2594.23	4593.85
2596.96	4582.96
2599.69	4534.97
2602.41	4577.24
2605.14	4534.55
2607.86	4537.88
2610.59	4493.17
2613.31	4501.83
2616.03	4517.88
2618.75	4478.76
2621.48	4479.26
2624.19	4470.05
2626.91	4496.8
2629.63	4456.14
2632.35	4435
2635.06	4448.2
2637.77	4475.77
2640.49	4450.38
2643.2	4431.41
2645.91	4434.06
2648.62	4450.31
2651.33	4462.3
2654.04	4446.66
2656.75	4389.57
2659.45	4433.45
2662.16	4457.84
2664.86	4441.47
2667.57	4467.39
2670.27	4441.54
2672.97	4453.26
2675.67	4450.99
2678.37	4444.77
2681.07	4404.15
2683.77	4402.19
2686.47	4416.56
2689.16	4384.22
2691.86	4386.99
2694.55	4401.16
2697.25	4382.06
2699.94	4376.31
2702.63	4411.19
2705.32	4399.82
2708.01	4419.58
2710.7	4452.54
2713.39	4455.71
2716.07	4478.67
2718.76	4496.49
2721.44	4491.15
2724.12	4458.39
2726.81	4498.77
2729.49	4473.33
2732.17	4466.42
2734.85	4420.3
2737.53	4374.1
2740.21	4297.51
2742.88	4258.45
2745.56	4208.81
2748.24	4176.3
2750.91	4130.86
2753.58	4107.27
2756.25	4067.57
2758.93	4043.23
2761.6	4045.3
2764.27	4043.47
2766.93	4035.04
2769.6	4016.17
2772.27	4004.56
2774.93	3988.5
2777.6	3969.69
2780.26	3972.38
2782.93	3963.25
2785.59	3934.3
2788.25	3917.98
2790.91	3957.91
2793.57	3967.64
2796.23	3981.15
2798.88	3949.34
2801.54	3960.08
2804.2	3982.82
2806.85	3981.28
2809.5	3959.1
2812.16	4010.87
2814.81	4007.03
2817.46	4027.41
2820.11	4108.17
2822.76	4160.82
2825.4	4213.89
2828.05	4297.44
2830.7	4421.81
2833.34	4612.77
2835.99	4871.18
2838.63	5268.17
2841.27	5908.95
2843.91	6952.86
2846.55	8377.37
2849.19	9781.63
2851.83	10281.2
2854.47	10134.4
2857.11	9736.83
2859.74	9339.35
2862.38	8945.54
2865.01	8674.64
2867.65	8570.1
2870.28	8674.64
2872.91	8860.42
2875.54	8992.41
2878.17	9091.55
2880.8	9169
2883.42	9299.07
2886.05	9532.25
2888.68	9631.7
2891.3	9745.56
2893.93	9796.21
2896.55	9830.96
2899.17	9778.57
2901.79	9765.39
2904.41	9690.28
2907.03	9602.91
2909.65	9543.54
2912.27	9493.36
2914.88	9455.84
2917.5	9400.16
2920.11	9357.69
2922.73	9352.33
2925.34	9331.46
2927.95	9376.69
2930.56	9389.13
2933.17	9304.13
2935.78	9204.22
2938.39	8970.72
2941	8440.05
2943.6	7914.15
2946.21	7262.29
2948.81	6872.82
2951.42	6563.75
2954.02	6392.46
2956.62	6278.49
2959.22	6197.88
2961.82	6036.72
2964.42	5824.08
2967.02	5680.08
2969.62	5435.03
2972.21	5177.87
2974.81	4994.63
2977.4	4854.25
2980	4681.51
2982.59	4536.04
2985.18	4436.72
2987.77	4337.07
2990.36	4260.26
2992.95	4230
2995.54	4202.41
2998.13	4179.23
3000.72	4171.7
3003.3	4194.01
3005.89	4187.7
3008.47	4153.35
3011.05	4061.15
3013.63	3990.43
3016.22	3922.35
3018.8	3843.19
3021.38	3776.82
3023.95	3717.41
3026.53	3641.25
3029.11	3635.65
3031.68	3622.23
3034.26	3588.69
3036.83	3587.2
3039.4	3594.49
3041.98	3561.01
3044.55	3555.19
3047.12	3551.43
3049.69	3580.59
3052.26	3561.58
3054.82	3604.94
3057.39	3599.73
3059.96	3621.89
3062.52	3608.35
3065.09	3614.29
3067.65	3613.3
3070.21	3627.97
3072.77	3599.21
3075.33	3625.71
3077.89	3640.73
3080.45	3652.47
3083.01	3645.81
3085.57	3638.15
3088.12	3643.64
3090.68	3648.75
3093.23	3662.23
3095.79	3705.95
3098.34	3724.11
3100.89	3730.95
3103.44	3729.92
3105.99	3779.53
3108.54	3796.36
3111.09	3825.52
3113.63	3845.17
3116.18	3896.33
3118.73	3887.11
3121.27	3928.79
3123.82	3928.3
3126.36	3988.46
3128.9	3982.85
3131.44	4021.92
3133.98	4050.06
3136.52	4104.45
3139.06	4137.77
3141.6	4145.83
3144.13	4207.79
3146.67	4210
3149.2	4241.88
3151.74	4264.71
3154.27	4310.01
3156.8	4341.88
3159.34	4346.72
3161.86	4370.63
3164.4	4400.02
3166.92	4437.83
3169.45	4467.45
3171.98	4459.19
3174.5	4464.44
3177.03	4487.97
3179.56	4497.51
3182.08	4503.67
3184.6	4523.05
3187.12	4526.19
3189.64	4536.87
3192.16	4546.36
3194.68	4549.68
3197.2	4544.51
3199.72	4536.15
3202.24	4537.93
3204.75	4548.43
3207.27	4544.14
3209.78	4547.12
3212.29	4525.75
3214.81	4534.58
3217.32	4529.99
3219.83	4501.39
3222.34	4523.46
3224.85	4503.38
3227.35	4487.69
3229.86	4496.53
3232.37	4494.11
3234.87	4462.55
3237.38	4455.77
3239.88	4444.25
3242.38	4438.43
3244.89	4428.22
3247.39	4415.89
3249.89	4393.74
3252.39	4387.35
3254.88	4366.23
3257.38	4351.31
3259.88	4321
3262.37	4318.24
3264.87	4300.71
3267.36	4287.84
3269.86	4264.87
3272.35	4288.39
3274.84	4257.81
3277.33	4253.96
3279.82	4226.67
3282.31	4224.18
3284.8	4189.68
3287.29	4193.14
3289.77	4204.84
3292.26	4176.63
3294.15	4163.52
3296.64	4145.67
3299.14	4150.85
3301.63	4147.14
3304.12	4135.61
3306.62	4109.73
3309.11	4112.4
3311.6	4106.27
3314.09	4085.26
3316.58	4055.05
3319.07	4069.62
3321.56	4087.78
3324.04	4099.07
3326.53	4073.05
3329.01	4080.99
3331.5	4051.39
3333.98	4075.02
3336.46	4039.71
3338.94	4027.53
3341.42	4048.59
3343.9	4006.02
3346.38	4021.51
3348.86	4001.23
3351.34	4030.59
3353.82	3997.76
3356.29	3974.89
3358.77	3995.64
3361.24	3983.43
3363.71	3965.91
3366.19	4004.31
3368.66	3956.15
3371.13	3992.12
3373.6	3972.49
3376.07	3954.41
3378.54	3964.94
3381	3942.1
3383.47	3937.41
3385.94	3947.63
3388.4	3936.5
3390.87	3954.32
3393.33	3955.23
3395.79	3893.99
3398.25	3918
3400.71	3912.88
3403.17	3893.92
3405.63	3886.68
3408.09	3873.88
3410.55	3876.73
3413	3857.93
3415.46	3831.63
3417.92	3833.42
3420.37	3815.05
3422.82	3819.99
3425.27	3809.82
3427.73	3756.45
3430.18	3761.89
3432.63	3740.77
3435.08	3754.67
3437.53	3728.95
3439.97	3727.86
3442.42	3698.42
3444.86	3660.79
3447.31	3656.5
3449.75	3640.15
3452.2	3608.63
3454.64	3552.7
3457.08	3560.47
3459.52	3557.19
3461.96	3507.67
3464.4	3485.46
3466.84	3478.37
3469.28	3455.9
3471.72	3437.65
3474.15	3391.23
3476.59	3362.27
3479.02	3357.58
3481.45	3307.95
3483.89	3299.72
3486.32	3259.53
3488.75	3239.78
3491.18	3216.69
3493.61	3173.62
3496.04	3140.91
3498.47	3124.05
3499.68	3089.21