File: src/Milk_AI/Nandani toned milk RT after 24 h 532nm 50% 600g 50xL 10s 10times 400-3500cm-1 200hole.txt
#Acq. time (s)=	7
#Accumulations=	20
#Range (cm-¹)=	400...3500
#Windows=	3
#Auto scanning=	Off
#Autofocus=	Off
#AutoExposure=	Off
#Spike filter=	Multiple accum.
#Delay time (s)=	0
#Binning=	1
#Readout mode=	Signal
#DeNoise=	Off
#ICS correction=	On
#Dark correction=	Off
#Inst. Process=	Off
#Detector Gain=	Best Dynamic Range
#Detector ADC=	45 kHz
#Detector temperature (°C)=	-60.1
#Instrument=	LabRAM HR Evol
#Detector=	Syncerity OE
#Objective=	x50_VIS_LWD
#Grating=	600 (500nm)
#ND Filter=	50%
#Laser=	532nm_Edge
#Hole=	199.981
#Range=	Visible
#E-Cal_Neon=	0
#StageXY=	75x50mm Scan+
#StageZ=	Z motor
#X (µm)=	0
#Y (µm)=	0
#Z (µm)=	335.4
#Spectral res.(cm-¹)=	12.8
#Full time(mm:ss)=	7:26
#AC=	Calibrated 2025-07-01 10:31
#Project=
#Sample=
#Site=
#Title=	D_1
#Remark=
#Date=	01.07.2025 12:55 (India Standard Time)
#Acquired=	01.07.2025 12:55:42 (India Standard Time)
#AxisType[0]=Intens
#AxisUnit[0]=Cnt
#AxisType[1]=Spectr
#AxisUnit[1]=1/cm
400.083	14002
403.63	13899
407.176	13874.6
410.72	13878.1
414.263	13838.9
417.805	13898.3
421.345	13912.8
424.884	13886.8
428.421	13864.6
431.955	13879.9
435.49	13841.6
439.023	13808.1
442.555	13784.6
446.084	13767.4
449.613	13773.7
453.141	13750
456.666	13735.3
460.191	13705.5
463.715	13697.6
467.235	13641.7
470.756	13651.6
474.274	13610.2
477.793	13598.5
481.308	13603.1
484.823	13570.3
488.336	13608.4
491.847	13570.7
495.358	13580.7
498.867	13589.3
502.374	13593.2
505.881	13644.9
509.386	13645.3
512.888	13642
516.39	13634.9
519.89	13600.7
523.391	13549.6
526.889	13524.4
530.385	13455.1
533.88	13450.4
537.373	13393.7
540.866	13354.7
544.357	13323
547.846	13325.2
551.334	13342.2
554.821	13311.1
558.307	13305.9
561.789	13260.8
565.272	13314
568.753	13279.1
572.233	13289.8
575.712	13342
579.188	13338.6
582.664	13298.3
586.139	13335
589.611	13346.2
593.083	13352.5
596.554	13380.8
600.021	13340.4
603.49	13383.5
606.955	13344.3
610.42	13284.1
613.882	13252.3
617.345	13197.1
620.805	13197.7
624.263	13132.5
627.722	13073.5
631.178	13058.7
634.633	13073.7
638.088	13071.9
641.539	13130.1
644.99	12997.4
648.439	12987.6
651.887	12942.1
655.335	12927.3
658.781	12940.7
662.225	12934.3
665.667	12904.6
669.108	12890.1
672.548	12864.3
675.987	12879.8
679.424	12897.8
682.86	12874.5
686.293	12858.7
689.727	12830.4
693.159	12840.7
696.59	12870.4
700.019	12895.1
703.448	12882.2
706.872	12841.7
710.298	12853.8
713.723	12841.4
717.144	12843.7
720.565	12860.5
723.984	12839.9
727.403	12852.7
730.821	12808.3
734.235	12793.7
737.651	12793.4
741.063	12777.8
744.474	12733.4
747.885	12733.1
751.293	12791
754.702	12779.9
758.108	12794.1
761.512	12763.4
764.915	12767.3
768.319	12783.3
771.719	12755.4
775.118	12825.9
778.516	12786.5
781.913	12781.7
785.308	12811.3
788.702	12761.5
792.095	12756.6
795.486	12747.3
798.876	12816.6
802.265	12796.4
805.653	12818.4
809.039	12823.6
812.424	12793
815.808	12846.3
819.191	12926.9
822.572	12954.4
825.95	13046.5
829.329	13039.5
832.706	13141.2
836.08	13145.6
839.455	13195.4
842.829	13272.4
846.199	13281.6
849.57	13323.1
852.938	13287.6
856.307	13320.6
859.672	13399.7
863.038	13450.3
866.401	13439.1
869.765	13424.5
873.125	13438.6
876.484	13380.5
879.844	13297.3
883.2	13263.9
886.555	13300.9
889.909	13241.3
893.262	13124.7
896.616	12979.7
899.966	12893
903.315	12821.1
906.663	12759
910.009	12758
913.354	12772.4
916.698	12768
920.041	12752.8
923.383	12725.2
926.723	12607.2
930.062	12551.4
933.399	12505.1
936.734	12472.5
940.069	12516.9
943.403	12550.5
946.736	12572.9
950.065	12566
953.396	12580.4
956.725	12579.4
960.051	12634.1
963.377	12561.9
966.7	12542.2
970.025	12511.7
973.345	12440.8
976.667	12402
979.985	12393.9
983.304	12407.9
986.62	12450.7
989.935	12550.8
993.25	12645.5
996.563	12939.8
999.874	13279.6
1003.19	13348.2
1006.49	13119
1009.8	12910.1
1013.11	12758.7
1016.41	12725.2
1019.72	12604.1
1023.02	12590.5
1026.32	12536.5
1029.62	12495.2
1032.92	12468.7
1036.22	12429.9
1039.51	12419.7
1042.81	12413.7
1046.1	12454
1049.39	12478
1052.68	12583.8
1055.97	12755.7
1059.26	13058.6
1062.55	13127.9
1065.83	12889.8
1069.12	12849.8
1072.4	12897.9
1075.68	12938.1
1078.97	12978
1082.24	12903.6
1085.52	12838.1
1088.8	12761.7
1092.08	12554.1
1095.35	12455.8
1098.62	12313.4
1101.9	12216
1105.17	12156
1108.44	12173.6
1111.7	12269.8
1114.97	12351.4
1118.23	12440.3
1121.5	12574.3
1124.76	12668.3
1128.03	12527
1131.29	12298.6
1134.54	12080.2
1137.8	12153.3
1141.06	12305.1
1144.31	12631.2
1147.57	13272.8
1150.82	14120
1154.07	14740.7
1157.32	14375.7
1160.57	13308.3
1163.82	12498.2
1167.07	12157.4
1170.31	12006.9
1173.56	11960.2
1176.8	11835.4
1180.04	11804.1
1183.28	11894.7
1186.52	11911.2
1189.76	11908.6
1192.99	11869
1196.23	11715.8
1199.46	11612.9
1202.7	11518.8
1205.93	11474.8
1209.16	11465.1
1212.39	11460.7
1215.62	11377.3
1218.84	11210.9
1222.07	11203.1
1225.29	11227
1228.52	11233.2
1231.74	11231.6
1234.96	11261.2
1238.18	11314.8
1241.4	11338.2
1244.61	11450.1
1247.83	11552.3
1251.04	11581.9
1254.25	11644
1257.47	11720.2
1260.68	11796.3
1263.89	11806.8
1267.09	11841.5
1270.3	11724.4
1273.51	11672.8
1276.71	11664.3
1279.91	11673.9
1283.12	11678.2
1286.32	11815.9
1289.52	12079.6
1292.72	12597.1
1295.91	12884.1
1299.11	12857.8
1302.3	12732
1305.5	12501.4
1308.69	12161.7
1311.88	11914.9
1315.07	11652.2
1318.26	11419.1
1321.44	11245.7
1324.63	11150.1
1327.82	11020
1331	10950.1
1334.18	10923.2
1337.36	10853.9
1340.54	10896
1343.72	10849.1
1346.9	10809.3
1350.07	10813.7
1353.25	10741.7
1356.42	10705.5
1359.6	10646
1362.77	10658.8
1365.94	10678.6
1369.11	10655.9
1372.28	10563.7
1375.44	10399.6
1378.61	10412.5
1381.77	10374.5
1384.93	10316.3
1388.1	10356.1
1391.26	10351.9
1394.41	10329.4
1397.57	10312.8
1400.73	10309.4
1403.89	10372.7
1407.04	10440.5
1410.19	10525.6
1413.35	10687.8
1416.5	10817.4
1419.65	11006.8
1422.8	11123.8
1425.94	11495.5
1429.09	12131.5
1432.23	12955
1435.38	13603.3
1438.52	13753.8
1441.66	13534
1444.8	13227.9
1447.94	13016.3
1451.08	12854.7
1454.22	12659.4
1457.35	12440.9
1460.48	12109.7
1463.62	11787.2
1466.75	11371
1469.88	11021.1
1473.01	10719.8
1476.14	10480.5
1479.26	10324.8
1482.39	10256.5
1485.51	10213.5
1488.64	10191.8
1491.76	10221.4
1494.88	10321.2
1498	10369.4
1501.12	10525.3
1504.24	10750.8
1507.35	11145.1
1510.47	11636.7
1513.58	12203.8
1516.69	12722.8
1519.81	12896
1522.92	12743.8
1526.03	12154.3
1529.13	11378.9
1532.24	10675.1
1535.35	10246.7
1538.45	9983.88
1541.55	9829.17
1544.66	9679.04
1547.76	9614.88
1550.86	9545.06
1553.96	9525.06
1557.05	9475.76
1560.15	9423.23
1563.24	9463.36
1566.34	9462.87
1569.43	9412.46
1572.52	9438.36
1575.61	9416.02
1578.7	9411.59
1581.79	9410.16
1584.88	9440.2
1587.96	9421.18
1591.05	9418.88
1594.13	9414.81
1597.21	9389.6
1600.3	9402.71
1603.37	9375.12
1606.45	9343.41
1609.53	9305.09
1612.61	9293.53
1615.68	9240.69
1618.76	9282.09
1621.83	9262.83
1624.9	9272.22
1627.97	9299.49
1631.04	9331.91
1634.11	9402.15
1637.18	9433.66
1640.24	9539.4
1643.31	9727.63
1646.37	10116.7
1649.44	10515.8
1652.5	10682.2
1655.56	10418.9
1658.62	9985.36
1661.67	9685
1664.73	9530.33
1667.79	9426.24
1670.84	9299.42
1673.89	9162.31
1676.95	9043.68
1680	8931.92
1683.05	8894.48
1686.1	8835.4
1689.14	8799.91
1692.19	8786.47
1695.23	8734.06
1698.28	8677.45
1701.32	8635.77
1704.36	8625.09
1707.4	8586.48
1710.44	8591.72
1713.48	8570.88
1716.52	8556.33
1719.56	8568.5
1722.59	8596.8
1725.63	8644.85
1728.66	8745.95
1731.69	8767.27
1734.72	8905.68
1737.75	9067.18
1740.78	9115.55
1743.8	9074.8
1746.83	9004.88
1749.86	8906.83
1752.88	8799.76
1755.9	8611.95
1758.92	8469.36
1761.94	8372.87
1764.96	8273.37
1767.98	8261.14
1771	8261.1
1774.01	8238.09
1777.03	8231.97
1780.04	8224.6
1783.05	8163.54
1786.06	8192.48
1789.07	8184.47
1792.08	8118.08
1795.09	8143.4
1798.1	8080.87
1801.1	8092.82
1804.11	8092.98
1807.11	8070.19
1810.11	8103.1
1813.11	8061.02
1816.11	8030
1819.11	8008.38
1822.11	7992.71
1825.11	7982.42
1828.1	7937.7
1831.1	7958.44
1834.09	7917.73
1837.08	7916.56
1840.07	7958.72
1843.06	7911.81
1846.05	7939.5
1849.04	7895.33
1852.02	7843.36
1855.01	7855.85
1857.99	7844.67
1860.98	7832.82
1863.96	7831.34
1866.94	7815.62
1869.92	7812.05
1872.9	7785.25
1875.88	7810.36
1878.85	7744.49
1881.83	7733.88
1884.8	7715.72
1887.78	7702.56
1890.75	7689.49
1893.72	7671.69
1896.69	7609.9
1899.66	7622.65
1902.63	7587.66
1905.59	7511.41
1908.56	7462.71
1911.52	7445.6
1914.49	7383.57
1917.45	7319.51
1920.41	7285.9
1923.37	7222.45
1926.33	7185.73
1929.29	7172.24
1932.24	7108.88
1935.2	7063.09
1938.15	7011.13
1941.1	6954.43
1944.06	6966.94
1947.01	6919.56
1949.96	6853.51
1952.91	6805.28
1955.86	6736.9
1958.8	6706.45
1961.75	6680.4
1964.69	6616.13
1967.64	6600.8
1970.58	6559.72
1973.52	6502.36
1976.46	6468.19
1979.4	6439.25
1982.34	6436.47
1985.27	6368.52
1988.21	6350.42
1991.14	6295.18
1994.08	6251.54
1997.01	6211.57
1999.94	6161.85
2002.87	6133.14
2005.8	6111.2
2008.73	6078.36
2011.66	6049.87
2014.58	6010.33
2017.51	5986.18
2020.43	5948.88
2023.36	5904.59
2026.28	5888.68
2029.2	5865.23
2032.12	5828.64
2035.04	5795.88
2037.95	5770.95
2040.87	5767.32
2043.78	5733.5
2045.76	5680.27
2048.69	5694.97
2051.61	5684.05
2054.54	5697.41
2057.46	5664.15
2060.38	5647.88
2063.3	5661.42
2066.22	5642.23
2069.14	5617.74
2072.06	5614.71
2074.98	5606.39
2077.89	5596.71
2080.81	5603.85
2083.72	5587.23
2086.63	5558.34
2089.55	5551.15
2092.46	5529.66
2095.37	5520.29
2098.28	5517.11
2101.18	5500.05
2104.09	5506.39
2106.99	5472.47
2109.9	5479.9
2112.8	5461.85
2115.71	5453.76
2118.61	5457.61
2121.51	5444.95
2124.4	5428.33
2127.3	5405.13
2130.2	5407.62
2133.09	5393.11
2135.99	5398.5
2138.88	5351.3
2141.78	5382.1
2144.67	5375.61
2147.56	5378.36
2150.45	5348.36
2153.34	5350.73
2156.22	5339.53
2159.11	5333.48
2162	5323.05
2164.88	5311.77
2167.76	5333.38
2170.64	5304.86
2173.53	5288.17
2176.41	5269.16
2179.29	5265.33
2182.16	5253.62
2185.04	5259.2
2187.92	5240.16
2190.79	5210.13
2193.66	5196.02
2196.54	5201.32
2199.41	5148.53
2202.28	5163.59
2205.15	5159.25
2208.02	5129.14
2210.88	5111.67
2213.75	5063.14
2216.62	5073.58
2219.48	5077.89
2222.34	5062.25
2225.21	5031.39
2228.07	5021.02
2230.93	5021.16
2233.79	5015.44
2236.65	5002.56
2239.5	4972.66
2242.36	4959.4
2245.21	4975.82
2248.07	4924.7
2250.92	4937.14
2253.77	4902.45
2256.62	4876.42
2259.47	4863.78
2262.32	4838.28
2265.17	4834.18
2268.02	4829.67
2270.86	4787.96
2273.71	4779.89
2276.55	4784.13
2279.39	4767.2
2282.24	4742.83
2285.08	4718.15
2287.92	4716.4
2290.75	4730.48
2293.59	4677.02
2296.43	4680.66
2299.26	4661.07
2302.1	4672.06
2304.93	4620.57
2307.76	4642.85
2310.6	4615.36
2313.43	4609.94
2316.25	4600.54
2319.08	4561.35
2321.91	4554.28
2324.74	4632.02
2327.56	4711.16
2330.39	4653.13
2333.21	4487.94
2336.03	4485.33
2338.85	4470
2341.67	4476.2
2344.49	4436.93
2347.31	4441.53
2350.13	4407.18
2352.94	4385.7
2355.76	4394.53
2358.57	4356.44
2361.39	4313.48
2364.2	4311.14
2367.01	4312.91
2369.82	4304.41
2372.63	4302.94
2375.44	4285.73
2378.24	4291.59
2381.05	4270.7
2383.85	4265.2
2386.66	4240.91
2389.46	4247.21
2392.26	4212.64
2395.06	4194.53
2397.86	4190.73
2400.66	4179.22
2403.46	4154.95
2406.26	4161.91
2409.05	4134.27
2411.85	4134.73
2414.64	4116.75
2417.43	4129.24
2420.23	4107.31
2423.02	4093.49
2425.81	4103.86
2428.6	4069.53
2431.38	4087.89
2434.17	4072.04
2436.96	4030.44
2439.74	4025.44
2442.53	4043.62
2445.31	4014.03
2448.09	4012.9
2450.87	4006.48
2453.65	3987.2
2456.43	3976.95
2459.21	3963.72
2461.98	3955.99
2464.76	3950.91
2467.53	3926.22
2470.31	3928.68
2473.08	3899.02
2475.85	3889.8
2478.63	3892.12
2481.39	3897.16
2484.16	3854.32
2486.93	3875.18
2489.7	3862.3
2492.46	3851.56
2495.23	3832.49
2497.99	3818.94
2500.76	3833.58
2503.52	3813.86
2506.28	3808.64
2509.04	3780.89
2511.8	3777.57
2514.56	3777.86
2517.31	3746.43
2520.07	3753.51
2522.82	3737.51
2525.58	3753.9
2528.33	3759.07
2531.09	3708.99
2533.84	3709.95
2536.59	3690.01
2539.34	3694.56
2542.08	3694.56
2544.83	3677.67
2547.58	3655.67
2550.32	3652.88
2553.07	3655.75
2555.81	3621.35
2558.55	3623.22
2561.29	3633.61
2564.03	3615.46
2566.77	3615.88
2569.51	3597.38
2572.25	3585.67
2574.99	3589.31
2577.72	3576.56
2580.46	3577.62
2583.19	3583.17
2585.92	3574.37
2588.65	3588.03
2591.38	3576.78
2594.11	3573.75
2596.84	3568.86
2599.57	3564.76
2602.3	3540.93
2605.02	3553.36
2607.75	3537.7
2610.47	3532.13
2613.19	3546.09
2615.92	3506.7
2618.64	3502.27
2621.36	3510.06
2624.08	3470.85
2626.8	3484.32
2629.51	3481.16
2632.23	3478.99
2634.94	3475.8
2637.66	3475.4
2640.37	3463.27
2643.08	3463.33
2645.79	3462.52
2648.5	3439.1
2651.21	3477.55
2653.92	3458.5
2656.63	3458.42
2659.33	3459.61
2662.04	3448.71
2664.75	3469.91
2667.45	3461.46
2670.15	3442.96
2672.85	3463.55
2675.55	3436.08
2678.25	3415.57
2680.95	3422.45
2683.65	3408.59
2686.35	3403.56
2689.04	3400.19
2691.74	3392.4
2694.43	3399.77
2697.13	3383.1
2699.82	3380.16
2702.51	3405
2705.2	3433.24
2707.89	3438.62
2710.58	3434.72
2713.26	3470.08
2715.95	3446.84
2718.64	3467.05
2721.32	3466.81
2724	3466.72
2726.69	3465.31
2729.37	3459.78
2732.05	3427.58
2734.73	3400.08
2737.41	3346.66
2740.09	3329.51
2742.76	3295.85
2745.44	3246.76
2748.11	3233.94
2750.79	3216.98
2753.46	3196
2756.13	3189.9
2758.81	3172.95
2761.47	3162.35
2764.14	3144.72
2766.81	3135.52
2769.48	3143.99
2772.15	3115.87
2774.81	3124.71
2777.48	3111.13
2780.14	3111.05
2782.8	3081.6
2785.47	3096.59
2788.13	3076.25
2790.79	3098.49
2793.44	3096.05
2796.1	3121.77
2798.76	3120.26
2801.42	3113.75
2804.07	3108.5
2806.73	3103.09
2809.38	3126.79
2812.03	3139.36
2814.68	3146.13
2817.33	3159.1
2819.98	3185.61
2822.63	3224.99
2825.28	3302.97
2827.93	3361.46
2830.57	3471.21
2833.22	3643.03
2835.86	3889.6
2838.51	4253.16
2841.15	4904.86
2843.79	5704.42
2846.43	6513.71
2849.07	6984.46
2851.71	7018.8
2854.35	6749.29
2856.98	6498.22
2859.62	6315.73
2862.25	6092.39
2864.89	6008.03
2867.52	6014.65
2870.15	6178.13
2872.78	6306.46
2875.41	6415.59
2878.04	6607.22
2880.67	6740.6
2883.3	6749.62
2885.92	6704.03
2888.55	6707.86
2891.18	6678.34
2893.8	6639.32
2896.42	6646.19
2899.04	6624.83
2901.67	6605.35
2904.29	6566.02
2906.9	6504.9
2909.52	6490.73
2912.14	6455.98
2914.76	6408.98
2917.37	6353.55
2919.99	6334.46
2922.6	6338.42
2925.21	6346.55
2927.82	6330.23
2930.44	6332.89
2933.05	6293.72
2935.65	6184.5
2938.26	5986.02
2940.87	5655.44
2943.48	5280.24
2946.08	4973.01
2948.69	4747.86
2951.29	4581.68
2953.89	4523.16
2956.49	4464.37
2959.1	4409.04
2961.7	4296.58
2964.29	4164.85
2966.89	4045.52
2969.49	3887.23
2972.09	3775.67
2974.68	3652.7
2977.28	3593.04
2979.87	3483.79
2982.46	3420.38
2985.05	3351.68
2987.65	3306.47
2990.24	3266.27
2992.82	3259.43
2995.41	3233.23
2998	3225.1
3000.59	3220.6
3003.17	3230.24
3005.76	3214.02
3008.34	3179.46
3010.92	3130.53
3013.5	3084.86
3016.09	3045.85
3018.67	2986
3021.25	2963.06
3023.82	2928.23
3026.4	2906.25
3028.98	2889.71
3031.55	2882.31
3034.13	2866.27
3036.7	2876.99
3039.28	2873.11
3041.85	2862.14
3044.42	2889.27
3046.99	2876.62
3049.56	2869.04
3052.13	2894.34
3054.69	2886.2
3057.26	2904.25
3059.83	2914.6
3062.39	2915.19
3064.95	2920.11
3067.52	2937.21
3070.08	2921.07
3072.64	2901.42
3075.2	2908.91
3077.76	2933.05
3080.32	2935.85
3082.88	2953.14
3085.44	2952.54
3087.99	2947.6
3090.55	2955.46
3093.1	2946.92
3095.65	2972.87
3098.21	2995.21
3100.76	2981.97
3103.31	3020.76
3105.86	3038.13
3108.41	3069.34
3110.96	3086.91
3113.5	3090.91
3116.05	3109.81
3118.59	3113.29
3121.14	3150.73
3123.68	3171.68
3126.23	3185.2
3128.77	3195.93
3131.31	3223.06
3133.85	3233.25
3136.39	3253.77
3138.93	3275.64
3141.46	3295.4
3144	3311.58
3146.54	3347.66
3149.07	3371.7
3151.6	3394.23
3154.14	3427.03
3156.67	3464.29
3159.2	3455.91
3161.73	3471.07
3164.26	3493.8
3166.79	3512.6
3169.32	3511.71
3171.84	3515.43
3174.37	3513.26
3176.9	3527.38
3179.42	3514.8
3181.94	3542.68
3184.47	3562.84
3186.99	3544.82
3189.51	3552.21
3192.03	3530.85
3194.55	3561.35
3197.07	3540.54
3199.58	3560.58
3202.1	3539.56
3204.62	3559.41
3207.13	3549.6
3209.65	3552.17
3212.16	3527.7
3214.67	3527.52
3217.18	3520.63
3219.69	3518.06
3222.2	3516.86
3224.71	3503.79
3227.22	3503.76
3229.73	3494.59
3232.23	3484
3234.74	3471.15
3237.24	3468.25
3239.75	3464.03
3242.25	3448.82
3244.75	3441.55
3247.25	3425.87
3249.75	3421.06
3252.25	3421.68
3254.75	3386.64
3257.25	3378.96
3259.74	3371.84
3262.24	3351.94
3264.73	3345.09
3267.23	3341.89
3269.72	3341.6
3272.21	3331.11
3274.7	3322.8
3277.2	3303.05
3279.69	3282.31
3282.17	3276.39
3284.66	3265.15
3287.15	3270.4
3289.64	3244.99
3292.12	3239.97
3293.56	3239.66
3296.05	3228.03
3298.55	3216.69
3301.04	3197.5
3303.54	3194.53
3306.03	3194.57
3308.52	3196.55
3311.01	3201.85
3313.5	3177.92
3315.99	3169.1
3318.48	3160.39
3320.97	3170.5
3323.45	3156.22
3325.94	3144.11
3328.42	3147.04
3330.91	3139.32
3333.39	3141.56
3335.87	3129.96
3338.36	3131.84
3340.84	3123.48
3343.32	3109.5
3345.8	3108.85
3348.27	3108.56
3350.75	3069.18
3353.23	3085
3355.7	3082.85
3358.18	3094.6
3360.65	3078
3363.13	3065.2
3365.6	3064.2
3368.07	3061.95
3370.54	3067.55
3373.01	3071.08
3375.48	3055.51
3377.95	3040.61
3380.42	3048.43
3382.88	3030.72
3385.35	3030.41
3387.81	3038.82
3390.28	3022.65
3392.74	3019.66
3395.2	3017.8
3397.67	3023.16
3400.13	3005.51
3402.58	3003
3405.05	2999.35
3407.5	2985.22
3409.96	2988.1
3412.42	2962.76
3414.87	2947.98
3417.33	2948.5
3419.78	2930.29
3422.23	2914.81
3424.69	2916.18
3427.14	2900.05
3429.59	2902.02
3432.04	2883.19
3434.49	2868.23
3436.94	2854.01
3439.39	2834.56
3441.83	2836.09
3444.28	2821.72
3446.72	2791.4
3449.17	2787.15
3451.61	2759.88
3454.05	2756.05
3456.5	2745.89
3458.94	2724.49
3461.38	2707.88
3463.81	2691.4
3466.25	2678.94
3468.69	2660.25
3471.13	2638.27
3473.56	2620.64
3476	2598.38
3478.43	2576.52
3480.87	2545.49
3483.3	2535.32
3485.73	2509.88
3488.16	2495.27
3490.59	2464.46
3493.02	2436.46
3495.45	2433.01
3497.88	2389.3
3499.09	2410.3