File: src/Milk_AI/Nandani toned milk Cold 532nm 50% 600g 50xL 10s 10times 400-3500cm-1 200hole.txt
#Acq. time (s)=	10
#Accumulations=	10
#Range (cm-¹)=	400...3500
#Windows=	3
#Auto scanning=	Off
#Autofocus=	Off
#AutoExposure=	Off
#Spike filter=	Multiple accum.
#Delay time (s)=	0
#Binning=	1
#Readout mode=	Signal
#DeNoise=	Off
#ICS correction=	On
#Dark correction=	Off
#Inst. Process=	Off
#Detector Gain=	Best Dynamic Range
#Detector ADC=	45 kHz
#Detector temperature (°C)=	-60.1
#Instrument=	LabRAM HR Evol
#Detector=	Syncerity OE
#Objective=	x50_VIS_LWD
#Grating=	600 (500nm)
#ND Filter=	50%
#Laser=	532nm_Edge
#Hole=	199.981
#Range=	Visible
#E-Cal_Neon=	0
#StageXY=	75x50mm Scan+
#StageZ=	Z motor
#X (µm)=	0
#Y (µm)=	0
#Z (µm)=	278.3
#Spectral res.(cm-¹)=	12.8
#Full time(mm:ss)=	5:19
#AC=	Calibrated 2025-07-01 10:31
#Project=
#Sample=
#Site=
#Title=	D_1
#Remark=
#Date=	01.07.2025 12:10 (India Standard Time)
#Acquired=	01.07.2025 12:10:33 (India Standard Time)
#AxisType[0]=Intens
#AxisUnit[0]=Cnt
#AxisType[1]=Spectr
#AxisUnit[1]=1/cm
400.083	23734.7
403.63	23559.4
407.176	23630
410.72	23603.1
414.263	23644.1
417.805	23620.9
421.345	23595.5
424.884	23594.1
428.421	23620.6
431.955	23701.2
435.49	23612.1
439.023	23587.1
442.555	23521.1
446.084	23476.4
449.613	23500
453.141	23382.7
456.666	23409.4
460.191	23332.8
463.715	23302.2
467.235	23275.1
470.756	23299
474.274	23273.7
477.793	23242.2
481.308	23143.3
484.823	23213.5
488.336	23132.5
491.847	23230.3
495.358	23193.7
498.867	23189.6
502.374	23224.3
505.881	23308
509.386	23376.9
512.888	23282.5
516.39	23283.6
519.89	23202.5
523.391	23136.6
526.889	23105.2
530.385	23076.8
533.88	23007.3
537.373	22970.6
540.866	22885
544.357	22834.7
547.846	22776.2
551.334	22783.2
554.821	22817.7
558.307	22783.7
561.789	22801.5
565.272	22689.6
568.753	22739.8
572.233	22836.6
575.712	22754.6
579.188	22803.5
582.664	22731.1
586.139	22767.6
589.611	22774.5
593.083	22786.9
596.554	22826.8
600.021	22798.1
603.49	22796.2
606.955	22766.6
610.42	22766.8
613.882	22600.9
617.345	22604.5
620.805	22542.3
624.263	22495.2
627.722	22309.7
631.178	22374.2
634.633	22312.9
638.088	22367.5
641.539	22417.4
644.99	22249.4
648.439	22204.3
651.887	22214.3
655.335	22144.4
658.781	22211.9
662.225	22114.3
665.667	22183.6
669.108	22080.4
672.548	22014.7
675.987	22084.1
679.424	22089.8
682.86	22117
686.293	22090.9
689.727	22037.2
693.159	22082
696.59	22116.7
700.019	22059.8
703.448	22136.1
706.872	21952.3
710.298	21914.2
713.723	21954.4
717.144	21996.3
720.565	22002.1
723.984	21983.9
727.403	21961.2
730.821	21913.4
734.235	21893.4
737.651	21916
741.063	21833.3
744.474	21766.1
747.885	21852.3
751.293	21880.9
754.702	21868.9
758.108	21865.4
761.512	21844.5
764.915	21818.6
768.319	21936.3
771.719	21883.7
775.118	21837.5
778.516	21868.6
781.913	21859.7
785.308	21864.8
788.702	21798.1
792.095	21760.9
795.486	21747.3
798.876	21804
802.265	21810.9
805.653	21839.4
809.039	21858.1
812.424	21792.1
815.808	21808.9
819.191	21904.9
822.572	21991.2
825.95	22038.5
829.329	22099.6
832.706	22137.3
836.08	22136
839.455	22143.3
842.829	22248.2
846.199	22279.5
849.57	22358.5
852.938	22282.7
856.307	22320.3
859.672	22453.1
863.038	22458.4
866.401	22468.5
869.765	22443
873.125	22431.3
876.484	22451.2
879.844	22325.2
883.2	22248.1
886.555	22250.6
889.909	22259.6
893.262	22066.5
896.616	21880.9
899.966	21855.6
903.315	21710.2
906.663	21590.7
910.009	21598.7
913.354	21529.5
916.698	21629.9
920.041	21486.9
923.383	21478.7
926.723	21327.5
930.062	21228
933.399	21250.9
936.734	21152.2
940.069	21245.2
943.403	21357.5
946.736	21289.5
950.065	21383.5
953.396	21383.3
956.725	21338
960.051	21384.7
963.377	21427
966.7	21317.7
970.025	21227.1
973.345	21201.9
976.667	21098
979.985	21104.6
983.304	21087.7
986.62	21216.6
989.935	21375
993.25	21485.2
996.563	21912.1
999.874	22455.9
1003.19	22599.7
1006.49	22385.6
1009.8	21973
1013.11	21618
1016.41	21512.9
1019.72	21395.7
1023.02	21302.6
1026.32	21220.2
1029.62	21117.2
1032.92	21118.2
1036.22	21005.2
1039.51	21023.3
1042.81	20978.8
1046.1	20950.8
1049.39	21008.4
1052.68	21111.4
1055.97	21317
1059.26	21669
1062.55	21694.4
1065.83	21452.8
1069.12	21422.3
1072.4	21518.8
1075.68	21539
1078.97	21624.1
1082.24	21529.1
1085.52	21446.5
1088.8	21296.4
1092.08	21105.5
1095.35	20970
1098.62	20721.4
1101.9	20691.4
1105.17	20569.7
1108.44	20600.8
1111.7	20707
1114.97	20905.1
1118.23	21025.5
1121.5	21167.6
1124.76	21143.9
1128.03	21110.3
1131.29	20813.3
1134.54	20698
1137.8	20722.9
1141.06	20973.9
1144.31	21559.9
1147.57	22413.1
1150.82	23816
1154.07	25021.1
1157.32	24522.2
1160.57	22756.6
1163.82	21318.3
1167.07	20740.3
1170.31	20563.7
1173.56	20426.5
1176.8	20188.7
1180.04	20253.8
1183.28	20281.8
1186.52	20436
1189.76	20454.1
1192.99	20329.2
1196.23	20206.3
1199.46	19949
1202.7	19746
1205.93	19737.8
1209.16	19692.8
1212.39	19680.9
1215.62	19537.7
1218.84	19319.2
1222.07	19277.9
1225.29	19247.9
1228.52	19227
1231.74	19267.5
1234.96	19289.8
1238.18	19355.2
1241.4	19448.4
1244.61	19445.8
1247.83	19693.8
1251.04	19634.1
1254.25	19757.2
1257.47	19858.1
1260.68	19868.5
1263.89	20018.8
1267.09	19994.1
1270.3	19823.7
1273.51	19800.2
1276.71	19687.7
1279.91	19646.4
1283.12	19622.3
1286.32	19767.3
1289.52	20050.4
1292.72	20658.6
1295.91	20975
1299.11	20964.4
1302.3	20885.8
1305.5	20586.2
1308.69	20205.5
1311.88	19866.8
1315.07	19538.1
1318.26	19329.5
1321.44	19147.2
1324.63	18954.1
1327.82	18908.7
1331	18814.4
1334.18	18733.8
1337.36	18716.9
1340.54	18751.4
1343.72	18582.2
1346.9	18598.2
1350.07	18585.2
1353.25	18552.5
1356.42	18436.9
1359.6	18356.8
1362.77	18401.5
1365.94	18348.9
1369.11	18312.7
1372.28	18179.3
1375.44	18034.4
1378.61	18006.6
1381.77	17960.3
1384.93	17882.3
1388.1	17932
1391.26	17941.1
1394.41	17907
1397.57	17864
1400.73	17883.8
1403.89	17931.5
1407.04	17924.9
1410.19	18046.5
1413.35	18264.5
1416.5	18423
1419.65	18565.9
1422.8	18672.5
1425.94	19026.3
1429.09	19805.5
1432.23	20796.1
1435.38	21628.3
1438.52	21809.2
1441.66	21643.8
1444.8	21293.6
1447.94	21064.6
1451.08	20771.3
1454.22	20543.2
1457.35	20300.2
1460.48	19920.7
1463.62	19532.7
1466.75	19089.8
1469.88	18646
1473.01	18291.3
1476.14	17933.8
1479.26	17792.5
1482.39	17711.5
1485.51	17647.4
1488.64	17648.2
1491.76	17693.5
1494.88	17805.7
1498	17931.9
1501.12	18205.1
1504.24	18583.1
1507.35	19164.6
1510.47	19918
1513.58	20936.2
1516.69	21782.3
1519.81	22148.8
1522.92	21935
1526.03	21075.9
1529.13	19824.2
1532.24	18574.3
1535.35	17822.7
1538.45	17348.7
1541.55	17150.9
1544.66	16921.7
1547.76	16772.9
1550.86	16684.4
1553.96	16668.7
1557.05	16511.1
1560.15	16524.3
1563.24	16526.4
1566.34	16547.2
1569.43	16545.7
1572.52	16575.9
1575.61	16478.8
1578.7	16488.1
1581.79	16547.4
1584.88	16541.7
1587.96	16521.8
1591.05	16502.9
1594.13	16529.1
1597.21	16466
1600.3	16526.9
1603.37	16476
1606.45	16428.4
1609.53	16398.8
1612.61	16317.9
1615.68	16297.5
1618.76	16296.1
1621.83	16271.9
1624.9	16302.1
1627.97	16269.8
1631.04	16380.8
1634.11	16463.1
1637.18	16454
1640.24	16568.9
1643.31	16758.6
1646.37	17164.8
1649.44	17635.3
1652.5	17825.9
1655.56	17552.7
1658.62	17137.6
1661.67	16729.1
1664.73	16589.8
1667.79	16367
1670.84	16233.7
1673.89	16042.8
1676.95	15871.3
1680	15795.2
1683.05	15748.1
1686.1	15618.2
1689.14	15533.9
1692.19	15516.2
1695.23	15439.9
1698.28	15354.2
1701.32	15295.3
1704.36	15235.3
1707.4	15216.1
1710.44	15216.6
1713.48	15195
1716.52	15100.8
1719.56	15164
1722.59	15175.2
1725.63	15198.8
1728.66	15249.7
1731.69	15346.4
1734.72	15446.4
1737.75	15584.8
1740.78	15653
1743.8	15610.6
1746.83	15539
1749.86	15535.2
1752.88	15313.5
1755.9	15075.8
1758.92	14910.1
1761.94	14770.3
1764.96	14763
1767.98	14698.8
1771	14601.5
1774.01	14600.9
1777.03	14604.3
1780.04	14565.8
1783.05	14507.3
1786.06	14548.5
1789.07	14517.8
1792.08	14477.7
1795.09	14463.1
1798.1	14422.2
1801.1	14401.2
1804.11	14390.1
1807.11	14389
1810.11	14344.2
1813.11	14309.4
1816.11	14289.3
1819.11	14319.4
1822.11	14250.4
1825.11	14211.3
1828.1	14241
1831.1	14198.9
1834.09	14229.3
1837.08	14162.4
1840.07	14128.7
1843.06	14169.6
1846.05	14137.4
1849.04	14052
1852.02	14060.4
1855.01	14045.8
1857.99	13984.4
1860.98	13968.5
1863.96	14034.6
1866.94	13953.3
1869.92	13975.1
1872.9	13945.1
1875.88	13932.7
1878.85	13928.1
1881.83	13880.4
1884.8	13846.2
1887.78	13751.1
1890.75	13715.5
1893.72	13782.4
1896.69	13636.3
1899.66	13679.4
1902.63	13625.9
1905.59	13514.7
1908.56	13490.5
1911.52	13353.1
1914.49	13314.4
1917.45	13175.3
1920.41	13153.4
1923.37	13068.3
1926.33	13036
1929.29	13002.2
1932.24	12899.7
1935.2	12810
1938.15	12744
1941.1	12656.8
1944.06	12581.8
1947.01	12523.1
1949.96	12438.4
1952.91	12350.4
1955.86	12238.4
1958.8	12202.3
1961.75	12172.8
1964.69	12090.7
1967.64	12014.8
1970.58	11971
1973.52	11910.2
1976.46	11865.5
1979.4	11781.1
1982.34	11720.3
1985.27	11659.8
1988.21	11612.5
1991.14	11520.6
1994.08	11448.7
1997.01	11384.1
1999.94	11322.4
2002.87	11284.1
2005.8	11215.8
2008.73	11146.5
2011.66	11126.7
2014.58	11073.2
2017.51	11015.3
2020.43	10954.1
2023.36	10883.9
2026.28	10834.5
2029.2	10775.9
2032.12	10742.6
2035.04	10684.9
2037.95	10660.3
2040.87	10598.8
2043.78	10538.4
2045.76	10518.7
2048.69	10533.6
2051.61	10469.7
2054.54	10484.8
2057.46	10404.4
2060.38	10400.5
2063.3	10409.6
2066.22	10385.8
2069.14	10386.8
2072.06	10365.7
2074.98	10303.7
2077.89	10315.7
2080.81	10323.6
2083.72	10291.9
2086.63	10234.1
2089.55	10225.7
2092.46	10233.3
2095.37	10157.8
2098.28	10169.5
2101.18	10136.6
2104.09	10162.8
2106.99	10118
2109.9	10119.3
2112.8	10064
2115.71	10029.1
2118.61	10067
2121.51	10027.7
2124.4	9952.05
2127.3	9970.48
2130.2	9957.38
2133.09	9957.1
2135.99	9959.88
2138.88	9888.67
2141.78	9866.74
2144.67	9908.75
2147.56	9835.22
2150.45	9839.27
2153.34	9801.37
2156.22	9819.89
2159.11	9800.68
2162	9795.24
2164.88	9801.32
2167.76	9725.46
2170.64	9739.5
2173.53	9763.47
2176.41	9708
2179.29	9707.14
2182.16	9656.13
2185.04	9656.25
2187.92	9645.56
2190.79	9607.24
2193.66	9574.8
2196.54	9496.06
2199.41	9537.54
2202.28	9481.25
2205.15	9487.1
2208.02	9440.8
2210.88	9411.81
2213.75	9353.17
2216.62	9411.14
2219.48	9331.63
2222.34	9291.26
2225.21	9293.33
2228.07	9293.96
2230.93	9278.49
2233.79	9249.32
2236.65	9186.38
2239.5	9181.87
2242.36	9136.29
2245.21	9159.33
2248.07	9135.22
2250.92	9109.13
2253.77	9032.31
2256.62	9017.4
2259.47	8995.3
2262.32	8939.18
2265.17	8924.54
2268.02	8854.43
2270.86	8847.75
2273.71	8826.75
2276.55	8810.38
2279.39	8801.86
2282.24	8740.39
2285.08	8725.31
2287.92	8706.91
2290.75	8742.41
2293.59	8656.88
2296.43	8628.13
2299.26	8628.42
2302.1	8578.96
2304.93	8559.26
2307.76	8541.84
2310.6	8541.64
2313.43	8531.23
2316.25	8462.04
2319.08	8445.67
2321.91	8437.1
2324.74	8443.58
2327.56	8606.74
2330.39	8563.04
2333.21	8310.34
2336.03	8275.18
2338.85	8274.43
2341.67	8261.19
2344.49	8243.66
2347.31	8189.92
2350.13	8158.19
2352.94	8135.94
2355.76	8129.81
2358.57	8102.47
2361.39	8022.49
2364.2	8033.57
2367.01	7980.89
2369.82	7992.63
2372.63	7956.96
2375.44	7922.77
2378.24	7924.5
2381.05	7887.4
2383.85	7886.86
2386.66	7846.92
2389.46	7852.45
2392.26	7832.31
2395.06	7789.29
2397.86	7769.39
2400.66	7734.76
2403.46	7712.74
2406.26	7735.15
2409.05	7718.99
2411.85	7677.79
2414.64	7662.39
2417.43	7656.9
2420.23	7611.72
2423.02	7600.82
2425.81	7568.02
2428.6	7551.14
2431.38	7544.87
2434.17	7539.88
2436.96	7486.63
2439.74	7484.91
2442.53	7462.33
2445.31	7421.59
2448.09	7454.81
2450.87	7405.44
2453.65	7355.75
2456.43	7406.34
2459.21	7372.68
2461.98	7340.8
2464.76	7328.3
2467.53	7292.87
2470.31	7267.27
2473.08	7283.78
2475.85	7247.64
2478.63	7223.27
2481.39	7210.27
2484.16	7232.77
2486.93	7190.85
2489.7	7156.3
2492.46	7163.25
2495.23	7088.49
2497.99	7142.49
2500.76	7089.14
2503.52	7066.36
2506.28	7038.68
2509.04	7054.98
2511.8	7016.4
2514.56	7008.29
2517.31	6985.72
2520.07	7026.12
2522.82	6963.18
2525.58	6977.28
2528.33	6941.42
2531.09	6956.16
2533.84	6952.66
2536.59	6912.11
2539.34	6862.17
2542.08	6875.55
2544.83	6828.98
2547.58	6834.76
2550.32	6758.31
2553.07	6785.51
2555.81	6748.87
2558.55	6741.37
2561.29	6735.23
2564.03	6728.94
2566.77	6671.64
2569.51	6639.23
2572.25	6694.16
2574.99	6657.73
2577.72	6665.28
2580.46	6648.91
2583.19	6656.49
2585.92	6627.18
2588.65	6627.03
2591.38	6609.84
2594.11	6651.61
2596.84	6645.2
2599.57	6614.4
2602.3	6565.53
2605.02	6564.66
2607.75	6569.42
2610.47	6561.89
2613.19	6554.03
2615.92	6497.41
2618.64	6482.26
2621.36	6478.47
2624.08	6476.45
2626.8	6503.42
2629.51	6457.79
2632.23	6434.44
2634.94	6463.03
2637.66	6400.16
2640.37	6397.81
2643.08	6456.51
2645.79	6416.92
2648.5	6424.77
2651.21	6387.66
2653.92	6395.73
2656.63	6411.85
2659.33	6360.85
2662.04	6401
2664.75	6380.55
2667.45	6398.08
2670.15	6440.23
2672.85	6360.93
2675.55	6352.61
2678.25	6343.86
2680.95	6334.93
2683.65	6299.12
2686.35	6264.82
2689.04	6281.4
2691.74	6292.95
2694.43	6247.82
2697.13	6245.35
2699.82	6276.29
2702.51	6276.47
2705.2	6318.54
2707.89	6280.84
2710.58	6341.51
2713.26	6320.39
2715.95	6316.5
2718.64	6337.02
2721.32	6359.47
2724	6308.17
2726.69	6324.86
2729.37	6274.24
2732.05	6274.35
2734.73	6228.71
2737.41	6187.56
2740.09	6094.94
2742.76	6049.65
2745.44	5999.82
2748.11	5989.44
2750.79	5942.7
2753.46	5918.59
2756.13	5911.18
2758.81	5874.56
2761.47	5859.74
2764.14	5875.84
2766.81	5815.26
2769.48	5846.35
2772.15	5819.23
2774.81	5823.99
2777.48	5792.16
2780.14	5779.47
2782.8	5759.57
2785.47	5783.04
2788.13	5713.19
2790.79	5710.57
2793.44	5732.12
2796.1	5790.92
2798.76	5769.61
2801.42	5744.84
2804.07	5733.2
2806.73	5784.99
2809.38	5753.09
2812.03	5787.87
2814.68	5779.52
2817.33	5852.67
2819.98	5836.26
2822.63	5923.71
2825.28	5957.84
2827.93	6065.14
2830.57	6196.63
2833.22	6368.02
2835.86	6727.22
2838.51	7182.17
2841.15	7933.65
2843.79	8909.8
2846.43	9878.9
2849.07	10589.9
2851.71	10638.6
2854.35	10443
2856.98	10103.1
2859.62	9827.32
2862.25	9637.11
2864.89	9513.69
2867.52	9529.45
2870.15	9656.8
2872.78	9895.68
2875.41	9982.72
2878.04	10264
2880.67	10395.9
2883.3	10489.2
2885.92	10414
2888.55	10486.7
2891.18	10445.5
2893.8	10370.1
2896.42	10361.4
2899.04	10356.6
2901.67	10293.5
2904.29	10294.7
2906.9	10226.8
2909.52	10251
2912.14	10170.6
2914.76	10104
2917.37	10073.9
2919.99	10044.4
2922.6	10040.3
2925.21	10054.4
2927.82	10070.5
2930.44	10069.2
2933.05	10013.8
2935.65	9911.89
2938.26	9686.03
2940.87	9280.76
2943.48	8794.82
2946.08	8329.82
2948.69	8100.24
2951.29	7840.51
2953.89	7747.09
2956.49	7664.3
2959.1	7518.6
2961.7	7415.13
2964.29	7192.1
2966.89	7022.96
2969.49	6868.72
2972.09	6671.63
2974.68	6481.99
2977.28	6399.31
2979.87	6251.83
2982.46	6153.44
2985.05	6054.83
2987.65	5955.14
2990.24	5914.38
2992.82	5858.63
2995.41	5834.56
2998	5858.53
3000.59	5800.48
3003.17	5814.43
3005.76	5774.21
3008.34	5742.43
3010.92	5688.33
3013.5	5622.6
3016.09	5485.71
3018.67	5458.18
3021.25	5394.47
3023.82	5413.51
3026.4	5366.2
3028.98	5322.47
3031.55	5296.78
3034.13	5289.5
3036.7	5302.71
3039.28	5275.84
3041.85	5316.94
3044.42	5293.59
3046.99	5327
3049.56	5304.44
3052.13	5339.36
3054.69	5347.59
3057.26	5348.29
3059.83	5400.75
3062.39	5389.51
3064.95	5384.72
3067.52	5418.73
3070.08	5370.64
3072.64	5413.69
3075.2	5448.94
3077.76	5448.31
3080.32	5443.2
3082.88	5430.11
3085.44	5469.83
3087.99	5477.77
3090.55	5521.1
3093.1	5550.47
3095.65	5557.2
3098.21	5582.15
3100.76	5604.86
3103.31	5660.92
3105.86	5645.53
3108.41	5706.97
3110.96	5761.37
3113.5	5757.77
3116.05	5829.36
3118.59	5848.4
3121.14	5918.83
3123.68	5897.57
3126.23	5966.69
3128.77	6027.96
3131.31	6071.4
3133.85	6121.26
3136.39	6094.2
3138.93	6188.63
3141.46	6194.38
3144	6253.31
3146.54	6312.77
3149.07	6369.46
3151.6	6409.4
3154.14	6472.05
3156.67	6479.24
3159.2	6544.87
3161.73	6569.5
3164.26	6602.9
3166.79	6659.36
3169.32	6656.03
3171.84	6687.5
3174.37	6639.85
3176.9	6683.97
3179.42	6677.46
3181.94	6718.95
3184.47	6688.23
3186.99	6701.17
3189.51	6734.26
3192.03	6766.52
3194.55	6706.82
3197.07	6723.64
3199.58	6747.86
3202.1	6736.5
3204.62	6765.33
3207.13	6768.14
3209.65	6756.34
3212.16	6751
3214.67	6731.44
3217.18	6697.33
3219.69	6710.34
3222.2	6717.82
3224.71	6717.55
3227.22	6668.98
3229.73	6684.76
3232.23	6657.34
3234.74	6639.39
3237.24	6617.36
3239.75	6585.1
3242.25	6617.94
3244.75	6565.67
3247.25	6551.53
3249.75	6527.28
3252.25	6489.9
3254.75	6503.98
3257.25	6472.8
3259.74	6449.33
3262.24	6437.52
3264.73	6400.25
3267.23	6410.18
3269.72	6391.79
3272.21	6375.49
3274.7	6363.3
3277.2	6349.92
3279.69	6315.1
3282.17	6289.66
3284.66	6255.54
3287.15	6277.85
3289.64	6246.02
3292.12	6226.45
3293.56	6247.3
3296.05	6215.98
3298.55	6217.2
3301.04	6165.17
3303.54	6179.8
3306.03	6202.85
3308.52	6191.69
3311.01	6191.11
3313.5	6144.7
3315.99	6129.61
3318.48	6101.39
3320.97	6121.23
3323.45	6154.14
3325.94	6123.84
3328.42	6112.66
3330.91	6130.65
3333.39	6133.93
3335.87	6110.16
3338.36	6070.24
3340.84	6065.3
3343.32	6040.81
3345.8	6063.77
3348.27	6070.07
3350.75	6038.89
3353.23	6031.17
3355.7	6018.92
3358.18	6010.8
3360.65	6036.93
3363.13	6011.68
3365.6	6027.99
3368.07	6022.74
3370.54	6030.35
3373.01	6019.6
3375.48	6008.66
3377.95	6016.11
3380.42	6001
3382.88	5973.69
3385.35	5956.67
3387.81	5972.29
3390.28	5929.08
3392.74	5947.13
3395.2	5934.42
3397.67	5967.4
3400.13	5918.92
3402.58	5923.71
3405.05	5914.63
3407.5	5906.07
3409.96	5866.32
3412.42	5858.18
3414.87	5842.51
3417.33	5851.52
3419.78	5803.13
3422.23	5799.52
3424.69	5766.82
3427.14	5780.62
3429.59	5754.95
3432.04	5730.22
3434.49	5684.39
3436.94	5695.6
3439.39	5633.24
3441.83	5643.32
3444.28	5632.95
3446.72	5552.29
3449.17	5561.78
3451.61	5510.4
3454.05	5477.02
3456.5	5458.08
3458.94	5422.98
3461.38	5402.2
3463.81	5407.45
3466.25	5359.67
3468.69	5303.01
3471.13	5278.71
3473.56	5216.34
3476	5224.98
3478.43	5132.4
3480.87	5143.02
3483.3	5085.9
3485.73	5024.87
3488.16	4996.87
3490.59	4982.2
3493.02	4936.24
3495.45	4896.11
3497.88	4836.34
3499.09	4814.72