File: src/Milk_AI/Nandani toned milk basic 532nm 50% 600g 50xL 10s 10times 400-3500cm-1 200hole.txt
#Acq. time (s)=	10
#Accumulations=	10
#Range (cm-¹)=	400...3500
#Windows=	3
#Auto scanning=	Off
#Autofocus=	Off
#AutoExposure=	Off
#Spike filter=	Multiple accum.
#Delay time (s)=	0
#Binning=	1
#Readout mode=	Signal
#DeNoise=	Off
#ICS correction=	On
#Dark correction=	Off
#Inst. Process=	Off
#Detector Gain=	Best Dynamic Range
#Detector ADC=	45 kHz
#Detector temperature (°C)=	-60.1
#Instrument=	LabRAM HR Evol
#Detector=	Syncerity OE
#Objective=	x50_VIS_LWD
#Grating=	600 (500nm)
#ND Filter=	50%
#Laser=	532nm_Edge
#Hole=	199.981
#Range=	Visible
#E-Cal_Neon=	0
#StageXY=	75x50mm Scan+
#StageZ=	Z motor
#X (µm)=	0
#Y (µm)=	0
#Z (µm)=	661.4
#Spectral res.(cm-¹)=	12.8
#Full time(mm:ss)=	5:19
#AC=	Calibrated 2025-07-01 10:31
#Project=
#Sample=
#Site=
#Title=	D_1
#Remark=
#Date=	01.07.2025 16:00 (India Standard Time)
#Acquired=	01.07.2025 16:00:50 (India Standard Time)
#AxisType[0]=Intens
#AxisUnit[0]=Cnt
#AxisType[1]=Spectr
#AxisUnit[1]=1/cm
400.083	25350.6
403.63	25193.6
407.176	25232.9
410.72	25256.2
414.263	25177.7
417.805	25327.5
421.345	25390.5
424.884	25289
428.421	25297.2
431.955	25321.9
435.49	25334.9
439.023	25330.7
442.555	25326.5
446.084	25279
449.613	25306.7
453.141	25337.8
456.666	25261.3
460.191	25226.4
463.715	25210.1
467.235	25226.8
470.756	25315.2
474.274	25189.2
477.793	25299.1
481.308	25255.5
484.823	25228.8
488.336	25215.1
491.847	25321.5
495.358	25324.7
498.867	25362.1
502.374	25439.5
505.881	25430.1
509.386	25526.3
512.888	25489.4
516.39	25528.3
519.89	25490.5
523.391	25433
526.889	25406.5
530.385	25394.3
533.88	25331.9
537.373	25308.5
540.866	25339.2
544.357	25225.2
547.846	25302.6
551.334	25198
554.821	25266.8
558.307	25280.9
561.789	25303.3
565.272	25364.8
568.753	25377.2
572.233	25453.7
575.712	25453.5
579.188	25541.1
582.664	25571.9
586.139	25589.7
589.611	25691.8
593.083	25786.5
596.554	25788
600.021	25699
603.49	25903.5
606.955	25870.4
610.42	25769.3
613.882	25609.5
617.345	25542.9
620.805	25562.2
624.263	25587.3
627.722	25485.1
631.178	25500
634.633	25547.4
638.088	25593.8
641.539	25640.1
644.99	25493
648.439	25473.3
651.887	25465.3
655.335	25458.7
658.781	25549.6
662.225	25480.8
665.667	25526.5
669.108	25487.3
672.548	25507.7
675.987	25511.9
679.424	25517.7
682.86	25557
686.293	25671.3
689.727	25625.1
693.159	25618.7
696.59	25758.1
700.019	25789.5
703.448	25749.6
706.872	25803.4
710.298	25761.5
713.723	25831.9
717.144	25830.2
720.565	26045.4
723.984	25954.6
727.403	25977.7
730.821	25902.1
734.235	25912.1
737.651	25898.1
741.063	25945.5
744.474	26012.3
747.885	26001.3
751.293	26116.7
754.702	26028.3
758.108	26140
761.512	26186.4
764.915	26197.7
768.319	26250.8
771.719	26228
775.118	26304.4
778.516	26352.2
781.913	26292.8
785.308	26478.8
788.702	26419.6
792.095	26430.2
795.486	26486.7
798.876	26566.8
802.265	26675.7
805.653	26721.9
809.039	26792.7
812.424	26865.5
815.808	26997.7
819.191	27084.9
822.572	27330.8
825.95	27450.7
829.329	27601.3
832.706	27776.2
836.08	27795.5
839.455	27906
842.829	28071.5
846.199	28082.5
849.57	28246.6
852.938	28229.9
856.307	28298.6
859.672	28523.6
863.038	28576.9
866.401	28652.5
869.765	28660.6
873.125	28628.8
876.484	28601.8
879.844	28463.1
883.2	28460.7
886.555	28579.2
889.909	28420.9
893.262	28207.6
896.616	28080.4
899.966	27882.1
903.315	27802.1
906.663	27719.7
910.009	27691.2
913.354	27744.9
916.698	27782.2
920.041	27804.3
923.383	27734.5
926.723	27503.4
930.062	27424.3
933.399	27422.1
936.734	27329.9
940.069	27450.8
943.403	27443.2
946.736	27462.3
950.065	27466
953.396	27541.3
956.725	27551.6
960.051	27552.8
963.377	27597.4
966.7	27597.4
970.025	27485.8
973.345	27483.4
976.667	27398.1
979.985	27442.8
983.304	27543.6
986.62	27643.9
989.935	27700.2
993.25	27926.5
996.563	28381.3
999.874	28716.6
1003.19	28741.9
1006.49	28401.9
1009.8	28188.1
1013.11	28176.3
1016.41	28252.7
1019.72	28158.1
1023.02	28217.6
1026.32	28155.8
1029.62	28198.5
1032.92	28145.6
1036.22	28288.1
1039.51	28297.4
1042.81	28260.3
1046.1	28375.2
1049.39	28554.7
1052.68	28838.4
1055.97	29458.9
1059.26	29945.7
1062.55	29804.3
1065.83	29477.7
1069.12	29525.6
1072.4	29833.2
1075.68	29970.7
1078.97	29964.2
1082.24	29801.8
1085.52	29554.9
1088.8	29361.3
1092.08	28940.3
1095.35	28680.8
1098.62	28426.8
1101.9	28425.8
1105.17	28245.8
1108.44	28357.4
1111.7	28585.8
1114.97	28897.4
1118.23	29039.4
1121.5	29258.8
1124.76	29055.6
1128.03	28580.6
1131.29	28097.8
1134.54	27948.6
1137.8	27945
1141.06	28294.7
1144.31	28712.3
1147.57	29439.3
1150.82	30234.2
1154.07	30544.6
1157.32	29866.9
1160.57	28795
1163.82	28155.3
1167.07	28025.3
1170.31	28029.1
1173.56	27778.7
1176.8	27794
1180.04	27698
1183.28	27830.8
1186.52	27939.4
1189.76	27833.2
1192.99	27783.5
1196.23	27693
1199.46	27554.2
1202.7	27535.9
1205.93	27600.9
1209.16	27642
1212.39	27609.4
1215.62	27456.8
1218.84	27412.2
1222.07	27518.8
1225.29	27592
1228.52	27718.2
1231.74	27734.4
1234.96	27882
1238.18	27945.7
1241.4	28208.8
1244.61	28387.1
1247.83	28533.3
1251.04	28654.9
1254.25	28810.2
1257.47	28903.5
1260.68	29077.6
1263.89	29143.8
1267.09	29152.8
1270.3	28943.9
1273.51	28951.8
1276.71	29034.8
1279.91	29082.6
1283.12	29306.2
1286.32	29747.3
1289.52	30559.8
1292.72	31655.5
1295.91	32170.8
1299.11	31992.4
1302.3	31764.7
1305.5	31088
1308.69	30433.8
1311.88	29878.3
1315.07	29368
1318.26	29060.3
1321.44	28607.6
1324.63	28435.5
1327.82	28243.7
1331	28126.8
1334.18	28094.9
1337.36	28122.3
1340.54	28121.5
1343.72	27945.1
1346.9	28019.9
1350.07	27991.7
1353.25	27893
1356.42	27801.9
1359.6	27867.9
1362.77	27944
1365.94	27898.8
1369.11	27847.5
1372.28	27655.5
1375.44	27444.9
1378.61	27305.8
1381.77	27392.3
1384.93	27261.3
1388.1	27367.2
1391.26	27414.2
1394.41	27420.5
1397.57	27504.6
1400.73	27524.7
1403.89	27705.2
1407.04	27844
1410.19	28154.2
1413.35	28527.2
1416.5	28881.8
1419.65	29218.5
1422.8	29591.7
1425.94	30737.7
1429.09	32420.5
1432.23	34363.2
1435.38	35460.6
1438.52	35386
1441.66	34745.4
1444.8	34133
1447.94	33731.5
1451.08	33205.7
1454.22	33015.6
1457.35	32361.6
1460.48	31547.8
1463.62	30837.5
1466.75	29928.4
1469.88	29300.3
1473.01	28676.2
1476.14	28151.2
1479.26	27887.1
1482.39	27676.8
1485.51	27624.6
1488.64	27529.9
1491.76	27563.2
1494.88	27715
1498	27779.6
1501.12	27860.9
1504.24	28145.6
1507.35	28559.7
1510.47	29121.4
1513.58	29568.6
1516.69	30010.9
1519.81	30036.9
1522.92	29748.6
1526.03	29205.7
1529.13	28446.2
1532.24	27821.8
1535.35	27522.4
1538.45	27252.3
1541.55	27232.4
1544.66	27074.3
1547.76	27036.2
1550.86	26958
1553.96	26991.2
1557.05	27067.9
1560.15	26879.1
1563.24	27080.4
1566.34	27115.1
1569.43	27137.5
1572.52	27141.3
1575.61	27029.3
1578.7	27086.9
1581.79	27096.7
1584.88	27091
1587.96	27164.5
1591.05	27147.3
1594.13	27191.2
1597.21	27232.5
1600.3	27262.5
1603.37	27335.1
1606.45	27235.6
1609.53	27246
1612.61	27128.5
1615.68	27168.4
1618.76	27156.3
1621.83	27198.2
1624.9	27198.4
1627.97	27362.5
1631.04	27478.8
1634.11	27605.8
1637.18	27770
1640.24	28093.5
1643.31	28571.5
1646.37	29532.1
1649.44	30205.5
1652.5	30251.2
1655.56	29569.1
1658.62	28806.8
1661.67	28251.4
1664.73	28053.4
1667.79	27869.1
1670.84	27583.6
1673.89	27324.3
1676.95	27198
1680	27044.9
1683.05	26951.6
1686.1	26758.3
1689.14	26825.4
1692.19	26738.1
1695.23	26686
1698.28	26604
1701.32	26526.7
1704.36	26557.4
1707.4	26567.2
1710.44	26437.2
1713.48	26509.3
1716.52	26493.5
1719.56	26541.2
1722.59	26764.4
1725.63	26878
1728.66	27026.7
1731.69	27185.7
1734.72	27517.8
1737.75	27811.2
1740.78	27953.8
1743.8	27958.8
1746.83	27737.8
1749.86	27510.5
1752.88	27146.8
1755.9	26723
1758.92	26654.7
1761.94	26505
1764.96	26323
1767.98	26353.8
1771	26375.3
1774.01	26290.8
1777.03	26223.6
1780.04	26294.1
1783.05	26250.4
1786.06	26259.7
1789.07	26288.9
1792.08	26255.1
1795.09	26222.2
1798.1	26163.7
1801.1	26202.4
1804.11	26290.6
1807.11	26109.2
1810.11	26221
1813.11	26179.5
1816.11	26175.3
1819.11	26143.2
1822.11	26155.5
1825.11	26174.8
1828.1	26204.8
1831.1	26178.3
1834.09	26214.4
1837.08	26095.8
1840.07	26180.1
1843.06	26207.1
1846.05	26204.8
1849.04	26165.8
1852.02	26188.4
1855.01	26065.6
1857.99	26129.5
1860.98	26174.8
1863.96	26135.9
1866.94	26191.7
1869.92	26171.1
1872.9	26076.7
1875.88	26189.8
1878.85	26116.5
1881.83	26135.3
1884.8	26038.7
1887.78	26016.9
1890.75	26015.1
1893.72	25998.8
1896.69	26044
1899.66	25926.1
1902.63	25919.8
1905.59	25779.3
1908.56	25746
1911.52	25554.5
1914.49	25464.9
1917.45	25348.5
1920.41	25223.5
1923.37	25154.9
1926.33	25220.2
1929.29	24983.8
1932.24	24934.4
1935.2	24858.3
1938.15	24700
1941.1	24618.4
1944.06	24526.8
1947.01	24442.7
1949.96	24344.6
1952.91	24228.8
1955.86	24065.9
1958.8	24026.2
1961.75	23911.2
1964.69	23874.4
1967.64	23783.5
1970.58	23655.9
1973.52	23599.7
1976.46	23511.3
1979.4	23439.5
1982.34	23318.9
1985.27	23253.7
1988.21	23145.3
1991.14	23078.2
1994.08	22876.1
1997.01	22838.6
1999.94	22725.5
2002.87	22642.7
2005.8	22625
2008.73	22585.5
2011.66	22497.5
2014.58	22431
2017.51	22312.6
2020.43	22242.8
2023.36	22100.2
2026.28	22040.7
2029.2	21976.2
2032.12	21931.7
2035.04	21834.6
2037.95	21828.3
2040.87	21723.9
2043.78	21644.3
2045.76	21593.5
2048.69	21575.5
2051.61	21458.6
2054.54	21542.1
2057.46	21514.2
2060.38	21411.5
2063.3	21476.2
2066.22	21450.8
2069.14	21429.7
2072.06	21388
2074.98	21381.4
2077.89	21317.6
2080.81	21271.2
2083.72	21296.6
2086.63	21263
2089.55	21184.9
2092.46	21242.3
2095.37	21137.6
2098.28	21181.3
2101.18	21123.5
2104.09	21095.8
2106.99	21030.5
2109.9	21019.6
2112.8	21001.5
2115.71	20956.2
2118.61	20981.4
2121.51	20958.9
2124.4	20943.6
2127.3	20914.3
2130.2	20849.9
2133.09	20884
2135.99	20840.7
2138.88	20929.8
2141.78	20818
2144.67	20860.5
2147.56	20780.5
2150.45	20799.5
2153.34	20791.5
2156.22	20799.1
2159.11	20789.9
2162	20766.4
2164.88	20731
2167.76	20722.3
2170.64	20678.6
2173.53	20727.9
2176.41	20671.6
2179.29	20636.4
2182.16	20579.9
2185.04	20562.6
2187.92	20523.9
2190.79	20539.6
2193.66	20496.8
2196.54	20406.4
2199.41	20493.4
2202.28	20437
2205.15	20434.1
2208.02	20435.3
2210.88	20376.2
2213.75	20274.3
2216.62	20285.6
2219.48	20162.6
2222.34	20168.7
2225.21	20095
2228.07	20158.3
2230.93	20110.9
2233.79	20061.8
2236.65	20053.7
2239.5	19976.2
2242.36	20001.8
2245.21	19901.9
2248.07	19860.1
2250.92	19816.9
2253.77	19741.5
2256.62	19718.3
2259.47	19653
2262.32	19558.2
2265.17	19593.6
2268.02	19486.8
2270.86	19482.3
2273.71	19470.4
2276.55	19398.7
2279.39	19370.7
2282.24	19328.6
2285.08	19247.7
2287.92	19224
2290.75	19247.2
2293.59	19177.7
2296.43	19212.4
2299.26	19174.9
2302.1	19103.3
2304.93	19061.5
2307.76	18936.7
2310.6	18986.3
2313.43	18935.5
2316.25	18882.9
2319.08	18817.1
2321.91	18821.1
2324.74	18946.1
2327.56	19042.5
2330.39	18718.3
2333.21	18667.6
2336.03	18561.1
2338.85	18616.1
2341.67	18587.3
2344.49	18585.7
2347.31	18515.7
2350.13	18491.3
2352.94	18376
2355.76	18349.7
2358.57	18216.6
2361.39	18285.6
2364.2	18243
2367.01	18265.3
2369.82	18159
2372.63	18132.1
2375.44	18112.1
2378.24	18099.5
2381.05	18059.8
2383.85	17996.4
2386.66	18036.7
2389.46	18023.4
2392.26	17936.1
2395.06	17975.6
2397.86	17834
2400.66	17936.7
2403.46	17892.6
2406.26	17746.3
2409.05	17824
2411.85	17744.9
2414.64	17763.7
2417.43	17701.1
2420.23	17580.1
2423.02	17632.1
2425.81	17581.6
2428.6	17574.5
2431.38	17645.7
2434.17	17593.6
2436.96	17549.8
2439.74	17465.7
2442.53	17395.4
2445.31	17427.4
2448.09	17442.3
2450.87	17383.9
2453.65	17380.3
2456.43	17427.1
2459.21	17252.2
2461.98	17321.4
2464.76	17264.1
2467.53	17183.6
2470.31	17220.9
2473.08	17149.3
2475.85	17116.1
2478.63	17106.2
2481.39	17107.3
2484.16	17047.6
2486.93	17071.2
2489.7	17040.6
2492.46	17031.1
2495.23	16913.9
2497.99	16933.3
2500.76	16877.8
2503.52	16864.8
2506.28	16820.9
2509.04	16837
2511.8	16831.1
2514.56	16756.8
2517.31	16779.6
2520.07	16770.9
2522.82	16702.1
2525.58	16736.3
2528.33	16744.4
2531.09	16634.2
2533.84	16694.2
2536.59	16641.2
2539.34	16625.8
2542.08	16596.5
2544.83	16534.2
2547.58	16482.2
2550.32	16446.8
2553.07	16388.3
2555.81	16373.9
2558.55	16392.1
2561.29	16313.4
2564.03	16366.4
2566.77	16311.8
2569.51	16304
2572.25	16327.7
2574.99	16227
2577.72	16252.1
2580.46	16258.5
2583.19	16231
2585.92	16273.2
2588.65	16186.9
2591.38	16206.6
2594.11	16228
2596.84	16219.3
2599.57	16131.4
2602.3	16152.9
2605.02	16166.2
2607.75	16121.5
2610.47	16140.7
2613.19	16087.8
2615.92	16002
2618.64	15990
2621.36	16000.2
2624.08	16003.2
2626.8	15988.1
2629.51	15922.1
2632.23	15894
2634.94	15930.3
2637.66	15856
2640.37	15878.6
2643.08	15818
2645.79	15849.2
2648.5	15886
2651.21	15855.9
2653.92	15821.3
2656.63	15776.7
2659.33	15813.4
2662.04	15803.8
2664.75	15744.4
2667.45	15787.9
2670.15	15759.6
2672.85	15760.7
2675.55	15734.5
2678.25	15643.2
2680.95	15634.5
2683.65	15604.4
2686.35	15598.2
2689.04	15617.6
2691.74	15581.3
2694.43	15543.2
2697.13	15568.7
2699.82	15554.1
2702.51	15557.8
2705.2	15579
2707.89	15562.1
2710.58	15511.7
2713.26	15546.9
2715.95	15531.9
2718.64	15520.2
2721.32	15552.1
2724	15443
2726.69	15420
2729.37	15435.2
2732.05	15391.2
2734.73	15418.5
2737.41	15216.4
2740.09	15164.8
2742.76	15089
2745.44	15130.6
2748.11	15038.7
2750.79	15000
2753.46	15009.3
2756.13	14932.5
2758.81	14955.4
2761.47	14855
2764.14	14847.1
2766.81	14862.9
2769.48	14836.1
2772.15	14779.3
2774.81	14758.6
2777.48	14766
2780.14	14684.3
2782.8	14671.1
2785.47	14626.7
2788.13	14576.9
2790.79	14677.4
2793.44	14634.4
2796.1	14622.4
2798.76	14630.7
2801.42	14585.8
2804.07	14550.7
2806.73	14551.6
2809.38	14580.8
2812.03	14592.1
2814.68	14563
2817.33	14592.2
2819.98	14600.6
2822.63	14667.7
2825.28	14692.3
2827.93	14825.2
2830.57	14915.9
2833.22	15153.2
2835.86	15586.2
2838.51	16092.1
2841.15	16911.5
2843.79	17909.5
2846.43	18779
2849.07	19175.6
2851.71	19054.4
2854.35	18826.3
2856.98	18482.9
2859.62	18196.5
2862.25	17988.5
2864.89	17884.1
2867.52	18009.2
2870.15	18226.4
2872.78	18344.4
2875.41	18536.5
2878.04	18691.2
2880.67	18802.6
2883.3	18759
2885.92	18713.8
2888.55	18852.8
2891.18	18794.3
2893.8	18712.2
2896.42	18757.9
2899.04	18655.2
2901.67	18609.8
2904.29	18538.8
2906.9	18463.9
2909.52	18470.3
2912.14	18377.2
2914.76	18379.3
2917.37	18279.5
2919.99	18249.9
2922.6	18248.9
2925.21	18163.8
2927.82	18174.8
2930.44	18151.8
2933.05	18082.2
2935.65	17903.4
2938.26	17609.1
2940.87	17157.8
2943.48	16604.3
2946.08	16217.3
2948.69	16005.9
2951.29	15808.7
2953.89	15789.3
2956.49	15663.1
2959.1	15504.7
2961.7	15399.2
2964.29	15183.5
2966.89	15001.8
2969.49	14873.9
2972.09	14666.2
2974.68	14535
2977.28	14579.5
2979.87	14364.3
2982.46	14324.1
2985.05	14169.1
2987.65	14084.9
2990.24	14018.8
2992.82	14004.8
2995.41	13986.1
2998	13963.9
3000.59	13921.7
3003.17	13946.6
3005.76	13949.9
3008.34	13876.8
3010.92	13808.4
3013.5	13730.5
3016.09	13706
3018.67	13619.4
3021.25	13618.2
3023.82	13649
3026.4	13635.4
3028.98	13541.2
3031.55	13493.8
3034.13	13495.6
3036.7	13526.8
3039.28	13538.4
3041.85	13596.3
3044.42	13531.4
3046.99	13519.2
3049.56	13602.4
3052.13	13590.5
3054.69	13663.2
3057.26	13639.9
3059.83	13665.6
3062.39	13733.3
3064.95	13693
3067.52	13747
3070.08	13748.9
3072.64	13750.8
3075.2	13833.9
3077.76	13788.4
3080.32	13775.1
3082.88	13859.7
3085.44	13836.6
3087.99	13867.3
3090.55	13930.6
3093.1	13947.4
3095.65	13918.6
3098.21	14026
3100.76	14049.8
3103.31	14080.9
3105.86	14163.5
3108.41	14220.8
3110.96	14271.5
3113.5	14287.7
3116.05	14370.5
3118.59	14347.9
3121.14	14436.9
3123.68	14471.5
3126.23	14591
3128.77	14678.1
3131.31	14770.9
3133.85	14750.8
3136.39	14807.3
3138.93	14895.2
3141.46	14835.3
3144	14955.8
3146.54	14984.2
3149.07	15063
3151.6	15146.3
3154.14	15227.2
3156.67	15286.8
3159.2	15349.7
3161.73	15336.9
3164.26	15367
3166.79	15409.3
3169.32	15420.9
3171.84	15387.1
3174.37	15342.9
3176.9	15363.5
3179.42	15288.3
3181.94	15301
3184.47	15274
3186.99	15261
3189.51	15245.2
3192.03	15204.2
3194.55	15200.4
3197.07	15134.9
3199.58	15128.2
3202.1	15094.8
3204.62	15061.9
3207.13	15019.8
3209.65	15003.9
3212.16	14920
3214.67	14863.7
3217.18	14840.8
3219.69	14841.9
3222.2	14768.1
3224.71	14739
3227.22	14679.1
3229.73	14659.8
3232.23	14609.6
3234.74	14548.7
3237.24	14545.3
3239.75	14456.2
3242.25	14390.1
3244.75	14385.4
3247.25	14298.9
3249.75	14257.9
3252.25	14167.5
3254.75	14112.8
3257.25	14026.1
3259.74	13966.1
3262.24	13884.9
3264.73	13831.6
3267.23	13826
3269.72	13746.3
3272.21	13727.9
3274.7	13684.4
3277.2	13607.3
3279.69	13492.7
3282.17	13438.9
3284.66	13415.1
3287.15	13400.6
3289.64	13323.7
3292.12	13281
3293.56	13205.8
3296.05	13135.8
3298.55	13126.8
3301.04	13054.8
3303.54	13019.2
3306.03	13011.1
3308.52	12979.8
3311.01	12939.1
3313.5	12866
3315.99	12800.8
3318.48	12751
3320.97	12769.3
3323.45	12747.7
3325.94	12665.1
3328.42	12577.8
3330.91	12593.5
3333.39	12556.7
3335.87	12503
3338.36	12430.1
3340.84	12396.7
3343.32	12347
3345.8	12327.6
3348.27	12270
3350.75	12209.9
3353.23	12158.9
3355.7	12172.3
3358.18	12092
3360.65	12081.6
3363.13	12011.3
3365.6	12000.7
3368.07	11940.3
3370.54	11933.6
3373.01	11922.9
3375.48	11857.1
3377.95	11815
3380.42	11764.1
3382.88	11744.4
3385.35	11606.4
3387.81	11608.1
3390.28	11547.8
3392.74	11549.2
3395.2	11494.6
3397.67	11447.2
3400.13	11464.5
3402.58	11342.3
3405.05	11328.1
3407.5	11294.5
3409.96	11245.6
3412.42	11117.2
3414.87	11117.2
3417.33	11089.6
3419.78	10995.1
3422.23	10978.9
3424.69	10890.9
3427.14	10848
3429.59	10785.8
3432.04	10714.8
3434.49	10625
3436.94	10607.8
3439.39	10558.8
3441.83	10466.2
3444.28	10383.1
3446.72	10315.2
3449.17	10278.8
3451.61	10196.1
3454.05	10174.9
3456.5	10053.7
3458.94	10023.8
3461.38	9914.24
3463.81	9855.21
3466.25	9829.04
3468.69	9726.77
3471.13	9631.96
3473.56	9549.57
3476	9482.5
3478.43	9366.33
3480.87	9348.2
3483.3	9183.12
3485.73	9175.44
3488.16	9066.9
3490.59	8996.38
3493.02	8935.98
3495.45	8826.34
3497.88	8712.37
3499.09	8710.55