File: src/Milk_AI/Nandani full cream RT 532nm 50% 600g 50xL 10s 10times 400-3500cm-1 200hole.txt
#Acq. time (s)=	10
#Accumulations=	10
#Range (cm-¹)=	400...3500
#Windows=	3
#Auto scanning=	Off
#Autofocus=	Off
#AutoExposure=	Off
#Spike filter=	Multiple accum.
#Delay time (s)=	0
#Binning=	1
#Readout mode=	Signal
#DeNoise=	Off
#ICS correction=	On
#Dark correction=	Off
#Inst. Process=	Off
#Detector Gain=	Best Dynamic Range
#Detector ADC=	45 kHz
#Detector temperature (°C)=	-60.1
#Instrument=	LabRAM HR Evol
#Detector=	Syncerity OE
#Objective=	x50_VIS_LWD
#Grating=	600 (500nm)
#ND Filter=	50%
#Laser=	532nm_Edge
#Hole=	199.981
#Range=	Visible
#E-Cal_Neon=	0
#StageXY=	75x50mm Scan+
#StageZ=	Z motor
#X (µm)=	0
#Y (µm)=	0
#Z (µm)=	870.3
#Spectral res.(cm-¹)=	12.8
#Full time(mm:ss)=	5:19
#AC=	Calibrated 2025-06-30 10:26
#Project=
#Sample=
#Site=
#Title=	D_99
#Remark=
#Date=	30.06.2025 14:38 (India Standard Time)
#Acquired=	30.06.2025 14:38:49 (India Standard Time)
#AxisType[0]=Intens
#AxisUnit[0]=Cnt
#AxisType[1]=Spectr
#AxisUnit[1]=1/cm
400.17	23367.3
403.717	23162.1
407.263	23284.9
410.807	23125.1
414.35	23094.9
417.892	23184.3
421.432	23190
424.971	23060.1
428.509	23078.2
432.045	23118.3
435.58	23084.7
439.111	22977.3
442.643	22984.1
446.174	22940.6
449.701	22925.4
453.229	22893.5
456.756	22769.3
460.279	22745.7
463.803	22656.7
467.326	22650.1
470.845	22643.2
474.365	22506.1
477.882	22506.1
481.399	22543
484.913	22458.4
488.425	22452.2
491.938	22480.1
495.448	22383.8
498.956	22439.8
502.465	22451.4
505.971	22494
509.475	22482
512.981	22491.8
516.482	22503.6
519.983	22431.4
523.482	22392.4
526.979	22349
530.476	22175.4
533.971	22135.4
537.464	22089.6
540.956	22012.6
544.447	21945.4
547.937	21919.9
551.425	21913.6
554.912	21868.2
558.398	21777.6
561.882	21736.1
565.365	21699.7
568.847	21742.6
572.325	21783
575.804	21838.5
579.282	21868.3
582.756	21739.3
586.231	21915.7
589.705	21931.2
593.175	21925
596.646	22006.6
600.116	21983.5
603.582	22095.6
607.049	22042.1
610.513	21948.5
613.977	21829.5
617.438	21717.3
620.898	21646.5
624.359	21564.5
627.816	21431.9
631.272	21395.7
634.728	21385.4
638.181	21331.3
641.633	21454.4
645.084	21267.9
648.535	21265.4
651.983	21118.7
655.43	21119.8
658.875	21117
662.319	21012.2
665.762	20957.7
669.203	20988.5
672.643	20964.1
676.082	20970.4
679.519	20897.6
682.955	20938.4
686.39	20917.6
689.824	20899.9
693.256	20958.8
696.685	20961
700.115	20998.3
703.543	20971.7
706.97	21026.2
710.394	20941.1
713.818	20982.8
717.241	20983.9
720.661	21079.5
724.082	21115.4
727.501	21060.3
730.917	20991.9
734.334	21005.5
737.747	20941.6
741.161	20909.1
744.572	20845.1
747.982	20870.9
751.392	20827.4
754.799	20932.4
758.205	20962.5
761.611	20948.5
765.014	20900.7
768.416	20968.2
771.816	20986.6
775.218	20935.9
778.616	20946.3
782.012	20975
785.408	20970
788.802	21005.8
792.195	21047.7
795.586	20983.2
798.977	21059.5
802.365	21149.4
805.753	21204.8
809.14	21299.6
812.525	21229.8
815.907	21386
819.289	21504
822.671	21675.2
826.051	21885
829.43	21867.7
832.805	22112.4
836.182	22155
839.557	22374.5
842.928	22494.1
846.301	22575.6
849.67	22596.8
853.04	22591.1
856.407	22678.5
859.774	22841.6
863.138	22903.2
866.503	23105
869.865	23178.1
873.225	23142.8
876.586	23034.5
879.944	22814.6
883.301	22686.3
886.658	22775.8
890.012	22790.4
893.365	22567.7
896.717	22270.2
900.067	21975.1
903.416	21794.1
906.766	21618.2
910.112	21478.9
913.458	21498.5
916.802	21456.8
920.145	21549.7
923.484	21430
926.825	21184
930.164	21095.9
933.501	20954.4
936.838	20881.5
940.173	20883.6
943.505	20862.2
946.838	20985.6
950.17	20947
953.5	21041.8
956.827	21042.1
960.155	20976.3
963.48	21039.3
966.805	20972.5
970.128	20890.5
973.45	20772
976.77	20668.5
980.091	20578.2
983.408	20638.5
986.726	20604.7
990.041	20815.8
993.354	21057.4
996.668	21366.7
999.979	22237.1
1003.29	22831
1006.6	22786
1009.91	22252.8
1013.21	21835.1
1016.52	21604.1
1019.82	21415.5
1023.12	21377
1026.43	21112.1
1029.73	21072.7
1033.02	20995.3
1036.32	21000.3
1039.62	20975.6
1042.91	20974.6
1046.21	20880.7
1049.5	20978
1052.79	21146.3
1056.08	21524.8
1059.37	22201.8
1062.65	22859.7
1065.94	22684.2
1069.23	22219.4
1072.51	22290
1075.79	22398.7
1079.07	22689.9
1082.35	22633.5
1085.63	22416.8
1088.91	22164.2
1092.18	21792.3
1095.46	21396.9
1098.73	21024
1102	20693.5
1105.27	20361.9
1108.54	20415.9
1111.81	20487.9
1115.08	20692.7
1118.34	20952.9
1121.61	21300.8
1124.87	21447.1
1128.13	21413.8
1131.39	20837.3
1134.65	20319.6
1137.91	20118
1141.17	20426.2
1144.42	21018.1
1147.68	21984.4
1150.93	23631.4
1154.18	25709.8
1157.43	26677.4
1160.68	24651.7
1163.93	22102.7
1167.18	20621
1170.42	20101.2
1173.67	19940.5
1176.91	19690.4
1180.15	19490.5
1183.39	19553.2
1186.63	19697.8
1189.87	19816.3
1193.11	19785.3
1196.34	19598.4
1199.58	19230.4
1202.81	19019.1
1206.04	18832
1209.27	18765.1
1212.5	18834.3
1215.73	18625.6
1218.95	18362
1222.18	18266.4
1225.4	18239.2
1228.63	18184.4
1231.85	18252.2
1235.07	18313.2
1238.29	18432.2
1241.51	18587.5
1244.72	18794.2
1247.94	18893.6
1251.15	19089.6
1254.37	19334.4
1257.58	19440.8
1260.79	19571.4
1264	19781.6
1267.21	19927.8
1270.41	19789.8
1273.62	19661.4
1276.82	19600.2
1280.03	19622.9
1283.23	19638.5
1286.43	19828.2
1289.63	20237
1292.83	21276
1296.03	22577.3
1299.22	23157.9
1302.42	23142.1
1305.61	22665.5
1308.8	21755.3
1311.99	20964.1
1315.18	20123.3
1318.37	19507.8
1321.56	18985.1
1324.74	18627
1327.93	18202.6
1331.11	17951
1334.3	17715.2
1337.48	17610.6
1340.66	17663
1343.84	17449.1
1347.01	17528.6
1350.19	17301.5
1353.37	17372.9
1356.54	17229.3
1359.71	17134.1
1362.88	17183.5
1366.05	17214
1369.22	17128.4
1372.39	17045.8
1375.56	16697.4
1378.72	16533.6
1381.89	16421
1385.05	16345.6
1388.21	16380.8
1391.37	16363
1394.53	16352.5
1397.69	16332.9
1400.85	16356.1
1404	16479.7
1407.16	16493.3
1410.31	16691.3
1413.46	17020.7
1416.61	17465.4
1419.76	17816.9
1422.91	18229.9
1426.06	18824.6
1429.21	20243.2
1432.35	22475.4
1435.49	24662.5
1438.64	25986.5
1441.78	25821.3
1444.92	25053.3
1448.06	24280.5
1451.2	23602.1
1454.33	23251.8
1457.47	22711.7
1460.6	21942.1
1463.74	20963.6
1466.87	19918.3
1470	18974.1
1473.13	18051.2
1476.26	17306
1479.38	16808.2
1482.51	16515.7
1485.63	16269
1488.76	16254.5
1491.88	16236.8
1495	16311.1
1498.12	16452.2
1501.24	16670.5
1504.36	17151.9
1507.47	17757.8
1510.59	18751.7
1513.7	20118.6
1516.81	21410.9
1519.93	22471.8
1523.04	22669
1526.15	21888.1
1529.25	20300
1532.36	18392.3
1535.47	16942.9
1538.57	16031.6
1541.67	15506.2
1544.78	15102
1547.88	14869.2
1550.98	14697.3
1554.08	14614.9
1557.18	14586.6
1560.27	14387.1
1563.37	14422.9
1566.46	14303.5
1569.55	14364.1
1572.64	14330.3
1575.74	14285.5
1578.83	14362.8
1581.91	14290.1
1585	14280.9
1588.09	14263
1591.17	14248
1594.25	14241.1
1597.34	14227.8
1600.42	14191.6
1603.5	14256.2
1606.58	14183
1609.65	14157.8
1612.73	14098
1615.8	13968.2
1618.88	14011.6
1621.95	13999.9
1625.03	14047.7
1628.1	14133.7
1631.17	14156.3
1634.23	14239.4
1637.3	14418.5
1640.37	14638
1643.43	15010
1646.5	15720
1649.56	16945.7
1652.62	17974.2
1655.68	17972
1658.74	16821
1661.8	15717.5
1664.85	15130.4
1667.91	14866.8
1670.96	14505.9
1674.02	14116.9
1677.07	13685.3
1680.12	13493.8
1683.17	13324.4
1686.22	13220.1
1689.27	13087.1
1692.31	13074.8
1695.36	12965.3
1698.4	12875
1701.45	12774.9
1704.49	12764.4
1707.53	12657.6
1710.57	12646.4
1713.61	12605.7
1716.65	12668.8
1719.68	12599.8
1722.72	12705.3
1725.75	12803.6
1728.78	12928.9
1731.82	13126.2
1734.84	13397.3
1737.87	13791.5
1740.9	14185.6
1743.93	14178.9
1746.96	14195
1749.98	13991.3
1753	13656.4
1756.03	13208.1
1759.05	12788.6
1762.07	12499.5
1765.09	12234.6
1768.11	12136.3
1771.12	12051.9
1774.14	11992.1
1777.15	11895.3
1780.17	11854.8
1783.18	11871.3
1786.19	11790.4
1789.2	11868
1792.21	11778.3
1795.22	11699.8
1798.22	11767.6
1801.23	11719.6
1804.23	11646.1
1807.24	11669.6
1810.24	11683.2
1813.24	11664
1816.24	11568.4
1819.24	11492
1822.24	11500.8
1825.23	11481.8
1828.23	11437
1831.22	11457.8
1834.22	11410.5
1837.21	11355.7
1840.2	11435.2
1843.19	11319.8
1846.18	11427.1
1849.17	11369.5
1852.15	11242.9
1855.14	11275.3
1858.12	11266
1861.11	11203.4
1864.09	11181.7
1867.07	11202.3
1870.05	11187.7
1873.03	11070
1876.01	11126.2
1878.98	11129.5
1881.96	11078.2
1884.93	11041.9
1887.91	10940.2
1890.88	11042.1
1893.85	10956.3
1896.82	10902.7
1899.79	10857.4
1902.76	10839.5
1905.72	10720.4
1908.69	10691.5
1911.65	10592.2
1914.62	10513.1
1917.58	10383.7
1920.54	10395.3
1923.5	10281.8
1926.46	10276.1
1929.42	10221
1932.37	10117.2
1935.33	10054.2
1938.28	9954.32
1941.24	9908.62
1944.19	9883.84
1947.14	9760.45
1950.09	9744.19
1953.04	9655.28
1955.99	9561.85
1958.93	9536.8
1961.88	9496
1964.82	9400.21
1967.77	9366.15
1970.71	9286.46
1973.65	9232
1976.59	9201.72
1979.53	9138.81
1982.47	9114.98
1985.41	9048.01
1988.34	9020.95
1991.28	8928.08
1994.21	8855.8
1997.14	8823.99
2000.07	8750.9
2003.01	8702.67
2005.94	8655.29
2008.86	8635.21
2011.79	8579.2
2014.72	8550.63
2017.64	8486.19
2020.57	8428.08
2023.49	8390.02
2026.41	8352.16
2029.33	8297.65
2032.25	8243.22
2035.17	8257.22
2038.09	8171.04
2041	8179.07
2043.92	8135.7
2045.86	8072.24
2048.79	8071.82
2051.71	8054.59
2054.64	8032.86
2057.56	8039.23
2060.48	8012.21
2063.4	7947.69
2066.32	7978.04
2069.24	7967.39
2072.16	7943.27
2075.08	7985.8
2077.99	7935.52
2080.91	7902.76
2083.82	7894.81
2086.74	7871.93
2089.65	7890.47
2092.56	7857.4
2095.47	7821.56
2098.38	7814.22
2101.29	7787.65
2104.19	7786.25
2107.1	7760.19
2110	7765.63
2112.91	7702.51
2115.81	7698.76
2118.71	7692.72
2121.61	7682.08
2124.51	7637.78
2127.4	7656.38
2130.3	7640.14
2133.2	7618.12
2136.09	7630.91
2138.99	7627.45
2141.88	7583.49
2144.77	7555.73
2147.66	7553.73
2150.55	7548.29
2153.44	7522.34
2156.33	7512.68
2159.21	7538.34
2162.1	7510.52
2164.98	7539.16
2167.87	7499.15
2170.75	7466.12
2173.63	7463.34
2176.51	7444.48
2179.39	7419.6
2182.27	7429.27
2185.14	7417.66
2188.02	7365.88
2190.9	7347.82
2193.77	7367.09
2196.64	7333.61
2199.51	7336.38
2202.39	7297.9
2205.25	7265.11
2208.12	7240.01
2210.99	7223.76
2213.86	7219.14
2216.72	7148
2219.59	7161.19
2222.45	7129.42
2225.31	7098.45
2228.17	7086.88
2231.03	7093.48
2233.89	7095.69
2236.75	7026.98
2239.61	7014.32
2242.46	6999.33
2245.32	6970.01
2248.17	6953.04
2251.03	6934.1
2253.88	6905.15
2256.73	6893.12
2259.58	6883.42
2262.43	6818.77
2265.28	6793.43
2268.12	6782.73
2270.97	6728.65
2273.81	6709.82
2276.66	6750.2
2279.5	6696.05
2282.34	6691.47
2285.18	6673.75
2288.02	6659.33
2290.86	6629.41
2293.7	6605.73
2296.54	6601.13
2299.37	6578.26
2302.21	6584.88
2305.04	6569.3
2307.87	6513.91
2310.7	6536.63
2313.53	6517
2316.36	6476.77
2319.19	6439.77
2322.02	6412.49
2324.85	6449.64
2327.67	6556.88
2330.5	6679.58
2333.32	6379.63
2336.14	6308.46
2338.96	6294.57
2341.78	6265.04
2344.6	6246.28
2347.42	6233.05
2350.24	6205.76
2353.05	6166.1
2355.87	6158.32
2358.68	6113.47
2361.5	6112.13
2364.31	6083.66
2367.12	6082.63
2369.93	6039.91
2372.74	6039.3
2375.55	6025.55
2378.35	5975.81
2381.16	5984.25
2383.96	5950.07
2386.77	5945.2
2389.57	5948.86
2392.37	5923.34
2395.17	5905.9
2397.97	5862.65
2400.77	5851.84
2403.57	5862.98
2406.37	5829.94
2409.16	5811.7
2411.96	5792.96
2414.75	5790.56
2417.55	5767
2420.34	5741.18
2423.13	5753.49
2425.92	5767.3
2428.71	5731.74
2431.5	5687.41
2434.28	5699.52
2437.07	5657.8
2439.85	5663.89
2442.64	5646.52
2445.42	5629.51
2448.2	5596.46
2450.98	5584.94
2453.76	5595.24
2456.54	5588.14
2459.32	5546.52
2462.1	5509.03
2464.87	5514.32
2467.65	5477.8
2470.42	5467.85
2473.2	5448.36
2475.97	5454.21
2478.74	5465.02
2481.51	5433.16
2484.28	5395.4
2487.05	5386.41
2489.81	5381.98
2492.58	5369.47
2495.34	5395.88
2498.11	5383.76
2500.87	5319.78
2503.63	5329.56
2506.39	5285.51
2509.15	5282
2511.91	5254.48
2514.67	5251.01
2517.43	5236.63
2520.19	5258.38
2522.94	5230.92
2525.7	5233.52
2528.45	5196.4
2531.2	5169.14
2533.95	5200.14
2536.7	5141.32
2539.45	5150.87
2542.2	5118.6
2544.95	5100.02
2547.69	5084.05
2550.44	5061.19
2553.18	5084.98
2555.93	5018.72
2558.67	5015.23
2561.41	5025.25
2564.15	5003.9
2566.89	5008.05
2569.63	4967.58
2572.36	4980.5
2575.1	4983.78
2577.84	4948.99
2580.57	4956.58
2583.31	4942.35
2586.04	4948.09
2588.77	4940.66
2591.5	4961.18
2594.23	4979.65
2596.96	4977.54
2599.69	4931.03
2602.41	4939.4
2605.14	4945.15
2607.86	4916.12
2610.59	4894.73
2613.31	4896.89
2616.03	4853.28
2618.75	4870.38
2621.48	4868.41
2624.19	4857.6
2626.91	4872.23
2629.63	4827.44
2632.35	4840.81
2635.06	4841.2
2637.77	4829.21
2640.49	4811.88
2643.2	4834.13
2645.91	4824.17
2648.62	4797.94
2651.33	4815.11
2654.04	4835.49
2656.75	4824.77
2659.45	4826.79
2662.16	4838.88
2664.86	4835.88
2667.57	4857.85
2670.27	4848.91
2672.97	4847.69
2675.67	4840.82
2678.37	4830.6
2681.07	4832.49
2683.77	4806.41
2686.47	4796.9
2689.16	4802.48
2691.86	4762.27
2694.55	4790.76
2697.25	4792.99
2699.94	4785.85
2702.63	4809.32
2705.32	4845.86
2708.01	4850.94
2710.7	4938.63
2713.39	4926.66
2716.07	4972.55
2718.76	5010.82
2721.44	5016.7
2724.12	5029.55
2726.81	5009.3
2729.49	5017.41
2732.17	4941.28
2734.85	4876.14
2737.53	4829.15
2740.21	4708.1
2742.88	4659.53
2745.56	4610.03
2748.24	4527.98
2750.91	4471.57
2753.58	4443.27
2756.25	4425.03
2758.93	4387.55
2761.6	4356.18
2764.27	4361.41
2766.93	4290.89
2769.6	4306.62
2772.27	4268.04
2774.93	4279.94
2777.6	4290.5
2780.26	4250.21
2782.93	4264.96
2785.59	4260.2
2788.25	4197.5
2790.91	4264.83
2793.57	4268.44
2796.23	4314.27
2798.88	4297.74
2801.54	4303.4
2804.2	4279.14
2806.85	4290.5
2809.5	4320.78
2812.16	4369.55
2814.81	4370.62
2817.46	4449.12
2820.11	4513.61
2822.76	4582.88
2825.4	4703.42
2828.05	4870.07
2830.7	5060.48
2833.34	5353.68
2835.99	5816.84
2838.63	6530.21
2841.27	7617.3
2843.91	9354.59
2846.55	11554.3
2849.19	13467.9
2851.83	14318
2854.47	14005.7
2857.11	13329.3
2859.74	12697.1
2862.38	12114.7
2865.01	11731.8
2867.65	11564.8
2870.28	11738.6
2872.91	12073.9
2875.54	12409.3
2878.17	12684.7
2880.8	13047
2883.42	13255.3
2886.05	13280.1
2888.68	13302.9
2891.3	13349.2
2893.93	13289.4
2896.55	13262.5
2899.17	13243.2
2901.79	13181.1
2904.41	13065.3
2907.03	12948
2909.65	12868.1
2912.27	12782.6
2914.88	12727.2
2917.5	12609.5
2920.11	12520.4
2922.73	12495
2925.34	12462.4
2927.95	12515.2
2930.56	12471.9
2933.17	12464.5
2935.78	12267.2
2938.39	11925.9
2941	11280.8
2943.6	10340.4
2946.21	9467.09
2948.81	8723.07
2951.42	8287.36
2954.02	8006.96
2956.62	7864.11
2959.22	7734.94
2961.82	7515.43
2964.42	7239.55
2967.02	6937.93
2969.62	6602.53
2972.21	6275.9
2974.81	5974.01
2977.4	5707.5
2980	5477.25
2982.59	5288.55
2985.18	5131.79
2987.77	5026.15
2990.36	4903.05
2992.95	4860.38
2995.54	4822.56
2998.13	4777.83
3000.72	4768.39
3003.3	4785.64
3005.89	4809.63
3008.47	4752.89
3011.05	4700.53
3013.63	4556.17
3016.22	4441.53
3018.8	4280.69
3021.38	4174.92
3023.95	4130.99
3026.53	4029.64
3029.11	3995.98
3031.68	3956.22
3034.26	3925.86
3036.83	3885.59
3039.4	3903.44
3041.98	3866.6
3044.55	3855.7
3047.12	3867.73
3049.69	3867.61
3052.26	3873.04
3054.82	3881.37
3057.39	3884.19
3059.96	3907.61
3062.52	3917.34
3065.09	3871.36
3067.65	3918.91
3070.21	3916.24
3072.77	3928.72
3075.33	3889.05
3077.89	3911.41
3080.45	3886.35
3083.01	3895.5
3085.57	3923.9
3088.12	3906.28
3090.68	3916.47
3093.23	3977.15
3095.79	3933.01
3098.34	3977.74
3100.89	3973.89
3103.44	4010.11
3105.99	4035.78
3108.54	4080.83
3111.09	4054.31
3113.63	4115.88
3116.18	4119.77
3118.73	4174.94
3121.27	4199.8
3123.82	4211.95
3126.36	4257.09
3128.9	4284.06
3131.44	4313.23
3133.98	4344.58
3136.52	4401.06
3139.06	4424.84
3141.6	4436.71
3144.13	4458.1
3146.67	4523.54
3149.2	4541.37
3151.74	4575.55
3154.27	4635.45
3156.8	4650.82
3159.34	4646.43
3161.86	4708.17
3164.4	4720.63
3166.92	4787.58
3169.45	4781.42
3171.98	4773.26
3174.5	4767.59
3177.03	4762.06
3179.56	4705.98
3182.08	4712.98
3184.6	4707.19
3187.12	4679.32
3189.64	4670.44
3192.16	4657.07
3194.68	4657.88
3197.2	4605.6
3199.72	4583
3202.24	4568.51
3204.75	4567.14
3207.27	4541.18
3209.78	4504.52
3212.29	4485.18
3214.81	4446.1
3217.32	4400.05
3219.83	4378.57
3222.34	4342.55
3224.85	4312.49
3227.35	4292.01
3229.86	4247.92
3232.37	4222.99
3234.87	4183.06
3237.38	4173.06
3239.88	4119.98
3242.38	4097.63
3244.89	4041.36
3247.39	4014.09
3249.89	3969.15
3252.39	3941.2
3254.88	3894.83
3257.38	3851.63
3259.88	3795.17
3262.37	3765.15
3264.87	3739.2
3267.36	3697.8
3269.86	3675.42
3272.35	3648.05
3274.84	3593.5
3277.33	3573.55
3279.82	3500.4
3282.31	3470.71
3284.8	3442.95
3287.29	3417.67
3289.77	3383.16
3292.26	3321.99
3294.15	3288.56
3296.64	3262.75
3299.14	3225.26
3301.63	3197.97
3304.12	3177.53
3306.62	3130.4
3309.11	3114.13
3311.6	3077.96
3314.09	3083.96
3316.58	3016.31
3319.07	2981
3321.56	2945.45
3324.04	2945.64
3326.53	2924.22
3329.01	2862.67
3331.5	2852.59
3333.98	2803.12
3336.46	2766.64
3338.94	2719.25
3341.42	2717.32
3343.9	2669.8
3346.38	2685.64
3348.86	2626.03
3351.34	2598.17
3353.82	2545.82
3356.29	2522.63
3358.77	2518.13
3361.24	2479.83
3363.71	2457.31
3366.19	2420.34
3368.66	2378.61
3371.13	2377.64
3373.6	2338.69
3376.07	2323.17
3378.54	2258.03
3381	2264.98
3383.47	2237.95
3385.94	2184.29
3388.4	2167.85
3390.87	2124.76
3393.33	2101.72
3395.79	2068.23
3398.25	2058.32
3400.71	2013.8
3403.17	1968.51
3405.63	1944.26
3408.09	1927.41
3410.55	1875.5
3413	1842.23
3415.46	1802.72
3417.92	1763.97
3420.37	1769.98
3422.82	1716.09
3425.27	1682.39
3427.73	1631.6
3430.18	1624.43
3432.63	1531.7
3435.08	1518.13
3437.53	1473.89
3439.97	1457.28
3442.42	1385.96
3444.86	1364.57
3447.31	1326.19
3449.75	1269.49
3452.2	1236.54
3454.64	1187.08
3457.08	1159.77
3459.52	1125.73
3461.96	1076.67
3464.4	1026.98
3466.84	977.497
3469.28	933.21
3471.72	899.138
3474.15	844.038
3476.59	789.491
3479.02	753.794
3481.45	698.173
3483.89	607.165
3486.32	578.926
3488.75	548.482
3491.18	477.145
3493.61	445.179
3496.04	360.68
3498.47	347.309
3499.68	331.418