File: src/Milk_AI/Nandani full cream RT after 24 h 532nm 50% 600g 50xL 10s 10times 400-3500cm-1 200hole.txt
#Acq. time (s)=	10
#Accumulations=	10
#Range (cm-¹)=	400...3500
#Windows=	3
#Auto scanning=	Off
#Autofocus=	Off
#AutoExposure=	Off
#Spike filter=	Multiple accum.
#Delay time (s)=	0
#Binning=	1
#Readout mode=	Signal
#DeNoise=	Off
#ICS correction=	On
#Dark correction=	Off
#Inst. Process=	Off
#Detector Gain=	Best Dynamic Range
#Detector ADC=	45 kHz
#Detector temperature (°C)=	-60.1
#Instrument=	LabRAM HR Evol
#Detector=	Syncerity OE
#Objective=	x50_VIS_LWD
#Grating=	600 (500nm)
#ND Filter=	50%
#Laser=	532nm_Edge
#Hole=	199.981
#Range=	Visible
#E-Cal_Neon=	0
#StageXY=	75x50mm Scan+
#StageZ=	Z motor
#X (µm)=	0
#Y (µm)=	0
#Z (µm)=	701.5
#Spectral res.(cm-¹)=	12.8
#Full time(mm:ss)=	5:19
#AC=	Calibrated 2025-07-01 10:31
#Project=
#Sample=
#Site=
#Title=	D_1
#Remark=
#Date=	01.07.2025 16:44 (India Standard Time)
#Acquired=	01.07.2025 16:44:43 (India Standard Time)
#AxisType[0]=Intens
#AxisUnit[0]=Cnt
#AxisType[1]=Spectr
#AxisUnit[1]=1/cm
400.083	19612.7
403.63	19441
407.176	19473.4
410.72	19482.2
414.263	19451.1
417.805	19471.3
421.345	19433.4
424.884	19441.8
428.421	19418.3
431.955	19341.8
435.49	19358.8
439.023	19310.2
442.555	19253.6
446.084	19287.9
449.613	19192.2
453.141	19172.1
456.666	19152.3
460.191	19129
463.715	19083.9
467.235	19023
470.756	19054.8
474.274	19036.1
477.793	19039.9
481.308	18980.6
484.823	18971.9
488.336	18982
491.847	18952.3
495.358	18941.1
498.867	18915.1
502.374	19011.1
505.881	19006.7
509.386	19061.2
512.888	19053.9
516.39	18984.2
519.89	18959.5
523.391	18825.5
526.889	18815.2
530.385	18762.8
533.88	18688.4
537.373	18620.5
540.866	18552
544.357	18642.7
547.846	18555.8
551.334	18481.1
554.821	18523.8
558.307	18486.9
561.789	18480.4
565.272	18491.6
568.753	18483.8
572.233	18459.6
575.712	18524.3
579.188	18481.4
582.664	18531.9
586.139	18505.7
589.611	18607.8
593.083	18616.2
596.554	18622.3
600.021	18633.2
603.49	18673.3
606.955	18602
610.42	18459.4
613.882	18358.3
617.345	18343
620.805	18299.5
624.263	18241.4
627.722	18265.2
631.178	18151.8
634.633	18280
638.088	18257
641.539	18277.9
644.99	18189.8
648.439	18136.7
651.887	18059.4
655.335	18006.1
658.781	18051.1
662.225	17973.3
665.667	17947.1
669.108	17981.7
672.548	17945.4
675.987	17912.6
679.424	17901.9
682.86	17847.8
686.293	17962.9
689.727	17910
693.159	17902.8
696.59	17949.8
700.019	17929.1
703.448	17977.6
706.872	17980.8
710.298	17963
713.723	17979
717.144	17968.6
720.565	18067.7
723.984	18043.7
727.403	18026.2
730.821	17957
734.235	17946.6
737.651	17935
741.063	17918.6
744.474	17931.6
747.885	17878.8
751.293	17968.7
754.702	18024.7
758.108	18039
761.512	18014.9
764.915	18046.5
768.319	18016.6
771.719	17970.8
775.118	18032.9
778.516	18011.5
781.913	17941.7
785.308	18021
788.702	17980.8
792.095	17928
795.486	17971.1
798.876	18090.1
802.265	18094.9
805.653	18095.4
809.039	18232.6
812.424	18318.9
815.808	18309.4
819.191	18503.6
822.572	18678.7
825.95	18798.8
829.329	18921.7
832.706	19059.7
836.08	19159.2
839.455	19200.1
842.829	19367.5
846.199	19445.8
849.57	19464.2
852.938	19495.7
856.307	19580.1
859.672	19726.3
863.038	19789.5
866.401	19835.8
869.765	19760
873.125	19724.2
876.484	19708
879.844	19563.4
883.2	19594.3
886.555	19485.4
889.909	19293.1
893.262	19018.6
896.616	18806
899.966	18636.7
903.315	18565.6
906.663	18473.3
910.009	18498.4
913.354	18539.5
916.698	18551.3
920.041	18531.2
923.383	18394.9
926.723	18234.6
930.062	18122.2
933.399	18034.4
936.734	17996
940.069	18113.9
943.403	18198.5
946.736	18161.7
950.065	18106.2
953.396	18132.3
956.725	18193.5
960.051	18221.9
963.377	18174.6
966.7	18065.2
970.025	17950.8
973.345	17865.5
976.667	17870.3
979.985	17936.3
983.304	17943.7
986.62	18077.1
989.935	18238.2
993.25	18593.2
996.563	19140.9
999.874	19704.8
1003.19	19536.4
1006.49	19167
1009.8	18787.2
1013.11	18534.2
1016.41	18600.9
1019.72	18467.3
1023.02	18415.2
1026.32	18313.6
1029.62	18353.5
1032.92	18251.1
1036.22	18293.5
1039.51	18270
1042.81	18355.3
1046.1	18296.5
1049.39	18530.7
1052.68	18889.7
1055.97	19491.1
1059.26	19946.5
1062.55	19776.3
1065.83	19356.9
1069.12	19355.2
1072.4	19569.4
1075.68	19708.7
1078.97	19610.8
1082.24	19516.4
1085.52	19247.3
1088.8	18992.4
1092.08	18667.7
1095.35	18428.6
1098.62	18173.5
1101.9	18043
1105.17	17906.3
1108.44	18051.9
1111.7	18333
1114.97	18510.5
1118.23	18835.2
1121.5	19013.2
1124.76	18995.8
1128.03	18457.9
1131.29	17973.9
1134.54	17863.3
1137.8	18048.1
1141.06	18455.2
1144.31	19209.4
1147.57	20344.1
1150.82	21785.3
1154.07	22202.4
1157.32	20744.7
1160.57	19040.8
1163.82	18103.1
1167.07	17707.3
1170.31	17618.6
1173.56	17407.1
1176.8	17402
1180.04	17309.2
1183.28	17524
1186.52	17535.7
1189.76	17515.2
1192.99	17272.7
1196.23	17165.7
1199.46	16955.9
1202.7	16866.8
1205.93	16855.7
1209.16	16826.1
1212.39	16755.6
1215.62	16528.4
1218.84	16447
1222.07	16425.6
1225.29	16473.6
1228.52	16541.6
1231.74	16569.6
1234.96	16642.3
1238.18	16785.1
1241.4	16947.6
1244.61	17143.3
1247.83	17268.1
1251.04	17397.5
1254.25	17528.3
1257.47	17692
1260.68	17737.7
1263.89	17841.8
1267.09	17763.1
1270.3	17588.8
1273.51	17616.3
1276.71	17573.8
1279.91	17611.1
1283.12	17790
1286.32	18257.5
1289.52	19133.2
1292.72	20070.3
1295.91	20346.3
1299.11	20104.8
1302.3	19769.6
1305.5	19171.1
1308.69	18527.4
1311.88	17968.7
1315.07	17449.3
1318.26	17121.3
1321.44	16845.9
1324.63	16560.2
1327.82	16413.9
1331	16266.6
1334.18	16214.1
1337.36	16134.8
1340.54	16168.1
1343.72	16056.7
1346.9	15959
1350.07	16005.2
1353.25	15929.1
1356.42	15811.1
1359.6	15835.9
1362.77	15835.2
1365.94	15893.5
1369.11	15701.5
1372.28	15579.3
1375.44	15409.6
1378.61	15310.9
1381.77	15278.3
1384.93	15194.4
1388.1	15298.3
1391.26	15273.4
1394.41	15296.7
1397.57	15325.2
1400.73	15369.2
1403.89	15432
1407.04	15589.9
1410.19	15947.6
1413.35	16270
1416.5	16603.2
1419.65	16871.4
1422.8	17299.7
1425.94	18407.2
1429.09	19987.5
1432.23	21643
1435.38	22624.2
1438.52	22368.5
1441.66	21884.8
1444.8	21247.8
1447.94	20895
1451.08	20539
1454.22	20239.3
1457.35	19628.7
1460.48	18824.4
1463.62	18104.8
1466.75	17331.4
1469.88	16647.3
1473.01	16083.2
1476.14	15660.9
1479.26	15388.6
1482.39	15301.6
1485.51	15162.5
1488.64	15176.6
1491.76	15269.6
1494.88	15423.6
1498	15549.1
1501.12	15871.2
1504.24	16341.4
1507.35	17072.8
1510.47	17951.4
1513.58	18900.2
1516.69	19515.8
1519.81	19623.6
1522.92	19024.3
1526.03	17896.9
1529.13	16680
1532.24	15626.4
1535.35	15003.8
1538.45	14600
1541.55	14462.5
1544.66	14296.1
1547.76	14184.1
1550.86	14156.9
1553.96	14084.1
1557.05	13961.3
1560.15	13892.1
1563.24	13917
1566.34	13966.9
1569.43	13959.1
1572.52	13960.7
1575.61	13925.6
1578.7	13931
1581.79	13971.4
1584.88	13884.5
1587.96	13949.8
1591.05	14002.6
1594.13	13989.9
1597.21	13939.9
1600.3	14002.8
1603.37	13997.6
1606.45	13981.9
1609.53	13952.9
1612.61	13929.1
1615.68	13907.1
1618.76	13937.1
1621.83	13923.6
1624.9	13960.3
1627.97	14046.4
1631.04	14195.6
1634.11	14305.6
1637.18	14470.1
1640.24	14776.6
1643.31	15389.1
1646.37	16237.2
1649.44	16980.1
1652.5	16794.4
1655.56	16114.1
1658.62	15285.3
1661.67	14811.5
1664.73	14514.1
1667.79	14378.7
1670.84	14004.9
1673.89	13773
1676.95	13589.5
1680	13464
1683.05	13379
1686.1	13281.8
1689.14	13181
1692.19	13120.6
1695.23	13045.7
1698.28	13037.4
1701.32	12955
1704.36	12860.4
1707.4	12905.9
1710.44	12845.8
1713.48	12830.9
1716.52	12816.2
1719.56	12899.5
1722.59	12982.7
1725.63	13181.1
1728.66	13274.3
1731.69	13470.1
1734.72	13791
1737.75	14044.4
1740.78	14076.5
1743.8	13993.5
1746.83	13787.8
1749.86	13584.6
1752.88	13269.9
1755.9	12914.5
1758.92	12721.8
1761.94	12571.9
1764.96	12465.7
1767.98	12407.2
1771	12345.2
1774.01	12311.1
1777.03	12287.6
1780.04	12293.2
1783.05	12242
1786.06	12248.6
1789.07	12239.7
1792.08	12229.1
1795.09	12218.8
1798.1	12168.2
1801.1	12154.6
1804.11	12082
1807.11	12101.3
1810.11	12111.7
1813.11	12093.8
1816.11	12036.9
1819.11	12015.5
1822.11	12044
1825.11	12006.1
1828.1	11991.4
1831.1	12006.4
1834.09	11985.3
1837.08	11892.9
1840.07	11999.8
1843.06	11900.9
1846.05	11923.1
1849.04	11962
1852.02	11894.5
1855.01	11882.2
1857.99	11854.5
1860.98	11857.8
1863.96	11826.8
1866.94	11780.1
1869.92	11773.9
1872.9	11828.6
1875.88	11817.5
1878.85	11783
1881.83	11800.5
1884.8	11776.3
1887.78	11711.9
1890.75	11714
1893.72	11716.8
1896.69	11672.6
1899.66	11591.4
1902.63	11628.4
1905.59	11536.3
1908.56	11506.2
1911.52	11507.5
1914.49	11419.8
1917.45	11421.2
1920.41	11315.7
1923.37	11307.9
1926.33	11279.8
1929.29	11223.9
1932.24	11207.5
1935.2	11174.8
1938.15	11096.8
1941.1	11077
1944.06	11055.7
1947.01	11031.6
1949.96	10943.1
1952.91	10918.2
1955.86	10823.3
1958.8	10799.5
1961.75	10784.3
1964.69	10762.1
1967.64	10753.4
1970.58	10688.8
1973.52	10657.6
1976.46	10643.6
1979.4	10599.5
1982.34	10567.2
1985.27	10564.3
1988.21	10499.9
1991.14	10484.5
1994.08	10392.7
1997.01	10377.2
1999.94	10330.6
2002.87	10319.1
2005.8	10299.7
2008.73	10268.7
2011.66	10252.4
2014.58	10212.7
2017.51	10165.4
2020.43	10118.5
2023.36	10107.9
2026.28	10086.6
2029.2	10051.4
2032.12	10022.6
2035.04	9994.05
2037.95	9976.54
2040.87	9934.26
2043.78	9937.02
2045.76	9862.54
2048.69	9865
2051.61	9830.25
2054.54	9815.35
2057.46	9811.39
2060.38	9796.08
2063.3	9775.69
2066.22	9788.33
2069.14	9776.18
2072.06	9747.2
2074.98	9717.81
2077.89	9695.02
2080.81	9648.51
2083.72	9665.52
2086.63	9682.39
2089.55	9612.28
2092.46	9562.77
2095.37	9599.1
2098.28	9589.72
2101.18	9562.81
2104.09	9597.41
2106.99	9550.69
2109.9	9540.37
2112.8	9522.81
2115.71	9454.28
2118.61	9428.34
2121.51	9488.46
2124.4	9458.48
2127.3	9437.52
2130.2	9377.61
2133.09	9403.77
2135.99	9354.26
2138.88	9378.13
2141.78	9369.34
2144.67	9355.04
2147.56	9324.15
2150.45	9336.79
2153.34	9328.64
2156.22	9315.83
2159.11	9315.65
2162	9313.08
2164.88	9237.28
2167.76	9233.17
2170.64	9208.4
2173.53	9209.66
2176.41	9188.75
2179.29	9187.19
2182.16	9154.65
2185.04	9133.82
2187.92	9109.16
2190.79	9052.7
2193.66	9027.2
2196.54	9081.91
2199.41	9030.44
2202.28	9009.34
2205.15	9050.06
2208.02	8938.93
2210.88	8902.45
2213.75	8898.74
2216.62	8851.9
2219.48	8814.79
2222.34	8786.52
2225.21	8776.85
2228.07	8757.91
2230.93	8677.67
2233.79	8779.11
2236.65	8674.6
2239.5	8653.04
2242.36	8656.65
2245.21	8624.04
2248.07	8584.88
2250.92	8604.58
2253.77	8563.22
2256.62	8511.99
2259.47	8488.18
2262.32	8462.09
2265.17	8392.71
2268.02	8413.62
2270.86	8403.14
2273.71	8337.02
2276.55	8340.96
2279.39	8274.72
2282.24	8306.02
2285.08	8243.45
2287.92	8185.14
2290.75	8212.09
2293.59	8243.08
2296.43	8182.97
2299.26	8180.3
2302.1	8164.07
2304.93	8122.37
2307.76	8114.99
2310.6	8091.17
2313.43	8046.64
2316.25	8022.9
2319.08	8000.18
2321.91	7996.89
2324.74	8087.85
2327.56	8253.76
2330.39	7948.18
2333.21	7830.06
2336.03	7807.58
2338.85	7820.61
2341.67	7811.14
2344.49	7794.72
2347.31	7772.25
2350.13	7687.29
2352.94	7703.1
2355.76	7678.82
2358.57	7615.82
2361.39	7634.15
2364.2	7564.78
2367.01	7558.89
2369.82	7552.39
2372.63	7512.8
2375.44	7489.33
2378.24	7470.08
2381.05	7484.83
2383.85	7419.21
2386.66	7430.51
2389.46	7426.83
2392.26	7381.02
2395.06	7336.6
2397.86	7318.12
2400.66	7312.4
2403.46	7332.02
2406.26	7279.82
2409.05	7262.58
2411.85	7261.88
2414.64	7209.49
2417.43	7237.23
2420.23	7182.72
2423.02	7173.93
2425.81	7122.22
2428.6	7183.54
2431.38	7130.13
2434.17	7105.4
2436.96	7103.52
2439.74	7051.03
2442.53	7050.06
2445.31	7035.82
2448.09	6982.44
2450.87	7006.34
2453.65	6957.19
2456.43	6977.91
2459.21	6933.38
2461.98	6904.34
2464.76	6929.92
2467.53	6907.3
2470.31	6856.93
2473.08	6859.04
2475.85	6838.81
2478.63	6800.57
2481.39	6820.38
2484.16	6774.72
2486.93	6798.52
2489.7	6741.05
2492.46	6738.15
2495.23	6735.15
2497.99	6710.67
2500.76	6684.29
2503.52	6696.76
2506.28	6663.97
2509.04	6640.96
2511.8	6630.41
2514.56	6659.09
2517.31	6614.93
2520.07	6592.58
2522.82	6611.55
2525.58	6570.01
2528.33	6579.33
2531.09	6561.69
2533.84	6510.38
2536.59	6488.46
2539.34	6490.05
2542.08	6481.67
2544.83	6451.35
2547.58	6417.16
2550.32	6418.05
2553.07	6417.12
2555.81	6330.97
2558.55	6412.83
2561.29	6372.71
2564.03	6345.47
2566.77	6314.21
2569.51	6327.96
2572.25	6305.91
2574.99	6309.18
2577.72	6308.85
2580.46	6290.73
2583.19	6291.52
2585.92	6325.53
2588.65	6272.27
2591.38	6327.56
2594.11	6301.62
2596.84	6273.05
2599.57	6271.49
2602.3	6244.2
2605.02	6243.56
2607.75	6249.8
2610.47	6221.65
2613.19	6219.14
2615.92	6186.52
2618.64	6182.83
2621.36	6179.35
2624.08	6161.8
2626.8	6140.18
2629.51	6159.49
2632.23	6141.77
2634.94	6143.48
2637.66	6152.38
2640.37	6134.62
2643.08	6154.65
2645.79	6151.04
2648.5	6214.93
2651.21	6132.84
2653.92	6181.01
2656.63	6145.55
2659.33	6181.6
2662.04	6172.72
2664.75	6184.13
2667.45	6198.62
2670.15	6178.43
2672.85	6155.8
2675.55	6166.95
2678.25	6144.38
2680.95	6159.56
2683.65	6143.09
2686.35	6130.08
2689.04	6104.87
2691.74	6118.99
2694.43	6074.3
2697.13	6062.71
2699.82	6075.17
2702.51	6110.02
2705.2	6199
2707.89	6226.62
2710.58	6226.44
2713.26	6228.58
2715.95	6291.77
2718.64	6258.46
2721.32	6306.66
2724	6271.98
2726.69	6278.33
2729.37	6230.78
2732.05	6180.84
2734.73	6055.86
2737.41	6012.09
2740.09	5951.63
2742.76	5857.63
2745.44	5848.3
2748.11	5782.24
2750.79	5789.1
2753.46	5718.14
2756.13	5727.88
2758.81	5687.18
2761.47	5673.83
2764.14	5635.16
2766.81	5642.63
2769.48	5620.65
2772.15	5611.72
2774.81	5598.11
2777.48	5605.56
2780.14	5564.27
2782.8	5589.24
2785.47	5595.31
2788.13	5572.48
2790.79	5586.1
2793.44	5593.72
2796.1	5574.62
2798.76	5620.66
2801.42	5601.77
2804.07	5669.78
2806.73	5599.39
2809.38	5661.37
2812.03	5694.06
2814.68	5730.63
2817.33	5807.96
2819.98	5911.42
2822.63	5971.18
2825.28	6124.76
2827.93	6360.25
2830.57	6572.42
2833.22	6986.71
2835.86	7718.32
2838.51	8780.15
2841.15	10376.3
2843.79	12272.5
2846.43	13817.9
2849.07	14428.4
2851.71	14149.7
2854.35	13587.8
2856.98	13010.7
2859.62	12595.5
2862.25	12223.7
2864.89	12104.7
2867.52	12306.9
2870.15	12687.8
2872.78	12994.2
2875.41	13315.4
2878.04	13723.3
2880.67	13879.6
2883.3	13844.2
2885.92	13767.8
2888.55	13778.1
2891.18	13753.6
2893.8	13717.2
2896.42	13649.1
2899.04	13688.7
2901.67	13539.9
2904.29	13453.4
2906.9	13426.5
2909.52	13340
2912.14	13254.2
2914.76	13225.4
2917.37	13095
2919.99	13125.4
2922.6	13107.7
2925.21	13138.7
2927.82	13095
2930.44	13129.2
2933.05	12944.2
2935.65	12630.2
2938.26	12070.1
2940.87	11258.9
2943.48	10468.5
2946.08	9869.13
2948.69	9427.98
2951.29	9180.45
2953.89	9022.81
2956.49	8884.8
2959.1	8720.98
2961.7	8469.5
2964.29	8171.28
2966.89	7865.15
2969.49	7538.53
2972.09	7304.14
2974.68	7079.95
2977.28	6876.73
2979.87	6728.68
2982.46	6602.5
2985.05	6436.77
2987.65	6352.53
2990.24	6272.86
2992.82	6224.54
2995.41	6204.51
2998	6219.75
3000.59	6214.5
3003.17	6180.37
3005.76	6120.33
3008.34	6072.68
3010.92	5931.15
3013.5	5870.3
3016.09	5721.3
3018.67	5627.64
3021.25	5568.75
3023.82	5510.05
3026.4	5495.87
3028.98	5423.46
3031.55	5452.31
3034.13	5412.55
3036.7	5360.71
3039.28	5384.4
3041.85	5394.31
3044.42	5395.62
3046.99	5406.79
3049.56	5405.88
3052.13	5424.08
3054.69	5383.91
3057.26	5441.54
3059.83	5501.55
3062.39	5480.87
3064.95	5467.74
3067.52	5502.11
3070.08	5487.51
3072.64	5518.92
3075.2	5508.82
3077.76	5488.99
3080.32	5502.02
3082.88	5489.85
3085.44	5544.81
3087.99	5566.81
3090.55	5573.06
3093.1	5601.53
3095.65	5604.18
3098.21	5652.29
3100.76	5657.82
3103.31	5711.8
3105.86	5731.17
3108.41	5765.75
3110.96	5817.79
3113.5	5849.02
3116.05	5866.04
3118.59	5917.64
3121.14	5951.7
3123.68	5982.11
3126.23	6065.02
3128.77	6040.89
3131.31	6082.77
3133.85	6186.97
3136.39	6194.91
3138.93	6225.42
3141.46	6314.72
3144	6366.12
3146.54	6345.32
3149.07	6438.19
3151.6	6468.01
3154.14	6526.75
3156.67	6585.78
3159.2	6630.46
3161.73	6638.12
3164.26	6734.39
3166.79	6697.24
3169.32	6714.42
3171.84	6696.89
3174.37	6733.4
3176.9	6713.68
3179.42	6734.08
3181.94	6745.62
3184.47	6779.33
3186.99	6785.85
3189.51	6760.16
3192.03	6776.85
3194.55	6756.13
3197.07	6715.44
3199.58	6750.2
3202.1	6761.43
3204.62	6766.93
3207.13	6752.32
3209.65	6732.29
3212.16	6709.95
3214.67	6703.56
3217.18	6664.14
3219.69	6652.5
3222.2	6661.99
3224.71	6657.77
3227.22	6647.41
3229.73	6625.42
3232.23	6584.64
3234.74	6567.14
3237.24	6574.63
3239.75	6506.58
3242.25	6524.04
3244.75	6487.66
3247.25	6461.21
3249.75	6451.47
3252.25	6426.29
3254.75	6391.08
3257.25	6380.93
3259.74	6350.27
3262.24	6319.38
3264.73	6284.88
3267.23	6283.83
3269.72	6277.98
3272.21	6275.96
3274.7	6236.3
3277.2	6196.34
3279.69	6171.95
3282.17	6176.33
3284.66	6159.3
3287.15	6147.72
3289.64	6114.36
3292.12	6095.93
3293.56	6065.94
3296.05	6103.07
3298.55	6047.19
3301.04	6045.57
3303.54	6036.16
3306.03	6021.79
3308.52	6028.28
3311.01	5998.38
3313.5	5985.86
3315.99	5989.61
3318.48	5975.61
3320.97	5974.32
3323.45	5964.36
3325.94	5939.73
3328.42	5962.41
3330.91	5917.64
3333.39	5926.73
3335.87	5934.02
3338.36	5883.22
3340.84	5862.78
3343.32	5871.36
3345.8	5892.72
3348.27	5877.9
3350.75	5846.45
3353.23	5864.43
3355.7	5878.84
3358.18	5882.18
3360.65	5862.07
3363.13	5830.59
3365.6	5828.62
3368.07	5830.02
3370.54	5837.17
3373.01	5840.35
3375.48	5847.26
3377.95	5824.38
3380.42	5778.84
3382.88	5795.82
3385.35	5786.52
3387.81	5760.77
3390.28	5740.4
3392.74	5773.24
3395.2	5745.46
3397.67	5734.82
3400.13	5679.64
3402.58	5683.14
3405.05	5699
3407.5	5684.71
3409.96	5674.29
3412.42	5649.46
3414.87	5658.34
3417.33	5628.24
3419.78	5615.5
3422.23	5582.29
3424.69	5580.31
3427.14	5549.16
3429.59	5527.25
3432.04	5482.61
3434.49	5461.79
3436.94	5467.96
3439.39	5420.62
3441.83	5375.83
3444.28	5370.67
3446.72	5320.17
3449.17	5328.06
3451.61	5286.04
3454.05	5272.51
3456.5	5223.24
3458.94	5217.61
3461.38	5172
3463.81	5164.03
3466.25	5120.04
3468.69	5028.05
3471.13	5015.71
3473.56	4980.97
3476	4981.23
3478.43	4943.16
3480.87	4903.42
3483.3	4815.6
3485.73	4812.84
3488.16	4774.26
3490.59	4718.13
3493.02	4715.44
3495.45	4646.71
3497.88	4607.62
3499.09	4596.08