File: src/Milk_AI/Nandani toned milk RT 532nm 50% 600g 50xL 10s 10times 400-3500cm-1 200hole.txt
#Acq. time (s)=	10
#Accumulations=	10
#Range (cm-¹)=	400...3500
#Windows=	3
#Auto scanning=	Off
#Autofocus=	Off
#AutoExposure=	Off
#Spike filter=	Multiple accum.
#Delay time (s)=	0
#Binning=	1
#Readout mode=	Signal
#DeNoise=	Off
#ICS correction=	On
#Dark correction=	Off
#Inst. Process=	Off
#Detector Gain=	Best Dynamic Range
#Detector ADC=	45 kHz
#Detector temperature (°C)=	-60.1
#Instrument=	LabRAM HR Evol
#Detector=	Syncerity OE
#Objective=	x50_VIS_LWD
#Grating=	600 (500nm)
#ND Filter=	50%
#Laser=	532nm_Edge
#Hole=	199.981
#Range=	Visible
#E-Cal_Neon=	0
#StageXY=	75x50mm Scan+
#StageZ=	Z motor
#X (µm)=	0
#Y (µm)=	0
#Z (µm)=	697.5
#Spectral res.(cm-¹)=	12.8
#Full time(mm:ss)=	5:19
#AC=	Calibrated 2025-06-30 10:26
#Project=
#Sample=
#Site=
#Title=	D_99
#Remark=
#Date=	30.06.2025 11:31 (India Standard Time)
#Acquired=	30.06.2025 11:31:53 (India Standard Time)
#AxisType[0]=Intens
#AxisUnit[0]=Cnt
#AxisType[1]=Spectr
#AxisUnit[1]=1/cm
400.17	20966
403.717	20842.1
407.263	20806.8
410.807	20809.9
414.35	20808.3
417.892	20824.5
421.432	20785
424.971	20790.5
428.509	20742.1
432.045	20754.7
435.58	20769.2
439.111	20699
442.643	20721.2
446.174	20656.6
449.701	20610.9
453.229	20603.6
456.756	20565.2
460.279	20482.7
463.803	20435.3
467.326	20444.5
470.845	20397.2
474.365	20423.6
477.882	20338.1
481.399	20320
484.913	20311
488.425	20318.4
491.938	20257.6
495.448	20223
498.956	20290.9
502.465	20291.7
505.971	20300
509.475	20282.5
512.981	20364.1
516.482	20344.9
519.983	20224.3
523.482	20205.2
526.979	20167.1
530.476	20143.2
533.971	20036.9
537.464	19988.1
540.956	19902.6
544.447	19905
547.937	19866.7
551.425	19832.7
554.912	19861.4
558.398	19753.5
561.882	19770.8
565.365	19737.4
568.847	19721.2
572.325	19795.9
575.804	19795.8
579.282	19883.1
582.756	19828.6
586.231	19848.1
589.705	19862.4
593.175	19898.2
596.646	19846.5
600.116	19814.1
603.582	19929.7
607.049	19891.7
610.513	19850.1
613.977	19687.2
617.438	19649
620.898	19628.2
624.359	19481.7
627.816	19418
631.272	19415.1
634.728	19394.2
638.181	19400.3
641.633	19406.9
645.084	19309.1
648.535	19282.6
651.983	19173.5
655.43	19248.6
658.875	19182.1
662.319	19126.1
665.762	19120.7
669.203	19125.3
672.643	19109.5
676.082	19059.1
679.519	19028.3
682.955	19064.2
686.39	19016.8
689.824	19047.8
693.256	19085.5
696.685	19031
700.115	19057.1
703.543	19024
706.97	19038
710.394	19003.8
713.818	18986.9
717.241	19002.2
720.661	19095.8
724.082	18998.4
727.501	19028.7
730.917	18921.8
734.334	18970.4
737.747	18912
741.161	18796.4
744.572	18861.6
747.982	18824.3
751.392	18894.6
754.799	18856.7
758.205	18884.5
761.611	18864.4
765.014	18870.8
768.416	18881
771.816	18882.3
775.218	18926.9
778.616	18884.7
782.012	18928.6
785.408	18899.7
788.802	18875.2
792.195	18846.1
795.586	18833.8
798.977	18936.3
802.365	18939.8
805.753	19011.5
809.14	18971.1
812.525	18941.6
815.907	19037.5
819.289	19121.9
822.671	19151
826.051	19341.6
829.43	19362.2
832.805	19464.8
836.182	19470.4
839.557	19498.7
842.928	19640.3
846.301	19690.2
849.67	19711.9
853.04	19724.6
856.407	19742.8
859.774	19860.8
863.138	19951.8
866.503	19983.9
869.865	19948.4
873.225	19998.2
876.586	19979.3
879.944	19745.6
883.301	19703.6
886.658	19751.9
890.012	19740.6
893.365	19575.3
896.717	19347.5
900.067	19190.7
903.416	19093.2
906.766	18943.3
910.112	18907.1
913.458	18880.5
916.802	18848.7
920.145	18856.6
923.484	18816.3
926.825	18662.3
930.164	18567.6
933.501	18420
936.838	18369.8
940.173	18433.2
943.505	18439.6
946.838	18383.4
950.17	18414
953.5	18444.5
956.827	18382.5
960.155	18453.5
963.48	18415.5
966.805	18412.9
970.128	18335.6
973.45	18222.8
976.77	18144.2
980.091	18108.4
983.408	18120.6
986.726	18138.3
990.041	18251.6
993.354	18306.9
996.668	18653.2
999.979	19045.9
1003.29	19466.9
1006.6	19380.4
1009.91	19028.2
1013.21	18717.2
1016.52	18631.5
1019.82	18583.3
1023.12	18497.4
1026.43	18359.2
1029.73	18347.6
1033.02	18288.7
1036.32	18224
1039.62	18234.9
1042.91	18181.7
1046.21	18170.9
1049.5	18209.2
1052.79	18353
1056.08	18606.1
1059.37	19053
1062.65	19366.2
1065.94	19260
1069.23	18879.4
1072.51	19027.8
1075.79	19086.9
1079.07	19187.3
1082.35	19116.7
1085.63	19020
1088.91	18852
1092.18	18627.6
1095.46	18267
1098.73	18019.8
1102	17813.7
1105.27	17747
1108.54	17629.3
1111.81	17754.4
1115.08	17897.3
1118.34	18117.2
1121.61	18153.9
1124.87	18348.4
1128.13	18243.5
1131.39	17823.7
1134.65	17544.2
1137.91	17371.8
1141.17	17531.9
1144.42	17886.9
1147.68	18414.8
1150.93	19406.8
1154.18	20543.2
1157.43	20968.5
1160.68	19822.9
1163.93	18322.8
1167.18	17527.9
1170.42	17221.7
1173.67	17080.1
1176.91	17002.4
1180.15	16872.1
1183.39	16920.5
1186.63	16991
1189.87	17000
1193.11	17040.3
1196.34	16870.6
1199.58	16688.8
1202.81	16575.4
1206.04	16398.3
1209.27	16397.5
1212.5	16442
1215.73	16293.8
1218.95	16150.7
1222.18	16033
1225.4	16066.7
1228.63	16061.7
1231.85	16086.2
1235.07	16107.8
1238.29	16122.7
1241.51	16302.6
1244.72	16404.8
1247.94	16506.7
1251.15	16583.3
1254.37	16709.6
1257.58	16805.4
1260.79	16919.3
1264	16959.3
1267.21	17091.1
1270.41	16912.9
1273.62	16851
1276.82	16767.1
1280.03	16802.9
1283.23	16795.3
1286.43	16946.8
1289.63	17295.7
1292.83	18025.3
1296.03	18761.6
1299.22	19105.4
1302.42	19013.4
1305.61	18637.6
1308.8	18103.9
1311.99	17579.5
1315.18	17043.4
1318.37	16594.1
1321.56	16319.4
1324.74	16039.2
1327.93	15817.6
1331.11	15676.1
1334.3	15577.3
1337.48	15467.3
1340.66	15465.1
1343.84	15374.9
1347.01	15322.4
1350.19	15310.4
1353.37	15287.1
1356.54	15143.5
1359.71	15125.9
1362.88	15100.7
1366.05	15105.1
1369.22	15083.5
1372.39	15003.5
1375.56	14807.2
1378.72	14664.7
1381.89	14548.1
1385.05	14530.7
1388.21	14553
1391.37	14516.5
1394.53	14493.3
1397.69	14428.4
1400.85	14492.9
1404	14517.4
1407.16	14560.5
1410.31	14764.5
1413.46	14960.9
1416.61	15182.2
1419.76	15424.1
1422.91	15617.5
1426.06	15995
1429.21	16963.1
1432.35	18483.4
1435.49	19885.9
1438.64	20619.7
1441.78	20467.6
1444.92	19971.5
1448.06	19501.2
1451.2	19078.6
1454.33	18785.1
1457.47	18430.4
1460.6	17926.7
1463.74	17248.9
1466.87	16603.7
1470	15954.1
1473.13	15265.6
1476.26	14876.4
1479.38	14546.6
1482.51	14318.4
1485.63	14217.1
1488.76	14111
1491.88	14079.1
1495	14144.5
1498.12	14187.2
1501.24	14301.4
1504.36	14520.9
1507.47	14953.9
1510.59	15504.9
1513.7	16254.2
1516.81	16972.3
1519.93	17538.7
1523.04	17662.4
1526.15	17089.1
1529.25	16227.8
1532.36	15140.4
1535.47	14347.1
1538.57	13813.9
1541.67	13547.5
1544.78	13291
1547.88	13138.6
1550.98	13057
1554.08	12998.4
1557.18	13019.2
1560.27	12887.1
1563.37	12839.3
1566.46	12832.3
1569.55	12823.8
1572.64	12815.1
1575.74	12813.1
1578.83	12813.6
1581.91	12768.7
1585	12739.4
1588.09	12736.6
1591.17	12731.4
1594.25	12742.1
1597.34	12799.2
1600.42	12748.5
1603.5	12742.8
1606.58	12640
1609.65	12659.1
1612.73	12584.1
1615.8	12562.7
1618.88	12523.3
1621.95	12528.6
1625.03	12573.2
1628.1	12626.6
1631.17	12629.7
1634.23	12713.1
1637.3	12789
1640.37	12930.9
1643.43	13175.5
1646.5	13737
1649.56	14488.6
1652.62	15077.5
1655.68	14885.2
1658.74	14263.3
1661.8	13568
1664.85	13145.1
1667.91	13017.7
1670.96	12782.1
1674.02	12486.8
1677.07	12287.2
1680.12	12070.1
1683.17	12008.8
1686.22	11891.7
1689.27	11842.3
1692.31	11807.3
1695.36	11677.3
1698.4	11674.6
1701.45	11506
1704.49	11537.3
1707.53	11420.6
1710.57	11495.4
1713.61	11394.6
1716.65	11378.7
1719.68	11403.3
1722.72	11399.9
1725.75	11529.5
1728.78	11590.1
1731.82	11729.4
1734.84	11880.7
1737.87	12104
1740.9	12311.2
1743.93	12291.4
1746.96	12334.1
1749.98	12163
1753	11946.7
1756.03	11638.5
1759.05	11364.8
1762.07	11182.3
1765.09	11019.1
1768.11	10926.1
1771.12	10857.9
1774.14	10833.1
1777.15	10839.7
1780.17	10827.8
1783.18	10723
1786.19	10760.8
1789.2	10735.2
1792.21	10680.4
1795.22	10712.1
1798.22	10662.5
1801.23	10611.1
1804.23	10607.9
1807.24	10575.5
1810.24	10588.7
1813.24	10494.4
1816.24	10524.6
1819.24	10476.3
1822.24	10490.1
1825.23	10435.1
1828.23	10388.8
1831.22	10470.8
1834.22	10364.6
1837.21	10346.9
1840.2	10357.7
1843.19	10370.8
1846.18	10344.5
1849.17	10285
1852.15	10239.1
1855.14	10231.9
1858.12	10223.1
1861.11	10204.4
1864.09	10204.9
1867.07	10199.1
1870.05	10165.9
1873.03	10121.9
1876.01	10126.6
1878.98	10105.6
1881.96	10065.7
1884.93	10043
1887.91	10009.8
1890.88	9976.27
1893.85	9926.13
1896.82	9919.81
1899.79	9863.7
1902.76	9844.94
1905.72	9797.94
1908.69	9677.32
1911.65	9646.45
1914.62	9615.59
1917.58	9526.75
1920.54	9476.15
1923.5	9438.67
1926.46	9372.88
1929.42	9311.43
1932.37	9286.49
1935.33	9235.15
1938.28	9157.24
1941.24	9095.84
1944.19	9074.25
1947.14	8980.83
1950.09	8958.14
1953.04	8884.33
1955.99	8836.35
1958.93	8768.95
1961.88	8715.31
1964.82	8714.48
1967.77	8637.32
1970.71	8609.3
1973.65	8573.68
1976.59	8515.03
1979.53	8453.12
1982.47	8416.5
1985.41	8405.58
1988.34	8350.61
1991.28	8288.88
1994.21	8244.95
1997.14	8179.18
2000.07	8120.45
2003.01	8111.57
2005.94	8079.81
2008.86	8042.8
2011.79	8006.94
2014.72	7971.44
2017.64	7941.96
2020.57	7902
2023.49	7855.51
2026.41	7823.36
2029.33	7791.03
2032.25	7779.98
2035.17	7747.65
2038.09	7713.58
2041	7668.92
2043.92	7649.9
2045.86	7651.53
2048.79	7603.72
2051.71	7598.78
2054.64	7581
2057.56	7573.28
2060.48	7546.23
2063.4	7555.21
2066.32	7543.9
2069.24	7512.98
2072.16	7504.31
2075.08	7490.52
2077.99	7477.99
2080.91	7460.91
2083.82	7456.48
2086.74	7447.44
2089.65	7395.8
2092.56	7404.99
2095.47	7363.8
2098.38	7406
2101.29	7375.88
2104.19	7354.31
2107.1	7306.54
2110	7322.17
2112.91	7286.1
2115.81	7302.28
2118.71	7281.43
2121.61	7269.12
2124.51	7243.6
2127.4	7241.89
2130.3	7236.67
2133.2	7224.04
2136.09	7209.62
2138.99	7192.63
2141.88	7192.89
2144.77	7162.18
2147.66	7150.91
2150.55	7125.3
2153.44	7101.02
2156.33	7104.13
2159.21	7121.16
2162.1	7118.37
2164.98	7095.21
2167.87	7092.73
2170.75	7078.35
2173.63	7040.47
2176.51	7021.38
2179.39	7024.05
2182.27	7038.51
2185.14	7029.61
2188.02	6981.17
2190.9	6985.58
2193.77	6962.88
2196.64	6943.42
2199.51	6940.3
2202.39	6911.98
2205.25	6911.77
2208.12	6904.61
2210.99	6854.27
2213.86	6847.42
2216.72	6794.65
2219.59	6769.38
2222.45	6751.39
2225.31	6742.6
2228.17	6720.49
2231.03	6733.38
2233.89	6694.03
2236.75	6695.49
2239.61	6662.14
2242.46	6645.02
2245.32	6659.5
2248.17	6596.78
2251.03	6625.15
2253.88	6582.03
2256.73	6568.4
2259.58	6510.71
2262.43	6506.07
2265.28	6450.21
2268.12	6483.74
2270.97	6425.57
2273.81	6401.22
2276.66	6411.93
2279.5	6356.41
2282.34	6328.89
2285.18	6334.58
2288.02	6343.7
2290.86	6326.49
2293.7	6300.4
2296.54	6258.93
2299.37	6277.47
2302.21	6238.9
2305.04	6246.92
2307.87	6214.84
2310.7	6226.74
2313.53	6183.43
2316.36	6178.16
2319.19	6141.73
2322.02	6150.55
2324.85	6156.89
2327.67	6256.59
2330.5	6387.47
2333.32	6103.59
2336.14	6018.46
2338.96	5995.83
2341.78	5986.94
2344.6	5960.81
2347.42	5980.77
2350.24	5926.5
2353.05	5921.4
2355.87	5888.61
2358.68	5853.44
2361.5	5819.45
2364.31	5811.82
2367.12	5818.85
2369.93	5767.33
2372.74	5787.61
2375.55	5791.24
2378.35	5720.85
2381.16	5717.55
2383.96	5741.84
2386.77	5741.64
2389.57	5695.4
2392.37	5679.95
2395.17	5669.89
2397.97	5658.87
2400.77	5637.93
2403.57	5627.46
2406.37	5588.38
2409.16	5605.96
2411.96	5556.71
2414.75	5556.28
2417.55	5544.08
2420.34	5570.82
2423.13	5506.24
2425.92	5494.17
2428.71	5501.28
2431.5	5468.3
2434.28	5489.73
2437.07	5464.91
2439.85	5464.4
2442.64	5412.1
2445.42	5428.07
2448.2	5390.47
2450.98	5374.56
2453.76	5354.92
2456.54	5398.87
2459.32	5354.34
2462.1	5326.71
2464.87	5322.65
2467.65	5298.13
2470.42	5318.54
2473.2	5280
2475.97	5262.96
2478.74	5267.69
2481.51	5260.35
2484.28	5229.74
2487.05	5214.45
2489.81	5209.99
2492.58	5174.38
2495.34	5173.41
2498.11	5158.51
2500.87	5161.8
2503.63	5131.59
2506.39	5122.56
2509.15	5130.35
2511.91	5090.67
2514.67	5067.78
2517.43	5059.86
2520.19	5068.27
2522.94	5063.01
2525.7	5046.23
2528.45	5045.45
2531.2	5041.18
2533.95	5012.25
2536.7	5008.48
2539.45	5005.95
2542.2	4953.41
2544.95	4960.4
2547.69	4956.44
2550.44	4917.44
2553.18	4897.05
2555.93	4957.89
2558.67	4915.19
2561.41	4895.35
2564.15	4874.52
2566.89	4858.23
2569.63	4858.74
2572.36	4860.93
2575.1	4864.11
2577.84	4865.1
2580.57	4834.76
2583.31	4877.68
2586.04	4837.65
2588.77	4836.65
2591.5	4865.07
2594.23	4861.52
2596.96	4832.06
2599.69	4839.39
2602.41	4829.11
2605.14	4808.94
2607.86	4816.03
2610.59	4782.17
2613.31	4770.48
2616.03	4789.96
2618.75	4785.72
2621.48	4751.8
2624.19	4739.7
2626.91	4768.76
2629.63	4746.07
2632.35	4736.78
2635.06	4699.69
2637.77	4724.91
2640.49	4711.4
2643.2	4681
2645.91	4728.69
2648.62	4714.01
2651.33	4730.01
2654.04	4715.73
2656.75	4729.03
2659.45	4740.58
2662.16	4708.3
2664.86	4730.9
2667.57	4740.34
2670.27	4763.7
2672.97	4734.77
2675.67	4744.56
2678.37	4738.4
2681.07	4705.87
2683.77	4701.5
2686.47	4709.75
2689.16	4696.34
2691.86	4680.67
2694.55	4694.75
2697.25	4689.88
2699.94	4708.12
2702.63	4736.19
2705.32	4777.43
2708.01	4795.69
2710.7	4818.72
2713.39	4889.85
2716.07	4911.02
2718.76	4908.73
2721.44	4930.96
2724.12	4949.64
2726.81	4966.24
2729.49	4952.47
2732.17	4899.25
2734.85	4824.32
2737.53	4737.15
2740.21	4694.24
2742.88	4596.54
2745.56	4539.22
2748.24	4471.49
2750.91	4447.76
2753.58	4384.53
2756.25	4363.72
2758.93	4318.1
2761.6	4326.57
2764.27	4288.92
2766.93	4293.9
2769.6	4265.39
2772.27	4234.63
2774.93	4234.33
2777.6	4221.41
2780.26	4190.46
2782.93	4241.64
2785.59	4205.13
2788.25	4210.24
2790.91	4229.71
2793.57	4229.56
2796.23	4260.68
2798.88	4233.96
2801.54	4276.4
2804.2	4270.34
2806.85	4266.97
2809.5	4311.24
2812.16	4342.84
2814.81	4363.28
2817.46	4419
2820.11	4482.76
2822.76	4560.44
2825.4	4667.01
2828.05	4831.69
2830.7	5066.44
2833.34	5399.86
2835.99	5838.66
2838.63	6587.31
2841.27	7772.31
2843.91	9486.66
2846.55	11688.4
2849.19	13562
2851.83	14262.8
2854.47	14073.1
2857.11	13335.2
2859.74	12643.4
2862.38	12163.8
2865.01	11685.2
2867.65	11511.3
2870.28	11750.4
2872.91	12185.8
2875.54	12410.5
2878.17	12742.1
2880.8	13108.9
2883.42	13338.3
2886.05	13331.4
2888.68	13325.6
2891.3	13352.6
2893.93	13298.3
2896.55	13303.3
2899.17	13234.9
2901.79	13134.3
2904.41	13062.7
2907.03	12975.8
2909.65	12869.6
2912.27	12757.1
2914.88	12718.4
2917.5	12616.5
2920.11	12483.1
2922.73	12507.1
2925.34	12513.5
2927.95	12525.4
2930.56	12502.3
2933.17	12476
2935.78	12271.2
2938.39	11939.7
2941	11252.4
2943.6	10285
2946.21	9455.36
2948.81	8768.29
2951.42	8282.97
2954.02	8011.72
2956.62	7852.51
2959.22	7723.29
2961.82	7557.66
2964.42	7266.3
2967.02	6958.1
2969.62	6581.29
2972.21	6225.03
2974.81	5946.13
2977.4	5726.72
2980	5478.77
2982.59	5310.38
2985.18	5134.1
2987.77	4982.13
2990.36	4892.54
2992.95	4856.65
2995.54	4779.42
2998.13	4788.56
3000.72	4740.96
3003.3	4777.25
3005.89	4728.28
3008.47	4697.09
3011.05	4603.51
3013.63	4482.28
3016.22	4345.11
3018.8	4291.01
3021.38	4136.73
3023.95	4070.79
3026.53	3976.09
3029.11	3928.87
3031.68	3900.35
3034.26	3894.43
3036.83	3864.66
3039.4	3838.45
3041.98	3811.75
3044.55	3841.46
3047.12	3825.42
3049.69	3816.52
3052.26	3820.98
3054.82	3812.14
3057.39	3816.73
3059.96	3836.22
3062.52	3859.85
3065.09	3883.06
3067.65	3850.22
3070.21	3833.33
3072.77	3855.5
3075.33	3858.39
3077.89	3856.57
3080.45	3835.78
3083.01	3847.63
3085.57	3839.43
3088.12	3859.82
3090.68	3874.03
3093.23	3861.59
3095.79	3847.59
3098.34	3917.25
3100.89	3933.31
3103.44	3938.2
3105.99	3970.56
3108.54	4006.71
3111.09	4037.98
3113.63	4054.28
3116.18	4089.69
3118.73	4091.9
3121.27	4146.86
3123.82	4149.22
3126.36	4178.26
3128.9	4204.25
3131.44	4248.53
3133.98	4291.06
3136.52	4303.1
3139.06	4317.1
3141.6	4373.83
3144.13	4407.46
3146.67	4439.15
3149.2	4491.3
3151.74	4501.33
3154.27	4545.86
3156.8	4583.64
3159.34	4617.68
3161.86	4633.32
3164.4	4649.17
3166.92	4705.49
3169.45	4743.13
3171.98	4741.46
3174.5	4725.3
3177.03	4753.53
3179.56	4746.63
3182.08	4760.08
3184.6	4801.5
3187.12	4747.42
3189.64	4796.41
3192.16	4776.4
3194.68	4791.59
3197.2	4779.81
3199.72	4781.86
3202.24	4806.96
3204.75	4793.54
3207.27	4786.08
3209.78	4762.72
3212.29	4736.98
3214.81	4749
3217.32	4745.95
3219.83	4731.21
3222.34	4729.33
3224.85	4724.75
3227.35	4710.04
3229.86	4703.29
3232.37	4692.92
3234.87	4671.99
3237.38	4652.43
3239.88	4647
3242.38	4629.85
3244.89	4602.64
3247.39	4608.19
3249.89	4579.19
3252.39	4575.53
3254.88	4537.77
3257.38	4538.11
3259.88	4505.46
3262.37	4468.07
3264.87	4472.14
3267.36	4462.46
3269.86	4452.79
3272.35	4435.65
3274.84	4436.02
3277.33	4416.54
3279.82	4388
3282.31	4377.73
3284.8	4348.77
3287.29	4354.75
3289.77	4331.32
3292.26	4314.33
3294.15	4312.69
3296.64	4282.81
3299.14	4271.36
3301.63	4279.67
3304.12	4262.55
3306.62	4240
3309.11	4264.79
3311.6	4254.6
3314.09	4238.21
3316.58	4224.95
3319.07	4214.28
3321.56	4209.89
3324.04	4207.72
3326.53	4206.68
3329.01	4209.73
3331.5	4182.44
3333.98	4192.53
3336.46	4158.38
3338.94	4161.51
3341.42	4142.88
3343.9	4136.53
3346.38	4147.85
3348.86	4105.28
3351.34	4119.62
3353.82	4111.58
3356.29	4129.54
3358.77	4090.86
3361.24	4112.11
3363.71	4078.01
3366.19	4096.2
3368.66	4091.51
3371.13	4067.52
3373.6	4093.53
3376.07	4056.74
3378.54	4071.43
3381	4039.35
3383.47	4007.98
3385.94	4037.43
3388.4	3986.67
3390.87	4044.71
3393.33	4021.88
3395.79	4033.57
3398.25	4006.98
3400.71	3976.95
3403.17	3997.28
3405.63	3952.72
3408.09	3965.92
3410.55	3966.17
3413	3958.69
3415.46	3942.03
3417.92	3905.98
3420.37	3892.65
3422.82	3903.62
3425.27	3876.26
3427.73	3846.52
3430.18	3840.16
3432.63	3806.54
3435.08	3808.51
3437.53	3779.96
3439.97	3774.94
3442.42	3715.87
3444.86	3700.7
3447.31	3690.89
3449.75	3679.9
3452.2	3652.85
3454.64	3621.52
3457.08	3614.45
3459.52	3593.46
3461.96	3548.12
3464.4	3534.86
3466.84	3535.73
3469.28	3495.82
3471.72	3456.63
3474.15	3433.58
3476.59	3389.83
3479.02	3363.32
3481.45	3322.93
3483.89	3280.11
3486.32	3263.15
3488.75	3245.93
3491.18	3211.98
3493.61	3177.92
3496.04	3133.94
3498.47	3104.81
3499.68	3067.03