File: src/Milk_AI/Nandani full cream basic 532nm 50% 600g 50xL 10s 10times 400-3500cm-1 200hole.txt
#Acq. time (s)=	10
#Accumulations=	10
#Range (cm-¹)=	400...3500
#Windows=	3
#Auto scanning=	Off
#Autofocus=	Off
#AutoExposure=	Off
#Spike filter=	Multiple accum.
#Delay time (s)=	0
#Binning=	1
#Readout mode=	Signal
#DeNoise=	Off
#ICS correction=	On
#Dark correction=	Off
#Inst. Process=	Off
#Detector Gain=	Best Dynamic Range
#Detector ADC=	45 kHz
#Detector temperature (°C)=	-60.1
#Instrument=	LabRAM HR Evol
#Detector=	Syncerity OE
#Objective=	x50_VIS_LWD
#Grating=	600 (500nm)
#ND Filter=	50%
#Laser=	532nm_Edge
#Hole=	199.981
#Range=	Visible
#E-Cal_Neon=	0
#StageXY=	75x50mm Scan+
#StageZ=	Z motor
#X (µm)=	0
#Y (µm)=	0
#Z (µm)=	649.4
#Spectral res.(cm-¹)=	12.8
#Full time(mm:ss)=	5:19
#AC=	Calibrated 2025-07-01 10:31
#Project=
#Sample=
#Site=
#Title=	D_1
#Remark=
#Date=	01.07.2025 15:53 (India Standard Time)
#Acquired=	01.07.2025 15:53:02 (India Standard Time)
#AxisType[0]=Intens
#AxisUnit[0]=Cnt
#AxisType[1]=Spectr
#AxisUnit[1]=1/cm
400.083	19794.8
403.63	19563.4
407.176	19576.6
410.72	19554.3
414.263	19503.3
417.805	19462.2
421.345	19482.3
424.884	19446.1
428.421	19421.3
431.955	19296.5
435.49	19311.2
439.023	19266.4
442.555	19161.8
446.084	19147.8
449.613	19132.7
453.141	19147.3
456.666	19144.9
460.191	18989
463.715	18909.2
467.235	18904.2
470.756	18898.3
474.274	18858.9
477.793	18810.7
481.308	18749.4
484.823	18743.5
488.336	18801.1
491.847	18711.1
495.358	18718.2
498.867	18764.9
502.374	18783.6
505.881	18830.7
509.386	18898
512.888	18800.5
516.39	18810.1
519.89	18667.5
523.391	18597.4
526.889	18595.3
530.385	18502.3
533.88	18363
537.373	18282.1
540.866	18190.9
544.357	18149.9
547.846	18077.1
551.334	18096.4
554.821	18083.9
558.307	17953.1
561.789	17952.6
565.272	17974.8
568.753	17990.6
572.233	18088.5
575.712	18128.1
579.188	18192.7
582.664	18244.1
586.139	18386.8
589.611	18426.4
593.083	18502.2
596.554	18535.9
600.021	18614.1
603.49	18707.7
606.955	18544.4
610.42	18341.5
613.882	18168.6
617.345	18161.2
620.805	18042.6
624.263	17986.9
627.722	17984.1
631.178	17889.7
634.633	17938.3
638.088	17841
641.539	17956.1
644.99	17744.5
648.439	17728.1
651.887	17662.5
655.335	17712
658.781	17573.9
662.225	17570.4
665.667	17491
669.108	17523
672.548	17439.8
675.987	17429.7
679.424	17469.5
682.86	17464.9
686.293	17482.8
689.727	17438.4
693.159	17582.8
696.59	17635.7
700.019	17572.7
703.448	17623.6
706.872	17653.5
710.298	17718.3
713.723	17807.8
717.144	17939
720.565	18069.8
723.984	17941.1
727.403	17996.1
730.821	17914.3
734.235	17897.5
737.651	17943.1
741.063	17867.8
744.474	17860.7
747.885	17852.9
751.293	17963.5
754.702	17959.2
758.108	18019.5
761.512	18000
764.915	18053
768.319	17981
771.719	18063.2
775.118	18046
778.516	18005.1
781.913	18032.7
785.308	18084.1
788.702	18138.8
792.095	18213.2
795.486	18319.9
798.876	18454.8
802.265	18595
805.653	18652.3
809.039	18722.4
812.424	18903.5
815.808	19124.8
819.191	19443
822.572	19686.4
825.95	19976.2
829.329	20203.7
832.706	20455
836.08	20727.7
839.455	20870.1
842.829	21036.4
846.199	21124.7
849.57	21204
852.938	21302.8
856.307	21371.7
859.672	21800.8
863.038	21969.3
866.401	22061.5
869.765	22013.4
873.125	21902.3
876.484	21729.2
879.844	21468.4
883.2	21523.5
886.555	21728.4
889.909	21374.3
893.262	20808.3
896.616	20466.6
899.966	20114.8
903.315	19924.5
906.663	19796.7
910.009	19815.4
913.354	19837.6
916.698	19968.1
920.041	19839.6
923.383	19689.9
926.723	19395
930.062	19326.3
933.399	19108.3
936.734	19039.5
940.069	19132.3
943.403	19207.1
946.736	19303.4
950.065	19318.2
953.396	19346.2
956.725	19446.6
960.051	19416.2
963.377	19363.8
966.7	19321.2
970.025	19178.2
973.345	18926.1
976.667	18844.3
979.985	18790.3
983.304	18844.3
986.62	19121.9
989.935	19417.8
993.25	20054
996.563	21016.7
999.874	21931.6
1003.19	21776.4
1006.49	21240.3
1009.8	20603.6
1013.11	20357.1
1016.41	20283
1019.72	20150.7
1023.02	20066.5
1026.32	19894.8
1029.62	19891.7
1032.92	19767.4
1036.22	19847.3
1039.51	19836.2
1042.81	19903
1046.1	19989.2
1049.39	20327.1
1052.68	20893.1
1055.97	22114.9
1059.26	23057.2
1062.55	22897.7
1065.83	22056.5
1069.12	22113.9
1072.4	22522.4
1075.68	22759
1078.97	22600.3
1082.24	22356.8
1085.52	21981.3
1088.8	21454.7
1092.08	20809.4
1095.35	20329.6
1098.62	19877.5
1101.9	19599.4
1105.17	19419.1
1108.44	19538.6
1111.7	19976.5
1114.97	20374.1
1118.23	20896.3
1121.5	21259.3
1124.76	21209.5
1128.03	20406
1131.29	19411
1134.54	19297.3
1137.8	19688
1141.06	20416.8
1144.31	21846.7
1147.57	24187.5
1150.82	26926.7
1154.07	27840.2
1157.32	25211.7
1160.57	21841.4
1163.82	19911
1167.07	19345.2
1170.31	19156.3
1173.56	18769.7
1176.8	18650.9
1180.04	18715.1
1183.28	18967.5
1186.52	19098.9
1189.76	18991.5
1192.99	18682.7
1196.23	18337.5
1199.46	17948.4
1202.7	17690
1205.93	17600.1
1209.16	17646.9
1212.39	17540.6
1215.62	17151.9
1218.84	16929.3
1222.07	16919.6
1225.29	16908.6
1228.52	17027.3
1231.74	17111.4
1234.96	17306.4
1238.18	17557.3
1241.4	17800.6
1244.61	18136.5
1247.83	18441.9
1251.04	18736.8
1254.25	19014.2
1257.47	19227.2
1260.68	19607.8
1263.89	19723.9
1267.09	19702.9
1270.3	19480.7
1273.51	19356.9
1276.71	19479.9
1279.91	19673.1
1283.12	19941.5
1286.32	20750.5
1289.52	22423.2
1292.72	24530.3
1295.91	25323
1299.11	24968.8
1302.3	24277.3
1305.5	23012.7
1308.69	21762.4
1311.88	20621.6
1315.07	19527.1
1318.26	18828
1321.44	18091.5
1324.63	17664.9
1327.82	17209.7
1331	16908.1
1334.18	16734.7
1337.36	16807.4
1340.54	16608.5
1343.72	16533.2
1346.9	16469.8
1350.07	16402.2
1353.25	16340
1356.42	16169
1359.6	16262
1362.77	16296.1
1365.94	16281.9
1369.11	16113.6
1372.28	15841.1
1375.44	15549.2
1378.61	15458.1
1381.77	15295.7
1384.93	15259
1388.1	15311
1391.26	15286.8
1394.41	15316.4
1397.57	15491.9
1400.73	15520.9
1403.89	15736.6
1407.04	16062.9
1410.19	16687.8
1413.35	17289.2
1416.5	18028.4
1419.65	18566.3
1422.8	19418.5
1425.94	21623.1
1429.09	24998
1432.23	28451.6
1435.38	30421.2
1438.52	30240.3
1441.66	28869.4
1444.8	27706.2
1447.94	26870.2
1451.08	26177
1454.22	25425.4
1457.35	24298.5
1460.48	22804.8
1463.62	21290.4
1466.75	19724.9
1469.88	18429.4
1473.01	17342.6
1476.14	16675.3
1479.26	16213.6
1482.39	15875.9
1485.51	15797.9
1488.64	15736.1
1491.76	15917.3
1494.88	16159.1
1498	16485.1
1501.12	17087.4
1504.24	18041.6
1507.35	19402
1510.47	21190.5
1513.58	23001
1516.69	24251.4
1519.81	24437.1
1522.92	23447
1526.03	21221.5
1529.13	18851.1
1532.24	16789.3
1535.35	15536.4
1538.45	14866.3
1541.55	14421.9
1544.66	14134.2
1547.76	13859.6
1550.86	13717.4
1553.96	13683.2
1557.05	13520.7
1560.15	13498.3
1563.24	13474.3
1566.34	13466.4
1569.43	13479.8
1572.52	13487.8
1575.61	13426
1578.7	13409.8
1581.79	13419
1584.88	13398.3
1587.96	13456.5
1591.05	13475.4
1594.13	13439.4
1597.21	13359.9
1600.3	13348.2
1603.37	13374.9
1606.45	13281.1
1609.53	13271.1
1612.61	13190
1615.68	13170.9
1618.76	13157.6
1621.83	13247.5
1624.9	13321.1
1627.97	13525.8
1631.04	13699.8
1634.11	14009
1637.18	14290.7
1640.24	14870.1
1643.31	15962.1
1646.37	17810.9
1649.44	19390.9
1652.5	19280.2
1655.56	17824.4
1658.62	16145.3
1661.67	15147.3
1664.73	14786.6
1667.79	14239.7
1670.84	13714.7
1673.89	13241.9
1676.95	12834.8
1680	12676.4
1683.05	12530.1
1686.1	12342.3
1689.14	12257.3
1692.19	12238.5
1695.23	12164.9
1698.28	12099.4
1701.32	12021.4
1704.36	12043.8
1707.4	11916.9
1710.44	11999.6
1713.48	11957.7
1716.52	12028.4
1719.56	12099.2
1722.59	12379
1725.63	12707.6
1728.66	12961.4
1731.69	13416.3
1734.72	14135.9
1737.75	14693.7
1740.78	14754.1
1743.8	14661.8
1746.83	14372.9
1749.86	13862.8
1752.88	13270.6
1755.9	12601.4
1758.92	12139.6
1761.94	11816.1
1764.96	11567.1
1767.98	11489
1771	11434.2
1774.01	11348.9
1777.03	11328.4
1780.04	11298.6
1783.05	11248.1
1786.06	11192.1
1789.07	11211.8
1792.08	11141
1795.09	11156.1
1798.1	11102.7
1801.1	11125.4
1804.11	11078.9
1807.11	11014.6
1810.11	11046.9
1813.11	10985.9
1816.11	10988.3
1819.11	10959.5
1822.11	10884.7
1825.11	10910.2
1828.1	10927.5
1831.1	10828.7
1834.09	10857.3
1837.08	10837.7
1840.07	10854.8
1843.06	10800.4
1846.05	10837.6
1849.04	10815.9
1852.02	10752.8
1855.01	10759.3
1857.99	10756.3
1860.98	10710.3
1863.96	10709.8
1866.94	10678.5
1869.92	10703.8
1872.9	10692.1
1875.88	10634
1878.85	10647.4
1881.83	10612.3
1884.8	10623.3
1887.78	10541.6
1890.75	10566.6
1893.72	10532.3
1896.69	10501.5
1899.66	10484.2
1902.63	10352.4
1905.59	10321.1
1908.56	10320.1
1911.52	10241.4
1914.49	10170.5
1917.45	10110.9
1920.41	10041.3
1923.37	10045.2
1926.33	9958.83
1929.29	9934.47
1932.24	9908.73
1935.2	9827.05
1938.15	9779.73
1941.1	9697.74
1944.06	9710.64
1947.01	9642.31
1949.96	9612.2
1952.91	9506.73
1955.86	9465.2
1958.8	9388.21
1961.75	9380.41
1964.69	9309.89
1967.64	9265.59
1970.58	9232.79
1973.52	9204.1
1976.46	9161.75
1979.4	9144.43
1982.34	9067.01
1985.27	9034.73
1988.21	8987.3
1991.14	8917.69
1994.08	8880.13
1997.01	8843.33
1999.94	8793.86
2002.87	8733
2005.8	8703.47
2008.73	8669.99
2011.66	8643.66
2014.58	8599.11
2017.51	8568.25
2020.43	8511.08
2023.36	8465.68
2026.28	8427.63
2029.2	8400.78
2032.12	8362.1
2035.04	8330.75
2037.95	8287.6
2040.87	8246.41
2043.78	8229.52
2045.76	8205.7
2048.69	8175.06
2051.61	8155.09
2054.54	8146.84
2057.46	8105.57
2060.38	8119.82
2063.3	8099.63
2066.22	8062.98
2069.14	8073.7
2072.06	8046.58
2074.98	8003.19
2077.89	8009.53
2080.81	8024.6
2083.72	7963.52
2086.63	7962.64
2089.55	7923.95
2092.46	7932.93
2095.37	7894.58
2098.28	7907.21
2101.18	7872.19
2104.09	7902.9
2106.99	7830.67
2109.9	7848.39
2112.8	7816.02
2115.71	7804.8
2118.61	7818.5
2121.51	7790.14
2124.4	7791.12
2127.3	7753.62
2130.2	7740.41
2133.09	7733.22
2135.99	7729.22
2138.88	7735.56
2141.78	7673.7
2144.67	7734.78
2147.56	7678.68
2150.45	7689.13
2153.34	7662.45
2156.22	7651.38
2159.11	7652.07
2162	7635.47
2164.88	7623.26
2167.76	7617.64
2170.64	7592.86
2173.53	7599.13
2176.41	7575.48
2179.29	7533.56
2182.16	7537.5
2185.04	7518.34
2187.92	7461.93
2190.79	7476.39
2193.66	7427.24
2196.54	7401.05
2199.41	7388.84
2202.28	7368.79
2205.15	7359.4
2208.02	7362.64
2210.88	7310.61
2213.75	7304.2
2216.62	7267.18
2219.48	7190.01
2222.34	7208.51
2225.21	7215.87
2228.07	7171.95
2230.93	7140.72
2233.79	7131.09
2236.65	7119.73
2239.5	7086.34
2242.36	7032.65
2245.21	7041.25
2248.07	7019.69
2250.92	7003.51
2253.77	6989.6
2256.62	6971.61
2259.47	6946
2262.32	6935.36
2265.17	6913.87
2268.02	6849.47
2270.86	6843.35
2273.71	6810.35
2276.55	6791.54
2279.39	6786.38
2282.24	6778.86
2285.08	6744.08
2287.92	6738.39
2290.75	6718.34
2293.59	6710.44
2296.43	6702.04
2299.26	6673.98
2302.1	6695.45
2304.93	6640.05
2307.76	6584.55
2310.6	6651.92
2313.43	6587.91
2316.25	6521.54
2319.08	6535.58
2321.91	6554.53
2324.74	6634.34
2327.56	6747.7
2330.39	6480.28
2333.21	6406.59
2336.03	6363.3
2338.85	6380.62
2341.67	6332.23
2344.49	6336.19
2347.31	6324.5
2350.13	6278.88
2352.94	6229.51
2355.76	6215.52
2358.57	6205.53
2361.39	6168.18
2364.2	6128.55
2367.01	6144.09
2369.82	6134.97
2372.63	6088.61
2375.44	6050.44
2378.24	6075.81
2381.05	6034.21
2383.85	6051.45
2386.66	6001.76
2389.46	5984.99
2392.26	6019.48
2395.06	5953.69
2397.86	5954.26
2400.66	5924.83
2403.46	5907.15
2406.26	5909.94
2409.05	5894.61
2411.85	5866.63
2414.64	5859.62
2417.43	5833.5
2420.23	5813.65
2423.02	5815.5
2425.81	5778.11
2428.6	5766.47
2431.38	5772.63
2434.17	5735.4
2436.96	5727.84
2439.74	5722.67
2442.53	5713.63
2445.31	5671.19
2448.09	5651.47
2450.87	5596.25
2453.65	5612.64
2456.43	5609.91
2459.21	5592.77
2461.98	5573.43
2464.76	5553.55
2467.53	5545.23
2470.31	5511.7
2473.08	5505.54
2475.85	5504.4
2478.63	5454.96
2481.39	5477.31
2484.16	5454.31
2486.93	5435.13
2489.7	5419.18
2492.46	5423
2495.23	5436.85
2497.99	5409
2500.76	5395.67
2503.52	5348.6
2506.28	5329.46
2509.04	5324.76
2511.8	5338.5
2514.56	5320.67
2517.31	5312.16
2520.07	5304.31
2522.82	5304.75
2525.58	5272.25
2528.33	5280.53
2531.09	5271.04
2533.84	5232.4
2536.59	5223.15
2539.34	5199.16
2542.08	5186.71
2544.83	5176.49
2547.58	5142.9
2550.32	5115.76
2553.07	5123.58
2555.81	5096.98
2558.55	5116.16
2561.29	5091.5
2564.03	5073.89
2566.77	5075.66
2569.51	5012.93
2572.25	5057.7
2574.99	5038.22
2577.72	5016.05
2580.46	5051.65
2583.19	5053.53
2585.92	5041.19
2588.65	5059.88
2591.38	5032.5
2594.11	5056.49
2596.84	5059.5
2599.57	5027.65
2602.3	5009.93
2605.02	5059.71
2607.75	5017.38
2610.47	5003.55
2613.19	4991.31
2615.92	4958.05
2618.64	4959.75
2621.36	5000.45
2624.08	4984.97
2626.8	4959.85
2629.51	4948.65
2632.23	4953.04
2634.94	4967.11
2637.66	4926.33
2640.37	4914.1
2643.08	4961.91
2645.79	4977.51
2648.5	4968.88
2651.21	4978.38
2653.92	5000.88
2656.63	5026.67
2659.33	5024.89
2662.04	5065.68
2664.75	5021.13
2667.45	5037.53
2670.15	5022.33
2672.85	5033.67
2675.55	5019.37
2678.25	5012.7
2680.95	5015.49
2683.65	4994.89
2686.35	4946.03
2689.04	4976.08
2691.74	4968.37
2694.43	4947.43
2697.13	4946.25
2699.82	4989.71
2702.51	5043.24
2705.2	5107.4
2707.89	5150.79
2710.58	5171.36
2713.26	5256.79
2715.95	5265.56
2718.64	5337.9
2721.32	5334.32
2724	5312.67
2726.69	5299.7
2729.37	5275.65
2732.05	5175
2734.73	5085.98
2737.41	4928
2740.09	4849.22
2742.76	4779.38
2745.44	4723.04
2748.11	4608.61
2750.79	4573.22
2753.46	4567.67
2756.13	4478.69
2758.81	4491.8
2761.47	4448.99
2764.14	4400.43
2766.81	4413.83
2769.48	4434.18
2772.15	4429.59
2774.81	4396.52
2777.48	4407.28
2780.14	4376.04
2782.8	4411.07
2785.47	4388.62
2788.13	4393.91
2790.79	4408.97
2793.44	4448.37
2796.1	4459.61
2798.76	4475.17
2801.42	4507.65
2804.07	4477.11
2806.73	4536.5
2809.38	4545.65
2812.03	4611.28
2814.68	4720.66
2817.33	4781.66
2819.98	4902.14
2822.63	5076.99
2825.28	5267.93
2827.93	5595.44
2830.57	6031.8
2833.22	6596.89
2835.86	7614.78
2838.51	9202.21
2841.15	11564.1
2843.79	14415.9
2846.43	16938.9
2849.07	17869.6
2851.71	17480.1
2854.35	16530.3
2856.98	15753.9
2859.62	15021.7
2862.25	14378.1
2864.89	14234.7
2867.52	14445.5
2870.15	14992
2872.78	15371
2875.41	15821.6
2878.04	16419.9
2880.67	16705.1
2883.3	16659.2
2885.92	16566.9
2888.55	16571.7
2891.18	16468.4
2893.8	16467.9
2896.42	16447.8
2899.04	16393
2901.67	16163.3
2904.29	16081.5
2906.9	15964.7
2909.52	15770.4
2912.14	15635.4
2914.76	15546.9
2917.37	15340.3
2919.99	15396.4
2922.6	15376.4
2925.21	15380.8
2927.82	15391
2930.44	15279.6
2933.05	15056.8
2935.65	14631.1
2938.26	13756.1
2940.87	12611
2943.48	11371.3
2946.08	10480.8
2948.69	9895.19
2951.29	9537.61
2953.89	9289.31
2956.49	9143.81
2959.1	8895.45
2961.7	8547.05
2964.29	8153.43
2966.89	7714.97
2969.49	7267.6
2972.09	6848.09
2974.68	6546.96
2977.28	6252.59
2979.87	6029.19
2982.46	5801.23
2985.05	5620.2
2987.65	5539.21
2990.24	5416.13
2992.82	5407.95
2995.41	5387.31
2998	5409.16
3000.59	5418.55
3003.17	5420.56
3005.76	5337.47
3008.34	5283.46
3010.92	5115.47
3013.5	4954.35
3016.09	4779.98
3018.67	4674.94
3021.25	4560.76
3023.82	4464.17
3026.4	4433.48
3028.98	4343.95
3031.55	4321.5
3034.13	4257.08
3036.7	4261.45
3039.28	4252.46
3041.85	4253.01
3044.42	4210.94
3046.99	4255.79
3049.56	4201.91
3052.13	4275.74
3054.69	4272.51
3057.26	4269.34
3059.83	4299.55
3062.39	4290.94
3064.95	4274.91
3067.52	4302.13
3070.08	4311.99
3072.64	4287.53
3075.2	4293.22
3077.76	4313.17
3080.32	4324.65
3082.88	4279.71
3085.44	4345.74
3087.99	4333.94
3090.55	4351.9
3093.1	4375.85
3095.65	4377.71
3098.21	4420.85
3100.76	4454.42
3103.31	4438.35
3105.86	4501.37
3108.41	4540.87
3110.96	4552.49
3113.5	4606.34
3116.05	4609.56
3118.59	4653.92
3121.14	4686.55
3123.68	4712.54
3126.23	4758.31
3128.77	4801.47
3131.31	4856.92
3133.85	4870.26
3136.39	4914.51
3138.93	4975.2
3141.46	4975.4
3144	5048.57
3146.54	5097.84
3149.07	5140.79
3151.6	5181.68
3154.14	5211.69
3156.67	5269.2
3159.2	5315.77
3161.73	5366.92
3164.26	5372.32
3166.79	5408.1
3169.32	5424.87
3171.84	5431
3174.37	5465.49
3176.9	5466.86
3179.42	5504.3
3181.94	5524.43
3184.47	5552.02
3186.99	5542.17
3189.51	5600.36
3192.03	5579.66
3194.55	5609.54
3197.07	5591.3
3199.58	5624.79
3202.1	5667.46
3204.62	5665.51
3207.13	5655.17
3209.65	5649.84
3212.16	5650.79
3214.67	5667.96
3217.18	5630.51
3219.69	5647.49
3222.2	5642.25
3224.71	5653.86
3227.22	5642.31
3229.73	5623.9
3232.23	5646.61
3234.74	5655.4
3237.24	5639.58
3239.75	5599.34
3242.25	5611.25
3244.75	5599.33
3247.25	5580.69
3249.75	5573.04
3252.25	5555.4
3254.75	5546.2
3257.25	5515.45
3259.74	5481.13
3262.24	5491.3
3264.73	5460.02
3267.23	5471.49
3269.72	5448.83
3272.21	5436.64
3274.7	5436.69
3277.2	5415.89
3279.69	5397.94
3282.17	5402.37
3284.66	5416.31
3287.15	5397.23
3289.64	5391.11
3292.12	5358.66
3293.56	5328.24
3296.05	5346.73
3298.55	5332.31
3301.04	5329.87
3303.54	5301.16
3306.03	5327.21
3308.52	5325.44
3311.01	5302.7
3313.5	5306.54
3315.99	5286.06
3318.48	5280.1
3320.97	5294.15
3323.45	5291.37
3325.94	5268.07
3328.42	5300.8
3330.91	5307.87
3333.39	5275.37
3335.87	5299.93
3338.36	5229.89
3340.84	5256.65
3343.32	5271.05
3345.8	5254.65
3348.27	5274.46
3350.75	5249.53
3353.23	5236.23
3355.7	5267.95
3358.18	5272.35
3360.65	5235.8
3363.13	5281.01
3365.6	5247.77
3368.07	5217.87
3370.54	5268.99
3373.01	5258.68
3375.48	5252.91
3377.95	5251.84
3380.42	5223.97
3382.88	5219.08
3385.35	5253.58
3387.81	5205.05
3390.28	5236.56
3392.74	5238.56
3395.2	5253.14
3397.67	5198.98
3400.13	5218.83
3402.58	5198.64
3405.05	5221.46
3407.5	5193.77
3409.96	5200.49
3412.42	5154.13
3414.87	5182.71
3417.33	5173.04
3419.78	5138.65
3422.23	5138.84
3424.69	5110.65
3427.14	5133.62
3429.59	5082.77
3432.04	5070.39
3434.49	5044.79
3436.94	5045.47
3439.39	4997.18
3441.83	5004.81
3444.28	5011.64
3446.72	4946.55
3449.17	4967.67
3451.61	4950.66
3454.05	4922.87
3456.5	4908.39
3458.94	4850.34
3461.38	4818.81
3463.81	4818.95
3466.25	4781.95
3468.69	4738.82
3471.13	4735.56
3473.56	4659.35
3476	4657.07
3478.43	4612.97
3480.87	4575.28
3483.3	4532.04
3485.73	4512.44
3488.16	4528.73
3490.59	4441.65
3493.02	4427.89
3495.45	4409.31
3497.88	4384.01
3499.09	4368.69