File: src/Milk_AI/Nandani full cream Cold 532nm 50% 600g 50xL 10s 10times 400-3500cm-1 200hole.txt
#Acq. time (s)=	10
#Accumulations=	10
#Range (cm-¹)=	400...3500
#Windows=	3
#Auto scanning=	Off
#Autofocus=	Off
#AutoExposure=	Off
#Spike filter=	Multiple accum.
#Delay time (s)=	0
#Binning=	1
#Readout mode=	Signal
#DeNoise=	Off
#ICS correction=	On
#Dark correction=	Off
#Inst. Process=	Off
#Detector Gain=	Best Dynamic Range
#Detector ADC=	45 kHz
#Detector temperature (°C)=	-60.1
#Instrument=	LabRAM HR Evol
#Detector=	Syncerity OE
#Objective=	x50_VIS_LWD
#Grating=	600 (500nm)
#ND Filter=	50%
#Laser=	532nm_Edge
#Hole=	199.981
#Range=	Visible
#E-Cal_Neon=	0
#StageXY=	75x50mm Scan+
#StageZ=	Z motor
#X (µm)=	0
#Y (µm)=	0
#Z (µm)=	237
#Spectral res.(cm-¹)=	12.8
#Full time(mm:ss)=	5:19
#AC=	Calibrated 2025-07-01 10:31
#Project=
#Sample=
#Site=
#Title=	D_3
#Remark=
#Date=	01.07.2025 11:28 (India Standard Time)
#Acquired=	01.07.2025 11:28:05 (India Standard Time)
#AxisType[0]=Intens
#AxisUnit[0]=Cnt
#AxisType[1]=Spectr
#AxisUnit[1]=1/cm
400.083	20685.7
403.63	20455.8
407.176	20486
410.72	20509.9
414.263	20406
417.805	20449.7
421.345	20363.3
424.884	20421.4
428.421	20400.5
431.955	20407.8
435.49	20294.3
439.023	20281.4
442.555	20200.3
446.084	20198
449.613	20165
453.141	20120.7
456.666	20089.7
460.191	20085.3
463.715	20007.4
467.235	19880.3
470.756	19933.5
474.274	19899.7
477.793	19868.9
481.308	19795.6
484.823	19804.9
488.336	19772.8
491.847	19764.7
495.358	19737.7
498.867	19766.5
502.374	19828.5
505.881	19839.7
509.386	19778.3
512.888	19818.2
516.39	19855.1
519.89	19769.2
523.391	19689.9
526.889	19609.5
530.385	19532.1
533.88	19474.9
537.373	19360.7
540.866	19317.7
544.357	19325
547.846	19219.6
551.334	19147.1
554.821	19181.7
558.307	19126.3
561.789	19122.8
565.272	19114.8
568.753	19143.3
572.233	19185.5
575.712	19158.5
579.188	19260.8
582.664	19265.4
586.139	19389.5
589.611	19360.7
593.083	19398.6
596.554	19490.1
600.021	19543.2
603.49	19574.6
606.955	19640.4
610.42	19544.2
613.882	19279.9
617.345	19181.6
620.805	19166.4
624.263	19051.1
627.722	18941.8
631.178	18927.3
634.633	18906.1
638.088	18858.5
641.539	18991
644.99	18787.5
648.439	18818.7
651.887	18635.1
655.335	18645.1
658.781	18571.1
662.225	18642.8
665.667	18565.4
669.108	18552.3
672.548	18503.3
675.987	18514.5
679.424	18488.6
682.86	18566.7
686.293	18493.8
689.727	18571.5
693.159	18544.6
696.59	18605.6
700.019	18661.3
703.448	18647.2
706.872	18668.5
710.298	18638.5
713.723	18738.1
717.144	18770.6
720.565	18886.9
723.984	18836.8
727.403	18857.7
730.821	18792.4
734.235	18776.1
737.651	18742.2
741.063	18682.6
744.474	18654.2
747.885	18654.1
751.293	18676.4
754.702	18730.4
758.108	18784.7
761.512	18737.6
764.915	18799.8
768.319	18755.5
771.719	18772.6
775.118	18881.8
778.516	18764.1
781.913	18831.4
785.308	18841.6
788.702	18801.8
792.095	18843.7
795.486	18914.8
798.876	18999.3
802.265	19104.8
805.653	19121.4
809.039	19173.8
812.424	19299.2
815.808	19493.8
819.191	19682.5
822.572	19843
825.95	20074.5
829.329	20248.3
832.706	20446.4
836.08	20643.6
839.455	20756.4
842.829	20848.2
846.199	21027.5
849.57	21080.8
852.938	21032.9
856.307	21085.8
859.672	21326.6
863.038	21528.3
866.401	21698.7
869.765	21723.6
873.125	21721.4
876.484	21503.9
879.844	21282.7
883.2	21227.1
886.555	21386.6
889.909	21331.8
893.262	20998.2
896.616	20548.2
899.966	20325.6
903.315	20170.9
906.663	19964.9
910.009	19975.8
913.354	20020.1
916.698	20015.2
920.041	20020.4
923.383	19905
926.723	19662.3
930.062	19503.4
933.399	19355.4
936.734	19322.3
940.069	19318.4
943.403	19271.1
946.736	19327.6
950.065	19463
953.396	19380
956.725	19484.8
960.051	19532.6
963.377	19533.1
966.7	19426.1
970.025	19323.4
973.345	19157.3
976.667	19015.3
979.985	18986
983.304	19052.1
986.62	19117.5
989.935	19258.1
993.25	19560.6
996.563	20187.9
999.874	21040.6
1003.19	21557.4
1006.49	21244.9
1009.8	20727.9
1013.11	20281.1
1016.41	20100
1019.72	20017.5
1023.02	19881.9
1026.32	19824.2
1029.62	19722.6
1032.92	19711.6
1036.22	19697.3
1039.51	19661.4
1042.81	19708.3
1046.1	19743.2
1049.39	19877.6
1052.68	20168.5
1055.97	20796.6
1059.26	21890
1062.55	22449.4
1065.83	21825.3
1069.12	21273.3
1072.4	21450.3
1075.68	21749.8
1078.97	21872
1082.24	21738.8
1085.52	21451.8
1088.8	21183.1
1092.08	20771.6
1095.35	20302.2
1098.62	19807.8
1101.9	19583.8
1105.17	19282
1108.44	19257
1111.7	19458.9
1114.97	19762
1118.23	20155.6
1121.5	20614.9
1124.76	20832.6
1128.03	20662.9
1131.29	19697.1
1134.54	19084.6
1137.8	19007.9
1141.06	19424.6
1144.31	20153.7
1147.57	21424.1
1150.82	23314.1
1154.07	25342.2
1157.32	25147.3
1160.57	22673.3
1163.82	20299.9
1167.07	19211.2
1170.31	18896.5
1173.56	18789.9
1176.8	18556.8
1180.04	18384.6
1183.28	18495.5
1186.52	18652.8
1189.76	18720.8
1192.99	18653.3
1196.23	18360.5
1199.46	18041.3
1202.7	17774.6
1205.93	17622.8
1209.16	17591
1212.39	17616.6
1215.62	17388.4
1218.84	17132.6
1222.07	17016.2
1225.29	17107.6
1228.52	17094.8
1231.74	17158.2
1234.96	17291.7
1238.18	17454.3
1241.4	17727.6
1244.61	17942.7
1247.83	18127.8
1251.04	18340.7
1254.25	18706.5
1257.47	18761.9
1260.68	18984.6
1263.89	19124.4
1267.09	19263.3
1270.3	19071.7
1273.51	18866.4
1276.71	18912.5
1279.91	18956.9
1283.12	19085.6
1286.32	19438.7
1289.52	20388.4
1292.72	22103.8
1295.91	23500.9
1299.11	23723.4
1302.3	23381.9
1305.5	22396.1
1308.69	21371.4
1311.88	20390.2
1315.07	19450.4
1318.26	18734.2
1321.44	18100
1324.63	17666.3
1327.82	17302.9
1331	17051.6
1334.18	16805.8
1337.36	16798
1340.54	16724.1
1343.72	16607.6
1346.9	16529
1350.07	16514.3
1353.25	16531.3
1356.42	16286.9
1359.6	16230.1
1362.77	16249.6
1365.94	16348.1
1369.11	16344.2
1372.28	16086.1
1375.44	15907.1
1378.61	15639.2
1381.77	15506.9
1384.93	15427
1388.1	15464.6
1391.26	15480.2
1394.41	15504.6
1397.57	15482.5
1400.73	15577.4
1403.89	15657.2
1407.04	15873.7
1410.19	16228
1413.35	16724.6
1416.5	17188.1
1419.65	17720
1422.8	18221.8
1425.94	19195.9
1429.09	21358
1432.23	24192.8
1435.38	26812.7
1438.52	27882.3
1441.66	27130.1
1444.8	26016.3
1447.94	25163.1
1451.08	24545.4
1454.22	24024.9
1457.35	23383.6
1460.48	22167.1
1463.62	20921.7
1466.75	19671.6
1469.88	18538.4
1473.01	17510.1
1476.14	16726.7
1479.26	16216.4
1482.39	15852
1485.51	15688.2
1488.64	15601.1
1491.76	15571.6
1494.88	15744.2
1498	15861.9
1501.12	16207.5
1504.24	16737
1507.35	17467.3
1510.47	18670.1
1513.58	20031.7
1516.69	21347.5
1519.81	22115.7
1522.92	22046
1526.03	20860.5
1529.13	19136.6
1532.24	17220.2
1535.35	15867.1
1538.45	15118.4
1541.55	14727.8
1544.66	14375.6
1547.76	14163.2
1550.86	13997
1553.96	13960.3
1557.05	13801.3
1560.15	13799.3
1563.24	13710.4
1566.34	13691.1
1569.43	13680.1
1572.52	13701.7
1575.61	13649
1578.7	13660.1
1581.79	13639.2
1584.88	13643
1587.96	13656.2
1591.05	13635.7
1594.13	13593.2
1597.21	13648.1
1600.3	13650.2
1603.37	13670.8
1606.45	13574.6
1609.53	13535.8
1612.61	13493.4
1615.68	13449.5
1618.76	13454.7
1621.83	13469.3
1624.9	13506
1627.97	13589.5
1631.04	13731
1634.11	13951
1637.18	14095.8
1640.24	14433.4
1643.31	14938.3
1646.37	16123.8
1649.44	17688.4
1652.5	18539.1
1655.56	18014.7
1658.62	16579.4
1661.67	15314.7
1664.73	14672.9
1667.79	14383.8
1670.84	14001.5
1673.89	13582.8
1676.95	13191.9
1680	12983.8
1683.05	12818
1686.1	12777.5
1689.14	12641
1692.19	12513.7
1695.23	12469.1
1698.28	12382.9
1701.32	12331.9
1704.36	12313.6
1707.4	12310.4
1710.44	12217.4
1713.48	12211.7
1716.52	12249.6
1719.56	12254.9
1722.59	12438.4
1725.63	12625
1728.66	12859.6
1731.69	13020.5
1734.72	13453.4
1737.75	13973.1
1740.78	14273.4
1743.8	14247.3
1746.83	14084.6
1749.86	13849.3
1752.88	13360.5
1755.9	12868.5
1758.92	12371.4
1761.94	12150.8
1764.96	11881.7
1767.98	11759.9
1771	11690.1
1774.01	11618.9
1777.03	11569
1780.04	11539.9
1783.05	11546.2
1786.06	11503.8
1789.07	11537
1792.08	11472.5
1795.09	11442.1
1798.1	11443.9
1801.1	11358.7
1804.11	11340.4
1807.11	11265.7
1810.11	11275.6
1813.11	11302.5
1816.11	11241.1
1819.11	11257.9
1822.11	11204.2
1825.11	11205.3
1828.1	11186.2
1831.1	11152.2
1834.09	11105
1837.08	11138.5
1840.07	11080.1
1843.06	11081.6
1846.05	11090
1849.04	11084
1852.02	11013.4
1855.01	11009.3
1857.99	10959.9
1860.98	10973
1863.96	10992.8
1866.94	10939.2
1869.92	10930.7
1872.9	10935
1875.88	10949.4
1878.85	10896.8
1881.83	10863
1884.8	10765.6
1887.78	10762.3
1890.75	10816.1
1893.72	10746.6
1896.69	10731.3
1899.66	10676.1
1902.63	10645.4
1905.59	10526.9
1908.56	10454.8
1911.52	10473.3
1914.49	10358.5
1917.45	10323.2
1920.41	10242.4
1923.37	10160
1926.33	10113.9
1929.29	10056.4
1932.24	9981.17
1935.2	9964.78
1938.15	9860.56
1941.1	9848.23
1944.06	9779.8
1947.01	9704.31
1949.96	9675.73
1952.91	9588.52
1955.86	9520.79
1958.8	9462.23
1961.75	9372.29
1964.69	9386.69
1967.64	9334.19
1970.58	9296.09
1973.52	9234.81
1976.46	9203.82
1979.4	9134.66
1982.34	9094.4
1985.27	9046.97
1988.21	8991.68
1991.14	8924.42
1994.08	8895.63
1997.01	8800.98
1999.94	8769.5
2002.87	8714.16
2005.8	8687.82
2008.73	8641.04
2011.66	8617.76
2014.58	8594.03
2017.51	8524.4
2020.43	8463.78
2023.36	8425.69
2026.28	8408.63
2029.2	8330.84
2032.12	8306.54
2035.04	8273.06
2037.95	8250.4
2040.87	8190.28
2043.78	8161.01
2045.76	8128.16
2048.69	8089.21
2051.61	8094.18
2054.54	8104.54
2057.46	8069.9
2060.38	8033.57
2063.3	8028.05
2066.22	8028.54
2069.14	8027.6
2072.06	7977.35
2074.98	7976.5
2077.89	7967.99
2080.81	7955.3
2083.72	7926.21
2086.63	7912.58
2089.55	7899.81
2092.46	7882.72
2095.37	7887.22
2098.28	7887.28
2101.18	7837.67
2104.09	7837.03
2106.99	7818.54
2109.9	7858.91
2112.8	7802.14
2115.71	7744.4
2118.61	7775.95
2121.51	7781.07
2124.4	7735.23
2127.3	7734.62
2130.2	7698.38
2133.09	7707.88
2135.99	7701.21
2138.88	7716.66
2141.78	7642.57
2144.67	7669.51
2147.56	7654.2
2150.45	7656.43
2153.34	7606.63
2156.22	7641.03
2159.11	7645.22
2162	7624.39
2164.88	7645.84
2167.76	7599.88
2170.64	7617.09
2173.53	7602.26
2176.41	7550.61
2179.29	7547.83
2182.16	7539.63
2185.04	7482.3
2187.92	7479.75
2190.79	7494.55
2193.66	7496.14
2196.54	7453.86
2199.41	7442
2202.28	7397.39
2205.15	7392.71
2208.02	7345.23
2210.88	7329.74
2213.75	7319.5
2216.62	7290.92
2219.48	7228.31
2222.34	7232.93
2225.21	7200.08
2228.07	7215.86
2230.93	7159.03
2233.79	7141
2236.65	7162.12
2239.5	7107.04
2242.36	7098.56
2245.21	7067.97
2248.07	7031.84
2250.92	7033.48
2253.77	7020.3
2256.62	6974.38
2259.47	6979.75
2262.32	6939.76
2265.17	6898.83
2268.02	6885.02
2270.86	6904.96
2273.71	6832.38
2276.55	6816.5
2279.39	6845.17
2282.24	6802.89
2285.08	6757.88
2287.92	6763.88
2290.75	6776.24
2293.59	6754.92
2296.43	6752.82
2299.26	6716.12
2302.1	6704.44
2304.93	6703.77
2307.76	6669.13
2310.6	6631.52
2313.43	6645.85
2316.25	6553.87
2319.08	6549.91
2321.91	6548.47
2324.74	6565.63
2327.56	6749.66
2330.39	6741.38
2333.21	6459.44
2336.03	6452.22
2338.85	6399.94
2341.67	6412.63
2344.49	6399.72
2347.31	6369
2350.13	6352.66
2352.94	6303.21
2355.76	6282.56
2358.57	6253.77
2361.39	6284.68
2364.2	6211.11
2367.01	6160.66
2369.82	6160.65
2372.63	6157.23
2375.44	6168.66
2378.24	6157.81
2381.05	6137.18
2383.85	6055.53
2386.66	6096.44
2389.46	6091.45
2392.26	6046.26
2395.06	6045.75
2397.86	6059.62
2400.66	5999.06
2403.46	6009.2
2406.26	5991.16
2409.05	5966.21
2411.85	5937.82
2414.64	5959.64
2417.43	5927.62
2420.23	5938.98
2423.02	5949.44
2425.81	5851.8
2428.6	5863.14
2431.38	5883.74
2434.17	5852.8
2436.96	5815
2439.74	5796.55
2442.53	5795.94
2445.31	5779.02
2448.09	5747.38
2450.87	5781.04
2453.65	5731.3
2456.43	5715.15
2459.21	5721.89
2461.98	5659.13
2464.76	5674.01
2467.53	5630.52
2470.31	5631.74
2473.08	5610.85
2475.85	5641.18
2478.63	5610.45
2481.39	5609.12
2484.16	5560.09
2486.93	5576.48
2489.7	5557.83
2492.46	5525.85
2495.23	5510.6
2497.99	5535.13
2500.76	5485.81
2503.52	5482.34
2506.28	5473.89
2509.04	5483.7
2511.8	5449.62
2514.56	5429.87
2517.31	5443.12
2520.07	5421.68
2522.82	5414.83
2525.58	5365.48
2528.33	5430.52
2531.09	5377.06
2533.84	5338.98
2536.59	5374.19
2539.34	5349.99
2542.08	5321.89
2544.83	5304.64
2547.58	5264.8
2550.32	5293.57
2553.07	5225.27
2555.81	5251.26
2558.55	5259.28
2561.29	5225.56
2564.03	5183.47
2566.77	5174.97
2569.51	5193.08
2572.25	5165.01
2574.99	5205.58
2577.72	5194.45
2580.46	5197.28
2583.19	5170.21
2585.92	5232.23
2588.65	5199.21
2591.38	5225.4
2594.11	5235.01
2596.84	5218.84
2599.57	5180.51
2602.3	5193.24
2605.02	5189.24
2607.75	5193.11
2610.47	5166.12
2613.19	5172.78
2615.92	5140.26
2618.64	5155.07
2621.36	5109.48
2624.08	5094.99
2626.8	5125.36
2629.51	5141.41
2632.23	5090.31
2634.94	5149.61
2637.66	5113.99
2640.37	5139.15
2643.08	5108.25
2645.79	5167.06
2648.5	5163.03
2651.21	5157.03
2653.92	5197.8
2656.63	5191.21
2659.33	5203.31
2662.04	5236.88
2664.75	5242.32
2667.45	5237.86
2670.15	5267.49
2672.85	5279.92
2675.55	5261.61
2678.25	5228.89
2680.95	5207.34
2683.65	5208.24
2686.35	5195.65
2689.04	5217.98
2691.74	5198.76
2694.43	5183.95
2697.13	5199.13
2699.82	5211.56
2702.51	5283.11
2705.2	5307.25
2707.89	5406.33
2710.58	5462
2713.26	5492.63
2715.95	5566.73
2718.64	5572.4
2721.32	5632.88
2724	5642.54
2726.69	5630.71
2729.37	5597.8
2732.05	5520.81
2734.73	5417.97
2737.41	5323.61
2740.09	5166.15
2742.76	5057.51
2745.44	4984.29
2748.11	4948.46
2750.79	4846.14
2753.46	4794.63
2756.13	4755.78
2758.81	4722.8
2761.47	4718.7
2764.14	4684.58
2766.81	4664.56
2769.48	4659.2
2772.15	4615.6
2774.81	4610.32
2777.48	4648.63
2780.14	4612.67
2782.8	4603.57
2785.47	4607.04
2788.13	4625.48
2790.79	4639.91
2793.44	4657.47
2796.1	4682.52
2798.76	4693.75
2801.42	4724.09
2804.07	4740.96
2806.73	4774.26
2809.38	4780.33
2812.03	4869.01
2814.68	4923.92
2817.33	5021.48
2819.98	5108.79
2822.63	5280.63
2825.28	5439.06
2827.93	5743.34
2830.57	6127.36
2833.22	6679.67
2835.86	7493.5
2838.51	8814.51
2841.15	10838.2
2843.79	13718.9
2846.43	16811.8
2849.07	18987.2
2851.71	19590.6
2854.35	18807
2856.98	17768.3
2859.62	16954.4
2862.25	16143.8
2864.89	15684.5
2867.52	15526.3
2870.15	16033.9
2872.78	16547.8
2875.41	16937.4
2878.04	17584.1
2880.67	18178
2883.3	18358.9
2885.92	18213.9
2888.55	18128.2
2891.18	18066.9
2893.8	17977.8
2896.42	17878.5
2899.04	17845.7
2901.67	17746.1
2904.29	17608.8
2906.9	17392
2909.52	17242.2
2912.14	17098.6
2914.76	16992.9
2917.37	16795.2
2919.99	16663
2922.6	16614.9
2925.21	16657.8
2927.82	16657.3
2930.44	16676.1
2933.05	16441.9
2935.65	16192.1
2938.26	15534.5
2940.87	14443.6
2943.48	13081.6
2946.08	11870
2948.69	10989.7
2951.29	10457.9
2953.89	10178.3
2956.49	9980.52
2959.1	9773.41
2961.7	9429.58
2964.29	8985.85
2966.89	8510.16
2969.49	8019.23
2972.09	7590.62
2974.68	7091.74
2977.28	6789.7
2979.87	6506.81
2982.46	6234.68
2985.05	6021.68
2987.65	5848.41
2990.24	5728.77
2992.82	5646.58
2995.41	5639.26
2998	5619.03
3000.59	5670.59
3003.17	5674.83
3005.76	5682.8
3008.34	5571.54
3010.92	5383.98
3013.5	5257.32
3016.09	5070.96
3018.67	4926.9
3021.25	4769.75
3023.82	4679.14
3026.4	4555.04
3028.98	4488.71
3031.55	4413.05
3034.13	4360.14
3036.7	4350.79
3039.28	4329.45
3041.85	4306.48
3044.42	4260.37
3046.99	4279.8
3049.56	4272.22
3052.13	4286.42
3054.69	4303.86
3057.26	4286.73
3059.83	4268.33
3062.39	4314.89
3064.95	4267.37
3067.52	4263.58
3070.08	4290.68
3072.64	4267.01
3075.2	4291.43
3077.76	4253.04
3080.32	4247.12
3082.88	4231.08
3085.44	4226.05
3087.99	4236.42
3090.55	4254.03
3093.1	4281.22
3095.65	4295.83
3098.21	4277.57
3100.76	4268.88
3103.31	4371.61
3105.86	4390.37
3108.41	4377.37
3110.96	4427.42
3113.5	4449.79
3116.05	4433.79
3118.59	4496.89
3121.14	4516.69
3123.68	4523.8
3126.23	4573.66
3128.77	4618.96
3131.31	4637.65
3133.85	4682.11
3136.39	4733.77
3138.93	4711.94
3141.46	4732.48
3144	4778.33
3146.54	4828.16
3149.07	4848.52
3151.6	4907.9
3154.14	4923.21
3156.67	4979.84
3159.2	5018.18
3161.73	5026.56
3164.26	5055.05
3166.79	5053.88
3169.32	5114.41
3171.84	5093.57
3174.37	5153.85
3176.9	5183.89
3179.42	5200.74
3181.94	5201.18
3184.47	5207.23
3186.99	5229.4
3189.51	5269.5
3192.03	5268.46
3194.55	5268.49
3197.07	5274.79
3199.58	5293.97
3202.1	5292.9
3204.62	5318.01
3207.13	5344.96
3209.65	5339.11
3212.16	5328.04
3214.67	5321.97
3217.18	5305.82
3219.69	5322.51
3222.2	5331.3
3224.71	5316.57
3227.22	5323.24
3229.73	5304.17
3232.23	5289.08
3234.74	5302.19
3237.24	5307.93
3239.75	5285.39
3242.25	5295.57
3244.75	5277.32
3247.25	5250.26
3249.75	5253.65
3252.25	5224.37
3254.75	5229.38
3257.25	5196.91
3259.74	5193.52
3262.24	5176.28
3264.73	5175.58
3267.23	5183.82
3269.72	5169.13
3272.21	5148.56
3274.7	5133.94
3277.2	5127.87
3279.69	5129.67
3282.17	5134.78
3284.66	5112.13
3287.15	5098.75
3289.64	5067.61
3292.12	5066.3
3293.56	5075.42
3296.05	5056.48
3298.55	5047.85
3301.04	5027.84
3303.54	5036.89
3306.03	5027.84
3308.52	5012.9
3311.01	5027.63
3313.5	4961.95
3315.99	5023.11
3318.48	4964.21
3320.97	5005.24
3323.45	4998.33
3325.94	4988.07
3328.42	4977.25
3330.91	4960.03
3333.39	4978.07
3335.87	4974.48
3338.36	4944.98
3340.84	4909.41
3343.32	4967.99
3345.8	4942.63
3348.27	4939
3350.75	4957.83
3353.23	4923.67
3355.7	4950.23
3358.18	4927.04
3360.65	4942.08
3363.13	4894.09
3365.6	4911.97
3368.07	4891.05
3370.54	4917.5
3373.01	4923.38
3375.48	4906.73
3377.95	4904.32
3380.42	4894.46
3382.88	4896.07
3385.35	4911.05
3387.81	4878.85
3390.28	4867.97
3392.74	4847.2
3395.2	4880.96
3397.67	4870.07
3400.13	4867.16
3402.58	4871.62
3405.05	4851.28
3407.5	4846.87
3409.96	4805.69
3412.42	4836.84
3414.87	4810.87
3417.33	4824.59
3419.78	4797.37
3422.23	4749.29
3424.69	4790.54
3427.14	4743.45
3429.59	4718.06
3432.04	4759.24
3434.49	4709.51
3436.94	4728.73
3439.39	4679.56
3441.83	4656.24
3444.28	4652.52
3446.72	4670.65
3449.17	4628.07
3451.61	4606.42
3454.05	4577.36
3456.5	4580.66
3458.94	4543.31
3461.38	4545.12
3463.81	4505.95
3466.25	4495.4
3468.69	4454.72
3471.13	4456.77
3473.56	4405.86
3476	4370.55
3478.43	4319.94
3480.87	4310.18
3483.3	4293.63
3485.73	4281.22
3488.16	4240.36
3490.59	4202.4
3493.02	4217.24
3495.45	4171.97
3497.88	4131.44
3499.09	4071.4