File: src/Milk_AI/Nandani toned milk RT after 24h 532nm 50% 600g 50xL 10s 10times 400-3500cm-1 200hole.txt
#Acq. time (s)=	10
#Accumulations=	10
#Range (cm-¹)=	400...3500
#Windows=	3
#Auto scanning=	Off
#Autofocus=	Off
#AutoExposure=	Off
#Spike filter=	Multiple accum.
#Delay time (s)=	0
#Binning=	1
#Readout mode=	Signal
#DeNoise=	Off
#ICS correction=	On
#Dark correction=	Off
#Inst. Process=	Off
#Detector Gain=	Best Dynamic Range
#Detector ADC=	45 kHz
#Detector temperature (°C)=	-60.1
#Instrument=	LabRAM HR Evol
#Detector=	Syncerity OE
#Objective=	x50_VIS_LWD
#Grating=	600 (500nm)
#ND Filter=	50%
#Laser=	532nm_Edge
#Hole=	199.981
#Range=	Visible
#E-Cal_Neon=	0
#StageXY=	75x50mm Scan+
#StageZ=	Z motor
#X (µm)=	0
#Y (µm)=	0
#Z (µm)=	693.1
#Spectral res.(cm-¹)=	12.8
#Full time(mm:ss)=	5:19
#AC=	Calibrated 2025-07-01 10:31
#Project=
#Sample=
#Site=
#Title=	D_1
#Remark=
#Date=	01.07.2025 17:02 (India Standard Time)
#Acquired=	01.07.2025 17:02:22 (India Standard Time)
#AxisType[0]=Intens
#AxisUnit[0]=Cnt
#AxisType[1]=Spectr
#AxisUnit[1]=1/cm
400.083	28687.2
403.63	28490.5
407.176	28564.8
410.72	28593.7
414.263	28620.3
417.805	28728.9
421.345	28606.8
424.884	28637.8
428.421	28707.3
431.955	28675.1
435.49	28784.7
439.023	28627.9
442.555	28639.2
446.084	28710
449.613	28608.9
453.141	28601.8
456.666	28699.8
460.191	28624.4
463.715	28614.5
467.235	28581.2
470.756	28664.4
474.274	28620.6
477.793	28668.8
481.308	28620.9
484.823	28668.8
488.336	28684.7
491.847	28686.8
495.358	28687.7
498.867	28745.4
502.374	28903.7
505.881	28975.9
509.386	28973.4
512.888	29002.5
516.39	29011.2
519.89	28885
523.391	28904.9
526.889	28891.4
530.385	28921.4
533.88	28867
537.373	28791.9
540.866	28784.6
544.357	28765.2
547.846	28768.2
551.334	28727.2
554.821	28806.2
558.307	28740.7
561.789	28877.7
565.272	28882.8
568.753	28927.3
572.233	28932.9
575.712	29030.9
579.188	29093.4
582.664	29088.2
586.139	29079.6
589.611	29246.4
593.083	29278.4
596.554	29271.6
600.021	29197
603.49	29470.8
606.955	29354.9
610.42	29226.2
613.882	29176.5
617.345	29192.8
620.805	29101.3
624.263	29023.1
627.722	29026.7
631.178	29003.7
634.633	29049.7
638.088	29129.1
641.539	29172
644.99	29057.2
648.439	28993.1
651.887	29041.5
655.335	29015
658.781	29120.4
662.225	29076.7
665.667	29177.5
669.108	29062.1
672.548	29129.2
675.987	29131.2
679.424	29135.1
682.86	29199.1
686.293	29212.9
689.727	29252.9
693.159	29305.6
696.59	29342.8
700.019	29405
703.448	29392.1
706.872	29361.9
710.298	29406.4
713.723	29334.7
717.144	29377.7
720.565	29563.4
723.984	29531.8
727.403	29477.4
730.821	29565.8
734.235	29520.6
737.651	29600.2
741.063	29533.3
744.474	29555.7
747.885	29602.6
751.293	29762.2
754.702	29723
758.108	29835.9
761.512	29834
764.915	29909.7
768.319	29955.8
771.719	29940.1
775.118	29995.5
778.516	30009.2
781.913	29980.5
785.308	29968.3
788.702	30012
792.095	30061.6
795.486	30105.8
798.876	30187.5
802.265	30246
805.653	30377.6
809.039	30257.4
812.424	30319.2
815.808	30469.6
819.191	30640.2
822.572	30854.4
825.95	30916.7
829.329	31055
832.706	31152.2
836.08	31315.4
839.455	31344.8
842.829	31514.2
846.199	31617.8
849.57	31679.1
852.938	31655.2
856.307	31688.7
859.672	32031
863.038	32085.8
866.401	32059
869.765	32068.3
873.125	32083.1
876.484	32065.1
879.844	31887.9
883.2	31981.2
886.555	31937.5
889.909	31903.8
893.262	31652.6
896.616	31450.3
899.966	31367.4
903.315	31262.2
906.663	31208
910.009	31344.6
913.354	31395.9
916.698	31381.9
920.041	31360.8
923.383	31301.9
926.723	31100.7
930.062	31041.7
933.399	30983.6
936.734	30966.3
940.069	31121.3
943.403	31027.7
946.736	31115.7
950.065	31068.6
953.396	31149
956.725	31137.7
960.051	31259
963.377	31222.7
966.7	31280.3
970.025	31170.5
973.345	31222.6
976.667	31122.6
979.985	31160.6
983.304	31208.1
986.62	31336.8
989.935	31521.3
993.25	31628.4
996.563	32068.9
999.874	32389.9
1003.19	32260.3
1006.49	32108
1009.8	31967.1
1013.11	31912.8
1016.41	31910.4
1019.72	31902.6
1023.02	31893.6
1026.32	31822.1
1029.62	31920.2
1032.92	31930
1036.22	31927.2
1039.51	31906.6
1042.81	31878.8
1046.1	31951.5
1049.39	32160.1
1052.68	32466.5
1055.97	33055.8
1059.26	33352.5
1062.55	33254.2
1065.83	33031.2
1069.12	33085.8
1072.4	33253.4
1075.68	33372.4
1078.97	33327
1082.24	33267.8
1085.52	33058.1
1088.8	32941.4
1092.08	32622.1
1095.35	32385.5
1098.62	32136.1
1101.9	32043.3
1105.17	31975
1108.44	32103.4
1111.7	32334.6
1114.97	32552.7
1118.23	32704.1
1121.5	32848.4
1124.76	32910.7
1128.03	32357.1
1131.29	31901.6
1134.54	31814.5
1137.8	31853.5
1141.06	32039.5
1144.31	32570.6
1147.57	33186.5
1150.82	34072.6
1154.07	34294.1
1157.32	33555
1160.57	32542.5
1163.82	32076.5
1167.07	31928.9
1170.31	31802.3
1173.56	31644.5
1176.8	31649.1
1180.04	31627.1
1183.28	31676.1
1186.52	31741.5
1189.76	31723.4
1192.99	31732.3
1196.23	31596.5
1199.46	31440.3
1202.7	31503.7
1205.93	31555.2
1209.16	31550.7
1212.39	31454.4
1215.62	31423
1218.84	31360.8
1222.07	31495.5
1225.29	31403.4
1228.52	31591.8
1231.74	31666.9
1234.96	31768.1
1238.18	31892.6
1241.4	32149.1
1244.61	32269.5
1247.83	32510.2
1251.04	32524
1254.25	32745.2
1257.47	32620.5
1260.68	32861
1263.89	32945.5
1267.09	32917.5
1270.3	32852.8
1273.51	32748.1
1276.71	32825.7
1279.91	32888.1
1283.12	33023.9
1286.32	33465.1
1289.52	34092.7
1292.72	34814
1295.91	35129.6
1299.11	35125.5
1302.3	34862.7
1305.5	34449.9
1308.69	33950.5
1311.88	33468.6
1315.07	33022.7
1318.26	32770.3
1321.44	32408.1
1324.63	32312.5
1327.82	32172.2
1331	32063.5
1334.18	32046.2
1337.36	32038.8
1340.54	32074.2
1343.72	31918.3
1346.9	31927.3
1350.07	31957.4
1353.25	31870.4
1356.42	31760.4
1359.6	31778.8
1362.77	31834.9
1365.94	31904.7
1369.11	31841.9
1372.28	31627.7
1375.44	31409.5
1378.61	31447.1
1381.77	31276.3
1384.93	31315.6
1388.1	31405.3
1391.26	31477
1394.41	31471.6
1397.57	31447.9
1400.73	31619.7
1403.89	31724.3
1407.04	31836.3
1410.19	32129.6
1413.35	32434.1
1416.5	32758
1419.65	32997.7
1422.8	33443.2
1425.94	34330.4
1429.09	35498.6
1432.23	36862.8
1435.38	37602.7
1438.52	37543.9
1441.66	37122.8
1444.8	36686.6
1447.94	36423.2
1451.08	36068.6
1454.22	35806
1457.35	35391.3
1460.48	34923.6
1463.62	34334.6
1466.75	33602.8
1469.88	33063.2
1473.01	32408.9
1476.14	32021.2
1479.26	31752.6
1482.39	31563.3
1485.51	31518.5
1488.64	31540.6
1491.76	31650.6
1494.88	31773.7
1498	31775.5
1501.12	31945.7
1504.24	32149.6
1507.35	32471.8
1510.47	33029.1
1513.58	33593.5
1516.69	33930.4
1519.81	33990.2
1522.92	33735.2
1526.03	33067
1529.13	32378.2
1532.24	31794.6
1535.35	31456.6
1538.45	31351
1541.55	31298.3
1544.66	31132.7
1547.76	31080.8
1550.86	31047.2
1553.96	31051.2
1557.05	30957.5
1560.15	31011.9
1563.24	31052.2
1566.34	31110.1
1569.43	31148.9
1572.52	31122
1575.61	30992.7
1578.7	31139.7
1581.79	31299.4
1584.88	31205.9
1587.96	31251
1591.05	31220.1
1594.13	31203.4
1597.21	31319.7
1600.3	31425.1
1603.37	31282.9
1606.45	31262.7
1609.53	31261.4
1612.61	31173.7
1615.68	31222.7
1618.76	31228.2
1621.83	31234.2
1624.9	31262.3
1627.97	31403.6
1631.04	31552.1
1634.11	31644.7
1637.18	31736.4
1640.24	32153
1643.31	32581.1
1646.37	33453.2
1649.44	34244.6
1652.5	34146
1655.56	33478
1658.62	32691.6
1661.67	32193.1
1664.73	32018.1
1667.79	31792.7
1670.84	31575.2
1673.89	31395.5
1676.95	31119.1
1680	31053.5
1683.05	30899.4
1686.1	30777.1
1689.14	30730.1
1692.19	30736.5
1695.23	30664
1698.28	30600.4
1701.32	30521.9
1704.36	30503.6
1707.4	30500.1
1710.44	30544.8
1713.48	30471
1716.52	30435.3
1719.56	30526.4
1722.59	30679.7
1725.63	30725.6
1728.66	30899.8
1731.69	31106.4
1734.72	31319.7
1737.75	31551
1740.78	31607.3
1743.8	31582.5
1746.83	31402.7
1749.86	31287.4
1752.88	30971.1
1755.9	30609.1
1758.92	30448.8
1761.94	30326.6
1764.96	30214.7
1767.98	30228.8
1771	30204.4
1774.01	30209.2
1777.03	30205.7
1780.04	30156.9
1783.05	30023.4
1786.06	30150.9
1789.07	30283.1
1792.08	30097.4
1795.09	30227.6
1798.1	30097.7
1801.1	30100.3
1804.11	30129.6
1807.11	30070.5
1810.11	30205.9
1813.11	30170.2
1816.11	30075.6
1819.11	30143.8
1822.11	30008.5
1825.11	30060.1
1828.1	30044.5
1831.1	30079.2
1834.09	30056.5
1837.08	30049.4
1840.07	29997.7
1843.06	30023.9
1846.05	30137.4
1849.04	30015
1852.02	29993.4
1855.01	29975
1857.99	30106.6
1860.98	29966.4
1863.96	29994.9
1866.94	30033.7
1869.92	29988.2
1872.9	29937.2
1875.88	30010.2
1878.85	29934.1
1881.83	29989.6
1884.8	29961.7
1887.78	29788.3
1890.75	29923.3
1893.72	29905.9
1896.69	29834.6
1899.66	29711.8
1902.63	29612
1905.59	29506.4
1908.56	29400.8
1911.52	29313.4
1914.49	29297.8
1917.45	29042.6
1920.41	29006.2
1923.37	28881.7
1926.33	28834.6
1929.29	28758.7
1932.24	28649.9
1935.2	28527.3
1938.15	28362.3
1941.1	28250.2
1944.06	28198.4
1947.01	28072.4
1949.96	27935
1952.91	27813.4
1955.86	27632.7
1958.8	27559.8
1961.75	27422.6
1964.69	27367
1967.64	27285.5
1970.58	27164
1973.52	27117.9
1976.46	27017.1
1979.4	26951
1982.34	26791
1985.27	26755.1
1988.21	26637.4
1991.14	26511.6
1994.08	26343.8
1997.01	26299.5
1999.94	26197.4
2002.87	26028.1
2005.8	25957.7
2008.73	25924
2011.66	25892.8
2014.58	25786.1
2017.51	25679.5
2020.43	25603.2
2023.36	25468.3
2026.28	25378.2
2029.2	25284.2
2032.12	25223.2
2035.04	25121.3
2037.95	25093.1
2040.87	24945.7
2043.78	24888.7
2045.76	24879
2048.69	24858
2051.61	24830.8
2054.54	24799.6
2057.46	24781
2060.38	24795.4
2063.3	24660.3
2066.22	24718.4
2069.14	24713.8
2072.06	24734.3
2074.98	24611.3
2077.89	24610.1
2080.81	24619.2
2083.72	24526
2086.63	24611.1
2089.55	24530.2
2092.46	24483.7
2095.37	24389.7
2098.28	24433.8
2101.18	24391.2
2104.09	24375.8
2106.99	24285.2
2109.9	24349.6
2112.8	24222.4
2115.71	24281
2118.61	24270.9
2121.51	24347.5
2124.4	24277.4
2127.3	24244.7
2130.2	24143.7
2133.09	24149.8
2135.99	24239.8
2138.88	24218.7
2141.78	24092.8
2144.67	24150.4
2147.56	24101.5
2150.45	24046
2153.34	24057
2156.22	24087.3
2159.11	24069.9
2162	24104.1
2164.88	24024.1
2167.76	23967.7
2170.64	23925.1
2173.53	24026.8
2176.41	24031.4
2179.29	23920.2
2182.16	23968.2
2185.04	23861.6
2187.92	23842.7
2190.79	23806.1
2193.66	23943
2196.54	23799.1
2199.41	23833.3
2202.28	23804.2
2205.15	23728.2
2208.02	23718
2210.88	23688.6
2213.75	23583.2
2216.62	23530.2
2219.48	23438.5
2222.34	23456.9
2225.21	23433.5
2228.07	23369.4
2230.93	23360
2233.79	23402.5
2236.65	23308.4
2239.5	23241.7
2242.36	23186.8
2245.21	23196.7
2248.07	23135
2250.92	23162.7
2253.77	23040.5
2256.62	23003.1
2259.47	22880.5
2262.32	22912.8
2265.17	22844
2268.02	22723
2270.86	22719.9
2273.71	22684.3
2276.55	22705.2
2279.39	22587.4
2282.24	22589.7
2285.08	22516.9
2287.92	22477.9
2290.75	22457.9
2293.59	22454.1
2296.43	22350
2299.26	22338.1
2302.1	22243.4
2304.93	22311.4
2307.76	22199.8
2310.6	22176.1
2313.43	22210.7
2316.25	22115.6
2319.08	22097
2321.91	22020.8
2324.74	22205.7
2327.56	22296.9
2330.39	21913.5
2333.21	21887.4
2336.03	21799.9
2338.85	21825.5
2341.67	21811.4
2344.49	21763.5
2347.31	21619.4
2350.13	21657
2352.94	21541.9
2355.76	21568.9
2358.57	21499.1
2361.39	21546.6
2364.2	21454.1
2367.01	21417.6
2369.82	21465.7
2372.63	21310.1
2375.44	21248.7
2378.24	21232.7
2381.05	21284.5
2383.85	21228.9
2386.66	21218.4
2389.46	21185.2
2392.26	21166.4
2395.06	21141.4
2397.86	21077.4
2400.66	21017.9
2403.46	21060
2406.26	20897.1
2409.05	20992.9
2411.85	21007
2414.64	20887.5
2417.43	20855.1
2420.23	20831.2
2423.02	20884.3
2425.81	20888.7
2428.6	20711
2431.38	20780.2
2434.17	20793.9
2436.96	20690
2439.74	20670
2442.53	20739.6
2445.31	20614.6
2448.09	20671.3
2450.87	20560.3
2453.65	20522.2
2456.43	20513.7
2459.21	20493.8
2461.98	20431.6
2464.76	20428.1
2467.53	20406.1
2470.31	20361.3
2473.08	20332
2475.85	20372.2
2478.63	20236.6
2481.39	20304.6
2484.16	20263.2
2486.93	20226.2
2489.7	20230.7
2492.46	20222.6
2495.23	20179.3
2497.99	20155.6
2500.76	20085.9
2503.52	20019.3
2506.28	20068.9
2509.04	19985.7
2511.8	20004.7
2514.56	19957.8
2517.31	19882.9
2520.07	19861
2522.82	19908.3
2525.58	19916.2
2528.33	19863.1
2531.09	19813.6
2533.84	19830.1
2536.59	19811.8
2539.34	19710.2
2542.08	19713.7
2544.83	19721.1
2547.58	19640.9
2550.32	19589
2553.07	19595.9
2555.81	19528.2
2558.55	19607.1
2561.29	19518
2564.03	19543.4
2566.77	19404.2
2569.51	19425.3
2572.25	19480.8
2574.99	19403.3
2577.72	19444.4
2580.46	19442
2583.19	19433.7
2585.92	19407.1
2588.65	19446.4
2591.38	19450.4
2594.11	19394.6
2596.84	19415.8
2599.57	19390.8
2602.3	19320.4
2605.02	19314.1
2607.75	19385.5
2610.47	19270.1
2613.19	19247.2
2615.92	19192.2
2618.64	19185.3
2621.36	19199.9
2624.08	19210.8
2626.8	19237.8
2629.51	19160.7
2632.23	19120.9
2634.94	19109.4
2637.66	19086.3
2640.37	19060.1
2643.08	19032.1
2645.79	19031.1
2648.5	19050.8
2651.21	19033.2
2653.92	18984
2656.63	18945.5
2659.33	18885.7
2662.04	18965.8
2664.75	18941.1
2667.45	18950.3
2670.15	18856.7
2672.85	18922.4
2675.55	18895.2
2678.25	18850.8
2680.95	18813.4
2683.65	18748
2686.35	18779.6
2689.04	18777.5
2691.74	18754.9
2694.43	18723.2
2697.13	18727.2
2699.82	18726
2702.51	18774
2705.2	18747
2707.89	18771.1
2710.58	18747.8
2713.26	18726.5
2715.95	18708.8
2718.64	18715.6
2721.32	18717.9
2724	18664.6
2726.69	18692.4
2729.37	18625.9
2732.05	18615.2
2734.73	18613.5
2737.41	18463
2740.09	18328.1
2742.76	18351.9
2745.44	18343.1
2748.11	18264.7
2750.79	18194
2753.46	18210.7
2756.13	18067.4
2758.81	18115
2761.47	18098.5
2764.14	18008.8
2766.81	18029
2769.48	17990.8
2772.15	17918.3
2774.81	17937.1
2777.48	18005.8
2780.14	17828.2
2782.8	17833.2
2785.47	17882.4
2788.13	17738
2790.79	17769.6
2793.44	17815.1
2796.1	17833.9
2798.76	17848.6
2801.42	17750.5
2804.07	17764.1
2806.73	17677.5
2809.38	17697.8
2812.03	17763.3
2814.68	17743.2
2817.33	17756.2
2819.98	17826.7
2822.63	17885.2
2825.28	17905.2
2827.93	18006.8
2830.57	18144.4
2833.22	18380.5
2835.86	18731.1
2838.51	19385.1
2841.15	20258.5
2843.79	21260.9
2846.43	21993
2849.07	22313.9
2851.71	22263.5
2854.35	21961.8
2856.98	21733
2859.62	21430.7
2862.25	21247.4
2864.89	21334.8
2867.52	21381.6
2870.15	21658.2
2872.78	21777.4
2875.41	22011.8
2878.04	22138.2
2880.67	22226.2
2883.3	22199.1
2885.92	22083
2888.55	22162.4
2891.18	22161.3
2893.8	22093.3
2896.42	22058.7
2899.04	22114.5
2901.67	22106.6
2904.29	21944.4
2906.9	21960.2
2909.52	21876.9
2912.14	21865.9
2914.76	21874.6
2917.37	21787.2
2919.99	21866.7
2922.6	21851.7
2925.21	21770.5
2927.82	21749.7
2930.44	21789
2933.05	21664.7
2935.65	21491.9
2938.26	21106.1
2940.87	20676.9
2943.48	20075.5
2946.08	19777.5
2948.69	19466.9
2951.29	19343.6
2953.89	19160.7
2956.49	19012.3
2959.1	18904.8
2961.7	18710.1
2964.29	18595.2
2966.89	18422.9
2969.49	18266.3
2972.09	18052.9
2974.68	17907.3
2977.28	17790.2
2979.87	17682.2
2982.46	17521.2
2985.05	17419.3
2987.65	17363.9
2990.24	17166
2992.82	17255.7
2995.41	17144.9
2998	17221.7
3000.59	17099.7
3003.17	17114.2
3005.76	17015.5
3008.34	16975.4
3010.92	16864.3
3013.5	16828
3016.09	16736.8
3018.67	16690.6
3021.25	16683.6
3023.82	16635.9
3026.4	16581.4
3028.98	16621.8
3031.55	16516.1
3034.13	16497.7
3036.7	16457.8
3039.28	16499.9
3041.85	16543.8
3044.42	16530.9
3046.99	16522
3049.56	16605
3052.13	16599.8
3054.69	16650.4
3057.26	16646.8
3059.83	16686.1
3062.39	16696.6
3064.95	16721.4
3067.52	16709.4
3070.08	16720.4
3072.64	16695.6
3075.2	16752.6
3077.76	16775.3
3080.32	16753.2
3082.88	16703.9
3085.44	16806.6
3087.99	16796.2
3090.55	16788.8
3093.1	16798.4
3095.65	16835.9
3098.21	16844.6
3100.76	16879.6
3103.31	16927.5
3105.86	17017.4
3108.41	17097.1
3110.96	17123.3
3113.5	17167.5
3116.05	17181.2
3118.59	17272.4
3121.14	17327
3123.68	17270.4
3126.23	17393.8
3128.77	17432.6
3131.31	17457
3133.85	17612
3136.39	17616.1
3138.93	17703.2
3141.46	17665.6
3144	17765.1
3146.54	17826.1
3149.07	17917.8
3151.6	17905.5
3154.14	18010.7
3156.67	18025.6
3159.2	18154.8
3161.73	18159.4
3164.26	18149.3
3166.79	18157.7
3169.32	18142.7
3171.84	18076.6
3174.37	17988.8
3176.9	18026
3179.42	17998.4
3181.94	17919.5
3184.47	17848.9
3186.99	17852.7
3189.51	17834.6
3192.03	17763.9
3194.55	17699.1
3197.07	17698.3
3199.58	17628.8
3202.1	17630.8
3204.62	17574.8
3207.13	17566.2
3209.65	17512.6
3212.16	17378.8
3214.67	17343.5
3217.18	17290.5
3219.69	17244.5
3222.2	17209.5
3224.71	17128.3
3227.22	17087.7
3229.73	17048.7
3232.23	17003.6
3234.74	16926.6
3237.24	16878.3
3239.75	16777.3
3242.25	16765.2
3244.75	16713.5
3247.25	16643
3249.75	16563.5
3252.25	16479.5
3254.75	16415
3257.25	16327.3
3259.74	16261.2
3262.24	16218.6
3264.73	16160
3267.23	16172.3
3269.72	16058.7
3272.21	16044.6
3274.7	15986.7
3277.2	15951
3279.69	15836.6
3282.17	15803.9
3284.66	15740.6
3287.15	15665.4
3289.64	15618.2
3292.12	15562.2
3293.56	15545.1
3296.05	15483.6
3298.55	15426.6
3301.04	15413.7
3303.54	15424.4
3306.03	15384.2
3308.52	15306.1
3311.01	15296.9
3313.5	15176.2
3315.99	15202
3318.48	15112.4
3320.97	15101.3
3323.45	15136.4
3325.94	15066.5
3328.42	15071.8
3330.91	15038.3
3333.39	15016.6
3335.87	14980.1
3338.36	14904.2
3340.84	14866.7
3343.32	14772.6
3345.8	14793.2
3348.27	14754
3350.75	14711.2
3353.23	14635.7
3355.7	14627.7
3358.18	14624
3360.65	14614.6
3363.13	14519.4
3365.6	14529.6
3368.07	14505.2
3370.54	14468.9
3373.01	14479.4
3375.48	14410.2
3377.95	14373.7
3380.42	14372.1
3382.88	14210.9
3385.35	14268.4
3387.81	14152.3
3390.28	14196.6
3392.74	14179.5
3395.2	14109
3397.67	14144.5
3400.13	14059.6
3402.58	14034
3405.05	14013.4
3407.5	13950.5
3409.96	13902.3
3412.42	13810.5
3414.87	13813.5
3417.33	13745.9
3419.78	13673.8
3422.23	13668.9
3424.69	13579.4
3427.14	13548
3429.59	13517.8
3432.04	13439.5
3434.49	13363.9
3436.94	13370.9
3439.39	13283.7
3441.83	13226.5
3444.28	13176.2
3446.72	13076.7
3449.17	13012
3451.61	12951.3
3454.05	12904
3456.5	12923.8
3458.94	12819.6
3461.38	12723.8
3463.81	12715.1
3466.25	12655.2
3468.69	12541.8
3471.13	12484.1
3473.56	12413.3
3476	12336.4
3478.43	12226.8
3480.87	12203.2
3483.3	12107.6
3485.73	12025.8
3488.16	11932.6
3490.59	11888
3493.02	11843.2
3495.45	11736
3497.88	11675
3499.09	11580.3