File: src/Milk_AI/Nandani full cream after heating 532nm 50% 600g 50xL 10s 10times 400-3500cm-1 200hole.txt
#Acq. time (s)=	8
#Accumulations=	15
#Range (cm-¹)=	400...3500
#Windows=	3
#Auto scanning=	Off
#Autofocus=	Off
#AutoExposure=	Off
#Spike filter=	Multiple accum.
#Delay time (s)=	0
#Binning=	1
#Readout mode=	Signal
#DeNoise=	Off
#ICS correction=	On
#Dark correction=	Off
#Inst. Process=	Off
#Detector Gain=	Best Dynamic Range
#Detector ADC=	45 kHz
#Detector temperature (°C)=	-60.1
#Instrument=	LabRAM HR Evol
#Detector=	Syncerity OE
#Objective=	x50_VIS_LWD
#Grating=	600 (500nm)
#ND Filter=	50%
#Laser=	532nm_Edge
#Hole=	199.981
#Range=	Visible
#E-Cal_Neon=	0
#StageXY=	75x50mm Scan+
#StageZ=	Z motor
#X (µm)=	0
#Y (µm)=	0
#Z (µm)=	1171.8
#Spectral res.(cm-¹)=	12.8
#Full time(mm:ss)=	6:23
#AC=	Calibrated 2025-06-30 10:26
#Project=
#Sample=
#Site=
#Title=	D_99
#Remark=
#Date=	30.06.2025 16:59 (India Standard Time)
#Acquired=	30.06.2025 16:59:15 (India Standard Time)
#AxisType[0]=Intens
#AxisUnit[0]=Cnt
#AxisType[1]=Spectr
#AxisUnit[1]=1/cm
400.17	16251.7
403.717	16208.7
407.263	16172.4
410.807	16152.7
414.35	16077.2
417.892	16106.4
421.432	16065.3
424.971	16097.2
428.509	16074.2
432.045	16064.4
435.58	16054.5
439.111	15975.5
442.643	15907.8
446.174	15892.3
449.701	15902.2
453.229	15890.2
456.756	15858.3
460.279	15828.7
463.803	15759.6
467.326	15761
470.845	15726.6
474.365	15644.7
477.882	15636.6
481.399	15618.2
484.913	15561.1
488.425	15655.4
491.938	15549.5
495.448	15602.8
498.956	15579.6
502.465	15592.3
505.971	15610
509.475	15638.6
512.981	15617.8
516.482	15686.8
519.983	15614.5
523.482	15574.1
526.979	15513.6
530.476	15462.3
533.971	15362.8
537.464	15359.9
540.956	15284.4
544.447	15242.1
547.937	15207.3
551.425	15149.1
554.912	15175.1
558.398	15102.6
561.882	15102.8
565.365	15098.8
568.847	15096.9
572.325	15066.6
575.804	15104.8
579.282	15182.6
582.756	15204.5
586.231	15235.6
589.705	15289.1
593.175	15261.1
596.646	15350.8
600.116	15334.1
603.582	15353.3
607.049	15364.7
610.513	15247.8
613.977	15195.5
617.438	15139.1
620.898	15037.1
624.359	15045.7
627.816	14930.1
631.272	14935.3
634.728	14862.8
638.181	14880.8
641.633	14936.9
645.084	14862.8
648.535	14768.5
651.983	14754.7
655.43	14719.2
658.875	14689
662.319	14701.7
665.762	14640.5
669.203	14624.6
672.643	14637.2
676.082	14537.2
679.519	14563.6
682.955	14603.8
686.39	14583.9
689.824	14544.3
693.256	14611.9
696.685	14647.9
700.115	14639.2
703.543	14610.2
706.97	14651.9
710.394	14663.5
713.818	14721
717.241	14716.8
720.661	14811.7
724.082	14824.5
727.501	14808.3
730.917	14791
734.334	14715.3
737.747	14748.1
741.161	14666
744.572	14614.7
747.982	14645.2
751.392	14706
754.799	14763.8
758.205	14725.4
761.611	14705.8
765.014	14779.5
768.416	14762.5
771.816	14843.6
775.218	14779.6
778.616	14761.1
782.012	14766.3
785.408	14790.5
788.802	14770.4
792.195	14837.8
795.586	14804.6
798.977	14926.6
802.365	14966.5
805.753	15080.7
809.14	15071.8
812.525	15161.4
815.907	15270.5
819.289	15389.5
822.671	15525.7
826.051	15715.6
829.43	15796.4
832.805	15971.7
836.182	16062.9
839.557	16138.9
842.928	16323.4
846.301	16447.1
849.67	16409.9
853.04	16479.3
856.407	16491.3
859.774	16584.3
863.138	16774.4
866.503	16836.6
869.865	16956.7
873.225	16900.7
876.586	16730.6
879.944	16572
883.301	16514.4
886.658	16537.4
890.012	16589
893.365	16468.1
896.717	16138
900.067	15980.3
903.416	15768.4
906.766	15608.7
910.112	15509
913.458	15514.5
916.802	15484.7
920.145	15442.4
923.484	15324.4
926.825	15191.7
930.164	15134.7
933.501	15055.2
936.838	15003.2
940.173	15051.8
943.505	14948.3
946.838	14992.3
950.17	15067.7
953.5	15050.7
956.827	15026.6
960.155	15087.3
963.48	15153
966.805	15039.9
970.128	15018
973.45	14876
976.77	14811.8
980.091	14757.5
983.408	14721.8
986.726	14772.5
990.041	14875.3
993.354	14997.4
996.668	15383.2
999.979	15935.9
1003.29	16488.5
1006.6	16450.2
1009.91	16045
1013.21	15710
1016.52	15558.4
1019.82	15467.7
1023.12	15439.2
1026.43	15295.2
1029.73	15302.6
1033.02	15225.3
1036.32	15171.9
1039.62	15201.7
1042.91	15214
1046.21	15209.7
1049.5	15212.2
1052.79	15348.2
1056.08	15616.8
1059.37	15991.3
1062.65	16462.3
1065.94	16567.4
1069.23	16381
1072.51	16495
1075.79	16677.3
1079.07	16869.3
1082.35	16829.1
1085.63	16638
1088.91	16357.6
1092.18	15970.9
1095.46	15566.5
1098.73	15123.9
1102	14872
1105.27	14564.7
1108.54	14574.8
1111.81	14706.7
1115.08	14903.1
1118.34	15223
1121.61	15392.5
1124.87	15401.2
1128.13	15098.8
1131.39	14671
1134.65	14412
1137.91	14405.5
1141.17	14578.5
1144.42	15078.7
1147.68	15822
1150.93	17041.1
1154.18	18598
1157.43	19179.7
1160.68	17836.3
1163.93	15894.8
1167.18	14785.1
1170.42	14329.1
1173.67	14213.8
1176.91	14011.8
1180.15	13865.2
1183.39	13969.9
1186.63	14066.6
1189.87	14194.8
1193.11	14135.1
1196.34	13956.9
1199.58	13769.7
1202.81	13535.3
1206.04	13398.9
1209.27	13402.7
1212.5	13386.7
1215.73	13234.6
1218.95	13126.2
1222.18	13023.9
1225.4	13023.8
1228.63	13002.8
1231.85	13073.8
1235.07	13126.3
1238.29	13158.7
1241.51	13327.3
1244.72	13468.7
1247.94	13599
1251.15	13749.5
1254.37	13946.8
1257.58	14081.7
1260.79	14233.6
1264	14394
1267.21	14472.1
1270.41	14478
1273.62	14332.1
1276.82	14254.5
1280.03	14306.7
1283.23	14431.6
1286.43	14514.4
1289.63	14904
1292.83	15604.1
1296.03	16616.4
1299.22	17498.4
1302.42	17731.3
1305.61	17368.5
1308.8	16620.6
1311.99	15840.3
1315.18	15053.8
1318.37	14448.5
1321.56	13942.4
1324.74	13575.7
1327.93	13303.6
1331.11	13007.6
1334.3	12762.3
1337.48	12694.2
1340.66	12656
1343.84	12541.3
1347.01	12540.8
1350.19	12504.4
1353.37	12431.1
1356.54	12315.3
1359.71	12289.1
1362.88	12298.6
1366.05	12299.4
1369.22	12270.9
1372.39	12115.3
1375.56	11946.6
1378.72	11816.1
1381.89	11695.5
1385.05	11647.5
1388.21	11636.5
1391.37	11632.9
1394.53	11604.6
1397.69	11572.1
1400.85	11651
1404	11692.2
1407.16	11749.6
1410.31	11875.8
1413.46	12096.6
1416.61	12552.9
1419.76	12825.3
1422.91	13148.8
1426.06	13734.7
1429.21	15076.4
1432.35	17207.8
1435.49	19248.8
1438.64	20351.4
1441.78	20230.5
1444.92	19545.9
1448.06	18903
1451.2	18364.1
1454.33	17919.4
1457.47	17421.4
1460.6	16714
1463.74	15723.3
1466.87	14806.7
1470	13884.3
1473.13	13126.2
1476.26	12501.8
1479.38	12070.6
1482.51	11819.8
1485.63	11636.3
1488.76	11548.7
1491.88	11511.4
1495	11569
1498.12	11651.4
1501.24	11842.5
1504.36	12131.7
1507.47	12623.1
1510.59	13398.7
1513.7	14318.9
1516.81	15328.1
1519.93	16062.9
1523.04	16232.6
1526.15	15722.2
1529.25	14456.8
1532.36	13125.6
1535.47	12016.2
1538.57	11305.9
1541.67	10915.6
1544.78	10669
1547.88	10452.7
1550.98	10355.2
1554.08	10264.8
1557.18	10239.9
1560.27	10146.1
1563.37	10123.2
1566.46	10067.3
1569.55	10084.7
1572.64	10079.5
1575.74	10031.7
1578.83	10025.1
1581.91	10061.3
1585	10012.6
1588.09	10018.3
1591.17	9992.15
1594.25	9961.6
1597.34	9997.36
1600.42	9993.87
1603.5	9991.4
1606.58	9963.82
1609.65	9957.72
1612.73	9833.06
1615.8	9831.57
1618.88	9810.08
1621.95	9802.7
1625.03	9849.8
1628.1	9890.2
1631.17	9974.9
1634.23	10080
1637.3	10234
1640.37	10417.8
1643.43	10658
1646.5	11335.5
1649.56	12368
1652.62	13298.2
1655.68	13237.7
1658.74	12390.9
1661.8	11435.3
1664.85	10843.4
1667.91	10545.7
1670.96	10308.5
1674.02	9997.87
1677.07	9706.06
1680.12	9506.49
1683.17	9358.28
1686.22	9261.29
1689.27	9206.19
1692.31	9133.88
1695.36	9062.72
1698.4	8966.77
1701.45	8928.3
1704.49	8938.37
1707.53	8874.61
1710.57	8847.68
1713.61	8824.66
1716.65	8819.15
1719.68	8837.38
1722.72	8855.2
1725.75	8927.37
1728.78	9000.13
1731.82	9261.85
1734.84	9500.52
1737.87	9807.27
1740.9	10079.5
1743.93	10256.4
1746.96	10343.6
1749.98	10224.4
1753	9918.32
1756.03	9514.78
1759.05	9135.04
1762.07	8816.91
1765.09	8588.17
1768.11	8466.6
1771.12	8432.69
1774.14	8342.05
1777.15	8340.98
1780.17	8282.01
1783.18	8261.69
1786.19	8247.49
1789.2	8250
1792.21	8162.66
1795.22	8159.57
1798.22	8119.63
1801.23	8144.4
1804.23	8100.21
1807.24	8103.54
1810.24	8089.17
1813.24	8067.21
1816.24	8032.25
1819.24	8009.31
1822.24	7993.83
1825.23	7969.46
1828.23	7954.72
1831.22	7919.03
1834.22	7908.44
1837.21	7885.94
1840.2	7897.12
1843.19	7911.78
1846.18	7874.97
1849.17	7864.99
1852.15	7827.55
1855.14	7818.62
1858.12	7791.6
1861.11	7757.96
1864.09	7790.14
1867.07	7760.37
1870.05	7722.66
1873.03	7688.85
1876.01	7712.88
1878.98	7663.67
1881.96	7717.41
1884.93	7627.7
1887.91	7631.05
1890.88	7589.84
1893.85	7575.68
1896.82	7529.36
1899.79	7516.18
1902.76	7484.16
1905.72	7371.08
1908.69	7347.55
1911.65	7291.11
1914.62	7228.47
1917.58	7155.52
1920.54	7089.89
1923.5	7065.69
1926.46	6997.67
1929.42	6957.68
1932.37	6905.73
1935.33	6847.44
1938.28	6805.62
1941.24	6752
1944.19	6689.74
1947.14	6664.21
1950.09	6606.64
1953.04	6524.67
1955.99	6488.26
1958.93	6420.56
1961.88	6372.06
1964.82	6337.4
1967.77	6291
1970.71	6227.25
1973.65	6196.4
1976.59	6176.01
1979.53	6130.68
1982.47	6083.57
1985.41	6043.41
1988.34	6001.75
1991.28	5944.61
1994.21	5886.98
1997.14	5859.54
2000.07	5821.45
2003.01	5772.24
2005.94	5734.11
2008.86	5720.29
2011.79	5691.11
2014.72	5647.9
2017.64	5618.76
2020.57	5572.3
2023.49	5539.23
2026.41	5501.02
2029.33	5462.43
2032.25	5434.93
2035.17	5409.83
2038.09	5372.92
2041	5366.93
2043.92	5321.36
2045.86	5303.93
2048.79	5306.33
2051.71	5275.13
2054.64	5273.45
2057.56	5257.31
2060.48	5244.53
2063.4	5248.15
2066.32	5234.02
2069.24	5221.38
2072.16	5214.33
2075.08	5198.78
2077.99	5197.24
2080.91	5221.64
2083.82	5193.97
2086.74	5159.06
2089.65	5147.63
2092.56	5144.48
2095.47	5139.45
2098.38	5134.33
2101.29	5126.36
2104.19	5123.74
2107.1	5091.25
2110	5098.47
2112.91	5068.07
2115.81	5067.75
2118.71	5069.33
2121.61	5023.02
2124.51	5025.65
2127.4	5041.82
2130.3	5035.61
2133.2	5014.93
2136.09	5017.94
2138.99	5009.02
2141.88	4977.26
2144.77	4978.12
2147.66	4995.73
2150.55	4976.67
2153.44	4960.46
2156.33	4970.97
2159.21	4931.11
2162.1	4966.6
2164.98	4970.48
2167.87	4931.89
2170.75	4938.23
2173.63	4930.08
2176.51	4906.28
2179.39	4902.89
2182.27	4895.35
2185.14	4882.11
2188.02	4896.23
2190.9	4863.12
2193.77	4857.29
2196.64	4819.54
2199.51	4820.18
2202.39	4819.69
2205.25	4811.04
2208.12	4806.27
2210.99	4778.33
2213.86	4779.73
2216.72	4746.07
2219.59	4725.6
2222.45	4716.68
2225.31	4698.83
2228.17	4685.89
2231.03	4676.59
2233.89	4693.68
2236.75	4677.23
2239.61	4634.75
2242.46	4630.62
2245.32	4634.25
2248.17	4613.95
2251.03	4603.24
2253.88	4587.39
2256.73	4561.67
2259.58	4550.1
2262.43	4545.82
2265.28	4501.81
2268.12	4481.04
2270.97	4475.86
2273.81	4474.76
2276.66	4481.22
2279.5	4475.9
2282.34	4438.2
2285.18	4423.31
2288.02	4403.15
2290.86	4395.53
2293.7	4382.15
2296.54	4394.34
2299.37	4369.83
2302.21	4367.5
2305.04	4358.98
2307.87	4340.72
2310.7	4341.98
2313.53	4290.48
2316.36	4281.81
2319.19	4294.31
2322.02	4275.33
2324.85	4295.99
2327.67	4389.54
2330.5	4465
2333.32	4251.8
2336.14	4189.82
2338.96	4217.4
2341.78	4160.38
2344.6	4176.05
2347.42	4144.28
2350.24	4147.02
2353.05	4115.46
2355.87	4124.45
2358.68	4093.07
2361.5	4088.47
2364.31	4063.7
2367.12	4050.07
2369.93	4030.06
2372.74	4033.74
2375.55	4025.26
2378.35	3999.35
2381.16	3986.31
2383.96	3976.53
2386.77	3993.27
2389.57	3970
2392.37	3972.64
2395.17	3940.94
2397.97	3953.44
2400.77	3940.45
2403.57	3926.54
2406.37	3907.3
2409.16	3898.73
2411.96	3885.19
2414.75	3887.54
2417.55	3885.48
2420.34	3874.09
2423.13	3849.95
2425.92	3848.91
2428.71	3841.22
2431.5	3819.24
2434.28	3829.71
2437.07	3812.93
2439.85	3809.81
2442.64	3794.81
2445.42	3773.64
2448.2	3775.86
2450.98	3758.18
2453.76	3755.84
2456.54	3767.05
2459.32	3755.65
2462.1	3734.53
2464.87	3729.34
2467.65	3708.52
2470.42	3671.83
2473.2	3678.79
2475.97	3659.87
2478.74	3649.82
2481.51	3645.65
2484.28	3645.84
2487.05	3648.42
2489.81	3636.87
2492.58	3622.18
2495.34	3615.36
2498.11	3615.2
2500.87	3609.85
2503.63	3589.86
2506.39	3573.61
2509.15	3564.22
2511.91	3573.51
2514.67	3546.67
2517.43	3541.8
2520.19	3532.51
2522.94	3527.46
2525.7	3550.62
2528.45	3551.71
2531.2	3529.47
2533.95	3512.64
2536.7	3506.59
2539.45	3495.67
2542.2	3473.61
2544.95	3439.93
2547.69	3461.69
2550.44	3431.13
2553.18	3426.07
2555.93	3412.23
2558.67	3423.34
2561.41	3409.46
2564.15	3407.26
2566.89	3387.06
2569.63	3387.01
2572.36	3400.81
2575.1	3402.38
2577.84	3372.26
2580.57	3373.57
2583.31	3389.56
2586.04	3364.45
2588.77	3374.02
2591.5	3380.95
2594.23	3385.23
2596.96	3361.35
2599.69	3390
2602.41	3362.48
2605.14	3361.06
2607.86	3340.59
2610.59	3332.11
2613.31	3341.8
2616.03	3326.82
2618.75	3334.07
2621.48	3322.02
2624.19	3293.98
2626.91	3295.97
2629.63	3301.17
2632.35	3312.27
2635.06	3300.58
2637.77	3287.41
2640.49	3274.08
2643.2	3294.18
2645.91	3317.17
2648.62	3280.96
2651.33	3290.3
2654.04	3282.91
2656.75	3292.83
2659.45	3293.34
2662.16	3290.61
2664.86	3321.18
2667.57	3297.02
2670.27	3316.48
2672.97	3300.39
2675.67	3299.42
2678.37	3288.71
2681.07	3284.82
2683.77	3267.21
2686.47	3268.28
2689.16	3270.93
2691.86	3268.88
2694.55	3260.19
2697.25	3242.84
2699.94	3281.84
2702.63	3279.12
2705.32	3301.41
2708.01	3310.7
2710.7	3350.66
2713.39	3374.09
2716.07	3390.86
2718.76	3390.92
2721.44	3398.29
2724.12	3410.24
2726.81	3422.02
2729.49	3427.09
2732.17	3399.74
2734.85	3351.24
2737.53	3278.6
2740.21	3237.04
2742.88	3190.89
2745.56	3131.01
2748.24	3100.03
2750.91	3060.42
2753.58	3055.51
2756.25	3024.07
2758.93	3010.11
2761.6	2977.23
2764.27	2980.93
2766.93	2974.74
2769.6	2958.42
2772.27	2959.54
2774.93	2949.23
2777.6	2927.33
2780.26	2909.32
2782.93	2929.25
2785.59	2903.1
2788.25	2905.45
2790.91	2912.01
2793.57	2915.74
2796.23	2945.8
2798.88	2933.03
2801.54	2931.7
2804.2	2937.79
2806.85	2946.69
2809.5	2947.54
2812.16	2984.53
2814.81	3030.15
2817.46	3026.63
2820.11	3101.32
2822.76	3151.27
2825.4	3182.1
2828.05	3293
2830.7	3438.98
2833.34	3634.18
2835.99	3907.36
2838.63	4298.9
2841.27	4961.49
2843.91	6057.21
2846.55	7586.8
2849.19	9024.07
2851.83	9719.86
2854.47	9572.62
2857.11	9094.81
2859.74	8639.83
2862.38	8261.13
2865.01	7935.7
2867.65	7831.17
2870.28	7920.47
2872.91	8137.44
2875.54	8298.16
2878.17	8350.11
2880.8	8428.87
2883.42	8612.08
2886.05	8812.07
2888.68	8995.85
2891.3	9103.26
2893.93	9131.44
2896.55	9088.58
2899.17	9103.19
2901.79	9044.99
2904.41	8994.66
2907.03	8956.21
2909.65	8883.21
2912.27	8815.46
2914.88	8738.05
2917.5	8684.91
2920.11	8645.79
2922.73	8620.12
2925.34	8628.1
2927.95	8672.94
2930.56	8651.67
2933.17	8594.88
2935.78	8455.04
2938.39	8184.53
2941	7750.09
2943.6	7105.71
2946.21	6501.65
2948.81	6019.88
2951.42	5701.11
2954.02	5495.29
2956.62	5404.52
2959.22	5308.21
2961.82	5175.49
2964.42	4985.56
2967.02	4779.66
2969.62	4537.38
2972.21	4319.43
2974.81	4117.59
2977.4	3941.14
2980	3788.97
2982.59	3634.7
2985.18	3533.86
2987.77	3406.3
2990.36	3383.33
2992.95	3324.82
2995.54	3295.58
2998.13	3282.86
3000.72	3288.39
3003.3	3254.13
3005.89	3292.82
3008.47	3264.46
3011.05	3182.22
3013.63	3087.09
3016.22	3014.27
3018.8	2937.26
3021.38	2891.23
3023.95	2820.52
3026.53	2776.41
3029.11	2723.63
3031.68	2698.18
3034.26	2669.18
3036.83	2663.08
3039.4	2653.04
3041.98	2650.23
3044.55	2641.67
3047.12	2656.17
3049.69	2620.23
3052.26	2644.59
3054.82	2662.56
3057.39	2662
3059.96	2674.21
3062.52	2657.4
3065.09	2677.93
3067.65	2674.01
3070.21	2677.65
3072.77	2666.34
3075.33	2659.64
3077.89	2659.54
3080.45	2652.43
3083.01	2649.58
3085.57	2672.07
3088.12	2677.14
3090.68	2685.07
3093.23	2689.65
3095.79	2691.78
3098.34	2707.87
3100.89	2708.54
3103.44	2720.36
3105.99	2742.43
3108.54	2758.23
3111.09	2786.81
3113.63	2796.37
3116.18	2797.33
3118.73	2814.5
3121.27	2868.03
3123.82	2851.49
3126.36	2876.78
3128.9	2874.95
3131.44	2913.3
3133.98	2945.33
3136.52	2960.55
3139.06	2971.73
3141.6	3010.41
3144.13	3010.74
3146.67	3021.97
3149.2	3075.79
3151.74	3081.63
3154.27	3100.69
3156.8	3107.15
3159.34	3142.85
3161.86	3162.6
3164.4	3192.08
3166.92	3199.32
3169.45	3237.57
3171.98	3215.5
3174.5	3228.42
3177.03	3232.21
3179.56	3221.48
3182.08	3222.96
3184.6	3255.92
3187.12	3232.59
3189.64	3257.14
3192.16	3259.58
3194.68	3243.35
3197.2	3250.83
3199.72	3240.06
3202.24	3249.29
3204.75	3262.88
3207.27	3244.61
3209.78	3242.36
3212.29	3234.84
3214.81	3235.07
3217.32	3207.36
3219.83	3218.99
3222.34	3220.17
3224.85	3209.09
3227.35	3203.97
3229.86	3187.89
3232.37	3188.79
3234.87	3179.61
3237.38	3171.86
3239.88	3143.79
3242.38	3145.19
3244.89	3142.85
3247.39	3123.13
3249.89	3127.16
3252.39	3108.15
3254.88	3103.81
3257.38	3079.83
3259.88	3071.22
3262.37	3061.58
3264.87	3042.16
3267.36	3036.9
3269.86	3033.75
3272.35	3021.12
3274.84	3016.52
3277.33	2996.29
3279.82	2972.6
3282.31	2965.81
3284.8	2963.63
3287.29	2953.74
3289.77	2953.11
3292.26	2923.93
3294.15	2933.66
3296.64	2925.27
3299.14	2917.56
3301.63	2906.02
3304.12	2913.93
3306.62	2892.85
3309.11	2874.79
3311.6	2881.54
3314.09	2885.72
3316.58	2880.36
3319.07	2863.21
3321.56	2856.44
3324.04	2862.05
3326.53	2833.67
3329.01	2848.56
3331.5	2820.16
3333.98	2819.25
3336.46	2814.8
3338.94	2826.74
3341.42	2821.59
3343.9	2804.18
3346.38	2803.63
3348.86	2792.88
3351.34	2800.81
3353.82	2778.35
3356.29	2766.27
3358.77	2763.88
3361.24	2769.39
3363.71	2777.9
3366.19	2746.72
3368.66	2750.73
3371.13	2739.75
3373.6	2753.12
3376.07	2751.69
3378.54	2742.44
3381	2728.21
3383.47	2731.2
3385.94	2710.86
3388.4	2721.42
3390.87	2696.38
3393.33	2687.75
3395.79	2687.74
3398.25	2695.62
3400.71	2677.28
3403.17	2686.59
3405.63	2666.39
3408.09	2662.62
3410.55	2650.7
3413	2633.91
3415.46	2632.13
3417.92	2636.91
3420.37	2620.33
3422.82	2602.06
3425.27	2612.18
3427.73	2585.67
3430.18	2584.93
3432.63	2557.39
3435.08	2558.16
3437.53	2553.34
3439.97	2530.25
3442.42	2507.63
3444.86	2489.44
3447.31	2496.9
3449.75	2471.4
3452.2	2457.65
3454.64	2416.9
3457.08	2439.72
3459.52	2426.32
3461.96	2397.87
3464.4	2387.23
3466.84	2373.89
3469.28	2350.48
3471.72	2325.83
3474.15	2309
3476.59	2302.79
3479.02	2268.77
3481.45	2263.75
3483.89	2263.93
3486.32	2213.83
3488.75	2192.03
3491.18	2179.29
3493.61	2160.47
3496.04	2151.8
3498.47	2113.76
3499.68	2110.58