File: src/Milk_AI/Nestle toned milk Cold 532nm 50% 600g 50xL 7s 20times 400-3500cm-1 200hole.txt
#Acq. time (s)=	7
#Accumulations=	20
#Range (cm-¹)=	400...3500
#Windows=	3
#Auto scanning=	Off
#Autofocus=	Off
#AutoExposure=	Off
#Spike filter=	Multiple accum.
#Delay time (s)=	0
#Binning=	1
#Readout mode=	Signal
#DeNoise=	Off
#ICS correction=	On
#Dark correction=	Off
#Inst. Process=	Off
#Detector Gain=	Best Dynamic Range
#Detector ADC=	45 kHz
#Detector temperature (°C)=	-60.1
#Instrument=	LabRAM HR Evol
#Detector=	Syncerity OE
#Objective=	x50_VIS_LWD
#Grating=	600 (500nm)
#ND Filter=	50%
#Laser=	532nm_Edge
#Hole=	199.981
#Range=	Visible
#E-Cal_Neon=	0
#StageXY=	75x50mm Scan+
#StageZ=	Z motor
#X (µm)=	0
#Y (µm)=	0
#Z (µm)=	332.8
#Spectral res.(cm-¹)=	12.8
#Full time(mm:ss)=	7:25
#AC=	Calibrated 2025-07-01 10:31
#Project=
#Sample=
#Site=
#Title=	D_1
#Remark=
#Date=	01.07.2025 12:21 (India Standard Time)
#Acquired=	01.07.2025 12:21:42 (India Standard Time)
#AxisType[0]=Intens
#AxisUnit[0]=Cnt
#AxisType[1]=Spectr
#AxisUnit[1]=1/cm
400.083	31576.6
403.63	31391.4
407.176	31553.8
410.72	31587
414.263	31568.7
417.805	31724.6
421.345	31767.2
424.884	31739.9
428.421	31805.8
431.955	31912.4
435.49	31849.4
439.023	31891.5
442.555	31949.3
446.084	31917.9
449.613	31930.8
453.141	32004.9
456.666	32013.6
460.191	31928.4
463.715	31983.2
467.235	32053.9
470.756	32059.7
474.274	32081.5
477.793	32220.7
481.308	32169.6
484.823	32225.5
488.336	32250.6
491.847	32216
495.358	32255.5
498.867	32416.8
502.374	32535.5
505.881	32607.9
509.386	32653.8
512.888	32663.4
516.39	32715.2
519.89	32736.9
523.391	32702.1
526.889	32745.2
530.385	32724
533.88	32709
537.373	32735.4
540.866	32712.8
544.357	32733.8
547.846	32745.3
551.334	32813
554.821	32843.3
558.307	32872.5
561.789	32886.3
565.272	32945.4
568.753	33047.5
572.233	33078.2
575.712	33139.8
579.188	33118
582.664	33146.4
586.139	33205.4
589.611	33366.8
593.083	33329.8
596.554	33339.7
600.021	33388.9
603.49	33445.2
606.955	33509.3
610.42	33532.2
613.882	33402.3
617.345	33455.8
620.805	33396.2
624.263	33338.7
627.722	33291.2
631.178	33209.2
634.633	33297
638.088	33354
641.539	33484.3
644.99	33360.9
648.439	33311.2
651.887	33362.2
655.335	33322.6
658.781	33422.9
662.225	33426.9
665.667	33463.9
669.108	33509.8
672.548	33524.7
675.987	33554.8
679.424	33535.3
682.86	33665.3
686.293	33693.1
689.727	33708.4
693.159	33753.6
696.59	33802.5
700.019	33840.3
703.448	33861.9
706.872	33804.5
710.298	33785.5
713.723	33812.8
717.144	33819.6
720.565	33964.8
723.984	33862.6
727.403	33901.4
730.821	33874.5
734.235	33856.9
737.651	33929
741.063	33875
744.474	33836.6
747.885	33918.6
751.293	34091.6
754.702	34069.4
758.108	34145.3
761.512	34204
764.915	34265.7
768.319	34336.7
771.719	34318.6
775.118	34416.4
778.516	34351.5
781.913	34451.9
785.308	34491.2
788.702	34473.8
792.095	34457.3
795.486	34419.9
798.876	34523.9
802.265	34585.1
805.653	34564.6
809.039	34495.3
812.424	34476.5
815.808	34500.8
819.191	34597.3
822.572	34691.4
825.95	34769.8
829.329	34770.1
832.706	34865.7
836.08	34818.5
839.455	34834.9
842.829	35035.9
846.199	35028.9
849.57	35119
852.938	35107.3
856.307	35094.4
859.672	35322.8
863.038	35196.5
866.401	35185
869.765	35155.8
873.125	35283.7
876.484	35424
879.844	35229.2
883.2	35195.1
886.555	35282.3
889.909	35337.6
893.262	35213.3
896.616	35072.6
899.966	35037.1
903.315	34977.2
906.663	34847.7
910.009	34892
913.354	34876.3
916.698	34891
920.041	34867.4
923.383	34790.2
926.723	34727.9
930.062	34722.7
933.399	34615.8
936.734	34619
940.069	34758.1
943.403	34759.1
946.736	34703
950.065	34710.9
953.396	34664.4
956.725	34802.2
960.051	34770.1
963.377	34851.9
966.7	34863
970.025	34844.2
973.345	34780.8
976.667	34805.9
979.985	34770.8
983.304	34878.6
986.62	34909.6
989.935	34896.7
993.25	35010.5
996.563	35116.7
999.874	35491.2
1003.19	35493.4
1006.49	35291
1009.8	35192.4
1013.11	35096.9
1016.41	35133.5
1019.72	35089.2
1023.02	34994
1026.32	34918.3
1029.62	34953.4
1032.92	34926.4
1036.22	34957.3
1039.51	34886.7
1042.81	34866.4
1046.1	34817.5
1049.39	34876.8
1052.68	34976.1
1055.97	35126.2
1059.26	35336.1
1062.55	35501.1
1065.83	35266.4
1069.12	35197
1072.4	35319.5
1075.68	35316
1078.97	35365.4
1082.24	35380.4
1085.52	35276.2
1088.8	35244.5
1092.08	35051
1095.35	34955.9
1098.62	34754
1101.9	34654.3
1105.17	34593.6
1108.44	34529.9
1111.7	34663.3
1114.97	34776.4
1118.23	34871.5
1121.5	34937.3
1124.76	34889
1128.03	34815.6
1131.29	34533.7
1134.54	34379.2
1137.8	34240.8
1141.06	34205.9
1144.31	34388.7
1147.57	34541.7
1150.82	34836.5
1154.07	35137.3
1157.32	35076.5
1160.57	34648.7
1163.82	34282.9
1167.07	34066.8
1170.31	34035.1
1173.56	33955.7
1176.8	33970
1180.04	33866.6
1183.28	33804.1
1186.52	33861.8
1189.76	33835.5
1192.99	33823.8
1196.23	33790.8
1199.46	33711
1202.7	33711.2
1205.93	33801.7
1209.16	33758
1212.39	33734.5
1215.62	33637.9
1218.84	33573.3
1222.07	33671.7
1225.29	33637.4
1228.52	33756.9
1231.74	33738.2
1234.96	33715.1
1238.18	33798
1241.4	33876.2
1244.61	33937
1247.83	34011.1
1251.04	33964.4
1254.25	34046.8
1257.47	34029.8
1260.68	34031.3
1263.89	34090.1
1267.09	33993.6
1270.3	33913.8
1273.51	33825
1276.71	33804.2
1279.91	33723.8
1283.12	33759.5
1286.32	33745.3
1289.52	33997.4
1292.72	34289.8
1295.91	34667.4
1299.11	34698.1
1302.3	34661.3
1305.5	34519.9
1308.69	34222.2
1311.88	33991.1
1315.07	33698.8
1318.26	33451.8
1321.44	33386.5
1324.63	33287.3
1327.82	33227.3
1331	33164.4
1334.18	33140.7
1337.36	33138.1
1340.54	33065.5
1343.72	33013.6
1346.9	32933.8
1350.07	32925.8
1353.25	32941.3
1356.42	32746
1359.6	32633.1
1362.77	32639.8
1365.94	32670
1369.11	32594.8
1372.28	32419.1
1375.44	32257.6
1378.61	32183.9
1381.77	32128.4
1384.93	31974.6
1388.1	32111.5
1391.26	32102.8
1394.41	32055.3
1397.57	32011.9
1400.73	31977.1
1403.89	31991.8
1407.04	31969.6
1410.19	32103.6
1413.35	32171.6
1416.5	32324.5
1419.65	32439
1422.8	32380.1
1425.94	32584.8
1429.09	33189
1432.23	33868.4
1435.38	34564.6
1438.52	34794.6
1441.66	34628.3
1444.8	34413.3
1447.94	34205.5
1451.08	34021.7
1454.22	33782.5
1457.35	33640.9
1460.48	33354
1463.62	33079.1
1466.75	32602.9
1469.88	32267.4
1473.01	31933.1
1476.14	31540.4
1479.26	31366
1482.39	31150.3
1485.51	31167.7
1488.64	31124.5
1491.76	31056.2
1494.88	31121.4
1498	31027.7
1501.12	31037.2
1504.24	31082.1
1507.35	31136.6
1510.47	31264.7
1513.58	31379.5
1516.69	31612.9
1519.81	31632.5
1522.92	31619.8
1526.03	31426.8
1529.13	31090.9
1532.24	30718.2
1535.35	30598
1538.45	30520.4
1541.55	30478.5
1544.66	30332.3
1547.76	30231.7
1550.86	30155.8
1553.96	30141.1
1557.05	30095.4
1560.15	30133.8
1563.24	30136.5
1566.34	30208.3
1569.43	30138.6
1572.52	30145.2
1575.61	29999.5
1578.7	30030.1
1581.79	30102.1
1584.88	29986.4
1587.96	30003
1591.05	29977
1594.13	29941.3
1597.21	29960.1
1600.3	30013.3
1603.37	29960.3
1606.45	29871.2
1609.53	29851
1612.61	29738.1
1615.68	29690.6
1618.76	29661.3
1621.83	29635.9
1624.9	29563.1
1627.97	29593.5
1631.04	29657.7
1634.11	29655.2
1637.18	29683.8
1640.24	29784
1643.31	29787.3
1646.37	30111
1649.44	30454.1
1652.5	30629.4
1655.56	30504.5
1658.62	30103.5
1661.67	29830.9
1664.73	29619.6
1667.79	29534
1670.84	29433.9
1673.89	29293
1676.95	29107.1
1680	28898.2
1683.05	28858.3
1686.1	28748.6
1689.14	28703.6
1692.19	28595.7
1695.23	28464.6
1698.28	28403.1
1701.32	28212.2
1704.36	28207.4
1707.4	28140.4
1710.44	28119
1713.48	28037.1
1716.52	27997.5
1719.56	27942.8
1722.59	27969.9
1725.63	28048.8
1728.66	28009.5
1731.69	28021.2
1734.72	28122.1
1737.75	28180.6
1740.78	28228.8
1743.8	28233.8
1746.83	28149.6
1749.86	28141.9
1752.88	27910.4
1755.9	27666.3
1758.92	27606
1761.94	27465
1764.96	27369.9
1767.98	27351.9
1771	27319.3
1774.01	27328.4
1777.03	27301
1780.04	27222.7
1783.05	27164.6
1786.06	27225.7
1789.07	27193.8
1792.08	27107.7
1795.09	27116.3
1798.1	27067.4
1801.1	26944.5
1804.11	26972.7
1807.11	26852
1810.11	26919.9
1813.11	26847.2
1816.11	26762.3
1819.11	26779.2
1822.11	26744.7
1825.11	26710.8
1828.1	26666.6
1831.1	26679.2
1834.09	26634.4
1837.08	26551.6
1840.07	26561.8
1843.06	26583.9
1846.05	26552.8
1849.04	26465.4
1852.02	26379.3
1855.01	26352.6
1857.99	26319.1
1860.98	26253.1
1863.96	26286
1866.94	26211.3
1869.92	26201.9
1872.9	26131.7
1875.88	26144.7
1878.85	26136.7
1881.83	26080.6
1884.8	25987.6
1887.78	25859.2
1890.75	25893.7
1893.72	25839.4
1896.69	25758.6
1899.66	25669.2
1902.63	25517.7
1905.59	25289.9
1908.56	25134.1
1911.52	24942.4
1914.49	24824.4
1917.45	24549
1920.41	24451.6
1923.37	24274.6
1926.33	24117.3
1929.29	24026.5
1932.24	23796.5
1935.2	23693.3
1938.15	23489.2
1941.1	23315.7
1944.06	23151.7
1947.01	23019.9
1949.96	22775.7
1952.91	22615.5
1955.86	22430.1
1958.8	22326.5
1961.75	22121.7
1964.69	22014.1
1967.64	21834.4
1970.58	21678.9
1973.52	21555.6
1976.46	21442.1
1979.4	21260.7
1982.34	21154
1985.27	21016.7
1988.21	20884.4
1991.14	20701.7
1994.08	20536.1
1997.01	20416
1999.94	20215
2002.87	20103.1
2005.8	20001.1
2008.73	19881.3
2011.66	19796.4
2014.58	19649
2017.51	19530.7
2020.43	19367.4
2023.36	19219.7
2026.28	19107.3
2029.2	19000
2032.12	18923.2
2035.04	18792.2
2037.95	18735
2040.87	18596.6
2043.78	18493.6
2045.76	18438
2048.69	18369.4
2051.61	18315.6
2054.54	18353.9
2057.46	18316.3
2060.38	18252.6
2063.3	18244.9
2066.22	18250.9
2069.14	18188.5
2072.06	18117.3
2074.98	18090.2
2077.89	18122
2080.81	18085.9
2083.72	18063.2
2086.63	17997
2089.55	17971.1
2092.46	18003.9
2095.37	17895.8
2098.28	17883.7
2101.18	17853.7
2104.09	17838.9
2106.99	17784.3
2109.9	17761.2
2112.8	17735.9
2115.71	17690.4
2118.61	17682.4
2121.51	17694.4
2124.4	17695.6
2127.3	17588.6
2130.2	17558.2
2133.09	17524.2
2135.99	17573.2
2138.88	17537.1
2141.78	17508.4
2144.67	17502.5
2147.56	17404.4
2150.45	17436.2
2153.34	17378.5
2156.22	17366.4
2159.11	17370.4
2162	17336
2164.88	17321.1
2167.76	17326.2
2170.64	17327.7
2173.53	17273.5
2176.41	17243.4
2179.29	17230.4
2182.16	17149.9
2185.04	17155.8
2187.92	17114.5
2190.79	17124
2193.66	17076.7
2196.54	17064.8
2199.41	17018.7
2202.28	17038.8
2205.15	16963.5
2208.02	16982.9
2210.88	16879.7
2213.75	16850.5
2216.62	16846.6
2219.48	16764.6
2222.34	16705.4
2225.21	16689.6
2228.07	16700.6
2230.93	16667
2233.79	16618.2
2236.65	16601.6
2239.5	16553.1
2242.36	16480.5
2245.21	16478.3
2248.07	16429.2
2250.92	16393.2
2253.77	16350.5
2256.62	16297.6
2259.47	16259.3
2262.32	16157
2265.17	16134.4
2268.02	16115
2270.86	16062.8
2273.71	16001.2
2276.55	16008.5
2279.39	15945.4
2282.24	15902.6
2285.08	15834.6
2287.92	15840.7
2290.75	15782.4
2293.59	15742.5
2296.43	15687.9
2299.26	15715.5
2302.1	15620.6
2304.93	15612.2
2307.76	15523.6
2310.6	15513.3
2313.43	15479.1
2316.25	15415.7
2319.08	15362.6
2321.91	15377.6
2324.74	15408
2327.56	15465.4
2330.39	15389.4
2333.21	15220.9
2336.03	15206
2338.85	15139.5
2341.67	15127.7
2344.49	15056.3
2347.31	15033.6
2350.13	14974.2
2352.94	14929.3
2355.76	14908.1
2358.57	14841.5
2361.39	14804
2364.2	14798
2367.01	14790.1
2369.82	14712.3
2372.63	14740.4
2375.44	14655
2378.24	14600.4
2381.05	14603.8
2383.85	14596.3
2386.66	14554.8
2389.46	14545.1
2392.26	14502.1
2395.06	14500.9
2397.86	14408.2
2400.66	14416.7
2403.46	14376.2
2406.26	14361.7
2409.05	14305.2
2411.85	14237.1
2414.64	14266.3
2417.43	14234.7
2420.23	14219.6
2423.02	14118.7
2425.81	14139.4
2428.6	14115.4
2431.38	14087.4
2434.17	14063.1
2436.96	14035.6
2439.74	14000.2
2442.53	13944.9
2445.31	13964.3
2448.09	13890.2
2450.87	13880.6
2453.65	13879
2456.43	13836.9
2459.21	13791.6
2461.98	13719
2464.76	13704.9
2467.53	13696.3
2470.31	13703.1
2473.08	13624
2475.85	13620.2
2478.63	13547.9
2481.39	13575
2484.16	13569.6
2486.93	13537.5
2489.7	13493.2
2492.46	13431.8
2495.23	13432.6
2497.99	13420.4
2500.76	13364.3
2503.52	13317.2
2506.28	13318.5
2509.04	13233.9
2511.8	13241.1
2514.56	13226.8
2517.31	13161.9
2520.07	13158.9
2522.82	13165
2525.58	13139.2
2528.33	13135.1
2531.09	13069.4
2533.84	13039.2
2536.59	13030.7
2539.34	13000.7
2542.08	12984.2
2544.83	12940.3
2547.58	12900.6
2550.32	12865.6
2553.07	12828.9
2555.81	12795.8
2558.55	12788.7
2561.29	12750.1
2564.03	12754.3
2566.77	12694.9
2569.51	12682.2
2572.25	12652
2574.99	12636.7
2577.72	12650
2580.46	12615.3
2583.19	12587.5
2585.92	12595.9
2588.65	12538
2591.38	12584.2
2594.11	12570.1
2596.84	12492.6
2599.57	12463.3
2602.3	12448.4
2605.02	12458.7
2607.75	12404.9
2610.47	12392.4
2613.19	12394
2615.92	12341.4
2618.64	12248.5
2621.36	12295.3
2624.08	12233.4
2626.8	12239.6
2629.51	12220.4
2632.23	12206.4
2634.94	12156.2
2637.66	12156.2
2640.37	12116.8
2643.08	12110.9
2645.79	12051.7
2648.5	12078.9
2651.21	12032.5
2653.92	12018
2656.63	12008.1
2659.33	11946.5
2662.04	11973.7
2664.75	11924.9
2667.45	11938.5
2670.15	11894.2
2672.85	11872.7
2675.55	11858.1
2678.25	11828.8
2680.95	11785.7
2683.65	11750.1
2686.35	11751.5
2689.04	11751.5
2691.74	11723.3
2694.43	11698.2
2697.13	11677
2699.82	11654.5
2702.51	11650.4
2705.2	11665.1
2707.89	11641.2
2710.58	11616.1
2713.26	11569
2715.95	11595.3
2718.64	11513.8
2721.32	11538.4
2724	11479
2726.69	11460.1
2729.37	11468.1
2732.05	11456.6
2734.73	11454
2737.41	11341.9
2740.09	11292.4
2742.76	11246.7
2745.44	11267.8
2748.11	11234.4
2750.79	11146.3
2753.46	11143.8
2756.13	11081.8
2758.81	11093.3
2761.47	11050.9
2764.14	11037.1
2766.81	11027.3
2769.48	11006.4
2772.15	10956.6
2774.81	10939.1
2777.48	10912
2780.14	10871.9
2782.8	10859.2
2785.47	10812.5
2788.13	10770.1
2790.79	10741
2793.44	10757.6
2796.1	10785.5
2798.76	10758.7
2801.42	10722.5
2804.07	10665.6
2806.73	10599.6
2809.38	10605.2
2812.03	10615.9
2814.68	10642
2817.33	10627.6
2819.98	10569.6
2822.63	10581.4
2825.28	10575.7
2827.93	10594.6
2830.57	10573.9
2833.22	10644
2835.86	10791.1
2838.51	10890.7
2841.15	11085
2843.79	11363.7
2846.43	11686.9
2849.07	11881.1
2851.71	11909.7
2854.35	11834.6
2856.98	11721.9
2859.62	11614.2
2862.25	11492.8
2864.89	11487.4
2867.52	11516.7
2870.15	11522
2872.78	11574.5
2875.41	11624.8
2878.04	11697.6
2880.67	11714.7
2883.3	11709.5
2885.92	11695.6
2888.55	11710.4
2891.18	11713.7
2893.8	11653.9
2896.42	11652.1
2899.04	11609.8
2901.67	11580.8
2904.29	11500.4
2906.9	11543.6
2909.52	11486.4
2912.14	11465.4
2914.76	11417.6
2917.37	11379.3
2919.99	11357.7
2922.6	11331.1
2925.21	11328.9
2927.82	11301.5
2930.44	11290.2
2933.05	11286.1
2935.65	11218.7
2938.26	11073.4
2940.87	10918.8
2943.48	10724.1
2946.08	10540.2
2948.69	10455.4
2951.29	10365
2953.89	10316.8
2956.49	10280.2
2959.1	10227.6
2961.7	10176.8
2964.29	10125.4
2966.89	10056.1
2969.49	9992.59
2972.09	9935.5
2974.68	9862.7
2977.28	9856.52
2979.87	9780.52
2982.46	9740.72
2985.05	9667.43
2987.65	9610.55
2990.24	9584.98
2992.82	9576.35
2995.41	9542.97
2998	9514.32
3000.59	9500.87
3003.17	9462.41
3005.76	9461
3008.34	9424.17
3010.92	9400.73
3013.5	9361.48
3016.09	9340.27
3018.67	9323.62
3021.25	9327.36
3023.82	9294.9
3026.4	9252.63
3028.98	9255.13
3031.55	9229.43
3034.13	9231.1
3036.7	9212.43
3039.28	9207.78
3041.85	9235.03
3044.42	9244.95
3046.99	9227.91
3049.56	9230.98
3052.13	9268.02
3054.69	9274.43
3057.26	9244.11
3059.83	9261.89
3062.39	9256.77
3064.95	9273.96
3067.52	9240.88
3070.08	9261.81
3072.64	9279.03
3075.2	9277.46
3077.76	9251.26
3080.32	9258.31
3082.88	9230.92
3085.44	9261.71
3087.99	9271.73
3090.55	9288.33
3093.1	9295.29
3095.65	9268.97
3098.21	9324.27
3100.76	9311.78
3103.31	9314.9
3105.86	9342.25
3108.41	9383.48
3110.96	9434.83
3113.5	9393.38
3116.05	9416.99
3118.59	9450.59
3121.14	9417.18
3123.68	9464.98
3126.23	9506.42
3128.77	9515.08
3131.31	9568.1
3133.85	9574.79
3136.39	9615
3138.93	9614.34
3141.46	9604.42
3144	9630.68
3146.54	9636.72
3149.07	9689.06
3151.6	9713.09
3154.14	9705.58
3156.67	9777.05
3159.2	9763.74
3161.73	9771.38
3164.26	9803.64
3166.79	9794.23
3169.32	9804.22
3171.84	9788.47
3174.37	9799.48
3176.9	9787.44
3179.42	9775.69
3181.94	9763.93
3184.47	9781.6
3186.99	9750.19
3189.51	9760.93
3192.03	9744.32
3194.55	9715.47
3197.07	9713.71
3199.58	9726.89
3202.1	9719.89
3204.62	9715.74
3207.13	9685.74
3209.65	9670.16
3212.16	9658.74
3214.67	9642.79
3217.18	9600.72
3219.69	9577.28
3222.2	9579.47
3224.71	9564.39
3227.22	9558.62
3229.73	9507.44
3232.23	9520.31
3234.74	9508.59
3237.24	9482.25
3239.75	9449.67
3242.25	9441.5
3244.75	9412.3
3247.25	9385.51
3249.75	9353.41
3252.25	9351.69
3254.75	9327.46
3257.25	9272.81
3259.74	9240.87
3262.24	9235.52
3264.73	9184.39
3267.23	9204.83
3269.72	9144.48
3272.21	9155.28
3274.7	9132.39
3277.2	9110.35
3279.69	9057.13
3282.17	9047.3
3284.66	9029.69
3287.15	9012.63
3289.64	8962.15
3292.12	8947.29
3293.56	8928.13
3296.05	8903.44
3298.55	8899.38
3301.04	8868.09
3303.54	8851.31
3306.03	8871.99
3308.52	8824.34
3311.01	8816.7
3313.5	8739.71
3315.99	8763.1
3318.48	8758.52
3320.97	8741.35
3323.45	8719.45
3325.94	8716.83
3328.42	8675.07
3330.91	8672.94
3333.39	8671.99
3335.87	8634.5
3338.36	8634.32
3340.84	8578.84
3343.32	8574.7
3345.8	8569.68
3348.27	8553.06
3350.75	8526.47
3353.23	8514.92
3355.7	8497
3358.18	8450.26
3360.65	8482.76
3363.13	8415.12
3365.6	8447.98
3368.07	8434.68
3370.54	8396.76
3373.01	8404.54
3375.48	8382.25
3377.95	8363.36
3380.42	8362.2
3382.88	8321.02
3385.35	8299.28
3387.81	8293.75
3390.28	8235.76
3392.74	8258.89
3395.2	8254.79
3397.67	8221.46
3400.13	8225
3402.58	8199.92
3405.05	8188.56
3407.5	8167.89
3409.96	8152.02
3412.42	8146.21
3414.87	8110.31
3417.33	8100.49
3419.78	8043.11
3422.23	8035.06
3424.69	7999.66
3427.14	7987.07
3429.59	7959.67
3432.04	7920.31
3434.49	7907.76
3436.94	7910.36
3439.39	7872.52
3441.83	7828.15
3444.28	7795.15
3446.72	7782.84
3449.17	7751.64
3451.61	7724.44
3454.05	7692.43
3456.5	7688.58
3458.94	7629.47
3461.38	7631.76
3463.81	7598.54
3466.25	7548.94
3468.69	7537.83
3471.13	7494.33
3473.56	7450.13
3476	7444.07
3478.43	7387.26
3480.87	7368.33
3483.3	7314.21
3485.73	7251.42
3488.16	7246.5
3490.59	7198.6
3493.02	7181
3495.45	7100.45
3497.88	7088.24
3499.09	7071.49