File: src/Milk_AI/Nestle toned milk RT 532nm 50% 600g 50xL 7s 20times 400-3500cm-1 200hole.txt
#Acq. time (s)=	7
#Accumulations=	20
#Range (cm-¹)=	400...3500
#Windows=	3
#Auto scanning=	Off
#Autofocus=	Off
#AutoExposure=	Off
#Spike filter=	Multiple accum.
#Delay time (s)=	0
#Binning=	1
#Readout mode=	Signal
#DeNoise=	Off
#ICS correction=	On
#Dark correction=	Off
#Inst. Process=	Off
#Detector Gain=	Best Dynamic Range
#Detector ADC=	45 kHz
#Detector temperature (°C)=	-60.1
#Instrument=	LabRAM HR Evol
#Detector=	Syncerity OE
#Objective=	x50_VIS_LWD
#Grating=	600 (500nm)
#ND Filter=	50%
#Laser=	532nm_Edge
#Hole=	199.981
#Range=	Visible
#E-Cal_Neon=	0
#StageXY=	75x50mm Scan+
#StageZ=	Z motor
#X (µm)=	0
#Y (µm)=	0
#Z (µm)=	946.1
#Spectral res.(cm-¹)=	12.8
#Full time(mm:ss)=	7:26
#AC=	Calibrated 2025-06-30 10:26
#Project=
#Sample=
#Site=
#Title=	D_99
#Remark=
#Date=	30.06.2025 14:54 (India Standard Time)
#Acquired=	30.06.2025 14:54:56 (India Standard Time)
#AxisType[0]=Intens
#AxisUnit[0]=Cnt
#AxisType[1]=Spectr
#AxisUnit[1]=1/cm
400.17	27557.6
403.717	27426.9
407.263	27517.9
410.807	27573.8
414.35	27540.6
417.892	27658.9
421.432	27637
424.971	27653.7
428.509	27695.6
432.045	27800.4
435.58	27861.7
439.111	27791.3
442.643	27845
446.174	27859.1
449.701	27897.9
453.229	27860.8
456.756	27930.7
460.279	27905.8
463.803	27897.7
467.326	27932.2
470.845	27971.3
474.365	28015.5
477.882	28069.8
481.399	28038.7
484.913	28126.6
488.425	28152.4
491.938	28139.7
495.448	28203.2
498.956	28279.5
502.465	28383
505.971	28418.5
509.475	28423.4
512.981	28536.6
516.482	28542.1
519.983	28522.1
523.482	28515.9
526.979	28590.1
530.476	28549.9
533.971	28538.3
537.464	28541.6
540.956	28587.6
544.447	28593.2
547.937	28658.5
551.425	28564.5
554.912	28682.1
558.398	28679.9
561.882	28698.1
565.365	28754.4
568.847	28778.9
572.325	28874.3
575.804	28842.5
579.282	28917.7
582.756	28988.3
586.231	28979.4
589.705	29059
593.175	29073.4
596.646	29074
600.116	29080.6
603.582	29117.4
607.049	29159.5
610.513	29171.2
613.977	29126.4
617.438	29201.7
620.898	29119.4
624.359	29067.5
627.816	29032.6
631.272	29019.7
634.728	29037.2
638.181	29047.5
641.633	29129.5
645.084	28980
648.535	29044
651.983	29018.9
655.43	29071.1
658.875	29085.4
662.319	29073.9
665.762	29104.4
669.203	29189.6
672.643	29173.7
676.082	29125.1
679.519	29273.3
682.955	29325.6
686.39	29397
689.824	29360.1
693.256	29421.1
696.685	29435.5
700.115	29514
703.543	29519.8
706.97	29498.4
710.394	29434
713.818	29389.8
717.241	29437.3
720.661	29482.6
724.082	29501.4
727.501	29472.1
730.917	29444
734.334	29489.1
737.747	29467.6
741.161	29433.7
744.572	29386
747.982	29472.7
751.392	29525.2
754.799	29573.7
758.205	29627.5
761.611	29641.1
765.014	29658.7
768.416	29778.7
771.816	29802.6
775.218	29865.4
778.616	29829.7
782.012	29891.3
785.408	29965.9
788.802	29966.5
792.195	29897.7
795.586	29888.8
798.977	29911.3
802.365	29912.8
805.753	30001.9
809.14	29934.8
812.525	29889.9
815.907	29863.7
819.289	29875.1
822.671	29939.3
826.051	30044.8
829.43	29973.3
832.805	29946.4
836.182	29951.3
839.557	29910.6
842.928	30007.8
846.301	30093.6
849.67	30116.8
853.04	30154.5
856.407	30129.8
859.774	30238.8
863.138	30214.4
866.503	30164.2
869.865	30150.5
873.225	30237.5
876.586	30264.5
879.944	30182.4
883.301	30196.7
886.658	30226.3
890.012	30230.1
893.365	30202.1
896.717	30211.7
900.067	30143.5
903.416	30177
906.766	30018.7
910.112	30065.6
913.458	30068.1
916.802	30000.2
920.145	30001.4
923.484	29922.7
926.825	29837.2
930.164	29806.2
933.501	29825.8
936.838	29802.7
940.173	29925.3
943.505	29878.6
946.838	29845.6
950.17	29836.6
953.5	29855.3
956.827	29827.5
960.155	29879.9
963.48	29948.6
966.805	29909.9
970.128	29936.2
973.45	29923.4
976.77	29851.4
980.091	29924.2
983.408	29977.2
986.726	29977.7
990.041	30041.6
993.354	30027.9
996.668	30075.7
999.979	30325.2
1003.29	30371.8
1006.6	30339.9
1009.91	30159.6
1013.21	30078.7
1016.52	30236.7
1019.82	30068
1023.12	30032.4
1026.43	29898.5
1029.73	29961.6
1033.02	29907.5
1036.32	29860.6
1039.62	29867.7
1042.91	29854.5
1046.21	29853.6
1049.5	29823.8
1052.79	29769
1056.08	29888.5
1059.37	29905.2
1062.65	29993.8
1065.94	29967.8
1069.23	29941.3
1072.51	29975.7
1075.79	29987.9
1079.07	29998.7
1082.35	30001
1085.63	29998.8
1088.91	30075.9
1092.18	29852.5
1095.46	29721.7
1098.73	29637.6
1102	29590.3
1105.27	29518.4
1108.54	29539.3
1111.81	29545.5
1115.08	29604.8
1118.34	29681.1
1121.61	29677.1
1124.87	29659.8
1128.13	29572.1
1131.39	29414.8
1134.65	29347.1
1137.91	29225.5
1141.17	29262.1
1144.42	29365.2
1147.68	29404.4
1150.93	29575.6
1154.18	29731.5
1157.43	29803.3
1160.68	29614.2
1163.93	29338.6
1167.18	29146.5
1170.42	29100.5
1173.67	29036.2
1176.91	28967.9
1180.15	28972.7
1183.39	28894.9
1186.63	28938.7
1189.87	28894.9
1193.11	28910.3
1196.34	28824.2
1199.58	28827.1
1202.81	28816.8
1206.04	28901.6
1209.27	28876.2
1212.5	28923.9
1215.73	28812.7
1218.95	28749.9
1222.18	28786.3
1225.4	28789.8
1228.63	28848
1231.85	28818.3
1235.07	28839.3
1238.29	28771
1241.51	28882.9
1244.72	28925.6
1247.94	28928
1251.15	28866.2
1254.37	28915.5
1257.58	28806.3
1260.79	28909
1264	28858.7
1267.21	28892.8
1270.41	28767.8
1273.62	28717.4
1276.82	28698.9
1280.03	28608.3
1283.23	28624.3
1286.43	28557.4
1289.63	28581.7
1292.83	28721
1296.03	28867.1
1299.22	29038.5
1302.42	29098.7
1305.61	29007.6
1308.8	28887.8
1311.99	28720.8
1315.18	28561
1318.37	28448.8
1321.56	28368.8
1324.74	28341.6
1327.93	28257.4
1331.11	28281.3
1334.3	28280.6
1337.48	28218.2
1340.66	28274.3
1343.84	28145
1347.01	28118.5
1350.19	28099.4
1353.37	28075.2
1356.54	28014.3
1359.71	27819.4
1362.88	27874.8
1366.05	27825.6
1369.22	27790.4
1372.39	27712.5
1375.56	27560.8
1378.72	27547.9
1381.89	27437.6
1385.05	27379.5
1388.21	27397.8
1391.37	27344.1
1394.53	27393.5
1397.69	27293.7
1400.85	27263.2
1404	27186.5
1407.16	27262.5
1410.31	27242.1
1413.46	27261.6
1416.61	27381.4
1419.76	27380.6
1422.91	27368.5
1426.06	27409.8
1429.21	27667.1
1432.35	28127.8
1435.49	28449.1
1438.64	28656.5
1441.78	28661.4
1444.92	28539.3
1448.06	28427.5
1451.2	28255.6
1454.33	28124.5
1457.47	28043.8
1460.6	27908.2
1463.74	27724.6
1466.87	27456.8
1470	27256.8
1473.13	27047.5
1476.26	26850.9
1479.38	26619.2
1482.51	26556.3
1485.63	26471.8
1488.76	26453.6
1491.88	26433
1495	26489.4
1498.12	26473.2
1501.24	26338.4
1504.36	26382.9
1507.47	26388.1
1510.59	26539.4
1513.7	26537.9
1516.81	26659.3
1519.93	26727.6
1523.04	26750.4
1526.15	26579.2
1529.25	26380.3
1532.36	26217.8
1535.47	26022.1
1538.57	25966.3
1541.67	25948.4
1544.78	25877.8
1547.88	25802
1550.98	25742.2
1554.08	25716.1
1557.18	25761.6
1560.27	25705.5
1563.37	25729.4
1566.46	25711
1569.55	25673.8
1572.64	25697.7
1575.74	25518.3
1578.83	25596
1581.91	25591.7
1585	25580.3
1588.09	25525.1
1591.17	25532
1594.25	25513.9
1597.34	25481.2
1600.42	25544.9
1603.5	25458.2
1606.58	25413.6
1609.65	25366.2
1612.73	25266.9
1615.8	25267.1
1618.88	25209.8
1621.95	25126.6
1625.03	25124.3
1628.1	25132.9
1631.17	25163.3
1634.23	25149.9
1637.3	25125.2
1640.37	25187.9
1643.43	25133.1
1646.5	25262.5
1649.56	25468
1652.62	25519.4
1655.68	25554.8
1658.74	25432.2
1661.8	25146.8
1664.85	25029.7
1667.91	24986.2
1670.96	24942.5
1674.02	24896.1
1677.07	24717.1
1680.12	24589.6
1683.17	24560.6
1686.22	24474.6
1689.27	24368.3
1692.31	24317.4
1695.36	24263.1
1698.4	24161.8
1701.45	24054
1704.49	23993.8
1707.53	23984.3
1710.57	23923.5
1713.61	23870.8
1716.65	23786.8
1719.68	23793.5
1722.72	23737.4
1725.75	23787.3
1728.78	23764.7
1731.82	23761.4
1734.84	23751.1
1737.87	23775
1740.9	23798.2
1743.93	23811
1746.96	23807.7
1749.98	23746.4
1753	23658.9
1756.03	23545.4
1759.05	23423.6
1762.07	23333.9
1765.09	23247.8
1768.11	23241.3
1771.12	23170.7
1774.14	23213.6
1777.15	23134.6
1780.17	23144.6
1783.18	23080.8
1786.19	23156.9
1789.2	23138.4
1792.21	23014
1795.22	22975.8
1798.22	22982
1801.23	22896
1804.23	22890.2
1807.24	22822.6
1810.24	22873.3
1813.24	22871.7
1816.24	22796.6
1819.24	22704.5
1822.24	22735.5
1825.23	22680.3
1828.23	22671
1831.22	22684
1834.22	22636.4
1837.21	22579.9
1840.2	22549.5
1843.19	22523.6
1846.18	22540.4
1849.17	22435.5
1852.15	22393.7
1855.14	22377.4
1858.12	22372.4
1861.11	22306.7
1864.09	22317.2
1867.07	22331.8
1870.05	22240.9
1873.03	22173.9
1876.01	22226.9
1878.98	22158.1
1881.96	22120.1
1884.93	22031.4
1887.91	21939.7
1890.88	21992.3
1893.85	21926
1896.82	21868.2
1899.79	21757.2
1902.76	21647.5
1905.72	21508.3
1908.69	21310.6
1911.65	21200.6
1914.62	21062.1
1917.58	20884.7
1920.54	20776.7
1923.5	20648.8
1926.46	20511
1929.42	20406.6
1932.37	20272.5
1935.33	20154.6
1938.28	19994.6
1941.24	19856.1
1944.19	19768.4
1947.14	19649
1950.09	19494.5
1953.04	19306.8
1955.99	19179.1
1958.93	19072.5
1961.88	18967.3
1964.82	18816.5
1967.77	18699.6
1970.71	18617.8
1973.65	18494.1
1976.59	18424.3
1979.53	18290.1
1982.47	18191.2
1985.41	18074.9
1988.34	17952.1
1991.28	17818.7
1994.21	17673.5
1997.14	17578.1
2000.07	17466.1
2003.01	17330
2005.94	17244.4
2008.86	17182.6
2011.79	17074.2
2014.72	17014.8
2017.64	16899.3
2020.57	16763.3
2023.49	16633.6
2026.41	16577.6
2029.33	16490.7
2032.25	16413.2
2035.17	16328.4
2038.09	16277.5
2041	16181.6
2043.92	16102.4
2045.86	16077.2
2048.79	16024.9
2051.71	15983.4
2054.64	15997.1
2057.56	15930.7
2060.48	15938.6
2063.4	15942.3
2066.32	15905.2
2069.24	15877.5
2072.16	15820.7
2075.08	15855.8
2077.99	15835.6
2080.91	15813.1
2083.82	15784.9
2086.74	15763.4
2089.65	15731.4
2092.56	15713.9
2095.47	15666.7
2098.38	15662.2
2101.29	15619.6
2104.19	15592.8
2107.1	15570
2110	15538.2
2112.91	15505.4
2115.81	15460.1
2118.71	15481.1
2121.61	15460.3
2124.51	15382.4
2127.4	15384.5
2130.3	15404.2
2133.2	15344.8
2136.09	15372.5
2138.99	15363.9
2141.88	15314.5
2144.77	15322.6
2147.66	15284.6
2150.55	15252.3
2153.44	15241.6
2156.33	15222.1
2159.21	15244.5
2162.1	15218.6
2164.98	15215.1
2167.87	15188.8
2170.75	15164.8
2173.63	15154.8
2176.51	15156.7
2179.39	15124.8
2182.27	15039.9
2185.14	15036.6
2188.02	15019.8
2190.9	15020.9
2193.77	14996
2196.64	14976.2
2199.51	14978.3
2202.39	14947.5
2205.25	14921.1
2208.12	14884.6
2210.99	14835.8
2213.86	14801.4
2216.72	14776.6
2219.59	14742.2
2222.45	14734.4
2225.31	14688.7
2228.17	14676.9
2231.03	14631.8
2233.89	14603.8
2236.75	14588.5
2239.61	14575
2242.46	14508.3
2245.32	14486.3
2248.17	14506.9
2251.03	14452.2
2253.88	14427
2256.73	14382.1
2259.58	14322.2
2262.43	14277.9
2265.28	14205.4
2268.12	14193.7
2270.97	14134
2273.81	14098.2
2276.66	14113.2
2279.5	14099
2282.34	14048.2
2285.18	13992.5
2288.02	13970.2
2290.86	13936.5
2293.7	13914.6
2296.54	13878.4
2299.37	13845.5
2302.21	13821.1
2305.04	13813.3
2307.87	13707.5
2310.7	13717.1
2313.53	13682.4
2316.36	13648.5
2319.19	13622
2322.02	13561.9
2324.85	13573.1
2327.67	13666.5
2330.5	13757.3
2333.32	13525.7
2336.14	13402.5
2338.96	13398.7
2341.78	13438.1
2344.6	13411.4
2347.42	13330.4
2350.24	13280.5
2353.05	13248.3
2355.87	13194.3
2358.68	13174.1
2361.5	13150
2364.31	13120.8
2367.12	13136.1
2369.93	13097.4
2372.74	12978.9
2375.55	13000.8
2378.35	12990
2381.16	12952.3
2383.96	12944.2
2386.77	12941.9
2389.57	12925
2392.37	12856.7
2395.17	12836.9
2397.97	12794.8
2400.77	12792.4
2403.57	12761.8
2406.37	12722.3
2409.16	12713.4
2411.96	12689.5
2414.75	12645.6
2417.55	12658.4
2420.34	12614.2
2423.13	12604.7
2425.92	12577.5
2428.71	12555.1
2431.5	12533.1
2434.28	12499.8
2437.07	12448.1
2439.85	12479.2
2442.64	12457.2
2445.42	12425
2448.2	12368.8
2450.98	12376
2453.76	12366.4
2456.54	12315.3
2459.32	12321.8
2462.1	12265.9
2464.87	12252.5
2467.65	12228
2470.42	12192.6
2473.2	12174.2
2475.97	12149.3
2478.74	12132.1
2481.51	12136.4
2484.28	12097.9
2487.05	12081.4
2489.81	12083.9
2492.58	12013.2
2495.34	11995.6
2498.11	12003.9
2500.87	11952.2
2503.63	11923
2506.39	11893.7
2509.15	11877.7
2511.91	11858.1
2514.67	11805
2517.43	11802.7
2520.19	11799.9
2522.94	11798.4
2525.7	11759.1
2528.45	11727.5
2531.2	11718.5
2533.95	11691.3
2536.7	11671.4
2539.45	11654.2
2542.2	11595.2
2544.95	11592.8
2547.69	11542.8
2550.44	11518.3
2553.18	11503.3
2555.93	11470.9
2558.67	11494.2
2561.41	11424.7
2564.15	11436.7
2566.89	11425.5
2569.63	11348.1
2572.36	11355.5
2575.1	11373.7
2577.84	11357.7
2580.57	11345.1
2583.31	11351
2586.04	11289.8
2588.77	11280.1
2591.5	11301
2594.23	11263.4
2596.96	11249.8
2599.69	11205.4
2602.41	11184.2
2605.14	11201.3
2607.86	11191.5
2610.59	11153.8
2613.31	11167.3
2616.03	11124.5
2618.75	11072.5
2621.48	11084
2624.19	11063.1
2626.91	11036.2
2629.63	11020.1
2632.35	11002.6
2635.06	10997.6
2637.77	10975.3
2640.49	10923.4
2643.2	10928.2
2645.91	10911.6
2648.62	10897.1
2651.33	10841.7
2654.04	10838.2
2656.75	10837.5
2659.45	10793.7
2662.16	10826.4
2664.86	10801.1
2667.57	10787.1
2670.27	10739.8
2672.97	10729
2675.67	10729.3
2678.37	10723.2
2681.07	10676.7
2683.77	10682
2686.47	10627.7
2689.16	10645.7
2691.86	10634.7
2694.55	10585.6
2697.25	10571.9
2699.94	10552.8
2702.63	10582.2
2705.32	10584.4
2708.01	10560.5
2710.7	10538.4
2713.39	10525.7
2716.07	10513.6
2718.76	10504.1
2721.44	10484.4
2724.12	10418
2726.81	10434.5
2729.49	10401.9
2732.17	10412.8
2734.85	10371.4
2737.53	10332.2
2740.21	10309.2
2742.88	10287.7
2745.56	10260.1
2748.24	10201.7
2750.91	10163.1
2753.58	10146.8
2756.25	10128.4
2758.93	10132.4
2761.6	10075
2764.27	10113.2
2766.93	10058.9
2769.6	10053.9
2772.27	10027
2774.93	9974.27
2777.6	9994.43
2780.26	9967.48
2782.93	9898.17
2785.59	9894.89
2788.25	9856.01
2790.91	9842.58
2793.57	9856.62
2796.23	9833.58
2798.88	9842.77
2801.54	9798.66
2804.2	9761.48
2806.85	9762.68
2809.5	9758.13
2812.16	9746.66
2814.81	9754.46
2817.46	9681.76
2820.11	9710.03
2822.76	9715.92
2825.4	9681.2
2828.05	9683.35
2830.7	9708.53
2833.34	9744.09
2835.99	9804.11
2838.63	9871.53
2841.27	10028.7
2843.91	10230.4
2846.55	10591.4
2849.19	10891.5
2851.83	11030.4
2854.47	11020.4
2857.11	10913.1
2859.74	10780.5
2862.38	10709.5
2865.01	10656.5
2867.65	10603.2
2870.28	10637.4
2872.91	10671.5
2875.54	10728.9
2878.17	10754.5
2880.8	10774.6
2883.42	10759.2
2886.05	10791.5
2888.68	10864.3
2891.3	10861.2
2893.93	10854.9
2896.55	10813
2899.17	10831.6
2901.79	10809.5
2904.41	10749.1
2907.03	10718.1
2909.65	10649.2
2912.27	10668.5
2914.88	10672.9
2917.5	10645.6
2920.11	10656.1
2922.73	10580.7
2925.34	10557.1
2927.95	10562.3
2930.56	10594.1
2933.17	10530.6
2935.78	10502.1
2938.39	10416.5
2941	10279.5
2943.6	10105.2
2946.21	9926.28
2948.81	9773.02
2951.42	9684.02
2954.02	9590.55
2956.62	9577.02
2959.22	9523.01
2961.82	9495.19
2964.42	9432.41
2967.02	9358.33
2969.62	9344.06
2972.21	9211.35
2974.81	9163.18
2977.4	9151.35
2980	9094.32
2982.59	9077.01
2985.18	8998.15
2987.77	8935.63
2990.36	8931.89
2992.95	8891.35
2995.54	8870.96
2998.13	8835.14
3000.72	8819.93
3003.3	8822.33
3005.89	8825.92
3008.47	8774.15
3011.05	8730.42
3013.63	8679.13
3016.22	8660.39
3018.8	8623.72
3021.38	8672.64
3023.95	8657.53
3026.53	8592.86
3029.11	8574.79
3031.68	8548.82
3034.26	8560.92
3036.83	8554.65
3039.4	8535.63
3041.98	8547.86
3044.55	8522.71
3047.12	8520.45
3049.69	8517
3052.26	8523.35
3054.82	8550.18
3057.39	8535.25
3059.96	8541.14
3062.52	8518.84
3065.09	8537.87
3067.65	8564.65
3070.21	8537.75
3072.77	8550.41
3075.33	8535.02
3077.89	8511.56
3080.45	8498.11
3083.01	8515.94
3085.57	8491.37
3088.12	8510.12
3090.68	8534.07
3093.23	8506.38
3095.79	8523.47
3098.34	8467.25
3100.89	8506.09
3103.44	8518.18
3105.99	8546.44
3108.54	8576.15
3111.09	8584.39
3113.63	8577.3
3116.18	8593.2
3118.73	8597.19
3121.27	8625.29
3123.82	8594.93
3126.36	8630.76
3128.9	8632.23
3131.44	8649.24
3133.98	8717.41
3136.52	8672.12
3139.06	8724.33
3141.6	8707.99
3144.13	8696.82
3146.67	8741.63
3149.2	8776.04
3151.74	8773.78
3154.27	8789.49
3156.8	8830.03
3159.34	8824.61
3161.86	8789.29
3164.4	8819.48
3166.92	8816.62
3169.45	8833.49
3171.98	8807.58
3174.5	8843
3177.03	8801.37
3179.56	8774.3
3182.08	8751.34
3184.6	8767.93
3187.12	8757.97
3189.64	8749.7
3192.16	8721.24
3194.68	8690.83
3197.2	8692.33
3199.72	8668.25
3202.24	8661.43
3204.75	8654.89
3207.27	8647.1
3209.78	8610.98
3212.29	8586.17
3214.81	8558.64
3217.32	8533.56
3219.83	8535.11
3222.34	8527.68
3224.85	8488.55
3227.35	8475.54
3229.86	8460.67
3232.37	8441.51
3234.87	8429.84
3237.38	8395.5
3239.88	8368.4
3242.38	8354.44
3244.89	8325.73
3247.39	8302.87
3249.89	8271.63
3252.39	8263.22
3254.88	8210.84
3257.38	8192.27
3259.88	8146.11
3262.37	8129.96
3264.87	8115.23
3267.36	8097.18
3269.86	8074.9
3272.35	8072.79
3274.84	8031.54
3277.33	8007.89
3279.82	7984.85
3282.31	7951.12
3284.8	7927.17
3287.29	7892.9
3289.77	7884.18
3292.26	7875.32
3294.15	7827.83
3296.64	7805.28
3299.14	7802.32
3301.63	7789.07
3304.12	7753.34
3306.62	7752.49
3309.11	7723.57
3311.6	7692.31
3314.09	7688.21
3316.58	7649.99
3319.07	7624.42
3321.56	7634.97
3324.04	7654.62
3326.53	7607.97
3329.01	7598.34
3331.5	7565.19
3333.98	7529.17
3336.46	7519.47
3338.94	7498.74
3341.42	7469.63
3343.9	7450.36
3346.38	7441.65
3348.86	7421.04
3351.34	7409.43
3353.82	7397.96
3356.29	7354.79
3358.77	7333.84
3361.24	7327.59
3363.71	7286.74
3366.19	7276.81
3368.66	7268.78
3371.13	7282.06
3373.6	7263.53
3376.07	7232.15
3378.54	7223.45
3381	7183.93
3383.47	7178.93
3385.94	7130.2
3388.4	7110.82
3390.87	7101.45
3393.33	7113.63
3395.79	7075.94
3398.25	7100.98
3400.71	7085
3403.17	7027.25
3405.63	6996.47
3408.09	6985.7
3410.55	6950.81
3413	6956.97
3415.46	6925.13
3417.92	6911.06
3420.37	6879.05
3422.82	6868.2
3425.27	6853.55
3427.73	6783.52
3430.18	6808.63
3432.63	6755.36
3435.08	6780.74
3437.53	6736.98
3439.97	6697.19
3442.42	6650.36
3444.86	6644.84
3447.31	6632.08
3449.75	6623.98
3452.2	6589.78
3454.64	6524.53
3457.08	6546.12
3459.52	6506.41
3461.96	6474.89
3464.4	6411.68
3466.84	6390.29
3469.28	6394.94
3471.72	6340.42
3474.15	6318.26
3476.59	6286.96
3479.02	6239.13
3481.45	6217.72
3483.89	6190.45
3486.32	6154.67
3488.75	6133.69
3491.18	6084.83
3493.61	6063.69
3496.04	6052.58
3498.47	6002.17
3499.68	5972.1