File: src/Milk_AI/Nestle toned milk basic 532nm 50% 600g 50xL 7s 20times 400-3500cm-1 200hole.txt
#Acq. time (s)=	7
#Accumulations=	20
#Range (cm-¹)=	400...3500
#Windows=	3
#Auto scanning=	Off
#Autofocus=	Off
#AutoExposure=	Off
#Spike filter=	Multiple accum.
#Delay time (s)=	0
#Binning=	1
#Readout mode=	Signal
#DeNoise=	Off
#ICS correction=	On
#Dark correction=	Off
#Inst. Process=	Off
#Detector Gain=	Best Dynamic Range
#Detector ADC=	45 kHz
#Detector temperature (°C)=	-60.1
#Instrument=	LabRAM HR Evol
#Detector=	Syncerity OE
#Objective=	x50_VIS_LWD
#Grating=	600 (500nm)
#ND Filter=	50%
#Laser=	532nm_Edge
#Hole=	199.981
#Range=	Visible
#E-Cal_Neon=	0
#StageXY=	75x50mm Scan+
#StageZ=	Z motor
#X (µm)=	0
#Y (µm)=	0
#Z (µm)=	724.6
#Spectral res.(cm-¹)=	12.8
#Full time(mm:ss)=	7:26
#AC=	Calibrated 2025-07-01 10:31
#Project=
#Sample=
#Site=
#Title=	D_1
#Remark=
#Date=	01.07.2025 16:21 (India Standard Time)
#Acquired=	01.07.2025 16:21:36 (India Standard Time)
#AxisType[0]=Intens
#AxisUnit[0]=Cnt
#AxisType[1]=Spectr
#AxisUnit[1]=1/cm
400.083	22451.1
403.63	22310.9
407.176	22367.3
410.72	22422.3
414.263	22448.4
417.805	22507.7
421.345	22493.7
424.884	22537.3
428.421	22571.7
431.955	22607.5
435.49	22629.5
439.023	22623.3
442.555	22621.6
446.084	22681.1
449.613	22633.2
453.141	22630.2
456.666	22729.6
460.191	22697.2
463.715	22667.9
467.235	22722.5
470.756	22766.1
474.274	22769.2
477.793	22852.8
481.308	22842.6
484.823	22874.6
488.336	22880
491.847	22947.8
495.358	22980.7
498.867	23066.7
502.374	23128.7
505.881	23170
509.386	23192.1
512.888	23221.2
516.39	23236.3
519.89	23235.1
523.391	23196.1
526.889	23277
530.385	23293.9
533.88	23233
537.373	23268.6
540.866	23228.6
544.357	23243.5
547.846	23315.3
551.334	23291.1
554.821	23393.6
558.307	23395.8
561.789	23402.8
565.272	23479.8
568.753	23496.7
572.233	23495.7
575.712	23534.4
579.188	23593.6
582.664	23589.8
586.139	23644
589.611	23673.9
593.083	23665.1
596.554	23729.1
600.021	23693.1
603.49	23763.7
606.955	23721.4
610.42	23737.2
613.882	23734.7
617.345	23664.5
620.805	23709.8
624.263	23662.5
627.722	23650.7
631.178	23668.1
634.633	23727.4
638.088	23744.5
641.539	23802.8
644.99	23701
648.439	23710.9
651.887	23730.8
655.335	23764.6
658.781	23873.8
662.225	23820.6
665.667	23856.4
669.108	23907.2
672.548	23888.1
675.987	23876.6
679.424	23883.7
682.86	24035
686.293	23994.7
689.727	24005.9
693.159	24019.1
696.59	24052.4
700.019	24112.8
703.448	24109
706.872	24075.9
710.298	24020.3
713.723	24028.7
717.144	24046.1
720.565	24079.8
723.984	24084.3
727.403	24051.3
730.821	24108.1
734.235	24162.4
737.651	24182.5
741.063	24116.5
744.474	24057.8
747.885	24203.2
751.293	24212.4
754.702	24224.7
758.108	24304.5
761.512	24289.9
764.915	24347.4
768.319	24435.3
771.719	24375
775.118	24407.5
778.516	24443.4
781.913	24494.1
785.308	24499.8
788.702	24435.9
792.095	24445.9
795.486	24417.6
798.876	24463
802.265	24461.9
805.653	24526.4
809.039	24438.6
812.424	24371.1
815.808	24393.5
819.191	24461.9
822.572	24478.2
825.95	24579.8
829.329	24557
832.706	24555.9
836.08	24571.4
839.455	24597.8
842.829	24711.6
846.199	24717.7
849.57	24694.7
852.938	24719.4
856.307	24703.8
859.672	24812.8
863.038	24789.9
866.401	24786.1
869.765	24781.3
873.125	24756.9
876.484	24832.7
879.844	24739.7
883.2	24790.5
886.555	24760.8
889.909	24749.5
893.262	24708.2
896.616	24668.9
899.966	24595.9
903.315	24674.9
906.663	24564.5
910.009	24612.2
913.354	24551.9
916.698	24528
920.041	24549.2
923.383	24596.1
926.723	24454.4
930.062	24523.9
933.399	24435.9
936.734	24462.2
940.069	24577
943.403	24547.4
946.736	24530.7
950.065	24557
953.396	24515.3
956.725	24546.5
960.051	24619.1
963.377	24639.2
966.7	24613.6
970.025	24606.6
973.345	24570
976.667	24573.5
979.985	24588
983.304	24649.5
986.62	24653.3
989.935	24647.5
993.25	24707.1
996.563	24813.3
999.874	24928.3
1003.19	24812.4
1006.49	24755.8
1009.8	24682.8
1013.11	24674.2
1016.41	24751.3
1019.72	24630
1023.02	24663.2
1026.32	24574.9
1029.62	24574.7
1032.92	24557.3
1036.22	24565.2
1039.51	24526.7
1042.81	24546.7
1046.1	24474.9
1049.39	24571
1052.68	24596.6
1055.97	24725
1059.26	24775.4
1062.55	24736.2
1065.83	24658.2
1069.12	24687.8
1072.4	24687.6
1075.68	24689.8
1078.97	24716.9
1082.24	24687.3
1085.52	24642
1088.8	24562
1092.08	24518.7
1095.35	24443.6
1098.62	24386.3
1101.9	24400.5
1105.17	24282.4
1108.44	24328.3
1111.7	24390.6
1114.97	24515
1118.23	24435.8
1121.5	24480.1
1124.76	24474.7
1128.03	24380.7
1131.29	24285.2
1134.54	24191.6
1137.8	24112.4
1141.06	24126.9
1144.31	24288
1147.57	24449.1
1150.82	24644.4
1154.07	24709.1
1157.32	24465.1
1160.57	24272.8
1163.82	24098.1
1167.07	24041
1170.31	23987.8
1173.56	23957.5
1176.8	23938.7
1180.04	23925.4
1183.28	23899.8
1186.52	23917.9
1189.76	23885.2
1192.99	23871.5
1196.23	23851.4
1199.46	23765.8
1202.7	23747
1205.93	23793.7
1209.16	23800.9
1212.39	23767.6
1215.62	23710.6
1218.84	23689.3
1222.07	23717
1225.29	23722.3
1228.52	23767.5
1231.74	23712.4
1234.96	23727.9
1238.18	23710.3
1241.4	23783.5
1244.61	23814.4
1247.83	23839.7
1251.04	23727.8
1254.25	23841.9
1257.47	23791.3
1260.68	23818.1
1263.89	23840
1267.09	23776.9
1270.3	23647.8
1273.51	23635.6
1276.71	23615.7
1279.91	23612.7
1283.12	23607.8
1286.32	23647.6
1289.52	23773.1
1292.72	23864.8
1295.91	23957.5
1299.11	23853.2
1302.3	23871.6
1305.5	23768.7
1308.69	23623.5
1311.88	23597.5
1315.07	23393.1
1318.26	23363.7
1321.44	23299.4
1324.63	23291.1
1327.82	23254.4
1331	23278.9
1334.18	23224.9
1337.36	23241.5
1340.54	23234.5
1343.72	23117.6
1346.9	23102.8
1350.07	23115.1
1353.25	23076.4
1356.42	22948.6
1359.6	22934
1362.77	22938
1365.94	22910.9
1369.11	22858.3
1372.28	22767.6
1375.44	22656.6
1378.61	22693.5
1381.77	22600.2
1384.93	22556
1388.1	22630.8
1391.26	22552.4
1394.41	22593.1
1397.57	22528.9
1400.73	22522.4
1403.89	22565.4
1407.04	22546.5
1410.19	22539.4
1413.35	22527.3
1416.5	22672
1419.65	22692
1422.8	22672.5
1425.94	22803.9
1429.09	23047.2
1432.23	23301.9
1435.38	23453.7
1438.52	23446
1441.66	23420.8
1444.8	23330.6
1447.94	23226.6
1451.08	23125.7
1454.22	23005.6
1457.35	22888.1
1460.48	22774.5
1463.62	22612.4
1466.75	22393.2
1469.88	22302
1473.01	22125.9
1476.14	22009.8
1479.26	21875.3
1482.39	21834.2
1485.51	21835.5
1488.64	21783.8
1491.76	21761.4
1494.88	21868.5
1498	21836.2
1501.12	21810.9
1504.24	21871.5
1507.35	21924.1
1510.47	21984.1
1513.58	22114.9
1516.69	22146.8
1519.81	22096.2
1522.92	22096.4
1526.03	21899.1
1529.13	21701.5
1532.24	21545.9
1535.35	21454.8
1538.45	21461.4
1541.55	21450.8
1544.66	21405.3
1547.76	21352
1550.86	21275
1553.96	21260.9
1557.05	21221.4
1560.15	21167.4
1563.24	21260.7
1566.34	21278.2
1569.43	21240.7
1572.52	21215
1575.61	21122.3
1578.7	21163.4
1581.79	21098.1
1584.88	21095.1
1587.96	21094.8
1591.05	21077.6
1594.13	21032.6
1597.21	21027.4
1600.3	21090.9
1603.37	20986.7
1606.45	21007.4
1609.53	20949.2
1612.61	20832
1615.68	20815.7
1618.76	20755.6
1621.83	20748.4
1624.9	20743.2
1627.97	20779.3
1631.04	20708.9
1634.11	20773.7
1637.18	20692
1640.24	20790
1643.31	20748.5
1646.37	20928.8
1649.44	21038
1652.5	21002.6
1655.56	20901.5
1658.62	20749.3
1661.67	20597.5
1664.73	20557.5
1667.79	20540.5
1670.84	20468.1
1673.89	20422.7
1676.95	20246.7
1680	20226.6
1683.05	20146.4
1686.1	20114.8
1689.14	20025.1
1692.19	19984.3
1695.23	19932.4
1698.28	19885.8
1701.32	19781.9
1704.36	19736.5
1707.4	19719
1710.44	19685.2
1713.48	19668.8
1716.52	19586.6
1719.56	19575
1722.59	19559.9
1725.63	19600.6
1728.66	19580.3
1731.69	19603.9
1734.72	19624.7
1737.75	19623
1740.78	19658
1743.8	19567.1
1746.83	19533.1
1749.86	19530.3
1752.88	19413.3
1755.9	19309
1758.92	19271.4
1761.94	19215.7
1764.96	19138.8
1767.98	19126.1
1771	19132.7
1774.01	19064.4
1777.03	19043.1
1780.04	19114.1
1783.05	19001.8
1786.06	18999
1789.07	18999.8
1792.08	18933.9
1795.09	18952.9
1798.1	18895.2
1801.1	18866.9
1804.11	18816.1
1807.11	18735.6
1810.11	18739.6
1813.11	18730.6
1816.11	18704
1819.11	18681.3
1822.11	18579.6
1825.11	18581.3
1828.1	18566.7
1831.1	18570.4
1834.09	18541.9
1837.08	18443.5
1840.07	18527.4
1843.06	18496.7
1846.05	18449.5
1849.04	18427.4
1852.02	18359.6
1855.01	18323.6
1857.99	18326.5
1860.98	18269.9
1863.96	18238.2
1866.94	18213.2
1869.92	18183.9
1872.9	18196.4
1875.88	18208.3
1878.85	18160.6
1881.83	18087.2
1884.8	18008.6
1887.78	18005.8
1890.75	18009
1893.72	17989.6
1896.69	17903.8
1899.66	17774.8
1902.63	17687.7
1905.59	17613.4
1908.56	17503.3
1911.52	17372.1
1914.49	17265.4
1917.45	17096.3
1920.41	16970
1923.37	16866.9
1926.33	16803.4
1929.29	16705.4
1932.24	16634.4
1935.2	16509.3
1938.15	16378.7
1941.1	16255.5
1944.06	16182
1947.01	16123.2
1949.96	16002.8
1952.91	15846
1955.86	15718.8
1958.8	15639.9
1961.75	15562.7
1964.69	15451.4
1967.64	15389.9
1970.58	15276.3
1973.52	15192
1976.46	15109.5
1979.4	15024.8
1982.34	14940.4
1985.27	14855.3
1988.21	14756.4
1991.14	14655.9
1994.08	14536.3
1997.01	14460.6
1999.94	14351.6
2002.87	14258.2
2005.8	14195.9
2008.73	14147.4
2011.66	14068
2014.58	14014
2017.51	13918.5
2020.43	13834.8
2023.36	13713.3
2026.28	13667.1
2029.2	13603.1
2032.12	13565.9
2035.04	13455.8
2037.95	13424.9
2040.87	13328
2043.78	13299.2
2045.76	13239.3
2048.69	13256.7
2051.61	13220.1
2054.54	13202.7
2057.46	13152.4
2060.38	13126.4
2063.3	13129.1
2066.22	13146.9
2069.14	13097.1
2072.06	13061.4
2074.98	13026.5
2077.89	13026.1
2080.81	12990.8
2083.72	13010.2
2086.63	12961.2
2089.55	12926
2092.46	12926.8
2095.37	12929.5
2098.28	12888.9
2101.18	12868.2
2104.09	12817.4
2106.99	12777.1
2109.9	12781.2
2112.8	12732.8
2115.71	12736.5
2118.61	12732.9
2121.51	12714.3
2124.4	12705.9
2127.3	12725.3
2130.2	12672.5
2133.09	12649.6
2135.99	12672
2138.88	12631.2
2141.78	12627.6
2144.67	12590.7
2147.56	12582.4
2150.45	12598.3
2153.34	12524.7
2156.22	12546.3
2159.11	12544.2
2162	12503
2164.88	12532.4
2167.76	12505.1
2170.64	12479.8
2173.53	12449.2
2176.41	12450.5
2179.29	12456.8
2182.16	12416.6
2185.04	12415.5
2187.92	12331.3
2190.79	12303
2193.66	12323.4
2196.54	12313.4
2199.41	12330.2
2202.28	12279.7
2205.15	12246.4
2208.02	12241.2
2210.88	12173.7
2213.75	12182.1
2216.62	12139.4
2219.48	12085.8
2222.34	12070
2225.21	12046.6
2228.07	12069
2230.93	12039.4
2233.79	11979.9
2236.65	11963.3
2239.5	11956.5
2242.36	11897.8
2245.21	11927.4
2248.07	11894.7
2250.92	11865.6
2253.77	11824.7
2256.62	11756.6
2259.47	11708.1
2262.32	11669.2
2265.17	11687.3
2268.02	11642.4
2270.86	11600.4
2273.71	11561.5
2276.55	11560.7
2279.39	11521.9
2282.24	11513.5
2285.08	11448.1
2287.92	11423.2
2290.75	11433.7
2293.59	11386.8
2296.43	11357.4
2299.26	11357.6
2302.1	11304.9
2304.93	11270.8
2307.76	11216.6
2310.6	11231
2313.43	11226.2
2316.25	11165.4
2319.08	11146.3
2321.91	11151.4
2324.74	11194.3
2327.56	11310.6
2330.39	11101.9
2333.21	11025.4
2336.03	10981.7
2338.85	10985.2
2341.67	10964.2
2344.49	10961.5
2347.31	10890
2350.13	10867.6
2352.94	10829.7
2355.76	10817.8
2358.57	10708.3
2361.39	10716.8
2364.2	10701.6
2367.01	10708.6
2369.82	10684
2372.63	10670.1
2375.44	10626.3
2378.24	10607.5
2381.05	10614.3
2383.85	10595.6
2386.66	10553.3
2389.46	10555.8
2392.26	10529
2395.06	10513.2
2397.86	10492.2
2400.66	10460.2
2403.46	10449.3
2406.26	10393.5
2409.05	10435.8
2411.85	10372.1
2414.64	10344.2
2417.43	10350.5
2420.23	10312.4
2423.02	10294.8
2425.81	10271.9
2428.6	10258.4
2431.38	10250.8
2434.17	10211.2
2436.96	10177.9
2439.74	10171.9
2442.53	10141.2
2445.31	10113.1
2448.09	10127.7
2450.87	10114.4
2453.65	10037
2456.43	10082.2
2459.21	10037.4
2461.98	10023.3
2464.76	9941.82
2467.53	9965.49
2470.31	9964.69
2473.08	9893.68
2475.85	9900.5
2478.63	9872.75
2481.39	9860.93
2484.16	9862.03
2486.93	9833.3
2489.7	9822.83
2492.46	9790.32
2495.23	9757.48
2497.99	9754.71
2500.76	9708.07
2503.52	9708.96
2506.28	9684.42
2509.04	9643.83
2511.8	9648.73
2514.56	9605.3
2517.31	9603.98
2520.07	9621.07
2522.82	9571.5
2525.58	9548.23
2528.33	9557.69
2531.09	9501.84
2533.84	9522.45
2536.59	9507.1
2539.34	9464.04
2542.08	9435.81
2544.83	9448.3
2547.58	9413.94
2550.32	9373.21
2553.07	9355.73
2555.81	9303.05
2558.55	9327.72
2561.29	9309.95
2564.03	9263.84
2566.77	9250.72
2569.51	9255.56
2572.25	9220.93
2574.99	9228.06
2577.72	9188.97
2580.46	9193.73
2583.19	9198.2
2585.92	9177.18
2588.65	9185.61
2591.38	9157.01
2594.11	9186.01
2596.84	9143.01
2599.57	9098.06
2602.3	9060.73
2605.02	9084.6
2607.75	9092.83
2610.47	9050.81
2613.19	9051.39
2615.92	8999.54
2618.64	8990.67
2621.36	8972.31
2624.08	8961.37
2626.8	8959.93
2629.51	8929.87
2632.23	8930.7
2634.94	8897.85
2637.66	8887.05
2640.37	8862.12
2643.08	8837.7
2645.79	8821.17
2648.5	8804.01
2651.21	8803.12
2653.92	8828.97
2656.63	8806.46
2659.33	8759.57
2662.04	8770.77
2664.75	8727.31
2667.45	8740.69
2670.15	8694.99
2672.85	8687.51
2675.55	8708.27
2678.25	8663.86
2680.95	8652.59
2683.65	8625.99
2686.35	8598.94
2689.04	8595.81
2691.74	8558.74
2694.43	8566.47
2697.13	8528.98
2699.82	8531.22
2702.51	8570.11
2705.2	8528.42
2707.89	8501.9
2710.58	8506.72
2713.26	8502.04
2715.95	8466.41
2718.64	8443.28
2721.32	8427.82
2724	8379.35
2726.69	8405.29
2729.37	8372.5
2732.05	8364.85
2734.73	8347.13
2737.41	8307.5
2740.09	8278.73
2742.76	8270.29
2745.44	8272.59
2748.11	8198.21
2750.79	8188.06
2753.46	8176.97
2756.13	8158.36
2758.81	8152.31
2761.47	8113.04
2764.14	8119.83
2766.81	8078.2
2769.48	8057.33
2772.15	8049.09
2774.81	8051.62
2777.48	8036.02
2780.14	8010.76
2782.8	7980.58
2785.47	7946.21
2788.13	7877.62
2790.79	7889.78
2793.44	7905.52
2796.1	7889.7
2798.76	7909.67
2801.42	7859.35
2804.07	7842.93
2806.73	7809.36
2809.38	7812.33
2812.03	7791.51
2814.68	7843.36
2817.33	7808.33
2819.98	7785.98
2822.63	7812.69
2825.28	7765.22
2827.93	7792.48
2830.57	7799.28
2833.22	7832.65
2835.86	7858.92
2838.51	7979.06
2841.15	8120
2843.79	8234.37
2846.43	8406.45
2849.07	8451.38
2851.71	8436.63
2854.35	8375.39
2856.98	8360.71
2859.62	8272.29
2862.25	8233.85
2864.89	8215.39
2867.52	8236.1
2870.15	8256.43
2872.78	8284.76
2875.41	8287.46
2878.04	8332.45
2880.67	8339.69
2883.3	8314.95
2885.92	8309.5
2888.55	8331.8
2891.18	8317.39
2893.8	8269.69
2896.42	8295.12
2899.04	8258.52
2901.67	8220.03
2904.29	8186.18
2906.9	8169.63
2909.52	8160.31
2912.14	8113.88
2914.76	8116.94
2917.37	8067.86
2919.99	8069.85
2922.6	8052.74
2925.21	8049.73
2927.82	8012.98
2930.44	8019.91
2933.05	7985.42
2935.65	7963.03
2938.26	7876.1
2940.87	7759.92
2943.48	7665.85
2946.08	7563.94
2948.69	7542.23
2951.29	7486.5
2953.89	7453.99
2956.49	7429.04
2959.1	7415.78
2961.7	7389.71
2964.29	7343.52
2966.89	7288.53
2969.49	7264.02
2972.09	7214.35
2974.68	7196.98
2977.28	7191.86
2979.87	7169.1
2982.46	7150.51
2985.05	7078.81
2987.65	7073.06
2990.24	7070.91
2992.82	7051.04
2995.41	7021.21
2998	7016.96
3000.59	6998.22
3003.17	6968.12
3005.76	7001.14
3008.34	6945.92
3010.92	6941.06
3013.5	6926.18
3016.09	6886.67
3018.67	6904.33
3021.25	6900.38
3023.82	6916.55
3026.4	6884.38
3028.98	6868.35
3031.55	6823.02
3034.13	6850.65
3036.7	6867.61
3039.28	6870.78
3041.85	6860.5
3044.42	6868.77
3046.99	6848.45
3049.56	6836.05
3052.13	6851.34
3054.69	6861.73
3057.26	6874.33
3059.83	6891.52
3062.39	6874.57
3064.95	6854.89
3067.52	6876.82
3070.08	6858.79
3072.64	6879.77
3075.2	6858.86
3077.76	6879.25
3080.32	6858.41
3082.88	6868.17
3085.44	6888.28
3087.99	6890.95
3090.55	6894.27
3093.1	6920.44
3095.65	6896.94
3098.21	6905.79
3100.76	6896.54
3103.31	6929.5
3105.86	6952.84
3108.41	6970.31
3110.96	6991.89
3113.5	6986.16
3116.05	7002.26
3118.59	7029.54
3121.14	7019.58
3123.68	7034.67
3126.23	7074.87
3128.77	7060.13
3131.31	7112.12
3133.85	7091.93
3136.39	7138.59
3138.93	7125.69
3141.46	7125.53
3144	7144.18
3146.54	7161.8
3149.07	7237.15
3151.6	7225.17
3154.14	7244.45
3156.67	7246.43
3159.2	7255.07
3161.73	7247.31
3164.26	7272.85
3166.79	7263.19
3169.32	7234.16
3171.84	7218.42
3174.37	7179.21
3176.9	7174.53
3179.42	7151.47
3181.94	7104.7
3184.47	7127.07
3186.99	7083.87
3189.51	7084.7
3192.03	7052.28
3194.55	7036.95
3197.07	7008.31
3199.58	6996.06
3202.1	6969.77
3204.62	6969.82
3207.13	6940.79
3209.65	6901.9
3212.16	6876.99
3214.67	6841.69
3217.18	6815
3219.69	6810.64
3222.2	6800.53
3224.71	6785.08
3227.22	6740.35
3229.73	6732.97
3232.23	6708.38
3234.74	6676.29
3237.24	6658.06
3239.75	6626.4
3242.25	6617.36
3244.75	6581.14
3247.25	6558.69
3249.75	6537.29
3252.25	6498.24
3254.75	6465.45
3257.25	6433.66
3259.74	6412.45
3262.24	6379.84
3264.73	6364.72
3267.23	6349.57
3269.72	6339.11
3272.21	6301.41
3274.7	6298.48
3277.2	6247.58
3279.69	6234.37
3282.17	6218.88
3284.66	6186.14
3287.15	6180.02
3289.64	6167.01
3292.12	6146.16
3293.56	6121.91
3296.05	6098.85
3298.55	6080.27
3301.04	6035.86
3303.54	6058.36
3306.03	6023.29
3308.52	6022.28
3311.01	5998.45
3313.5	5977.8
3315.99	5956.27
3318.48	5953.02
3320.97	5944.2
3323.45	5923.49
3325.94	5904.76
3328.42	5901.76
3330.91	5895.04
3333.39	5875.02
3335.87	5870.4
3338.36	5839.47
3340.84	5787.39
3343.32	5809.33
3345.8	5786.92
3348.27	5773.72
3350.75	5764.91
3353.23	5729.42
3355.7	5729.53
3358.18	5712.91
3360.65	5700.7
3363.13	5678.09
3365.6	5669.3
3368.07	5658.35
3370.54	5645.04
3373.01	5657.86
3375.48	5597.05
3377.95	5612.35
3380.42	5601.77
3382.88	5577.42
3385.35	5558.94
3387.81	5550.54
3390.28	5525.5
3392.74	5529.68
3395.2	5493.71
3397.67	5501.26
3400.13	5480.82
3402.58	5455.37
3405.05	5463.78
3407.5	5393.94
3409.96	5425.47
3412.42	5377.95
3414.87	5370.21
3417.33	5362.82
3419.78	5334.38
3422.23	5309.63
3424.69	5316.94
3427.14	5267.15
3429.59	5240.18
3432.04	5234.15
3434.49	5217.28
3436.94	5170.11
3439.39	5157.9
3441.83	5135.4
3444.28	5102.06
3446.72	5101.25
3449.17	5054.48
3451.61	5060.57
3454.05	5029.88
3456.5	5021.6
3458.94	4983.87
3461.38	4959.77
3463.81	4926.24
3466.25	4892.46
3468.69	4862.51
3471.13	4857.21
3473.56	4822.71
3476	4790.47
3478.43	4785.56
3480.87	4730.16
3483.3	4688.92
3485.73	4683.2
3488.16	4644.4
3490.59	4623.01
3493.02	4574.73
3495.45	4561.16
3497.88	4526.7
3499.09	4501.84