File: src/Milk_AI/Nestle toned milk after heating 532nm 50% 600g 50xL 7s 20times 400-3500cm-1 200hole.txt
#Acq. time (s)=	7
#Accumulations=	15
#Range (cm-¹)=	400...3500
#Windows=	3
#Auto scanning=	Off
#Autofocus=	Off
#AutoExposure=	Off
#Spike filter=	Multiple accum.
#Delay time (s)=	0
#Binning=	1
#Readout mode=	Signal
#DeNoise=	Off
#ICS correction=	On
#Dark correction=	Off
#Inst. Process=	Off
#Detector Gain=	Best Dynamic Range
#Detector ADC=	45 kHz
#Detector temperature (°C)=	-60.1
#Instrument=	LabRAM HR Evol
#Detector=	Syncerity OE
#Objective=	x50_VIS_LWD
#Grating=	600 (500nm)
#ND Filter=	50%
#Laser=	532nm_Edge
#Hole=	199.981
#Range=	Visible
#E-Cal_Neon=	0
#StageXY=	75x50mm Scan+
#StageZ=	Z motor
#X (µm)=	0
#Y (µm)=	0
#Z (µm)=	1272.8
#Spectral res.(cm-¹)=	12.8
#Full time(mm:ss)=	5:38
#AC=	Calibrated 2025-06-30 10:26
#Project=
#Sample=
#Site=
#Title=	D_99
#Remark=
#Date=	30.06.2025 17:22 (India Standard Time)
#Acquired=	30.06.2025 17:22:48 (India Standard Time)
#AxisType[0]=Intens
#AxisUnit[0]=Cnt
#AxisType[1]=Spectr
#AxisUnit[1]=1/cm
400.17	32862.3
403.717	32732
407.263	32763.3
410.807	32950.6
414.35	32887.2
417.892	33033
421.432	33063.8
424.971	33106.9
428.509	33151
432.045	33261.6
435.58	33330.2
439.111	33324.4
442.643	33370.4
446.174	33395.6
449.701	33404.6
453.229	33431.7
456.756	33479.7
460.279	33502.5
463.803	33518.6
467.326	33549.4
470.845	33579.1
474.365	33615.6
477.882	33739.1
481.399	33735.6
484.913	33871.6
488.425	33914
491.938	33947.2
495.448	34017.7
498.956	34102.9
502.465	34291.6
505.971	34342.3
509.475	34385.7
512.981	34427.2
516.482	34526
519.983	34478.8
523.482	34496.3
526.979	34557.8
530.476	34599.3
533.971	34563.6
537.464	34575.6
540.956	34522.8
544.447	34681.4
547.937	34784.5
551.425	34699.8
554.912	34792.2
558.398	34862.5
561.882	34826.3
565.365	34981.6
568.847	35025.3
572.325	35102.9
575.804	35118.8
579.282	35173.4
582.756	35222.4
586.231	35302.5
589.705	35356.4
593.175	35375.4
596.646	35498.1
600.116	35438.4
603.582	35629.1
607.049	35596
610.513	35665.7
613.977	35620.4
617.438	35600.4
620.898	35542.7
624.359	35575.7
627.816	35472.2
631.272	35444.5
634.728	35482.5
638.181	35565.5
641.633	35680.4
645.084	35552.3
648.535	35525.2
651.983	35499.2
655.43	35599.7
658.875	35683.6
662.319	35704
665.762	35778.1
669.203	35820
672.643	35779.9
676.082	35839.1
679.519	35890.3
682.955	36032.1
686.39	36068.4
689.824	36117.5
693.256	36194.9
696.685	36173.1
700.115	36296.8
703.543	36286.5
706.97	36241.4
710.394	36247.2
713.818	36250.3
717.241	36232.9
720.661	36306.9
724.082	36230.2
727.501	36271.7
730.917	36196.2
734.334	36368
737.747	36295.1
741.161	36244.3
744.572	36319.3
747.982	36297.5
751.392	36398.7
754.799	36453.2
758.205	36623.6
761.611	36609.6
765.014	36672.7
768.416	36765.4
771.816	36807.6
775.218	36880.7
778.616	36986.2
782.012	36991.6
785.408	37029.3
788.802	37078.7
792.195	37037.3
795.586	37029.4
798.977	37044.7
802.365	37179.8
805.753	37174.9
809.14	37137.7
812.525	36934.6
815.907	36904.4
819.289	36989.6
822.671	37037
826.051	37123.2
829.43	37070.3
832.805	37111.8
836.182	36970.1
839.557	36961.6
842.928	37055.7
846.301	37206.1
849.67	37186.1
853.04	37152.5
856.407	37228.8
859.774	37329.1
863.138	37297.2
866.503	37207.3
869.865	37236.3
873.225	37297.3
876.586	37506.3
879.944	37344.5
883.301	37294.2
886.658	37303.1
890.012	37397.4
893.365	37448.1
896.717	37395.7
900.067	37337.6
903.416	37378.3
906.766	37342.9
910.112	37335.2
913.458	37347
916.802	37264.1
920.145	37281.7
923.484	37287.3
926.825	37169.9
930.164	37085.4
933.501	37129.9
936.838	37091.9
940.173	37192.1
943.505	37252
946.838	37221.3
950.17	37158.8
953.5	37219.9
956.827	37205.3
960.155	37240.4
963.48	37379.3
966.805	37356.9
970.128	37364.4
973.45	37268.3
976.77	37308.5
980.091	37405
983.408	37561
986.726	37485.8
990.041	37560.6
993.354	37558.9
996.668	37645.8
999.979	37719.5
1003.29	37870.9
1006.6	37855.4
1009.91	37701.3
1013.21	37667.9
1016.52	37671.9
1019.82	37630.4
1023.12	37624.6
1026.43	37539.6
1029.73	37395.7
1033.02	37388.4
1036.32	37379
1039.62	37430.5
1042.91	37384.9
1046.21	37291.6
1049.5	37295.5
1052.79	37345
1056.08	37335.7
1059.37	37381.8
1062.65	37517.7
1065.94	37393.2
1069.23	37353
1072.51	37427.3
1075.79	37340.7
1079.07	37432.7
1082.35	37403.8
1085.63	37455.1
1088.91	37493.7
1092.18	37368.8
1095.46	37294.1
1098.73	37256.5
1102	37198.9
1105.27	37104
1108.54	37117.1
1111.81	37248.4
1115.08	37227.6
1118.34	37322.8
1121.61	37300.9
1124.87	37275.3
1128.13	37252.8
1131.39	37144.8
1134.65	37147.8
1137.91	36957.7
1141.17	36963.6
1144.42	37059.6
1147.68	37067.8
1150.93	37242.5
1154.18	37517.5
1157.43	37592.1
1160.68	37320.9
1163.93	36992
1167.18	36883
1170.42	36867.5
1173.67	36718.7
1176.91	36784.8
1180.15	36644.5
1183.39	36706.9
1186.63	36663.9
1189.87	36710.5
1193.11	36718.8
1196.34	36637.3
1199.58	36583
1202.81	36631.5
1206.04	36634.5
1209.27	36720.2
1212.5	36658.4
1215.73	36516.8
1218.95	36554.9
1222.18	36534.1
1225.4	36532.7
1228.63	36631
1231.85	36602.3
1235.07	36569.7
1238.29	36552.5
1241.51	36625.8
1244.72	36649.6
1247.94	36627.2
1251.15	36672.6
1254.37	36593.1
1257.58	36480.4
1260.79	36598.9
1264	36505.7
1267.21	36494.2
1270.41	36457.8
1273.62	36347.7
1276.82	36337.6
1280.03	36289.7
1283.23	36244.7
1286.43	36187.9
1289.63	36213.5
1292.83	36247.9
1296.03	36292.9
1299.22	36391.6
1302.42	36496.3
1305.61	36497
1308.8	36432.7
1311.99	36314.8
1315.18	36150.6
1318.37	36070.1
1321.56	35952.6
1324.74	36008.5
1327.93	35975.1
1331.11	36080.6
1334.3	35967.5
1337.48	36038.5
1340.66	36020.9
1343.84	35941.9
1347.01	35988.5
1350.19	35906.6
1353.37	35877.8
1356.54	35651.3
1359.71	35610.7
1362.88	35686.7
1366.05	35611.9
1369.22	35556.9
1372.39	35539.6
1375.56	35304.3
1378.72	35237.8
1381.89	35201.5
1385.05	35102.2
1388.21	35163.7
1391.37	35165.9
1394.53	35137.7
1397.69	34949.2
1400.85	34997
1404	34861.2
1407.16	34948.5
1410.31	34955.3
1413.46	34939.2
1416.61	35055.5
1419.76	35015.4
1422.91	35038.4
1426.06	34987.9
1429.21	35066.7
1432.35	35412.7
1435.49	35624
1438.64	35777.9
1441.78	35789.5
1444.92	35639.2
1448.06	35586.1
1451.2	35457.3
1454.33	35462.5
1457.47	35340
1460.6	35242.9
1463.74	35121.9
1466.87	34926.5
1470	34801.3
1473.13	34629.3
1476.26	34428
1479.38	34250.2
1482.51	34217.1
1485.63	34152.6
1488.76	34174
1491.88	34112.4
1495	34187.2
1498.12	34137
1501.24	34051.8
1504.36	34191.6
1507.47	34006.8
1510.59	34221.9
1513.7	34228.7
1516.81	34372.2
1519.93	34418.8
1523.04	34450.4
1526.15	34265.8
1529.25	34175
1532.36	33810.6
1535.47	33745.7
1538.57	33675
1541.67	33645.3
1544.78	33499.2
1547.88	33521.5
1550.98	33365.9
1554.08	33387.2
1557.18	33379.1
1560.27	33363.8
1563.37	33415.2
1566.46	33392.2
1569.55	33372.6
1572.64	33335.4
1575.74	33270.3
1578.83	33267.7
1581.91	33262.9
1585	33223
1588.09	33189.5
1591.17	33174.3
1594.25	33031.7
1597.34	33074.7
1600.42	33071.1
1603.5	33063.4
1606.58	32984.6
1609.65	32959.8
1612.73	32838.7
1615.8	32797.8
1618.88	32778.6
1621.95	32621.8
1625.03	32676.7
1628.1	32677.5
1631.17	32641.4
1634.23	32629.3
1637.3	32584
1640.37	32672.5
1643.43	32518.2
1646.5	32639.6
1649.56	32717.4
1652.62	32809.8
1655.68	32787.8
1658.74	32647.6
1661.8	32534.9
1664.85	32472.8
1667.91	32346.6
1670.96	32344.6
1674.02	32265.8
1677.07	32179.8
1680.12	31967.3
1683.17	31970.4
1686.22	31830.7
1689.27	31773.8
1692.31	31750.8
1695.36	31698.4
1698.4	31642.4
1701.45	31432.7
1704.49	31425.8
1707.53	31382.3
1710.57	31380.1
1713.61	31311
1716.65	31180.8
1719.68	31159.6
1722.72	31194.3
1725.75	31142.8
1728.78	31167.9
1731.82	31079.5
1734.84	31071.3
1737.87	31161.4
1740.9	31047.6
1743.93	31116
1746.96	31029.8
1749.98	31059.9
1753	30880.5
1756.03	30787.5
1759.05	30714.4
1762.07	30704.5
1765.09	30486.1
1768.11	30604.4
1771.12	30545.9
1774.14	30651.1
1777.15	30449.7
1780.17	30540.6
1783.18	30418
1786.19	30454.8
1789.2	30479.1
1792.21	30320.2
1795.22	30402.6
1798.22	30317.4
1801.23	30191.6
1804.23	30217.5
1807.24	30133.7
1810.24	30180
1813.24	30178.3
1816.24	30087.3
1819.24	30043.8
1822.24	30001.6
1825.23	29918
1828.23	29932.9
1831.22	29919.1
1834.22	29959
1837.21	29797.4
1840.2	29877.5
1843.19	29813.7
1846.18	29859.8
1849.17	29797.5
1852.15	29650.5
1855.14	29583.3
1858.12	29602.5
1861.11	29562.6
1864.09	29602.4
1867.07	29470
1870.05	29493.1
1873.03	29437.5
1876.01	29444.1
1878.98	29352.9
1881.96	29237.5
1884.93	29165.1
1887.91	29183.6
1890.88	29175.7
1893.85	29121.8
1896.82	28926.6
1899.79	28902.7
1902.76	28832.9
1905.72	28625.2
1908.69	28452.4
1911.65	28299.4
1914.62	28181
1917.58	28056.1
1920.54	27923
1923.5	27770.8
1926.46	27682.7
1929.42	27579.2
1932.37	27431.1
1935.33	27345
1938.28	27166.3
1941.24	27049
1944.19	26893.8
1947.14	26763.5
1950.09	26647.1
1953.04	26456.9
1955.99	26261
1958.93	26149.2
1961.88	26078.1
1964.82	25942.4
1967.77	25828.9
1970.71	25723.3
1973.65	25588.7
1976.59	25466.5
1979.53	25329.3
1982.47	25248.3
1985.41	25167.8
1988.34	25047.4
1991.28	24880.9
1994.21	24761.2
1997.14	24604.8
2000.07	24477.6
2003.01	24365.2
2005.94	24264.3
2008.86	24231.4
2011.79	24123.1
2014.72	24000.6
2017.64	23880.4
2020.57	23798
2023.49	23639.6
2026.41	23568.2
2029.33	23492.7
2032.25	23402.9
2035.17	23309.5
2038.09	23226.5
2041	23199.4
2043.92	23109.9
2045.86	23007.6
2048.79	23003.4
2051.71	22914.2
2054.64	23029.3
2057.56	22907.4
2060.48	22889.8
2063.4	22861.8
2066.32	22873.4
2069.24	22784.9
2072.16	22708.9
2075.08	22719.9
2077.99	22668
2080.91	22650.8
2083.82	22611
2086.74	22576.3
2089.65	22512.6
2092.56	22460.2
2095.47	22382.1
2098.38	22437.5
2101.29	22301.3
2104.19	22320.8
2107.1	22261.5
2110	22250.2
2112.91	22161.9
2115.81	22067.8
2118.71	22151.9
2121.61	22103
2124.51	22004.2
2127.4	21998.6
2130.3	21934.7
2133.2	21933.5
2136.09	21963.1
2138.99	21917.8
2141.88	21854.8
2144.77	21849
2147.66	21791.9
2150.55	21789
2153.44	21722.8
2156.33	21685.9
2159.21	21704.9
2162.1	21654
2164.98	21608.1
2167.87	21615.6
2170.75	21609.4
2173.63	21687.6
2176.51	21509.6
2179.39	21524
2182.27	21453.7
2185.14	21466.3
2188.02	21413.1
2190.9	21352.4
2193.77	21331.9
2196.64	21296.7
2199.51	21234.3
2202.39	21288.3
2205.25	21228.8
2208.12	21176.3
2210.99	21117
2213.86	21033.9
2216.72	20983
2219.59	20953.2
2222.45	20893
2225.31	20909.1
2228.17	20833.4
2231.03	20796.5
2233.89	20756.5
2236.75	20719.2
2239.61	20734.8
2242.46	20603.1
2245.32	20589.9
2248.17	20508.1
2251.03	20510.5
2253.88	20451
2256.73	20371.8
2259.58	20347
2262.43	20169.9
2265.28	20141.2
2268.12	20078.8
2270.97	20000.9
2273.81	20022.6
2276.66	19965.9
2279.5	19891.3
2282.34	19837.1
2285.18	19743.6
2288.02	19725.8
2290.86	19756.1
2293.7	19632.8
2296.54	19587.7
2299.37	19514.3
2302.21	19526.2
2305.04	19431.9
2307.87	19408.3
2310.7	19399.2
2313.53	19287.7
2316.36	19285.5
2319.19	19213.1
2322.02	19079.4
2324.85	19171.2
2327.67	19189
2330.5	19237.4
2333.32	19005.2
2336.14	18958.1
2338.96	18930.4
2341.78	18884.1
2344.6	18810.7
2347.42	18756.6
2350.24	18658.3
2353.05	18630
2355.87	18610.2
2358.68	18496.7
2361.5	18505.9
2364.31	18383.3
2367.12	18412.8
2369.93	18362.3
2372.74	18310.3
2375.55	18252.5
2378.35	18251.1
2381.16	18276.3
2383.96	18176.8
2386.77	18092.3
2389.57	18138.5
2392.37	18093.9
2395.17	18004.9
2397.97	17993
2400.77	17933.5
2403.57	17903.1
2406.37	17827.6
2409.16	17839.2
2411.96	17741.2
2414.75	17777.7
2417.55	17743.4
2420.34	17620.8
2423.13	17630.1
2425.92	17588.5
2428.71	17538.7
2431.5	17548.8
2434.28	17469.3
2437.07	17454
2439.85	17412.9
2442.64	17401.4
2445.42	17337
2448.2	17357.9
2450.98	17308.2
2453.76	17251.3
2456.54	17233.9
2459.32	17121.8
2462.1	17149.9
2464.87	17113.7
2467.65	17074.5
2470.42	17012.6
2473.2	16981.4
2475.97	16909.3
2478.74	16905.1
2481.51	16901
2484.28	16919.3
2487.05	16793
2489.81	16777.4
2492.58	16688
2495.34	16681.9
2498.11	16725.8
2500.87	16579.6
2503.63	16574.9
2506.39	16575.3
2509.15	16485.6
2511.91	16478.4
2514.67	16363.8
2517.43	16359.8
2520.19	16354.8
2522.94	16305.4
2525.7	16302.6
2528.45	16258
2531.2	16236.7
2533.95	16236.4
2536.7	16151.2
2539.45	16169.2
2542.2	16134.8
2544.95	16051.5
2547.69	15982.4
2550.44	15953.7
2553.18	15914.6
2555.93	15900.3
2558.67	15840.1
2561.41	15790.1
2564.15	15809.5
2566.89	15774.4
2569.63	15731.7
2572.36	15699.3
2575.1	15681.8
2577.84	15638.4
2580.57	15628.8
2583.31	15587.3
2586.04	15584.9
2588.77	15569.8
2591.5	15556.5
2594.23	15474.2
2596.96	15560.6
2599.69	15456.9
2602.41	15429.3
2605.14	15416.2
2607.86	15378.5
2610.59	15366.2
2613.31	15345.4
2616.03	15274.7
2618.75	15251.6
2621.48	15170.1
2624.19	15184.8
2626.91	15154.7
2629.63	15121.5
2632.35	15083
2635.06	15055.5
2637.77	15006.2
2640.49	14956.9
2643.2	14974.7
2645.91	14948.2
2648.62	14874.4
2651.33	14871.8
2654.04	14875.6
2656.75	14796.2
2659.45	14786.1
2662.16	14783.8
2664.86	14739.8
2667.57	14676.2
2670.27	14667.9
2672.97	14697.3
2675.67	14627.7
2678.37	14631.2
2681.07	14547.3
2683.77	14538.9
2686.47	14519.9
2689.16	14516.3
2691.86	14461.2
2694.55	14435.2
2697.25	14402.7
2699.94	14395.2
2702.63	14367.6
2705.32	14354.2
2708.01	14310
2710.7	14303.5
2713.39	14243.6
2716.07	14228.3
2718.76	14205.8
2721.44	14171.1
2724.12	14089.9
2726.81	14087.5
2729.49	14069.5
2732.17	14056.3
2734.85	14043.3
2737.53	13964.9
2740.21	13903.2
2742.88	13877.5
2745.56	13837.7
2748.24	13797.7
2750.91	13755
2753.58	13760.7
2756.25	13665.4
2758.93	13637.7
2761.6	13580.5
2764.27	13592.8
2766.93	13575.6
2769.6	13538.9
2772.27	13525.3
2774.93	13455.7
2777.6	13428.9
2780.26	13351.2
2782.93	13331.8
2785.59	13271.5
2788.25	13259.5
2790.91	13199.2
2793.57	13255.7
2796.23	13229.7
2798.88	13160.5
2801.54	13144.6
2804.2	13067.1
2806.85	13053
2809.5	13039.5
2812.16	13020.4
2814.81	13031.9
2817.46	12986.1
2820.11	12968.7
2822.76	12952.1
2825.4	12900.1
2828.05	12903.5
2830.7	12915.6
2833.34	12894.8
2835.99	12908.8
2838.63	12928.7
2841.27	13038.6
2843.91	13172.1
2846.55	13367
2849.19	13589.8
2851.83	13661.3
2854.47	13686.7
2857.11	13595
2859.74	13484.5
2862.38	13394.5
2865.01	13342.9
2867.65	13292.9
2870.28	13304.6
2872.91	13309.7
2875.54	13348.4
2878.17	13373.9
2880.8	13304.4
2883.42	13310.8
2886.05	13361.8
2888.68	13357
2891.3	13437.7
2893.93	13376.8
2896.55	13278.6
2899.17	13289.6
2901.79	13218.1
2904.41	13182.9
2907.03	13163.2
2909.65	13106.5
2912.27	13098.6
2914.88	13028.1
2917.5	13036.6
2920.11	13004.5
2922.73	12902.4
2925.34	12903.2
2927.95	12828.8
2930.56	12830.7
2933.17	12824.5
2935.78	12782.9
2938.39	12731
2941	12579.2
2943.6	12407.5
2946.21	12245.4
2948.81	12189.1
2951.42	12086.7
2954.02	12020.4
2956.62	12001.3
2959.22	11948.2
2961.82	11932.2
2964.42	11871.7
2967.02	11821.6
2969.62	11776.4
2972.21	11732.8
2974.81	11694.9
2977.4	11680.8
2980	11618.9
2982.59	11567.5
2985.18	11549.6
2987.77	11462.5
2990.36	11423.2
2992.95	11492.3
2995.54	11409.4
2998.13	11406.8
3000.72	11404.7
3003.3	11348.9
3005.89	11316.7
3008.47	11304.5
3011.05	11262.1
3013.63	11240.1
3016.22	11204.5
3018.8	11207.9
3021.38	11199.4
3023.95	11235.9
3026.53	11158.3
3029.11	11137.2
3031.68	11112.3
3034.26	11078.5
3036.83	11095
3039.4	11093.5
3041.98	11123.8
3044.55	11080.2
3047.12	11079.6
3049.69	11086.7
3052.26	11068
3054.82	11081.6
3057.39	11089.4
3059.96	11052.6
3062.52	11065
3065.09	11048.3
3067.65	11055.3
3070.21	11096.3
3072.77	11040.6
3075.33	11072.4
3077.89	11061.8
3080.45	11078.7
3083.01	11011.4
3085.57	10999.2
3088.12	11041.9
3090.68	11057.5
3093.23	11070.7
3095.79	11029.8
3098.34	10992.8
3100.89	11057.4
3103.44	11022.9
3105.99	11081.6
3108.54	11100.6
3111.09	11084.2
3113.63	11063
3116.18	11096.7
3118.73	11107.6
3121.27	11106.6
3123.82	11119.5
3126.36	11130.2
3128.9	11159.7
3131.44	11160.9
3133.98	11210.4
3136.52	11218.5
3139.06	11228.8
3141.6	11193.5
3144.13	11255.8
3146.67	11210.4
3149.2	11256.7
3151.74	11258.5
3154.27	11264.6
3156.8	11313.7
3159.34	11295.8
3161.86	11293
3164.4	11292.9
3166.92	11315.4
3169.45	11313.2
3171.98	11312.1
3174.5	11279.7
3177.03	11280.5
3179.56	11233.3
3182.08	11224.6
3184.6	11230.3
3187.12	11208.6
3189.64	11213.4
3192.16	11140.1
3194.68	11153.6
3197.2	11133.5
3199.72	11078.5
3202.24	11116.3
3204.75	11069.9
3207.27	11048
3209.78	11055.8
3212.29	11003.6
3214.81	10988.1
3217.32	10934.5
3219.83	10934.8
3222.34	10939.7
3224.85	10902.3
3227.35	10886
3229.86	10847.8
3232.37	10830.4
3234.87	10815
3237.38	10807.8
3239.88	10768.3
3242.38	10755.9
3244.89	10703.7
3247.39	10677.2
3249.89	10666.6
3252.39	10642.9
3254.88	10605
3257.38	10534.6
3259.88	10512.6
3262.37	10485.8
3264.87	10471.8
3267.36	10447.9
3269.86	10416.3
3272.35	10421.2
3274.84	10360.2
3277.33	10352.3
3279.82	10315.4
3282.31	10255.4
3284.8	10260.1
3287.29	10232.9
3289.77	10204.4
3292.26	10194.9
3294.15	10176.5
3296.64	10107.3
3299.14	10087.9
3301.63	10125.7
3304.12	10091.9
3306.62	10053.6
3309.11	9990.01
3311.6	10001.1
3314.09	9953.29
3316.58	9953.2
3319.07	9948.38
3321.56	9900.36
3324.04	9889.59
3326.53	9902.33
3329.01	9832.12
3331.5	9834.86
3333.98	9759.57
3336.46	9750.97
3338.94	9768.96
3341.42	9673.33
3343.9	9691.52
3346.38	9688.03
3348.86	9679.44
3351.34	9631.11
3353.82	9605.5
3356.29	9568.7
3358.77	9555.06
3361.24	9563.99
3363.71	9514.24
3366.19	9481.36
3368.66	9470.07
3371.13	9456.66
3373.6	9474.67
3376.07	9430.9
3378.54	9401.21
3381	9344.9
3383.47	9374.88
3385.94	9335.62
3388.4	9308.93
3390.87	9265.75
3393.33	9278.8
3395.79	9253.8
3398.25	9242.9
3400.71	9243.43
3403.17	9192.44
3405.63	9163.34
3408.09	9151.61
3410.55	9109.81
3413	9071.31
3415.46	9070.79
3417.92	9008.93
3420.37	9005.22
3422.82	8976.69
3425.27	8945.17
3427.73	8932.76
3430.18	8886.12
3432.63	8890.77
3435.08	8850.58
3437.53	8802.22
3439.97	8766.7
3442.42	8756.67
3444.86	8733.24
3447.31	8721.4
3449.75	8668.6
3452.2	8637.67
3454.64	8584.96
3457.08	8566.44
3459.52	8549.57
3461.96	8531.59
3464.4	8478.44
3466.84	8470.72
3469.28	8465.72
3471.72	8383.29
3474.15	8348.28
3476.59	8310.32
3479.02	8225.43
3481.45	8186.4
3483.89	8216.35
3486.32	8156
3488.75	8151.44
3491.18	8078.55
3493.61	8033.94
3496.04	8020.71
3498.47	7979.36
3499.68	7929